Workbook

Sheet Overview
A2: Model: | B2: H998192
A3: Version: | B3: 2.0.0.0
A5: Coin | B5: Coin in | C5: Pay Back (%) | D5: Simulate Round
A6: 100 | B6: 1 | C6: =B13+B14 -> 0.92000243 | D6: 100000000
A7: {=A6*B7:B9} -> 125 | B7: 1.25 | C7: =B18+B19 -> 0.91995941
A8: 10000 | B8: 100 | C8: =B23+B24 -> 0.92499137
A9: 50000 | B9: 500 | C9: =B28+B29 -> 0.92498006
A11: The Normal Bet Total Pay Back Percentage includes the following adjustments.
A12: Coin | B12: Pay Back | C12: Hit% | D12: Pulls/Hit | E12: Description
A13: =A6 -> 100 | B13: =Multiplier_Weight_Oldhand!C7 -> 0.7550351 | C13: - | D13: - | E13: Base Game
B14: =Multiplier_Weight_Oldhand!D7 -> 0.16496733 | C14: =1/Multiplier_Weight_Oldhand!G7 -> 0.001999942 | D14: =1/C14 -> 500.0145 | E14: Free Game
A16: The Extra Bet Total Pay Back Percentage includes the following adjustments.
A17: Coin | B17: Pay Back | C17: Hit% | D17: Pulls/Hit | E17: Description
A18: =A7 -> 125 | B18: =Multiplier_Weight_Oldhand!C8 -> 0.61294967 | C18: - | D18: - | E18: Base Game
B19: =Multiplier_Weight_Oldhand!D8 -> 0.30700974 | C19: =1/Multiplier_Weight_Oldhand!G8 -> 0.004652449 | D19: =1/C19 -> 214.94056 | E19: Free Game
A21: The Buy Feature Total Pay Back Percentage includes the following adjustments.
A22: Coin | B22: Pay Back | C22: Hit% | D22: Pulls/Hit | E22: Description
A23: =A8 -> 10000 | B23: =Multiplier_Weight_Oldhand!C9 -> 0.033142974 | C23: - | D23: - | E23: Base Game
B24: =Multiplier_Weight_Oldhand!D9 -> 0.8918484 | C24: - | D24: - | E24: Free Game
A26: The Super Feature Total Pay Back Percentage includes the following adjustments.
A27: Coin | B27: Pay Back | C27: Hit% | D27: Pulls/Hit | E27: Description
A28: =A9 -> 50000 | B28: =Multiplier_Weight_Oldhand!C10 -> 0.0066285948 | C28: - | D28: - | E28: Base Game
B29: =Multiplier_Weight_Oldhand!D10 -> 0.91835147 | C29: - | D29: - | E29: Free Game
A32: Reel # | B32: 1 | C32: 2 | D32: 3 | E32: 4 | F32: 5 | G32: 6
A33: Visible Window Size | B33: 5 | C33: 5 | D33: 5 | E33: 5 | F33: 5 | G33: 5
A36: Feature Description
A37: 1. Base Game中，為5x6的盤面，任一Symbol在盤面上超過8顆即可消除。消除所有贏分的標誌後，剩餘標誌往下掉落。 2. 初始盤面為輪帶滾停，消除後依照輪帶Symbol順序掉落 3. 每一滾輪皆有機會出現C1，連線消除後也有機會出現C1。當無得分時，當盤面上出現四個以上的C1，則觸發免費遊戲。四個C1、五個C1與六個C1皆可獲得10場免費遊戲。
A43: Free Spins Setting
A44: C1 Num | B44: Add Free Spin
A45: 4 | B45: 10
A46: 5 | B46: 10
A47: 6 | B47: 10
A49: Retrigger Setting
A50: C1 Num | B50: Add Free Spin
A51: 3 | B51: 5
A52: 4 | B52: 5
A53: 5 | B53: 5
A54: 6 | B54: 5
A56: ="All wins show for "&A6&" credit bet." -> All wins show for 100 credit bet.
A57: Symbol | B57: Description | C57: 4 | D57: 5 | E57: 6 | F57: 8~9 | G57: 10~11 | H57: 12+ | I57: Id
...

Sheet Description
B3: 1. 遊戲盤面為5X6
B5: 2. 消除條件為 Symbol 總數超過8顆即可消除
B7: 3. 消除掉落依照輪帶順序掉落
B9: 4. 單一輪帶只會出現一顆 C1，若掉落時遇到下一顆 C1 需跳過
B11: 5. Normal Bet BG 使用兩張表，選表權重如下
C13: Table | D13: Weight
C14: Symbol-1 | D14: {=Parameter!C6:C8} -> 1
C15: Symbol-2 | D15: 0
C16: Symbol-3 | D16: 0
B19: 6. Extra Bet BG 使用兩張表，選表權重如下
C21: Table | D21: Weight
C22: Symbol-1 | D22: {=Parameter!D6:D8} -> 1
C23: Symbol-2 | D23: 0
C24: Symbol-3 | D24: 0
B27: 7. FG 乘倍符號於輪帶中，乘倍數字依權重產生
B29: 8. 當盤面無法消除時，將盤面上的乘倍符號倍數加總乘上此次 Spin 分數即為總贏分
B31: 9. 在 Normal Bet 與 Extra Bet 中進入的 FG 使用高低表，場次由權重決定，Retrigger 增加1場高表4場低表，最大場次為50場
C33: 高表場次 | D33: 低表場次 | E33: Weight
C34: 0 | D34: 10 | E34: {=Parameter!D12:D22} -> 0
C35: 1 | D35: 9 | E35: 0
C36: 2 | D36: 8 | E36: 1
C37: 3 | D37: 7 | E37: 0
C38: 4 | D38: 6 | E38: 0
C39: 5 | D39: 5 | E39: 0
C40: 6 | D40: 4 | E40: 0
C41: 7 | D41: 3 | E41: 0
C42: 8 | D42: 2 | E42: 0
C43: 9 | D43: 1 | E43: 0
C44: 10 | D44: 0 | E44: 0
B47: 10. 在 Feature Buy 中進入的 FG 使用高低表，場次由權重決定，Retrigger 增加1場高表4場低表，最大場次為50場
C49: 高表場次 | D49: 低表場次 | E49: Weight
C50: 0 | D50: 10 | E50: {=Parameter!E12:E22} -> 0
C51: 1 | D51: 9 | E51: 0
C52: 2 | D52: 8 | E52: 1
C53: 3 | D53: 7 | E53: 0
C54: 4 | D54: 6 | E54: 0
C55: 5 | D55: 5 | E55: 0
C56: 6 | D56: 4 | E56: 0
C57: 7 | D57: 3 | E57: 0
C58: 8 | D58: 2 | E58: 0
...

Sheet Parameter
A3: 1
A4: {=_xlfn.LET(_xlpm.x, CHOOSE(A3, A44:H83,A84:H123), IF(_xlpm.x="", "", _xlpm.x))} -> [A] | B4: Normal Bet BG 和 Extra Bet 選表的權重如下
B5: Table | C5: Normal Bet | D5: Extra Bet
B6: Symbol-1 | C6: 1 | D6: 1
B7: Symbol-2 | C7: 0 | D7: 0
B8: Symbol-3 | C8: 0 | D8: 0
B10: Normal / Extra Bet 和 Feature Buy，幾張高表、幾張低表權重如下
B11: 高表場次 | C11: 低表場次 | D11: Normal / Extra Bet | E11: Feature Buy | F11: Super Feature Buy
B12: 0 | C12: 10 | D12: 0 | E12: 0 | F12: 0
B13: 1 | C13: 9 | D13: 0 | E13: 0 | F13: 0
B14: 2 | C14: 8 | D14: 1 | E14: 1 | F14: 1
B15: 3 | C15: 7 | D15: 0 | E15: 0 | F15: 0
B16: 4 | C16: 6 | D16: 0 | E16: 0 | F16: 0
B17: 5 | C17: 5 | D17: 0 | E17: 0 | F17: 0
B18: 6 | C18: 4 | D18: 0 | E18: 0 | F18: 0
B19: 7 | C19: 3 | D19: 0 | E19: 0 | F19: 0
B20: 8 | C20: 2 | D20: 0 | E20: 0 | F20: 0
B21: 9 | C21: 1 | D21: 0 | E21: 0 | F21: 0
B22: 10 | C22: 0 | D22: 0 | E22: 0 | F22: 0
B24: Free Game 和 Feature Buy C2 上的倍數權重如下
B25: C2 Multiplier | C25: Weight
C26: Free Game Symbol (1) | D26: Free Game Symbol (2) | E26: Buy Feature FG Symbol (1) | F26: Buy Feature FG Symbol (2) | G26: Super Feature FG Symbol (1) | H26: Super Feature FG Symbol (2)
A27: 2 | B27: 2x | C27: 9500 | D27: 9500 | E27: 1 | F27: 1 | G27: 0 | H27: 0
A28: 3 | B28: 3x | C28: 8600 | D28: 8600 | E28: 0 | F28: 0 | G28: 0 | H28: 0
A29: 4 | B29: 4x | C29: 6200 | D29: 6200 | E29: 0 | F29: 0 | G29: 0 | H29: 0
A30: 5 | B30: 5x | C30: 7900 | D30: 7900 | E30: 0 | F30: 0 | G30: 0 | H30: 0
A31: 6 | B31: 6x | C31: 7100 | D31: 7100 | E31: 0 | F31: 0 | G31: 0 | H31: 0
A32: 8 | B32: 8x | C32: 10400 | D32: 10400 | E32: 0 | F32: 0 | G32: 0 | H32: 0
A33: 10 | B33: 10x | C33: 9900 | D33: 9900 | E33: 0 | F33: 0 | G33: 0 | H33: 0
A34: 12 | B34: 12x | C34: 9700 | D34: 9700 | E34: 0 | F34: 0 | G34: 0 | H34: 0
A35: 15 | B35: 15x | C35: 5900 | D35: 5900 | E35: 0 | F35: 0 | G35: 0 | H35: 0
A36: 20 | B36: 20x | C36: 2400 | D36: 2400 | E36: 0 | F36: 0 | G36: 407 | H36: 407
A37: 25 | B37: 25x | C37: 700 | D37: 700 | E37: 0 | F37: 0 | G37: 1010 | H37: 1010
A38: 50 | B38: 50x | C38: 900 | D38: 900 | E38: 0 | F38: 0 | G38: 254 | H38: 254
... A41: 2500 | B41: 2500x | C41: 1 | D41: 1 | E41: 0 | F41: 0 | G41: 0 | H41: 0
A44: [A] | B44: Normal Bet BG 和 Extra Bet 選表的權重如下
B45: Table | C45: Normal Bet | D45: Extra Bet
B46: Symbol-1 | C46: 1 | D46: 1
B47: Symbol-2 | C47: 0 | D47: 0
B48: Symbol-3 | C48: 0 | D48: 0
...

Sheet Multiplier_Weight_Newbie
A2: Threshold | B2: 1000000000
A3: Coin in | B3: 500 | C3: Simulate
B6: Bet | C6: Base Game RTP | D6: Free Game RTP | E6: Total RTP | F6: Hit Rate | G6: FG Period
A7: Normal Bet | B7: {=Overview!B6:B7} -> 1 | C7: =SUM(T18:T75)/B7 -> 0.76506702 | D7: =SUM(T148:T204)/G7 -> 0.16495823 | E7: =SUM(C7:D7) -> 0.93002525 | F7: =1-S18 -> 0.39510727 | G7: =1/S75 -> 500.0145 | H7: =D7*G7 -> 82.481506
A8: Extra Bet | B8: 1.25 | C8: =SUM(T83:T140) -> 0.62299759 | D8: =D7/B8*G7/G8 -> 0.3069928 | E8: =SUM(C8:D8) -> 0.92999038 | F8: =1-S83 -> 0.39681309 | G8: =1/S140 -> 214.94056 | H8: =D8*G8 -> 65.985205
A13: Base Game
A16: Lower | B16: Upper | C16: Simulator Cnt | E16: Simulator Pay | G16: Simulator Rate | I16: Avg. Multi. | L16: Range | M16: 使用的表 | N16: Fix Num | O16: Rate | P16: Fix Rate | Q16: Final Rate | R16: Weight | S16: Hit Rate | T16: Simulator RTP | V16: 目前 | W16: 競品 | X16: 差異
C17: A | D17: B | E17: A | F17: B | G17: A | H17: B | I17: A | J17: B
A18: -1 | B18: 0 | C18: {=工作表1!D2:D59} -> 55325589 | D18: {=工作表1!I2:I59} -> 56174458 | E18: {=工作表1!F2:F59} -> 0 | F18: {=工作表1!K2:K59} -> 0 | G18: {=_xlfn.LET(_xlpm.x, C18:C74, _xlpm.x/SUM(_xlpm.x))} -> 0.55508811 | H18: {=_xlfn.LET(_xlpm.x, D18:D74, _xlpm.x/SUM(_xlpm.x))} -> 0.56355133 | I18: {=_xlfn.LET(_xlpm.x, E18:E74/C18:C74/B3, IFERROR(_xlpm.x, 0))} -> 0 | J18: {=_xlfn.LET(_xlpm.x, F18:F74/D18:D74/B3, IFERROR(_xlpm.x, 0))} -> 0 | L18: ="("&$A18&", "&$B18&"]" -> (-1, 0] | M18: B | N18: 1 | O18: =_xlfn.SINGLE(_xlfn.XLOOKUP(M18, $G$17:$H$17, G18:H18)) -> 0.56355133 | P18: {=O18:O75*N18:N75} -> 0.56355133 | Q18: {=P18:P74/SUM(_xlfn.ANCHORARRAY(P18))} -> 0.60474653 | R18: =B2-SUM(_xlfn.ANCHORARRAY(R19)) -> 604892726 | S18: {=_xlfn.LET(_xlpm.x, R18:R75, _xlpm.x/SUM(_xlpm.x))} -> 0.60489273 | T18: =_xlfn.LET(_xlpm.x, _xlfn.XLOOKUP(M18, $I$17:$J$17, I18:J18), IF(ISERROR(_xlpm.x), 0, _xlpm.x) * S18)/Overview!$B$7 -> 0 | V18: {=_xlfn.LET(_xlpm.x, R18:R75, _xlpm.x/SUM(_xlpm.x))} -> 0.60489273 | W18: 0.56983153 | X18: {=_xlfn.LET(_xlpm.x, ROUND(W18:W75/_xlfn.ANCHORARRAY(V18), 2), IFERROR(_xlpm.x, 0))} -> 0.94
A19: 0 | B19: 1 | C19: 24069989 | D19: 14293217 | E19: 6484275025 | F19: 3231900200 | G19: 0.24149702 | H19: 0.14339189 | I19: 0.53878504 | J19: 0.45222852 | L19: ="("&$A19&", "&$B19&"]" -> (0, 1] | M19: B | N19: 1.4 | O19: =_xlfn.SINGLE(_xlfn.XLOOKUP(M19, $G$17:$H$17, G19:H19)) -> 0.14339189 | P19: 0.20074864 | Q19: 0.21542322 | R19: {=INT(Q19:Q75*$B$2)} -> 215423220 | S19: 0.21542322 | T19: =_xlfn.LET(_xlpm.x, _xlfn.XLOOKUP(M19, $I$17:$J$17, I19:J19),_xlfn.SINGLE( IF(ISERROR(_xlfn.SINGLE(_xlpm.x)), 0, _xlpm.x)) * S19) -> 0.097420524 | V19: 0.21542322 | W19: 0.22894175 | X19: 1.06
A20: 1 | B20: 2 | C20: 10599327 | D20: 7577504 | E20: 7916648100 | F20: 6307987850 | G20: 0.10634429 | H20: 0.076018757 | I20: 1.493802 | J20: 1.664925 | L20: ="("&$A20&", "&$B20&"]" -> (1, 2] | M20: B | N20: 0.73 | O20: =_xlfn.SINGLE(_xlfn.XLOOKUP(M20, $G$17:$H$17, G20:H20)) -> 0.076018757 | P20: 0.055493693 | Q20: 0.059550241 | R20: 59550241 | S20: 0.059550241 | T20: =_xlfn.LET(_xlpm.x, _xlfn.XLOOKUP(M20, $I$17:$J$17, I20:J20),_xlfn.SINGLE( IF(ISERROR(_xlfn.SINGLE(_xlpm.x)), 0, _xlpm.x)) * S20) -> 0.099146684 | V20: 0.059550241 | W20: 0.0854506 | X20: 1.43
A21: 2 | B21: 3 | C21: 4317872 | D21: 8212762 | E21: 5365074350 | F21: 10557718000 | G21: 0.043321715 | H21: 0.082391769 | I21: 2.4850548 | J21: 2.5710517 | L21: ="("&$A21&", "&$B21&"]" -> (2, 3] | M21: B | N21: 0.44 | O21: =_xlfn.SINGLE(_xlfn.XLOOKUP(M21, $G$17:$H$17, G21:H21)) -> 0.082391769 | P21: 0.036252378 | Q21: 0.038902401 | R21: 38902400 | S21: 0.0389024 | T21: =_xlfn.LET(_xlpm.x, _xlfn.XLOOKUP(M21, $I$17:$J$17, I21:J21),_xlfn.SINGLE( IF(ISERROR(_xlfn.SINGLE(_xlpm.x)), 0, _xlpm.x)) * S21) -> 0.10002008 | V21: 0.0389024 | W21: 0.038785624 | X21: 1
A22: 3 | B22: 4 | C22: 2319169 | D22: 3584475 | E22: 4053262600 | F22: 6293472375 | G22: 0.023268494 | H22: 0.035960038 | I22: 3.4954439 | J22: 3.511517 | L22: ="("&$A22&", "&$B22&"]" -> (3, 4] | M22: B | N22: 0.73 | O22: =_xlfn.SINGLE(_xlfn.XLOOKUP(M22, $G$17:$H$17, G22:H22)) -> 0.035960038 | P22: 0.026250828 | Q22: 0.028169744 | R22: 28169744 | S22: 0.028169744 | T22: =_xlfn.LET(_xlpm.x, _xlfn.XLOOKUP(M22, $I$17:$J$17, I22:J22),_xlfn.SINGLE( IF(ISERROR(_xlfn.SINGLE(_xlpm.x)), 0, _xlpm.x)) * S22) -> 0.098918534 | V22: 0.028169744 | W22: 0.031936909 | X22: 1.13
A23: 4 | B23: 5 | C23: 1225076 | D23: 2870564 | E23: 2763500775 | F23: 6548399325 | G23: 0.012291331 | H23: 0.028797967 | I23: 4.5115581 | J23: 4.5624479 | L23: ="("&$A23&", "&$B23&"]" -> (4, 5] | M23: B | N23: 0.52 | O23: =_xlfn.SINGLE(_xlfn.XLOOKUP(M23, $G$17:$H$17, G23:H23)) -> 0.028797967 | P23: 0.014974943 | Q23: 0.0160696 | R23: 16069600 | S23: 0.0160696 | T23: =_xlfn.LET(_xlpm.x, _xlfn.XLOOKUP(M23, $I$17:$J$17, I23:J23),_xlfn.SINGLE( IF(ISERROR(_xlfn.SINGLE(_xlpm.x)), 0, _xlpm.x)) * S23) -> 0.073316713 | V23: 0.0160696 | W23: 0.014822717 | X23: 0.92
A24: 5 | B24: 6 | C24: 635676 | D24: 1428287 | E24: 1744656300 | F24: 3879725800 | G24: 0.0063778118 | H24: 0.014328808 | I24: 5.4891369 | J24: 5.4326978 | L24: ="("&$A24&", "&$B24&"]" -> (5, 6] | M24: B | N24: 0.6 | O24: =_xlfn.SINGLE(_xlfn.XLOOKUP(M24, $G$17:$H$17, G24:H24)) -> 0.014328808 | P24: 0.008597285 | Q24: 0.0092257403 | R24: 9225740 | S24: 0.00922574 | T24: =_xlfn.LET(_xlpm.x, _xlfn.XLOOKUP(M24, $I$17:$J$17, I24:J24),_xlfn.SINGLE( IF(ISERROR(_xlfn.SINGLE(_xlpm.x)), 0, _xlpm.x)) * S24) -> 0.050120657 | V24: 0.00922574 | W24: 0.0085792977 | X24: 0.93
A25: 6 | B25: 7 | C25: 344873 | D25: 667809 | E25: 1117022675 | F25: 2174876225 | G25: 0.0034601512 | H25: 0.0066995689 | I25: 6.4778784 | J25: 6.5134678 | L25: ="("&$A25&", "&$B25&"]" -> (6, 7] | M25: B | N25: 0.78 | O25: =_xlfn.SINGLE(_xlfn.XLOOKUP(M25, $G$17:$H$17, G25:H25)) -> 0.0066995689 | P25: 0.0052256637 | Q25: 0.005607656 | R25: 5607655 | S25: 0.005607655 | T25: =_xlfn.LET(_xlpm.x, _xlfn.XLOOKUP(M25, $I$17:$J$17, I25:J25),_xlfn.SINGLE( IF(ISERROR(_xlfn.SINGLE(_xlpm.x)), 0, _xlpm.x)) * S25) -> 0.036525281 | V25: 0.005607655 | W25: 0.0052116137 | X25: 0.93
A26: 7 | B26: 8 | C26: 180642 | D26: 448887 | E26: 679329150 | F26: 1680408050 | G26: 0.0018124023 | H26: 0.0045033076 | I26: 7.5212758 | J26: 7.4869981 | L26: ="("&$A26&", "&$B26&"]" -> (7, 8] | M26: B | N26: 1.01156 | O26: =_xlfn.SINGLE(_xlfn.XLOOKUP(M26, $G$17:$H$17, G26:H26)) -> 0.0045033076 | P26: 0.0045553659 | Q26: 0.0048883598 | R26: 4888359 | S26: 0.004888359 | T26: =_xlfn.LET(_xlpm.x, _xlfn.XLOOKUP(M26, $I$17:$J$17, I26:J26),_xlfn.SINGLE( IF(ISERROR(_xlfn.SINGLE(_xlpm.x)), 0, _xlpm.x)) * S26) -> 0.036599134 | V26: 0.004888359 | W26: 0.003414425 | X26: 0.7
A27: 8 | B27: 9 | C27: 115360 | D27: 203025 | E27: 490405250 | F27: 858801925 | G27: 0.0011574204 | H27: 0.0020367799 | I27: 8.5021715 | J27: 8.4600608 | L27: ="("&$A27&", "&$B27&"]" -> (8, 9] | M27: B | N27: 1.26445 | O27: =_xlfn.SINGLE(_xlfn.XLOOKUP(M27, $G$17:$H$17, G27:H27)) -> 0.0020367799 | P27: 0.0025754064 | Q27: 0.0027636667 | R27: 2763666 | S27: 0.002763666 | T27: =_xlfn.LET(_xlpm.x, _xlfn.XLOOKUP(M27, $I$17:$J$17, I27:J27),_xlfn.SINGLE( IF(ISERROR(_xlfn.SINGLE(_xlpm.x)), 0, _xlpm.x)) * S27) -> 0.023380782 | V27: 0.002763666 | W27: 0.0021115215 | X27: 0.76
A28: 9 | B28: 10 | C28: 110733 | D28: 809720 | E28: 536395525 | F28: 4017884675 | G28: 0.0011109972 | H28: 0.0081232432 | I28: 9.688088 | J28: 9.9241335 | L28: ="("&$A28&", "&$B28&"]" -> (9, 10] | M28: B | N28: 0.465 | O28: =_xlfn.SINGLE(_xlfn.XLOOKUP(M28, $G$17:$H$17, G28:H28)) -> 0.0081232432 | P28: 0.0037773081 | Q28: 0.0040534266 | R28: 4053426 | S28: 0.004053426 | T28: =_xlfn.LET(_xlpm.x, _xlfn.XLOOKUP(M28, $I$17:$J$17, I28:J28),_xlfn.SINGLE( IF(ISERROR(_xlfn.SINGLE(_xlpm.x)), 0, _xlpm.x)) * S28) -> 0.040226741 | V28: 0.004053426 | W28: 0.0020624435 | X28: 0.51
A29: 10 | B29: 15 | C29: 368403 | D29: 2617397 | E29: 2180791300 | F29: 15386252675 | G29: 0.0036962304 | H29: 0.026258154 | I29: 11.839161 | J29: 11.756912 | L29: ="("&$A29&", "&$B29&"]" -> (10, 15] | M29: B | N29: 0.3 | O29: =_xlfn.SINGLE(_xlfn.XLOOKUP(M29, $G$17:$H$17, G29:H29)) -> 0.026258154 | P29: 0.0078774462 | Q29: 0.0084532818 | R29: 8453281 | S29: 0.008453281 | T29: =_xlfn.LET(_xlpm.x, _xlfn.XLOOKUP(M29, $I$17:$J$17, I29:J29),_xlfn.SINGLE( IF(ISERROR(_xlfn.SINGLE(_xlpm.x)), 0, _xlpm.x)) * S29) -> 0.099384478 | V29: 0.008453281 | W29: 0.0057070676 | X29: 0.68
A30: 15 | B30: 20 | C30: 40589 | D30: 376908 | E30: 337397050 | F30: 3135325925 | G30: 0.00040723419 | H30: 0.0037812026 | I30: 16.625049 | J30: 16.637089 | L30: ="("&$A30&", "&$B30&"]" -> (15, 20] | M30: B | N30: 0 | O30: =_xlfn.SINGLE(_xlfn.XLOOKUP(M30, $G$17:$H$17, G30:H30)) -> 0.0037812026 | P30: 0 | Q30: 0 | R30: 0 | S30: 0 | T30: =_xlfn.LET(_xlpm.x, _xlfn.XLOOKUP(M30, $I$17:$J$17, I30:J30),_xlfn.SINGLE( IF(ISERROR(_xlfn.SINGLE(_xlpm.x)), 0, _xlpm.x)) * S30) -> 0 | V30: 0 | W30: 0.0009897392 | X30: 0
A31: 20 | B31: 25 | C31: 5841 | D31: 138274 | E31: 65928150 | F31: 1616441950 | G31: 5.8603437e-05 | H31: 0.0013871873 | I31: 22.574268 | J31: 23.380273 | L31: ="("&$A31&", "&$B31&"]" -> (20, 25] | M31: B | N31: 0 | O31: =_xlfn.SINGLE(_xlfn.XLOOKUP(M31, $G$17:$H$17, G31:H31)) -> 0.0013871873 | P31: 0 | Q31: 0 | R31: 0 | S31: 0 | T31: =_xlfn.LET(_xlpm.x, _xlfn.XLOOKUP(M31, $I$17:$J$17, I31:J31),_xlfn.SINGLE( IF(ISERROR(_xlfn.SINGLE(_xlpm.x)), 0, _xlpm.x)) * S31) -> 0 | V31: 0 | W31: 0.00030965866 | X31: 0
... A54: 550 | B54: 600 | C54: 0 | D54: 0 | E54: 0 | F54: 0 | G54: 0 | H54: 0 | I54: 0 | J54: 0 | L54: ="("&$A54&", "&$B54&"]" -> (550, 600] | M54: B | N54: 0 | O54: =_xlfn.SINGLE(_xlfn.XLOOKUP(M54, $G$17:$H$17, G54:H54)) -> 0 | P54: 0 | Q54: 0 | R54: 0 | S54: 0 | T54: =_xlfn.LET(_xlpm.x, _xlfn.XLOOKUP(M54, $I$17:$J$17, I54:J54),_xlfn.SINGLE( IF(ISERROR(_xlfn.SINGLE(_xlpm.x)), 0, _xlpm.x)) * S54) -> 0 | V54: 0 | W54: 2.3370465e-06 | X54: 0
A55: 600 | B55: 650 | C55: 0 | D55: 0 | E55: 0 | F55: 0 | G55: 0 | H55: 0 | I55: 0 | J55: 0 | L55: ="("&$A55&", "&$B55&"]" -> (600, 650] | M55: B | N55: 0 | O55: =_xlfn.SINGLE(_xlfn.XLOOKUP(M55, $G$17:$H$17, G55:H55)) -> 0 | P55: 0 | Q55: 0 | R55: 0 | S55: 0 | T55: =_xlfn.LET(_xlpm.x, _xlfn.XLOOKUP(M55, $I$17:$J$17, I55:J55),_xlfn.SINGLE( IF(ISERROR(_xlfn.SINGLE(_xlpm.x)), 0, _xlpm.x)) * S55) -> 0 | V55: 0 | X55: 0
A56: 650 | B56: 700 | C56: 0 | D56: 0 | E56: 0 | F56: 0 | G56: 0 | H56: 0 | I56: 0 | J56: 0 | L56: ="("&$A56&", "&$B56&"]" -> (650, 700] | M56: B | N56: 0 | O56: =_xlfn.SINGLE(_xlfn.XLOOKUP(M56, $G$17:$H$17, G56:H56)) -> 0 | P56: 0 | Q56: 0 | R56: 0 | S56: 0 | T56: =_xlfn.LET(_xlpm.x, _xlfn.XLOOKUP(M56, $I$17:$J$17, I56:J56),_xlfn.SINGLE( IF(ISERROR(_xlfn.SINGLE(_xlpm.x)), 0, _xlpm.x)) * S56) -> 0 | V56: 0 | W56: 1.1685233e-06 | X56: 0
A57: 700 | B57: 750 | C57: 0 | D57: 0 | E57: 0 | F57: 0 | G57: 0 | H57: 0 | I57: 0 | J57: 0 | L57: ="("&$A57&", "&$B57&"]" -> (700, 750] | M57: B | N57: 0 | O57: =_xlfn.SINGLE(_xlfn.XLOOKUP(M57, $G$17:$H$17, G57:H57)) -> 0 | P57: 0 | Q57: 0 | R57: 0 | S57: 0 | T57: =_xlfn.LET(_xlpm.x, _xlfn.XLOOKUP(M57, $I$17:$J$17, I57:J57),_xlfn.SINGLE( IF(ISERROR(_xlfn.SINGLE(_xlpm.x)), 0, _xlpm.x)) * S57) -> 0 | V57: 0 | X57: 0
A58: 750 | B58: 800 | C58: 0 | D58: 0 | E58: 0 | F58: 0 | G58: 0 | H58: 0 | I58: 0 | J58: 0 | L58: ="("&$A58&", "&$B58&"]" -> (750, 800] | M58: B | N58: 0 | O58: =_xlfn.SINGLE(_xlfn.XLOOKUP(M58, $G$17:$H$17, G58:H58)) -> 0 | P58: 0 | Q58: 0 | R58: 0 | S58: 0 | T58: =_xlfn.LET(_xlpm.x, _xlfn.XLOOKUP(M58, $I$17:$J$17, I58:J58),_xlfn.SINGLE( IF(ISERROR(_xlfn.SINGLE(_xlpm.x)), 0, _xlpm.x)) * S58) -> 0 | V58: 0 | W58: 3.5055698e-06 | X58: 0
A59: 800 | B59: 850 | C59: 0 | D59: 0 | E59: 0 | F59: 0 | G59: 0 | H59: 0 | I59: 0 | J59: 0 | L59: ="("&$A59&", "&$B59&"]" -> (800, 850] | M59: B | N59: 0 | O59: =_xlfn.SINGLE(_xlfn.XLOOKUP(M59, $G$17:$H$17, G59:H59)) -> 0 | P59: 0 | Q59: 0 | R59: 0 | S59: 0 | T59: =_xlfn.LET(_xlpm.x, _xlfn.XLOOKUP(M59, $I$17:$J$17, I59:J59),_xlfn.SINGLE( IF(ISERROR(_xlfn.SINGLE(_xlpm.x)), 0, _xlpm.x)) * S59) -> 0 | V59: 0 | X59: 0
A60: 850 | B60: 900 | C60: 0 | D60: 0 | E60: 0 | F60: 0 | G60: 0 | H60: 0 | I60: 0 | J60: 0 | L60: ="("&$A60&", "&$B60&"]" -> (850, 900] | M60: B | N60: 0 | O60: =_xlfn.SINGLE(_xlfn.XLOOKUP(M60, $G$17:$H$17, G60:H60)) -> 0 | P60: 0 | Q60: 0 | R60: 0 | S60: 0 | T60: =_xlfn.LET(_xlpm.x, _xlfn.XLOOKUP(M60, $I$17:$J$17, I60:J60),_xlfn.SINGLE( IF(ISERROR(_xlfn.SINGLE(_xlpm.x)), 0, _xlpm.x)) * S60) -> 0 | V60: 0 | X60: 0
A61: 900 | B61: 950 | C61: 0 | D61: 0 | E61: 0 | F61: 0 | G61: 0 | H61: 0 | I61: 0 | J61: 0 | L61: ="("&$A61&", "&$B61&"]" -> (900, 950] | M61: B | N61: 0 | O61: =_xlfn.SINGLE(_xlfn.XLOOKUP(M61, $G$17:$H$17, G61:H61)) -> 0 | P61: 0 | Q61: 0 | R61: 0 | S61: 0 | T61: =_xlfn.LET(_xlpm.x, _xlfn.XLOOKUP(M61, $I$17:$J$17, I61:J61),_xlfn.SINGLE( IF(ISERROR(_xlfn.SINGLE(_xlpm.x)), 0, _xlpm.x)) * S61) -> 0 | V61: 0 | X61: 0
A62: 950 | B62: 1000 | C62: 0 | D62: 0 | E62: 0 | F62: 0 | G62: 0 | H62: 0 | I62: 0 | J62: 0 | L62: ="("&$A62&", "&$B62&"]" -> (950, 1000] | M62: B | N62: 0 | O62: =_xlfn.SINGLE(_xlfn.XLOOKUP(M62, $G$17:$H$17, G62:H62)) -> 0 | P62: 0 | Q62: 0 | R62: 0 | S62: 0 | T62: =_xlfn.LET(_xlpm.x, _xlfn.XLOOKUP(M62, $I$17:$J$17, I62:J62),_xlfn.SINGLE( IF(ISERROR(_xlfn.SINGLE(_xlpm.x)), 0, _xlpm.x)) * S62) -> 0 | V62: 0 | X62: 0
A63: 1000 | B63: 2000 | C63: 0 | D63: 0 | E63: 0 | F63: 0 | G63: 0 | H63: 0 | I63: 0 | J63: 0 | L63: ="("&$A63&", "&$B63&"]" -> (1000, 2000] | M63: B | N63: 0 | O63: =_xlfn.SINGLE(_xlfn.XLOOKUP(M63, $G$17:$H$17, G63:H63)) -> 0 | P63: 0 | Q63: 0 | R63: 0 | S63: 0 | T63: =_xlfn.LET(_xlpm.x, _xlfn.XLOOKUP(M63, $I$17:$J$17, I63:J63),_xlfn.SINGLE( IF(ISERROR(_xlfn.SINGLE(_xlpm.x)), 0, _xlpm.x)) * S63) -> 0 | V63: 0 | W63: 7.0111395e-06 | X63: 0
A64: 2000 | B64: 3000 | C64: 0 | D64: 0 | E64: 0 | F64: 0 | G64: 0 | H64: 0 | I64: 0 | J64: 0 | L64: ="("&$A64&", "&$B64&"]" -> (2000, 3000] | M64: B | N64: 0 | O64: =_xlfn.SINGLE(_xlfn.XLOOKUP(M64, $G$17:$H$17, G64:H64)) -> 0 | P64: 0 | Q64: 0 | R64: 0 | S64: 0 | T64: =_xlfn.LET(_xlpm.x, _xlfn.XLOOKUP(M64, $I$17:$J$17, I64:J64),_xlfn.SINGLE( IF(ISERROR(_xlfn.SINGLE(_xlpm.x)), 0, _xlpm.x)) * S64) -> 0 | V64: 0 | W64: 1.1685233e-06 | X64: 0
A65: 3000 | B65: 4000 | C65: 0 | D65: 0 | E65: 0 | F65: 0 | G65: 0 | H65: 0 | I65: 0 | J65: 0 | L65: ="("&$A65&", "&$B65&"]" -> (3000, 4000] | M65: B | N65: 0 | O65: =_xlfn.SINGLE(_xlfn.XLOOKUP(M65, $G$17:$H$17, G65:H65)) -> 0 | P65: 0 | Q65: 0 | R65: 0 | S65: 0 | T65: =_xlfn.LET(_xlpm.x, _xlfn.XLOOKUP(M65, $I$17:$J$17, I65:J65),_xlfn.SINGLE( IF(ISERROR(_xlfn.SINGLE(_xlpm.x)), 0, _xlpm.x)) * S65) -> 0 | V65: 0 | W65: 2.3370465e-06 | X65: 0
A66: 4000 | B66: 5000 | C66: 0 | D66: 0 | E66: 0 | F66: 0 | G66: 0 | H66: 0 | I66: 0 | J66: 0 | L66: ="("&$A66&", "&$B66&"]" -> (4000, 5000] | M66: B | N66: 0 | O66: =_xlfn.SINGLE(_xlfn.XLOOKUP(M66, $G$17:$H$17, G66:H66)) -> 0 | P66: 0 | Q66: 0 | R66: 0 | S66: 0 | T66: =_xlfn.LET(_xlpm.x, _xlfn.XLOOKUP(M66, $I$17:$J$17, I66:J66),_xlfn.SINGLE( IF(ISERROR(_xlfn.SINGLE(_xlpm.x)), 0, _xlpm.x)) * S66) -> 0 | V66: 0 | X66: 0
A67: 5000 | B67: 6000 | C67: 0 | D67: 0 | E67: 0 | F67: 0 | G67: 0 | H67: 0 | I67: 0 | J67: 0 | L67: ="("&$A67&", "&$B67&"]" -> (5000, 6000] | M67: B | N67: 0 | O67: =_xlfn.SINGLE(_xlfn.XLOOKUP(M67, $G$17:$H$17, G67:H67)) -> 0 | P67: 0 | Q67: 0 | R67: 0 | S67: 0 | T67: =_xlfn.LET(_xlpm.x, _xlfn.XLOOKUP(M67, $I$17:$J$17, I67:J67),_xlfn.SINGLE( IF(ISERROR(_xlfn.SINGLE(_xlpm.x)), 0, _xlpm.x)) * S67) -> 0 | V67: 0 | X67: 0
A68: 6000 | B68: 7000 | C68: 0 | D68: 0 | E68: 0 | F68: 0 | G68: 0 | H68: 0 | I68: 0 | J68: 0 | L68: ="("&$A68&", "&$B68&"]" -> (6000, 7000] | M68: B | N68: 0 | O68: =_xlfn.SINGLE(_xlfn.XLOOKUP(M68, $G$17:$H$17, G68:H68)) -> 0 | P68: 0 | Q68: 0 | R68: 0 | S68: 0 | T68: =_xlfn.LET(_xlpm.x, _xlfn.XLOOKUP(M68, $I$17:$J$17, I68:J68),_xlfn.SINGLE( IF(ISERROR(_xlfn.SINGLE(_xlpm.x)), 0, _xlpm.x)) * S68) -> 0 | V68: 0 | X68: 0
A69: 7000 | B69: 8000 | C69: 0 | D69: 0 | E69: 0 | F69: 0 | G69: 0 | H69: 0 | I69: 0 | J69: 0 | L69: ="("&$A69&", "&$B69&"]" -> (7000, 8000] | M69: B | N69: 0 | O69: =_xlfn.XLOOKUP(M69, $G$17:$H$17, G69:H69) -> 0 | P69: 0 | Q69: 0 | R69: 0 | S69: 0 | T69: =_xlfn.LET(_xlpm.x, _xlfn.XLOOKUP(M69, $I$17:$J$17, I69:J69),_xlfn.SINGLE( IF(ISERROR(_xlfn.SINGLE(_xlpm.x)), 0, _xlpm.x)) * S69) -> 0 | V69: 0 | X69: 0
A70: 8000 | B70: 9000 | C70: 0 | D70: 0 | E70: 0 | F70: 0 | G70: 0 | H70: 0 | I70: 0 | J70: 0 | L70: ="("&$A70&", "&$B70&"]" -> (8000, 9000] | M70: B | N70: 0 | O70: =_xlfn.XLOOKUP(M70, $G$17:$H$17, G70:H70) -> 0 | P70: 0 | Q70: 0 | R70: 0 | S70: 0 | T70: =_xlfn.LET(_xlpm.x, _xlfn.XLOOKUP(M70, $I$17:$J$17, I70:J70),_xlfn.SINGLE( IF(ISERROR(_xlfn.SINGLE(_xlpm.x)), 0, _xlpm.x)) * S70) -> 0 | V70: 0 | X70: 0
A71: 9000 | B71: 10000 | C71: 0 | D71: 0 | E71: 0 | F71: 0 | G71: 0 | H71: 0 | I71: 0 | J71: 0 | L71: ="("&$A71&", "&$B71&"]" -> (9000, 10000] | M71: B | N71: 0 | O71: =_xlfn.XLOOKUP(M71, $G$17:$H$17, G71:H71) -> 0 | P71: 0 | Q71: 0 | R71: 0 | S71: 0 | T71: =_xlfn.LET(_xlpm.x, _xlfn.XLOOKUP(M71, $I$17:$J$17, I71:J71),_xlfn.SINGLE( IF(ISERROR(_xlfn.SINGLE(_xlpm.x)), 0, _xlpm.x)) * S71) -> 0 | V71: 0 | X71: 0
...

Sheet Multiplier_Weight_Oldhand
A2: Threshold | B2: 1000000000
A3: Coin in | B3: 500 | C3: Simulate
B6: Bet | C6: Base Game RTP | D6: Free Game RTP | E6: Total RTP | F6: Hit Rate | G6: FG Period
A7: Normal Bet | B7: {=Overview!B6:B9} -> 1 | C7: =SUM(T18:T75)/B7 -> 0.7550351 | D7: =SUM(T148:T204)/G7 -> 0.16496733 | E7: =SUM(C7:D7) -> 0.92000243 | F7: =1-S18 -> 0.39333522 | G7: =1/S75 -> 500.0145 | H7: =D7*G7 -> 82.486058
A8: Extra Bet | B8: 1.25 | C8: =SUM(T83:T140) -> 0.61294967 | D8: =D7/B8*G7/G8 -> 0.30700974 | E8: =SUM(C8:D8) -> 0.91995941 | F8: =1-S83 -> 0.39487376 | G8: =1/S140 -> 214.94056 | H8: =D8*G8 -> 65.988846
A9: Buy Feature | B9: 100 | C9: =E77/C77/500/B9 -> 0.033142974 | D9: =SUM(T212:T268) -> 0.8918484 | E9: =SUM(C9:D9) -> 0.92499137 | F9: - | G9: - | H9: =SUM(S236:S268) -> 0.27165743 | I9: =1/S257 -> 369.64377
A10: Super Feature | B10: 500 | C10: =E77/C77/500/B10 -> 0.0066285948 | D10: =SUM(T276:T332) -> 0.91835147 | E10: =SUM(C10:D10) -> 0.92498006 | F10: - | G10: - | H10: =SUM(S311:S332) -> 0.23771734 | I10: =1/S327 -> 2339.0447
A13: Base Game
A16: Lower | B16: Upper | C16: Simulator Cnt | E16: Simulator Pay | G16: Simulator Rate | I16: Avg. Multi. | L16: Range | M16: 使用的表 | N16: Fix Num | O16: Rate | P16: Fix Rate | Q16: Final Rate | R16: Weight | S16: Hit Rate | T16: Simulator RTP | V16: 目前 | W16: 競品 | X16: 差異
C17: A | D17: B | E17: A | F17: B | G17: A | H17: B | I17: A | J17: B
A18: -1 | B18: 0 | C18: {=工作表1!D2:D59} -> 55325589 | D18: {=工作表1!I2:I59} -> 56174458 | E18: {=工作表1!F2:F59} -> 0 | F18: {=工作表1!K2:K59} -> 0 | G18: {=_xlfn.LET(_xlpm.x, C18:C74, _xlpm.x/SUM(_xlpm.x))} -> 0.55508811 | H18: {=_xlfn.LET(_xlpm.x, D18:D74, _xlpm.x/SUM(_xlpm.x))} -> 0.56355133 | I18: {=_xlfn.LET(_xlpm.x, E18:E74/C18:C74/B3, IFERROR(_xlpm.x, 0))} -> 0 | J18: {=_xlfn.LET(_xlpm.x, F18:F74/D18:D74/B3, IFERROR(_xlpm.x, 0))} -> 0 | L18: ="("&$A18&", "&$B18&"]" -> (-1, 0] | M18: B | N18: 1 | O18: =_xlfn.SINGLE(_xlfn.XLOOKUP(M18, $G$17:$H$17, G18:H18)) -> 0.56355133 | P18: {=O18:O75*N18:N75} -> 0.56355133 | Q18: {=P18:P74/SUM(_xlfn.ANCHORARRAY(P18))} -> 0.60651231 | R18: =B2-SUM(_xlfn.ANCHORARRAY(R19)) -> 606664780 | S18: {=_xlfn.LET(_xlpm.x, R18:R75, _xlpm.x/SUM(_xlpm.x))} -> 0.60666478 | T18: =_xlfn.LET(_xlpm.x, _xlfn.XLOOKUP(M18, $I$17:$J$17, I18:J18), IF(ISERROR(_xlpm.x), 0, _xlpm.x) * S18)/Overview!$B$7 -> 0 | V18: {=_xlfn.LET(_xlpm.x, R18:R75, _xlpm.x/SUM(_xlpm.x))} -> 0.60666478 | W18: 0.56983153 | X18: {=_xlfn.LET(_xlpm.x, ROUND(W18:W75/_xlfn.ANCHORARRAY(V18), 2), IFERROR(_xlpm.x, 0))} -> 0.94
A19: 0 | B19: 1 | C19: 24069989 | D19: 14293217 | E19: 6484275025 | F19: 3231900200 | G19: 0.24149702 | H19: 0.14339189 | I19: 0.53878504 | J19: 0.45222852 | L19: ="("&$A19&", "&$B19&"]" -> (0, 1] | M19: B | N19: 1.4 | O19: =_xlfn.SINGLE(_xlfn.XLOOKUP(M19, $G$17:$H$17, G19:H19)) -> 0.14339189 | P19: 0.20074864 | Q19: 0.21605223 | R19: {=INT(Q19:Q75*$B$2)} -> 216052229 | S19: 0.21605223 | T19: =_xlfn.LET(_xlpm.x, _xlfn.XLOOKUP(M19, $I$17:$J$17, I19:J19),_xlfn.SINGLE( IF(ISERROR(_xlfn.SINGLE(_xlpm.x)), 0, _xlpm.x)) * S19) -> 0.09770498 | V19: 0.21605223 | W19: 0.22894175 | X19: 1.06
A20: 1 | B20: 2 | C20: 10599327 | D20: 7577504 | E20: 7916648100 | F20: 6307987850 | G20: 0.10634429 | H20: 0.076018757 | I20: 1.493802 | J20: 1.664925 | L20: ="("&$A20&", "&$B20&"]" -> (1, 2] | M20: B | N20: 0.73 | O20: =_xlfn.SINGLE(_xlfn.XLOOKUP(M20, $G$17:$H$17, G20:H20)) -> 0.076018757 | P20: 0.055493693 | Q20: 0.059724121 | R20: 59724120 | S20: 0.05972412 | T20: =_xlfn.LET(_xlpm.x, _xlfn.XLOOKUP(M20, $I$17:$J$17, I20:J20),_xlfn.SINGLE( IF(ISERROR(_xlfn.SINGLE(_xlpm.x)), 0, _xlpm.x)) * S20) -> 0.099436179 | V20: 0.05972412 | W20: 0.0854506 | X20: 1.43
A21: 2 | B21: 3 | C21: 4317872 | D21: 8212762 | E21: 5365074350 | F21: 10557718000 | G21: 0.043321715 | H21: 0.082391769 | I21: 2.4850548 | J21: 2.5710517 | L21: ="("&$A21&", "&$B21&"]" -> (2, 3] | M21: B | N21: 0.44 | O21: =_xlfn.SINGLE(_xlfn.XLOOKUP(M21, $G$17:$H$17, G21:H21)) -> 0.082391769 | P21: 0.036252378 | Q21: 0.039015991 | R21: 39015991 | S21: 0.039015991 | T21: =_xlfn.LET(_xlpm.x, _xlfn.XLOOKUP(M21, $I$17:$J$17, I21:J21),_xlfn.SINGLE( IF(ISERROR(_xlfn.SINGLE(_xlpm.x)), 0, _xlpm.x)) * S21) -> 0.10031213 | V21: 0.039015991 | W21: 0.038785624 | X21: 0.99
A22: 3 | B22: 4 | C22: 2319169 | D22: 3584475 | E22: 4053262600 | F22: 6293472375 | G22: 0.023268494 | H22: 0.035960038 | I22: 3.4954439 | J22: 3.511517 | L22: ="("&$A22&", "&$B22&"]" -> (3, 4] | M22: B | N22: 0.73 | O22: =_xlfn.SINGLE(_xlfn.XLOOKUP(M22, $G$17:$H$17, G22:H22)) -> 0.035960038 | P22: 0.026250828 | Q22: 0.028251997 | R22: 28251996 | S22: 0.028251996 | T22: =_xlfn.LET(_xlpm.x, _xlfn.XLOOKUP(M22, $I$17:$J$17, I22:J22),_xlfn.SINGLE( IF(ISERROR(_xlfn.SINGLE(_xlpm.x)), 0, _xlpm.x)) * S22) -> 0.099207363 | V22: 0.028251996 | W22: 0.031936909 | X22: 1.13
A23: 4 | B23: 5 | C23: 1225076 | D23: 2870564 | E23: 2763500775 | F23: 6548399325 | G23: 0.012291331 | H23: 0.028797967 | I23: 4.5115581 | J23: 4.5624479 | L23: ="("&$A23&", "&$B23&"]" -> (4, 5] | M23: B | N23: 0.52 | O23: =_xlfn.SINGLE(_xlfn.XLOOKUP(M23, $G$17:$H$17, G23:H23)) -> 0.028797967 | P23: 0.014974943 | Q23: 0.016116521 | R23: 16116521 | S23: 0.016116521 | T23: =_xlfn.LET(_xlpm.x, _xlfn.XLOOKUP(M23, $I$17:$J$17, I23:J23),_xlfn.SINGLE( IF(ISERROR(_xlfn.SINGLE(_xlpm.x)), 0, _xlpm.x)) * S23) -> 0.073530787 | V23: 0.016116521 | W23: 0.014822717 | X23: 0.92
A24: 5 | B24: 6 | C24: 635676 | D24: 1428287 | E24: 1744656300 | F24: 3879725800 | G24: 0.0063778118 | H24: 0.014328808 | I24: 5.4891369 | J24: 5.4326978 | L24: ="("&$A24&", "&$B24&"]" -> (5, 6] | M24: B | N24: 0.6 | O24: =_xlfn.SINGLE(_xlfn.XLOOKUP(M24, $G$17:$H$17, G24:H24)) -> 0.014328808 | P24: 0.008597285 | Q24: 0.0092526783 | R24: 9252678 | S24: 0.009252678 | T24: =_xlfn.LET(_xlpm.x, _xlfn.XLOOKUP(M24, $I$17:$J$17, I24:J24),_xlfn.SINGLE( IF(ISERROR(_xlfn.SINGLE(_xlpm.x)), 0, _xlpm.x)) * S24) -> 0.050267003 | V24: 0.009252678 | W24: 0.0085792977 | X24: 0.93
A25: 6 | B25: 7 | C25: 344873 | D25: 667809 | E25: 1117022675 | F25: 2174876225 | G25: 0.0034601512 | H25: 0.0066995689 | I25: 6.4778784 | J25: 6.5134678 | L25: ="("&$A25&", "&$B25&"]" -> (6, 7] | M25: B | N25: 0.78 | O25: =_xlfn.SINGLE(_xlfn.XLOOKUP(M25, $G$17:$H$17, G25:H25)) -> 0.0066995689 | P25: 0.0052256637 | Q25: 0.0056240296 | R25: 5624029 | S25: 0.005624029 | T25: =_xlfn.LET(_xlpm.x, _xlfn.XLOOKUP(M25, $I$17:$J$17, I25:J25),_xlfn.SINGLE( IF(ISERROR(_xlfn.SINGLE(_xlpm.x)), 0, _xlpm.x)) * S25) -> 0.036631932 | V25: 0.005624029 | W25: 0.0052116137 | X25: 0.93
A26: 7 | B26: 8 | C26: 180642 | D26: 448887 | E26: 679329150 | F26: 1680408050 | G26: 0.0018124023 | H26: 0.0045033076 | I26: 7.5212758 | J26: 7.4869981 | L26: ="("&$A26&", "&$B26&"]" -> (7, 8] | M26: B | N26: 0.76 | O26: =_xlfn.SINGLE(_xlfn.XLOOKUP(M26, $G$17:$H$17, G26:H26)) -> 0.0045033076 | P26: 0.0034225138 | Q26: 0.0036834209 | R26: 3683420 | S26: 0.00368342 | T26: =_xlfn.LET(_xlpm.x, _xlfn.XLOOKUP(M26, $I$17:$J$17, I26:J26),_xlfn.SINGLE( IF(ISERROR(_xlfn.SINGLE(_xlpm.x)), 0, _xlpm.x)) * S26) -> 0.027577758 | V26: 0.00368342 | W26: 0.003414425 | X26: 0.93
A27: 8 | B27: 9 | C27: 115360 | D27: 203025 | E27: 490405250 | F27: 858801925 | G27: 0.0011574204 | H27: 0.0020367799 | I27: 8.5021715 | J27: 8.4600608 | L27: ="("&$A27&", "&$B27&"]" -> (8, 9] | M27: B | N27: 0.95 | O27: =_xlfn.SINGLE(_xlfn.XLOOKUP(M27, $G$17:$H$17, G27:H27)) -> 0.0020367799 | P27: 0.0019349409 | Q27: 0.0020824465 | R27: 2082446 | S27: 0.002082446 | T27: =_xlfn.LET(_xlpm.x, _xlfn.XLOOKUP(M27, $I$17:$J$17, I27:J27),_xlfn.SINGLE( IF(ISERROR(_xlfn.SINGLE(_xlpm.x)), 0, _xlpm.x)) * S27) -> 0.01761762 | V27: 0.002082446 | W27: 0.0021115215 | X27: 1.01
A28: 9 | B28: 10 | C28: 110733 | D28: 809720 | E28: 536395525 | F28: 4017884675 | G28: 0.0011109972 | H28: 0.0081232432 | I28: 9.688088 | J28: 9.9241335 | L28: ="("&$A28&", "&$B28&"]" -> (9, 10] | M28: B | N28: 0.219 | O28: =_xlfn.SINGLE(_xlfn.XLOOKUP(M28, $G$17:$H$17, G28:H28)) -> 0.0081232432 | P28: 0.0017789903 | Q28: 0.0019146073 | R28: 1914607 | S28: 0.001914607 | T28: =_xlfn.LET(_xlpm.x, _xlfn.XLOOKUP(M28, $I$17:$J$17, I28:J28),_xlfn.SINGLE( IF(ISERROR(_xlfn.SINGLE(_xlpm.x)), 0, _xlpm.x)) * S28) -> 0.019000815 | V28: 0.001914607 | W28: 0.0020624435 | X28: 1.08
A29: 10 | B29: 15 | C29: 368403 | D29: 2617397 | E29: 2180791300 | F29: 15386252675 | G29: 0.0036962304 | H29: 0.026258154 | I29: 11.839161 | J29: 11.756912 | L29: ="("&$A29&", "&$B29&"]" -> (10, 15] | M29: B | N29: 0.3 | O29: =_xlfn.SINGLE(_xlfn.XLOOKUP(M29, $G$17:$H$17, G29:H29)) -> 0.026258154 | P29: 0.0078774462 | Q29: 0.0084779643 | R29: 8477964 | S29: 0.008477964 | T29: =_xlfn.LET(_xlpm.x, _xlfn.XLOOKUP(M29, $I$17:$J$17, I29:J29),_xlfn.SINGLE( IF(ISERROR(_xlfn.SINGLE(_xlpm.x)), 0, _xlpm.x)) * S29) -> 0.099674674 | V29: 0.008477964 | W29: 0.0057070676 | X29: 0.67
A30: 15 | B30: 20 | C30: 40589 | D30: 376908 | E30: 337397050 | F30: 3135325925 | G30: 0.00040723419 | H30: 0.0037812026 | I30: 16.625049 | J30: 16.637089 | L30: ="("&$A30&", "&$B30&"]" -> (15, 20] | M30: B | N30: 0.13 | O30: =_xlfn.SINGLE(_xlfn.XLOOKUP(M30, $G$17:$H$17, G30:H30)) -> 0.0037812026 | P30: 0.00049155633 | Q30: 0.00052902895 | R30: 529028 | S30: 0.000529028 | T30: =_xlfn.LET(_xlpm.x, _xlfn.XLOOKUP(M30, $I$17:$J$17, I30:J30),_xlfn.SINGLE( IF(ISERROR(_xlfn.SINGLE(_xlpm.x)), 0, _xlpm.x)) * S30) -> 0.0088014858 | V30: 0.000529028 | W30: 0.0009897392 | X30: 1.87
A31: 20 | B31: 25 | C31: 5841 | D31: 138274 | E31: 65928150 | F31: 1616441950 | G31: 5.8603437e-05 | H31: 0.0013871873 | I31: 22.574268 | J31: 23.380273 | L31: ="("&$A31&", "&$B31&"]" -> (20, 25] | M31: B | N31: 0.21 | O31: =_xlfn.SINGLE(_xlfn.XLOOKUP(M31, $G$17:$H$17, G31:H31)) -> 0.0013871873 | P31: 0.00029130934 | Q31: 0.00031351661 | R31: 313516 | S31: 0.000313516 | T31: =_xlfn.LET(_xlpm.x, _xlfn.XLOOKUP(M31, $I$17:$J$17, I31:J31),_xlfn.SINGLE( IF(ISERROR(_xlfn.SINGLE(_xlpm.x)), 0, _xlpm.x)) * S31) -> 0.0073300897 | V31: 0.000313516 | W31: 0.00030965866 | X31: 0.99
... A54: 550 | B54: 600 | C54: 0 | D54: 0 | E54: 0 | F54: 0 | G54: 0 | H54: 0 | I54: 0 | J54: 0 | L54: ="("&$A54&", "&$B54&"]" -> (550, 600] | M54: B | N54: 0 | O54: =_xlfn.SINGLE(_xlfn.XLOOKUP(M54, $G$17:$H$17, G54:H54)) -> 0 | P54: 0 | Q54: 0 | R54: 0 | S54: 0 | T54: =_xlfn.LET(_xlpm.x, _xlfn.XLOOKUP(M54, $I$17:$J$17, I54:J54),_xlfn.SINGLE( IF(ISERROR(_xlfn.SINGLE(_xlpm.x)), 0, _xlpm.x)) * S54) -> 0 | V54: 0 | W54: 2.3370465e-06 | X54: 0
A55: 600 | B55: 650 | C55: 0 | D55: 0 | E55: 0 | F55: 0 | G55: 0 | H55: 0 | I55: 0 | J55: 0 | L55: ="("&$A55&", "&$B55&"]" -> (600, 650] | M55: B | N55: 0 | O55: =_xlfn.SINGLE(_xlfn.XLOOKUP(M55, $G$17:$H$17, G55:H55)) -> 0 | P55: 0 | Q55: 0 | R55: 0 | S55: 0 | T55: =_xlfn.LET(_xlpm.x, _xlfn.XLOOKUP(M55, $I$17:$J$17, I55:J55),_xlfn.SINGLE( IF(ISERROR(_xlfn.SINGLE(_xlpm.x)), 0, _xlpm.x)) * S55) -> 0 | V55: 0 | X55: 0
A56: 650 | B56: 700 | C56: 0 | D56: 0 | E56: 0 | F56: 0 | G56: 0 | H56: 0 | I56: 0 | J56: 0 | L56: ="("&$A56&", "&$B56&"]" -> (650, 700] | M56: B | N56: 0 | O56: =_xlfn.SINGLE(_xlfn.XLOOKUP(M56, $G$17:$H$17, G56:H56)) -> 0 | P56: 0 | Q56: 0 | R56: 0 | S56: 0 | T56: =_xlfn.LET(_xlpm.x, _xlfn.XLOOKUP(M56, $I$17:$J$17, I56:J56),_xlfn.SINGLE( IF(ISERROR(_xlfn.SINGLE(_xlpm.x)), 0, _xlpm.x)) * S56) -> 0 | V56: 0 | W56: 1.1685233e-06 | X56: 0
A57: 700 | B57: 750 | C57: 0 | D57: 0 | E57: 0 | F57: 0 | G57: 0 | H57: 0 | I57: 0 | J57: 0 | L57: ="("&$A57&", "&$B57&"]" -> (700, 750] | M57: B | N57: 0 | O57: =_xlfn.SINGLE(_xlfn.XLOOKUP(M57, $G$17:$H$17, G57:H57)) -> 0 | P57: 0 | Q57: 0 | R57: 0 | S57: 0 | T57: =_xlfn.LET(_xlpm.x, _xlfn.XLOOKUP(M57, $I$17:$J$17, I57:J57),_xlfn.SINGLE( IF(ISERROR(_xlfn.SINGLE(_xlpm.x)), 0, _xlpm.x)) * S57) -> 0 | V57: 0 | X57: 0
A58: 750 | B58: 800 | C58: 0 | D58: 0 | E58: 0 | F58: 0 | G58: 0 | H58: 0 | I58: 0 | J58: 0 | L58: ="("&$A58&", "&$B58&"]" -> (750, 800] | M58: B | N58: 0 | O58: =_xlfn.SINGLE(_xlfn.XLOOKUP(M58, $G$17:$H$17, G58:H58)) -> 0 | P58: 0 | Q58: 0 | R58: 0 | S58: 0 | T58: =_xlfn.LET(_xlpm.x, _xlfn.XLOOKUP(M58, $I$17:$J$17, I58:J58),_xlfn.SINGLE( IF(ISERROR(_xlfn.SINGLE(_xlpm.x)), 0, _xlpm.x)) * S58) -> 0 | V58: 0 | W58: 3.5055698e-06 | X58: 0
A59: 800 | B59: 850 | C59: 0 | D59: 0 | E59: 0 | F59: 0 | G59: 0 | H59: 0 | I59: 0 | J59: 0 | L59: ="("&$A59&", "&$B59&"]" -> (800, 850] | M59: B | N59: 0 | O59: =_xlfn.SINGLE(_xlfn.XLOOKUP(M59, $G$17:$H$17, G59:H59)) -> 0 | P59: 0 | Q59: 0 | R59: 0 | S59: 0 | T59: =_xlfn.LET(_xlpm.x, _xlfn.XLOOKUP(M59, $I$17:$J$17, I59:J59),_xlfn.SINGLE( IF(ISERROR(_xlfn.SINGLE(_xlpm.x)), 0, _xlpm.x)) * S59) -> 0 | V59: 0 | X59: 0
A60: 850 | B60: 900 | C60: 0 | D60: 0 | E60: 0 | F60: 0 | G60: 0 | H60: 0 | I60: 0 | J60: 0 | L60: ="("&$A60&", "&$B60&"]" -> (850, 900] | M60: B | N60: 0 | O60: =_xlfn.SINGLE(_xlfn.XLOOKUP(M60, $G$17:$H$17, G60:H60)) -> 0 | P60: 0 | Q60: 0 | R60: 0 | S60: 0 | T60: =_xlfn.LET(_xlpm.x, _xlfn.XLOOKUP(M60, $I$17:$J$17, I60:J60),_xlfn.SINGLE( IF(ISERROR(_xlfn.SINGLE(_xlpm.x)), 0, _xlpm.x)) * S60) -> 0 | V60: 0 | X60: 0
A61: 900 | B61: 950 | C61: 0 | D61: 0 | E61: 0 | F61: 0 | G61: 0 | H61: 0 | I61: 0 | J61: 0 | L61: ="("&$A61&", "&$B61&"]" -> (900, 950] | M61: B | N61: 0 | O61: =_xlfn.SINGLE(_xlfn.XLOOKUP(M61, $G$17:$H$17, G61:H61)) -> 0 | P61: 0 | Q61: 0 | R61: 0 | S61: 0 | T61: =_xlfn.LET(_xlpm.x, _xlfn.XLOOKUP(M61, $I$17:$J$17, I61:J61),_xlfn.SINGLE( IF(ISERROR(_xlfn.SINGLE(_xlpm.x)), 0, _xlpm.x)) * S61) -> 0 | V61: 0 | X61: 0
A62: 950 | B62: 1000 | C62: 0 | D62: 0 | E62: 0 | F62: 0 | G62: 0 | H62: 0 | I62: 0 | J62: 0 | L62: ="("&$A62&", "&$B62&"]" -> (950, 1000] | M62: B | N62: 0 | O62: =_xlfn.SINGLE(_xlfn.XLOOKUP(M62, $G$17:$H$17, G62:H62)) -> 0 | P62: 0 | Q62: 0 | R62: 0 | S62: 0 | T62: =_xlfn.LET(_xlpm.x, _xlfn.XLOOKUP(M62, $I$17:$J$17, I62:J62),_xlfn.SINGLE( IF(ISERROR(_xlfn.SINGLE(_xlpm.x)), 0, _xlpm.x)) * S62) -> 0 | V62: 0 | X62: 0
A63: 1000 | B63: 2000 | C63: 0 | D63: 0 | E63: 0 | F63: 0 | G63: 0 | H63: 0 | I63: 0 | J63: 0 | L63: ="("&$A63&", "&$B63&"]" -> (1000, 2000] | M63: B | N63: 0 | O63: =_xlfn.SINGLE(_xlfn.XLOOKUP(M63, $G$17:$H$17, G63:H63)) -> 0 | P63: 0 | Q63: 0 | R63: 0 | S63: 0 | T63: =_xlfn.LET(_xlpm.x, _xlfn.XLOOKUP(M63, $I$17:$J$17, I63:J63),_xlfn.SINGLE( IF(ISERROR(_xlfn.SINGLE(_xlpm.x)), 0, _xlpm.x)) * S63) -> 0 | V63: 0 | W63: 7.0111395e-06 | X63: 0
A64: 2000 | B64: 3000 | C64: 0 | D64: 0 | E64: 0 | F64: 0 | G64: 0 | H64: 0 | I64: 0 | J64: 0 | L64: ="("&$A64&", "&$B64&"]" -> (2000, 3000] | M64: B | N64: 0 | O64: =_xlfn.SINGLE(_xlfn.XLOOKUP(M64, $G$17:$H$17, G64:H64)) -> 0 | P64: 0 | Q64: 0 | R64: 0 | S64: 0 | T64: =_xlfn.LET(_xlpm.x, _xlfn.XLOOKUP(M64, $I$17:$J$17, I64:J64),_xlfn.SINGLE( IF(ISERROR(_xlfn.SINGLE(_xlpm.x)), 0, _xlpm.x)) * S64) -> 0 | V64: 0 | W64: 1.1685233e-06 | X64: 0
A65: 3000 | B65: 4000 | C65: 0 | D65: 0 | E65: 0 | F65: 0 | G65: 0 | H65: 0 | I65: 0 | J65: 0 | L65: ="("&$A65&", "&$B65&"]" -> (3000, 4000] | M65: B | N65: 0 | O65: =_xlfn.SINGLE(_xlfn.XLOOKUP(M65, $G$17:$H$17, G65:H65)) -> 0 | P65: 0 | Q65: 0 | R65: 0 | S65: 0 | T65: =_xlfn.LET(_xlpm.x, _xlfn.XLOOKUP(M65, $I$17:$J$17, I65:J65),_xlfn.SINGLE( IF(ISERROR(_xlfn.SINGLE(_xlpm.x)), 0, _xlpm.x)) * S65) -> 0 | V65: 0 | W65: 2.3370465e-06 | X65: 0
A66: 4000 | B66: 5000 | C66: 0 | D66: 0 | E66: 0 | F66: 0 | G66: 0 | H66: 0 | I66: 0 | J66: 0 | L66: ="("&$A66&", "&$B66&"]" -> (4000, 5000] | M66: B | N66: 0 | O66: =_xlfn.SINGLE(_xlfn.XLOOKUP(M66, $G$17:$H$17, G66:H66)) -> 0 | P66: 0 | Q66: 0 | R66: 0 | S66: 0 | T66: =_xlfn.LET(_xlpm.x, _xlfn.XLOOKUP(M66, $I$17:$J$17, I66:J66),_xlfn.SINGLE( IF(ISERROR(_xlfn.SINGLE(_xlpm.x)), 0, _xlpm.x)) * S66) -> 0 | V66: 0 | X66: 0
A67: 5000 | B67: 6000 | C67: 0 | D67: 0 | E67: 0 | F67: 0 | G67: 0 | H67: 0 | I67: 0 | J67: 0 | L67: ="("&$A67&", "&$B67&"]" -> (5000, 6000] | M67: B | N67: 0 | O67: =_xlfn.SINGLE(_xlfn.XLOOKUP(M67, $G$17:$H$17, G67:H67)) -> 0 | P67: 0 | Q67: 0 | R67: 0 | S67: 0 | T67: =_xlfn.LET(_xlpm.x, _xlfn.XLOOKUP(M67, $I$17:$J$17, I67:J67),_xlfn.SINGLE( IF(ISERROR(_xlfn.SINGLE(_xlpm.x)), 0, _xlpm.x)) * S67) -> 0 | V67: 0 | X67: 0
A68: 6000 | B68: 7000 | C68: 0 | D68: 0 | E68: 0 | F68: 0 | G68: 0 | H68: 0 | I68: 0 | J68: 0 | L68: ="("&$A68&", "&$B68&"]" -> (6000, 7000] | M68: B | N68: 0 | O68: =_xlfn.SINGLE(_xlfn.XLOOKUP(M68, $G$17:$H$17, G68:H68)) -> 0 | P68: 0 | Q68: 0 | R68: 0 | S68: 0 | T68: =_xlfn.LET(_xlpm.x, _xlfn.XLOOKUP(M68, $I$17:$J$17, I68:J68),_xlfn.SINGLE( IF(ISERROR(_xlfn.SINGLE(_xlpm.x)), 0, _xlpm.x)) * S68) -> 0 | V68: 0 | X68: 0
A69: 7000 | B69: 8000 | C69: 0 | D69: 0 | E69: 0 | F69: 0 | G69: 0 | H69: 0 | I69: 0 | J69: 0 | L69: ="("&$A69&", "&$B69&"]" -> (7000, 8000] | M69: B | N69: 0 | O69: =_xlfn.XLOOKUP(M69, $G$17:$H$17, G69:H69) -> 0 | P69: 0 | Q69: 0 | R69: 0 | S69: 0 | T69: =_xlfn.LET(_xlpm.x, _xlfn.XLOOKUP(M69, $I$17:$J$17, I69:J69),_xlfn.SINGLE( IF(ISERROR(_xlfn.SINGLE(_xlpm.x)), 0, _xlpm.x)) * S69) -> 0 | V69: 0 | X69: 0
...

Sheet OP Jackpot
B2: 新手
B3: Scatter Combo Rate
C4: Normal Bet | D4: Extra Bet
B5: Scatter Combo Rate | C5: 5517581100 | D5: 5664933900
B7: Threshold | C7: 10000000000
B10: 老手
C11: Normal Bet | D11: Extra Bet | E11: Buy Feature | F11: Super Feature
B12: Scatter Combo Rate | C12: 5511849100 | D12: 5653716200 | E12: 5.8987363e+10 | F12: 5.5972176e+10
B14: Threshold | C14: 10000000000

Sheet 工作表1
A1: 500 | C1: A | H1: B
A2: BG | B2: -1 | C2: BaseGame 00 | D2: 55325589 | H2: BaseGame 00 | I2: 56174458 | M2: -1
B3: 0 | C3: BaseGame 0x | D3: 24069989 | E3: Pay | F3: 6484275025 | H3: BaseGame 0x | I3: 14293217 | J3: Pay | K3: 3231900200 | M3: 0
B4: 1 | C4: BaseGame 1x | D4: 10599327 | E4: Pay | F4: 7916648100 | H4: BaseGame 1x | I4: 7577504 | J4: Pay | K4: 6307987850 | M4: 1
B5: 2 | C5: BaseGame 2x | D5: 4317872 | E5: Pay | F5: 5365074350 | H5: BaseGame 2x | I5: 8212762 | J5: Pay | K5: 10557718000 | M5: 2
B6: 3 | C6: BaseGame 3x | D6: 2319169 | E6: Pay | F6: 4053262600 | H6: BaseGame 3x | I6: 3584475 | J6: Pay | K6: 6293472375 | M6: 3
B7: 4 | C7: BaseGame 4x | D7: 1225076 | E7: Pay | F7: 2763500775 | H7: BaseGame 4x | I7: 2870564 | J7: Pay | K7: 6548399325 | M7: 4
B8: 5 | C8: BaseGame 5x | D8: 635676 | E8: Pay | F8: 1744656300 | H8: BaseGame 5x | I8: 1428287 | J8: Pay | K8: 3879725800 | M8: 5
B9: 6 | C9: BaseGame 6x | D9: 344873 | E9: Pay | F9: 1117022675 | H9: BaseGame 6x | I9: 667809 | J9: Pay | K9: 2174876225 | M9: 6
B10: 7 | C10: BaseGame 7x | D10: 180642 | E10: Pay | F10: 679329150 | H10: BaseGame 7x | I10: 448887 | J10: Pay | K10: 1680408050 | M10: 7
B11: 8 | C11: BaseGame 8x | D11: 115360 | E11: Pay | F11: 490405250 | H11: BaseGame 8x | I11: 203025 | J11: Pay | K11: 858801925 | M11: 8
B12: 9 | C12: BaseGame 9x | D12: 110733 | E12: Pay | F12: 536395525 | H12: BaseGame 9x | I12: 809720 | J12: Pay | K12: 4017884675 | M12: 9
B13: 10 | C13: BaseGame 10x | D13: 368403 | E13: Pay | F13: 2180791300 | H13: BaseGame 10x | I13: 2617397 | J13: Pay | K13: 15386252675 | M13: 10
B14: 15 | C14: BaseGame 15x | D14: 40589 | E14: Pay | F14: 337397050 | H14: BaseGame 15x | I14: 376908 | J14: Pay | K14: 3135325925 | M14: 15
... B22: 60 | C22: BaseGame 60x | D22: 3 | E22: Pay | F22: 96500 | H22: BaseGame 60x | I22: 133 | J22: Pay | K22: 4246600 | M22: 60
B23: 70 | H23: BaseGame 70x | I23: 15 | J23: Pay | K23: 556850 | M23: 70
B24: 80 | H24: BaseGame 80x | I24: 2 | J24: Pay | K24: 81725 | M24: 80
B25: 90 | M25: 90
B26: 100 | H26: BaseGame 100x | I26: 1 | J26: Pay | K26: 53350 | M26: 100
B27: 120 | M27: 120
B28: 140 | M28: 140
B29: 160 | M29: 160
B30: 180 | M30: 180
B31: 200 | M31: 200
B32: 250 | M32: 250
B33: 300 | M33: 300
B34: 350 | M34: 350
B35: 400 | M35: 400
B36: 450 | M36: 450
B37: 500 | M37: 500
B38: 550 | M38: 550
... B52: 6000 | M52: 6000
B53: 7000
B54: 8000
B55: 9000
B56: 10000
B57: 20000
B58: 30000 | M58: 7000
D59: 330078 | F59: 825830650
A61: 625
...

Sheet Base Game Symbol (1)
C2: =SUM(C4:C15) -> 200 | D2: =SUM(D4:D15) -> 200 | E2: =SUM(E4:E15) -> 200 | F2: =SUM(F4:F15) -> 200 | G2: =SUM(G4:G15) -> 200 | H2: =SUM(H4:H15) -> 200 | K2: Symbol | S2: ID | Z2: Description | AG2: Reel Weight
A3: Symbol | B3: Description | C3: R1 | D3: R2 | E3: R3 | F3: R4 | G3: R5 | H3: R6 | I3: ID | K3: Line # | L3: R1 | M3: R2 | N3: R3 | O3: R4 | P3: R5 | Q3: R6 | S3: R1 | T3: R2 | U3: R3 | V3: R4 | W3: R5 | X3: R6 | Z3: R1 | AA3: R2 | AB3: R3 | AC3: R4 | AD3: R5 | AE3: R6 | AG3: R1 | AH3: R2 | AI3: R3 | AJ3: R4 | AK3: R5 | AL3: R6
A4: {=Overview!A58:A69} -> WW | B4: {=Overview!B58:B69} -> Wild | C4: =COUNTIF(L:L,$A4) -> 0 | D4: =COUNTIF(M:M,$A4) -> 0 | E4: =COUNTIF(N:N,$A4) -> 0 | F4: =COUNTIF(O:O,$A4) -> 0 | G4: =COUNTIF(P:P,$A4) -> 0 | H4: =COUNTIF(Q:Q,$A4) -> 0 | I4: {=Overview!I58:I69} -> 0 | K4: {=_xlfn.SEQUENCE(300)-1} -> 0 | L4: TE | M4: TE | N4: M4 | O4: M3 | P4: Q | Q4: J | S4: =VLOOKUP(L4,$A$4:$I$15,9,FALSE) -> 11 | T4: =VLOOKUP(M4,$A$4:$I$15,9,FALSE) -> 11 | U4: =VLOOKUP(N4,$A$4:$I$15,9,FALSE) -> 6 | V4: =VLOOKUP(O4,$A$4:$I$15,9,FALSE) -> 5 | W4: =VLOOKUP(P4,$A$4:$I$15,9,FALSE) -> 9 | X4: =VLOOKUP(Q4,$A$4:$I$15,9,FALSE) -> 10 | Z4: =VLOOKUP(L4,$A$4:$I$15,2,FALSE) -> Bananas | AA4: =VLOOKUP(M4,$A$4:$I$15,2,FALSE) -> Bananas | AB4: =VLOOKUP(N4,$A$4:$I$15,2,FALSE) -> Rectangle | AC4: =VLOOKUP(O4,$A$4:$I$15,2,FALSE) -> pentagon | AD4: =VLOOKUP(P4,$A$4:$I$15,2,FALSE) -> Watermelon | AE4: =VLOOKUP(Q4,$A$4:$I$15,2,FALSE) -> Grapes | AG4: 1 | AH4: 1 | AI4: 1 | AJ4: 1 | AK4: 1 | AL4: 1
A5: C1 | B5: Scatter | C5: =COUNTIF(L:L,$A5) -> 4 | D5: =COUNTIF(M:M,$A5) -> 6 | E5: =COUNTIF(N:N,$A5) -> 2 | F5: =COUNTIF(O:O,$A5) -> 4 | G5: =COUNTIF(P:P,$A5) -> 4 | H5: =COUNTIF(Q:Q,$A5) -> 4 | I5: 1 | K5: 1 | L5: TE | M5: TE | N5: M4 | O5: M3 | P5: Q | Q5: J | S5: =VLOOKUP(L5,$A$4:$I$15,9,FALSE) -> 11 | T5: =VLOOKUP(M5,$A$4:$I$15,9,FALSE) -> 11 | U5: =VLOOKUP(N5,$A$4:$I$15,9,FALSE) -> 6 | V5: =VLOOKUP(O5,$A$4:$I$15,9,FALSE) -> 5 | W5: =VLOOKUP(P5,$A$4:$I$15,9,FALSE) -> 9 | X5: =VLOOKUP(Q5,$A$4:$I$15,9,FALSE) -> 10 | Z5: =VLOOKUP(L5,$A$4:$I$15,2,FALSE) -> Bananas | AA5: =VLOOKUP(M5,$A$4:$I$15,2,FALSE) -> Bananas | AB5: =VLOOKUP(N5,$A$4:$I$15,2,FALSE) -> Rectangle | AC5: =VLOOKUP(O5,$A$4:$I$15,2,FALSE) -> pentagon | AD5: =VLOOKUP(P5,$A$4:$I$15,2,FALSE) -> Watermelon | AE5: =VLOOKUP(Q5,$A$4:$I$15,2,FALSE) -> Grapes | AG5: 1 | AH5: 1 | AI5: 1 | AJ5: 1 | AK5: 1 | AL5: 1
A6: C2 | B6: Multiplier | C6: =COUNTIF(L:L,$A6) -> 0 | D6: =COUNTIF(M:M,$A6) -> 0 | E6: =COUNTIF(N:N,$A6) -> 0 | F6: =COUNTIF(O:O,$A6) -> 0 | G6: =COUNTIF(P:P,$A6) -> 0 | H6: =COUNTIF(Q:Q,$A6) -> 0 | I6: 2 | K6: 2 | L6: K | M6: J | N6: M1 | O6: K | P6: M3 | Q6: C1 | S6: =VLOOKUP(L6,$A$4:$I$15,9,FALSE) -> 8 | T6: =VLOOKUP(M6,$A$4:$I$15,9,FALSE) -> 10 | U6: =VLOOKUP(N6,$A$4:$I$15,9,FALSE) -> 3 | V6: =VLOOKUP(O6,$A$4:$I$15,9,FALSE) -> 8 | W6: =VLOOKUP(P6,$A$4:$I$15,9,FALSE) -> 5 | X6: =VLOOKUP(Q6,$A$4:$I$15,9,FALSE) -> 1 | Z6: =VLOOKUP(L6,$A$4:$I$15,2,FALSE) -> Peaches | AA6: =VLOOKUP(M6,$A$4:$I$15,2,FALSE) -> Grapes | AB6: =VLOOKUP(N6,$A$4:$I$15,2,FALSE) -> Heart | AC6: =VLOOKUP(O6,$A$4:$I$15,2,FALSE) -> Peaches | AD6: =VLOOKUP(P6,$A$4:$I$15,2,FALSE) -> pentagon | AE6: =VLOOKUP(Q6,$A$4:$I$15,2,FALSE) -> Scatter | AG6: 1 | AH6: 1 | AI6: 1 | AJ6: 1 | AK6: 1 | AL6: 1
A7: M1 | B7: Heart | C7: =COUNTIF(L:L,$A7) -> 6 | D7: =COUNTIF(M:M,$A7) -> 6 | E7: =COUNTIF(N:N,$A7) -> 16 | F7: =COUNTIF(O:O,$A7) -> 12 | G7: =COUNTIF(P:P,$A7) -> 6 | H7: =COUNTIF(Q:Q,$A7) -> 6 | I7: 3 | K7: 3 | L7: K | M7: J | N7: M1 | O7: K | P7: M3 | Q7: Q | S7: =VLOOKUP(L7,$A$4:$I$15,9,FALSE) -> 8 | T7: =VLOOKUP(M7,$A$4:$I$15,9,FALSE) -> 10 | U7: =VLOOKUP(N7,$A$4:$I$15,9,FALSE) -> 3 | V7: =VLOOKUP(O7,$A$4:$I$15,9,FALSE) -> 8 | W7: =VLOOKUP(P7,$A$4:$I$15,9,FALSE) -> 5 | X7: =VLOOKUP(Q7,$A$4:$I$15,9,FALSE) -> 9 | Z7: =VLOOKUP(L7,$A$4:$I$15,2,FALSE) -> Peaches | AA7: =VLOOKUP(M7,$A$4:$I$15,2,FALSE) -> Grapes | AB7: =VLOOKUP(N7,$A$4:$I$15,2,FALSE) -> Heart | AC7: =VLOOKUP(O7,$A$4:$I$15,2,FALSE) -> Peaches | AD7: =VLOOKUP(P7,$A$4:$I$15,2,FALSE) -> pentagon | AE7: =VLOOKUP(Q7,$A$4:$I$15,2,FALSE) -> Watermelon | AG7: 1 | AH7: 1 | AI7: 1 | AJ7: 1 | AK7: 1 | AL7: 1
A8: M2 | B8: Square | C8: =COUNTIF(L:L,$A8) -> 12 | D8: =COUNTIF(M:M,$A8) -> 12 | E8: =COUNTIF(N:N,$A8) -> 18 | F8: =COUNTIF(O:O,$A8) -> 12 | G8: =COUNTIF(P:P,$A8) -> 12 | H8: =COUNTIF(Q:Q,$A8) -> 24 | I8: 4 | K8: 4 | L8: A | M8: M4 | N8: TE | O8: M2 | P8: M4 | Q8: Q | S8: =VLOOKUP(L8,$A$4:$I$15,9,FALSE) -> 7 | T8: =VLOOKUP(M8,$A$4:$I$15,9,FALSE) -> 6 | U8: =VLOOKUP(N8,$A$4:$I$15,9,FALSE) -> 11 | V8: =VLOOKUP(O8,$A$4:$I$15,9,FALSE) -> 4 | W8: =VLOOKUP(P8,$A$4:$I$15,9,FALSE) -> 6 | X8: =VLOOKUP(Q8,$A$4:$I$15,9,FALSE) -> 9 | Z8: =VLOOKUP(L8,$A$4:$I$15,2,FALSE) -> Apples | AA8: =VLOOKUP(M8,$A$4:$I$15,2,FALSE) -> Rectangle | AB8: =VLOOKUP(N8,$A$4:$I$15,2,FALSE) -> Bananas | AC8: =VLOOKUP(O8,$A$4:$I$15,2,FALSE) -> Square | AD8: =VLOOKUP(P8,$A$4:$I$15,2,FALSE) -> Rectangle | AE8: =VLOOKUP(Q8,$A$4:$I$15,2,FALSE) -> Watermelon | AG8: 1 | AH8: 1 | AI8: 1 | AJ8: 1 | AK8: 1 | AL8: 1
A9: M3 | B9: pentagon | C9: =COUNTIF(L:L,$A9) -> 12 | D9: =COUNTIF(M:M,$A9) -> 12 | E9: =COUNTIF(N:N,$A9) -> 12 | F9: =COUNTIF(O:O,$A9) -> 20 | G9: =COUNTIF(P:P,$A9) -> 18 | H9: =COUNTIF(Q:Q,$A9) -> 12 | I9: 5 | K9: 5 | L9: A | M9: M4 | N9: TE | O9: M2 | P9: M4 | Q9: J | S9: =VLOOKUP(L9,$A$4:$I$15,9,FALSE) -> 7 | T9: =VLOOKUP(M9,$A$4:$I$15,9,FALSE) -> 6 | U9: =VLOOKUP(N9,$A$4:$I$15,9,FALSE) -> 11 | V9: =VLOOKUP(O9,$A$4:$I$15,9,FALSE) -> 4 | W9: =VLOOKUP(P9,$A$4:$I$15,9,FALSE) -> 6 | X9: =VLOOKUP(Q9,$A$4:$I$15,9,FALSE) -> 10 | Z9: =VLOOKUP(L9,$A$4:$I$15,2,FALSE) -> Apples | AA9: =VLOOKUP(M9,$A$4:$I$15,2,FALSE) -> Rectangle | AB9: =VLOOKUP(N9,$A$4:$I$15,2,FALSE) -> Bananas | AC9: =VLOOKUP(O9,$A$4:$I$15,2,FALSE) -> Square | AD9: =VLOOKUP(P9,$A$4:$I$15,2,FALSE) -> Rectangle | AE9: =VLOOKUP(Q9,$A$4:$I$15,2,FALSE) -> Grapes | AG9: 1 | AH9: 1 | AI9: 1 | AJ9: 1 | AK9: 1 | AL9: 1
A10: M4 | B10: Rectangle | C10: =COUNTIF(L:L,$A10) -> 18 | D10: =COUNTIF(M:M,$A10) -> 20 | E10: =COUNTIF(N:N,$A10) -> 20 | F10: =COUNTIF(O:O,$A10) -> 24 | G10: =COUNTIF(P:P,$A10) -> 20 | H10: =COUNTIF(Q:Q,$A10) -> 24 | I10: 6 | K10: 6 | L10: M2 | M10: M3 | N10: Q | O10: TE | P10: M1 | Q10: J | S10: =VLOOKUP(L10,$A$4:$I$15,9,FALSE) -> 4 | T10: =VLOOKUP(M10,$A$4:$I$15,9,FALSE) -> 5 | U10: =VLOOKUP(N10,$A$4:$I$15,9,FALSE) -> 9 | V10: =VLOOKUP(O10,$A$4:$I$15,9,FALSE) -> 11 | W10: =VLOOKUP(P10,$A$4:$I$15,9,FALSE) -> 3 | X10: =VLOOKUP(Q10,$A$4:$I$15,9,FALSE) -> 10 | Z10: =VLOOKUP(L10,$A$4:$I$15,2,FALSE) -> Square | AA10: =VLOOKUP(M10,$A$4:$I$15,2,FALSE) -> pentagon | AB10: =VLOOKUP(N10,$A$4:$I$15,2,FALSE) -> Watermelon | AC10: =VLOOKUP(O10,$A$4:$I$15,2,FALSE) -> Bananas | AD10: =VLOOKUP(P10,$A$4:$I$15,2,FALSE) -> Heart | AE10: =VLOOKUP(Q10,$A$4:$I$15,2,FALSE) -> Grapes | AG10: 1 | AH10: 1 | AI10: 1 | AJ10: 1 | AK10: 1 | AL10: 1
A11: A | B11: Apples | C11: =COUNTIF(L:L,$A11) -> 22 | D11: =COUNTIF(M:M,$A11) -> 20 | E11: =COUNTIF(N:N,$A11) -> 22 | F11: =COUNTIF(O:O,$A11) -> 12 | G11: =COUNTIF(P:P,$A11) -> 16 | H11: =COUNTIF(Q:Q,$A11) -> 18 | I11: 7 | K11: 7 | L11: M2 | M11: M3 | N11: Q | O11: TE | P11: M1 | Q11: M2 | S11: =VLOOKUP(L11,$A$4:$I$15,9,FALSE) -> 4 | T11: =VLOOKUP(M11,$A$4:$I$15,9,FALSE) -> 5 | U11: =VLOOKUP(N11,$A$4:$I$15,9,FALSE) -> 9 | V11: =VLOOKUP(O11,$A$4:$I$15,9,FALSE) -> 11 | W11: =VLOOKUP(P11,$A$4:$I$15,9,FALSE) -> 3 | X11: =VLOOKUP(Q11,$A$4:$I$15,9,FALSE) -> 4 | Z11: =VLOOKUP(L11,$A$4:$I$15,2,FALSE) -> Square | AA11: =VLOOKUP(M11,$A$4:$I$15,2,FALSE) -> pentagon | AB11: =VLOOKUP(N11,$A$4:$I$15,2,FALSE) -> Watermelon | AC11: =VLOOKUP(O11,$A$4:$I$15,2,FALSE) -> Bananas | AD11: =VLOOKUP(P11,$A$4:$I$15,2,FALSE) -> Heart | AE11: =VLOOKUP(Q11,$A$4:$I$15,2,FALSE) -> Square | AG11: 1 | AH11: 1 | AI11: 1 | AJ11: 1 | AK11: 1 | AL11: 1
A12: K | B12: Peaches | C12: =COUNTIF(L:L,$A12) -> 24 | D12: =COUNTIF(M:M,$A12) -> 24 | E12: =COUNTIF(N:N,$A12) -> 30 | F12: =COUNTIF(O:O,$A12) -> 12 | G12: =COUNTIF(P:P,$A12) -> 24 | H12: =COUNTIF(Q:Q,$A12) -> 24 | I12: 8 | K12: 8 | L12: Q | M12: Q | N12: M4 | O12: Q | P12: M4 | Q12: M2 | S12: =VLOOKUP(L12,$A$4:$I$15,9,FALSE) -> 9 | T12: =VLOOKUP(M12,$A$4:$I$15,9,FALSE) -> 9 | U12: =VLOOKUP(N12,$A$4:$I$15,9,FALSE) -> 6 | V12: =VLOOKUP(O12,$A$4:$I$15,9,FALSE) -> 9 | W12: =VLOOKUP(P12,$A$4:$I$15,9,FALSE) -> 6 | X12: =VLOOKUP(Q12,$A$4:$I$15,9,FALSE) -> 4 | Z12: =VLOOKUP(L12,$A$4:$I$15,2,FALSE) -> Watermelon | AA12: =VLOOKUP(M12,$A$4:$I$15,2,FALSE) -> Watermelon | AB12: =VLOOKUP(N12,$A$4:$I$15,2,FALSE) -> Rectangle | AC12: =VLOOKUP(O12,$A$4:$I$15,2,FALSE) -> Watermelon | AD12: =VLOOKUP(P12,$A$4:$I$15,2,FALSE) -> Rectangle | AE12: =VLOOKUP(Q12,$A$4:$I$15,2,FALSE) -> Square | AG12: 1 | AH12: 1 | AI12: 1 | AJ12: 1 | AK12: 1 | AL12: 1
A13: Q | B13: Watermelon | C13: =COUNTIF(L:L,$A13) -> 24 | D13: =COUNTIF(M:M,$A13) -> 30 | E13: =COUNTIF(N:N,$A13) -> 20 | F13: =COUNTIF(O:O,$A13) -> 24 | G13: =COUNTIF(P:P,$A13) -> 46 | H13: =COUNTIF(Q:Q,$A13) -> 36 | I13: 9 | K13: 9 | L13: Q | M13: Q | N13: M4 | O13: Q | P13: M4 | Q13: A | S13: =VLOOKUP(L13,$A$4:$I$15,9,FALSE) -> 9 | T13: =VLOOKUP(M13,$A$4:$I$15,9,FALSE) -> 9 | U13: =VLOOKUP(N13,$A$4:$I$15,9,FALSE) -> 6 | V13: =VLOOKUP(O13,$A$4:$I$15,9,FALSE) -> 9 | W13: =VLOOKUP(P13,$A$4:$I$15,9,FALSE) -> 6 | X13: =VLOOKUP(Q13,$A$4:$I$15,9,FALSE) -> 7 | Z13: =VLOOKUP(L13,$A$4:$I$15,2,FALSE) -> Watermelon | AA13: =VLOOKUP(M13,$A$4:$I$15,2,FALSE) -> Watermelon | AB13: =VLOOKUP(N13,$A$4:$I$15,2,FALSE) -> Rectangle | AC13: =VLOOKUP(O13,$A$4:$I$15,2,FALSE) -> Watermelon | AD13: =VLOOKUP(P13,$A$4:$I$15,2,FALSE) -> Rectangle | AE13: =VLOOKUP(Q13,$A$4:$I$15,2,FALSE) -> Apples | AG13: 1 | AH13: 1 | AI13: 1 | AJ13: 1 | AK13: 1 | AL13: 1
A14: J | B14: Grapes | C14: =COUNTIF(L:L,$A14) -> 40 | D14: =COUNTIF(M:M,$A14) -> 30 | E14: =COUNTIF(N:N,$A14) -> 30 | F14: =COUNTIF(O:O,$A14) -> 34 | G14: =COUNTIF(P:P,$A14) -> 24 | H14: =COUNTIF(Q:Q,$A14) -> 24 | I14: 10 | K14: 10 | L14: J | M14: J | N14: C1 | O14: TE | P14: A | Q14: A | S14: =VLOOKUP(L14,$A$4:$I$15,9,FALSE) -> 10 | T14: =VLOOKUP(M14,$A$4:$I$15,9,FALSE) -> 10 | U14: =VLOOKUP(N14,$A$4:$I$15,9,FALSE) -> 1 | V14: =VLOOKUP(O14,$A$4:$I$15,9,FALSE) -> 11 | W14: =VLOOKUP(P14,$A$4:$I$15,9,FALSE) -> 7 | X14: =VLOOKUP(Q14,$A$4:$I$15,9,FALSE) -> 7 | Z14: =VLOOKUP(L14,$A$4:$I$15,2,FALSE) -> Grapes | AA14: =VLOOKUP(M14,$A$4:$I$15,2,FALSE) -> Grapes | AB14: =VLOOKUP(N14,$A$4:$I$15,2,FALSE) -> Scatter | AC14: =VLOOKUP(O14,$A$4:$I$15,2,FALSE) -> Bananas | AD14: =VLOOKUP(P14,$A$4:$I$15,2,FALSE) -> Apples | AE14: =VLOOKUP(Q14,$A$4:$I$15,2,FALSE) -> Apples | AG14: 1 | AH14: 1 | AI14: 1 | AJ14: 1 | AK14: 1 | AL14: 1
A15: TE | B15: Bananas | C15: =COUNTIF(L:L,$A15) -> 38 | D15: =COUNTIF(M:M,$A15) -> 40 | E15: =COUNTIF(N:N,$A15) -> 30 | F15: =COUNTIF(O:O,$A15) -> 46 | G15: =COUNTIF(P:P,$A15) -> 30 | H15: =COUNTIF(Q:Q,$A15) -> 28 | I15: 11 | K15: 11 | L15: J | M15: J | N15: K | O15: TE | P15: A | Q15: M4 | S15: =VLOOKUP(L15,$A$4:$I$15,9,FALSE) -> 10 | T15: =VLOOKUP(M15,$A$4:$I$15,9,FALSE) -> 10 | U15: =VLOOKUP(N15,$A$4:$I$15,9,FALSE) -> 8 | V15: =VLOOKUP(O15,$A$4:$I$15,9,FALSE) -> 11 | W15: =VLOOKUP(P15,$A$4:$I$15,9,FALSE) -> 7 | X15: =VLOOKUP(Q15,$A$4:$I$15,9,FALSE) -> 6 | Z15: =VLOOKUP(L15,$A$4:$I$15,2,FALSE) -> Grapes | AA15: =VLOOKUP(M15,$A$4:$I$15,2,FALSE) -> Grapes | AB15: =VLOOKUP(N15,$A$4:$I$15,2,FALSE) -> Peaches | AC15: =VLOOKUP(O15,$A$4:$I$15,2,FALSE) -> Bananas | AD15: =VLOOKUP(P15,$A$4:$I$15,2,FALSE) -> Apples | AE15: =VLOOKUP(Q15,$A$4:$I$15,2,FALSE) -> Rectangle | AG15: 1 | AH15: 1 | AI15: 1 | AJ15: 1 | AK15: 1 | AL15: 1
K16: 12 | L16: K | M16: TE | N16: K | O16: M4 | P16: TE | Q16: M4 | S16: =VLOOKUP(L16,$A$4:$I$15,9,FALSE) -> 8 | T16: =VLOOKUP(M16,$A$4:$I$15,9,FALSE) -> 11 | U16: =VLOOKUP(N16,$A$4:$I$15,9,FALSE) -> 8 | V16: =VLOOKUP(O16,$A$4:$I$15,9,FALSE) -> 6 | W16: =VLOOKUP(P16,$A$4:$I$15,9,FALSE) -> 11 | X16: =VLOOKUP(Q16,$A$4:$I$15,9,FALSE) -> 6 | Z16: =VLOOKUP(L16,$A$4:$I$15,2,FALSE) -> Peaches | AA16: =VLOOKUP(M16,$A$4:$I$15,2,FALSE) -> Bananas | AB16: =VLOOKUP(N16,$A$4:$I$15,2,FALSE) -> Peaches | AC16: =VLOOKUP(O16,$A$4:$I$15,2,FALSE) -> Rectangle | AD16: =VLOOKUP(P16,$A$4:$I$15,2,FALSE) -> Bananas | AE16: =VLOOKUP(Q16,$A$4:$I$15,2,FALSE) -> Rectangle | AG16: 1 | AH16: 1 | AI16: 1 | AJ16: 1 | AK16: 1 | AL16: 1
K17: 13 | L17: K | M17: TE | N17: J | O17: M4 | P17: TE | Q17: TE | S17: =VLOOKUP(L17,$A$4:$I$15,9,FALSE) -> 8 | T17: =VLOOKUP(M17,$A$4:$I$15,9,FALSE) -> 11 | U17: =VLOOKUP(N17,$A$4:$I$15,9,FALSE) -> 10 | V17: =VLOOKUP(O17,$A$4:$I$15,9,FALSE) -> 6 | W17: =VLOOKUP(P17,$A$4:$I$15,9,FALSE) -> 11 | X17: =VLOOKUP(Q17,$A$4:$I$15,9,FALSE) -> 11 | Z17: =VLOOKUP(L17,$A$4:$I$15,2,FALSE) -> Peaches | AA17: =VLOOKUP(M17,$A$4:$I$15,2,FALSE) -> Bananas | AB17: =VLOOKUP(N17,$A$4:$I$15,2,FALSE) -> Grapes | AC17: =VLOOKUP(O17,$A$4:$I$15,2,FALSE) -> Rectangle | AD17: =VLOOKUP(P17,$A$4:$I$15,2,FALSE) -> Bananas | AE17: =VLOOKUP(Q17,$A$4:$I$15,2,FALSE) -> Bananas | AG17: 1 | AH17: 1 | AI17: 1 | AJ17: 1 | AK17: 1 | AL17: 1
K18: 14 | L18: M2 | M18: Q | N18: J | O18: K | P18: M4 | Q18: TE | S18: =VLOOKUP(L18,$A$4:$I$15,9,FALSE) -> 4 | T18: =VLOOKUP(M18,$A$4:$I$15,9,FALSE) -> 9 | U18: =VLOOKUP(N18,$A$4:$I$15,9,FALSE) -> 10 | V18: =VLOOKUP(O18,$A$4:$I$15,9,FALSE) -> 8 | W18: =VLOOKUP(P18,$A$4:$I$15,9,FALSE) -> 6 | X18: =VLOOKUP(Q18,$A$4:$I$15,9,FALSE) -> 11 | Z18: =VLOOKUP(L18,$A$4:$I$15,2,FALSE) -> Square | AA18: =VLOOKUP(M18,$A$4:$I$15,2,FALSE) -> Watermelon | AB18: =VLOOKUP(N18,$A$4:$I$15,2,FALSE) -> Grapes | AC18: =VLOOKUP(O18,$A$4:$I$15,2,FALSE) -> Peaches | AD18: =VLOOKUP(P18,$A$4:$I$15,2,FALSE) -> Rectangle | AE18: =VLOOKUP(Q18,$A$4:$I$15,2,FALSE) -> Bananas | AG18: 1 | AH18: 1 | AI18: 1 | AJ18: 1 | AK18: 1 | AL18: 1
K19: 15 | L19: M2 | M19: Q | N19: M2 | O19: K | P19: M4 | Q19: M2 | S19: =VLOOKUP(L19,$A$4:$I$15,9,FALSE) -> 4 | T19: =VLOOKUP(M19,$A$4:$I$15,9,FALSE) -> 9 | U19: =VLOOKUP(N19,$A$4:$I$15,9,FALSE) -> 4 | V19: =VLOOKUP(O19,$A$4:$I$15,9,FALSE) -> 8 | W19: =VLOOKUP(P19,$A$4:$I$15,9,FALSE) -> 6 | X19: =VLOOKUP(Q19,$A$4:$I$15,9,FALSE) -> 4 | Z19: =VLOOKUP(L19,$A$4:$I$15,2,FALSE) -> Square | AA19: =VLOOKUP(M19,$A$4:$I$15,2,FALSE) -> Watermelon | AB19: =VLOOKUP(N19,$A$4:$I$15,2,FALSE) -> Square | AC19: =VLOOKUP(O19,$A$4:$I$15,2,FALSE) -> Peaches | AD19: =VLOOKUP(P19,$A$4:$I$15,2,FALSE) -> Rectangle | AE19: =VLOOKUP(Q19,$A$4:$I$15,2,FALSE) -> Square | AG19: 1 | AH19: 1 | AI19: 1 | AJ19: 1 | AK19: 1 | AL19: 1
K20: 16 | L20: C1 | M20: TE | N20: M2 | O20: A | P20: M2 | Q20: M2 | S20: =VLOOKUP(L20,$A$4:$I$15,9,FALSE) -> 1 | T20: =VLOOKUP(M20,$A$4:$I$15,9,FALSE) -> 11 | U20: =VLOOKUP(N20,$A$4:$I$15,9,FALSE) -> 4 | V20: =VLOOKUP(O20,$A$4:$I$15,9,FALSE) -> 7 | W20: =VLOOKUP(P20,$A$4:$I$15,9,FALSE) -> 4 | X20: =VLOOKUP(Q20,$A$4:$I$15,9,FALSE) -> 4 | Z20: =VLOOKUP(L20,$A$4:$I$15,2,FALSE) -> Scatter | AA20: =VLOOKUP(M20,$A$4:$I$15,2,FALSE) -> Bananas | AB20: =VLOOKUP(N20,$A$4:$I$15,2,FALSE) -> Square | AC20: =VLOOKUP(O20,$A$4:$I$15,2,FALSE) -> Apples | AD20: =VLOOKUP(P20,$A$4:$I$15,2,FALSE) -> Square | AE20: =VLOOKUP(Q20,$A$4:$I$15,2,FALSE) -> Square | AG20: 1 | AH20: 1 | AI20: 1 | AJ20: 1 | AK20: 1 | AL20: 1
K21: 17 | L21: TE | M21: TE | N21: TE | O21: A | P21: M2 | Q21: M3 | S21: =VLOOKUP(L21,$A$4:$I$15,9,FALSE) -> 11 | T21: =VLOOKUP(M21,$A$4:$I$15,9,FALSE) -> 11 | U21: =VLOOKUP(N21,$A$4:$I$15,9,FALSE) -> 11 | V21: =VLOOKUP(O21,$A$4:$I$15,9,FALSE) -> 7 | W21: =VLOOKUP(P21,$A$4:$I$15,9,FALSE) -> 4 | X21: =VLOOKUP(Q21,$A$4:$I$15,9,FALSE) -> 5 | Z21: =VLOOKUP(L21,$A$4:$I$15,2,FALSE) -> Bananas | AA21: =VLOOKUP(M21,$A$4:$I$15,2,FALSE) -> Bananas | AB21: =VLOOKUP(N21,$A$4:$I$15,2,FALSE) -> Bananas | AC21: =VLOOKUP(O21,$A$4:$I$15,2,FALSE) -> Apples | AD21: =VLOOKUP(P21,$A$4:$I$15,2,FALSE) -> Square | AE21: =VLOOKUP(Q21,$A$4:$I$15,2,FALSE) -> pentagon | AG21: 1 | AH21: 1 | AI21: 1 | AJ21: 1 | AK21: 1 | AL21: 1
K22: 18 | L22: TE | M22: M2 | N22: TE | O22: M1 | P22: M3 | Q22: M3 | S22: =VLOOKUP(L22,$A$4:$I$15,9,FALSE) -> 11 | T22: =VLOOKUP(M22,$A$4:$I$15,9,FALSE) -> 4 | U22: =VLOOKUP(N22,$A$4:$I$15,9,FALSE) -> 11 | V22: =VLOOKUP(O22,$A$4:$I$15,9,FALSE) -> 3 | W22: =VLOOKUP(P22,$A$4:$I$15,9,FALSE) -> 5 | X22: =VLOOKUP(Q22,$A$4:$I$15,9,FALSE) -> 5 | Z22: =VLOOKUP(L22,$A$4:$I$15,2,FALSE) -> Bananas | AA22: =VLOOKUP(M22,$A$4:$I$15,2,FALSE) -> Square | AB22: =VLOOKUP(N22,$A$4:$I$15,2,FALSE) -> Bananas | AC22: =VLOOKUP(O22,$A$4:$I$15,2,FALSE) -> Heart | AD22: =VLOOKUP(P22,$A$4:$I$15,2,FALSE) -> pentagon | AE22: =VLOOKUP(Q22,$A$4:$I$15,2,FALSE) -> pentagon | AG22: 1 | AH22: 1 | AI22: 1 | AJ22: 1 | AK22: 1 | AL22: 1
