Workbook

Sheet Overview
A2: Model: | B2: H019194
A3: Version: | B3: 3.0.0.1
A6: Base Bet
A7: 100
A10: Coin in | B10: Price(x) | C10: Total RTP | D10: Bet Type
A11: {=B11:B14*A7} -> 100 | B11: 1 | C11: =SUM(B19:B20) -> 0.93002249 | D11: Normal Bet Newbie
A12: 100 | B12: 1 | C12: =SUM(B23:B24) -> 0.94004301 | D12: Normal Bet Oldhand
A13: 10000 | B13: 100 | C13: =SUM(B27:B28) -> 0.9250001 | D13: Buy Feature
A14: 50000 | B14: 500 | C14: =SUM(B31:B32) -> 0.92499974 | D14: Super Feature
A17: Total Pay Back Percentage includes the following adjustments.
A18: Bet Type | B18: Pay Back | C18: Hit% | D18: Pulls/Hit | E18: Description
A19: =D11 -> Normal Bet Newbie | B19: =Multiplier_Weight_Newbie!C7 -> 0.68549637 | C19: =1/D19 -> 0.003576446 | D19: =Multiplier_Weight_Newbie!G7 -> 279.60719 | E19: Base Game | F19: =SUM(B19:B20) -> 0.93002249
B20: =Multiplier_Weight_Newbie!D7 -> 0.24452612 | E20: Free Game | F20: 4, 5 ,6 SC Free Game
A22: Bet Type | B22: Pay Back | C22: Hit% | D22: Pulls/Hit | E22: Description
A23: =D12 -> Normal Bet Oldhand | B23: =Multiplier_Weight_Oldhand!C7 -> 0.71000054 | C23: =1/D23 -> 0.002222125 | D23: =Multiplier_Weight_Oldhand!G7 -> 450.01969 | E23: Base Game | F23: =SUM(B23:B24) -> 0.94004301
B24: =Multiplier_Weight_Oldhand!D7 -> 0.23004247 | E24: Free Game | F24: 4, 5 ,6 SC Free Game
A26: Bet Type | B26: Pay Back | C26: Hit% | D26: Pulls/Hit | E26: Description
A27: =D13 -> Buy Feature | B27: =Multiplier_Weight_Oldhand!C8 -> 0.032893867 | C27: =1/D27 -> 1 | D27: 1 | E27: Base Game | F27: =SUM(B27:B28) -> 0.9250001
B28: =Multiplier_Weight_Oldhand!D8 -> 0.89210623 | E28: Free Game | F28: 4 SC Free Game
A30: Bet Type | B30: Pay Back | C30: Hit% | D30: Pulls/Hit | E30: Description
A31: =D14 -> Super Feature | B31: =Multiplier_Weight_Oldhand!C9 -> 0.0065787734 | C31: =1/D31 -> 1 | D31: 1 | E31: Base Game | F31: =SUM(B31:B32) -> 0.92499974
B32: =Multiplier_Weight_Oldhand!D9 -> 0.91842097 | E32: Free Game | F32: 4 SC Free Game
A35: Reel # | B35: 1 | C35: 2 | D35: 3 | E35: 4 | F35: 5 | G35: 6
A36: Visible Window Size | B36: 5 | C36: 5 | D36: 5 | E36: 5 | F36: 5 | G36: 5
A39: Feature Description
A40: =" Base Game 1. 5x6的盤面，任一標誌在盤面上超過8顆即可消除。消除所有贏分的標誌後，剩餘標誌往下掉落。 2. 當盤面上沒有符號可消除時，盤面上的C2上的倍數加總會等於總倍數，而該次總贏分=贏分x總倍數。 3. 倍數標誌上會出現的倍數包含"&_xlfn.TEXTJOIN("x,", TRUE, Parameter!J28:J44)&"x。"&" 4. 每一滾輪皆有機會出現C1，連線消除後也有機會出現C1。當無得分時，當盤面上出現四個以上的C1，則觸發免費遊戲。四個C1、五個C1與六個C1皆可獲得15場免費遊戲。 "&" Free Game 1. 免費遊戲中的單次Spin的最終盤面中若再出現三個C1以上可以再觸發5場免費遊戲。 2. 免費遊戲中出現的倍數會累積直到免費遊戲結束。 "&" Buy Feature 1.前四滾輪會出現C1進入Free Game。 "&" Super Feature 1. 前四滾輪會出現C1進入Free Game。 2. 在Super Feature模式中，會出現的倍數符號只會包含"&_xlfn.TEXTJOIN("x,", TRUE, Parameter!AD28:AD44)&"x。 " -> Base Game 1. 5x6的盤面，任一標誌在盤面上超過8顆即可消除。消除所有贏分的標誌後，剩餘標誌往下掉落。 2. 當盤面上沒有符號可消除時，盤面上的C2上的倍數加總會等於總倍數，而該次總贏分=贏分x總倍數。 3. 倍數標誌上會出現的倍數包含2x,3x,4x,5x,8x,10x,12x,15x,20x,25x,50x,100x,150x,200x,250x,500x,1000x。 4. 每一滾輪皆有機會出現C1，連線消除後也有機會出現C1。當無得分時，當盤面上出現四個以上的C1，則觸發免費遊戲。四個C1、五個C1與六個C1皆可獲得15場免費遊戲。 Free Game 1. 免費遊戲中的單次Spin的最終盤面中若再出現三個C1以上可以再觸發5場免費遊戲。 2. 免費遊戲中出現的倍數會累積直到免費遊戲結束。 Buy Feature 1.前四滾輪會出現C1進入Free Game。 Super Feature 1. 前四滾輪會出現C1進入Free Game。 2. 在Super Feature模式中，會出現的倍數符號只會包含10x,12x,15x,20x,25x,50x,100x,150x,200x,250x,500x,1000x。
A61: Free Spins Setting
A62: C1 Num. | B62: Base Game | C62: Free Game
A63: 3 | B63: 0 | C63: 5
A64: 4 | B64: 15 | C64: 5
A65: 5 | B65: 15 | C65: 5
A66: 6 | B66: 15 | C66: 5
A69: Pay Table： | B69: ="All wins show for "&A12&" credit bet." -> All wins show for 100 credit bet.
A70: Symbol | B70: Description | C70: 4 | D70: 5 | E70: 6 | F70: 8~9 | G70: 10~11 | H70: 12+ | I70: Id
A71: WW | B71: Wild | C71: 0 | D71: 0 | E71: 0 | F71: 0 | G71: 0 | H71: 0 | I71: 0
A72: C1 | B72: Scatter | C72: 300 | D72: 500 | E72: 10000 | F72: 0 | G72: 0 | H72: 0 | I72: 1
A73: C2 | B73: Multiplier | C73: 0 | D73: 0 | E73: 0 | F73: 0 | G73: 0 | H73: 0 | I73: 2
A74: M1 | B74: M1 | C74: 0 | D74: 0 | E74: 0 | F74: 1000 | G74: 2500 | H74: 5000 | I74: 3
A75: M2 | B75: M2 | C75: 0 | D75: 0 | E75: 0 | F75: 250 | G75: 1000 | H75: 2500 | I75: 4
A76: M3 | B76: M3 | C76: 0 | D76: 0 | E76: 0 | F76: 200 | G76: 500 | H76: 1500 | I76: 5
...

Sheet Parameter
B2: Normal Bet | L2: Buy Feature | V2: Super Feature
B4: Weight Base Reelset | L4: Weight Base Reelset | V4: Weight Base Reelset
B5: type | C5: weight | D5: prob. | L5: type | M5: weight | N5: prob. | V5: type | W5: weight | X5: prob.
B6: BG_Symbol | C6: 300 | D6: =C6/$C$10 -> 0.3 | L6: BF_Symbol | M6: 1 | N6: =M6/$M$7 -> 1 | V6: BF_Symbol | W6: 1 | X6: =W6/$M$7 -> 1
B7: BG_Symbol (2) | C7: 0 | D7: =C7/$C$10 -> 0 | M7: 1 | N7: =SUM(N6:N6) -> 1 | W7: 1 | X7: =SUM(X6:X6) -> 1
B8: BG_Symbol (3) | C8: 50 | D8: =C8/$C$10 -> 0.05
B9: BG_Symbol (4) | C9: 650 | D9: =C9/$C$10 -> 0.65
C10: =SUM(C6:C9) -> 1000 | D10: =SUM(D6:D9) -> 1
B12: Free Game Table Setting | L12: Free Game Table Setting | V12: Free Game Table Setting
C13: Free Game | D13: Retrigger | E13: prob. | M13: Free Game | N13: Retrigger | W13: Free Game | X13: Retrigger
B14: FG_Symbol | C14: 5 | D14: 2 | E14: =C14/$C$18 -> 0.33333333 | L14: FG_Symbol | M14: {=C14:D17} -> 5 | N14: 2 | V14: FG_Symbol | W14: {=M14:N17} -> 5 | X14: 2
B15: FG_Symbol (2) | C15: 0 | D15: 0 | E15: =C15/$C$18 -> 0 | L15: FG_Symbol (2) | M15: 0 | N15: 0 | V15: FG_Symbol (2) | W15: 0 | X15: 0
B16: FG_Symbol (3) | C16: 2 | D16: 1 | E16: =C16/$C$18 -> 0.13333333 | L16: FG_Symbol (3) | M16: 2 | N16: 1 | V16: FG_Symbol (3) | W16: 2 | X16: 1
B17: FG_Symbol (4) | C17: 8 | D17: 2 | E17: =C17/$C$18 -> 0.53333333 | L17: FG_Symbol (4) | M17: 8 | N17: 2 | V17: FG_Symbol (4) | W17: 8 | X17: 2
C18: =SUM(C14:C17) -> 15
B20: Weight Selection Probs | L20: Weight Selection Probs | V20: Weight Selection Probs
B21: scene | C21: normal | D21: super | E21: ultimate | L21: scene | M21: normal | N21: super | O21: ultimate | V21: scene | W21: normal | X21: super | Y21: ultimate
B22: weight_base | C22: 5000 | D22: 2500 | E22: 1500 | L22: weight_base | M22: {=C22:E23} -> 5000 | N22: 2500 | O22: 1500 | V22: weight_base | W22: {=M22:O23} -> 5000 | X22: 2500 | Y22: 1500
B23: weight_free | C23: 5000 | D23: 2500 | E23: 1500 | L23: weight_free | M23: 5000 | N23: 2500 | O23: 1500 | V23: weight_free | W23: 5000 | X23: 2500 | Y23: 1500
B26: Weight C2 | L26: Weight C2 | V26: Weight C2
B27: multiplier | C27: base_direct | D27: base_wild | E27: free_direct | F27: free_wild | G27: super | H27: ultimate | I27: bad | L27: multiplier | M27: base_direct | N27: base_wild | O27: free_direct | P27: free_wild | Q27: super | R27: ultimate | S27: bad | V27: multiplier | W27: base_direct | X27: base_wild | Y27: free_direct | Z27: free_wild | AA27: super | AB27: ultimate | AC27: bad
B28: 2 | C28: 5000 | D28: 5000 | E28: 5000 | F28: 5000 | G28: 40000 | H28: 40000 | I28: 10000 | J28: =IF(SUM(C28:H28)>0, B28, "") -> 2 | L28: 2 | M28: {=C28:I44} -> 5000 | N28: 5000 | O28: 5000 | P28: 5000 | Q28: 40000 | R28: 40000 | S28: 10000 | T28: =IF(SUM(M28:R28)>0, L28, "") -> 2 | V28: 2 | W28: 0 | X28: 0 | Y28: 0 | Z28: 0 | AA28: 0 | AB28: 0 | AC28: 10000 | AD28: =IF(SUM(W28:AB28)>0, V28, "")
B29: 3 | C29: 5000 | D29: 5000 | E29: 5000 | F29: 5000 | G29: 40000 | H29: 40000 | I29: 0 | J29: =IF(SUM(C29:H29)>0, B29, "") -> 3 | L29: 3 | M29: 5000 | N29: 5000 | O29: 5000 | P29: 5000 | Q29: 40000 | R29: 40000 | S29: 0 | T29: =IF(SUM(M29:R29)>0, L29, "") -> 3 | V29: 3 | W29: 0 | X29: 0 | Y29: 0 | Z29: 0 | AA29: 0 | AB29: 0 | AC29: 0 | AD29: =IF(SUM(W29:AB29)>0, V29, "")
B30: 4 | C30: 500 | D30: 350 | E30: 500 | F30: 350 | G30: 0 | H30: 0 | I30: 0 | J30: =IF(SUM(C30:H30)>0, B30, "") -> 4 | L30: 4 | M30: 500 | N30: 350 | O30: 500 | P30: 350 | Q30: 0 | R30: 0 | S30: 0 | T30: =IF(SUM(M30:R30)>0, L30, "") -> 4 | V30: 4 | W30: 0 | X30: 0 | Y30: 0 | Z30: 0 | AA30: 0 | AB30: 0 | AC30: 0 | AD30: =IF(SUM(W30:AB30)>0, V30, "")
B31: 5 | C31: 500 | D31: 350 | E31: 500 | F31: 350 | G31: 0 | H31: 0 | I31: 0 | J31: =IF(SUM(C31:H31)>0, B31, "") -> 5 | L31: 5 | M31: 500 | N31: 350 | O31: 500 | P31: 350 | Q31: 0 | R31: 0 | S31: 0 | T31: =IF(SUM(M31:R31)>0, L31, "") -> 5 | V31: 5 | W31: 0 | X31: 0 | Y31: 0 | Z31: 0 | AA31: 0 | AB31: 0 | AC31: 0 | AD31: =IF(SUM(W31:AB31)>0, V31, "")
B32: 8 | C32: 500 | D32: 350 | E32: 500 | F32: 350 | G32: 0 | H32: 0 | I32: 0 | J32: =IF(SUM(C32:H32)>0, B32, "") -> 8 | L32: 8 | M32: 500 | N32: 350 | O32: 500 | P32: 350 | Q32: 0 | R32: 0 | S32: 0 | T32: =IF(SUM(M32:R32)>0, L32, "") -> 8 | V32: 8 | W32: 0 | X32: 0 | Y32: 0 | Z32: 0 | AA32: 0 | AB32: 0 | AC32: 0 | AD32: =IF(SUM(W32:AB32)>0, V32, "")
B33: 10 | C33: 900 | D33: 600 | E33: 900 | F33: 600 | G33: 8000 | H33: 0 | I33: 0 | J33: =IF(SUM(C33:H33)>0, B33, "") -> 10 | L33: 10 | M33: 900 | N33: 600 | O33: 900 | P33: 600 | Q33: 8000 | R33: 0 | S33: 0 | T33: =IF(SUM(M33:R33)>0, L33, "") -> 10 | V33: 10 | W33: 5900 | X33: 5600 | Y33: 5900 | Z33: 5600 | AA33: 50000 | AB33: 40000 | AC33: 0 | AD33: =IF(SUM(W33:AB33)>0, V33, "") -> 10
B34: 12 | C34: 0 | D34: 350 | E34: 0 | F34: 350 | G34: 4700 | H34: 0 | I34: 0 | J34: =IF(SUM(C34:H34)>0, B34, "") -> 12 | L34: 12 | M34: 0 | N34: 350 | O34: 0 | P34: 350 | Q34: 4700 | R34: 0 | S34: 0 | T34: =IF(SUM(M34:R34)>0, L34, "") -> 12 | V34: 12 | W34: 5000 | X34: 5350 | Y34: 5000 | Z34: 5350 | AA34: 45000 | AB34: 40000 | AC34: 0 | AD34: =IF(SUM(W34:AB34)>0, V34, "") -> 12
B35: 15 | C35: 0 | D35: 350 | E35: 0 | F35: 350 | G35: 4700 | H35: 0 | I35: 0 | J35: =IF(SUM(C35:H35)>0, B35, "") -> 15 | L35: 15 | M35: 0 | N35: 350 | O35: 0 | P35: 350 | Q35: 4700 | R35: 0 | S35: 0 | T35: =IF(SUM(M35:R35)>0, L35, "") -> 15 | V35: 15 | W35: 500 | X35: 700 | Y35: 500 | Z35: 700 | AA35: 8000 | AB35: 0 | AC35: 0 | AD35: =IF(SUM(W35:AB35)>0, V35, "") -> 15
B36: 20 | C36: 500 | D36: 350 | E36: 500 | F36: 350 | G36: 4700 | H36: 0 | I36: 0 | J36: =IF(SUM(C36:H36)>0, B36, "") -> 20 | L36: 20 | M36: 500 | N36: 350 | O36: 500 | P36: 350 | Q36: 4700 | R36: 0 | S36: 0 | T36: =IF(SUM(M36:R36)>0, L36, "") -> 20 | V36: 20 | W36: 1000 | X36: 700 | Y36: 1000 | Z36: 700 | AA36: 8000 | AB36: 0 | AC36: 0 | AD36: =IF(SUM(W36:AB36)>0, V36, "") -> 20
B37: 25 | C37: 0 | D37: 0 | E37: 0 | F37: 0 | G37: 4700 | H37: 0 | I37: 0 | J37: =IF(SUM(C37:H37)>0, B37, "") -> 25 | L37: 25 | M37: 0 | N37: 0 | O37: 0 | P37: 0 | Q37: 4700 | R37: 0 | S37: 0 | T37: =IF(SUM(M37:R37)>0, L37, "") -> 25 | V37: 25 | W37: 500 | X37: 350 | Y37: 500 | Z37: 350 | AA37: 8000 | AB37: 0 | AC37: 0 | AD37: =IF(SUM(W37:AB37)>0, V37, "") -> 25
B38: 50 | C38: 0 | D38: 0 | E38: 0 | F38: 0 | G38: 4700 | H38: 0 | I38: 0 | J38: =IF(SUM(C38:H38)>0, B38, "") -> 50 | L38: 50 | M38: 0 | N38: 0 | O38: 0 | P38: 0 | Q38: 4700 | R38: 0 | S38: 0 | T38: =IF(SUM(M38:R38)>0, L38, "") -> 50 | V38: 50 | W38: 0 | X38: 0 | Y38: 0 | Z38: 0 | AA38: 8000 | AB38: 0 | AC38: 0 | AD38: =IF(SUM(W38:AB38)>0, V38, "") -> 50
B39: 100 | C39: 0 | D39: 350 | E39: 0 | F39: 0 | G39: 4700 | H39: 10000 | I39: 0 | J39: =IF(SUM(C39:H39)>0, B39, "") -> 100 | L39: 100 | M39: 0 | N39: 350 | O39: 0 | P39: 0 | Q39: 4700 | R39: 10000 | S39: 0 | T39: =IF(SUM(M39:R39)>0, L39, "") -> 100 | V39: 100 | W39: 0 | X39: 350 | Y39: 0 | Z39: 350 | AA39: 8000 | AB39: 8000 | AC39: 0 | AD39: =IF(SUM(W39:AB39)>0, V39, "") -> 100
B40: 150 | C40: 0 | D40: 0 | E40: 0 | F40: 0 | G40: 0 | H40: 6000 | I40: 0 | J40: =IF(SUM(C40:H40)>0, B40, "") -> 150 | L40: 150 | M40: 0 | N40: 0 | O40: 0 | P40: 0 | Q40: 0 | R40: 6000 | S40: 0 | T40: =IF(SUM(M40:R40)>0, L40, "") -> 150 | V40: 150 | W40: 0 | X40: 0 | Y40: 0 | Z40: 0 | AA40: 0 | AB40: 5000 | AC40: 0 | AD40: =IF(SUM(W40:AB40)>0, V40, "") -> 150
... B44: 1000 | C44: 0 | D44: 0 | E44: 0 | F44: 0 | G44: 0 | H44: 6000 | I44: 0 | J44: =IF(SUM(C44:H44)>0, B44, "") -> 1000 | L44: 1000 | M44: 0 | N44: 0 | O44: 0 | P44: 0 | Q44: 0 | R44: 6000 | S44: 0 | T44: =IF(SUM(M44:R44)>0, L44, "") -> 1000 | V44: 1000 | W44: 0 | X44: 0 | Y44: 0 | Z44: 0 | AA44: 0 | AB44: 5000 | AC44: 0 | AD44: =IF(SUM(W44:AB44)>0, V44, "") -> 1000
B47: Prob C2 | L47: Prob C2 | V47: Prob C2
B48: multiplier | C48: base_direct | D48: base_wild | E48: free_direct | F48: free_wild | G48: super | H48: ultimate | I48: bad | L48: multiplier | M48: base_direct | N48: base_wild | O48: free_direct | P48: free_wild | Q48: super | R48: ultimate | S48: bad | V48: multiplier | W48: base_direct | X48: base_wild | Y48: free_direct | Z48: free_wild | AA48: super | AB48: ultimate | AC48: bad
B49: 2 | C49: =C28/SUM(C$28:C$44) -> 0.3875969 | D49: =D28/SUM(D$28:D$44) -> 0.38314176 | E49: =E28/SUM(E$28:E$44) -> 0.3875969 | F49: =F28/SUM(F$28:F$44) -> 0.39370079 | G49: =G28/SUM(G$28:G$44) -> 0.34423408 | H49: =H28/SUM(H$28:H$44) -> 0.33333333 | I49: =I28/SUM(I$28:I$44) -> 1 | L49: 2 | M49: =M28/SUM(M$28:M$44) -> 0.3875969 | N49: =N28/SUM(N$28:N$44) -> 0.38314176 | O49: =O28/SUM(O$28:O$44) -> 0.3875969 | P49: =P28/SUM(P$28:P$44) -> 0.39370079 | Q49: =Q28/SUM(Q$28:Q$44) -> 0.34423408 | R49: =R28/SUM(R$28:R$44) -> 0.33333333 | S49: =S28/SUM(S$28:S$44) -> 1 | V49: 2 | W49: =W28/SUM(W$28:W$44) -> 0 | X49: =X28/SUM(X$28:X$44) -> 0 | Y49: =Y28/SUM(Y$28:Y$44) -> 0 | Z49: =Z28/SUM(Z$28:Z$44) -> 0 | AA49: =AA28/SUM(AA$28:AA$44) -> 0 | AB49: =AB28/SUM(AB$28:AB$44) -> 0 | AC49: =AC28/SUM(AC$28:AC$44) -> 1
B50: 3 | C50: =C29/SUM(C$28:C$44) -> 0.3875969 | D50: =D29/SUM(D$28:D$44) -> 0.38314176 | E50: =E29/SUM(E$28:E$44) -> 0.3875969 | F50: =F29/SUM(F$28:F$44) -> 0.39370079 | G50: =G29/SUM(G$28:G$44) -> 0.34423408 | H50: =H29/SUM(H$28:H$44) -> 0.33333333 | I50: =I29/SUM(I$28:I$44) -> 0 | L50: 3 | M50: =M29/SUM(M$28:M$44) -> 0.3875969 | N50: =N29/SUM(N$28:N$44) -> 0.38314176 | O50: =O29/SUM(O$28:O$44) -> 0.3875969 | P50: =P29/SUM(P$28:P$44) -> 0.39370079 | Q50: =Q29/SUM(Q$28:Q$44) -> 0.34423408 | R50: =R29/SUM(R$28:R$44) -> 0.33333333 | S50: =S29/SUM(S$28:S$44) -> 0 | V50: 3 | W50: =W29/SUM(W$28:W$44) -> 0 | X50: =X29/SUM(X$28:X$44) -> 0 | Y50: =Y29/SUM(Y$28:Y$44) -> 0 | Z50: =Z29/SUM(Z$28:Z$44) -> 0 | AA50: =AA29/SUM(AA$28:AA$44) -> 0 | AB50: =AB29/SUM(AB$28:AB$44) -> 0 | AC50: =AC29/SUM(AC$28:AC$44) -> 0
B51: 4 | C51: =C30/SUM(C$28:C$44) -> 0.03875969 | D51: =D30/SUM(D$28:D$44) -> 0.026819923 | E51: =E30/SUM(E$28:E$44) -> 0.03875969 | F51: =F30/SUM(F$28:F$44) -> 0.027559055 | G51: =G30/SUM(G$28:G$44) -> 0 | H51: =H30/SUM(H$28:H$44) -> 0 | I51: =I30/SUM(I$28:I$44) -> 0 | L51: 4 | M51: =M30/SUM(M$28:M$44) -> 0.03875969 | N51: =N30/SUM(N$28:N$44) -> 0.026819923 | O51: =O30/SUM(O$28:O$44) -> 0.03875969 | P51: =P30/SUM(P$28:P$44) -> 0.027559055 | Q51: =Q30/SUM(Q$28:Q$44) -> 0 | R51: =R30/SUM(R$28:R$44) -> 0 | S51: =S30/SUM(S$28:S$44) -> 0 | V51: 4 | W51: =W30/SUM(W$28:W$44) -> 0 | X51: =X30/SUM(X$28:X$44) -> 0 | Y51: =Y30/SUM(Y$28:Y$44) -> 0 | Z51: =Z30/SUM(Z$28:Z$44) -> 0 | AA51: =AA30/SUM(AA$28:AA$44) -> 0 | AB51: =AB30/SUM(AB$28:AB$44) -> 0 | AC51: =AC30/SUM(AC$28:AC$44) -> 0
...

Sheet Tool_BG
B2: 新手A | C2: =" ["&_xlfn.TEXTJOIN(", ",,Multiplier_Weight_Newbie!L16:L80)&"]," -> [716089973, 150413198, 54248599, 17724287, 12618997, 14755671, 12270945, 1699777, 1372633, 1238230, 1113887, 6052235, 2902448, 2152521, 1770153, 0, 0, 0, 0, 0, 0, 0, 0, 0, 0, 0, 0, 0, 0, 0, 0, 0, 0, 0, 0, 0, 0, 0, 0, 0, 0, 0, 0, 0, 0, 0, 0, 0, 0, 0, 0, 0, 0, 0, 0, 0, 0, 0, 0, 0, 0, 0, 0, 0, 3576446],
B3: 新手B | C3: =C2 -> [716089973, 150413198, 54248599, 17724287, 12618997, 14755671, 12270945, 1699777, 1372633, 1238230, 1113887, 6052235, 2902448, 2152521, 1770153, 0, 0, 0, 0, 0, 0, 0, 0, 0, 0, 0, 0, 0, 0, 0, 0, 0, 0, 0, 0, 0, 0, 0, 0, 0, 0, 0, 0, 0, 0, 0, 0, 0, 0, 0, 0, 0, 0, 0, 0, 0, 0, 0, 0, 0, 0, 0, 0, 0, 3576446],
B4: 老手A | C4: =" ["&_xlfn.TEXTJOIN(", ",,Multiplier_Weight_Oldhand!L16:L80)&"]," -> [719471124, 151113333, 54501112, 17806789, 12677735, 14824355, 12328063, 1707689, 1379023, 1243993, 1119072, 5438967, 1070357, 790550, 650119, 560054, 58189, 43433, 38501, 61914, 50646, 45978, 307039, 23792, 235818, 40314, 27608, 21812, 22511, 117985, 0, 0, 0, 0, 0, 0, 0, 0, 0, 0, 0, 0, 0, 0, 0, 0, 0, 0, 0, 0, 0, 0, 0, 0, 0, 0, 0, 0, 0, 0, 0, 0, 0, 0, 2222125],
B5: 老手B | C5: =C4 -> [719471124, 151113333, 54501112, 17806789, 12677735, 14824355, 12328063, 1707689, 1379023, 1243993, 1119072, 5438967, 1070357, 790550, 650119, 560054, 58189, 43433, 38501, 61914, 50646, 45978, 307039, 23792, 235818, 40314, 27608, 21812, 22511, 117985, 0, 0, 0, 0, 0, 0, 0, 0, 0, 0, 0, 0, 0, 0, 0, 0, 0, 0, 0, 0, 0, 0, 0, 0, 0, 0, 0, 0, 0, 0, 0, 0, 0, 0, 2222125],
B8: 0 | C8: [ | H8: 0 | I8: [
B9: 0 | C9: { | H9: 0 | I9: {
B10: 0 | C10: "noWinIndex": [0], | H10: 0 | I10: "noWinIndex": [0],
B11: 0 | C11: =" ""wheelLength"": "&BG_Symbol!$C$16&"," -> "wheelLength": 100, | H11: 0 | I11: =" ""wheelLength"": "&BG_Symbol!$C$16&"," -> "wheelLength": 100,
B12: 0 | C12: =" ""wheelData"": ["&_xlfn.TEXTJOIN(",",,BG_Symbol!$S$4:$S$304)&"]}" -> "wheelData": [6,6,4,4,7,7,11,11,8,8,2,10,10,8,8,10,10,6,6,7,7,5,5,6,6,11,11,10,10,6,6,10,10,9,9,10,10,1,8,8,10,10,8,8,4,4,7,7,4,4,6,6,7,7,0,0,9,9,6,6,8,8,10,10,6,6,0,4,4,7,7,10,10,6,6,8,8,4,4,1,10,10,4,4,7,7,10,10,2,2,8,8,3,3,4,4,7,7,4,4]} | H12: 0 | I12: =" ""wheelData"": ["&_xlfn.TEXTJOIN(",",,BG_Symbol!$Z$4:$Z$304)&"]}" -> "wheelData": [1,1,1,1,1,1,1,1,1,1,1,1,1,1,1,1,1,1,1,1,1,1,1,1,1,1,1,1,1,1,1,1,1,1,1,1,1,1,1,1,1,1,1,1,1,1,1,1,1,1,0,1,1,1,1,0,2,2,2,2,1,1,0,0,0,0,0,1,1,1,1,1,1,1,1,1,1,1,1,1,1,1,1,1,0,0,0,0,0,0,1,1,1,1,1,1,1,1,1,1]}
B13: 0 | C13: ,{ | H13: 0 | I13: ,{
B14: 0 | C14: "noWinIndex": [0], | H14: 0 | I14: "noWinIndex": [0],
B15: 0 | C15: =" ""wheelLength"": "&BG_Symbol!$D$16&"," -> "wheelLength": 100, | H15: 0 | I15: =" ""wheelLength"": "&BG_Symbol!$D$16&"," -> "wheelLength": 100,
B16: 0 | C16: =" ""wheelData"": ["&_xlfn.TEXTJOIN(",",,BG_Symbol!$T$4:$T$304)&"]}" -> "wheelData": [3,3,7,7,8,8,5,9,9,11,11,8,8,5,5,9,9,5,5,11,8,8,5,5,3,3,4,4,11,11,5,5,11,11,5,5,2,2,9,9,11,11,6,6,8,8,11,11,8,8,3,3,8,8,5,5,11,11,3,3,8,8,11,11,2,8,8,11,11,9,9,11,11,9,9,5,5,9,9,0,9,9,11,11,9,9,3,3,9,9,10,10,0,0,3,3,8,8,9,9]} | H16: 0 | I16: =" ""wheelData"": ["&_xlfn.TEXTJOIN(",",,BG_Symbol!$AA$4:$AA$304)&"]}" -> "wheelData": [1,1,1,1,1,1,1,1,1,1,1,1,1,1,1,1,1,1,1,1,1,1,1,1,1,1,1,1,1,1,1,1,0,0,0,0,0,0,1,1,1,1,1,1,1,1,1,1,1,1,1,1,1,1,1,1,1,1,1,1,1,1,1,1,1,1,1,1,1,1,1,1,1,1,1,0,0,0,0,0,1,1,1,1,1,1,1,1,0,0,1,1,0,0,2,2,2,2,1,1]}
B17: 0 | C17: ,{ | H17: 0 | I17: ,{
B18: 0 | C18: "noWinIndex": [0], | H18: 0 | I18: "noWinIndex": [0],
B19: 0 | C19: =" ""wheelLength"": "&BG_Symbol!$E$16&"," -> "wheelLength": 100, | H19: 0 | I19: =" ""wheelLength"": "&BG_Symbol!$E$16&"," -> "wheelLength": 100,
B20: 0 | C20: =" ""wheelData"": ["&_xlfn.TEXTJOIN(",",,BG_Symbol!$U$4:$U$304)&"]}" -> "wheelData": [7,7,6,7,7,5,5,10,10,2,2,9,9,11,11,6,6,5,5,6,6,0,0,6,6,10,10,7,7,9,9,7,7,5,5,11,11,6,6,4,4,10,10,2,10,10,11,11,10,10,9,9,6,6,9,7,7,4,4,11,11,4,4,9,9,7,7,10,10,3,3,11,11,7,7,4,4,0,6,6,7,7,10,10,7,7,4,4,9,9,4,4,7,7,10,10,7,7,8,8]} | H20: 0 | I20: =" ""wheelData"": ["&_xlfn.TEXTJOIN(",",,BG_Symbol!$AB$4:$AB$304)&"]}" -> "wheelData": [1,1,1,1,1,0,0,0,0,0,0,1,1,1,1,1,1,0,1,1,1,1,0,2,2,2,2,1,1,1,1,1,1,1,1,1,1,1,1,1,1,1,1,1,1,1,1,1,1,1,1,1,1,1,1,1,1,1,1,1,1,1,1,1,1,1,1,1,1,1,1,1,1,0,0,0,0,0,1,1,1,1,1,1,1,1,1,1,1,1,1,1,1,1,1,1,1,1,1,1]}
B21: 0 | C21: ,{ | H21: 0 | I21: ,{
B22: 0 | C22: "noWinIndex": [0], | H22: 0 | I22: "noWinIndex": [0],
B23: 0 | C23: =" ""wheelLength"": "&BG_Symbol!$F$16&"," -> "wheelLength": 100, | H23: 0 | I23: =" ""wheelLength"": "&BG_Symbol!$F$16&"," -> "wheelLength": 100,
B24: 0 | C24: =" ""wheelData"": ["&_xlfn.TEXTJOIN(",",,BG_Symbol!$V$4:$V$304)&"]}" -> "wheelData": [9,9,3,3,9,9,11,11,3,3,11,11,7,7,11,11,4,4,11,11,4,4,11,11,2,7,7,11,11,7,7,3,3,4,4,2,2,10,10,11,11,5,5,4,4,0,0,11,11,9,9,11,11,4,4,3,3,6,6,3,3,7,7,11,11,7,7,1,7,7,9,9,7,7,9,9,8,8,9,9,7,7,9,9,0,7,7,9,9,11,11,11,11,1,3,3,9,9,11,11]} | H24: 0 | I24: =" ""wheelData"": ["&_xlfn.TEXTJOIN(",",,BG_Symbol!$AC$4:$AC$304)&"]}" -> "wheelData": [1,1,1,1,1,1,1,1,1,1,1,1,1,1,1,1,1,1,1,1,1,1,1,1,1,1,1,1,1,1,1,0,0,0,0,0,0,1,1,1,1,0,0,1,1,0,0,2,2,2,2,1,1,1,1,1,1,1,1,1,1,1,1,1,1,1,1,1,1,1,1,1,1,1,1,1,1,1,1,1,0,0,0,0,0,1,1,1,1,1,1,1,1,1,1,1,1,1,1,1]}
B25: 0 | C25: ,{ | H25: 0 | I25: ,{
B26: 0 | C26: "noWinIndex": [0], | H26: 0 | I26: "noWinIndex": [0],
B27: 0 | C27: =" ""wheelLength"": "&BG_Symbol!$G$16&"," -> "wheelLength": 100, | H27: 0 | I27: =" ""wheelLength"": "&BG_Symbol!$G$16&"," -> "wheelLength": 100,
B28: 0 | C28: =" ""wheelData"": ["&_xlfn.TEXTJOIN(",",,BG_Symbol!$W$4:$W$304)&"]}" -> "wheelData": [6,6,2,11,11,10,10,3,3,11,11,5,5,10,10,0,0,11,11,5,5,1,8,8,10,10,11,11,10,10,3,3,1,10,10,11,11,6,6,10,10,11,11,10,10,2,2,8,8,4,4,10,10,8,8,5,5,8,8,10,10,11,11,8,8,9,9,5,5,11,11,10,10,8,8,5,5,10,10,8,8,7,7,5,5,4,4,11,11,8,8,0,8,8,11,11,5,5,8,8]} | H28: 0 | I28: =" ""wheelData"": ["&_xlfn.TEXTJOIN(",",,BG_Symbol!$AD$4:$AD$304)&"]}" -> "wheelData": [1,1,1,1,1,1,1,1,1,1,1,0,1,1,1,1,0,2,2,2,2,1,1,1,1,1,1,1,1,1,1,1,1,1,1,1,1,1,1,1,1,0,0,0,0,0,0,1,1,1,1,1,1,1,1,1,1,1,1,1,1,1,1,1,1,1,1,1,1,1,1,1,1,1,1,1,1,1,1,1,1,1,1,1,1,1,1,0,0,0,0,0,1,1,1,1,1,1,1,1]}
B29: 0 | C29: ,{ | H29: 0 | I29: ,{
B30: 0 | C30: "noWinIndex": [0], | H30: 0 | I30: "noWinIndex": [0],
B31: 0 | C31: =" ""wheelLength"": "&BG_Symbol!$H$16&"," -> "wheelLength": 100, | H31: 0 | I31: =" ""wheelLength"": "&BG_Symbol!$H$16&"," -> "wheelLength": 100,
B32: 0 | C32: =" ""wheelData"": ["&_xlfn.TEXTJOIN(",",,BG_Symbol!$X$4:$X$304)&"]}" -> "wheelData": [11,11,9,9,11,11,3,3,11,11,9,9,11,11,3,3,11,2,9,9,6,6,11,11,3,9,9,11,11,6,6,9,9,6,6,9,9,3,3,6,6,3,3,6,6,3,3,0,7,7,9,9,3,3,9,9,0,0,11,11,9,9,11,11,3,3,2,2,9,9,7,7,8,8,9,9,6,6,8,8,11,6,6,11,5,5,9,9,11,11,6,6,11,11,4,4,11,11,10,10]} | H32: 0 | I32: =" ""wheelData"": ["&_xlfn.TEXTJOIN(",",,BG_Symbol!$AE$4:$AE$304)&"]}" -> "wheelData": [1,1,1,1,1,1,1,1,1,1,1,1,1,1,1,1,1,1,1,1,1,1,1,1,1,1,1,1,1,1,1,1,1,1,1,1,1,1,1,1,1,1,1,0,0,0,0,0,1,1,1,1,0,0,1,1,0,0,2,2,2,2,0,0,0,0,0,0,1,1,1,1,1,1,1,1,1,1,1,1,1,1,1,1,1,1,1,1,1,1,1,1,1,1,1,1,1,1,1,1]}
B33: 0 | C33: ], | H33: 0 | I33: ],
B34: {=B8:B33+1} -> 1 | C34: [ | H34: {=H8:H33+1} -> 1 | I34: [
B35: 1 | C35: { | H35: 1 | I35: {
B36: 1 | C36: "noWinIndex": [0], | H36: 1 | I36: "noWinIndex": [0],
B37: 1 | C37: =" ""wheelLength"": "&'BG_Symbol (2)'!$C$16&"," -> "wheelLength": 104, | H37: 1 | I37: =" ""wheelLength"": "&'BG_Symbol (2)'!$C$16&"," -> "wheelLength": 104,
B38: 1 | C38: =" ""wheelData"": ["&_xlfn.TEXTJOIN(",",,'BG_Symbol (2)'!$S$4:$S$304)&"]}" -> "wheelData": [3,3,6,6,9,9,6,6,8,8,11,11,6,6,7,7,3,3,8,8,3,3,11,11,7,7,11,11,6,6,11,11,10,10,9,9,10,10,11,11,8,8,10,10,9,9,10,10,11,11,7,7,10,10,4,4,9,9,3,3,9,9,3,3,6,6,8,8,10,10,9,9,10,10,6,6,9,9,10,10,6,6,9,9,6,6,9,9,3,3,6,6,9,9,6,6,9,9,3,3,6,6,9,9]} | H38: 1 | I38: =" ""wheelData"": ["&_xlfn.TEXTJOIN(",",,'BG_Symbol (2)'!$Z$4:$Z$304)&"]}" -> "wheelData": [2,2,2,2,2,2,2,2,2,2,2,2,2,2,2,2,2,2,2,2,2,2,2,2,2,2,2,2,2,2,2,2,2,2,2,2,2,2,2,2,2,2,2,2,2,2,2,2,2,1,1,1,1,1,2,2,2,2,2,2,2,2,2,2,2,2,2,2,2,2,2,2,2,2,2,2,2,2,2,2,2,2,2,2,2,2,2,2,2,2,2,2,2,2,2,2,2,2,2,2,2,2,2,2,2,2,2,2]}
B39: 1 | C39: ,{ | H39: 1 | I39: ,{
B40: 1 | C40: "noWinIndex": [0], | H40: 1 | I40: "noWinIndex": [0],
B41: 1 | C41: =" ""wheelLength"": "&'BG_Symbol (2)'!$D$16&"," -> "wheelLength": 104, | H41: 1 | I41: =" ""wheelLength"": "&'BG_Symbol (2)'!$D$16&"," -> "wheelLength": 104,
B42: 1 | C42: =" ""wheelData"": ["&_xlfn.TEXTJOIN(",",,'BG_Symbol (2)'!$T$4:$T$304)&"]}" -> "wheelData": [4,4,9,9,10,10,7,7,9,9,10,10,7,7,9,9,10,10,9,9,7,7,10,10,9,9,7,7,9,9,10,10,4,4,7,7,10,10,4,4,7,7,11,11,4,4,7,7,10,10,7,7,4,4,7,7,10,10,4,4,7,7,10,10,4,4,7,7,10,10,4,4,7,7,10,10,3,3,4,4,7,7,10,10,4,4,7,7,8,8,10,10,7,7,10,10,4,4,7,7,9,9,7,7]} | H42: 1 | I42: =" ""wheelData"": ["&_xlfn.TEXTJOIN(",",,'BG_Symbol (2)'!$AA$4:$AA$304)&"]}" -> "wheelData": [2,2,2,2,2,2,2,2,2,2,2,2,2,2,2,2,2,2,2,2,2,2,2,2,2,2,2,2,2,2,2,2,2,2,2,2,2,2,2,2,2,2,2,2,2,2,2,2,2,1,1,1,1,1,2,2,2,2,2,2,2,2,2,2,2,2,2,2,2,2,2,2,2,2,2,2,2,2,2,2,2,2,2,2,2,2,2,2,2,2,2,2,2,2,2,2,2,2,2,2,2,2,2,2,2,2,2,2]}
B43: 1 | C43: ,{ | H43: 1 | I43: ,{
...

Sheet Tool_FG
B3: 新手A | C3: =" ["&_xlfn.TEXTJOIN(", ",,Multiplier_Weight_Newbie!L89:L152)&"]," -> [0, 0, 0, 0, 0, 0, 0, 0, 0, 0, 0, 0, 0, 0, 0, 0, 0, 0, 0, 557069786, 95271780, 91553387, 87242488, 85769090, 83093469, 0, 0, 0, 0, 0, 0, 0, 0, 0, 0, 0, 0, 0, 0, 0, 0, 0, 0, 0, 0, 0, 0, 0, 0, 0, 0, 0, 0, 0, 0, 0, 0, 0, 0, 0, 0, 0, 0, 0],
B4: 新手B | C4: =C3 -> [0, 0, 0, 0, 0, 0, 0, 0, 0, 0, 0, 0, 0, 0, 0, 0, 0, 0, 0, 557069786, 95271780, 91553387, 87242488, 85769090, 83093469, 0, 0, 0, 0, 0, 0, 0, 0, 0, 0, 0, 0, 0, 0, 0, 0, 0, 0, 0, 0, 0, 0, 0, 0, 0, 0, 0, 0, 0, 0, 0, 0, 0, 0, 0, 0, 0, 0, 0],
B5: 老手A | C5: =" ["&_xlfn.TEXTJOIN(", ",,Multiplier_Weight_Oldhand!L89:L152)&"]," -> [0, 0, 0, 0, 0, 0, 0, 0, 0, 0, 0, 38890097, 86411234, 76453090, 63797415, 56784736, 51452062, 42043400, 41610170, 70104419, 58903513, 50101820, 41981152, 35655571, 54971101, 40670181, 29834910, 21973233, 25896315, 35566662, 13317928, 10535561, 9226289, 6765914, 3998141, 2330336, 15972289, 3607343, 2417921, 805618, 722742, 691282, 645271, 594408, 553940, 4713936, 0, 0, 0, 0, 0, 0, 0, 0, 0, 0, 0, 0, 0, 0, 0, 0, 0, 0],
B6: 老手B | C6: =C5 -> [0, 0, 0, 0, 0, 0, 0, 0, 0, 0, 0, 38890097, 86411234, 76453090, 63797415, 56784736, 51452062, 42043400, 41610170, 70104419, 58903513, 50101820, 41981152, 35655571, 54971101, 40670181, 29834910, 21973233, 25896315, 35566662, 13317928, 10535561, 9226289, 6765914, 3998141, 2330336, 15972289, 3607343, 2417921, 805618, 722742, 691282, 645271, 594408, 553940, 4713936, 0, 0, 0, 0, 0, 0, 0, 0, 0, 0, 0, 0, 0, 0, 0, 0, 0, 0],
B7: BF | C7: =" ["&_xlfn.TEXTJOIN(", ",,Multiplier_Weight_Oldhand!L159:L222)&"]," -> [0, 0, 0, 0, 0, 0, 0, 0, 0, 0, 0, 19716216, 81349051, 72030796, 60043863, 53482829, 48518042, 39569296, 39202108, 90567505, 76098324, 64726121, 54235663, 46063394, 74434756, 36024077, 26506030, 19481865, 23258767, 32062086, 8545765, 6582127, 5764155, 4426637, 2716414, 1407356, 5706293, 1146136, 1056316, 391106, 350871, 335599, 313261, 288569, 268923, 3329683, 0, 0, 0, 0, 0, 0, 0, 0, 0, 0, 0, 0, 0, 0, 0, 0, 0, 0],
B8: SF | C8: =" ["&_xlfn.TEXTJOIN(", ",,_xlfn.ANCHORARRAY(Multiplier_Weight_Oldhand!L229))&"]," -> [0, 0, 0, 0, 0, 0, 0, 0, 0, 0, 0, 0, 0, 0, 0, 0, 0, 0, 0, 0, 0, 0, 0, 0, 65146622, 58023904, 51045020, 45892892, 40935150, 78188198, 63159643, 54478019, 47523624, 77482320, 69453892, 63242035, 69852776, 64342863, 24269628, 21442607, 20830560, 16248096, 15029607, 14518441, 13473626, 13912388, 3997878, 2829193, 2149765, 386642, 281027, 212016, 164192, 1487360, 0, 0, 0, 0, 0, 0, 0, 0, 0, 0],
B12: 0 | C12: [ | I12: 0 | J12: [
B13: 0 | C13: { | I13: 0 | J13: {
B14: 0 | C14: "noWinIndex": [0], | I14: 0 | J14: "noWinIndex": [0],
B15: 0 | C15: =" ""wheelLength"": "&FG_Symbol!$C$16&"," -> "wheelLength": 100, | I15: 0 | J15: =C15 -> "wheelLength": 100,
B16: 0 | C16: =" ""wheelData"": ["&_xlfn.TEXTJOIN(",",,FG_Symbol!$S$4:$S$304)&"]}" -> "wheelData": [5,5,1,10,10,11,11,10,10,11,11,10,10,0,0,7,7,5,5,11,11,7,7,4,4,10,10,11,11,1,5,5,10,10,11,11,3,3,10,10,3,3,11,11,2,2,9,9,11,11,6,6,3,3,10,10,11,11,10,10,11,11,10,10,2,11,11,10,10,11,11,0,10,10,5,5,10,10,8,8,11,11,9,9,10,10,5,5,10,10,11,11,8,8,3,3,10,10,11,11]} | I16: 0 | J16: =" ""wheelData"": ["&_xlfn.TEXTJOIN(",",,FG_Symbol!$Z$4:$Z$304)&"]}" -> "wheelData": [1,1,1,1,1,1,1,1,1,0,1,1,1,1,0,1,1,1,1,1,1,1,1,1,1,1,1,1,1,1,1,1,1,1,1,1,1,1,1,1,0,0,0,0,0,0,1,1,1,1,1,1,1,1,1,1,1,1,1,1,0,1,1,1,0,1,1,0,0,0,0,0,2,2,2,2,1,1,1,1,1,1,1,1,1,1,1,1,1,1,1,1,1,1,1,1,1,1,1,1]}
B17: 0 | C17: ,{ | I17: 0 | J17: ,{
B18: 0 | C18: "noWinIndex": [0], | I18: 0 | J18: "noWinIndex": [0],
B19: 0 | C19: =" ""wheelLength"": "&FG_Symbol!$D$16&"," -> "wheelLength": 100, | I19: 0 | J19: =C19 -> "wheelLength": 100,
B20: 0 | C20: =" ""wheelData"": ["&_xlfn.TEXTJOIN(",",,FG_Symbol!$T$4:$T$304)&"]}" -> "wheelData": [9,9,5,5,9,9,2,2,10,10,11,11,5,5,9,9,8,8,9,9,4,4,9,9,11,11,1,7,7,8,8,9,9,7,7,8,8,9,9,6,6,1,9,9,6,6,8,8,11,11,8,8,9,9,8,8,11,11,0,0,8,8,9,9,8,8,11,11,6,6,8,8,9,9,11,11,8,8,3,3,2,11,11,5,5,9,9,11,11,6,6,0,8,8,5,5,10,10,6,6]} | I20: 0 | J20: =" ""wheelData"": ["&_xlfn.TEXTJOIN(",",,FG_Symbol!$AA$4:$AA$304)&"]}" -> "wheelData": [1,1,0,0,0,0,0,0,1,1,1,1,1,1,1,1,1,1,1,1,1,1,1,1,1,1,1,1,1,1,1,1,1,1,1,1,1,1,1,1,1,1,1,1,1,1,1,1,1,1,1,1,1,1,0,1,1,1,1,0,2,2,2,2,1,1,1,1,1,1,1,1,1,1,1,1,0,1,1,1,0,1,1,1,1,1,1,0,0,0,0,0,2,2,2,2,1,1,1,1]}
B21: 0 | C21: ,{ | I21: 0 | J21: ,{
B22: 0 | C22: "noWinIndex": [0], | I22: 0 | J22: "noWinIndex": [0],
B23: 0 | C23: =" ""wheelLength"": "&FG_Symbol!$E$16&"," -> "wheelLength": 100, | I23: 0 | J23: =C23 -> "wheelLength": 100,
B24: 0 | C24: =" ""wheelData"": ["&_xlfn.TEXTJOIN(",",,FG_Symbol!$U$4:$U$304)&"]}" -> "wheelData": [10,10,8,8,4,4,8,8,7,7,8,8,4,4,10,10,4,4,11,11,2,9,9,7,7,8,8,9,9,0,8,8,7,7,8,8,3,3,2,2,10,10,3,3,7,7,0,0,10,10,7,7,10,10,4,4,8,8,7,7,5,5,1,10,10,8,8,4,4,3,3,1,7,7,10,10,8,8,7,7,8,8,10,10,7,7,10,10,3,3,10,10,6,6,10,10,7,7,11,11]} | I24: 0 | J24: =" ""wheelData"": ["&_xlfn.TEXTJOIN(",",,FG_Symbol!$AB$4:$AB$304)&"]}" -> "wheelData": [1,1,1,1,1,1,1,1,1,1,1,1,1,1,1,1,0,1,1,1,0,1,1,1,1,0,0,0,0,0,1,1,1,1,0,0,0,0,0,0,1,1,0,1,1,1,1,0,1,1,1,1,1,1,1,1,1,1,1,1,1,1,1,1,1,1,1,1,1,1,1,1,1,1,1,1,1,1,1,1,1,1,1,1,1,1,1,1,1,1,1,1,1,1,1,1,1,1,1,1]}
B25: 0 | C25: ,{ | I25: 0 | J25: ,{
B26: 0 | C26: "noWinIndex": [0], | I26: 0 | J26: "noWinIndex": [0],
B27: 0 | C27: =" ""wheelLength"": "&FG_Symbol!$F$16&"," -> "wheelLength": 100, | I27: 0 | J27: =C27 -> "wheelLength": 100,
B28: 0 | C28: =" ""wheelData"": ["&_xlfn.TEXTJOIN(",",,FG_Symbol!$V$4:$V$304)&"]}" -> "wheelData": [11,11,7,7,10,10,8,8,11,11,9,9,10,10,11,11,10,10,6,6,7,7,6,6,10,10,0,0,11,11,5,5,11,11,10,10,6,6,5,5,11,11,4,4,11,11,5,5,7,7,2,5,5,10,10,9,9,10,10,0,10,10,6,6,10,10,11,11,10,10,2,2,10,10,11,11,5,5,10,10,11,11,8,8,10,10,11,11,7,7,11,11,10,10,11,11,7,7,3,3]} | I28: 0 | J28: =" ""wheelData"": ["&_xlfn.TEXTJOIN(",",,FG_Symbol!$AC$4:$AC$304)&"]}" -> "wheelData": [1,1,1,1,1,1,1,1,1,1,1,1,1,1,1,1,1,1,1,1,1,1,0,1,1,1,1,0,2,2,2,2,1,1,1,1,1,1,1,1,1,1,1,1,1,1,0,1,1,1,0,1,1,1,1,0,0,0,0,0,2,2,2,2,1,1,0,0,0,0,0,0,1,1,1,1,1,1,1,1,1,1,1,1,1,1,1,1,1,1,1,1,1,1,1,1,1,1,1,1]}
B29: 0 | C29: ,{ | I29: 0 | J29: ,{
B30: 0 | C30: "noWinIndex": [0], | I30: 0 | J30: "noWinIndex": [0],
B31: 0 | C31: =" ""wheelLength"": "&FG_Symbol!$G$16&"," -> "wheelLength": 100, | I31: 0 | J31: =C31 -> "wheelLength": 100,
B32: 0 | C32: =" ""wheelData"": ["&_xlfn.TEXTJOIN(",",,FG_Symbol!$W$4:$W$304)&"]}" -> "wheelData": [3,3,10,10,7,7,4,4,6,6,9,9,2,9,9,10,10,9,9,8,8,0,0,7,7,3,3,10,10,9,9,10,10,7,7,9,9,7,7,0,9,9,7,7,9,9,4,4,10,10,11,11,9,9,4,4,9,9,7,7,9,9,4,4,7,7,8,8,3,3,9,9,7,7,9,9,7,7,3,3,9,9,10,10,9,9,7,7,3,3,2,2,10,10,11,11,5,5,7,7]} | I32: 0 | J32: =" ""wheelData"": ["&_xlfn.TEXTJOIN(",",,FG_Symbol!$AD$4:$AD$304)&"]}" -> "wheelData": [1,1,1,1,1,1,1,1,0,1,1,1,0,1,1,1,1,0,1,1,1,1,0,2,2,2,2,1,1,1,1,1,1,1,1,0,0,0,0,0,2,2,2,2,1,1,1,1,1,1,1,1,1,1,1,1,1,1,1,1,1,1,1,1,1,1,1,1,1,1,1,1,1,1,1,1,1,1,1,1,1,1,1,1,1,1,0,0,0,0,0,0,1,1,1,1,1,1,1,1]}
B33: 0 | C33: ,{ | I33: 0 | J33: ,{
B34: 0 | C34: "noWinIndex": [0], | I34: 0 | J34: "noWinIndex": [0],
B35: 0 | C35: =" ""wheelLength"": "&FG_Symbol!$H$16&"," -> "wheelLength": 100, | I35: 0 | J35: =C35 -> "wheelLength": 100,
B36: 0 | C36: =" ""wheelData"": ["&_xlfn.TEXTJOIN(",",,FG_Symbol!$X$4:$X$304)&"]}" -> "wheelData": [11,11,8,8,11,11,7,7,8,8,10,10,11,11,9,9,6,6,9,9,8,8,11,11,4,4,11,11,8,8,6,6,8,8,6,6,4,4,8,8,11,11,0,9,9,11,11,9,9,3,3,8,8,11,11,6,6,9,9,8,8,9,9,8,8,2,7,7,11,11,9,9,2,2,8,8,4,4,8,8,9,9,5,5,4,4,11,11,8,8,6,6,10,10,9,9,11,11,0,0]} | I36: 0 | J36: =" ""wheelData"": ["&_xlfn.TEXTJOIN(",",,FG_Symbol!$AE$4:$AE$304)&"]}" -> "wheelData": [1,1,1,1,1,1,1,1,1,1,1,1,1,1,1,1,1,1,1,1,1,1,1,1,1,1,1,1,1,1,1,1,1,1,1,1,1,1,0,0,0,0,0,2,2,2,2,1,1,1,1,1,1,1,1,1,1,1,1,1,1,0,1,1,1,0,1,1,0,0,0,0,0,0,1,1,1,1,1,1,1,1,1,1,1,1,1,1,1,1,1,1,1,1,0,1,1,1,1,0]}
B37: 0 | C37: ], | I37: 0 | J37: ],
B38: {=B12:B37+1} -> 1 | C38: [ | I38: {=I12:I37+1} -> 1 | J38: [
B39: 1 | C39: { | I39: 1 | J39: {
B40: 1 | C40: "noWinIndex": [0], | I40: 1 | J40: "noWinIndex": [0],
B41: 1 | C41: =" ""wheelLength"": "&'FG_Symbol (2)'!$C$16&"," -> "wheelLength": 100, | I41: 1 | J41: =C41 -> "wheelLength": 100,
B42: 1 | C42: =" ""wheelData"": ["&_xlfn.TEXTJOIN(",",,'FG_Symbol (2)'!$S$4:$S$304)&"]}" -> "wheelData": [9,9,11,11,4,4,6,6,10,10,11,11,5,5,8,8,2,2,10,10,11,11,7,7,9,9,11,11,4,4,7,7,9,9,11,11,4,4,2,2,10,10,11,11,9,9,11,11,4,4,7,7,10,10,3,2,2,10,10,11,11,7,7,10,10,6,6,10,10,11,11,5,5,2,8,8,7,7,8,8,3,3,5,5,7,7,6,6,10,10,11,11,5,5,8,8,10,10,8,8]} | I42: 1 | J42: =" ""wheelData"": ["&_xlfn.TEXTJOIN(",",,'FG_Symbol (2)'!$Z$4:$Z$304)&"]}" -> "wheelData": [1,1,1,1,1,1,1,1,1,1,1,1,1,1,1,1,1,1,1,1,1,1,1,1,1,1,1,1,1,1,1,1,1,1,1,1,1,1,1,1,1,1,1,1,1,1,1,1,1,1,1,1,1,1,1,1,1,1,1,1,1,1,1,1,1,1,1,1,1,1,1,1,1,1,1,1,1,1,1,1,1,1,1,1,1,1,1,1,1,1,1,1,1,1,1,1,1,1,1,1]}
B43: 1 | C43: ,{ | I43: 1 | J43: ,{
B44: 1 | C44: "noWinIndex": [0], | I44: 1 | J44: "noWinIndex": [0],
B45: 1 | C45: =" ""wheelLength"": "&'FG_Symbol (2)'!$D$16&"," -> "wheelLength": 100, | I45: 1 | J45: =C45 -> "wheelLength": 100,
...

Sheet NB_Flow
B2: # Storm of Seth 遊戲邏輯
B4: ## BaseGame (主遊戲)
B6: ### 如何決定盤面
B7: 1. **輪盤選擇**:
B8: - 從 base1、base2、base3 三組輪盤集合中選擇一組
B9: - 使用 `weight.cumulativeWeight(weight.weightBaseReelSet)` 根據權重來決定使用哪一組輪盤
B10: - 每組輪盤集合的選擇權重分配為：
B11: - base1
B12: - base2
B13: - base3
B14: - base4
B16: 2. **符號決定**:
... B120: 1. 若該次 FreeGame > 9000 * 押注或 FreeGame < 10 * 押注，則重抽 FreeGame 完整結果
B123: C1 Num. | C123: Base Game | D123: Free Game | F123: Description | G123: 4 | H123: 5 | I123: 6
B124: 3 | C124: 0 | D124: 5 | F124: Wild | G124: 0 | H124: 0 | I124: 0
B125: 4 | C125: 15 | D125: 5 | F125: Scatter | G125: 300 | H125: 500 | I125: 10000
B126: 5 | C126: 15 | D126: 5
B127: 6 | C127: 15 | D127: 5
C129: 在BG 4C1 pay 300 + 15次Free Spin
C130: 在BG 5C1 pay 500 + 15次Free Spin
C131: 在BG 6C1 pay 10000 + 15次Free Spin
C133: 在FG 3C1 5次Free Spin
C134: 在FG 4C1 pay 300 + 5次Free Spin
C135: 在FG 5C1 pay 500 + 5次Free Spin
C136: 在FG 6C1 pay 10000 + 5次Free Spin

Sheet Multiplier_Weight
B2: A | C2: Newbie | D2: Newbie | E2: Oldhand | F2: Oldhand | G2: Oldhand | H2: Oldhand
B3: Range | C3: Weight_NB_BG | D3: Weight_NB_FG | E3: Weight_NB_BG | F3: Weight_NB_FG | G3: Weight_BF_FG | H3: Weight_SF_FG
B4: (-1, 0] | C4: {=Multiplier_Weight_Newbie!L16:L80} -> 716089973 | D4: {=Multiplier_Weight_Newbie!L89:L152} -> 0 | E4: {=Multiplier_Weight_Oldhand!L16:L80} -> 719471124 | F4: {=Multiplier_Weight_Oldhand!L89:L152} -> 0 | G4: {=Multiplier_Weight_Oldhand!L159:L222} -> 0 | H4: {=_xlfn.ANCHORARRAY(Multiplier_Weight_Oldhand!L229)} -> 0
B5: (0, 1] | C5: 150413198 | D5: 0 | E5: 151113333 | F5: 0 | G5: 0 | H5: 0
B6: (1, 2] | C6: 54248599 | D6: 0 | E6: 54501112 | F6: 0 | G6: 0 | H6: 0
B7: (2, 3] | C7: 17724287 | D7: 0 | E7: 17806789 | F7: 0 | G7: 0 | H7: 0
B8: (3, 4] | C8: 12618997 | D8: 0 | E8: 12677735 | F8: 0 | G8: 0 | H8: 0
B9: (4, 5] | C9: 14755671 | D9: 0 | E9: 14824355 | F9: 0 | G9: 0 | H9: 0
B10: (5, 6] | C10: 12270945 | D10: 0 | E10: 12328063 | F10: 0 | G10: 0 | H10: 0
B11: (6, 7] | C11: 1699777 | D11: 0 | E11: 1707689 | F11: 0 | G11: 0 | H11: 0
B12: (7, 8] | C12: 1372633 | D12: 0 | E12: 1379023 | F12: 0 | G12: 0 | H12: 0
B13: (8, 9] | C13: 1238230 | D13: 0 | E13: 1243993 | F13: 0 | G13: 0 | H13: 0
B14: (9, 10] | C14: 1113887 | D14: 0 | E14: 1119072 | F14: 0 | G14: 0 | H14: 0
B15: (10, 15] | C15: 6052235 | D15: 0 | E15: 5438967 | F15: 38890097 | G15: 19716216 | H15: 0
B16: (15, 20] | C16: 2902448 | D16: 0 | E16: 1070357 | F16: 86411234 | G16: 81349051 | H16: 0
... B67: (100000, 9999999] | C67: 0 | D67: 0 | E67: 0 | F67: 0 | G67: 0 | H67: 0
B68: Free Game | C68: 3576446 | E68: 2222125

Sheet Multiplier_Weight_Newbie
A2: Threshold | B2: 1000000000
A3: Coin in | B3: =Overview!A12 -> 100
E4: 0.00017112
C5: RTP | E5: 0.647223 | F5: 0.017112
B6: Bet | C6: Base Game | D6: Free Game | E6: Total | F6: Hit Rate | G6: FG Period | H6: Avg Multi
A7: Normal Bet | B7: {=Overview!B12:B14} -> 1 | C7: =SUM(N16:N80) -> 0.68549637 | D7: =SUM(_xlfn.ANCHORARRAY(N89))*M80 -> 0.24452612 | E7: =SUM(C7:D7) -> 0.93002249 | F7: =M80 -> 0.003576446 | G7: =1/F7 -> 279.60719 | H7: =D7*G7 -> 68.371261
A8: Buy Feature | B8: 100
A9: Super Feature | B9: 500
A12: Base Game
A14: Simulator | B14: =10^8 -> 100000000 | H14: Calculate | P14: Compare
A15: Lower | B15: Upper | C15: Cnt | D15: Pay | E15: Hit Rate | F15: Avg. Multi. | H15: Range | I15: Fix Num | J15: Fix Rate | K15: Final Rate | L15: Weight | M15: Hit Rate | N15: Simulator RTP | O15: 1.05 | P15: 目前 | Q15: 競品 | R15: 差異
A16: -1 | B16: 0 | C16: {=Multiplier_Weight_Oldhand!C16:D79} -> 53951733 | D16: 0 | E16: {=_xlfn.LET(_xlpm.x, C16:C79, _xlpm.x/SUM(_xlpm.x))} -> 0.54156878 | F16: {=_xlfn.LET(_xlpm.x, D16:D82/C16:C82/B3, IF(ISERR(_xlpm.x), 0, _xlpm.x))} -> 0 | H16: ="("&$A16&", "&$B16&"]" -> (-1, 0] | I16: 1.36 | J16: {=E16:E80*I16:I80} -> 0.73653354 | K16: {=J16:J79/SUM(_xlfn.ANCHORARRAY(J16))} -> 0.71618876 | L16: =INT($B$2-SUM(_xlfn.ANCHORARRAY(L17))) -> 716089973 | M16: {=_xlfn.LET(_xlpm.x, L16:L80, _xlpm.x/SUM(_xlpm.x))} -> 0.71608997 | N16: {=M16:M80*F16:F80} -> 0 | O16: {=ROUND(O15*I16:I80, 2)} -> 1.43 | P16: {=M16:M79} -> 0.71608997 | Q16: 0.73158454 | R16: {=_xlfn.LET(_xlpm.x, Q16:Q79/M16:M79, IF(ISERR(_xlpm.x), 0, ROUND(_xlpm.x,2)))} -> 1.02
A17: 0 | B17: 1 | C17: 11945134 | D17: 660879425 | E17: 0.11990554 | F17: 0.55326246 | H17: ="("&$A17&", "&$B17&"]" -> (0, 1] | I17: 1.2900654 | J17: 0.15468599 | K17: 0.1504132 | L17: {=INT(K17:K80*$B$2)} -> 150413198 | M17: 0.1504132 | N17: 0.083217976 | O17: 1.35 | P17: 0.1504132 | Q17: 0.13579919 | R17: 0.9
A18: 1 | B18: 2 | C18: 6059424 | D18: 936595100 | E18: 0.060824643 | F18: 1.5456834 | H18: ="("&$A18&", "&$B18&"]" -> (1, 2] | I18: 0.91722102 | J18: 0.05578964 | K18: 0.0542486 | L18: 54248599 | M18: 0.054248599 | N18: 0.083851158 | O18: 0.96 | P18: 0.054248599 | Q18: 0.046629 | R18: 0.86
A19: 2 | B19: 3 | C19: 3590142 | D19: 911783495 | E19: 0.036037931 | F19: 2.5396864 | H19: ="("&$A19&", "&$B19&"]" -> (2, 3] | I19: 0.50579434 | J19: 0.018227782 | K19: 0.017724287 | L19: 17724287 | M19: 0.017724287 | N19: 0.045014131 | O19: 0.53 | P19: 0.017724287 | Q19: 0.022302529 | R19: 1.26
A20: 3 | B20: 4 | C20: 2476164 | D20: 896079365 | E20: 0.024855793 | F20: 3.6188207 | H20: ="("&$A20&", "&$B20&"]" -> (3, 4] | I20: 0.52211029 | J20: 0.012977465 | K20: 0.012618997 | L20: 12618997 | M20: 0.012618997 | N20: 0.045665888 | O20: 0.55 | P20: 0.012618997 | Q20: 0.015819895 | R20: 1.25
A21: 4 | B21: 5 | C21: 1559894 | D21: 724044715 | E21: 0.015658253 | F21: 4.6416277 | H21: ="("&$A21&", "&$B21&"]" -> (4, 5] | I21: 0.969127 | J21: 0.015174836 | K21: 0.014755671 | L21: 14755671 | M21: 0.014755671 | N21: 0.068490331 | O21: 1.02 | P21: 0.014755671 | Q21: 0.016012707 | R21: 1.09
A22: 5 | B22: 6 | C22: 1553649 | D22: 874821260 | E22: 0.015595566 | F22: 5.6307522 | H22: ="("&$A22&", "&$B22&"]" -> (5, 6] | I22: 0.809174 | J22: 0.012619526 | K22: 0.012270945 | L22: 12270945 | M22: 0.012270945 | N22: 0.069094651 | O22: 0.85 | P22: 0.012270945 | Q22: 0.013282794 | R22: 1.08
A23: 6 | B23: 7 | C23: 1002882 | D23: 660232270 | E23: 0.010066953 | F23: 6.5833495 | H23: ="("&$A23&", "&$B23&"]" -> (6, 7] | I23: 0.17364375 | J23: 0.0017480635 | K23: 0.0016997779 | L23: 1699777 | M23: 0.001699777 | N23: 0.011190226 | O23: 0.18 | P23: 0.001699777 | Q23: 0.001541177 | R23: 0.91
A24: 7 | B24: 8 | C24: 934459 | D24: 709283665 | E24: 0.0093801217 | F24: 7.5903134 | H24: ="("&$A24&", "&$B24&"]" -> (7, 8] | I24: 0.15049125 | J24: 0.0014116262 | K24: 0.0013726338 | L24: 1372633 | M24: 0.001372633 | N24: 0.010418715 | O24: 0.16 | P24: 0.001372633 | Q24: 0.001177802 | R24: 0.86
A25: 8 | B25: 9 | C25: 842960 | D25: 727119225 | E25: 0.0084616526 | F25: 8.6257856 | H25: ="("&$A25&", "&$B25&"]" -> (8, 9] | I25: 0.15049125 | J25: 0.0012734047 | K25: 0.0012382302 | L25: 1238230 | M25: 0.00123823 | N25: 0.010680707 | O25: 0.16 | P25: 0.00123823 | Q25: 0.001098453 | R25: 0.89
A26: 9 | B26: 10 | C26: 758310 | D26: 737465410 | E26: 0.0076119339 | F26: 9.7251178 | H26: ="("&$A26&", "&$B26&"]" -> (9, 10] | I26: 0.15049125 | J26: 0.0011455294 | K26: 0.0011138872 | L26: 1113887 | M26: 0.001113887 | N26: 0.010832682 | O26: 0.16 | P26: 0.001113887 | Q26: 0.00099536 | R26: 0.89
A27: 10 | B27: 15 | C27: 2590052 | D27: 3231669960 | E27: 0.025999004 | F27: 12.47724 | H27: ="("&$A27&", "&$B27&"]" -> (10, 15] | I27: 0.2394 | J27: 0.0062241615 | K27: 0.0060522355 | L27: 6052235 | M27: 0.006052235 | N27: 0.075515187 | O27: 0.25 | P27: 0.006052235 | Q27: 0.004708171 | R27: 0.78
A28: 15 | B28: 20 | C28: 1571483 | D28: 2763510455 | E28: 0.015774584 | F28: 17.585367 | H28: ="("&$A28&", "&$B28&"]" -> (15, 20] | I28: 0.189222 | J28: 0.0029848983 | K28: 0.0029024484 | L28: 2902448 | M28: 0.002902448 | N28: 0.051040612 | O28: 0.2 | P28: 0.002902448 | Q28: 0.002323036 | R28: 0.8
A29: 20 | B29: 25 | C29: 1160675 | D29: 2636526365 | E29: 0.011650883 | F29: 22.715458 | H29: ="("&$A29&", "&$B29&"]" -> (20, 25] | I29: 0.19 | J29: 0.0022136678 | K29: 0.0021525211 | L29: 2152521 | M29: 0.002152521 | N29: 0.048895499 | O29: 0.2 | P29: 0.002152521 | Q29: 0.00175918 | R29: 0.82
... A79: 100000 | B79: 9999999 | C79: 41 | D79: 506435290 | E79: 4.1155898e-07 | F79: 123520.8 | H79: ="("&$A79&", "&$B79&"]" -> (100000, 9999999] | I79: 0 | J79: 0 | K79: 0 | L79: 0 | M79: 0 | N79: 0 | O79: 0 | P79: 0 | Q79: 0 | R79: 0
A80: Free Game | C80: =E80*B14 -> 362500 | D80: =Multiplier_Weight_Oldhand!D80 -> 233603075 | E80: =Multiplier_Weight_Oldhand!E80 -> 0.003625 | F80: 6.4442228 | H80: Free Game | I80: 0.986606 | J80: 0.0035764468 | K80: =J80 -> 0.0035764468 | L80: 3576446 | M80: 0.003576446 | N80: 0.023047415 | O80: 1.04 | Q80: 0.003502411
A81: Buy Feature | C81: 10000000 | D81: =Multiplier_Weight_Oldhand!D81 -> 32893867050 | E81: =Multiplier_Weight_Oldhand!E81 -> 1 | F81: 32.893867 | H81: Buy Feature | M81: =E81 -> 1 | N81: =F81/#REF! -> #REF!
A82: Super Feature | C82: 10000000 | D82: =D81 -> 32893867050 | E82: =Multiplier_Weight_Oldhand!E82 -> 1 | F82: 32.893867 | H82: Buy Feature | M82: =E82 -> 1 | N82: =F82/#REF! -> #REF!
A85: Free Game
A87: Simulator | B87: 10000000 | H87: Calculate | P87: Compare
A88: Lower | B88: Upper | C88: Cnt | D88: Pay | E88: Hit Rate | F88: Avg. Multi. | H88: Range | I88: Fix Num | J88: Fix Rate | K88: Final Rate | L88: Weight | M88: Hit Rate | N88: Simulator RTP | O88: 0.95 | P88: 目前 | Q88: 競品 | R88: 差異
A89: -1 | B89: 0 | C89: {=Multiplier_Weight_Oldhand!C89:D152} -> 20 | D89: 0 | E89: {=_xlfn.LET(_xlpm.x, C89:C152, _xlpm.x/SUM(_xlpm.x))} -> 5.2798589e-05 | F89: {=_xlfn.LET(_xlpm.x, D89:D152/C89:C152/B3, IF(ISERR(_xlpm.x), 0, _xlpm.x))} -> 0 | H89: ="("&$A89&", "&$B89&"]" -> (-1, 0] | I89: 0 | J89: {=_xlfn.ANCHORARRAY(E89)*I89:I152} -> 0 | K89: {=J89:J152/SUM(_xlfn.ANCHORARRAY(J89))} -> 0 | L89: 0 | M89: {=_xlfn.LET(_xlpm.x, L89:L152, _xlpm.x/SUM(_xlpm.x))} -> 0 | N89: {=M89:M152*_xlfn.ANCHORARRAY(F89)} -> 0 | O89: {=ROUND(O88*I89:I152, 2)} -> 0 | P89: {=_xlfn.ANCHORARRAY(M89)} -> 0 | Q89: 0 | R89: {=_xlfn.LET(_xlpm.x, Q89:Q152/M89:M152, IF(ISERR(_xlpm.x), 0, ROUND(_xlpm.x,2)))} -> 0
A90: 0 | B90: 1 | C90: 156 | D90: 10705 | E90: 0.000411829 | F90: 0.68621795 | H90: ="("&$A90&", "&$B90&"]" -> (0, 1] | I90: 0 | J90: 0 | K90: 0 | L90: 0 | M90: 0 | N90: 0 | O90: 0 | P90: 0 | Q90: 0 | R90: 0
A91: 1 | B91: 2 | C91: 301 | D91: 48160 | E91: 0.00079461877 | F91: 1.6 | H91: ="("&$A91&", "&$B91&"]" -> (1, 2] | I91: 0 | J91: 0 | K91: 0 | L91: 0 | M91: 0 | N91: 0 | O91: 0 | P91: 0 | Q91: 0 | R91: 0
A92: 2 | B92: 3 | C92: 471 | D92: 120465 | E92: 0.0012434068 | F92: 2.5576433 | H92: ="("&$A92&", "&$B92&"]" -> (2, 3] | I92: 0 | J92: 0 | K92: 0 | L92: 0 | M92: 0 | N92: 0 | O92: 0 | P92: 0 | Q92: 0 | R92: 0
A93: 3 | B93: 4 | C93: 536 | D93: 190190 | E93: 0.0014150022 | F93: 3.5483209 | H93: ="("&$A93&", "&$B93&"]" -> (3, 4] | I93: 0 | J93: 0 | K93: 0 | L93: 0 | M93: 0 | N93: 0 | O93: 0 | P93: 0 | Q93: 0 | R93: 0
A94: 4 | B94: 5 | C94: 505 | D94: 229835 | E94: 0.0013331644 | F94: 4.5511881 | H94: ="("&$A94&", "&$B94&"]" -> (4, 5] | I94: 0 | J94: 0 | K94: 0 | L94: 0 | M94: 0 | N94: 0 | O94: 0 | P94: 0 | Q94: 0 | R94: 0
A95: 5 | B95: 6 | C95: 548 | D95: 301735 | E95: 0.0014466813 | F95: 5.5061131 | H95: ="("&$A95&", "&$B95&"]" -> (5, 6] | I95: 0 | J95: 0 | K95: 0 | L95: 0 | M95: 0 | N95: 0 | O95: 0 | P95: 0 | Q95: 0 | R95: 0
A96: 6 | B96: 7 | C96: 573 | D96: 374860 | E96: 0.0015126796 | F96: 6.5420593 | H96: ="("&$A96&", "&$B96&"]" -> (6, 7] | I96: 0 | J96: 0 | K96: 0 | L96: 0 | M96: 0 | N96: 0 | O96: 0 | P96: 0 | Q96: 0 | R96: 0
...

Sheet Multiplier_Weight_Oldhand
A2: Threshold | B2: 1000000000
A3: Coin in | B3: =Overview!A12 -> 100
C5: RTP
B6: Bet | C6: Base Game | D6: Free Game | E6: Total | F6: Hit Rate | G6: FG Period | H6: Avg Multi
A7: Normal Bet | B7: {=Overview!B12:B14} -> 1 | C7: =SUM(N16:N80) -> 0.71000054 | D7: =SUM(_xlfn.ANCHORARRAY(N89))*M80 -> 0.23004247 | E7: =SUM(C7:D7) -> 0.94004301 | F7: =M80 -> 0.002222125 | G7: =1/F7 -> 450.01969 | H7: =D7*G7 -> 103.52364
A8: Buy Feature | B8: 100 | C8: =N81 -> 0.032893867 | D8: =SUM(_xlfn.ANCHORARRAY(N159))/B8 -> 0.89210623 | E8: =SUM(C8:D8) -> 0.9250001 | F8: =E81 -> 1 | G8: =1/F8 -> 1 | H8: =D8*G8*B8 -> 89.210623 | I8: =SUM(M183:M222) -> 0.25439679
A9: Super Feature | B9: 500 | C9: =N82 -> 0.0065787734 | D9: =SUM(_xlfn.ANCHORARRAY(N229))/B9 -> 0.91842097 | E9: =SUM(C9:D9) -> 0.92499974 | F9: =F8 -> 1 | G9: =1/F9 -> 1 | H9: =D9*G9*B9 -> 459.21049 | I9: =SUM(M264:M292) -> 0.34867071
A12: Base Game
A14: Simulator | B14: =10^8 -> 100000000 | H14: Calculate | I14: 1 | P14: Compare | Q14: 1 | U14: 1 | V14: 2 | W14: 3 | X14: 4 | Z14: AB Test
A15: Lower | B15: Upper | C15: Cnt | D15: Pay | E15: Hit Rate | F15: Avg. Multi. | H15: Range | I15: Fix Num | J15: Fix Rate | K15: Final Rate | L15: Weight | M15: Hit Rate | N15: Simulator RTP | O15: 1.05 | P15: 目前 | Q15: 競品 | R15: 差異 | T15: Range | U15: 1.0.0.3 | V15: =Overview!B3 -> 3.0.0.1 | W15: 奧林帕斯 | X15: 糖果 | Z15: A版 | AA15: B版 | AB15: Weight A版 | AC15: Weight B版
A16: -1 | B16: 0 | C16: 53951733 | D16: 0 | E16: {=_xlfn.LET(_xlpm.x, C16:C79, _xlpm.x/SUM(_xlpm.x))} -> 0.54156878 | F16: {=_xlfn.LET(_xlpm.x, D16:D82/C16:C82/B3, IF(ISERR(_xlpm.x), 0, _xlpm.x))} -> 0 | H16: ="("&$A16&", "&$B16&"]" -> (-1, 0] | I16: 1.36 | J16: {=E16:E80*I16:I80} -> 0.73653354 | K16: {=J16:J79/SUM(_xlfn.ANCHORARRAY(J16))} -> 0.71952243 | L16: =INT($B$2-SUM(_xlfn.ANCHORARRAY(L17))) -> 719471124 | M16: {=_xlfn.LET(_xlpm.x, L16:L80, _xlpm.x/SUM(_xlpm.x))} -> 0.71947112 | N16: {=M16:M80*F16:F80} -> 0 | O16: =$O$15*I16 -> 1.428 | P16: {=M16:M79} -> 0.71947112 | Q16: {=CHOOSE(Q14, U16:U79,W16:W79,X16:X79)} -> 0.73388045 | R16: {=_xlfn.LET(_xlpm.x, Q16:Q79/M16:M79, IF(ISERR(_xlpm.x), 0, ROUND(_xlpm.x,2)))} -> 1.02 | T16: ="("&$A16&", "&$B16&"]" -> (-1, 0] | U16: 0.73388045 | V16: {=_xlfn.ANCHORARRAY(M16)} -> 0.71947112 | W16: 0.71481219 | X16: 0.56957507 | Z16: 1.36 | AA16: 1.36 | AB16: 719471124 | AC16: 719471124
A17: 0 | B17: 1 | C17: 11945134 | D17: 660879425 | E17: 0.11990554 | F17: 0.55326246 | H17: ="("&$A17&", "&$B17&"]" -> (0, 1] | I17: 1.2900654 | J17: 0.15468599 | K17: 0.15111333 | L17: {=INT(K17:K80*$B$2)} -> 151113333 | M17: 0.15111333 | N17: 0.083605335 | O17: =$O$15*I17 -> 1.3545687 | P17: 0.15111333 | Q17: 0.13623061 | R17: 0.9 | T17: ="("&$A17&", "&$B17&"]" -> (0, 1] | U17: 0.13623061 | V17: 0.15111333 | W17: 0.17448618 | X17: 0.22958295 | Z17: 1.2900654 | AA17: 1.2900654 | AB17: 151113333 | AC17: 151113333
A18: 1 | B18: 2 | C18: 6059424 | D18: 936595100 | E18: 0.060824643 | F18: 1.5456834 | H18: ="("&$A18&", "&$B18&"]" -> (1, 2] | I18: 0.91722102 | J18: 0.05578964 | K18: 0.054501113 | L18: 54501112 | M18: 0.054501112 | N18: 0.084241463 | O18: =$O$15*I18 -> 0.96308207 | P18: 0.054501112 | Q18: 0.046777134 | R18: 0.86 | T18: ="("&$A18&", "&$B18&"]" -> (1, 2] | U18: 0.046777134 | V18: 0.054501112 | W18: 0.056413891 | X18: 0.085959579 | Z18: 0.91722102 | AA18: 0.91722102 | AB18: 54501112 | AC18: 54501112
A19: 2 | B19: 3 | C19: 3590142 | D19: 911783495 | E19: 0.036037931 | F19: 2.5396864 | H19: ="("&$A19&", "&$B19&"]" -> (2, 3] | I19: 0.50579434 | J19: 0.018227782 | K19: 0.017806789 | L19: 17806789 | M19: 0.017806789 | N19: 0.045223661 | O19: =$O$15*I19 -> 0.53108406 | P19: 0.017806789 | Q19: 0.022373381 | R19: 1.26 | T19: ="("&$A19&", "&$B19&"]" -> (2, 3] | U19: 0.022373381 | V19: 0.017806789 | W19: 0.021261517 | X19: 0.03875045 | Z19: 0.50579434 | AA19: 0.50579434 | AB19: 17806789 | AC19: 17806789
A20: 3 | B20: 4 | C20: 2476164 | D20: 896079365 | E20: 0.024855793 | F20: 3.6188207 | H20: ="("&$A20&", "&$B20&"]" -> (3, 4] | I20: 0.52211029 | J20: 0.012977465 | K20: 0.012677735 | L20: 12677735 | M20: 0.012677735 | N20: 0.04587845 | O20: =$O$15*I20 -> 0.5482158 | P20: 0.012677735 | Q20: 0.015870153 | R20: 1.25 | T20: ="("&$A20&", "&$B20&"]" -> (3, 4] | U20: 0.015870153 | V20: 0.012677735 | W20: 0.013465627 | X20: 0.032026186 | Z20: 0.52211029 | AA20: 0.52211029 | AB20: 12677735 | AC20: 12677735
A21: 4 | B21: 5 | C21: 1559894 | D21: 724044715 | E21: 0.015658253 | F21: 4.6416277 | H21: ="("&$A21&", "&$B21&"]" -> (4, 5] | I21: 0.969127 | J21: 0.015174836 | K21: 0.014824355 | L21: 14824355 | M21: 0.014824355 | N21: 0.068809136 | O21: =$O$15*I21 -> 1.0175833 | P21: 0.014824355 | Q21: 0.016063577 | R21: 1.08 | T21: ="("&$A21&", "&$B21&"]" -> (4, 5] | U21: 0.016063577 | V21: 0.014824355 | W21: 0.0066619419 | X21: 0.01498512 | Z21: 0.969127 | AA21: 0.969127 | AB21: 14824355 | AC21: 14824355
A22: 5 | B22: 6 | C22: 1553649 | D22: 874821260 | E22: 0.015595566 | F22: 5.6307522 | H22: ="("&$A22&", "&$B22&"]" -> (5, 6] | I22: 0.809174 | J22: 0.012619526 | K22: 0.012328063 | L22: 12328063 | M22: 0.012328063 | N22: 0.069416268 | O22: =$O$15*I22 -> 0.8496327 | P22: 0.012328063 | Q22: 0.013324992 | R22: 1.08 | T22: ="("&$A22&", "&$B22&"]" -> (5, 6] | U22: 0.013324992 | V22: 0.012328063 | W22: 0.0036853296 | X22: 0.008603128 | Z22: 0.809174 | AA22: 0.809174 | AB22: 12328063 | AC22: 12328063
A23: 6 | B23: 7 | C23: 1002882 | D23: 660232270 | E23: 0.010066953 | F23: 6.5833495 | H23: ="("&$A23&", "&$B23&"]" -> (6, 7] | I23: 0.17364375 | J23: 0.0017480635 | K23: 0.00170769 | L23: 1707689 | M23: 0.001707689 | N23: 0.011242314 | O23: =$O$15*I23 -> 0.18232594 | P23: 0.001707689 | Q23: 0.001546074 | R23: 0.91 | T23: ="("&$A23&", "&$B23&"]" -> (6, 7] | U23: 0.001546074 | V23: 0.001707689 | W23: 0.0015591779 | X23: 0.005229215 | Z23: 0.17364375 | AA23: 0.17364375 | AB23: 1707689 | AC23: 1707689
A24: 7 | B24: 8 | C24: 934459 | D24: 709283665 | E24: 0.0093801217 | F24: 7.5903134 | H24: ="("&$A24&", "&$B24&"]" -> (7, 8] | I24: 0.15049125 | J24: 0.0014116262 | K24: 0.0013790231 | L24: 1379023 | M24: 0.001379023 | N24: 0.010467217 | O24: =$O$15*I24 -> 0.15801581 | P24: 0.001379023 | Q24: 0.001181544 | R24: 0.86 | T24: ="("&$A24&", "&$B24&"]" -> (7, 8] | U24: 0.001181544 | V24: 0.001379023 | W24: 0.0011339476 | X24: 0.003424839 | Z24: 0.15049125 | AA24: 0.15049125 | AB24: 1379023 | AC24: 1379023
A25: 8 | B25: 9 | C25: 842960 | D25: 727119225 | E25: 0.0084616526 | F25: 8.6257856 | H25: ="("&$A25&", "&$B25&"]" -> (8, 9] | I25: 0.15049125 | J25: 0.0012734047 | K25: 0.0012439939 | L25: 1243993 | M25: 0.001243993 | N25: 0.010730417 | O25: =$O$15*I25 -> 0.15801581 | P25: 0.001243993 | Q25: 0.001101943 | R25: 0.89 | T25: ="("&$A25&", "&$B25&"]" -> (8, 9] | U25: 0.001101943 | V25: 0.001243993 | W25: 0.00056697378 | X25: 0.001936256 | Z25: 0.15049125 | AA25: 0.15049125 | AB25: 1243993 | AC25: 1243993
A26: 9 | B26: 10 | C26: 758310 | D26: 737465410 | E26: 0.0076119339 | F26: 9.7251178 | H26: ="("&$A26&", "&$B26&"]" -> (9, 10] | I26: 0.15049125 | J26: 0.0011455294 | K26: 0.0011190721 | L26: 1119072 | M26: 0.001119072 | N26: 0.010883107 | O26: =$O$15*I26 -> 0.15801581 | P26: 0.001119072 | Q26: 0.000998522 | R26: 0.89 | T26: ="("&$A26&", "&$B26&"]" -> (9, 10] | U26: 0.000998522 | V26: 0.001119072 | W26: 0.0019844082 | X26: 0.001804585 | Z26: 0.15049125 | AA26: 0.15049125 | AB26: 1119072 | AC26: 1119072
A27: 10 | B27: 15 | C27: 2590052 | D27: 3231669960 | E27: 0.025999004 | F27: 12.47724 | G27: =SUM($L$16:L27) -> 993611255 | H27: ="("&$A27&", "&$B27&"]" -> (10, 15] | I27: 0.214145 | J27: 0.0055675566 | K27: 0.0054389674 | L27: 5438967 | M27: 0.005438967 | N27: 0.067863295 | O27: =$O$15*I27 -> 0.22485225 | P27: 0.005438967 | Q27: 0.004723128 | R27: 0.87 | T27: ="("&$A27&", "&$B27&"]" -> (10, 15] | U27: 0.004723128 | V27: 0.005438967 | W27: 0.0034018427 | X27: 0.005063385 | Z27: 0.214145 | AA27: 0.214145 | AB27: 5438967 | AC27: 5438967
A28: 15 | B28: 20 | C28: 1571483 | D28: 2763510455 | E28: 0.015774584 | F28: 17.585367 | G28: =SUM($L$16:L28) -> 994681612 | H28: ="("&$A28&", "&$B28&"]" -> (15, 20] | I28: 0.0694575 | J28: 0.0010956632 | K28: 0.0010703575 | L28: 1070357 | M28: 0.001070357 | N28: 0.01882262 | O28: =$O$15*I28 -> 0.072930375 | P28: 0.001070357 | Q28: 0.000942471 | R28: 0.88 | T28: ="("&$A28&", "&$B28&"]" -> (15, 20] | U28: 0.000942471 | V28: 0.001070357 | W28: 0.00028348689 | X28: 0.00049189 | Z28: 0.0694575 | AA28: 0.0694575 | AB28: 1070357 | AC28: 1070357
A29: 20 | B29: 25 | C29: 1160675 | D29: 2636526365 | E29: 0.011650883 | F29: 22.715458 | G29: =SUM($L$16:L29) -> 995472162 | H29: ="("&$A29&", "&$B29&"]" -> (20, 25] | I29: 0.0694575 | J29: 0.00080924123 | K29: 0.00079055085 | L29: 790550 | M29: 0.00079055 | N29: 0.017957705 | O29: =$O$15*I29 -> 0.072930375 | P29: 0.00079055 | Q29: 0.000713326 | R29: 0.9 | T29: ="("&$A29&", "&$B29&"]" -> (20, 25] | U29: 0.000713326 | V29: 0.00079055 | W29: 0.00014174344 | X29: 0.000291507 | Z29: 0.0694575 | AA29: 0.0694575 | AB29: 790550 | AC29: 790550
A30: 25 | B30: 30 | C30: 954496 | D30: 2617421805 | E30: 0.0095812536 | F30: 27.42203 | G30: =SUM($L$16:L30) -> 996122281 | H30: ="("&$A30&", "&$B30&"]" -> (25, 30] | I30: 0.0694575 | J30: 0.00066548992 | K30: 0.00065011965 | L30: 650119 | M30: 0.000650119 | N30: 0.017827583 | O30: =$O$15*I30 -> 0.072930375 | P30: 0.000650119 | Q30: 0.000603455 | R30: 0.93 | T30: ="("&$A30&", "&$B30&"]" -> (25, 30] | U30: 0.000603455 | V30: 0.000650119 | W30: 0.00014174344 | X30: 0.000275902 | Z30: 0.0694575 | AA30: 0.0694575 | AB30: 650119 | AC30: 650119
A31: 30 | B31: 35 | C31: 602324 | D31: 1967658950 | E31: 0.0060461427 | F31: 32.667783 | H31: ="("&$A31&", "&$B31&"]" -> (30, 35] | I31: 0.09482 | J31: 0.00057329525 | K31: 0.00056005432 | L31: 560054 | M31: 0.000560054 | N31: 0.018295722 | O31: =$O$15*I31 -> 0.099561 | P31: 0.000560054 | Q31: 0.000494072 | R31: 0.88 | T31: ="("&$A31&", "&$B31&"]" -> (30, 35] | U31: 0.000494072 | V31: 0.000560054 | W31: 0 | X31: 0 | Z31: 0.09482 | AA31: 0.09482 | AB31: 560054 | AC31: 560054
A32: 35 | B32: 40 | C32: 593397 | D32: 2245299070 | E32: 0.0059565332 | F32: 37.838059 | H32: ="("&$A32&", "&$B32&"]" -> (35, 40] | I32: 0.01 | J32: 5.9565332e-05 | K32: 5.8189601e-05 | L32: 58189 | M32: 5.8189e-05 | N32: 0.0022017588 | O32: =$O$15*I32 -> 0.0105 | P32: 5.8189e-05 | Q32: 6.7206e-05 | R32: 1.15 | T32: ="("&$A32&", "&$B32&"]" -> (35, 40] | U32: 6.7206e-05 | V32: 5.8189e-05 | W32: 0 | X32: 0 | Z32: 0.01 | AA32: 0.01 | AB32: 58189 | AC32: 58189
A33: 40 | B33: 45 | C33: 442915 | D33: 1884995925 | E33: 0.0044459913 | F33: 42.558864 | H33: ="("&$A33&", "&$B33&"]" -> (40, 45] | I33: 0.01 | J33: 4.4459913e-05 | K33: 4.3433059e-05 | L33: 43433 | M33: 4.3433e-05 | N33: 0.0018484591 | O33: =$O$15*I33 -> 0.0105 | P33: 4.3433e-05 | Q33: 5.1912e-05 | R33: 1.2 | T33: ="("&$A33&", "&$B33&"]" -> (40, 45] | U33: 5.1912e-05 | V33: 4.3433e-05 | W33: 0 | X33: 0 | Z33: 0.01 | AA33: 0.01 | AB33: 43433 | AC33: 43433
A34: 45 | B34: 50 | C34: 392626 | D34: 1889578815 | E34: 0.0039411891 | F34: 48.126686 | H34: ="("&$A34&", "&$B34&"]" -> (45, 50] | I34: 0.01 | J34: 3.9411891e-05 | K34: 3.8501627e-05 | L34: 38501 | M34: 3.8501e-05 | N34: 0.0018529255 | O34: =$O$15*I34 -> 0.0105 | P34: 3.8501e-05 | Q34: 3.9448e-05 | R34: 1.02 | T34: ="("&$A34&", "&$B34&"]" -> (45, 50] | U34: 3.9448e-05 | V34: 3.8501e-05 | W34: 0 | X34: 0 | Z34: 0.01 | AA34: 0.01 | AB34: 38501 | AC34: 38501
A35: 50 | B35: 60 | C35: 631386 | D35: 3453044240 | E35: 0.0063378677 | F35: 54.689908 | H35: ="("&$A35&", "&$B35&"]" -> (50, 60] | I35: 0.01 | J35: 6.3378677e-05 | K35: 6.1914872e-05 | L35: 61914 | M35: 6.1914e-05 | N35: 0.003386071 | O35: =$O$15*I35 -> 0.0105 | P35: 6.1914e-05 | Q35: 4.8644e-05 | R35: 0.79 | T35: ="("&$A35&", "&$B35&"]" -> (50, 60] | U35: 4.8644e-05 | V35: 6.1914e-05 | W35: 0 | X35: 0 | Z35: 0.01 | AA35: 0.01 | AB35: 61914 | AC35: 61914
A36: 60 | B36: 70 | C36: 516477 | D36: 3344835120 | E36: 0.0051844084 | F36: 64.762518 | H36: ="("&$A36&", "&$B36&"]" -> (60, 70] | I36: 0.01 | J36: 5.1844084e-05 | K36: 5.0646684e-05 | L36: 50646 | M36: 5.0646e-05 | N36: 0.0032799625 | O36: =$O$15*I36 -> 0.0105 | P36: 5.0646e-05 | Q36: 3.595e-05 | R36: 0.71 | T36: ="("&$A36&", "&$B36&"]" -> (60, 70] | U36: 3.595e-05 | V36: 5.0646e-05 | W36: 0 | X36: 0 | Z36: 0.01 | AA36: 0.01 | AB36: 50646 | AC36: 50646
A37: 70 | B37: 80 | C37: 468872 | D37: 3552163945 | E37: 0.0047065483 | F37: 75.75978 | H37: ="("&$A37&", "&$B37&"]" -> (70, 80] | I37: 0.01 | J37: 4.7065483e-05 | K37: 4.597845e-05 | L37: 45978 | M37: 4.5978e-05 | N37: 0.0034832832 | O37: =$O$15*I37 -> 0.0105 | P37: 4.5978e-05 | Q37: 3.3654e-05 | R37: 0.73 | T37: ="("&$A37&", "&$B37&"]" -> (70, 80] | U37: 3.3654e-05 | V37: 4.5978e-05 | W37: 0 | X37: 0 | Z37: 0.01 | AA37: 0.01 | AB37: 45978 | AC37: 45978
A38: 80 | B38: 90 | C38: 313108 | D38: 2661579535 | E38: 0.0031429856 | F38: 85.005159 | H38: ="("&$A38&", "&$B38&"]" -> (80, 90] | I38: 0.1 | J38: 0.00031429856 | K38: 0.00030703946 | L38: 307039 | M38: 0.000307039 | N38: 0.026099899 | O38: =$O$15*I38 -> 0.105 | P38: 0.000307039 | Q38: 0.000320946 | R38: 1.05 | T38: ="("&$A38&", "&$B38&"]" -> (80, 90] | U38: 0.000320946 | V38: 0.000307039 | W38: 0 | X38: 0 | Z38: 0.1 | AA38: 0.1 | AB38: 307039 | AC38: 307039
A39: 90 | B39: 100 | C39: 242632 | D39: 2320117030 | E39: 0.0024355458 | F39: 95.622879 | H39: ="("&$A39&", "&$B39&"]" -> (90, 100] | I39: 0.01 | J39: 2.4355458e-05 | K39: 2.379294e-05 | L39: 23792 | M39: 2.3792e-05 | N39: 0.0022750595 | O39: 0.01 | P39: 2.3792e-05 | Q39: 1.8359e-05 | R39: 0.77 | T39: ="("&$A39&", "&$B39&"]" -> (90, 100] | U39: 1.8359e-05 | V39: 2.3792e-05 | W39: 0 | X39: 0 | Z39: 0.01 | AA39: 0.01 | AB39: 23792 | AC39: 23792
A40: 100 | B40: 120 | C40: 437236 | D40: 4812572280 | E40: 0.0043889854 | F40: 110.06807 | H40: ="("&$A40&", "&$B40&"]" -> (100, 120] | I40: 0.055 | J40: 0.0002413942 | K40: 0.00023581891 | L40: 235818 | M40: 0.000235818 | N40: 0.025956032 | O40: =$O$15*I40 -> 0.05775 | P40: 0.000235818 | Q40: 0.000252204 | R40: 1.07 | T40: ="("&$A40&", "&$B40&"]" -> (100, 120] | U40: 0.000252204 | V40: 0.000235818 | W40: 0 | X40: 0 | Z40: 0.055 | AA40: 0.055 | AB40: 235818 | AC40: 235818
A41: 120 | B41: 140 | C41: 411109 | D41: 5297759450 | E41: 0.0041267219 | F41: 128.86508 | H41: ="("&$A41&", "&$B41&"]" -> (120, 140] | I41: 0.01 | J41: 4.1267219e-05 | K41: 4.0314104e-05 | L41: 40314 | M41: 4.0314e-05 | N41: 0.0051950669 | O41: 0.01 | P41: 4.0314e-05 | Q41: 3.3536e-05 | R41: 0.83 | T41: ="("&$A41&", "&$B41&"]" -> (120, 140] | U41: 3.3536e-05 | V41: 4.0314e-05 | W41: 0 | X41: 0 | Z41: 0.01 | AA41: 0.01 | AB41: 40314 | AC41: 40314
A42: 140 | B42: 160 | C42: 281540 | D42: 4244782625 | E42: 0.0028261052 | F42: 150.77014 | H42: ="("&$A42&", "&$B42&"]" -> (140, 160] | I42: 0.01 | J42: 2.8261052e-05 | K42: 2.760833e-05 | L42: 27608 | M42: 2.7608e-05 | N42: 0.0041624621 | O42: 0.01 | P42: 2.7608e-05 | Q42: 1.872e-05 | R42: 0.68 | T42: ="("&$A42&", "&$B42&"]" -> (140, 160] | U42: 1.872e-05 | V42: 2.7608e-05 | W42: 0 | X42: 0 | Z42: 0.01 | AA42: 0.01 | AB42: 27608 | AC42: 27608
A43: 160 | B43: 180 | C43: 222436 | D43: 3786636560 | E43: 0.0022328179 | F43: 170.23488 | H43: ="("&$A43&", "&$B43&"]" -> (160, 180] | I43: 0.01 | J43: 2.2328179e-05 | K43: 2.1812483e-05 | L43: 21812 | M43: 2.1812e-05 | N43: 0.0037131632 | O43: 0.01 | P43: 2.1812e-05 | Q43: 1.4365e-05 | R43: 0.66 | T43: ="("&$A43&", "&$B43&"]" -> (160, 180] | U43: 1.4365e-05 | V43: 2.1812e-05 | W43: 0 | X43: 0 | Z43: 0.01 | AA43: 0.01 | AB43: 21812 | AC43: 21812
