Workbook

Sheet Revision History
B2: 版號 | C2: 日期 | D2: 修改人 | E2: 修改內容 | F2: 備註
B3: 2.01 | C3: 45293 | D3: Karry | E3: 定版，自Bet/Currency 改版，使設定更加簡便 - 所有 SLOT 使用相同設定 - 所有 賓果 使用相同設定 - 新增幣別 MYRC
B4: 2.02 | C4: 45294 | D4: Karry | E4: 改變名稱 將 賓果 - 10分4卡、賓果 - 10分20卡 改為 賓果 - 1分4卡、賓果 - 1分20卡
B5: 2.03 | C5: 45310 | D5: Karry | E5: 新增幣別 XSD
B6: 2.04 | C6: 45323 | D6: Karry | E6: 新增幣別 DZD、MAD、FRF、GHS
B7: 2.05 | C7: 45338 | D7: Karry | E7: 刪除100 - 彩金、150 - 彩金頁籤 編輯總表中被影響到的遊戲，改為使用對應分數的幣別設定
B8: 2.06 | C8: 45349 | D8: Karry | E8: 編輯100、150頁面中的XSD倍數設定 改為使用30組中的第1~第20組
B9: 2.07 | C9: 45370 | D9: Karry | E9: -在總表新增1040、1041、1042 -因應1041幣別將特規處理，新增1041所使用的幣別頁籤
B10: 2.08 | C10: 45385 | D10: Karry | E10: 編輯100、150頁面中的XSD倍數設定 改回2.03~2.05時期的設定
B11: 2.09 | C11: 45418 | D11: Karry | E11: 編輯100、150 NGN 倍數組數
B12: 2.10 | C12: 45440 | D12: Karry | E12: 修改150頁籤中的人民幣所選擇的其中幾組倍數設定，刪除5、8，新增25、26
B13: 2.11 | C13: 45449 | D13: Karry | E13: 在總表新增1043、1044、1045
B14: 2.12 | C14: 45450 | D14: Karry | E14: - 新增88頁籤供1045專案使用 - 新增幣別 RC
B15: 2.13 | C15: 45454 | D15: Karry | E15: 新增幣別 KBB
B16: 2.14 | C16: 45456 | D16: Karry | E16: 修正幣別 RC幣 為 RCC幣
B17: 2.15 | C17: 45474 | D17: Karry | E17: - 因應需求調整幣別 KBB 選用的 Denom 以及 20組押注組合 (除了魚機以外都有改動) - 調整IDRO 選用的第一組押注設定 - 新增 1043 的頁籤
B18: 2.16 | C18: 45485 | D18: Karry | E18: 新增幣別 XSMY

Sheet 總表
A1: 專案代號 | B1: 類別 | D1: 快速查找(請在下方欄位輸入專案代號)
A2: 1001 | B2: 150 | D2: 1043
A3: 1002 | B3: 150 | D3: =IF(ISNA(VLOOKUP(D2,$A:$B,2,FALSE)),"專案代號輸入錯誤",VLOOKUP(D2,$A:$B,2,FALSE)) -> 1043
A4: 1003 | B4: 100
A5: 1004 | B5: 100
A6: 1005 | B6: 100
A7: 1006
A8: 1007
A9: 1008 | B9: 150
A10: 1009 | B10: 150
A11: 1010 | B11: 100
A12: 1011 | B12: 100 | D12: 專案類別整理
A13: 1012 | B13: 150 | D13: 100 | E13: 100與150是相同設定
A14: 1013 | B14: 150 | D14: 150
A15: 1014 | B15: 150 | D15: 魚機
A16: 1015 | B16: 100 | D16: 賓果 - 1分4卡 | E16: 賓果 - 1分4卡與賓果 - 1分20卡是相同設定
A17: 1016 | B17: 150 | D17: 賓果 - 1分20卡
A18: 1017 | B18: 100 | D18: JHA4001
A19: 1018 | B19: 100 | D19: JHA4002
A20: 1019 | B20: 100 | D20: JHA4003
A21: 1020 | B21: 100 | D21: JHB3011
A22: 1021 | B22: 100 | D22: 88
A23: 1022 | B23: 100
A24: 1023 | B24: 100
A25: 1024 | B25: 100
A26: 1025 | B26: 150
A27: 1026 | B27: 100
A28: 1027 | B28: 150
A29: 1028 | B29: 150
A30: 1029 | B30: 100
A31: 1030 | B31: 100
A32: 1031 | B32: 100
A33: 1032 | B33: 100
A34: 1033 | B34: 150
... A39: 1038 | B39: 100
A40: 1039 | B40: 100
A41: 1040 | B41: 100
A42: 1041 | B42: 1041
A43: 1042 | B43: 100
A44: 1043 | B44: 1043
...

Sheet 100
C1: 最小押分 | D1: 100 | E1: 倍數 設定 | F1: 1 | G1: 2 | H1: 3 | I1: 4 | J1: 5 | K1: 6 | L1: 7 | M1: 8 | N1: 9 | O1: 10 | P1: 11 | Q1: 12 | R1: 13 | S1: 14 | T1: 15 | U1: 16 | V1: 17 | W1: 18 | X1: 19 | Y1: 20 | Z1: 21 | AA1: 22 | AB1: 23 | AC1: 24 | AD1: 25 | AE1: 26 | AF1: 27 | AG1: 28 | AH1: 29 | AI1: 30
F2: 1 | G2: 2 | H2: 5 | I2: 10 | J2: 12 | K2: 15 | L2: 20 | M2: 25 | N2: 30 | O2: 35 | P2: 40 | Q2: 45 | R2: 50 | S2: 60 | T2: 70 | U2: 80 | V2: 90 | W2: 100 | X2: 150 | Y2: 200 | Z2: 300 | AA2: 500 | AB2: 1000 | AC2: 1500 | AD2: 3000 | AE2: 5000 | AF2: 7500 | AG2: 10000 | AH2: 15000 | AI2: 25000
A5: 貨幣簡稱 | B5: 貨幣符號 | C5: 中文名稱 | D5: 貨幣轉換 | E5: Denom | F5: 第 1 組 | G5: 第 2 組 | H5: 第 3 組 | I5: 第 4 組 | J5: 第 5 組 | K5: 第 6 組 | L5: 第 7 組 | M5: 第 8 組 | N5: 第 9 組 | O5: 第 10 組 | P5: 第 11 組 | Q5: 第 12 組 | R5: 第 13 組 | S5: 第 14 組 | T5: 第 15 組 | U5: 第 16 組 | V5: 第 17 組 | W5: 第 18 組 | X5: 第 19 組 | Y5: 第 20 組 | AA5: 顯示倍數組別
A6: ='試算-SLOT'!A6 -> THB | B6: ='試算-SLOT'!B6 -> ฿ | C6: ='試算-SLOT'!C6 -> 泰銖 | D6: =IF('試算-SLOT'!D6=1,"",'試算-SLOT'!D6) | E6: ='試算-SLOT'!G6 -> 0.002 | F6: 3 | G6: 4 | H6: 6 | I6: 7 | J6: 8 | K6: 9 | L6: 11 | M6: 13 | N6: 14 | O6: 16 | P6: 18 | Q6: 19 | R6: 20 | S6: 21 | T6: 22 | U6: 23 | V6: 24 | W6: 25 | X6: 26 | Y6: 27
A7: ='試算-SLOT'!A7 -> HKD | B7: ='試算-SLOT'!B7 -> HK$ | C7: ='試算-SLOT'!C7 -> 港幣 | D7: =IF('試算-SLOT'!D7=1,"",'試算-SLOT'!D7) | E7: ='試算-SLOT'!G7 -> 0.002 | F7: 1 | G7: 2 | H7: 3 | I7: 4 | J7: 5 | K7: 6 | L7: 7 | M7: 8 | N7: 9 | O7: 11 | P7: 13 | Q7: 14 | R7: 16 | S7: 18 | T7: 19 | U7: 20 | V7: 21 | W7: 22 | X7: 23 | Y7: 24
A8: ='試算-SLOT'!A8 -> INR | B8: ='試算-SLOT'!B8 -> ₹ | C8: ='試算-SLOT'!C8 -> 印度盧比 | D8: =IF('試算-SLOT'!D8=1,"",'試算-SLOT'!D8) | E8: ='試算-SLOT'!G8 -> 0.002 | F8: 4 | G8: 6 | H8: 7 | I8: 9 | J8: 11 | K8: 13 | L8: 14 | M8: 16 | N8: 18 | O8: 19 | P8: 20 | Q8: 21 | R8: 22 | S8: 23 | T8: 24 | U8: 25 | V8: 26 | W8: 27 | X8: 28 | Y8: 29
A9: ='試算-SLOT'!A9 -> IDR | B9: ='試算-SLOT'!B9 -> Rp | C9: ='試算-SLOT'!C9 -> 印尼盧比(K) | D9: =IF('試算-SLOT'!D9=1,"",'試算-SLOT'!D9) -> 1000 | E9: ='試算-SLOT'!G9 -> 0.002 | F9: 2 | G9: 3 | H9: 4 | I9: 5 | J9: 6 | K9: 7 | L9: 8 | M9: 9 | N9: 11 | O9: 13 | P9: 14 | Q9: 16 | R9: 18 | S9: 19 | T9: 20 | U9: 21 | V9: 22 | W9: 23 | X9: 24 | Y9: 25
A10: ='試算-SLOT'!A10 -> VND | B10: ='試算-SLOT'!B10 -> ₫ | C10: ='試算-SLOT'!C10 -> 越南盾(K) | D10: =IF('試算-SLOT'!D10=1,"",'試算-SLOT'!D10) -> 1000 | E10: ='試算-SLOT'!G10 -> 0.002 | F10: 3 | G10: 4 | H10: 5 | I10: 6 | J10: 7 | K10: 8 | L10: 9 | M10: 11 | N10: 13 | O10: 14 | P10: 16 | Q10: 18 | R10: 19 | S10: 20 | T10: 21 | U10: 22 | V10: 23 | W10: 24 | X10: 25 | Y10: 26
A11: ='試算-SLOT'!A11 -> MYR | B11: ='試算-SLOT'!B11 -> RM | C11: ='試算-SLOT'!C11 -> 馬來西亞令吉 | D11: =IF('試算-SLOT'!D11=1,"",'試算-SLOT'!D11) | E11: ='試算-SLOT'!G11 -> 0.002 | F11: 1 | G11: 2 | H11: 3 | I11: 4 | J11: 5 | K11: 6 | L11: 7 | M11: 8 | N11: 9 | O11: 10 | P11: 11 | Q11: 13 | R11: 14 | S11: 16 | T11: 18 | U11: 19 | V11: 20 | W11: 21 | X11: 22 | Y11: 23
A12: ='試算-SLOT'!A12 -> SGD | B12: ='試算-SLOT'!B12 -> S$ | C12: ='試算-SLOT'!C12 -> 新加坡幣 | D12: =IF('試算-SLOT'!D12=1,"",'試算-SLOT'!D12) | E12: ='試算-SLOT'!G12 -> 0.002 | F12: 1 | G12: 2 | H12: 3 | I12: 4 | J12: 5 | K12: 6 | L12: 7 | M12: 8 | N12: 9 | O12: 10 | P12: 11 | Q12: 12 | R12: 13 | S12: 14 | T12: 15 | U12: 16 | V12: 17 | W12: 18 | X12: 19 | Y12: 20
A13: ='試算-SLOT'!A13 -> USD | B13: ='試算-SLOT'!B13 -> $ | C13: ='試算-SLOT'!C13 -> 美元 | D13: =IF('試算-SLOT'!D13=1,"",'試算-SLOT'!D13) | E13: ='試算-SLOT'!G13 -> 0.002 | F13: 1 | G13: 2 | H13: 3 | I13: 4 | J13: 5 | K13: 6 | L13: 7 | M13: 8 | N13: 9 | O13: 10 | P13: 11 | Q13: 12 | R13: 13 | S13: 14 | T13: 15 | U13: 16 | V13: 17 | W13: 18 | X13: 19 | Y13: 20
A14: ='試算-SLOT'!A14 -> BDT | B14: ='試算-SLOT'!B14 -> ৳ | C14: ='試算-SLOT'!C14 -> 孟加拉塔卡 | D14: =IF('試算-SLOT'!D14=1,"",'試算-SLOT'!D14) | E14: ='試算-SLOT'!G14 -> 0.002 | F14: 4 | G14: 6 | H14: 7 | I14: 9 | J14: 11 | K14: 13 | L14: 14 | M14: 16 | N14: 18 | O14: 19 | P14: 20 | Q14: 21 | R14: 22 | S14: 23 | T14: 24 | U14: 25 | V14: 26 | W14: 27 | X14: 28 | Y14: 29
A15: ='試算-SLOT'!A15 -> PKR | B15: ='試算-SLOT'!B15 -> ₨ | C15: ='試算-SLOT'!C15 -> 巴基斯坦盧比 | D15: =IF('試算-SLOT'!D15=1,"",'試算-SLOT'!D15) | E15: ='試算-SLOT'!G15 -> 0.01 | F15: 3 | G15: 4 | H15: 6 | I15: 7 | J15: 9 | K15: 11 | L15: 13 | M15: 14 | N15: 16 | O15: 18 | P15: 19 | Q15: 20 | R15: 21 | S15: 22 | T15: 23 | U15: 24 | V15: 25 | W15: 26 | X15: 27 | Y15: 28
A16: ='試算-SLOT'!A16 -> MMK | B16: ='試算-SLOT'!B16 -> K | C16: ='試算-SLOT'!C16 -> 緬甸元(K) | D16: =IF('試算-SLOT'!D16=1,"",'試算-SLOT'!D16) -> 1000 | E16: ='試算-SLOT'!G16 -> 0.002 | F16: 1 | G16: 2 | H16: 3 | I16: 4 | J16: 5 | K16: 6 | L16: 7 | M16: 8 | N16: 9 | O16: 10 | P16: 11 | Q16: 12 | R16: 13 | S16: 14 | T16: 15 | U16: 16 | V16: 18 | W16: 19 | X16: 20 | Y16: 21
A17: ='試算-SLOT'!A17 -> MMH | B17: ='試算-SLOT'!B17 -> K | C17: ='試算-SLOT'!C17 -> 緬甸元(H) | D17: =IF('試算-SLOT'!D17=1,"",'試算-SLOT'!D17) -> 100 | E17: ='試算-SLOT'!G17 -> 0.004 | F17: 1 | G17: 2 | H17: 3 | I17: 4 | J17: 5 | K17: 6 | L17: 7 | M17: 8 | N17: 9 | O17: 11 | P17: 13 | Q17: 14 | R17: 16 | S17: 18 | T17: 19 | U17: 20 | V17: 21 | W17: 22 | X17: 23 | Y17: 24
... A55: ='試算-SLOT'!A55 -> XSMY | B55: ='試算-SLOT'!B55 | C55: ='試算-SLOT'!C55 -> 星城馬來西亞 | D55: =IF('試算-SLOT'!D55=1,"",'試算-SLOT'!D55) | E55: ='試算-SLOT'!G55 -> 1 | F55: 1 | G55: 2 | H55: 3 | I55: 4 | J55: 5 | K55: 6 | L55: 7 | M55: 8 | N55: 9 | O55: 10 | P55: 11 | Q55: 13 | R55: 14 | S55: 16 | T55: 17 | U55: 18 | V55: 19 | W55: 20 | X55: 21 | Y55: 22
A58: =A5 -> 貨幣簡稱 | B58: =B5 -> 貨幣符號 | C58: =C5 -> 中文名稱 | D58: =D5 -> 貨幣轉換 | E58: =E5 -> Denom | F58: =F5 -> 第 1 組 | G58: =G5 -> 第 2 組 | H58: =H5 -> 第 3 組 | ... Y58: =Y5 -> 第 20 組 | AA58: 顯示金額
A59: =A6 -> THB | B59: =B6 -> ฿ | C59: =C6 -> 泰銖 | D59: =D6 | E59: =E6 -> 0.002 | F59: =HLOOKUP(F6,$F$1:$AI$2,2) * $D$1 * $E59 -> 1 | G59: =HLOOKUP(G6,$F$1:$AI$2,2) * $D$1 * $E59 -> 2 | H59: =HLOOKUP(H6,$F$1:$AI$2,2) * $D$1 * $E59 -> 3 | I59: =HLOOKUP(I6,$F$1:$AI$2,2) * $D$1 * $E59 -> 4 | J59: =HLOOKUP(J6,$F$1:$AI$2,2) * $D$1 * $E59 -> 5 | K59: =HLOOKUP(K6,$F$1:$AI$2,2) * $D$1 * $E59 -> 6 | L59: =HLOOKUP(L6,$F$1:$AI$2,2) * $D$1 * $E59 -> 8 | M59: =HLOOKUP(M6,$F$1:$AI$2,2) * $D$1 * $E59 -> 10 | ... Y59: =HLOOKUP(Y6,$F$1:$AI$2,2) * $D$1 * $E59 -> 1500
A60: =A7 -> HKD | B60: =B7 -> HK$ | C60: =C7 -> 港幣 | D60: =D7 | E60: =E7 -> 0.002 | F60: =HLOOKUP(F7,$F$1:$AI$2,2) * $D$1 * $E60 -> 0.2 | G60: =HLOOKUP(G7,$F$1:$AI$2,2) * $D$1 * $E60 -> 0.4 | H60: =HLOOKUP(H7,$F$1:$AI$2,2) * $D$1 * $E60 -> 1 | I60: =HLOOKUP(I7,$F$1:$AI$2,2) * $D$1 * $E60 -> 2 | J60: =HLOOKUP(J7,$F$1:$AI$2,2) * $D$1 * $E60 -> 2.4 | K60: =HLOOKUP(K7,$F$1:$AI$2,2) * $D$1 * $E60 -> 3 | L60: =HLOOKUP(L7,$F$1:$AI$2,2) * $D$1 * $E60 -> 4 | M60: =HLOOKUP(M7,$F$1:$AI$2,2) * $D$1 * $E60 -> 5 | ... Y60: =HLOOKUP(Y7,$F$1:$AI$2,2) * $D$1 * $E60 -> 300
A61: =A8 -> INR | B61: =B8 -> ₹ | C61: =C8 -> 印度盧比 | D61: =D8 | E61: =E8 -> 0.002 | F61: =HLOOKUP(F8,$F$1:$AI$2,2) * $D$1 * $E61 -> 2 | G61: =HLOOKUP(G8,$F$1:$AI$2,2) * $D$1 * $E61 -> 3 | H61: =HLOOKUP(H8,$F$1:$AI$2,2) * $D$1 * $E61 -> 4 | I61: =HLOOKUP(I8,$F$1:$AI$2,2) * $D$1 * $E61 -> 6 | J61: =HLOOKUP(J8,$F$1:$AI$2,2) * $D$1 * $E61 -> 8 | K61: =HLOOKUP(K8,$F$1:$AI$2,2) * $D$1 * $E61 -> 10 | L61: =HLOOKUP(L8,$F$1:$AI$2,2) * $D$1 * $E61 -> 12 | M61: =HLOOKUP(M8,$F$1:$AI$2,2) * $D$1 * $E61 -> 16 | ... Y61: =HLOOKUP(Y8,$F$1:$AI$2,2) * $D$1 * $E61 -> 3000
A62: =A9 -> IDR | B62: =B9 -> Rp | C62: =C9 -> 印尼盧比(K) | D62: =D9 -> 1000 | E62: =E9 -> 0.002 | F62: =HLOOKUP(F9,$F$1:$AI$2,2) * $D$1 * $E62 -> 0.4 | G62: =HLOOKUP(G9,$F$1:$AI$2,2) * $D$1 * $E62 -> 1 | H62: =HLOOKUP(H9,$F$1:$AI$2,2) * $D$1 * $E62 -> 2 | I62: =HLOOKUP(I9,$F$1:$AI$2,2) * $D$1 * $E62 -> 2.4 | J62: =HLOOKUP(J9,$F$1:$AI$2,2) * $D$1 * $E62 -> 3 | K62: =HLOOKUP(K9,$F$1:$AI$2,2) * $D$1 * $E62 -> 4 | L62: =HLOOKUP(L9,$F$1:$AI$2,2) * $D$1 * $E62 -> 5 | M62: =HLOOKUP(M9,$F$1:$AI$2,2) * $D$1 * $E62 -> 6 | ... Y62: =HLOOKUP(Y9,$F$1:$AI$2,2) * $D$1 * $E62 -> 600
A63: =A10 -> VND | B63: =B10 -> ₫ | C63: =C10 -> 越南盾(K) | D63: =D10 -> 1000 | E63: =E10 -> 0.002 | F63: =HLOOKUP(F10,$F$1:$AI$2,2) * $D$1 * $E63 -> 1 | G63: =HLOOKUP(G10,$F$1:$AI$2,2) * $D$1 * $E63 -> 2 | H63: =HLOOKUP(H10,$F$1:$AI$2,2) * $D$1 * $E63 -> 2.4 | I63: =HLOOKUP(I10,$F$1:$AI$2,2) * $D$1 * $E63 -> 3 | J63: =HLOOKUP(J10,$F$1:$AI$2,2) * $D$1 * $E63 -> 4 | K63: =HLOOKUP(K10,$F$1:$AI$2,2) * $D$1 * $E63 -> 5 | L63: =HLOOKUP(L10,$F$1:$AI$2,2) * $D$1 * $E63 -> 6 | M63: =HLOOKUP(M10,$F$1:$AI$2,2) * $D$1 * $E63 -> 8 | ... Y63: =HLOOKUP(Y10,$F$1:$AI$2,2) * $D$1 * $E63 -> 1000
A64: =A11 -> MYR | B64: =B11 -> RM | C64: =C11 -> 馬來西亞令吉 | D64: =D11 | E64: =E11 -> 0.002 | F64: =HLOOKUP(F11,$F$1:$AI$2,2) * $D$1 * $E64 -> 0.2 | G64: =HLOOKUP(G11,$F$1:$AI$2,2) * $D$1 * $E64 -> 0.4 | H64: =HLOOKUP(H11,$F$1:$AI$2,2) * $D$1 * $E64 -> 1 | I64: =HLOOKUP(I11,$F$1:$AI$2,2) * $D$1 * $E64 -> 2 | J64: =HLOOKUP(J11,$F$1:$AI$2,2) * $D$1 * $E64 -> 2.4 | K64: =HLOOKUP(K11,$F$1:$AI$2,2) * $D$1 * $E64 -> 3 | L64: =HLOOKUP(L11,$F$1:$AI$2,2) * $D$1 * $E64 -> 4 | M64: =HLOOKUP(M11,$F$1:$AI$2,2) * $D$1 * $E64 -> 5 | ... Y64: =HLOOKUP(Y11,$F$1:$AI$2,2) * $D$1 * $E64 -> 200
A65: =A12 -> SGD | B65: =B12 -> S$ | C65: =C12 -> 新加坡幣 | D65: =D12 | E65: =E12 -> 0.002 | F65: =HLOOKUP(F12,$F$1:$AI$2,2) * $D$1 * $E65 -> 0.2 | G65: =HLOOKUP(G12,$F$1:$AI$2,2) * $D$1 * $E65 -> 0.4 | H65: =HLOOKUP(H12,$F$1:$AI$2,2) * $D$1 * $E65 -> 1 | I65: =HLOOKUP(I12,$F$1:$AI$2,2) * $D$1 * $E65 -> 2 | J65: =HLOOKUP(J12,$F$1:$AI$2,2) * $D$1 * $E65 -> 2.4 | K65: =HLOOKUP(K12,$F$1:$AI$2,2) * $D$1 * $E65 -> 3 | L65: =HLOOKUP(L12,$F$1:$AI$2,2) * $D$1 * $E65 -> 4 | M65: =HLOOKUP(M12,$F$1:$AI$2,2) * $D$1 * $E65 -> 5 | ... Y65: =HLOOKUP(Y12,$F$1:$AI$2,2) * $D$1 * $E65 -> 40
A66: =A13 -> USD | B66: =B13 -> $ | C66: =C13 -> 美元 | D66: =D13 | E66: =E13 -> 0.002 | F66: =HLOOKUP(F13,$F$1:$AI$2,2) * $D$1 * $E66 -> 0.2 | G66: =HLOOKUP(G13,$F$1:$AI$2,2) * $D$1 * $E66 -> 0.4 | H66: =HLOOKUP(H13,$F$1:$AI$2,2) * $D$1 * $E66 -> 1 | I66: =HLOOKUP(I13,$F$1:$AI$2,2) * $D$1 * $E66 -> 2 | J66: =HLOOKUP(J13,$F$1:$AI$2,2) * $D$1 * $E66 -> 2.4 | K66: =HLOOKUP(K13,$F$1:$AI$2,2) * $D$1 * $E66 -> 3 | L66: =HLOOKUP(L13,$F$1:$AI$2,2) * $D$1 * $E66 -> 4 | M66: =HLOOKUP(M13,$F$1:$AI$2,2) * $D$1 * $E66 -> 5 | ... Y66: =HLOOKUP(Y13,$F$1:$AI$2,2) * $D$1 * $E66 -> 40
A67: =A14 -> BDT | B67: =B14 -> ৳ | C67: =C14 -> 孟加拉塔卡 | D67: =D14 | E67: =E14 -> 0.002 | F67: =HLOOKUP(F14,$F$1:$AI$2,2) * $D$1 * $E67 -> 2 | G67: =HLOOKUP(G14,$F$1:$AI$2,2) * $D$1 * $E67 -> 3 | H67: =HLOOKUP(H14,$F$1:$AI$2,2) * $D$1 * $E67 -> 4 | I67: =HLOOKUP(I14,$F$1:$AI$2,2) * $D$1 * $E67 -> 6 | J67: =HLOOKUP(J14,$F$1:$AI$2,2) * $D$1 * $E67 -> 8 | K67: =HLOOKUP(K14,$F$1:$AI$2,2) * $D$1 * $E67 -> 10 | L67: =HLOOKUP(L14,$F$1:$AI$2,2) * $D$1 * $E67 -> 12 | M67: =HLOOKUP(M14,$F$1:$AI$2,2) * $D$1 * $E67 -> 16 | ... Y67: =HLOOKUP(Y14,$F$1:$AI$2,2) * $D$1 * $E67 -> 3000
A68: =A15 -> PKR | B68: =B15 -> ₨ | C68: =C15 -> 巴基斯坦盧比 | D68: =D15 | E68: =E15 -> 0.01 | F68: =HLOOKUP(F15,$F$1:$AI$2,2) * $D$1 * $E68 -> 5 | G68: =HLOOKUP(G15,$F$1:$AI$2,2) * $D$1 * $E68 -> 10 | H68: =HLOOKUP(H15,$F$1:$AI$2,2) * $D$1 * $E68 -> 15 | I68: =HLOOKUP(I15,$F$1:$AI$2,2) * $D$1 * $E68 -> 20 | J68: =HLOOKUP(J15,$F$1:$AI$2,2) * $D$1 * $E68 -> 30 | K68: =HLOOKUP(K15,$F$1:$AI$2,2) * $D$1 * $E68 -> 40 | L68: =HLOOKUP(L15,$F$1:$AI$2,2) * $D$1 * $E68 -> 50 | M68: =HLOOKUP(M15,$F$1:$AI$2,2) * $D$1 * $E68 -> 60 | ... Y68: =HLOOKUP(Y15,$F$1:$AI$2,2) * $D$1 * $E68 -> 10000
A69: =A16 -> MMK | B69: =B16 -> K | C69: =C16 -> 緬甸元(K) | D69: =D16 -> 1000 | E69: =E16 -> 0.002 | F69: =HLOOKUP(F16,$F$1:$AI$2,2) * $D$1 * $E69 -> 0.2 | G69: =HLOOKUP(G16,$F$1:$AI$2,2) * $D$1 * $E69 -> 0.4 | H69: =HLOOKUP(H16,$F$1:$AI$2,2) * $D$1 * $E69 -> 1 | I69: =HLOOKUP(I16,$F$1:$AI$2,2) * $D$1 * $E69 -> 2 | J69: =HLOOKUP(J16,$F$1:$AI$2,2) * $D$1 * $E69 -> 2.4 | K69: =HLOOKUP(K16,$F$1:$AI$2,2) * $D$1 * $E69 -> 3 | L69: =HLOOKUP(L16,$F$1:$AI$2,2) * $D$1 * $E69 -> 4 | M69: =HLOOKUP(M16,$F$1:$AI$2,2) * $D$1 * $E69 -> 5 | ... Y69: =HLOOKUP(Y16,$F$1:$AI$2,2) * $D$1 * $E69 -> 60
A70: =A17 -> MMH | B70: =B17 -> K | C70: =C17 -> 緬甸元(H) | D70: =D17 -> 100 | E70: =E17 -> 0.004 | F70: =HLOOKUP(F17,$F$1:$AI$2,2) * $D$1 * $E70 -> 0.4 | G70: =HLOOKUP(G17,$F$1:$AI$2,2) * $D$1 * $E70 -> 0.8 | H70: =HLOOKUP(H17,$F$1:$AI$2,2) * $D$1 * $E70 -> 2 | I70: =HLOOKUP(I17,$F$1:$AI$2,2) * $D$1 * $E70 -> 4 | J70: =HLOOKUP(J17,$F$1:$AI$2,2) * $D$1 * $E70 -> 4.8 | K70: =HLOOKUP(K17,$F$1:$AI$2,2) * $D$1 * $E70 -> 6 | L70: =HLOOKUP(L17,$F$1:$AI$2,2) * $D$1 * $E70 -> 8 | M70: =HLOOKUP(M17,$F$1:$AI$2,2) * $D$1 * $E70 -> 10 | ... Y70: =HLOOKUP(Y17,$F$1:$AI$2,2) * $D$1 * $E70 -> 600
... A108: =A55 -> XSMY | B108: =B55 | C108: =C55 -> 星城馬來西亞 | D108: =D55 | E108: =E55 -> 1 | F108: =HLOOKUP(F55,$F$1:$AI$2,2) * $D$1 * $E108 -> 100 | G108: =HLOOKUP(G55,$F$1:$AI$2,2) * $D$1 * $E108 -> 200 | H108: =HLOOKUP(H55,$F$1:$AI$2,2) * $D$1 * $E108 -> 500 | I108: =HLOOKUP(I55,$F$1:$AI$2,2) * $D$1 * $E108 -> 1000 | J108: =HLOOKUP(J55,$F$1:$AI$2,2) * $D$1 * $E108 -> 1200 | K108: =HLOOKUP(K55,$F$1:$AI$2,2) * $D$1 * $E108 -> 1500 | L108: =HLOOKUP(L55,$F$1:$AI$2,2) * $D$1 * $E108 -> 2000 | M108: =HLOOKUP(M55,$F$1:$AI$2,2) * $D$1 * $E108 -> 2500 | ... Y108: =HLOOKUP(Y55,$F$1:$AI$2,2) * $D$1 * $E108 -> 50000

Sheet 150
C1: 最小押分 | D1: 150 | E1: 倍數 設定 | F1: 1 | G1: 2 | H1: 3 | I1: 4 | J1: 5 | K1: 6 | L1: 7 | M1: 8 | N1: 9 | O1: 10 | P1: 11 | Q1: 12 | R1: 13 | S1: 14 | T1: 15 | U1: 16 | V1: 17 | W1: 18 | X1: 19 | Y1: 20 | Z1: 21 | AA1: 22 | AB1: 23 | AC1: 24 | AD1: 25 | AE1: 26 | AF1: 27 | AG1: 28 | AH1: 29 | AI1: 30
F2: ='100'!F2 -> 1 | G2: ='100'!G2 -> 2 | H2: ='100'!H2 -> 5 | I2: ='100'!I2 -> 10 | J2: ='100'!J2 -> 12 | K2: ='100'!K2 -> 15 | L2: ='100'!L2 -> 20 | M2: ='100'!M2 -> 25 | ... AI2: ='100'!AI2 -> 25000
A5: 貨幣簡稱 | B5: 貨幣符號 | C5: 中文名稱 | D5: 貨幣轉換 | E5: Denom | F5: 第 1 組 | G5: 第 2 組 | H5: 第 3 組 | I5: 第 4 組 | J5: 第 5 組 | K5: 第 6 組 | L5: 第 7 組 | M5: 第 8 組 | N5: 第 9 組 | O5: 第 10 組 | P5: 第 11 組 | Q5: 第 12 組 | R5: 第 13 組 | S5: 第 14 組 | T5: 第 15 組 | U5: 第 16 組 | V5: 第 17 組 | W5: 第 18 組 | X5: 第 19 組 | Y5: 第 20 組 | AA5: 顯示倍數組別
A6: ='試算-SLOT'!A6 -> THB | B6: ='試算-SLOT'!B6 -> ฿ | C6: ='試算-SLOT'!C6 -> 泰銖 | D6: =IF('試算-SLOT'!D6=1,"",'試算-SLOT'!D6) | E6: ='100'!E6 -> 0.002 | F6: 3 | G6: 4 | H6: 6 | I6: 7 | J6: 8 | K6: 9 | L6: 11 | M6: 13 | N6: 14 | O6: 16 | P6: 18 | Q6: 19 | R6: 20 | S6: 21 | T6: 22 | U6: 23 | V6: 24 | W6: 25 | X6: 26 | Y6: 27
A7: ='試算-SLOT'!A7 -> HKD | B7: ='試算-SLOT'!B7 -> HK$ | C7: ='試算-SLOT'!C7 -> 港幣 | D7: =IF('試算-SLOT'!D7=1,"",'試算-SLOT'!D7) | E7: ='100'!E7 -> 0.002 | F7: 1 | G7: 2 | H7: 3 | I7: 4 | J7: 5 | K7: 6 | L7: 7 | M7: 8 | N7: 9 | O7: 11 | P7: 13 | Q7: 14 | R7: 16 | S7: 18 | T7: 19 | U7: 20 | V7: 21 | W7: 22 | X7: 23 | Y7: 24
A8: ='試算-SLOT'!A8 -> INR | B8: ='試算-SLOT'!B8 -> ₹ | C8: ='試算-SLOT'!C8 -> 印度盧比 | D8: =IF('試算-SLOT'!D8=1,"",'試算-SLOT'!D8) | E8: ='100'!E8 -> 0.002 | F8: 4 | G8: 6 | H8: 7 | I8: 9 | J8: 11 | K8: 13 | L8: 14 | M8: 16 | N8: 18 | O8: 19 | P8: 20 | Q8: 21 | R8: 22 | S8: 23 | T8: 24 | U8: 25 | V8: 26 | W8: 27 | X8: 28 | Y8: 29
A9: ='試算-SLOT'!A9 -> IDR | B9: ='試算-SLOT'!B9 -> Rp | C9: ='試算-SLOT'!C9 -> 印尼盧比(K) | D9: =IF('試算-SLOT'!D9=1,"",'試算-SLOT'!D9) -> 1000 | E9: ='100'!E9 -> 0.002 | F9: 2 | G9: 3 | H9: 4 | I9: 5 | J9: 6 | K9: 7 | L9: 8 | M9: 9 | N9: 11 | O9: 13 | P9: 14 | Q9: 16 | R9: 18 | S9: 19 | T9: 20 | U9: 21 | V9: 22 | W9: 23 | X9: 24 | Y9: 25
A10: ='試算-SLOT'!A10 -> VND | B10: ='試算-SLOT'!B10 -> ₫ | C10: ='試算-SLOT'!C10 -> 越南盾(K) | D10: =IF('試算-SLOT'!D10=1,"",'試算-SLOT'!D10) -> 1000 | E10: ='100'!E10 -> 0.002 | F10: 3 | G10: 4 | H10: 5 | I10: 6 | J10: 7 | K10: 8 | L10: 9 | M10: 11 | N10: 13 | O10: 14 | P10: 16 | Q10: 18 | R10: 19 | S10: 20 | T10: 21 | U10: 22 | V10: 23 | W10: 24 | X10: 25 | Y10: 26
A11: ='試算-SLOT'!A11 -> MYR | B11: ='試算-SLOT'!B11 -> RM | C11: ='試算-SLOT'!C11 -> 馬來西亞令吉 | D11: =IF('試算-SLOT'!D11=1,"",'試算-SLOT'!D11) | E11: ='100'!E11 -> 0.002 | F11: 1 | G11: 2 | H11: 3 | I11: 4 | J11: 5 | K11: 6 | L11: 7 | M11: 8 | N11: 9 | O11: 10 | P11: 11 | Q11: 13 | R11: 14 | S11: 16 | T11: 18 | U11: 19 | V11: 20 | W11: 21 | X11: 22 | Y11: 23
A12: ='試算-SLOT'!A12 -> SGD | B12: ='試算-SLOT'!B12 -> S$ | C12: ='試算-SLOT'!C12 -> 新加坡幣 | D12: =IF('試算-SLOT'!D12=1,"",'試算-SLOT'!D12) | E12: ='100'!E12 -> 0.002 | F12: 1 | G12: 2 | H12: 3 | I12: 4 | J12: 5 | K12: 6 | L12: 7 | M12: 8 | N12: 9 | O12: 10 | P12: 11 | Q12: 12 | R12: 13 | S12: 14 | T12: 15 | U12: 16 | V12: 17 | W12: 18 | X12: 19 | Y12: 20
A13: ='試算-SLOT'!A13 -> USD | B13: ='試算-SLOT'!B13 -> $ | C13: ='試算-SLOT'!C13 -> 美元 | D13: =IF('試算-SLOT'!D13=1,"",'試算-SLOT'!D13) | E13: ='100'!E13 -> 0.002 | F13: 1 | G13: 2 | H13: 3 | I13: 4 | J13: 5 | K13: 6 | L13: 7 | M13: 8 | N13: 9 | O13: 10 | P13: 11 | Q13: 12 | R13: 13 | S13: 14 | T13: 15 | U13: 16 | V13: 17 | W13: 18 | X13: 19 | Y13: 20
A14: ='試算-SLOT'!A14 -> BDT | B14: ='試算-SLOT'!B14 -> ৳ | C14: ='試算-SLOT'!C14 -> 孟加拉塔卡 | D14: =IF('試算-SLOT'!D14=1,"",'試算-SLOT'!D14) | E14: ='100'!E14 -> 0.002 | F14: 4 | G14: 6 | H14: 7 | I14: 9 | J14: 11 | K14: 13 | L14: 14 | M14: 16 | N14: 18 | O14: 19 | P14: 20 | Q14: 21 | R14: 22 | S14: 23 | T14: 24 | U14: 25 | V14: 26 | W14: 27 | X14: 28 | Y14: 29
A15: ='試算-SLOT'!A15 -> PKR | B15: ='試算-SLOT'!B15 -> ₨ | C15: ='試算-SLOT'!C15 -> 巴基斯坦盧比 | D15: =IF('試算-SLOT'!D15=1,"",'試算-SLOT'!D15) | E15: ='100'!E15 -> 0.01 | F15: 3 | G15: 4 | H15: 6 | I15: 7 | J15: 9 | K15: 11 | L15: 13 | M15: 14 | N15: 16 | O15: 18 | P15: 19 | Q15: 20 | R15: 21 | S15: 22 | T15: 23 | U15: 24 | V15: 25 | W15: 26 | X15: 27 | Y15: 28
A16: ='試算-SLOT'!A16 -> MMK | B16: ='試算-SLOT'!B16 -> K | C16: ='試算-SLOT'!C16 -> 緬甸元(K) | D16: =IF('試算-SLOT'!D16=1,"",'試算-SLOT'!D16) -> 1000 | E16: ='100'!E16 -> 0.002 | F16: 1 | G16: 2 | H16: 3 | I16: 4 | J16: 5 | K16: 6 | L16: 7 | M16: 8 | N16: 9 | O16: 10 | P16: 11 | Q16: 12 | R16: 13 | S16: 14 | T16: 15 | U16: 16 | V16: 18 | W16: 19 | X16: 20 | Y16: 21
A17: ='試算-SLOT'!A17 -> MMH | B17: ='試算-SLOT'!B17 -> K | C17: ='試算-SLOT'!C17 -> 緬甸元(H) | D17: =IF('試算-SLOT'!D17=1,"",'試算-SLOT'!D17) -> 100 | E17: ='100'!E17 -> 0.004 | F17: 1 | G17: 2 | H17: 3 | I17: 4 | J17: 5 | K17: 6 | L17: 7 | M17: 8 | N17: 9 | O17: 11 | P17: 13 | Q17: 14 | R17: 16 | S17: 18 | T17: 19 | U17: 20 | V17: 21 | W17: 22 | X17: 23 | Y17: 24
... A48: ='試算-SLOT'!A48 -> XSD | B48: ='試算-SLOT'!B48 | C48: ='試算-SLOT'!C48 -> 星幣 | D48: =IF('試算-SLOT'!D48=1,"",'試算-SLOT'!D48) | E48: ='100'!E48 -> 1 | F48: 1 | G48: 2 | H48: 3 | I48: 4 | J48: 5 | K48: 6 | L48: 7 | M48: 8 | N48: 9 | O48: 10 | P48: 11 | Q48: 13 | R48: 14 | S48: 16 | T48: 17 | U48: 18 | V48: 19 | W48: 20 | X48: 21 | Y48: 22
A49: ='試算-SLOT'!A49 -> DZD | B49: ='試算-SLOT'!B49 -> دج | C49: ='試算-SLOT'!C49 -> 阿爾及利亞第納爾 | D49: =IF('試算-SLOT'!D49=1,"",'試算-SLOT'!D49) | E49: ='試算-SLOT'!G49 -> 0.002 | F49: 7 | G49: 9 | H49: 11 | I49: 14 | J49: 15 | K49: 16 | L49: 17 | M49: 18 | N49: 19 | O49: 20 | P49: 21 | Q49: 22 | R49: 23 | S49: 24 | T49: 25 | U49: 26 | V49: 27 | W49: 28 | X49: 29 | Y49: 30
A50: ='試算-SLOT'!A50 -> MAD | B50: ='試算-SLOT'!B50 -> DH | C50: ='試算-SLOT'!C50 -> 摩洛哥迪拉姆 | D50: =IF('試算-SLOT'!D50=1,"",'試算-SLOT'!D50) | E50: ='試算-SLOT'!G50 -> 0.002 | F50: 1 | G50: 2 | H50: 3 | I50: 4 | J50: 5 | K50: 6 | L50: 7 | M50: 8 | N50: 9 | O50: 11 | P50: 13 | Q50: 14 | R50: 16 | S50: 18 | T50: 19 | U50: 20 | V50: 21 | W50: 22 | X50: 23 | Y50: 24
A51: ='試算-SLOT'!A51 -> FRF | B51: ='試算-SLOT'!B51 -> ₣ | C51: ='試算-SLOT'!C51 -> 法國法郎 | D51: =IF('試算-SLOT'!D51=1,"",'試算-SLOT'!D51) | E51: ='試算-SLOT'!G51 -> 0.002 | F51: 1 | G51: 2 | H51: 3 | I51: 4 | J51: 5 | K51: 6 | L51: 7 | M51: 8 | N51: 9 | O51: 11 | P51: 13 | Q51: 14 | R51: 16 | S51: 18 | T51: 19 | U51: 20 | V51: 21 | W51: 22 | X51: 23 | Y51: 24
A52: ='試算-SLOT'!A52 -> GHS | B52: ='試算-SLOT'!B52 -> Gp | C52: ='試算-SLOT'!C52 -> 迦納塞地 | D52: =IF('試算-SLOT'!D52=1,"",'試算-SLOT'!D52) | E52: ='試算-SLOT'!G52 -> 0.002 | F52: 2 | G52: 3 | H52: 4 | I52: 5 | J52: 6 | K52: 7 | L52: 8 | M52: 9 | N52: 11 | O52: 13 | P52: 14 | Q52: 16 | R52: 18 | S52: 19 | T52: 20 | U52: 21 | V52: 22 | W52: 23 | X52: 24 | Y52: 25
A53: ='試算-SLOT'!A53 -> RCC | B53: ='試算-SLOT'!B53 | C53: ='試算-SLOT'!C53 -> RCC幣 | D53: =IF('試算-SLOT'!D53=1,"",'試算-SLOT'!D53) | E53: ='100'!E53 -> 0.002 | F53: 1 | G53: 2 | H53: 3 | I53: 4 | J53: 5 | K53: 6 | L53: 7 | M53: 8 | N53: 9 | O53: 10 | P53: 11 | Q53: 12 | R53: 13 | S53: 14 | T53: 15 | U53: 16 | V53: 17 | W53: 18 | X53: 19 | Y53: 20
A54: ='試算-SLOT'!A54 -> KBB | B54: ='試算-SLOT'!B54 | C54: ='試算-SLOT'!C54 -> 爸幣 | D54: =IF('試算-SLOT'!D54=1,"",'試算-SLOT'!D54) | E54: ='100'!E54 -> 0.01 | F54: 3 | G54: 4 | H54: 6 | I54: 7 | J54: 8 | K54: 9 | L54: 11 | M54: 13 | N54: 14 | O54: 16 | P54: 18 | Q54: 19 | R54: 20 | S54: 21 | T54: 22 | U54: 23 | V54: 24 | W54: 25 | X54: 26 | Y54: 27
A55: ='試算-SLOT'!A55 -> XSMY | B55: ='試算-SLOT'!B55 | C55: ='試算-SLOT'!C55 -> 星城馬來西亞 | D55: =IF('試算-SLOT'!D55=1,"",'試算-SLOT'!D55) | E55: ='100'!E55 -> 1 | F55: 1 | G55: 2 | H55: 3 | I55: 4 | J55: 5 | K55: 6 | L55: 7 | M55: 8 | N55: 9 | O55: 10 | P55: 11 | Q55: 13 | R55: 14 | S55: 16 | T55: 17 | U55: 18 | V55: 19 | W55: 20 | X55: 21 | Y55: 22
A58: =A5 -> 貨幣簡稱 | B58: =B5 -> 貨幣符號 | C58: =C5 -> 中文名稱 | D58: =D5 -> 貨幣轉換 | E58: =E5 -> Denom | F58: =F5 -> 第 1 組 | G58: =G5 -> 第 2 組 | H58: =H5 -> 第 3 組 | ... Y58: =Y5 -> 第 20 組 | AA58: 顯示金額
A59: =A6 -> THB | B59: =B6 -> ฿ | C59: =C6 -> 泰銖 | D59: =D6 | E59: =E6 -> 0.002 | F59: =HLOOKUP(F6,$F$1:$AI$2,2) * $D$1 * $E59 -> 1.5 | G59: =HLOOKUP(G6,$F$1:$AI$2,2) * $D$1 * $E59 -> 3 | H59: =HLOOKUP(H6,$F$1:$AI$2,2) * $D$1 * $E59 -> 4.5 | I59: =HLOOKUP(I6,$F$1:$AI$2,2) * $D$1 * $E59 -> 6 | J59: =HLOOKUP(J6,$F$1:$AI$2,2) * $D$1 * $E59 -> 7.5 | K59: =HLOOKUP(K6,$F$1:$AI$2,2) * $D$1 * $E59 -> 9 | L59: =HLOOKUP(L6,$F$1:$AI$2,2) * $D$1 * $E59 -> 12 | M59: =HLOOKUP(M6,$F$1:$AI$2,2) * $D$1 * $E59 -> 15 | ... Y59: =HLOOKUP(Y6,$F$1:$AI$2,2) * $D$1 * $E59 -> 2250
A60: =A7 -> HKD | B60: =B7 -> HK$ | C60: =C7 -> 港幣 | D60: =D7 | E60: =E7 -> 0.002 | F60: =HLOOKUP(F7,$F$1:$AI$2,2) * $D$1 * $E60 -> 0.3 | G60: =HLOOKUP(G7,$F$1:$AI$2,2) * $D$1 * $E60 -> 0.6 | H60: =HLOOKUP(H7,$F$1:$AI$2,2) * $D$1 * $E60 -> 1.5 | I60: =HLOOKUP(I7,$F$1:$AI$2,2) * $D$1 * $E60 -> 3 | J60: =HLOOKUP(J7,$F$1:$AI$2,2) * $D$1 * $E60 -> 3.6 | K60: =HLOOKUP(K7,$F$1:$AI$2,2) * $D$1 * $E60 -> 4.5 | L60: =HLOOKUP(L7,$F$1:$AI$2,2) * $D$1 * $E60 -> 6 | M60: =HLOOKUP(M7,$F$1:$AI$2,2) * $D$1 * $E60 -> 7.5 | ... Y60: =HLOOKUP(Y7,$F$1:$AI$2,2) * $D$1 * $E60 -> 450
A61: =A8 -> INR | B61: =B8 -> ₹ | C61: =C8 -> 印度盧比 | D61: =D8 | E61: =E8 -> 0.002 | F61: =HLOOKUP(F8,$F$1:$AI$2,2) * $D$1 * $E61 -> 3 | G61: =HLOOKUP(G8,$F$1:$AI$2,2) * $D$1 * $E61 -> 4.5 | H61: =HLOOKUP(H8,$F$1:$AI$2,2) * $D$1 * $E61 -> 6 | I61: =HLOOKUP(I8,$F$1:$AI$2,2) * $D$1 * $E61 -> 9 | J61: =HLOOKUP(J8,$F$1:$AI$2,2) * $D$1 * $E61 -> 12 | K61: =HLOOKUP(K8,$F$1:$AI$2,2) * $D$1 * $E61 -> 15 | L61: =HLOOKUP(L8,$F$1:$AI$2,2) * $D$1 * $E61 -> 18 | M61: =HLOOKUP(M8,$F$1:$AI$2,2) * $D$1 * $E61 -> 24 | ... Y61: =HLOOKUP(Y8,$F$1:$AI$2,2) * $D$1 * $E61 -> 4500
A62: =A9 -> IDR | B62: =B9 -> Rp | C62: =C9 -> 印尼盧比(K) | D62: =D9 -> 1000 | E62: =E9 -> 0.002 | F62: =HLOOKUP(F9,$F$1:$AI$2,2) * $D$1 * $E62 -> 0.6 | G62: =HLOOKUP(G9,$F$1:$AI$2,2) * $D$1 * $E62 -> 1.5 | H62: =HLOOKUP(H9,$F$1:$AI$2,2) * $D$1 * $E62 -> 3 | I62: =HLOOKUP(I9,$F$1:$AI$2,2) * $D$1 * $E62 -> 3.6 | J62: =HLOOKUP(J9,$F$1:$AI$2,2) * $D$1 * $E62 -> 4.5 | K62: =HLOOKUP(K9,$F$1:$AI$2,2) * $D$1 * $E62 -> 6 | L62: =HLOOKUP(L9,$F$1:$AI$2,2) * $D$1 * $E62 -> 7.5 | M62: =HLOOKUP(M9,$F$1:$AI$2,2) * $D$1 * $E62 -> 9 | ... Y62: =HLOOKUP(Y9,$F$1:$AI$2,2) * $D$1 * $E62 -> 900
A63: =A10 -> VND | B63: =B10 -> ₫ | C63: =C10 -> 越南盾(K) | D63: =D10 -> 1000 | E63: =E10 -> 0.002 | F63: =HLOOKUP(F10,$F$1:$AI$2,2) * $D$1 * $E63 -> 1.5 | G63: =HLOOKUP(G10,$F$1:$AI$2,2) * $D$1 * $E63 -> 3 | H63: =HLOOKUP(H10,$F$1:$AI$2,2) * $D$1 * $E63 -> 3.6 | I63: =HLOOKUP(I10,$F$1:$AI$2,2) * $D$1 * $E63 -> 4.5 | J63: =HLOOKUP(J10,$F$1:$AI$2,2) * $D$1 * $E63 -> 6 | K63: =HLOOKUP(K10,$F$1:$AI$2,2) * $D$1 * $E63 -> 7.5 | L63: =HLOOKUP(L10,$F$1:$AI$2,2) * $D$1 * $E63 -> 9 | M63: =HLOOKUP(M10,$F$1:$AI$2,2) * $D$1 * $E63 -> 12 | ... Y63: =HLOOKUP(Y10,$F$1:$AI$2,2) * $D$1 * $E63 -> 1500
A64: =A11 -> MYR | B64: =B11 -> RM | C64: =C11 -> 馬來西亞令吉 | D64: =D11 | E64: =E11 -> 0.002 | F64: =HLOOKUP(F11,$F$1:$AI$2,2) * $D$1 * $E64 -> 0.3 | G64: =HLOOKUP(G11,$F$1:$AI$2,2) * $D$1 * $E64 -> 0.6 | H64: =HLOOKUP(H11,$F$1:$AI$2,2) * $D$1 * $E64 -> 1.5 | I64: =HLOOKUP(I11,$F$1:$AI$2,2) * $D$1 * $E64 -> 3 | J64: =HLOOKUP(J11,$F$1:$AI$2,2) * $D$1 * $E64 -> 3.6 | K64: =HLOOKUP(K11,$F$1:$AI$2,2) * $D$1 * $E64 -> 4.5 | L64: =HLOOKUP(L11,$F$1:$AI$2,2) * $D$1 * $E64 -> 6 | M64: =HLOOKUP(M11,$F$1:$AI$2,2) * $D$1 * $E64 -> 7.5 | ... Y64: =HLOOKUP(Y11,$F$1:$AI$2,2) * $D$1 * $E64 -> 300
A65: =A12 -> SGD | B65: =B12 -> S$ | C65: =C12 -> 新加坡幣 | D65: =D12 | E65: =E12 -> 0.002 | F65: =HLOOKUP(F12,$F$1:$AI$2,2) * $D$1 * $E65 -> 0.3 | G65: =HLOOKUP(G12,$F$1:$AI$2,2) * $D$1 * $E65 -> 0.6 | H65: =HLOOKUP(H12,$F$1:$AI$2,2) * $D$1 * $E65 -> 1.5 | I65: =HLOOKUP(I12,$F$1:$AI$2,2) * $D$1 * $E65 -> 3 | J65: =HLOOKUP(J12,$F$1:$AI$2,2) * $D$1 * $E65 -> 3.6 | K65: =HLOOKUP(K12,$F$1:$AI$2,2) * $D$1 * $E65 -> 4.5 | L65: =HLOOKUP(L12,$F$1:$AI$2,2) * $D$1 * $E65 -> 6 | M65: =HLOOKUP(M12,$F$1:$AI$2,2) * $D$1 * $E65 -> 7.5 | ... Y65: =HLOOKUP(Y12,$F$1:$AI$2,2) * $D$1 * $E65 -> 60
A66: =A13 -> USD | B66: =B13 -> $ | C66: =C13 -> 美元 | D66: =D13 | E66: =E13 -> 0.002 | F66: =HLOOKUP(F13,$F$1:$AI$2,2) * $D$1 * $E66 -> 0.3 | G66: =HLOOKUP(G13,$F$1:$AI$2,2) * $D$1 * $E66 -> 0.6 | H66: =HLOOKUP(H13,$F$1:$AI$2,2) * $D$1 * $E66 -> 1.5 | I66: =HLOOKUP(I13,$F$1:$AI$2,2) * $D$1 * $E66 -> 3 | J66: =HLOOKUP(J13,$F$1:$AI$2,2) * $D$1 * $E66 -> 3.6 | K66: =HLOOKUP(K13,$F$1:$AI$2,2) * $D$1 * $E66 -> 4.5 | L66: =HLOOKUP(L13,$F$1:$AI$2,2) * $D$1 * $E66 -> 6 | M66: =HLOOKUP(M13,$F$1:$AI$2,2) * $D$1 * $E66 -> 7.5 | ... Y66: =HLOOKUP(Y13,$F$1:$AI$2,2) * $D$1 * $E66 -> 60
A67: =A14 -> BDT | B67: =B14 -> ৳ | C67: =C14 -> 孟加拉塔卡 | D67: =D14 | E67: =E14 -> 0.002 | F67: =HLOOKUP(F14,$F$1:$AI$2,2) * $D$1 * $E67 -> 3 | G67: =HLOOKUP(G14,$F$1:$AI$2,2) * $D$1 * $E67 -> 4.5 | H67: =HLOOKUP(H14,$F$1:$AI$2,2) * $D$1 * $E67 -> 6 | I67: =HLOOKUP(I14,$F$1:$AI$2,2) * $D$1 * $E67 -> 9 | J67: =HLOOKUP(J14,$F$1:$AI$2,2) * $D$1 * $E67 -> 12 | K67: =HLOOKUP(K14,$F$1:$AI$2,2) * $D$1 * $E67 -> 15 | L67: =HLOOKUP(L14,$F$1:$AI$2,2) * $D$1 * $E67 -> 18 | M67: =HLOOKUP(M14,$F$1:$AI$2,2) * $D$1 * $E67 -> 24 | ... Y67: =HLOOKUP(Y14,$F$1:$AI$2,2) * $D$1 * $E67 -> 4500
A68: =A15 -> PKR | B68: =B15 -> ₨ | C68: =C15 -> 巴基斯坦盧比 | D68: =D15 | E68: =E15 -> 0.01 | F68: =HLOOKUP(F15,$F$1:$AI$2,2) * $D$1 * $E68 -> 7.5 | G68: =HLOOKUP(G15,$F$1:$AI$2,2) * $D$1 * $E68 -> 15 | H68: =HLOOKUP(H15,$F$1:$AI$2,2) * $D$1 * $E68 -> 22.5 | I68: =HLOOKUP(I15,$F$1:$AI$2,2) * $D$1 * $E68 -> 30 | J68: =HLOOKUP(J15,$F$1:$AI$2,2) * $D$1 * $E68 -> 45 | K68: =HLOOKUP(K15,$F$1:$AI$2,2) * $D$1 * $E68 -> 60 | L68: =HLOOKUP(L15,$F$1:$AI$2,2) * $D$1 * $E68 -> 75 | M68: =HLOOKUP(M15,$F$1:$AI$2,2) * $D$1 * $E68 -> 90 | ... Y68: =HLOOKUP(Y15,$F$1:$AI$2,2) * $D$1 * $E68 -> 15000
A69: =A16 -> MMK | B69: =B16 -> K | C69: =C16 -> 緬甸元(K) | D69: =D16 -> 1000 | E69: =E16 -> 0.002 | F69: =HLOOKUP(F16,$F$1:$AI$2,2) * $D$1 * $E69 -> 0.3 | G69: =HLOOKUP(G16,$F$1:$AI$2,2) * $D$1 * $E69 -> 0.6 | H69: =HLOOKUP(H16,$F$1:$AI$2,2) * $D$1 * $E69 -> 1.5 | I69: =HLOOKUP(I16,$F$1:$AI$2,2) * $D$1 * $E69 -> 3 | J69: =HLOOKUP(J16,$F$1:$AI$2,2) * $D$1 * $E69 -> 3.6 | K69: =HLOOKUP(K16,$F$1:$AI$2,2) * $D$1 * $E69 -> 4.5 | L69: =HLOOKUP(L16,$F$1:$AI$2,2) * $D$1 * $E69 -> 6 | M69: =HLOOKUP(M16,$F$1:$AI$2,2) * $D$1 * $E69 -> 7.5 | ... Y69: =HLOOKUP(Y16,$F$1:$AI$2,2) * $D$1 * $E69 -> 90
A70: =A17 -> MMH | B70: =B17 -> K | C70: =C17 -> 緬甸元(H) | D70: =D17 -> 100 | E70: =E17 -> 0.004 | F70: =HLOOKUP(F17,$F$1:$AI$2,2) * $D$1 * $E70 -> 0.6 | G70: =HLOOKUP(G17,$F$1:$AI$2,2) * $D$1 * $E70 -> 1.2 | H70: =HLOOKUP(H17,$F$1:$AI$2,2) * $D$1 * $E70 -> 3 | I70: =HLOOKUP(I17,$F$1:$AI$2,2) * $D$1 * $E70 -> 6 | J70: =HLOOKUP(J17,$F$1:$AI$2,2) * $D$1 * $E70 -> 7.2 | K70: =HLOOKUP(K17,$F$1:$AI$2,2) * $D$1 * $E70 -> 9 | L70: =HLOOKUP(L17,$F$1:$AI$2,2) * $D$1 * $E70 -> 12 | M70: =HLOOKUP(M17,$F$1:$AI$2,2) * $D$1 * $E70 -> 15 | ... Y70: =HLOOKUP(Y17,$F$1:$AI$2,2) * $D$1 * $E70 -> 900
... A108: =A55 -> XSMY | B108: =B55 | C108: =C55 -> 星城馬來西亞 | D108: =D55 | E108: =E55 -> 1 | F108: =HLOOKUP(F55,$F$1:$AI$2,2) * $D$1 * $E108 -> 150 | G108: =HLOOKUP(G55,$F$1:$AI$2,2) * $D$1 * $E108 -> 300 | H108: =HLOOKUP(H55,$F$1:$AI$2,2) * $D$1 * $E108 -> 750 | I108: =HLOOKUP(I55,$F$1:$AI$2,2) * $D$1 * $E108 -> 1500 | J108: =HLOOKUP(J55,$F$1:$AI$2,2) * $D$1 * $E108 -> 1800 | K108: =HLOOKUP(K55,$F$1:$AI$2,2) * $D$1 * $E108 -> 2250 | L108: =HLOOKUP(L55,$F$1:$AI$2,2) * $D$1 * $E108 -> 3000 | M108: =HLOOKUP(M55,$F$1:$AI$2,2) * $D$1 * $E108 -> 3750 | ... Y108: =HLOOKUP(Y55,$F$1:$AI$2,2) * $D$1 * $E108 -> 75000

Sheet 88
C1: 最小押分 | D1: 88 | E1: 倍數 設定 | F1: 1 | G1: 2 | H1: 3 | I1: 4 | J1: 5 | K1: 6 | L1: 7 | M1: 8 | N1: 9 | O1: 10 | P1: 11 | Q1: 12 | R1: 13 | S1: 14 | T1: 15 | U1: 16 | V1: 17 | W1: 18 | X1: 19 | Y1: 20 | Z1: 21 | AA1: 22 | AB1: 23 | AC1: 24 | AD1: 25 | AE1: 26 | AF1: 27 | AG1: 28 | AH1: 29 | AI1: 30
F2: 1 | G2: 2 | H2: 5 | I2: 10 | J2: 15 | K2: 20 | L2: 30 | M2: 40 | N2: 50 | O2: 60 | P2: 100 | Q2: 120 | R2: 150 | S2: 200 | T2: 250 | U2: 300 | V2: 350 | W2: 400 | X2: 450 | Y2: 500 | Z2: 600 | AA2: 750 | AB2: 1000 | AC2: 1500 | AD2: 1750 | AE2: 2000 | AF2: 3000 | AG2: 4000 | AH2: 5000 | AI2: 6000
AB4: 除了PHP以外的都尚未評估
A5: 貨幣簡稱 | B5: 貨幣符號 | C5: 中文名稱 | D5: 貨幣轉換 | E5: Denom | F5: 第 1 組 | G5: 第 2 組 | H5: 第 3 組 | I5: 第 4 組 | J5: 第 5 組 | K5: 第 6 組 | L5: 第 7 組 | M5: 第 8 組 | N5: 第 9 組 | O5: 第 10 組 | P5: 第 11 組 | Q5: 第 12 組 | R5: 第 13 組 | S5: 第 14 組 | T5: 第 15 組 | U5: 第 16 組 | V5: 第 17 組 | W5: 第 18 組 | X5: 第 19 組 | Y5: 第 20 組 | AA5: 顯示倍數組別
A6: ='試算-SLOT'!A6 -> THB | B6: ='試算-SLOT'!B6 -> ฿ | C6: ='試算-SLOT'!C6 -> 泰銖 | D6: =IF('試算-SLOT'!D6=1,"",'試算-SLOT'!D6) | E6: ='試算-SLOT'!Q6 -> 0.002 | F6: 3 | G6: 4 | H6: 6 | I6: 7 | J6: 8 | K6: 9 | L6: 11 | M6: 13 | N6: 14 | O6: 16 | P6: 18 | Q6: 19 | R6: 20 | S6: 21 | T6: 22 | U6: 23 | V6: 24 | W6: 25 | X6: 26 | Y6: 27
A7: ='試算-SLOT'!A7 -> HKD | B7: ='試算-SLOT'!B7 -> HK$ | C7: ='試算-SLOT'!C7 -> 港幣 | D7: =IF('試算-SLOT'!D7=1,"",'試算-SLOT'!D7) | E7: ='試算-SLOT'!Q7 -> 0.002 | F7: 1 | G7: 2 | H7: 3 | I7: 4 | J7: 5 | K7: 6 | L7: 7 | M7: 8 | N7: 9 | O7: 11 | P7: 13 | Q7: 14 | R7: 16 | S7: 18 | T7: 19 | U7: 20 | V7: 21 | W7: 22 | X7: 23 | Y7: 24
A8: ='試算-SLOT'!A8 -> INR | B8: ='試算-SLOT'!B8 -> ₹ | C8: ='試算-SLOT'!C8 -> 印度盧比 | D8: =IF('試算-SLOT'!D8=1,"",'試算-SLOT'!D8) | E8: ='試算-SLOT'!Q8 -> 0.002 | F8: 4 | G8: 6 | H8: 7 | I8: 9 | J8: 11 | K8: 13 | L8: 14 | M8: 16 | N8: 18 | O8: 19 | P8: 20 | Q8: 21 | R8: 22 | S8: 23 | T8: 24 | U8: 25 | V8: 26 | W8: 27 | X8: 28 | Y8: 29
A9: ='試算-SLOT'!A9 -> IDR | B9: ='試算-SLOT'!B9 -> Rp | C9: ='試算-SLOT'!C9 -> 印尼盧比(K) | D9: =IF('試算-SLOT'!D9=1,"",'試算-SLOT'!D9) -> 1000 | E9: ='試算-SLOT'!Q9 -> 0.002 | F9: 2 | G9: 3 | H9: 4 | I9: 5 | J9: 6 | K9: 7 | L9: 8 | M9: 9 | N9: 11 | O9: 13 | P9: 14 | Q9: 16 | R9: 18 | S9: 19 | T9: 20 | U9: 21 | V9: 22 | W9: 23 | X9: 24 | Y9: 25
A10: ='試算-SLOT'!A10 -> VND | B10: ='試算-SLOT'!B10 -> ₫ | C10: ='試算-SLOT'!C10 -> 越南盾(K) | D10: =IF('試算-SLOT'!D10=1,"",'試算-SLOT'!D10) -> 1000 | E10: ='試算-SLOT'!Q10 -> 0.002 | F10: 3 | G10: 4 | H10: 5 | I10: 6 | J10: 7 | K10: 8 | L10: 9 | M10: 11 | N10: 13 | O10: 14 | P10: 16 | Q10: 18 | R10: 19 | S10: 20 | T10: 21 | U10: 22 | V10: 23 | W10: 24 | X10: 25 | Y10: 26
A11: ='試算-SLOT'!A11 -> MYR | B11: ='試算-SLOT'!B11 -> RM | C11: ='試算-SLOT'!C11 -> 馬來西亞令吉 | D11: =IF('試算-SLOT'!D11=1,"",'試算-SLOT'!D11) | E11: ='試算-SLOT'!Q11 -> 0.002 | F11: 1 | G11: 2 | H11: 3 | I11: 4 | J11: 5 | K11: 6 | L11: 7 | M11: 8 | N11: 9 | O11: 10 | P11: 11 | Q11: 13 | R11: 14 | S11: 16 | T11: 18 | U11: 19 | V11: 20 | W11: 21 | X11: 22 | Y11: 23
A12: ='試算-SLOT'!A12 -> SGD | B12: ='試算-SLOT'!B12 -> S$ | C12: ='試算-SLOT'!C12 -> 新加坡幣 | D12: =IF('試算-SLOT'!D12=1,"",'試算-SLOT'!D12) | E12: ='試算-SLOT'!Q12 -> 0.002 | F12: 1 | G12: 2 | H12: 3 | I12: 4 | J12: 5 | K12: 6 | L12: 7 | M12: 8 | N12: 9 | O12: 10 | P12: 11 | Q12: 12 | R12: 13 | S12: 14 | T12: 15 | U12: 16 | V12: 17 | W12: 18 | X12: 19 | Y12: 20
A13: ='試算-SLOT'!A13 -> USD | B13: ='試算-SLOT'!B13 -> $ | C13: ='試算-SLOT'!C13 -> 美元 | D13: =IF('試算-SLOT'!D13=1,"",'試算-SLOT'!D13) | E13: ='試算-SLOT'!Q13 -> 0.002 | F13: 1 | G13: 2 | H13: 3 | I13: 4 | J13: 5 | K13: 6 | L13: 7 | M13: 8 | N13: 9 | O13: 10 | P13: 11 | Q13: 12 | R13: 13 | S13: 14 | T13: 15 | U13: 16 | V13: 17 | W13: 18 | X13: 19 | Y13: 20
A14: ='試算-SLOT'!A14 -> BDT | B14: ='試算-SLOT'!B14 -> ৳ | C14: ='試算-SLOT'!C14 -> 孟加拉塔卡 | D14: =IF('試算-SLOT'!D14=1,"",'試算-SLOT'!D14) | E14: ='試算-SLOT'!Q14 -> 0.002 | F14: 4 | G14: 6 | H14: 7 | I14: 9 | J14: 11 | K14: 13 | L14: 14 | M14: 16 | N14: 18 | O14: 19 | P14: 20 | Q14: 21 | R14: 22 | S14: 23 | T14: 24 | U14: 25 | V14: 26 | W14: 27 | X14: 28 | Y14: 29
A15: ='試算-SLOT'!A15 -> PKR | B15: ='試算-SLOT'!B15 -> ₨ | C15: ='試算-SLOT'!C15 -> 巴基斯坦盧比 | D15: =IF('試算-SLOT'!D15=1,"",'試算-SLOT'!D15) | E15: ='試算-SLOT'!Q15 -> 0.01 | F15: 3 | G15: 4 | H15: 6 | I15: 7 | J15: 9 | K15: 11 | L15: 13 | M15: 14 | N15: 16 | O15: 18 | P15: 19 | Q15: 20 | R15: 21 | S15: 22 | T15: 23 | U15: 24 | V15: 25 | W15: 26 | X15: 27 | Y15: 28
A16: ='試算-SLOT'!A16 -> MMK | B16: ='試算-SLOT'!B16 -> K | C16: ='試算-SLOT'!C16 -> 緬甸元(K) | D16: =IF('試算-SLOT'!D16=1,"",'試算-SLOT'!D16) -> 1000 | E16: ='試算-SLOT'!Q16 -> 0.002 | F16: 1 | G16: 2 | H16: 3 | I16: 4 | J16: 5 | K16: 6 | L16: 7 | M16: 8 | N16: 9 | O16: 10 | P16: 11 | Q16: 12 | R16: 13 | S16: 14 | T16: 15 | U16: 16 | V16: 18 | W16: 19 | X16: 20 | Y16: 21
A17: ='試算-SLOT'!A17 -> MMH | B17: ='試算-SLOT'!B17 -> K | C17: ='試算-SLOT'!C17 -> 緬甸元(H) | D17: =IF('試算-SLOT'!D17=1,"",'試算-SLOT'!D17) -> 100 | E17: ='試算-SLOT'!Q17 -> 0.004 | F17: 1 | G17: 2 | H17: 3 | I17: 4 | J17: 5 | K17: 6 | L17: 7 | M17: 8 | N17: 9 | O17: 11 | P17: 13 | Q17: 14 | R17: 16 | S17: 18 | T17: 19 | U17: 20 | V17: 21 | W17: 22 | X17: 23 | Y17: 24
... A55: ='試算-SLOT'!A55 -> XSMY | B55: ='試算-SLOT'!B55 | C55: ='試算-SLOT'!C55 -> 星城馬來西亞 | D55: =IF('試算-SLOT'!D55=1,"",'試算-SLOT'!D55) | E55: ='試算-SLOT'!Q55 -> 1 | F55: 1 | G55: 2 | H55: 3 | I55: 4 | J55: 5 | K55: 6 | L55: 7 | M55: 8 | N55: 9 | O55: 10 | P55: 11 | Q55: 13 | R55: 14 | S55: 16 | T55: 17 | U55: 18 | V55: 19 | W55: 20 | X55: 21 | Y55: 22
A58: =A5 -> 貨幣簡稱 | B58: =B5 -> 貨幣符號 | C58: =C5 -> 中文名稱 | D58: =D5 -> 貨幣轉換 | E58: =E5 -> Denom | F58: =F5 -> 第 1 組 | G58: =G5 -> 第 2 組 | H58: =H5 -> 第 3 組 | ... Y58: =Y5 -> 第 20 組 | AA58: 顯示金額
A59: =A6 -> THB | B59: =B6 -> ฿ | C59: =C6 -> 泰銖 | D59: =D6 | E59: =E6 -> 0.002 | F59: =HLOOKUP(F6,$F$1:$AI$2,2) * $D$1 * $E59 -> 0.88 | G59: =HLOOKUP(G6,$F$1:$AI$2,2) * $D$1 * $E59 -> 1.76 | H59: =HLOOKUP(H6,$F$1:$AI$2,2) * $D$1 * $E59 -> 3.52 | I59: =HLOOKUP(I6,$F$1:$AI$2,2) * $D$1 * $E59 -> 5.28 | J59: =HLOOKUP(J6,$F$1:$AI$2,2) * $D$1 * $E59 -> 7.04 | K59: =HLOOKUP(K6,$F$1:$AI$2,2) * $D$1 * $E59 -> 8.8 | L59: =HLOOKUP(L6,$F$1:$AI$2,2) * $D$1 * $E59 -> 17.6 | M59: =HLOOKUP(M6,$F$1:$AI$2,2) * $D$1 * $E59 -> 26.4 | ... Y59: =HLOOKUP(Y6,$F$1:$AI$2,2) * $D$1 * $E59 -> 528
A60: =A7 -> HKD | B60: =B7 -> HK$ | C60: =C7 -> 港幣 | D60: =D7 | E60: =E7 -> 0.002 | F60: =HLOOKUP(F7,$F$1:$AI$2,2) * $D$1 * $E60 -> 0.176 | G60: =HLOOKUP(G7,$F$1:$AI$2,2) * $D$1 * $E60 -> 0.352 | H60: =HLOOKUP(H7,$F$1:$AI$2,2) * $D$1 * $E60 -> 0.88 | I60: =HLOOKUP(I7,$F$1:$AI$2,2) * $D$1 * $E60 -> 1.76 | J60: =HLOOKUP(J7,$F$1:$AI$2,2) * $D$1 * $E60 -> 2.64 | K60: =HLOOKUP(K7,$F$1:$AI$2,2) * $D$1 * $E60 -> 3.52 | L60: =HLOOKUP(L7,$F$1:$AI$2,2) * $D$1 * $E60 -> 5.28 | M60: =HLOOKUP(M7,$F$1:$AI$2,2) * $D$1 * $E60 -> 7.04 | ... Y60: =HLOOKUP(Y7,$F$1:$AI$2,2) * $D$1 * $E60 -> 264
A61: =A8 -> INR | B61: =B8 -> ₹ | C61: =C8 -> 印度盧比 | D61: =D8 | E61: =E8 -> 0.002 | F61: =HLOOKUP(F8,$F$1:$AI$2,2) * $D$1 * $E61 -> 1.76 | G61: =HLOOKUP(G8,$F$1:$AI$2,2) * $D$1 * $E61 -> 3.52 | H61: =HLOOKUP(H8,$F$1:$AI$2,2) * $D$1 * $E61 -> 5.28 | I61: =HLOOKUP(I8,$F$1:$AI$2,2) * $D$1 * $E61 -> 8.8 | J61: =HLOOKUP(J8,$F$1:$AI$2,2) * $D$1 * $E61 -> 17.6 | K61: =HLOOKUP(K8,$F$1:$AI$2,2) * $D$1 * $E61 -> 26.4 | L61: =HLOOKUP(L8,$F$1:$AI$2,2) * $D$1 * $E61 -> 35.2 | M61: =HLOOKUP(M8,$F$1:$AI$2,2) * $D$1 * $E61 -> 52.8 | ... Y61: =HLOOKUP(Y8,$F$1:$AI$2,2) * $D$1 * $E61 -> 880
A62: =A9 -> IDR | B62: =B9 -> Rp | C62: =C9 -> 印尼盧比(K) | D62: =D9 -> 1000 | E62: =E9 -> 0.002 | F62: =HLOOKUP(F9,$F$1:$AI$2,2) * $D$1 * $E62 -> 0.352 | G62: =HLOOKUP(G9,$F$1:$AI$2,2) * $D$1 * $E62 -> 0.88 | H62: =HLOOKUP(H9,$F$1:$AI$2,2) * $D$1 * $E62 -> 1.76 | I62: =HLOOKUP(I9,$F$1:$AI$2,2) * $D$1 * $E62 -> 2.64 | J62: =HLOOKUP(J9,$F$1:$AI$2,2) * $D$1 * $E62 -> 3.52 | K62: =HLOOKUP(K9,$F$1:$AI$2,2) * $D$1 * $E62 -> 5.28 | L62: =HLOOKUP(L9,$F$1:$AI$2,2) * $D$1 * $E62 -> 7.04 | M62: =HLOOKUP(M9,$F$1:$AI$2,2) * $D$1 * $E62 -> 8.8 | ... Y62: =HLOOKUP(Y9,$F$1:$AI$2,2) * $D$1 * $E62 -> 308
A63: =A10 -> VND | B63: =B10 -> ₫ | C63: =C10 -> 越南盾(K) | D63: =D10 -> 1000 | E63: =E10 -> 0.002 | F63: =HLOOKUP(F10,$F$1:$AI$2,2) * $D$1 * $E63 -> 0.88 | G63: =HLOOKUP(G10,$F$1:$AI$2,2) * $D$1 * $E63 -> 1.76 | H63: =HLOOKUP(H10,$F$1:$AI$2,2) * $D$1 * $E63 -> 2.64 | I63: =HLOOKUP(I10,$F$1:$AI$2,2) * $D$1 * $E63 -> 3.52 | J63: =HLOOKUP(J10,$F$1:$AI$2,2) * $D$1 * $E63 -> 5.28 | K63: =HLOOKUP(K10,$F$1:$AI$2,2) * $D$1 * $E63 -> 7.04 | L63: =HLOOKUP(L10,$F$1:$AI$2,2) * $D$1 * $E63 -> 8.8 | M63: =HLOOKUP(M10,$F$1:$AI$2,2) * $D$1 * $E63 -> 17.6 | ... Y63: =HLOOKUP(Y10,$F$1:$AI$2,2) * $D$1 * $E63 -> 352
A64: =A11 -> MYR | B64: =B11 -> RM | C64: =C11 -> 馬來西亞令吉 | D64: =D11 | E64: =E11 -> 0.002 | F64: =HLOOKUP(F11,$F$1:$AI$2,2) * $D$1 * $E64 -> 0.176 | G64: =HLOOKUP(G11,$F$1:$AI$2,2) * $D$1 * $E64 -> 0.352 | H64: =HLOOKUP(H11,$F$1:$AI$2,2) * $D$1 * $E64 -> 0.88 | I64: =HLOOKUP(I11,$F$1:$AI$2,2) * $D$1 * $E64 -> 1.76 | J64: =HLOOKUP(J11,$F$1:$AI$2,2) * $D$1 * $E64 -> 2.64 | K64: =HLOOKUP(K11,$F$1:$AI$2,2) * $D$1 * $E64 -> 3.52 | L64: =HLOOKUP(L11,$F$1:$AI$2,2) * $D$1 * $E64 -> 5.28 | M64: =HLOOKUP(M11,$F$1:$AI$2,2) * $D$1 * $E64 -> 7.04 | ... Y64: =HLOOKUP(Y11,$F$1:$AI$2,2) * $D$1 * $E64 -> 176
A65: =A12 -> SGD | B65: =B12 -> S$ | C65: =C12 -> 新加坡幣 | D65: =D12 | E65: =E12 -> 0.002 | F65: =HLOOKUP(F12,$F$1:$AI$2,2) * $D$1 * $E65 -> 0.176 | G65: =HLOOKUP(G12,$F$1:$AI$2,2) * $D$1 * $E65 -> 0.352 | H65: =HLOOKUP(H12,$F$1:$AI$2,2) * $D$1 * $E65 -> 0.88 | I65: =HLOOKUP(I12,$F$1:$AI$2,2) * $D$1 * $E65 -> 1.76 | J65: =HLOOKUP(J12,$F$1:$AI$2,2) * $D$1 * $E65 -> 2.64 | K65: =HLOOKUP(K12,$F$1:$AI$2,2) * $D$1 * $E65 -> 3.52 | L65: =HLOOKUP(L12,$F$1:$AI$2,2) * $D$1 * $E65 -> 5.28 | M65: =HLOOKUP(M12,$F$1:$AI$2,2) * $D$1 * $E65 -> 7.04 | ... Y65: =HLOOKUP(Y12,$F$1:$AI$2,2) * $D$1 * $E65 -> 88
A66: =A13 -> USD | B66: =B13 -> $ | C66: =C13 -> 美元 | D66: =D13 | E66: =E13 -> 0.002 | F66: =HLOOKUP(F13,$F$1:$AI$2,2) * $D$1 * $E66 -> 0.176 | G66: =HLOOKUP(G13,$F$1:$AI$2,2) * $D$1 * $E66 -> 0.352 | H66: =HLOOKUP(H13,$F$1:$AI$2,2) * $D$1 * $E66 -> 0.88 | I66: =HLOOKUP(I13,$F$1:$AI$2,2) * $D$1 * $E66 -> 1.76 | J66: =HLOOKUP(J13,$F$1:$AI$2,2) * $D$1 * $E66 -> 2.64 | K66: =HLOOKUP(K13,$F$1:$AI$2,2) * $D$1 * $E66 -> 3.52 | L66: =HLOOKUP(L13,$F$1:$AI$2,2) * $D$1 * $E66 -> 5.28 | M66: =HLOOKUP(M13,$F$1:$AI$2,2) * $D$1 * $E66 -> 7.04 | ... Y66: =HLOOKUP(Y13,$F$1:$AI$2,2) * $D$1 * $E66 -> 88
A67: =A14 -> BDT | B67: =B14 -> ৳ | C67: =C14 -> 孟加拉塔卡 | D67: =D14 | E67: =E14 -> 0.002 | F67: =HLOOKUP(F14,$F$1:$AI$2,2) * $D$1 * $E67 -> 1.76 | G67: =HLOOKUP(G14,$F$1:$AI$2,2) * $D$1 * $E67 -> 3.52 | H67: =HLOOKUP(H14,$F$1:$AI$2,2) * $D$1 * $E67 -> 5.28 | I67: =HLOOKUP(I14,$F$1:$AI$2,2) * $D$1 * $E67 -> 8.8 | J67: =HLOOKUP(J14,$F$1:$AI$2,2) * $D$1 * $E67 -> 17.6 | K67: =HLOOKUP(K14,$F$1:$AI$2,2) * $D$1 * $E67 -> 26.4 | L67: =HLOOKUP(L14,$F$1:$AI$2,2) * $D$1 * $E67 -> 35.2 | M67: =HLOOKUP(M14,$F$1:$AI$2,2) * $D$1 * $E67 -> 52.8 | ... Y67: =HLOOKUP(Y14,$F$1:$AI$2,2) * $D$1 * $E67 -> 880
A68: =A15 -> PKR | B68: =B15 -> ₨ | C68: =C15 -> 巴基斯坦盧比 | D68: =D15 | E68: =E15 -> 0.01 | F68: =HLOOKUP(F15,$F$1:$AI$2,2) * $D$1 * $E68 -> 4.4 | G68: =HLOOKUP(G15,$F$1:$AI$2,2) * $D$1 * $E68 -> 8.8 | H68: =HLOOKUP(H15,$F$1:$AI$2,2) * $D$1 * $E68 -> 17.6 | I68: =HLOOKUP(I15,$F$1:$AI$2,2) * $D$1 * $E68 -> 26.4 | J68: =HLOOKUP(J15,$F$1:$AI$2,2) * $D$1 * $E68 -> 44 | K68: =HLOOKUP(K15,$F$1:$AI$2,2) * $D$1 * $E68 -> 88 | L68: =HLOOKUP(L15,$F$1:$AI$2,2) * $D$1 * $E68 -> 132 | M68: =HLOOKUP(M15,$F$1:$AI$2,2) * $D$1 * $E68 -> 176 | ... Y68: =HLOOKUP(Y15,$F$1:$AI$2,2) * $D$1 * $E68 -> 3520
A69: =A16 -> MMK | B69: =B16 -> K | C69: =C16 -> 緬甸元(K) | D69: =D16 -> 1000 | E69: =E16 -> 0.002 | F69: =HLOOKUP(F16,$F$1:$AI$2,2) * $D$1 * $E69 -> 0.176 | G69: =HLOOKUP(G16,$F$1:$AI$2,2) * $D$1 * $E69 -> 0.352 | H69: =HLOOKUP(H16,$F$1:$AI$2,2) * $D$1 * $E69 -> 0.88 | I69: =HLOOKUP(I16,$F$1:$AI$2,2) * $D$1 * $E69 -> 1.76 | J69: =HLOOKUP(J16,$F$1:$AI$2,2) * $D$1 * $E69 -> 2.64 | K69: =HLOOKUP(K16,$F$1:$AI$2,2) * $D$1 * $E69 -> 3.52 | L69: =HLOOKUP(L16,$F$1:$AI$2,2) * $D$1 * $E69 -> 5.28 | M69: =HLOOKUP(M16,$F$1:$AI$2,2) * $D$1 * $E69 -> 7.04 | ... Y69: =HLOOKUP(Y16,$F$1:$AI$2,2) * $D$1 * $E69 -> 105.6
A70: =A17 -> MMH | B70: =B17 -> K | C70: =C17 -> 緬甸元(H) | D70: =D17 -> 100 | E70: =E17 -> 0.004 | F70: =HLOOKUP(F17,$F$1:$AI$2,2) * $D$1 * $E70 -> 0.352 | G70: =HLOOKUP(G17,$F$1:$AI$2,2) * $D$1 * $E70 -> 0.704 | H70: =HLOOKUP(H17,$F$1:$AI$2,2) * $D$1 * $E70 -> 1.76 | I70: =HLOOKUP(I17,$F$1:$AI$2,2) * $D$1 * $E70 -> 3.52 | J70: =HLOOKUP(J17,$F$1:$AI$2,2) * $D$1 * $E70 -> 5.28 | K70: =HLOOKUP(K17,$F$1:$AI$2,2) * $D$1 * $E70 -> 7.04 | L70: =HLOOKUP(L17,$F$1:$AI$2,2) * $D$1 * $E70 -> 10.56 | M70: =HLOOKUP(M17,$F$1:$AI$2,2) * $D$1 * $E70 -> 14.08 | ... Y70: =HLOOKUP(Y17,$F$1:$AI$2,2) * $D$1 * $E70 -> 528
... A108: =A55 -> XSMY | B108: =B55 | C108: =C55 -> 星城馬來西亞 | D108: =D55 | E108: =E55 -> 1 | F108: =HLOOKUP(F55,$F$1:$AI$2,2) * $D$1 * $E108 -> 88 | G108: =HLOOKUP(G55,$F$1:$AI$2,2) * $D$1 * $E108 -> 176 | H108: =HLOOKUP(H55,$F$1:$AI$2,2) * $D$1 * $E108 -> 440 | I108: =HLOOKUP(I55,$F$1:$AI$2,2) * $D$1 * $E108 -> 880 | J108: =HLOOKUP(J55,$F$1:$AI$2,2) * $D$1 * $E108 -> 1320 | K108: =HLOOKUP(K55,$F$1:$AI$2,2) * $D$1 * $E108 -> 1760 | L108: =HLOOKUP(L55,$F$1:$AI$2,2) * $D$1 * $E108 -> 2640 | M108: =HLOOKUP(M55,$F$1:$AI$2,2) * $D$1 * $E108 -> 3520 | ... Y108: =HLOOKUP(Y55,$F$1:$AI$2,2) * $D$1 * $E108 -> 66000

Sheet 1041
C1: 最小押分 | D1: 1 | E1: 倍數 設定 | F1: 1 | G1: 2 | H1: 3 | I1: 4 | J1: 5 | K1: 6 | L1: 7 | M1: 8 | N1: 9 | O1: 10 | P1: 11 | Q1: 12 | R1: 13 | S1: 14 | T1: 15 | U1: 16 | V1: 17 | W1: 18 | X1: 19 | Y1: 20 | Z1: 21 | AA1: 22 | AB1: 23 | AC1: 24 | AD1: 25 | AE1: 26 | AF1: 27 | AG1: 28 | AH1: 29 | AI1: 30
F2: 1 | G2: 5 | H2: 10 | I2: 50 | J2: 100
A5: 貨幣簡稱 | B5: 貨幣符號 | C5: 中文名稱 | D5: 貨幣轉換 | E5: Denom | F5: 第 1 組 | G5: 第 2 組 | H5: 第 3 組 | I5: 第 4 組 | J5: 第 5 組 | K5: 第 6 組 | L5: 第 7 組 | M5: 第 8 組 | N5: 第 9 組 | O5: 第 10 組 | P5: 第 11 組 | Q5: 第 12 組 | R5: 第 13 組 | S5: 第 14 組 | T5: 第 15 組 | U5: 第 16 組 | V5: 第 17 組 | W5: 第 18 組 | X5: 第 19 組 | Y5: 第 20 組 | AA5: 顯示倍數組別
A6: ='試算-SLOT'!A6 -> THB | B6: ='試算-SLOT'!B6 -> ฿ | C6: ='試算-SLOT'!C6 -> 泰銖 | D6: =IF('試算-SLOT'!D6=1,"",'試算-SLOT'!D6) | E6: 1 | F6: 1 | G6: 2 | H6: 3 | I6: 4 | J6: 5
A7: ='試算-SLOT'!A7 -> HKD | B7: ='試算-SLOT'!B7 -> HK$ | C7: ='試算-SLOT'!C7 -> 港幣 | D7: =IF('試算-SLOT'!D7=1,"",'試算-SLOT'!D7) | E7: 1 | F7: 1 | G7: 2 | H7: 3 | I7: 4 | J7: 5
A8: ='試算-SLOT'!A8 -> INR | B8: ='試算-SLOT'!B8 -> ₹ | C8: ='試算-SLOT'!C8 -> 印度盧比 | D8: =IF('試算-SLOT'!D8=1,"",'試算-SLOT'!D8) | E8: 1 | F8: 1 | G8: 2 | H8: 3 | I8: 4 | J8: 5
A9: ='試算-SLOT'!A9 -> IDR | B9: ='試算-SLOT'!B9 -> Rp | C9: ='試算-SLOT'!C9 -> 印尼盧比(K) | D9: =IF('試算-SLOT'!D9=1,"",'試算-SLOT'!D9) -> 1000 | E9: 1 | F9: 1 | G9: 2 | H9: 3 | I9: 4 | J9: 5
A10: ='試算-SLOT'!A10 -> VND | B10: ='試算-SLOT'!B10 -> ₫ | C10: ='試算-SLOT'!C10 -> 越南盾(K) | D10: =IF('試算-SLOT'!D10=1,"",'試算-SLOT'!D10) -> 1000 | E10: 1 | F10: 1 | G10: 2 | H10: 3 | I10: 4 | J10: 5
A11: ='試算-SLOT'!A11 -> MYR | B11: ='試算-SLOT'!B11 -> RM | C11: ='試算-SLOT'!C11 -> 馬來西亞令吉 | D11: =IF('試算-SLOT'!D11=1,"",'試算-SLOT'!D11) | E11: 1 | F11: 1 | G11: 2 | H11: 3 | I11: 4 | J11: 5
A12: ='試算-SLOT'!A12 -> SGD | B12: ='試算-SLOT'!B12 -> S$ | C12: ='試算-SLOT'!C12 -> 新加坡幣 | D12: =IF('試算-SLOT'!D12=1,"",'試算-SLOT'!D12) | E12: 1 | F12: 1 | G12: 2 | H12: 3 | I12: 4 | J12: 5
A13: ='試算-SLOT'!A13 -> USD | B13: ='試算-SLOT'!B13 -> $ | C13: ='試算-SLOT'!C13 -> 美元 | D13: =IF('試算-SLOT'!D13=1,"",'試算-SLOT'!D13) | E13: 1 | F13: 1 | G13: 2 | H13: 3 | I13: 4 | J13: 5
A14: ='試算-SLOT'!A14 -> BDT | B14: ='試算-SLOT'!B14 -> ৳ | C14: ='試算-SLOT'!C14 -> 孟加拉塔卡 | D14: =IF('試算-SLOT'!D14=1,"",'試算-SLOT'!D14) | E14: 1 | F14: 1 | G14: 2 | H14: 3 | I14: 4 | J14: 5
A15: ='試算-SLOT'!A15 -> PKR | B15: ='試算-SLOT'!B15 -> ₨ | C15: ='試算-SLOT'!C15 -> 巴基斯坦盧比 | D15: =IF('試算-SLOT'!D15=1,"",'試算-SLOT'!D15) | E15: 1 | F15: 1 | G15: 2 | H15: 3 | I15: 4 | J15: 5
A16: ='試算-SLOT'!A16 -> MMK | B16: ='試算-SLOT'!B16 -> K | C16: ='試算-SLOT'!C16 -> 緬甸元(K) | D16: =IF('試算-SLOT'!D16=1,"",'試算-SLOT'!D16) -> 1000 | E16: 1 | F16: 1 | G16: 2 | H16: 3 | I16: 4 | J16: 5
A17: ='試算-SLOT'!A17 -> MMH | B17: ='試算-SLOT'!B17 -> K | C17: ='試算-SLOT'!C17 -> 緬甸元(H) | D17: =IF('試算-SLOT'!D17=1,"",'試算-SLOT'!D17) -> 100 | E17: 1 | F17: 1 | G17: 2 | H17: 3 | I17: 4 | J17: 5
... A55: ='試算-SLOT'!A55 -> XSMY | B55: ='試算-SLOT'!B55 | C55: ='試算-SLOT'!C55 -> 星城馬來西亞 | D55: =IF('試算-SLOT'!D55=1,"",'試算-SLOT'!D55) | E55: 1 | F55: 1 | G55: 2 | H55: 3 | I55: 4 | J55: 5
A58: =A5 -> 貨幣簡稱 | B58: =B5 -> 貨幣符號 | C58: =C5 -> 中文名稱 | D58: =D5 -> 貨幣轉換 | E58: =E5 -> Denom | F58: =F5 -> 第 1 組 | G58: =G5 -> 第 2 組 | H58: =H5 -> 第 3 組 | ... Y58: =Y5 -> 第 20 組 | AA58: 顯示金額
A59: =A6 -> THB | B59: =B6 -> ฿ | C59: =C6 -> 泰銖 | D59: =D6 | E59: =E6 -> 1 | F59: =HLOOKUP(F6,$F$1:$AI$2,2) * $D$1 * $E59 -> 1 | G59: =HLOOKUP(G6,$F$1:$AI$2,2) * $D$1 * $E59 -> 5 | H59: =HLOOKUP(H6,$F$1:$AI$2,2) * $D$1 * $E59 -> 10 | I59: =HLOOKUP(I6,$F$1:$AI$2,2) * $D$1 * $E59 -> 50 | J59: =HLOOKUP(J6,$F$1:$AI$2,2) * $D$1 * $E59 -> 100
A60: =A7 -> HKD | B60: =B7 -> HK$ | C60: =C7 -> 港幣 | D60: =D7 | E60: =E7 -> 1 | F60: =HLOOKUP(F7,$F$1:$AI$2,2) * $D$1 * $E60 -> 1 | G60: =HLOOKUP(G7,$F$1:$AI$2,2) * $D$1 * $E60 -> 5 | H60: =HLOOKUP(H7,$F$1:$AI$2,2) * $D$1 * $E60 -> 10 | I60: =HLOOKUP(I7,$F$1:$AI$2,2) * $D$1 * $E60 -> 50 | J60: =HLOOKUP(J7,$F$1:$AI$2,2) * $D$1 * $E60 -> 100
A61: =A8 -> INR | B61: =B8 -> ₹ | C61: =C8 -> 印度盧比 | D61: =D8 | E61: =E8 -> 1 | F61: =HLOOKUP(F8,$F$1:$AI$2,2) * $D$1 * $E61 -> 1 | G61: =HLOOKUP(G8,$F$1:$AI$2,2) * $D$1 * $E61 -> 5 | H61: =HLOOKUP(H8,$F$1:$AI$2,2) * $D$1 * $E61 -> 10 | I61: =HLOOKUP(I8,$F$1:$AI$2,2) * $D$1 * $E61 -> 50 | J61: =HLOOKUP(J8,$F$1:$AI$2,2) * $D$1 * $E61 -> 100
A62: =A9 -> IDR | B62: =B9 -> Rp | C62: =C9 -> 印尼盧比(K) | D62: =D9 -> 1000 | E62: =E9 -> 1 | F62: =HLOOKUP(F9,$F$1:$AI$2,2) * $D$1 * $E62 -> 1 | G62: =HLOOKUP(G9,$F$1:$AI$2,2) * $D$1 * $E62 -> 5 | H62: =HLOOKUP(H9,$F$1:$AI$2,2) * $D$1 * $E62 -> 10 | I62: =HLOOKUP(I9,$F$1:$AI$2,2) * $D$1 * $E62 -> 50 | J62: =HLOOKUP(J9,$F$1:$AI$2,2) * $D$1 * $E62 -> 100
A63: =A10 -> VND | B63: =B10 -> ₫ | C63: =C10 -> 越南盾(K) | D63: =D10 -> 1000 | E63: =E10 -> 1 | F63: =HLOOKUP(F10,$F$1:$AI$2,2) * $D$1 * $E63 -> 1 | G63: =HLOOKUP(G10,$F$1:$AI$2,2) * $D$1 * $E63 -> 5 | H63: =HLOOKUP(H10,$F$1:$AI$2,2) * $D$1 * $E63 -> 10 | I63: =HLOOKUP(I10,$F$1:$AI$2,2) * $D$1 * $E63 -> 50 | J63: =HLOOKUP(J10,$F$1:$AI$2,2) * $D$1 * $E63 -> 100
A64: =A11 -> MYR | B64: =B11 -> RM | C64: =C11 -> 馬來西亞令吉 | D64: =D11 | E64: =E11 -> 1 | F64: =HLOOKUP(F11,$F$1:$AI$2,2) * $D$1 * $E64 -> 1 | G64: =HLOOKUP(G11,$F$1:$AI$2,2) * $D$1 * $E64 -> 5 | H64: =HLOOKUP(H11,$F$1:$AI$2,2) * $D$1 * $E64 -> 10 | I64: =HLOOKUP(I11,$F$1:$AI$2,2) * $D$1 * $E64 -> 50 | J64: =HLOOKUP(J11,$F$1:$AI$2,2) * $D$1 * $E64 -> 100
A65: =A12 -> SGD | B65: =B12 -> S$ | C65: =C12 -> 新加坡幣 | D65: =D12 | E65: =E12 -> 1 | F65: =HLOOKUP(F12,$F$1:$AI$2,2) * $D$1 * $E65 -> 1 | G65: =HLOOKUP(G12,$F$1:$AI$2,2) * $D$1 * $E65 -> 5 | H65: =HLOOKUP(H12,$F$1:$AI$2,2) * $D$1 * $E65 -> 10 | I65: =HLOOKUP(I12,$F$1:$AI$2,2) * $D$1 * $E65 -> 50 | J65: =HLOOKUP(J12,$F$1:$AI$2,2) * $D$1 * $E65 -> 100
A66: =A13 -> USD | B66: =B13 -> $ | C66: =C13 -> 美元 | D66: =D13 | E66: =E13 -> 1 | F66: =HLOOKUP(F13,$F$1:$AI$2,2) * $D$1 * $E66 -> 1 | G66: =HLOOKUP(G13,$F$1:$AI$2,2) * $D$1 * $E66 -> 5 | H66: =HLOOKUP(H13,$F$1:$AI$2,2) * $D$1 * $E66 -> 10 | I66: =HLOOKUP(I13,$F$1:$AI$2,2) * $D$1 * $E66 -> 50 | J66: =HLOOKUP(J13,$F$1:$AI$2,2) * $D$1 * $E66 -> 100
A67: =A14 -> BDT | B67: =B14 -> ৳ | C67: =C14 -> 孟加拉塔卡 | D67: =D14 | E67: =E14 -> 1 | F67: =HLOOKUP(F14,$F$1:$AI$2,2) * $D$1 * $E67 -> 1 | G67: =HLOOKUP(G14,$F$1:$AI$2,2) * $D$1 * $E67 -> 5 | H67: =HLOOKUP(H14,$F$1:$AI$2,2) * $D$1 * $E67 -> 10 | I67: =HLOOKUP(I14,$F$1:$AI$2,2) * $D$1 * $E67 -> 50 | J67: =HLOOKUP(J14,$F$1:$AI$2,2) * $D$1 * $E67 -> 100
A68: =A15 -> PKR | B68: =B15 -> ₨ | C68: =C15 -> 巴基斯坦盧比 | D68: =D15 | E68: =E15 -> 1 | F68: =HLOOKUP(F15,$F$1:$AI$2,2) * $D$1 * $E68 -> 1 | G68: =HLOOKUP(G15,$F$1:$AI$2,2) * $D$1 * $E68 -> 5 | H68: =HLOOKUP(H15,$F$1:$AI$2,2) * $D$1 * $E68 -> 10 | I68: =HLOOKUP(I15,$F$1:$AI$2,2) * $D$1 * $E68 -> 50 | J68: =HLOOKUP(J15,$F$1:$AI$2,2) * $D$1 * $E68 -> 100
A69: =A16 -> MMK | B69: =B16 -> K | C69: =C16 -> 緬甸元(K) | D69: =D16 -> 1000 | E69: =E16 -> 1 | F69: =HLOOKUP(F16,$F$1:$AI$2,2) * $D$1 * $E69 -> 1 | G69: =HLOOKUP(G16,$F$1:$AI$2,2) * $D$1 * $E69 -> 5 | H69: =HLOOKUP(H16,$F$1:$AI$2,2) * $D$1 * $E69 -> 10 | I69: =HLOOKUP(I16,$F$1:$AI$2,2) * $D$1 * $E69 -> 50 | J69: =HLOOKUP(J16,$F$1:$AI$2,2) * $D$1 * $E69 -> 100
A70: =A17 -> MMH | B70: =B17 -> K | C70: =C17 -> 緬甸元(H) | D70: =D17 -> 100 | E70: =E17 -> 1 | F70: =HLOOKUP(F17,$F$1:$AI$2,2) * $D$1 * $E70 -> 1 | G70: =HLOOKUP(G17,$F$1:$AI$2,2) * $D$1 * $E70 -> 5 | H70: =HLOOKUP(H17,$F$1:$AI$2,2) * $D$1 * $E70 -> 10 | I70: =HLOOKUP(I17,$F$1:$AI$2,2) * $D$1 * $E70 -> 50 | J70: =HLOOKUP(J17,$F$1:$AI$2,2) * $D$1 * $E70 -> 100
... A108: =A55 -> XSMY | B108: =B55 | C108: =C55 -> 星城馬來西亞 | D108: =D55 | E108: =E55 -> 1 | F108: =HLOOKUP(F55,$F$1:$AI$2,2) * $D$1 * $E108 -> 1 | G108: =HLOOKUP(G55,$F$1:$AI$2,2) * $D$1 * $E108 -> 5 | H108: =HLOOKUP(H55,$F$1:$AI$2,2) * $D$1 * $E108 -> 10 | I108: =HLOOKUP(I55,$F$1:$AI$2,2) * $D$1 * $E108 -> 50 | J108: =HLOOKUP(J55,$F$1:$AI$2,2) * $D$1 * $E108 -> 100

Sheet 1043
C1: 最小押分 | D1: 100 | E1: 倍數 設定 | F1: 1 | G1: 2 | H1: 3 | I1: 4 | J1: 5 | K1: 6 | L1: 7 | M1: 8 | N1: 9 | O1: 10 | P1: 11 | Q1: 12 | R1: 13 | S1: 14 | T1: 15 | U1: 16 | V1: 17 | W1: 18 | X1: 19 | Y1: 20 | Z1: 21 | AA1: 22 | AB1: 23 | AC1: 24 | AD1: 25 | AE1: 26 | AF1: 27 | AG1: 28 | AH1: 29 | AI1: 30
F2: 1 | G2: 2 | H2: 5 | I2: 10 | J2: 12 | K2: 15 | L2: 20 | M2: 25 | N2: 30 | O2: 35 | P2: 40 | Q2: 45 | R2: 50 | S2: 60 | T2: 70 | U2: 80 | V2: 90 | W2: 100 | X2: 150 | Y2: 200 | Z2: 300 | AA2: 500 | AB2: 1000 | AC2: 1500 | AD2: 3000 | AE2: 5000 | AF2: 7500 | AG2: 10000 | AH2: 15000 | AI2: 25000
A5: 貨幣簡稱 | B5: 貨幣符號 | C5: 中文名稱 | D5: 貨幣轉換 | E5: Denom | F5: 第 1 組 | G5: 第 2 組 | H5: 第 3 組 | I5: 第 4 組 | J5: 第 5 組 | K5: 第 6 組 | L5: 第 7 組 | M5: 第 8 組 | N5: 第 9 組 | O5: 第 10 組 | P5: 第 11 組 | Q5: 第 12 組 | R5: 第 13 組 | S5: 第 14 組 | T5: 第 15 組 | U5: 第 16 組 | V5: 第 17 組 | W5: 第 18 組 | X5: 第 19 組 | Y5: 第 20 組 | AA5: 顯示倍數組別
A6: ='試算-SLOT'!A6 -> THB | B6: ='試算-SLOT'!B6 -> ฿ | C6: ='試算-SLOT'!C6 -> 泰銖 | D6: =IF('試算-SLOT'!D6=1,"",'試算-SLOT'!D6) | E6: ='試算-SLOT'!G6 -> 0.002 | F6: 3 | G6: 4 | H6: 6 | I6: 7 | J6: 8 | K6: 9 | L6: 11 | M6: 13 | N6: 14 | O6: 16 | P6: 18 | Q6: 19 | R6: 20 | S6: 21 | T6: 22 | U6: 23 | V6: 24 | W6: 25 | X6: 26 | Y6: 27
A7: ='試算-SLOT'!A7 -> HKD | B7: ='試算-SLOT'!B7 -> HK$ | C7: ='試算-SLOT'!C7 -> 港幣 | D7: =IF('試算-SLOT'!D7=1,"",'試算-SLOT'!D7) | E7: ='試算-SLOT'!G7 -> 0.002 | F7: 1 | G7: 2 | H7: 3 | I7: 4 | J7: 5 | K7: 6 | L7: 7 | M7: 8 | N7: 9 | O7: 11 | P7: 13 | Q7: 14 | R7: 16 | S7: 18 | T7: 19 | U7: 20 | V7: 21 | W7: 22 | X7: 23 | Y7: 24
A8: ='試算-SLOT'!A8 -> INR | B8: ='試算-SLOT'!B8 -> ₹ | C8: ='試算-SLOT'!C8 -> 印度盧比 | D8: =IF('試算-SLOT'!D8=1,"",'試算-SLOT'!D8) | E8: ='試算-SLOT'!G8 -> 0.002 | F8: 4 | G8: 6 | H8: 7 | I8: 9 | J8: 11 | K8: 13 | L8: 14 | M8: 16 | N8: 18 | O8: 19 | P8: 20 | Q8: 21 | R8: 22 | S8: 23 | T8: 24 | U8: 25 | V8: 26 | W8: 27 | X8: 28 | Y8: 29
A9: ='試算-SLOT'!A9 -> IDR | B9: ='試算-SLOT'!B9 -> Rp | C9: ='試算-SLOT'!C9 -> 印尼盧比(K) | D9: =IF('試算-SLOT'!D9=1,"",'試算-SLOT'!D9) -> 1000 | E9: ='試算-SLOT'!G9 -> 0.002 | F9: 2 | G9: 3 | H9: 4 | I9: 5 | J9: 6 | K9: 7 | L9: 8 | M9: 9 | N9: 11 | O9: 13 | P9: 14 | Q9: 16 | R9: 18 | S9: 19 | T9: 20 | U9: 21 | V9: 22 | W9: 23 | X9: 24 | Y9: 25
A10: ='試算-SLOT'!A10 -> VND | B10: ='試算-SLOT'!B10 -> ₫ | C10: ='試算-SLOT'!C10 -> 越南盾(K) | D10: =IF('試算-SLOT'!D10=1,"",'試算-SLOT'!D10) -> 1000 | E10: ='試算-SLOT'!G10 -> 0.002 | F10: 3 | G10: 4 | H10: 5 | I10: 6 | J10: 7 | K10: 8 | L10: 9 | M10: 11 | N10: 13 | O10: 14 | P10: 16 | Q10: 18 | R10: 19 | S10: 20 | T10: 21 | U10: 22 | V10: 23 | W10: 24 | X10: 25 | Y10: 26
A11: ='試算-SLOT'!A11 -> MYR | B11: ='試算-SLOT'!B11 -> RM | C11: ='試算-SLOT'!C11 -> 馬來西亞令吉 | D11: =IF('試算-SLOT'!D11=1,"",'試算-SLOT'!D11) | E11: ='試算-SLOT'!G11 -> 0.002 | F11: 1 | G11: 2 | H11: 3 | I11: 4 | J11: 5 | K11: 6 | L11: 7 | M11: 8 | N11: 9 | O11: 10 | P11: 11 | Q11: 13 | R11: 14 | S11: 16 | T11: 18 | U11: 19 | V11: 20 | W11: 21 | X11: 22 | Y11: 23
A12: ='試算-SLOT'!A12 -> SGD | B12: ='試算-SLOT'!B12 -> S$ | C12: ='試算-SLOT'!C12 -> 新加坡幣 | D12: =IF('試算-SLOT'!D12=1,"",'試算-SLOT'!D12) | E12: ='試算-SLOT'!G12 -> 0.002 | F12: 1 | G12: 2 | H12: 3 | I12: 4 | J12: 5 | K12: 6 | L12: 7 | M12: 8 | N12: 9 | O12: 10 | P12: 11 | Q12: 12 | R12: 13 | S12: 14 | T12: 15 | U12: 16 | V12: 17 | W12: 18 | X12: 19 | Y12: 20
A13: ='試算-SLOT'!A13 -> USD | B13: ='試算-SLOT'!B13 -> $ | C13: ='試算-SLOT'!C13 -> 美元 | D13: =IF('試算-SLOT'!D13=1,"",'試算-SLOT'!D13) | E13: ='試算-SLOT'!G13 -> 0.002 | F13: 1 | G13: 2 | H13: 3 | I13: 4 | J13: 5 | K13: 6 | L13: 7 | M13: 8 | N13: 9 | O13: 10 | P13: 11 | Q13: 12 | R13: 13 | S13: 14 | T13: 15 | U13: 16 | V13: 17 | W13: 18 | X13: 19 | Y13: 20
A14: ='試算-SLOT'!A14 -> BDT | B14: ='試算-SLOT'!B14 -> ৳ | C14: ='試算-SLOT'!C14 -> 孟加拉塔卡 | D14: =IF('試算-SLOT'!D14=1,"",'試算-SLOT'!D14) | E14: ='試算-SLOT'!G14 -> 0.002 | F14: 4 | G14: 6 | H14: 7 | I14: 9 | J14: 11 | K14: 13 | L14: 14 | M14: 16 | N14: 18 | O14: 19 | P14: 20 | Q14: 21 | R14: 22 | S14: 23 | T14: 24 | U14: 25 | V14: 26 | W14: 27 | X14: 28 | Y14: 29
A15: ='試算-SLOT'!A15 -> PKR | B15: ='試算-SLOT'!B15 -> ₨ | C15: ='試算-SLOT'!C15 -> 巴基斯坦盧比 | D15: =IF('試算-SLOT'!D15=1,"",'試算-SLOT'!D15) | E15: ='試算-SLOT'!G15 -> 0.01 | F15: 3 | G15: 4 | H15: 6 | I15: 7 | J15: 9 | K15: 11 | L15: 13 | M15: 14 | N15: 16 | O15: 18 | P15: 19 | Q15: 20 | R15: 21 | S15: 22 | T15: 23 | U15: 24 | V15: 25 | W15: 26 | X15: 27 | Y15: 28
A16: ='試算-SLOT'!A16 -> MMK | B16: ='試算-SLOT'!B16 -> K | C16: ='試算-SLOT'!C16 -> 緬甸元(K) | D16: =IF('試算-SLOT'!D16=1,"",'試算-SLOT'!D16) -> 1000 | E16: ='試算-SLOT'!G16 -> 0.002 | F16: 1 | G16: 2 | H16: 3 | I16: 4 | J16: 5 | K16: 6 | L16: 7 | M16: 8 | N16: 9 | O16: 10 | P16: 11 | Q16: 12 | R16: 13 | S16: 14 | T16: 15 | U16: 16 | V16: 18 | W16: 19 | X16: 20 | Y16: 21
A17: ='試算-SLOT'!A17 -> MMH | B17: ='試算-SLOT'!B17 -> K | C17: ='試算-SLOT'!C17 -> 緬甸元(H) | D17: =IF('試算-SLOT'!D17=1,"",'試算-SLOT'!D17) -> 100 | E17: ='試算-SLOT'!G17 -> 0.004 | F17: 1 | G17: 2 | H17: 3 | I17: 4 | J17: 5 | K17: 6 | L17: 7 | M17: 8 | N17: 9 | O17: 11 | P17: 13 | Q17: 14 | R17: 16 | S17: 18 | T17: 19 | U17: 20 | V17: 21 | W17: 22 | X17: 23 | Y17: 24
... A55: ='試算-SLOT'!A55 -> XSMY | B55: ='試算-SLOT'!B55 | C55: ='試算-SLOT'!C55 -> 星城馬來西亞 | D55: =IF('試算-SLOT'!D55=1,"",'試算-SLOT'!D55) | E55: ='試算-SLOT'!G55 -> 1 | F55: 1 | G55: 2 | H55: 3 | I55: 4 | J55: 5 | K55: 6 | L55: 7 | M55: 8 | N55: 9 | O55: 10 | P55: 11 | Q55: 13 | R55: 14 | S55: 16 | T55: 17 | U55: 18 | V55: 19 | W55: 20 | X55: 21 | Y55: 22
A57: Normal Bet (100)
A58: =A5 -> 貨幣簡稱 | B58: =B5 -> 貨幣符號 | C58: =C5 -> 中文名稱 | D58: =D5 -> 貨幣轉換 | E58: =E5 -> Denom | F58: =F5 -> 第 1 組 | G58: =G5 -> 第 2 組 | H58: =H5 -> 第 3 組 | ... Y58: =Y5 -> 第 20 組 | AA58: 顯示金額
A59: =A6 -> THB | B59: =B6 -> ฿ | C59: =C6 -> 泰銖 | D59: =D6 | E59: =E6 -> 0.002 | F59: =HLOOKUP(F6,$F$1:$AI$2,2) * $D$1 * $E59 -> 1 | G59: =HLOOKUP(G6,$F$1:$AI$2,2) * $D$1 * $E59 -> 2 | H59: =HLOOKUP(H6,$F$1:$AI$2,2) * $D$1 * $E59 -> 3 | I59: =HLOOKUP(I6,$F$1:$AI$2,2) * $D$1 * $E59 -> 4 | J59: =HLOOKUP(J6,$F$1:$AI$2,2) * $D$1 * $E59 -> 5 | K59: =HLOOKUP(K6,$F$1:$AI$2,2) * $D$1 * $E59 -> 6 | L59: =HLOOKUP(L6,$F$1:$AI$2,2) * $D$1 * $E59 -> 8 | M59: =HLOOKUP(M6,$F$1:$AI$2,2) * $D$1 * $E59 -> 10 | ... Y59: =HLOOKUP(Y6,$F$1:$AI$2,2) * $D$1 * $E59 -> 1500
A60: =A7 -> HKD | B60: =B7 -> HK$ | C60: =C7 -> 港幣 | D60: =D7 | E60: =E7 -> 0.002 | F60: =HLOOKUP(F7,$F$1:$AI$2,2) * $D$1 * $E60 -> 0.2 | G60: =HLOOKUP(G7,$F$1:$AI$2,2) * $D$1 * $E60 -> 0.4 | H60: =HLOOKUP(H7,$F$1:$AI$2,2) * $D$1 * $E60 -> 1 | I60: =HLOOKUP(I7,$F$1:$AI$2,2) * $D$1 * $E60 -> 2 | J60: =HLOOKUP(J7,$F$1:$AI$2,2) * $D$1 * $E60 -> 2.4 | K60: =HLOOKUP(K7,$F$1:$AI$2,2) * $D$1 * $E60 -> 3 | L60: =HLOOKUP(L7,$F$1:$AI$2,2) * $D$1 * $E60 -> 4 | M60: =HLOOKUP(M7,$F$1:$AI$2,2) * $D$1 * $E60 -> 5 | ... Y60: =HLOOKUP(Y7,$F$1:$AI$2,2) * $D$1 * $E60 -> 300
A61: =A8 -> INR | B61: =B8 -> ₹ | C61: =C8 -> 印度盧比 | D61: =D8 | E61: =E8 -> 0.002 | F61: =HLOOKUP(F8,$F$1:$AI$2,2) * $D$1 * $E61 -> 2 | G61: =HLOOKUP(G8,$F$1:$AI$2,2) * $D$1 * $E61 -> 3 | H61: =HLOOKUP(H8,$F$1:$AI$2,2) * $D$1 * $E61 -> 4 | I61: =HLOOKUP(I8,$F$1:$AI$2,2) * $D$1 * $E61 -> 6 | J61: =HLOOKUP(J8,$F$1:$AI$2,2) * $D$1 * $E61 -> 8 | K61: =HLOOKUP(K8,$F$1:$AI$2,2) * $D$1 * $E61 -> 10 | L61: =HLOOKUP(L8,$F$1:$AI$2,2) * $D$1 * $E61 -> 12 | M61: =HLOOKUP(M8,$F$1:$AI$2,2) * $D$1 * $E61 -> 16 | ... Y61: =HLOOKUP(Y8,$F$1:$AI$2,2) * $D$1 * $E61 -> 3000
