Workbook

Sheet Overview
A2: Model: | B2: H0161
A3: Version: | B3: 8
A6: Base Bet | B6: Multiway
A7: 100 | B7: =PRODUCT(B17:F17) -> 1024
A10: Coin in | B10: Price(x) | C10: Bet Type
A11: =A7*B11 -> 100 | B11: 1 | C11: Normal Bet
A12: =A7*B12 -> 4050 | B12: 40.5 | C12: Buy Feature
A13: =A7*B13 -> 25000 | B13: 250 | C13: Super Feature
A16: Reel # | B16: 1 | C16: 2 | D16: 3 | E16: 4 | F16: 5
A17: Visible Window Size | B17: 4 | C17: 4 | D17: 4 | E17: 4 | F17: 4
A20: Free Spins Setting
A21: C1 Num | B21: Initial Free Spins | C21: Retrigger
A22: 3 | B22: 10 | C22: 5
A23: 4 | B23: 10 | C23: 5
A24: 5 | B24: 10 | C24: 5
A25: The maximum of free spins is 50.
A28: Pay Table： | B28: ="All wins show for "&A7&" credit bet." -> All wins show for 100 credit bet.
A29: Symbol | B29: Description | C29: 1 | D29: 2 | E29: 3 | F29: 4 | G29: 5 | H29: Id
A30: WW | B30: Wild | C30: 0 | D30: 0 | E30: 0 | F30: 0 | G30: 0 | H30: 0
A31: W2 | B31: Super Wild | C31: 0 | D31: 0 | E31: 0 | F31: 0 | G31: 0 | H31: 1
A32: C1 | B32: Scatter | C32: 0 | D32: 0 | E32: 0 | F32: 0 | G32: 0 | H32: 2
A33: M1 | B33: M1 | C33: 0 | D33: 0 | E33: 50 | F33: 150 | G33: 250 | H33: 3
A34: M2 | B34: M2 | C34: 0 | D34: 0 | E34: 40 | F34: 120 | G34: 200 | H34: 4
A35: M3 | B35: M3 | C35: 0 | D35: 0 | E35: 30 | F35: 90 | G35: 150 | H35: 5
A36: M4 | B36: M4 | C36: 0 | D36: 0 | E36: 20 | F36: 60 | G36: 100 | H36: 6
A37: A | B37: A | C37: 0 | D37: 0 | E37: 10 | F37: 30 | G37: 50 | H37: 7
A38: K | B38: K | C38: 0 | D38: 0 | E38: 10 | F38: 30 | G38: 50 | H38: 8
A39: Q | B39: Q | C39: 0 | D39: 0 | E39: 5 | F39: 15 | G39: 25 | H39: 9
A40: J | B40: J | C40: 0 | D40: 0 | E40: 5 | F40: 15 | G40: 25 | H40: 10
A41: G1 | B41: Golden M1 | C41: 0 | D41: 0 | E41: 50 | F41: 150 | G41: 250 | H41: 11
... A48: GJ | B48: Golden J | C48: 0 | D48: 0 | E48: 5 | F48: 15 | G48: 25 | H48: 18

Sheet Parameter
B2: Table Selection Weight - Base Game (Weight/Total)
B3: Worksheet Name | C3: Weight
B4: BG_Symbol | C4: 450000 | D4: {=C4:C6/SUM(C4:C6)} -> 0.45
B5: BG_Symbol (2) | C5: 50000 | D5: 0.05
B6: BG_Symbol (3) | C6: 500000 | D6: 0.5
B9: Table Selection Weight - Free Game (Weight/Total)
B10: Worksheet Name | C10: Weight
B11: FG_Symbol | C11: 0
B12: FG_Symbol (2) | C12: 6500
B13: FG_Symbol (3) | C13: 3500
B16: Table Selection Weight - Retrigger (Weight/Total)
B17: Worksheet Name | C17: Weight
B18: FG_Symbol | C18: 0
B19: FG_Symbol (2) | C19: 6500
B20: FG_Symbol (3) | C20: 3500
B23: Table Selection Weight - SF Free Game (Weight/Total)
B24: Worksheet Name | C24: Weight
B25: SF_Symbol | C25: 0
B26: SF_Symbol (2) | C26: 5500
B27: SF_Symbol (3) | C27: 4500
B30: Table Selection Weight - SF Retrigger (Weight/Total)
B31: Worksheet Name | C31: Weight
B32: SF_Symbol | C32: 0
B33: SF_Symbol (2) | C33: 5500
B34: SF_Symbol (3) | C34: 4500

Sheet BG_Symbol
J2: Symbol | Q2: Symbol ID | W2: Symbol Weight | AC2: Random Wild Trigger Weight | AF2: Symbol Drop Weight
A3: Symbol | B3: Description | C3: R1 | D3: R2 | E3: R3 | F3: R4 | G3: R5 | H3: ID | J3: Line # | K3: R1 | L3: R2 | M3: R3 | N3: R4 | O3: R5 | Q3: R1 | R3: R2 | S3: R3 | T3: R4 | U3: R5 | W3: R1 | X3: R2 | Y3: R3 | Z3: R4 | AA3: R5 | AC3: Random Wild | AD3: Weight | AF3: Symbol | AG3: R1 | AH3: R2 | AI3: R3 | AJ3: R4 | AK3: R5
A4: {=Overview!A30:A48} -> WW | B4: {=Overview!B30:B48} -> Wild | C4: =COUNTIF(K:K,$A4) -> 0 | D4: =COUNTIF(L:L,$A4) -> 0 | E4: =COUNTIF(M:M,$A4) -> 0 | F4: =COUNTIF(N:N,$A4) -> 0 | G4: =COUNTIF(O:O,$A4) -> 0 | H4: {=Overview!H30:H48} -> 0 | J4: 0 | K4: M4 | L4: M1 | M4: J | N4: K | O4: M2 | Q4: =IF(K4="","",VLOOKUP(K4,$A$4:$H$22,8,FALSE)) -> 6 | R4: =IF(L4="","",VLOOKUP(L4,$A$4:$H$22,8,FALSE)) -> 3 | S4: =IF(M4="","",VLOOKUP(M4,$A$4:$H$22,8,FALSE)) -> 10 | T4: =IF(N4="","",VLOOKUP(N4,$A$4:$H$22,8,FALSE)) -> 8 | U4: =IF(O4="","",VLOOKUP(O4,$A$4:$H$22,8,FALSE)) -> 4 | W4: 12571 | X4: 11024 | Y4: 0 | Z4: 12985 | AA4: 12527 | AC4: 0 | AD4: 21860 | AF4: WW | AG4: 0 | AH4: 0 | AI4: 0 | AJ4: 0 | AK4: 0
A5: W2 | B5: Super Wild | C5: =COUNTIF(K:K,$A5) -> 0 | D5: =COUNTIF(L:L,$A5) -> 0 | E5: =COUNTIF(M:M,$A5) -> 0 | F5: =COUNTIF(N:N,$A5) -> 0 | G5: =COUNTIF(O:O,$A5) -> 0 | H5: 1 | J5: 1 | K5: A | L5: G3 | M5: C1 | N5: J | O5: A | Q5: =IF(K5="","",VLOOKUP(K5,$A$4:$H$22,8,FALSE)) -> 7 | R5: =IF(L5="","",VLOOKUP(L5,$A$4:$H$22,8,FALSE)) -> 13 | S5: =IF(M5="","",VLOOKUP(M5,$A$4:$H$22,8,FALSE)) -> 2 | T5: =IF(N5="","",VLOOKUP(N5,$A$4:$H$22,8,FALSE)) -> 10 | U5: =IF(O5="","",VLOOKUP(O5,$A$4:$H$22,8,FALSE)) -> 7 | W5: 12714 | X5: 10407 | Y5: 0 | Z5: 12646 | AA5: 12028 | AC5: 2 | AD5: 1401 | AF5: W2 | AG5: 0 | AH5: 0 | AI5: 0 | AJ5: 0 | AK5: 0
A6: C1 | B6: Scatter | C6: =COUNTIF(K:K,$A6) -> 4 | D6: =COUNTIF(L:L,$A6) -> 4 | E6: =COUNTIF(M:M,$A6) -> 4 | F6: =COUNTIF(N:N,$A6) -> 4 | G6: =COUNTIF(O:O,$A6) -> 6 | H6: 2 | J6: 2 | K6: K | L6: M3 | M6: Q | N6: Q | O6: M3 | Q6: =IF(K6="","",VLOOKUP(K6,$A$4:$H$22,8,FALSE)) -> 8 | R6: =IF(L6="","",VLOOKUP(L6,$A$4:$H$22,8,FALSE)) -> 5 | S6: =IF(M6="","",VLOOKUP(M6,$A$4:$H$22,8,FALSE)) -> 9 | T6: =IF(N6="","",VLOOKUP(N6,$A$4:$H$22,8,FALSE)) -> 9 | U6: =IF(O6="","",VLOOKUP(O6,$A$4:$H$22,8,FALSE)) -> 5 | W6: 12414 | X6: 11480 | Y6: 6283 | Z6: 12189 | AA6: 12744 | AC6: 3 | AD6: 235 | AF6: C1 | AG6: 0 | AH6: 0 | AI6: 0 | AJ6: 0 | AK6: 0
A7: M1 | B7: M1 | C7: =COUNTIF(K:K,$A7) -> 14 | D7: =COUNTIF(L:L,$A7) -> 9 | E7: =COUNTIF(M:M,$A7) -> 10 | F7: =COUNTIF(N:N,$A7) -> 9 | G7: =COUNTIF(O:O,$A7) -> 14 | H7: 3 | J7: 3 | K7: M1 | L7: M4 | M7: Q | N7: J | O7: K | Q7: =IF(K7="","",VLOOKUP(K7,$A$4:$H$22,8,FALSE)) -> 3 | R7: =IF(L7="","",VLOOKUP(L7,$A$4:$H$22,8,FALSE)) -> 6 | S7: =IF(M7="","",VLOOKUP(M7,$A$4:$H$22,8,FALSE)) -> 9 | T7: =IF(N7="","",VLOOKUP(N7,$A$4:$H$22,8,FALSE)) -> 10 | U7: =IF(O7="","",VLOOKUP(O7,$A$4:$H$22,8,FALSE)) -> 8 | W7: 11463 | X7: 13087 | Y7: 12324 | Z7: 10462 | AA7: 6442 | AC7: 4 | AD7: 18 | AF7: M1 | AG7: 50122 | AH7: 85723 | AI7: 46185 | AJ7: 93970 | AK7: 50452
A8: M2 | B8: M2 | C8: =COUNTIF(K:K,$A8) -> 28 | D8: =COUNTIF(L:L,$A8) -> 33 | E8: =COUNTIF(M:M,$A8) -> 15 | F8: =COUNTIF(N:N,$A8) -> 12 | G8: =COUNTIF(O:O,$A8) -> 24 | H8: 4 | J8: 4 | K8: A | L8: M2 | M8: Q | N8: G3 | O8: M3 | Q8: =IF(K8="","",VLOOKUP(K8,$A$4:$H$22,8,FALSE)) -> 7 | R8: =IF(L8="","",VLOOKUP(L8,$A$4:$H$22,8,FALSE)) -> 4 | S8: =IF(M8="","",VLOOKUP(M8,$A$4:$H$22,8,FALSE)) -> 9 | T8: =IF(N8="","",VLOOKUP(N8,$A$4:$H$22,8,FALSE)) -> 13 | U8: =IF(O8="","",VLOOKUP(O8,$A$4:$H$22,8,FALSE)) -> 5 | W8: 12427 | X8: 11708 | Y8: 15054 | Z8: 10538 | AA8: 5167 | AF8: M2 | AG8: 100486 | AH8: 41636 | AI8: 91061 | AJ8: 45998 | AK8: 104798
A9: M3 | B9: M3 | C9: =COUNTIF(K:K,$A9) -> 18 | D9: =COUNTIF(L:L,$A9) -> 12 | E9: =COUNTIF(M:M,$A9) -> 30 | F9: =COUNTIF(N:N,$A9) -> 13 | G9: =COUNTIF(O:O,$A9) -> 28 | H9: 5 | J9: 5 | K9: J | L9: C1 | M9: A | N9: M3 | O9: J | Q9: =IF(K9="","",VLOOKUP(K9,$A$4:$H$22,8,FALSE)) -> 10 | R9: =IF(L9="","",VLOOKUP(L9,$A$4:$H$22,8,FALSE)) -> 2 | S9: =IF(M9="","",VLOOKUP(M9,$A$4:$H$22,8,FALSE)) -> 7 | T9: =IF(N9="","",VLOOKUP(N9,$A$4:$H$22,8,FALSE)) -> 5 | U9: =IF(O9="","",VLOOKUP(O9,$A$4:$H$22,8,FALSE)) -> 10 | W9: 0 | X9: 13334 | Y9: 13804 | Z9: 11001 | AA9: 9970 | AF9: M3 | AG9: 100381 | AH9: 62016 | AI9: 71224 | AJ9: 67745 | AK9: 82539
A10: M4 | B10: M4 | C10: =COUNTIF(K:K,$A10) -> 19 | D10: =COUNTIF(L:L,$A10) -> 37 | E10: =COUNTIF(M:M,$A10) -> 12 | F10: =COUNTIF(N:N,$A10) -> 40 | G10: =COUNTIF(O:O,$A10) -> 15 | H10: 6 | J10: 6 | K10: M4 | L10: M2 | M10: Q | N10: J | O10: A | Q10: =IF(K10="","",VLOOKUP(K10,$A$4:$H$22,8,FALSE)) -> 6 | R10: =IF(L10="","",VLOOKUP(L10,$A$4:$H$22,8,FALSE)) -> 4 | S10: =IF(M10="","",VLOOKUP(M10,$A$4:$H$22,8,FALSE)) -> 9 | T10: =IF(N10="","",VLOOKUP(N10,$A$4:$H$22,8,FALSE)) -> 10 | U10: =IF(O10="","",VLOOKUP(O10,$A$4:$H$22,8,FALSE)) -> 7 | W10: 0 | X10: 11046 | Y10: 13592 | Z10: 13103 | AA10: 10140 | AF10: M4 | AG10: 96855 | AH10: 107933 | AI10: 68378 | AJ10: 114300 | AK10: 77965
A11: A | B11: A | C11: =COUNTIF(K:K,$A11) -> 33 | D11: =COUNTIF(L:L,$A11) -> 43 | E11: =COUNTIF(M:M,$A11) -> 15 | F11: =COUNTIF(N:N,$A11) -> 9 | G11: =COUNTIF(O:O,$A11) -> 31 | H11: 7 | J11: 7 | K11: K | L11: M4 | M11: M4 | N11: A | O11: M4 | Q11: =IF(K11="","",VLOOKUP(K11,$A$4:$H$22,8,FALSE)) -> 8 | R11: =IF(L11="","",VLOOKUP(L11,$A$4:$H$22,8,FALSE)) -> 6 | S11: =IF(M11="","",VLOOKUP(M11,$A$4:$H$22,8,FALSE)) -> 6 | T11: =IF(N11="","",VLOOKUP(N11,$A$4:$H$22,8,FALSE)) -> 7 | U11: =IF(O11="","",VLOOKUP(O11,$A$4:$H$22,8,FALSE)) -> 6 | W11: 0 | X11: 10429 | Y11: 11149 | Z11: 13051 | AA11: 12488 | AF11: A | AG11: 148704 | AH11: 149629 | AI11: 142185 | AJ11: 159075 | AK11: 157042
A12: K | B12: K | C12: =COUNTIF(K:K,$A12) -> 33 | D12: =COUNTIF(L:L,$A12) -> 12 | E12: =COUNTIF(M:M,$A12) -> 11 | F12: =COUNTIF(N:N,$A12) -> 50 | G12: =COUNTIF(O:O,$A12) -> 26 | H12: 8 | J12: 8 | K12: C1 | L12: G1 | M12: Q | N12: Q | O12: M1 | Q12: =IF(K12="","",VLOOKUP(K12,$A$4:$H$22,8,FALSE)) -> 2 | R12: =IF(L12="","",VLOOKUP(L12,$A$4:$H$22,8,FALSE)) -> 11 | S12: =IF(M12="","",VLOOKUP(M12,$A$4:$H$22,8,FALSE)) -> 9 | T12: =IF(N12="","",VLOOKUP(N12,$A$4:$H$22,8,FALSE)) -> 9 | U12: =IF(O12="","",VLOOKUP(O12,$A$4:$H$22,8,FALSE)) -> 3 | W12: 0 | X12: 10927 | Y12: 10982 | Z12: 11474 | AA12: 11874 | AF12: K | AG12: 150681 | AH12: 143546 | AI12: 138412 | AJ12: 162412 | AK12: 166316
A13: Q | B13: Q | C13: =COUNTIF(K:K,$A13) -> 18 | D13: =COUNTIF(L:L,$A13) -> 12 | E13: =COUNTIF(M:M,$A13) -> 39 | F13: =COUNTIF(N:N,$A13) -> 34 | G13: =COUNTIF(O:O,$A13) -> 30 | H13: 9 | J13: 9 | K13: M1 | L13: M1 | M13: GJ | N13: M3 | O13: A | Q13: =IF(K13="","",VLOOKUP(K13,$A$4:$H$22,8,FALSE)) -> 3 | R13: =IF(L13="","",VLOOKUP(L13,$A$4:$H$22,8,FALSE)) -> 3 | S13: =IF(M13="","",VLOOKUP(M13,$A$4:$H$22,8,FALSE)) -> 18 | T13: =IF(N13="","",VLOOKUP(N13,$A$4:$H$22,8,FALSE)) -> 5 | U13: =IF(O13="","",VLOOKUP(O13,$A$4:$H$22,8,FALSE)) -> 7 | W13: 12584 | X13: 12424 | Y13: 8186 | Z13: 10516 | AA13: 12885 | AF13: Q | AG13: 174591 | AH13: 126836 | AI13: 165974 | AJ13: 137382 | AK13: 176580
A14: J | B14: J | C14: =COUNTIF(K:K,$A14) -> 33 | D14: =COUNTIF(L:L,$A14) -> 8 | E14: =COUNTIF(M:M,$A14) -> 38 | F14: =COUNTIF(N:N,$A14) -> 13 | G14: =COUNTIF(O:O,$A14) -> 26 | H14: 10 | J14: 10 | K14: J | L14: GA | M14: Q | N14: K | O14: Q | Q14: =IF(K14="","",VLOOKUP(K14,$A$4:$H$22,8,FALSE)) -> 10 | R14: =IF(L14="","",VLOOKUP(L14,$A$4:$H$22,8,FALSE)) -> 15 | S14: =IF(M14="","",VLOOKUP(M14,$A$4:$H$22,8,FALSE)) -> 9 | T14: =IF(N14="","",VLOOKUP(N14,$A$4:$H$22,8,FALSE)) -> 8 | U14: =IF(O14="","",VLOOKUP(O14,$A$4:$H$22,8,FALSE)) -> 9 | W14: 10628 | X14: 13737 | Y14: 12057 | Z14: 3582 | AA14: 12297 | AF14: J | AG14: 178180 | AH14: 126422 | AI14: 164613 | AJ14: 138328 | AK14: 184308
A15: G1 | B15: Golden M1 | C15: =COUNTIF(K:K,$A15) -> 0 | D15: =COUNTIF(L:L,$A15) -> 2 | E15: =COUNTIF(M:M,$A15) -> 1 | F15: =COUNTIF(N:N,$A15) -> 1 | G15: =COUNTIF(O:O,$A15) -> 0 | H15: 11 | J15: 11 | K15: M3 | L15: M2 | M15: M4 | N15: M1 | O15: J | Q15: =IF(K15="","",VLOOKUP(K15,$A$4:$H$22,8,FALSE)) -> 5 | R15: =IF(L15="","",VLOOKUP(L15,$A$4:$H$22,8,FALSE)) -> 4 | S15: =IF(M15="","",VLOOKUP(M15,$A$4:$H$22,8,FALSE)) -> 6 | T15: =IF(N15="","",VLOOKUP(N15,$A$4:$H$22,8,FALSE)) -> 3 | U15: =IF(O15="","",VLOOKUP(O15,$A$4:$H$22,8,FALSE)) -> 10 | W15: 9770 | X15: 12930 | Y15: 11215 | Z15: 5364 | AA15: 12604 | AF15: G1 | AG15: 0 | AH15: 16564 | AI15: 6454 | AJ15: 7481 | AK15: 0
A16: G2 | B16: Golden M2 | C16: =COUNTIF(K:K,$A16) -> 0 | D16: =COUNTIF(L:L,$A16) -> 5 | E16: =COUNTIF(M:M,$A16) -> 2 | F16: =COUNTIF(N:N,$A16) -> 1 | G16: =COUNTIF(O:O,$A16) -> 0 | H16: 12 | J16: 12 | K16: M2 | L16: M2 | M16: J | N16: K | O16: A | Q16: =IF(K16="","",VLOOKUP(K16,$A$4:$H$22,8,FALSE)) -> 4 | R16: =IF(L16="","",VLOOKUP(L16,$A$4:$H$22,8,FALSE)) -> 4 | S16: =IF(M16="","",VLOOKUP(M16,$A$4:$H$22,8,FALSE)) -> 10 | T16: =IF(N16="","",VLOOKUP(N16,$A$4:$H$22,8,FALSE)) -> 8 | U16: =IF(O16="","",VLOOKUP(O16,$A$4:$H$22,8,FALSE)) -> 7 | W16: 0 | X16: 13334 | Y16: 12727 | Z16: 3557 | AA16: 12194 | AF16: G2 | AG16: 0 | AH16: 7923 | AI16: 11642 | AJ16: 4645 | AK16: 0
A17: G3 | B17: Golden M3 | C17: =COUNTIF(K:K,$A17) -> 0 | D17: =COUNTIF(L:L,$A17) -> 2 | E17: =COUNTIF(M:M,$A17) -> 4 | F17: =COUNTIF(N:N,$A17) -> 1 | G17: =COUNTIF(O:O,$A17) -> 0 | H17: 13 | J17: 13 | K17: M4 | L17: K | M17: J | N17: M4 | O17: Q | Q17: =IF(K17="","",VLOOKUP(K17,$A$4:$H$22,8,FALSE)) -> 6 | R17: =IF(L17="","",VLOOKUP(L17,$A$4:$H$22,8,FALSE)) -> 8 | S17: =IF(M17="","",VLOOKUP(M17,$A$4:$H$22,8,FALSE)) -> 10 | T17: =IF(N17="","",VLOOKUP(N17,$A$4:$H$22,8,FALSE)) -> 6 | U17: =IF(O17="","",VLOOKUP(O17,$A$4:$H$22,8,FALSE)) -> 9 | W17: 0 | X17: 11903 | Y17: 12341 | Z17: 3527 | AA17: 12757 | AF17: G3 | AG17: 0 | AH17: 11409 | AI17: 9525 | AJ17: 5451 | AK17: 0
A18: G4 | B18: Golden M4 | C18: =COUNTIF(K:K,$A18) -> 0 | D18: =COUNTIF(L:L,$A18) -> 7 | E18: =COUNTIF(M:M,$A18) -> 2 | F18: =COUNTIF(N:N,$A18) -> 3 | G18: =COUNTIF(O:O,$A18) -> 0 | H18: 14 | J18: 14 | K18: M4 | L18: M2 | M18: M3 | N18: K | O18: A | Q18: =IF(K18="","",VLOOKUP(K18,$A$4:$H$22,8,FALSE)) -> 6 | R18: =IF(L18="","",VLOOKUP(L18,$A$4:$H$22,8,FALSE)) -> 4 | S18: =IF(M18="","",VLOOKUP(M18,$A$4:$H$22,8,FALSE)) -> 5 | T18: =IF(N18="","",VLOOKUP(N18,$A$4:$H$22,8,FALSE)) -> 8 | U18: =IF(O18="","",VLOOKUP(O18,$A$4:$H$22,8,FALSE)) -> 7 | W18: 0 | X18: 11695 | Y18: 10993 | Z18: 3582 | AA18: 0 | AF18: G4 | AG18: 0 | AH18: 20294 | AI18: 8340 | AJ18: 9789 | AK18: 0
A19: GA | B19: Golden A | C19: =COUNTIF(K:K,$A19) -> 0 | D19: =COUNTIF(L:L,$A19) -> 8 | E19: =COUNTIF(M:M,$A19) -> 2 | F19: =COUNTIF(N:N,$A19) -> 1 | G19: =COUNTIF(O:O,$A19) -> 0 | H19: 15 | J19: 15 | K19: C1 | L19: G4 | M19: M3 | N19: K | O19: M4 | Q19: =IF(K19="","",VLOOKUP(K19,$A$4:$H$22,8,FALSE)) -> 2 | R19: =IF(L19="","",VLOOKUP(L19,$A$4:$H$22,8,FALSE)) -> 14 | S19: =IF(M19="","",VLOOKUP(M19,$A$4:$H$22,8,FALSE)) -> 5 | T19: =IF(N19="","",VLOOKUP(N19,$A$4:$H$22,8,FALSE)) -> 8 | U19: =IF(O19="","",VLOOKUP(O19,$A$4:$H$22,8,FALSE)) -> 6 | W19: 0 | X19: 5307 | Y19: 10993 | Z19: 5364 | AA19: 0 | AF19: GA | AG19: 0 | AH19: 27449 | AI19: 17176 | AJ19: 13711 | AK19: 0
... A22: GJ | B22: Golden J | C22: =COUNTIF(K:K,$A22) -> 0 | D22: =COUNTIF(L:L,$A22) -> 2 | E22: =COUNTIF(M:M,$A22) -> 10 | F22: =COUNTIF(N:N,$A22) -> 1 | G22: =COUNTIF(O:O,$A22) -> 0 | H22: 18 | J22: 18 | K22: A | L22: M2 | M22: M3 | N22: M4 | O22: A | Q22: =IF(K22="","",VLOOKUP(K22,$A$4:$H$22,8,FALSE)) -> 7 | R22: =IF(L22="","",VLOOKUP(L22,$A$4:$H$22,8,FALSE)) -> 4 | S22: =IF(M22="","",VLOOKUP(M22,$A$4:$H$22,8,FALSE)) -> 5 | T22: =IF(N22="","",VLOOKUP(N22,$A$4:$H$22,8,FALSE)) -> 6 | U22: =IF(O22="","",VLOOKUP(O22,$A$4:$H$22,8,FALSE)) -> 7 | W22: 11959 | X22: 10916 | Y22: 1379 | Z22: 3582 | AA22: 10450 | AF22: GJ | AG22: 0 | AH22: 23000 | AI22: 21167 | AJ22: 13182 | AK22: 0
C23: =SUM(C4:C22) -> 200 | D23: =SUM(D4:D22) -> 200 | E23: =SUM(E4:E22) -> 200 | F23: =SUM(F4:F22) -> 200 | G23: =SUM(G4:G22) -> 200 | J23: 19 | K23: J | L23: G2 | M23: M4 | N23: K | O23: Q | Q23: =IF(K23="","",VLOOKUP(K23,$A$4:$H$22,8,FALSE)) -> 10 | R23: =IF(L23="","",VLOOKUP(L23,$A$4:$H$22,8,FALSE)) -> 12 | S23: =IF(M23="","",VLOOKUP(M23,$A$4:$H$22,8,FALSE)) -> 6 | T23: =IF(N23="","",VLOOKUP(N23,$A$4:$H$22,8,FALSE)) -> 8 | U23: =IF(O23="","",VLOOKUP(O23,$A$4:$H$22,8,FALSE)) -> 9 | W23: 10465 | X23: 7441 | Y23: 1379 | Z23: 5364 | AA23: 10482
J24: 20 | K24: Q | L24: K | M24: J | N24: J | O24: A | Q24: =IF(K24="","",VLOOKUP(K24,$A$4:$H$22,8,FALSE)) -> 9 | R24: =IF(L24="","",VLOOKUP(L24,$A$4:$H$22,8,FALSE)) -> 8 | S24: =IF(M24="","",VLOOKUP(M24,$A$4:$H$22,8,FALSE)) -> 10 | T24: =IF(N24="","",VLOOKUP(N24,$A$4:$H$22,8,FALSE)) -> 10 | U24: =IF(O24="","",VLOOKUP(O24,$A$4:$H$22,8,FALSE)) -> 7 | W24: 10834 | X24: 7473 | Y24: 1379 | Z24: 3557 | AA24: 11874
J25: 21 | K25: M3 | L25: M2 | M25: GJ | N25: K | O25: Q | Q25: =IF(K25="","",VLOOKUP(K25,$A$4:$H$22,8,FALSE)) -> 5 | R25: =IF(L25="","",VLOOKUP(L25,$A$4:$H$22,8,FALSE)) -> 4 | S25: =IF(M25="","",VLOOKUP(M25,$A$4:$H$22,8,FALSE)) -> 18 | T25: =IF(N25="","",VLOOKUP(N25,$A$4:$H$22,8,FALSE)) -> 8 | U25: =IF(O25="","",VLOOKUP(O25,$A$4:$H$22,8,FALSE)) -> 9 | W25: 10172 | X25: 6669 | Y25: 1379 | Z25: 3527 | AA25: 12310
J26: 22 | K26: M3 | L26: A | M26: GJ | N26: M4 | O26: K | Q26: =IF(K26="","",VLOOKUP(K26,$A$4:$H$22,8,FALSE)) -> 5 | R26: =IF(L26="","",VLOOKUP(L26,$A$4:$H$22,8,FALSE)) -> 7 | S26: =IF(M26="","",VLOOKUP(M26,$A$4:$H$22,8,FALSE)) -> 18 | T26: =IF(N26="","",VLOOKUP(N26,$A$4:$H$22,8,FALSE)) -> 6 | U26: =IF(O26="","",VLOOKUP(O26,$A$4:$H$22,8,FALSE)) -> 8 | W26: 10748 | X26: 4033 | Y26: 1379 | Z26: 10614 | AA26: 11759
J27: 23 | K27: J | L27: A | M27: GJ | N27: K | O27: A | Q27: =IF(K27="","",VLOOKUP(K27,$A$4:$H$22,8,FALSE)) -> 10 | R27: =IF(L27="","",VLOOKUP(L27,$A$4:$H$22,8,FALSE)) -> 7 | S27: =IF(M27="","",VLOOKUP(M27,$A$4:$H$22,8,FALSE)) -> 18 | T27: =IF(N27="","",VLOOKUP(N27,$A$4:$H$22,8,FALSE)) -> 8 | U27: =IF(O27="","",VLOOKUP(O27,$A$4:$H$22,8,FALSE)) -> 7 | W27: 9873 | X27: 4033 | Y27: 1379 | Z27: 10778 | AA27: 12553
J28: 24 | K28: A | L28: A | M28: M3 | N28: M1 | O28: M4 | Q28: =IF(K28="","",VLOOKUP(K28,$A$4:$H$22,8,FALSE)) -> 7 | R28: =IF(L28="","",VLOOKUP(L28,$A$4:$H$22,8,FALSE)) -> 7 | S28: =IF(M28="","",VLOOKUP(M28,$A$4:$H$22,8,FALSE)) -> 5 | T28: =IF(N28="","",VLOOKUP(N28,$A$4:$H$22,8,FALSE)) -> 3 | U28: =IF(O28="","",VLOOKUP(O28,$A$4:$H$22,8,FALSE)) -> 6 | W28: 9922 | X28: 4033 | Y28: 1379 | Z28: 12698 | AA28: 12540
J29: 25 | K29: A | L29: M4 | M29: Q | N29: M2 | O29: J | Q29: =IF(K29="","",VLOOKUP(K29,$A$4:$H$22,8,FALSE)) -> 7 | R29: =IF(L29="","",VLOOKUP(L29,$A$4:$H$22,8,FALSE)) -> 6 | S29: =IF(M29="","",VLOOKUP(M29,$A$4:$H$22,8,FALSE)) -> 9 | T29: =IF(N29="","",VLOOKUP(N29,$A$4:$H$22,8,FALSE)) -> 4 | U29: =IF(O29="","",VLOOKUP(O29,$A$4:$H$22,8,FALSE)) -> 10 | W29: 11685 | X29: 4033 | Y29: 12301 | Z29: 12476 | AA29: 11977
J30: 26 | K30: M4 | L30: M4 | M30: Q | N30: GQ | O30: Q | Q30: =IF(K30="","",VLOOKUP(K30,$A$4:$H$22,8,FALSE)) -> 6 | R30: =IF(L30="","",VLOOKUP(L30,$A$4:$H$22,8,FALSE)) -> 6 | S30: =IF(M30="","",VLOOKUP(M30,$A$4:$H$22,8,FALSE)) -> 9 | T30: =IF(N30="","",VLOOKUP(N30,$A$4:$H$22,8,FALSE)) -> 17 | U30: =IF(O30="","",VLOOKUP(O30,$A$4:$H$22,8,FALSE)) -> 9 | W30: 11424 | X30: 4033 | Y30: 11049 | Z30: 12724 | AA30: 12502
J31: 27 | K31: M3 | L31: A | M31: Q | N31: Q | O31: J | Q31: =IF(K31="","",VLOOKUP(K31,$A$4:$H$22,8,FALSE)) -> 5 | R31: =IF(L31="","",VLOOKUP(L31,$A$4:$H$22,8,FALSE)) -> 7 | S31: =IF(M31="","",VLOOKUP(M31,$A$4:$H$22,8,FALSE)) -> 9 | T31: =IF(N31="","",VLOOKUP(N31,$A$4:$H$22,8,FALSE)) -> 9 | U31: =IF(O31="","",VLOOKUP(O31,$A$4:$H$22,8,FALSE)) -> 10 | W31: 11991 | X31: 4033 | Y31: 13006 | Z31: 12868 | AA31: 11912
J32: 28 | K32: K | L32: M4 | M32: Q | N32: M4 | O32: Q | Q32: =IF(K32="","",VLOOKUP(K32,$A$4:$H$22,8,FALSE)) -> 8 | R32: =IF(L32="","",VLOOKUP(L32,$A$4:$H$22,8,FALSE)) -> 6 | S32: =IF(M32="","",VLOOKUP(M32,$A$4:$H$22,8,FALSE)) -> 9 | T32: =IF(N32="","",VLOOKUP(N32,$A$4:$H$22,8,FALSE)) -> 6 | U32: =IF(O32="","",VLOOKUP(O32,$A$4:$H$22,8,FALSE)) -> 9 | W32: 12233 | X32: 4033 | Y32: 11716 | Z32: 13037 | AA32: 11900
J33: 29 | K33: M2 | L33: A | M33: K | N33: Q | O33: J | Q33: =IF(K33="","",VLOOKUP(K33,$A$4:$H$22,8,FALSE)) -> 4 | R33: =IF(L33="","",VLOOKUP(L33,$A$4:$H$22,8,FALSE)) -> 7 | S33: =IF(M33="","",VLOOKUP(M33,$A$4:$H$22,8,FALSE)) -> 8 | T33: =IF(N33="","",VLOOKUP(N33,$A$4:$H$22,8,FALSE)) -> 9 | U33: =IF(O33="","",VLOOKUP(O33,$A$4:$H$22,8,FALSE)) -> 10 | W33: 11855 | X33: 4033 | Y33: 11597 | Z33: 13064 | AA33: 9927
J34: 30 | K34: M1 | L34: M1 | M34: M1 | N34: GK | O34: A | Q34: =IF(K34="","",VLOOKUP(K34,$A$4:$H$22,8,FALSE)) -> 3 | R34: =IF(L34="","",VLOOKUP(L34,$A$4:$H$22,8,FALSE)) -> 3 | S34: =IF(M34="","",VLOOKUP(M34,$A$4:$H$22,8,FALSE)) -> 3 | T34: =IF(N34="","",VLOOKUP(N34,$A$4:$H$22,8,FALSE)) -> 16 | U34: =IF(O34="","",VLOOKUP(O34,$A$4:$H$22,8,FALSE)) -> 7 | W34: 12037 | X34: 4033 | Y34: 11782 | Z34: 13064 | AA34: 10247
J35: 31 | K35: M4 | L35: GK | M35: Q | N35: Q | O35: Q | Q35: =IF(K35="","",VLOOKUP(K35,$A$4:$H$22,8,FALSE)) -> 6 | R35: =IF(L35="","",VLOOKUP(L35,$A$4:$H$22,8,FALSE)) -> 16 | S35: =IF(M35="","",VLOOKUP(M35,$A$4:$H$22,8,FALSE)) -> 9 | T35: =IF(N35="","",VLOOKUP(N35,$A$4:$H$22,8,FALSE)) -> 9 | U35: =IF(O35="","",VLOOKUP(O35,$A$4:$H$22,8,FALSE)) -> 9 | W35: 11802 | X35: 5491 | Y35: 11849 | Z35: 10810 | AA35: 10375
... J203: 199 | K203: M1 | L203: A | M203: J | N203: K | O203: M3 | Q203: =IF(K203="","",VLOOKUP(K203,$A$4:$H$22,8,FALSE)) -> 3 | R203: =IF(L203="","",VLOOKUP(L203,$A$4:$H$22,8,FALSE)) -> 7 | S203: =IF(M203="","",VLOOKUP(M203,$A$4:$H$22,8,FALSE)) -> 10 | T203: =IF(N203="","",VLOOKUP(N203,$A$4:$H$22,8,FALSE)) -> 8 | U203: =IF(O203="","",VLOOKUP(O203,$A$4:$H$22,8,FALSE)) -> 5 | W203: 13093 | X203: 10375 | Y203: 0 | Z203: 13339 | AA203: 13013

Sheet BG_Symbol (2)
J2: Symbol | Q2: Symbol ID | W2: Symbol Weight | AC2: Random Wild Trigger Weight | AF2: Symbol Drop Weight
A3: Symbol | B3: Description | C3: R1 | D3: R2 | E3: R3 | F3: R4 | G3: R5 | H3: ID | J3: Line # | K3: R1 | L3: R2 | M3: R3 | N3: R4 | O3: R5 | Q3: R1 | R3: R2 | S3: R3 | T3: R4 | U3: R5 | W3: R1 | X3: R2 | Y3: R3 | Z3: R4 | AA3: R5 | AC3: Random Wild | AD3: Weight | AF3: Symbol | AG3: R1 | AH3: R2 | AI3: R3 | AJ3: R4 | AK3: R5
A4: {=Overview!A30:A48} -> WW | B4: {=Overview!B30:B48} -> Wild | C4: =COUNTIF(K:K,$A4) -> 0 | D4: =COUNTIF(L:L,$A4) -> 0 | E4: =COUNTIF(M:M,$A4) -> 0 | F4: =COUNTIF(N:N,$A4) -> 0 | G4: =COUNTIF(O:O,$A4) -> 0 | H4: {=Overview!H30:H48} -> 0 | J4: 0 | K4: M4 | L4: M1 | M4: J | N4: K | O4: M2 | Q4: =IF(K4="","",VLOOKUP(K4,$A$4:$H$22,8,FALSE)) -> 6 | R4: =IF(L4="","",VLOOKUP(L4,$A$4:$H$22,8,FALSE)) -> 3 | S4: =IF(M4="","",VLOOKUP(M4,$A$4:$H$22,8,FALSE)) -> 10 | T4: =IF(N4="","",VLOOKUP(N4,$A$4:$H$22,8,FALSE)) -> 8 | U4: =IF(O4="","",VLOOKUP(O4,$A$4:$H$22,8,FALSE)) -> 4 | W4: 6958 | X4: 3992 | Y4: 0 | Z4: 6012 | AA4: 6096 | AC4: 0 | AD4: 12792 | AF4: {=A4:A22} -> WW | AG4: 0 | AH4: 0 | AI4: 0 | AJ4: 0 | AK4: 0
A5: W2 | B5: Super Wild | C5: =COUNTIF(K:K,$A5) -> 0 | D5: =COUNTIF(L:L,$A5) -> 0 | E5: =COUNTIF(M:M,$A5) -> 0 | F5: =COUNTIF(N:N,$A5) -> 0 | G5: =COUNTIF(O:O,$A5) -> 0 | H5: 1 | J5: 1 | K5: A | L5: G3 | M5: C1 | N5: J | O5: A | Q5: =IF(K5="","",VLOOKUP(K5,$A$4:$H$22,8,FALSE)) -> 7 | R5: =IF(L5="","",VLOOKUP(L5,$A$4:$H$22,8,FALSE)) -> 13 | S5: =IF(M5="","",VLOOKUP(M5,$A$4:$H$22,8,FALSE)) -> 2 | T5: =IF(N5="","",VLOOKUP(N5,$A$4:$H$22,8,FALSE)) -> 10 | U5: =IF(O5="","",VLOOKUP(O5,$A$4:$H$22,8,FALSE)) -> 7 | W5: 7015 | X5: 4035 | Y5: 0 | Z5: 5855 | AA5: 5854 | AC5: 2 | AD5: 1401 | AF5: W2 | AG5: 0 | AH5: 0 | AI5: 0 | AJ5: 0 | AK5: 0
A6: C1 | B6: Scatter | C6: =COUNTIF(K:K,$A6) -> 4 | D6: =COUNTIF(L:L,$A6) -> 4 | E6: =COUNTIF(M:M,$A6) -> 4 | F6: =COUNTIF(N:N,$A6) -> 4 | G6: =COUNTIF(O:O,$A6) -> 6 | H6: 2 | J6: 2 | K6: K | L6: M3 | M6: Q | N6: Q | O6: M3 | Q6: =IF(K6="","",VLOOKUP(K6,$A$4:$H$22,8,FALSE)) -> 8 | R6: =IF(L6="","",VLOOKUP(L6,$A$4:$H$22,8,FALSE)) -> 5 | S6: =IF(M6="","",VLOOKUP(M6,$A$4:$H$22,8,FALSE)) -> 9 | T6: =IF(N6="","",VLOOKUP(N6,$A$4:$H$22,8,FALSE)) -> 9 | U6: =IF(O6="","",VLOOKUP(O6,$A$4:$H$22,8,FALSE)) -> 5 | W6: 6538 | X6: 3975 | Y6: 20755 | Z6: 5785 | AA6: 17425 | AC6: 3 | AD6: 235 | AF6: C1 | AG6: 0 | AH6: 0 | AI6: 0 | AJ6: 0 | AK6: 0
A7: M1 | B7: M1 | C7: =COUNTIF(K:K,$A7) -> 14 | D7: =COUNTIF(L:L,$A7) -> 9 | E7: =COUNTIF(M:M,$A7) -> 10 | F7: =COUNTIF(N:N,$A7) -> 9 | G7: =COUNTIF(O:O,$A7) -> 14 | H7: 3 | J7: 3 | K7: M1 | L7: M4 | M7: Q | N7: J | O7: K | Q7: =IF(K7="","",VLOOKUP(K7,$A$4:$H$22,8,FALSE)) -> 3 | R7: =IF(L7="","",VLOOKUP(L7,$A$4:$H$22,8,FALSE)) -> 6 | S7: =IF(M7="","",VLOOKUP(M7,$A$4:$H$22,8,FALSE)) -> 9 | T7: =IF(N7="","",VLOOKUP(N7,$A$4:$H$22,8,FALSE)) -> 10 | U7: =IF(O7="","",VLOOKUP(O7,$A$4:$H$22,8,FALSE)) -> 8 | W7: 18141 | X7: 11451 | Y7: 43698 | Z7: 4966 | AA7: 5399 | AC7: 4 | AD7: 18 | AF7: M1 | AG7: 25644 | AH7: 43685 | AI7: 23458 | AJ7: 48177 | AK7: 25951
A8: M2 | B8: M2 | C8: =COUNTIF(K:K,$A8) -> 28 | D8: =COUNTIF(L:L,$A8) -> 33 | E8: =COUNTIF(M:M,$A8) -> 15 | F8: =COUNTIF(N:N,$A8) -> 12 | G8: =COUNTIF(O:O,$A8) -> 24 | H8: 4 | J8: 4 | K8: A | L8: M2 | M8: Q | N8: G3 | O8: M3 | Q8: =IF(K8="","",VLOOKUP(K8,$A$4:$H$22,8,FALSE)) -> 7 | R8: =IF(L8="","",VLOOKUP(L8,$A$4:$H$22,8,FALSE)) -> 4 | S8: =IF(M8="","",VLOOKUP(M8,$A$4:$H$22,8,FALSE)) -> 9 | T8: =IF(N8="","",VLOOKUP(N8,$A$4:$H$22,8,FALSE)) -> 13 | U8: =IF(O8="","",VLOOKUP(O8,$A$4:$H$22,8,FALSE)) -> 5 | W8: 18249 | X8: 10244 | Y8: 49723 | Z8: 13687 | AA8: 4633 | AF8: M2 | AG8: 54011 | AH8: 22291 | AI8: 48588 | AJ8: 24775 | AK8: 56629
A9: M3 | B9: M3 | C9: =COUNTIF(K:K,$A9) -> 18 | D9: =COUNTIF(L:L,$A9) -> 12 | E9: =COUNTIF(M:M,$A9) -> 30 | F9: =COUNTIF(N:N,$A9) -> 13 | G9: =COUNTIF(O:O,$A9) -> 28 | H9: 5 | J9: 5 | K9: J | L9: C1 | M9: A | N9: M3 | O9: J | Q9: =IF(K9="","",VLOOKUP(K9,$A$4:$H$22,8,FALSE)) -> 10 | R9: =IF(L9="","",VLOOKUP(L9,$A$4:$H$22,8,FALSE)) -> 2 | S9: =IF(M9="","",VLOOKUP(M9,$A$4:$H$22,8,FALSE)) -> 7 | T9: =IF(N9="","",VLOOKUP(N9,$A$4:$H$22,8,FALSE)) -> 5 | U9: =IF(O9="","",VLOOKUP(O9,$A$4:$H$22,8,FALSE)) -> 10 | W9: 0 | X9: 11958 | Y9: 16230 | Z9: 15616 | AA9: 5435 | AF9: M3 | AG9: 53695 | AH9: 33042 | AI9: 37821 | AJ9: 36313 | AK9: 44385
A10: M4 | B10: M4 | C10: =COUNTIF(K:K,$A10) -> 19 | D10: =COUNTIF(L:L,$A10) -> 37 | E10: =COUNTIF(M:M,$A10) -> 12 | F10: =COUNTIF(N:N,$A10) -> 40 | G10: =COUNTIF(O:O,$A10) -> 15 | H10: 6 | J10: 6 | K10: M4 | L10: M2 | M10: Q | N10: J | O10: A | Q10: =IF(K10="","",VLOOKUP(K10,$A$4:$H$22,8,FALSE)) -> 6 | R10: =IF(L10="","",VLOOKUP(L10,$A$4:$H$22,8,FALSE)) -> 4 | S10: =IF(M10="","",VLOOKUP(M10,$A$4:$H$22,8,FALSE)) -> 9 | T10: =IF(N10="","",VLOOKUP(N10,$A$4:$H$22,8,FALSE)) -> 10 | U10: =IF(O10="","",VLOOKUP(O10,$A$4:$H$22,8,FALSE)) -> 7 | W10: 0 | X10: 15420 | Y10: 17155 | Z10: 18203 | AA10: 5529 | AF10: M4 | AG10: 133864 | AH10: 148579 | AI10: 93816 | AJ10: 158296 | AK10: 108328
A11: A | B11: A | C11: =COUNTIF(K:K,$A11) -> 33 | D11: =COUNTIF(L:L,$A11) -> 43 | E11: =COUNTIF(M:M,$A11) -> 15 | F11: =COUNTIF(N:N,$A11) -> 9 | G11: =COUNTIF(O:O,$A11) -> 31 | H11: 7 | J11: 7 | K11: K | L11: M4 | M11: M4 | N11: A | O11: M4 | Q11: =IF(K11="","",VLOOKUP(K11,$A$4:$H$22,8,FALSE)) -> 8 | R11: =IF(L11="","",VLOOKUP(L11,$A$4:$H$22,8,FALSE)) -> 6 | S11: =IF(M11="","",VLOOKUP(M11,$A$4:$H$22,8,FALSE)) -> 6 | T11: =IF(N11="","",VLOOKUP(N11,$A$4:$H$22,8,FALSE)) -> 7 | U11: =IF(O11="","",VLOOKUP(O11,$A$4:$H$22,8,FALSE)) -> 6 | W11: 0 | X11: 5190 | Y11: 14072 | Z11: 5907 | AA11: 17814 | AF11: A | AG11: 203445 | AH11: 203896 | AI11: 193108 | AJ11: 218079 | AK11: 215994
A12: K | B12: K | C12: =COUNTIF(K:K,$A12) -> 33 | D12: =COUNTIF(L:L,$A12) -> 12 | E12: =COUNTIF(M:M,$A12) -> 11 | F12: =COUNTIF(N:N,$A12) -> 50 | G12: =COUNTIF(O:O,$A12) -> 26 | H12: 8 | J12: 8 | K12: C1 | L12: G1 | M12: Q | N12: Q | O12: M1 | Q12: =IF(K12="","",VLOOKUP(K12,$A$4:$H$22,8,FALSE)) -> 2 | R12: =IF(L12="","",VLOOKUP(L12,$A$4:$H$22,8,FALSE)) -> 11 | S12: =IF(M12="","",VLOOKUP(M12,$A$4:$H$22,8,FALSE)) -> 9 | T12: =IF(N12="","",VLOOKUP(N12,$A$4:$H$22,8,FALSE)) -> 9 | U12: =IF(O12="","",VLOOKUP(O12,$A$4:$H$22,8,FALSE)) -> 3 | W12: 0 | X12: 4969 | Y12: 13862 | Z12: 4412 | AA12: 46429 | AF12: K | AG12: 60671 | AH12: 57568 | AI12: 55324 | AJ12: 65528 | AK12: 67322
A13: Q | B13: Q | C13: =COUNTIF(K:K,$A13) -> 18 | D13: =COUNTIF(L:L,$A13) -> 12 | E13: =COUNTIF(M:M,$A13) -> 39 | F13: =COUNTIF(N:N,$A13) -> 34 | G13: =COUNTIF(O:O,$A13) -> 30 | H13: 9 | J13: 9 | K13: M1 | L13: M1 | M13: GJ | N13: M3 | O13: A | Q13: =IF(K13="","",VLOOKUP(K13,$A$4:$H$22,8,FALSE)) -> 3 | R13: =IF(L13="","",VLOOKUP(L13,$A$4:$H$22,8,FALSE)) -> 3 | S13: =IF(M13="","",VLOOKUP(M13,$A$4:$H$22,8,FALSE)) -> 18 | T13: =IF(N13="","",VLOOKUP(N13,$A$4:$H$22,8,FALSE)) -> 5 | U13: =IF(O13="","",VLOOKUP(O13,$A$4:$H$22,8,FALSE)) -> 7 | W13: 6529 | X13: 5529 | Y13: 27038 | Z13: 4412 | AA13: 50384 | AF13: Q | AG13: 258467 | AH13: 187024 | AI13: 243920 | AJ13: 203800 | AK13: 262802
A14: J | B14: J | C14: =COUNTIF(K:K,$A14) -> 33 | D14: =COUNTIF(L:L,$A14) -> 8 | E14: =COUNTIF(M:M,$A14) -> 38 | F14: =COUNTIF(N:N,$A14) -> 13 | G14: =COUNTIF(O:O,$A14) -> 26 | H14: 10 | J14: 10 | K14: J | L14: GA | M14: Q | N14: K | O14: Q | Q14: =IF(K14="","",VLOOKUP(K14,$A$4:$H$22,8,FALSE)) -> 10 | R14: =IF(L14="","",VLOOKUP(L14,$A$4:$H$22,8,FALSE)) -> 15 | S14: =IF(M14="","",VLOOKUP(M14,$A$4:$H$22,8,FALSE)) -> 9 | T14: =IF(N14="","",VLOOKUP(N14,$A$4:$H$22,8,FALSE)) -> 8 | U14: =IF(O14="","",VLOOKUP(O14,$A$4:$H$22,8,FALSE)) -> 9 | W14: 6436 | X14: 4843 | Y14: 13981 | Z14: 4412 | AA14: 17116 | AF14: J | AG14: 210203 | AH14: 148550 | AI14: 192783 | AJ14: 163524 | AK14: 218589
A15: G1 | B15: Golden M1 | C15: =COUNTIF(K:K,$A15) -> 0 | D15: =COUNTIF(L:L,$A15) -> 2 | E15: =COUNTIF(M:M,$A15) -> 1 | F15: =COUNTIF(N:N,$A15) -> 1 | G15: =COUNTIF(O:O,$A15) -> 0 | H15: 11 | J15: 11 | K15: M3 | L15: M2 | M15: M4 | N15: M1 | O15: J | Q15: =IF(K15="","",VLOOKUP(K15,$A$4:$H$22,8,FALSE)) -> 5 | R15: =IF(L15="","",VLOOKUP(L15,$A$4:$H$22,8,FALSE)) -> 4 | S15: =IF(M15="","",VLOOKUP(M15,$A$4:$H$22,8,FALSE)) -> 6 | T15: =IF(N15="","",VLOOKUP(N15,$A$4:$H$22,8,FALSE)) -> 3 | U15: =IF(O15="","",VLOOKUP(O15,$A$4:$H$22,8,FALSE)) -> 10 | W15: 6020 | X15: 4770 | Y15: 12113 | Z15: 4412 | AA15: 6134 | AF15: G1 | AG15: 0 | AH15: 8441 | AI15: 3278 | AJ15: 3836 | AK15: 0
A16: G2 | B16: Golden M2 | C16: =COUNTIF(K:K,$A16) -> 0 | D16: =COUNTIF(L:L,$A16) -> 5 | E16: =COUNTIF(M:M,$A16) -> 2 | F16: =COUNTIF(N:N,$A16) -> 1 | G16: =COUNTIF(O:O,$A16) -> 0 | H16: 12 | J16: 12 | K16: M2 | L16: M2 | M16: J | N16: K | O16: A | Q16: =IF(K16="","",VLOOKUP(K16,$A$4:$H$22,8,FALSE)) -> 4 | R16: =IF(L16="","",VLOOKUP(L16,$A$4:$H$22,8,FALSE)) -> 4 | S16: =IF(M16="","",VLOOKUP(M16,$A$4:$H$22,8,FALSE)) -> 10 | T16: =IF(N16="","",VLOOKUP(N16,$A$4:$H$22,8,FALSE)) -> 8 | U16: =IF(O16="","",VLOOKUP(O16,$A$4:$H$22,8,FALSE)) -> 7 | W16: 0 | X16: 5214 | Y16: 5306 | Z16: 4412 | AA16: 5408 | AF16: G2 | AG16: 0 | AH16: 4241 | AI16: 6212 | AJ16: 2502 | AK16: 0
A17: G3 | B17: Golden M3 | C17: =COUNTIF(K:K,$A17) -> 0 | D17: =COUNTIF(L:L,$A17) -> 2 | E17: =COUNTIF(M:M,$A17) -> 4 | F17: =COUNTIF(N:N,$A17) -> 1 | G17: =COUNTIF(O:O,$A17) -> 0 | H17: 13 | J17: 13 | K17: M4 | L17: K | M17: J | N17: M4 | O17: Q | Q17: =IF(K17="","",VLOOKUP(K17,$A$4:$H$22,8,FALSE)) -> 6 | R17: =IF(L17="","",VLOOKUP(L17,$A$4:$H$22,8,FALSE)) -> 8 | S17: =IF(M17="","",VLOOKUP(M17,$A$4:$H$22,8,FALSE)) -> 10 | T17: =IF(N17="","",VLOOKUP(N17,$A$4:$H$22,8,FALSE)) -> 6 | U17: =IF(O17="","",VLOOKUP(O17,$A$4:$H$22,8,FALSE)) -> 9 | W17: 0 | X17: 5214 | Y17: 5306 | Z17: 4412 | AA17: 5527 | AF17: G3 | AG17: 0 | AH17: 6079 | AI17: 5057 | AJ17: 2922 | AK17: 0
A18: G4 | B18: Golden M4 | C18: =COUNTIF(K:K,$A18) -> 0 | D18: =COUNTIF(L:L,$A18) -> 7 | E18: =COUNTIF(M:M,$A18) -> 2 | F18: =COUNTIF(N:N,$A18) -> 3 | G18: =COUNTIF(O:O,$A18) -> 0 | H18: 14 | J18: 14 | K18: M4 | L18: M2 | M18: M3 | N18: K | O18: A | Q18: =IF(K18="","",VLOOKUP(K18,$A$4:$H$22,8,FALSE)) -> 6 | R18: =IF(L18="","",VLOOKUP(L18,$A$4:$H$22,8,FALSE)) -> 4 | S18: =IF(M18="","",VLOOKUP(M18,$A$4:$H$22,8,FALSE)) -> 5 | T18: =IF(N18="","",VLOOKUP(N18,$A$4:$H$22,8,FALSE)) -> 8 | U18: =IF(O18="","",VLOOKUP(O18,$A$4:$H$22,8,FALSE)) -> 7 | W18: 0 | X18: 5465 | Y18: 12059 | Z18: 4412 | AA18: 5396 | AF18: G4 | AG18: 0 | AH18: 27936 | AI18: 11443 | AJ18: 13558 | AK18: 0
A19: GA | B19: Golden A | C19: =COUNTIF(K:K,$A19) -> 0 | D19: =COUNTIF(L:L,$A19) -> 8 | E19: =COUNTIF(M:M,$A19) -> 2 | F19: =COUNTIF(N:N,$A19) -> 1 | G19: =COUNTIF(O:O,$A19) -> 0 | H19: 15 | J19: 15 | K19: C1 | L19: G4 | M19: M3 | N19: K | O19: M4 | Q19: =IF(K19="","",VLOOKUP(K19,$A$4:$H$22,8,FALSE)) -> 2 | R19: =IF(L19="","",VLOOKUP(L19,$A$4:$H$22,8,FALSE)) -> 14 | S19: =IF(M19="","",VLOOKUP(M19,$A$4:$H$22,8,FALSE)) -> 5 | T19: =IF(N19="","",VLOOKUP(N19,$A$4:$H$22,8,FALSE)) -> 8 | U19: =IF(O19="","",VLOOKUP(O19,$A$4:$H$22,8,FALSE)) -> 6 | W19: 0 | X19: 6892 | Y19: 12059 | Z19: 4412 | AA19: 5414 | AF19: GA | AG19: 0 | AH19: 37404 | AI19: 23328 | AJ19: 18796 | AK19: 0
... A22: GJ | B22: Golden J | C22: =COUNTIF(K:K,$A22) -> 0 | D22: =COUNTIF(L:L,$A22) -> 2 | E22: =COUNTIF(M:M,$A22) -> 10 | F22: =COUNTIF(N:N,$A22) -> 1 | G22: =COUNTIF(O:O,$A22) -> 0 | H22: 18 | J22: 18 | K22: A | L22: M2 | M22: M3 | N22: M4 | O22: A | Q22: =IF(K22="","",VLOOKUP(K22,$A$4:$H$22,8,FALSE)) -> 7 | R22: =IF(L22="","",VLOOKUP(L22,$A$4:$H$22,8,FALSE)) -> 4 | S22: =IF(M22="","",VLOOKUP(M22,$A$4:$H$22,8,FALSE)) -> 5 | T22: =IF(N22="","",VLOOKUP(N22,$A$4:$H$22,8,FALSE)) -> 6 | U22: =IF(O22="","",VLOOKUP(O22,$A$4:$H$22,8,FALSE)) -> 7 | W22: 19608 | X22: 4405 | Y22: 4422 | Z22: 4412 | AA22: 44961 | AF22: GJ | AG22: 0 | AH22: 27026 | AI22: 24788 | AJ22: 15584 | AK22: 0
C23: =SUM(C4:C22) -> 200 | D23: =SUM(D4:D22) -> 200 | E23: =SUM(E4:E22) -> 200 | F23: =SUM(F4:F22) -> 200 | G23: =SUM(G4:G22) -> 200 | J23: 19 | K23: J | L23: G2 | M23: M4 | N23: K | O23: Q | Q23: =IF(K23="","",VLOOKUP(K23,$A$4:$H$22,8,FALSE)) -> 10 | R23: =IF(L23="","",VLOOKUP(L23,$A$4:$H$22,8,FALSE)) -> 12 | S23: =IF(M23="","",VLOOKUP(M23,$A$4:$H$22,8,FALSE)) -> 6 | T23: =IF(N23="","",VLOOKUP(N23,$A$4:$H$22,8,FALSE)) -> 8 | U23: =IF(O23="","",VLOOKUP(O23,$A$4:$H$22,8,FALSE)) -> 9 | W23: 6260 | X23: 4405 | Y23: 4422 | Z23: 4412 | AA23: 15832
J24: 20 | K24: Q | L24: K | M24: J | N24: J | O24: A | Q24: =IF(K24="","",VLOOKUP(K24,$A$4:$H$22,8,FALSE)) -> 9 | R24: =IF(L24="","",VLOOKUP(L24,$A$4:$H$22,8,FALSE)) -> 8 | S24: =IF(M24="","",VLOOKUP(M24,$A$4:$H$22,8,FALSE)) -> 10 | T24: =IF(N24="","",VLOOKUP(N24,$A$4:$H$22,8,FALSE)) -> 10 | U24: =IF(O24="","",VLOOKUP(O24,$A$4:$H$22,8,FALSE)) -> 7 | W24: 6481 | X24: 4261 | Y24: 4422 | Z24: 4412 | AA24: 17496
J25: 21 | K25: M3 | L25: M2 | M25: GJ | N25: K | O25: Q | Q25: =IF(K25="","",VLOOKUP(K25,$A$4:$H$22,8,FALSE)) -> 5 | R25: =IF(L25="","",VLOOKUP(L25,$A$4:$H$22,8,FALSE)) -> 4 | S25: =IF(M25="","",VLOOKUP(M25,$A$4:$H$22,8,FALSE)) -> 18 | T25: =IF(N25="","",VLOOKUP(N25,$A$4:$H$22,8,FALSE)) -> 8 | U25: =IF(O25="","",VLOOKUP(O25,$A$4:$H$22,8,FALSE)) -> 9 | W25: 5938 | X25: 8646 | Y25: 4422 | Z25: 4412 | AA25: 6467
J26: 22 | K26: M3 | L26: A | M26: GJ | N26: M4 | O26: K | Q26: =IF(K26="","",VLOOKUP(K26,$A$4:$H$22,8,FALSE)) -> 5 | R26: =IF(L26="","",VLOOKUP(L26,$A$4:$H$22,8,FALSE)) -> 7 | S26: =IF(M26="","",VLOOKUP(M26,$A$4:$H$22,8,FALSE)) -> 18 | T26: =IF(N26="","",VLOOKUP(N26,$A$4:$H$22,8,FALSE)) -> 6 | U26: =IF(O26="","",VLOOKUP(O26,$A$4:$H$22,8,FALSE)) -> 8 | W26: 17193 | X26: 14310 | Y26: 4422 | Z26: 4412 | AA26: 6471
J27: 23 | K27: J | L27: A | M27: GJ | N27: K | O27: A | Q27: =IF(K27="","",VLOOKUP(K27,$A$4:$H$22,8,FALSE)) -> 10 | R27: =IF(L27="","",VLOOKUP(L27,$A$4:$H$22,8,FALSE)) -> 7 | S27: =IF(M27="","",VLOOKUP(M27,$A$4:$H$22,8,FALSE)) -> 18 | T27: =IF(N27="","",VLOOKUP(N27,$A$4:$H$22,8,FALSE)) -> 8 | U27: =IF(O27="","",VLOOKUP(O27,$A$4:$H$22,8,FALSE)) -> 7 | W27: 43425 | X27: 14310 | Y27: 4422 | Z27: 4575 | AA27: 18327
J28: 24 | K28: A | L28: A | M28: M3 | N28: M1 | O28: M4 | Q28: =IF(K28="","",VLOOKUP(K28,$A$4:$H$22,8,FALSE)) -> 7 | R28: =IF(L28="","",VLOOKUP(L28,$A$4:$H$22,8,FALSE)) -> 7 | S28: =IF(M28="","",VLOOKUP(M28,$A$4:$H$22,8,FALSE)) -> 5 | T28: =IF(N28="","",VLOOKUP(N28,$A$4:$H$22,8,FALSE)) -> 3 | U28: =IF(O28="","",VLOOKUP(O28,$A$4:$H$22,8,FALSE)) -> 6 | W28: 16677 | X28: 14310 | Y28: 4422 | Z28: 15411 | AA28: 18766
J29: 25 | K29: A | L29: M4 | M29: Q | N29: M2 | O29: J | Q29: =IF(K29="","",VLOOKUP(K29,$A$4:$H$22,8,FALSE)) -> 7 | R29: =IF(L29="","",VLOOKUP(L29,$A$4:$H$22,8,FALSE)) -> 6 | S29: =IF(M29="","",VLOOKUP(M29,$A$4:$H$22,8,FALSE)) -> 9 | T29: =IF(N29="","",VLOOKUP(N29,$A$4:$H$22,8,FALSE)) -> 4 | U29: =IF(O29="","",VLOOKUP(O29,$A$4:$H$22,8,FALSE)) -> 10 | W29: 6556 | X29: 14310 | Y29: 37846 | Z29: 46491 | AA29: 49050
J30: 26 | K30: M4 | L30: M4 | M30: Q | N30: GQ | O30: Q | Q30: =IF(K30="","",VLOOKUP(K30,$A$4:$H$22,8,FALSE)) -> 6 | R30: =IF(L30="","",VLOOKUP(L30,$A$4:$H$22,8,FALSE)) -> 6 | S30: =IF(M30="","",VLOOKUP(M30,$A$4:$H$22,8,FALSE)) -> 9 | T30: =IF(N30="","",VLOOKUP(N30,$A$4:$H$22,8,FALSE)) -> 17 | U30: =IF(O30="","",VLOOKUP(O30,$A$4:$H$22,8,FALSE)) -> 9 | W30: 6366 | X30: 14310 | Y30: 11888 | Z30: 15779 | AA30: 52478
J31: 27 | K31: M3 | L31: A | M31: Q | N31: Q | O31: J | Q31: =IF(K31="","",VLOOKUP(K31,$A$4:$H$22,8,FALSE)) -> 5 | R31: =IF(L31="","",VLOOKUP(L31,$A$4:$H$22,8,FALSE)) -> 7 | S31: =IF(M31="","",VLOOKUP(M31,$A$4:$H$22,8,FALSE)) -> 9 | T31: =IF(N31="","",VLOOKUP(N31,$A$4:$H$22,8,FALSE)) -> 9 | U31: =IF(O31="","",VLOOKUP(O31,$A$4:$H$22,8,FALSE)) -> 10 | W31: 6458 | X31: 14310 | Y31: 5306 | Z31: 5688 | AA31: 19108
J32: 28 | K32: K | L32: M4 | M32: Q | N32: M4 | O32: Q | Q32: =IF(K32="","",VLOOKUP(K32,$A$4:$H$22,8,FALSE)) -> 8 | R32: =IF(L32="","",VLOOKUP(L32,$A$4:$H$22,8,FALSE)) -> 6 | S32: =IF(M32="","",VLOOKUP(M32,$A$4:$H$22,8,FALSE)) -> 9 | T32: =IF(N32="","",VLOOKUP(N32,$A$4:$H$22,8,FALSE)) -> 6 | U32: =IF(O32="","",VLOOKUP(O32,$A$4:$H$22,8,FALSE)) -> 9 | W32: 6277 | X32: 14310 | Y32: 5306 | Z32: 5764 | AA32: 17780
J33: 29 | K33: M2 | L33: A | M33: K | N33: Q | O33: J | Q33: =IF(K33="","",VLOOKUP(K33,$A$4:$H$22,8,FALSE)) -> 4 | R33: =IF(L33="","",VLOOKUP(L33,$A$4:$H$22,8,FALSE)) -> 7 | S33: =IF(M33="","",VLOOKUP(M33,$A$4:$H$22,8,FALSE)) -> 8 | T33: =IF(N33="","",VLOOKUP(N33,$A$4:$H$22,8,FALSE)) -> 9 | U33: =IF(O33="","",VLOOKUP(O33,$A$4:$H$22,8,FALSE)) -> 10 | W33: 7360 | X33: 14310 | Y33: 5306 | Z33: 5295 | AA33: 14162
J34: 30 | K34: M1 | L34: M1 | M34: M1 | N34: GK | O34: A | Q34: =IF(K34="","",VLOOKUP(K34,$A$4:$H$22,8,FALSE)) -> 3 | R34: =IF(L34="","",VLOOKUP(L34,$A$4:$H$22,8,FALSE)) -> 3 | S34: =IF(M34="","",VLOOKUP(M34,$A$4:$H$22,8,FALSE)) -> 3 | T34: =IF(N34="","",VLOOKUP(N34,$A$4:$H$22,8,FALSE)) -> 16 | U34: =IF(O34="","",VLOOKUP(O34,$A$4:$H$22,8,FALSE)) -> 7 | W34: 6828 | X34: 14310 | Y34: 5306 | Z34: 5653 | AA34: 13618
J35: 31 | K35: M4 | L35: GK | M35: Q | N35: Q | O35: Q | Q35: =IF(K35="","",VLOOKUP(K35,$A$4:$H$22,8,FALSE)) -> 6 | R35: =IF(L35="","",VLOOKUP(L35,$A$4:$H$22,8,FALSE)) -> 16 | S35: =IF(M35="","",VLOOKUP(M35,$A$4:$H$22,8,FALSE)) -> 9 | T35: =IF(N35="","",VLOOKUP(N35,$A$4:$H$22,8,FALSE)) -> 9 | U35: =IF(O35="","",VLOOKUP(O35,$A$4:$H$22,8,FALSE)) -> 9 | W35: 6788 | X35: 7120 | Y35: 13733 | Z35: 12842 | AA35: 37908
... J203: 199 | K203: M1 | L203: A | M203: J | N203: K | O203: M3 | Q203: =IF(K203="","",VLOOKUP(K203,$A$4:$H$22,8,FALSE)) -> 3 | R203: =IF(L203="","",VLOOKUP(L203,$A$4:$H$22,8,FALSE)) -> 7 | S203: =IF(M203="","",VLOOKUP(M203,$A$4:$H$22,8,FALSE)) -> 10 | T203: =IF(N203="","",VLOOKUP(N203,$A$4:$H$22,8,FALSE)) -> 8 | U203: =IF(O203="","",VLOOKUP(O203,$A$4:$H$22,8,FALSE)) -> 5 | W203: 7246 | X203: 3975 | Y203: 0 | Z203: 6167 | AA203: 5396

Sheet BG_Symbol (3)
J2: Symbol | Q2: Symbol ID | W2: Symbol Weight | AC2: Random Wild Trigger Weight | AF2: Symbol Drop Weight
A3: Symbol | B3: Description | C3: R1 | D3: R2 | E3: R3 | F3: R4 | G3: R5 | H3: ID | J3: Line # | K3: R1 | L3: R2 | M3: R3 | N3: R4 | O3: R5 | Q3: R1 | R3: R2 | S3: R3 | T3: R4 | U3: R5 | W3: R1 | X3: R2 | Y3: R3 | Z3: R4 | AA3: R5 | AC3: Random Wild | AD3: Weight | AF3: Symbol | AG3: R1 | AH3: R2 | AI3: R3 | AJ3: R4 | AK3: R5
A4: {=Overview!A30:A48} -> WW | B4: {=Overview!B30:B48} -> Wild | C4: =COUNTIF(K:K,$A4) -> 0 | D4: =COUNTIF(L:L,$A4) -> 0 | E4: =COUNTIF(M:M,$A4) -> 0 | F4: =COUNTIF(N:N,$A4) -> 0 | G4: =COUNTIF(O:O,$A4) -> 0 | H4: {=Overview!H30:H48} -> 0 | J4: 0 | K4: M4 | L4: M1 | M4: J | N4: K | O4: M2 | Q4: =IF(K4="","",VLOOKUP(K4,$A$4:$H$22,8,FALSE)) -> 6 | R4: =IF(L4="","",VLOOKUP(L4,$A$4:$H$22,8,FALSE)) -> 3 | S4: =IF(M4="","",VLOOKUP(M4,$A$4:$H$22,8,FALSE)) -> 10 | T4: =IF(N4="","",VLOOKUP(N4,$A$4:$H$22,8,FALSE)) -> 8 | U4: =IF(O4="","",VLOOKUP(O4,$A$4:$H$22,8,FALSE)) -> 4 | W4: 10416 | X4: 8833 | Y4: 14188 | Z4: 10719 | AA4: 10237 | AC4: 0 | AD4: 1 | AF4: {=A4:A22} -> WW | AG4: 0 | AH4: 0 | AI4: 0 | AJ4: 0 | AK4: 0
A5: W2 | B5: Super Wild | C5: =COUNTIF(K:K,$A5) -> 0 | D5: =COUNTIF(L:L,$A5) -> 0 | E5: =COUNTIF(M:M,$A5) -> 0 | F5: =COUNTIF(N:N,$A5) -> 0 | G5: =COUNTIF(O:O,$A5) -> 0 | H5: 1 | J5: 1 | K5: A | L5: G3 | M5: C1 | N5: J | O5: A | Q5: =IF(K5="","",VLOOKUP(K5,$A$4:$H$22,8,FALSE)) -> 7 | R5: =IF(L5="","",VLOOKUP(L5,$A$4:$H$22,8,FALSE)) -> 13 | S5: =IF(M5="","",VLOOKUP(M5,$A$4:$H$22,8,FALSE)) -> 2 | T5: =IF(N5="","",VLOOKUP(N5,$A$4:$H$22,8,FALSE)) -> 10 | U5: =IF(O5="","",VLOOKUP(O5,$A$4:$H$22,8,FALSE)) -> 7 | W5: 10416 | X5: 8833 | Y5: 11824 | Z5: 10719 | AA5: 10237 | AC5: 2 | AD5: 0 | AF5: W2 | AG5: 0 | AH5: 0 | AI5: 0 | AJ5: 0 | AK5: 0
A6: C1 | B6: Scatter | C6: =COUNTIF(K:K,$A6) -> 4 | D6: =COUNTIF(L:L,$A6) -> 4 | E6: =COUNTIF(M:M,$A6) -> 4 | F6: =COUNTIF(N:N,$A6) -> 4 | G6: =COUNTIF(O:O,$A6) -> 6 | H6: 2 | J6: 2 | K6: K | L6: M3 | M6: Q | N6: Q | O6: M3 | Q6: =IF(K6="","",VLOOKUP(K6,$A$4:$H$22,8,FALSE)) -> 8 | R6: =IF(L6="","",VLOOKUP(L6,$A$4:$H$22,8,FALSE)) -> 5 | S6: =IF(M6="","",VLOOKUP(M6,$A$4:$H$22,8,FALSE)) -> 9 | T6: =IF(N6="","",VLOOKUP(N6,$A$4:$H$22,8,FALSE)) -> 9 | U6: =IF(O6="","",VLOOKUP(O6,$A$4:$H$22,8,FALSE)) -> 5 | W6: 10416 | X6: 11660 | Y6: 8957 | Z6: 10719 | AA6: 10237 | AC6: 3 | AD6: 0 | AF6: C1 | AG6: 19997 | AH6: 19703 | AI6: 0 | AJ6: 20405 | AK6: 0
A7: M1 | B7: M1 | C7: =COUNTIF(K:K,$A7) -> 14 | D7: =COUNTIF(L:L,$A7) -> 9 | E7: =COUNTIF(M:M,$A7) -> 10 | F7: =COUNTIF(N:N,$A7) -> 9 | G7: =COUNTIF(O:O,$A7) -> 14 | H7: 3 | J7: 3 | K7: M1 | L7: M4 | M7: Q | N7: J | O7: K | Q7: =IF(K7="","",VLOOKUP(K7,$A$4:$H$22,8,FALSE)) -> 3 | R7: =IF(L7="","",VLOOKUP(L7,$A$4:$H$22,8,FALSE)) -> 6 | S7: =IF(M7="","",VLOOKUP(M7,$A$4:$H$22,8,FALSE)) -> 9 | T7: =IF(N7="","",VLOOKUP(N7,$A$4:$H$22,8,FALSE)) -> 10 | U7: =IF(O7="","",VLOOKUP(O7,$A$4:$H$22,8,FALSE)) -> 8 | W7: 10416 | X7: 13992 | Y7: 8957 | Z7: 8933 | AA7: 10237 | AC7: 4 | AD7: 0 | AF7: M1 | AG7: 49120 | AH7: 84034 | AI7: 46185 | AJ7: 92053 | AK7: 50452
A8: M2 | B8: M2 | C8: =COUNTIF(K:K,$A8) -> 28 | D8: =COUNTIF(L:L,$A8) -> 33 | E8: =COUNTIF(M:M,$A8) -> 15 | F8: =COUNTIF(N:N,$A8) -> 12 | G8: =COUNTIF(O:O,$A8) -> 24 | H8: 4 | J8: 4 | K8: A | L8: M2 | M8: Q | N8: G3 | O8: M3 | Q8: =IF(K8="","",VLOOKUP(K8,$A$4:$H$22,8,FALSE)) -> 7 | R8: =IF(L8="","",VLOOKUP(L8,$A$4:$H$22,8,FALSE)) -> 4 | S8: =IF(M8="","",VLOOKUP(M8,$A$4:$H$22,8,FALSE)) -> 9 | T8: =IF(N8="","",VLOOKUP(N8,$A$4:$H$22,8,FALSE)) -> 13 | U8: =IF(O8="","",VLOOKUP(O8,$A$4:$H$22,8,FALSE)) -> 5 | W8: 10416 | X8: 13992 | Y8: 10748 | Z8: 8933 | AA8: 8531 | AF8: M2 | AG8: 98476 | AH8: 40816 | AI8: 91061 | AJ8: 45059 | AK8: 104798
A9: M3 | B9: M3 | C9: =COUNTIF(K:K,$A9) -> 18 | D9: =COUNTIF(L:L,$A9) -> 12 | E9: =COUNTIF(M:M,$A9) -> 30 | F9: =COUNTIF(N:N,$A9) -> 13 | G9: =COUNTIF(O:O,$A9) -> 28 | H9: 5 | J9: 5 | K9: J | L9: C1 | M9: A | N9: M3 | O9: J | Q9: =IF(K9="","",VLOOKUP(K9,$A$4:$H$22,8,FALSE)) -> 10 | R9: =IF(L9="","",VLOOKUP(L9,$A$4:$H$22,8,FALSE)) -> 2 | S9: =IF(M9="","",VLOOKUP(M9,$A$4:$H$22,8,FALSE)) -> 7 | T9: =IF(N9="","",VLOOKUP(N9,$A$4:$H$22,8,FALSE)) -> 5 | U9: =IF(O9="","",VLOOKUP(O9,$A$4:$H$22,8,FALSE)) -> 10 | W9: 13750 | X9: 13992 | Y9: 10748 | Z9: 8933 | AA9: 8531 | AF9: M3 | AG9: 98374 | AH9: 60794 | AI9: 71224 | AJ9: 66363 | AK9: 82539
A10: M4 | B10: M4 | C10: =COUNTIF(K:K,$A10) -> 19 | D10: =COUNTIF(L:L,$A10) -> 37 | E10: =COUNTIF(M:M,$A10) -> 12 | F10: =COUNTIF(N:N,$A10) -> 40 | G10: =COUNTIF(O:O,$A10) -> 15 | H10: 6 | J10: 6 | K10: M4 | L10: M2 | M10: Q | N10: J | O10: A | Q10: =IF(K10="","",VLOOKUP(K10,$A$4:$H$22,8,FALSE)) -> 6 | R10: =IF(L10="","",VLOOKUP(L10,$A$4:$H$22,8,FALSE)) -> 4 | S10: =IF(M10="","",VLOOKUP(M10,$A$4:$H$22,8,FALSE)) -> 9 | T10: =IF(N10="","",VLOOKUP(N10,$A$4:$H$22,8,FALSE)) -> 10 | U10: =IF(O10="","",VLOOKUP(O10,$A$4:$H$22,8,FALSE)) -> 7 | W10: 13750 | X10: 8833 | Y10: 10748 | Z10: 10719 | AA10: 8531 | AF10: M4 | AG10: 94918 | AH10: 105806 | AI10: 68378 | AJ10: 111968 | AK10: 77965
A11: A | B11: A | C11: =COUNTIF(K:K,$A11) -> 33 | D11: =COUNTIF(L:L,$A11) -> 43 | E11: =COUNTIF(M:M,$A11) -> 15 | F11: =COUNTIF(N:N,$A11) -> 9 | G11: =COUNTIF(O:O,$A11) -> 31 | H11: 7 | J11: 7 | K11: K | L11: M4 | M11: M4 | N11: A | O11: M4 | Q11: =IF(K11="","",VLOOKUP(K11,$A$4:$H$22,8,FALSE)) -> 8 | R11: =IF(L11="","",VLOOKUP(L11,$A$4:$H$22,8,FALSE)) -> 6 | S11: =IF(M11="","",VLOOKUP(M11,$A$4:$H$22,8,FALSE)) -> 6 | T11: =IF(N11="","",VLOOKUP(N11,$A$4:$H$22,8,FALSE)) -> 7 | U11: =IF(O11="","",VLOOKUP(O11,$A$4:$H$22,8,FALSE)) -> 6 | W11: 13750 | X11: 8833 | Y11: 8957 | Z11: 10719 | AA11: 10237 | AF11: A | AG11: 145730 | AH11: 146681 | AI11: 142185 | AJ11: 155829 | AK11: 157042
A12: K | B12: K | C12: =COUNTIF(K:K,$A12) -> 33 | D12: =COUNTIF(L:L,$A12) -> 12 | E12: =COUNTIF(M:M,$A12) -> 11 | F12: =COUNTIF(N:N,$A12) -> 50 | G12: =COUNTIF(O:O,$A12) -> 26 | H12: 8 | J12: 8 | K12: C1 | L12: G1 | M12: Q | N12: Q | O12: M1 | Q12: =IF(K12="","",VLOOKUP(K12,$A$4:$H$22,8,FALSE)) -> 2 | R12: =IF(L12="","",VLOOKUP(L12,$A$4:$H$22,8,FALSE)) -> 11 | S12: =IF(M12="","",VLOOKUP(M12,$A$4:$H$22,8,FALSE)) -> 9 | T12: =IF(N12="","",VLOOKUP(N12,$A$4:$H$22,8,FALSE)) -> 9 | U12: =IF(O12="","",VLOOKUP(O12,$A$4:$H$22,8,FALSE)) -> 3 | W12: 13750 | X12: 8833 | Y12: 8957 | Z12: 8933 | AA12: 10237 | AF12: K | AG12: 147668 | AH12: 140718 | AI12: 138412 | AJ12: 159098 | AK12: 166316
A13: Q | B13: Q | C13: =COUNTIF(K:K,$A13) -> 18 | D13: =COUNTIF(L:L,$A13) -> 12 | E13: =COUNTIF(M:M,$A13) -> 39 | F13: =COUNTIF(N:N,$A13) -> 34 | G13: =COUNTIF(O:O,$A13) -> 30 | H13: 9 | J13: 9 | K13: M1 | L13: M1 | M13: GJ | N13: M3 | O13: A | Q13: =IF(K13="","",VLOOKUP(K13,$A$4:$H$22,8,FALSE)) -> 3 | R13: =IF(L13="","",VLOOKUP(L13,$A$4:$H$22,8,FALSE)) -> 3 | S13: =IF(M13="","",VLOOKUP(M13,$A$4:$H$22,8,FALSE)) -> 18 | T13: =IF(N13="","",VLOOKUP(N13,$A$4:$H$22,8,FALSE)) -> 5 | U13: =IF(O13="","",VLOOKUP(O13,$A$4:$H$22,8,FALSE)) -> 7 | W13: 10416 | X13: 10600 | Y13: 8957 | Z13: 8933 | AA13: 10237 | AF13: Q | AG13: 171100 | AH13: 124337 | AI13: 165974 | AJ13: 134579 | AK13: 176580
A14: J | B14: J | C14: =COUNTIF(K:K,$A14) -> 33 | D14: =COUNTIF(L:L,$A14) -> 8 | E14: =COUNTIF(M:M,$A14) -> 38 | F14: =COUNTIF(N:N,$A14) -> 13 | G14: =COUNTIF(O:O,$A14) -> 26 | H14: 10 | J14: 10 | K14: J | L14: GA | M14: Q | N14: K | O14: Q | Q14: =IF(K14="","",VLOOKUP(K14,$A$4:$H$22,8,FALSE)) -> 10 | R14: =IF(L14="","",VLOOKUP(L14,$A$4:$H$22,8,FALSE)) -> 15 | S14: =IF(M14="","",VLOOKUP(M14,$A$4:$H$22,8,FALSE)) -> 9 | T14: =IF(N14="","",VLOOKUP(N14,$A$4:$H$22,8,FALSE)) -> 8 | U14: =IF(O14="","",VLOOKUP(O14,$A$4:$H$22,8,FALSE)) -> 9 | W14: 10416 | X14: 10600 | Y14: 8957 | Z14: 8933 | AA14: 10237 | AF14: J | AG14: 174617 | AH14: 123931 | AI14: 164613 | AJ14: 135505 | AK14: 184308
A15: G1 | B15: Golden M1 | C15: =COUNTIF(K:K,$A15) -> 0 | D15: =COUNTIF(L:L,$A15) -> 2 | E15: =COUNTIF(M:M,$A15) -> 1 | F15: =COUNTIF(N:N,$A15) -> 1 | G15: =COUNTIF(O:O,$A15) -> 0 | H15: 11 | J15: 11 | K15: M3 | L15: M2 | M15: M4 | N15: M1 | O15: J | Q15: =IF(K15="","",VLOOKUP(K15,$A$4:$H$22,8,FALSE)) -> 5 | R15: =IF(L15="","",VLOOKUP(L15,$A$4:$H$22,8,FALSE)) -> 4 | S15: =IF(M15="","",VLOOKUP(M15,$A$4:$H$22,8,FALSE)) -> 6 | T15: =IF(N15="","",VLOOKUP(N15,$A$4:$H$22,8,FALSE)) -> 3 | U15: =IF(O15="","",VLOOKUP(O15,$A$4:$H$22,8,FALSE)) -> 10 | W15: 8680 | X15: 10600 | Y15: 8957 | Z15: 8933 | AA15: 10237 | AF15: G1 | AG15: 0 | AH15: 16238 | AI15: 6454 | AJ15: 7328 | AK15: 0
A16: G2 | B16: Golden M2 | C16: =COUNTIF(K:K,$A16) -> 0 | D16: =COUNTIF(L:L,$A16) -> 5 | E16: =COUNTIF(M:M,$A16) -> 2 | F16: =COUNTIF(N:N,$A16) -> 1 | G16: =COUNTIF(O:O,$A16) -> 0 | H16: 12 | J16: 12 | K16: M2 | L16: M2 | M16: J | N16: K | O16: A | Q16: =IF(K16="","",VLOOKUP(K16,$A$4:$H$22,8,FALSE)) -> 4 | R16: =IF(L16="","",VLOOKUP(L16,$A$4:$H$22,8,FALSE)) -> 4 | S16: =IF(M16="","",VLOOKUP(M16,$A$4:$H$22,8,FALSE)) -> 10 | T16: =IF(N16="","",VLOOKUP(N16,$A$4:$H$22,8,FALSE)) -> 8 | U16: =IF(O16="","",VLOOKUP(O16,$A$4:$H$22,8,FALSE)) -> 7 | W16: 11458 | X16: 10600 | Y16: 10748 | Z16: 8933 | AA16: 10237 | AF16: G2 | AG16: 0 | AH16: 7767 | AI16: 11642 | AJ16: 4550 | AK16: 0
A17: G3 | B17: Golden M3 | C17: =COUNTIF(K:K,$A17) -> 0 | D17: =COUNTIF(L:L,$A17) -> 2 | E17: =COUNTIF(M:M,$A17) -> 4 | F17: =COUNTIF(N:N,$A17) -> 1 | G17: =COUNTIF(O:O,$A17) -> 0 | H17: 13 | J17: 13 | K17: M4 | L17: K | M17: J | N17: M4 | O17: Q | Q17: =IF(K17="","",VLOOKUP(K17,$A$4:$H$22,8,FALSE)) -> 6 | R17: =IF(L17="","",VLOOKUP(L17,$A$4:$H$22,8,FALSE)) -> 8 | S17: =IF(M17="","",VLOOKUP(M17,$A$4:$H$22,8,FALSE)) -> 10 | T17: =IF(N17="","",VLOOKUP(N17,$A$4:$H$22,8,FALSE)) -> 6 | U17: =IF(O17="","",VLOOKUP(O17,$A$4:$H$22,8,FALSE)) -> 9 | W17: 11458 | X17: 10600 | Y17: 10748 | Z17: 8933 | AA17: 10237 | AF17: G3 | AG17: 0 | AH17: 11184 | AI17: 9525 | AJ17: 5340 | AK17: 0
A18: G4 | B18: Golden M4 | C18: =COUNTIF(K:K,$A18) -> 0 | D18: =COUNTIF(L:L,$A18) -> 7 | E18: =COUNTIF(M:M,$A18) -> 2 | F18: =COUNTIF(N:N,$A18) -> 3 | G18: =COUNTIF(O:O,$A18) -> 0 | H18: 14 | J18: 14 | K18: M4 | L18: M2 | M18: M3 | N18: K | O18: A | Q18: =IF(K18="","",VLOOKUP(K18,$A$4:$H$22,8,FALSE)) -> 6 | R18: =IF(L18="","",VLOOKUP(L18,$A$4:$H$22,8,FALSE)) -> 4 | S18: =IF(M18="","",VLOOKUP(M18,$A$4:$H$22,8,FALSE)) -> 5 | T18: =IF(N18="","",VLOOKUP(N18,$A$4:$H$22,8,FALSE)) -> 8 | U18: =IF(O18="","",VLOOKUP(O18,$A$4:$H$22,8,FALSE)) -> 7 | W18: 13750 | X18: 10600 | Y18: 8957 | Z18: 8933 | AA18: 13513 | AF18: G4 | AG18: 0 | AH18: 19894 | AI18: 8340 | AJ18: 9589 | AK18: 0
A19: GA | B19: Golden A | C19: =COUNTIF(K:K,$A19) -> 0 | D19: =COUNTIF(L:L,$A19) -> 8 | E19: =COUNTIF(M:M,$A19) -> 2 | F19: =COUNTIF(N:N,$A19) -> 1 | G19: =COUNTIF(O:O,$A19) -> 0 | H19: 15 | J19: 15 | K19: C1 | L19: G4 | M19: M3 | N19: K | O19: M4 | Q19: =IF(K19="","",VLOOKUP(K19,$A$4:$H$22,8,FALSE)) -> 2 | R19: =IF(L19="","",VLOOKUP(L19,$A$4:$H$22,8,FALSE)) -> 14 | S19: =IF(M19="","",VLOOKUP(M19,$A$4:$H$22,8,FALSE)) -> 5 | T19: =IF(N19="","",VLOOKUP(N19,$A$4:$H$22,8,FALSE)) -> 8 | U19: =IF(O19="","",VLOOKUP(O19,$A$4:$H$22,8,FALSE)) -> 6 | W19: 13750 | X19: 8833 | Y19: 8957 | Z19: 8933 | AA19: 13513 | AF19: GA | AG19: 0 | AH19: 26908 | AI19: 17176 | AJ19: 13431 | AK19: 0
... A22: GJ | B22: Golden J | C22: =COUNTIF(K:K,$A22) -> 0 | D22: =COUNTIF(L:L,$A22) -> 2 | E22: =COUNTIF(M:M,$A22) -> 10 | F22: =COUNTIF(N:N,$A22) -> 1 | G22: =COUNTIF(O:O,$A22) -> 0 | H22: 18 | J22: 18 | K22: A | L22: M2 | M22: M3 | N22: M4 | O22: A | Q22: =IF(K22="","",VLOOKUP(K22,$A$4:$H$22,8,FALSE)) -> 7 | R22: =IF(L22="","",VLOOKUP(L22,$A$4:$H$22,8,FALSE)) -> 4 | S22: =IF(M22="","",VLOOKUP(M22,$A$4:$H$22,8,FALSE)) -> 5 | T22: =IF(N22="","",VLOOKUP(N22,$A$4:$H$22,8,FALSE)) -> 6 | U22: =IF(O22="","",VLOOKUP(O22,$A$4:$H$22,8,FALSE)) -> 7 | W22: 10416 | X22: 8833 | Y22: 8957 | Z22: 8933 | AA22: 8531 | AF22: GJ | AG22: 0 | AH22: 22547 | AI22: 21167 | AJ22: 12913 | AK22: 0
C23: =SUM(C4:C22) -> 200 | D23: =SUM(D4:D22) -> 200 | E23: =SUM(E4:E22) -> 200 | F23: =SUM(F4:F22) -> 200 | G23: =SUM(G4:G22) -> 200 | J23: 19 | K23: J | L23: G2 | M23: M4 | N23: K | O23: Q | Q23: =IF(K23="","",VLOOKUP(K23,$A$4:$H$22,8,FALSE)) -> 10 | R23: =IF(L23="","",VLOOKUP(L23,$A$4:$H$22,8,FALSE)) -> 12 | S23: =IF(M23="","",VLOOKUP(M23,$A$4:$H$22,8,FALSE)) -> 6 | T23: =IF(N23="","",VLOOKUP(N23,$A$4:$H$22,8,FALSE)) -> 8 | U23: =IF(O23="","",VLOOKUP(O23,$A$4:$H$22,8,FALSE)) -> 9 | W23: 8680 | X23: 8833 | Y23: 8957 | Z23: 8933 | AA23: 8531
J24: 20 | K24: Q | L24: K | M24: J | N24: J | O24: A | Q24: =IF(K24="","",VLOOKUP(K24,$A$4:$H$22,8,FALSE)) -> 9 | R24: =IF(L24="","",VLOOKUP(L24,$A$4:$H$22,8,FALSE)) -> 8 | S24: =IF(M24="","",VLOOKUP(M24,$A$4:$H$22,8,FALSE)) -> 10 | T24: =IF(N24="","",VLOOKUP(N24,$A$4:$H$22,8,FALSE)) -> 10 | U24: =IF(O24="","",VLOOKUP(O24,$A$4:$H$22,8,FALSE)) -> 7 | W24: 8680 | X24: 8833 | Y24: 8957 | Z24: 8933 | AA24: 10237
J25: 21 | K25: M3 | L25: M2 | M25: GJ | N25: K | O25: Q | Q25: =IF(K25="","",VLOOKUP(K25,$A$4:$H$22,8,FALSE)) -> 5 | R25: =IF(L25="","",VLOOKUP(L25,$A$4:$H$22,8,FALSE)) -> 4 | S25: =IF(M25="","",VLOOKUP(M25,$A$4:$H$22,8,FALSE)) -> 18 | T25: =IF(N25="","",VLOOKUP(N25,$A$4:$H$22,8,FALSE)) -> 8 | U25: =IF(O25="","",VLOOKUP(O25,$A$4:$H$22,8,FALSE)) -> 9 | W25: 8680 | X25: 8833 | Y25: 8957 | Z25: 8933 | AA25: 10237
J26: 22 | K26: M3 | L26: A | M26: GJ | N26: M4 | O26: K | Q26: =IF(K26="","",VLOOKUP(K26,$A$4:$H$22,8,FALSE)) -> 5 | R26: =IF(L26="","",VLOOKUP(L26,$A$4:$H$22,8,FALSE)) -> 7 | S26: =IF(M26="","",VLOOKUP(M26,$A$4:$H$22,8,FALSE)) -> 18 | T26: =IF(N26="","",VLOOKUP(N26,$A$4:$H$22,8,FALSE)) -> 6 | U26: =IF(O26="","",VLOOKUP(O26,$A$4:$H$22,8,FALSE)) -> 8 | W26: 8680 | X26: 8833 | Y26: 8957 | Z26: 8933 | AA26: 10237
J27: 23 | K27: J | L27: A | M27: GJ | N27: K | O27: A | Q27: =IF(K27="","",VLOOKUP(K27,$A$4:$H$22,8,FALSE)) -> 10 | R27: =IF(L27="","",VLOOKUP(L27,$A$4:$H$22,8,FALSE)) -> 7 | S27: =IF(M27="","",VLOOKUP(M27,$A$4:$H$22,8,FALSE)) -> 18 | T27: =IF(N27="","",VLOOKUP(N27,$A$4:$H$22,8,FALSE)) -> 8 | U27: =IF(O27="","",VLOOKUP(O27,$A$4:$H$22,8,FALSE)) -> 7 | W27: 8680 | X27: 8833 | Y27: 8957 | Z27: 8933 | AA27: 10237
J28: 24 | K28: A | L28: A | M28: M3 | N28: M1 | O28: M4 | Q28: =IF(K28="","",VLOOKUP(K28,$A$4:$H$22,8,FALSE)) -> 7 | R28: =IF(L28="","",VLOOKUP(L28,$A$4:$H$22,8,FALSE)) -> 7 | S28: =IF(M28="","",VLOOKUP(M28,$A$4:$H$22,8,FALSE)) -> 5 | T28: =IF(N28="","",VLOOKUP(N28,$A$4:$H$22,8,FALSE)) -> 3 | U28: =IF(O28="","",VLOOKUP(O28,$A$4:$H$22,8,FALSE)) -> 6 | W28: 8680 | X28: 8833 | Y28: 8957 | Z28: 10719 | AA28: 10237
J29: 25 | K29: A | L29: M4 | M29: Q | N29: M2 | O29: J | Q29: =IF(K29="","",VLOOKUP(K29,$A$4:$H$22,8,FALSE)) -> 7 | R29: =IF(L29="","",VLOOKUP(L29,$A$4:$H$22,8,FALSE)) -> 6 | S29: =IF(M29="","",VLOOKUP(M29,$A$4:$H$22,8,FALSE)) -> 9 | T29: =IF(N29="","",VLOOKUP(N29,$A$4:$H$22,8,FALSE)) -> 4 | U29: =IF(O29="","",VLOOKUP(O29,$A$4:$H$22,8,FALSE)) -> 10 | W29: 10416 | X29: 8833 | Y29: 8957 | Z29: 10719 | AA29: 10237
J30: 26 | K30: M4 | L30: M4 | M30: Q | N30: GQ | O30: Q | Q30: =IF(K30="","",VLOOKUP(K30,$A$4:$H$22,8,FALSE)) -> 6 | R30: =IF(L30="","",VLOOKUP(L30,$A$4:$H$22,8,FALSE)) -> 6 | S30: =IF(M30="","",VLOOKUP(M30,$A$4:$H$22,8,FALSE)) -> 9 | T30: =IF(N30="","",VLOOKUP(N30,$A$4:$H$22,8,FALSE)) -> 17 | U30: =IF(O30="","",VLOOKUP(O30,$A$4:$H$22,8,FALSE)) -> 9 | W30: 10416 | X30: 8833 | Y30: 8957 | Z30: 10719 | AA30: 10237
J31: 27 | K31: M3 | L31: A | M31: Q | N31: Q | O31: J | Q31: =IF(K31="","",VLOOKUP(K31,$A$4:$H$22,8,FALSE)) -> 5 | R31: =IF(L31="","",VLOOKUP(L31,$A$4:$H$22,8,FALSE)) -> 7 | S31: =IF(M31="","",VLOOKUP(M31,$A$4:$H$22,8,FALSE)) -> 9 | T31: =IF(N31="","",VLOOKUP(N31,$A$4:$H$22,8,FALSE)) -> 9 | U31: =IF(O31="","",VLOOKUP(O31,$A$4:$H$22,8,FALSE)) -> 10 | W31: 10416 | X31: 8833 | Y31: 10748 | Z31: 10719 | AA31: 10237
J32: 28 | K32: K | L32: M4 | M32: Q | N32: M4 | O32: Q | Q32: =IF(K32="","",VLOOKUP(K32,$A$4:$H$22,8,FALSE)) -> 8 | R32: =IF(L32="","",VLOOKUP(L32,$A$4:$H$22,8,FALSE)) -> 6 | S32: =IF(M32="","",VLOOKUP(M32,$A$4:$H$22,8,FALSE)) -> 9 | T32: =IF(N32="","",VLOOKUP(N32,$A$4:$H$22,8,FALSE)) -> 6 | U32: =IF(O32="","",VLOOKUP(O32,$A$4:$H$22,8,FALSE)) -> 9 | W32: 10416 | X32: 8833 | Y32: 10748 | Z32: 10719 | AA32: 10237
J33: 29 | K33: M2 | L33: A | M33: K | N33: Q | O33: J | Q33: =IF(K33="","",VLOOKUP(K33,$A$4:$H$22,8,FALSE)) -> 4 | R33: =IF(L33="","",VLOOKUP(L33,$A$4:$H$22,8,FALSE)) -> 7 | S33: =IF(M33="","",VLOOKUP(M33,$A$4:$H$22,8,FALSE)) -> 8 | T33: =IF(N33="","",VLOOKUP(N33,$A$4:$H$22,8,FALSE)) -> 9 | U33: =IF(O33="","",VLOOKUP(O33,$A$4:$H$22,8,FALSE)) -> 10 | W33: 10416 | X33: 8833 | Y33: 10748 | Z33: 10719 | AA33: 8531
J34: 30 | K34: M1 | L34: M1 | M34: M1 | N34: GK | O34: A | Q34: =IF(K34="","",VLOOKUP(K34,$A$4:$H$22,8,FALSE)) -> 3 | R34: =IF(L34="","",VLOOKUP(L34,$A$4:$H$22,8,FALSE)) -> 3 | S34: =IF(M34="","",VLOOKUP(M34,$A$4:$H$22,8,FALSE)) -> 3 | T34: =IF(N34="","",VLOOKUP(N34,$A$4:$H$22,8,FALSE)) -> 16 | U34: =IF(O34="","",VLOOKUP(O34,$A$4:$H$22,8,FALSE)) -> 7 | W34: 10416 | X34: 8833 | Y34: 10748 | Z34: 10719 | AA34: 8531
J35: 31 | K35: M4 | L35: GK | M35: Q | N35: Q | O35: Q | Q35: =IF(K35="","",VLOOKUP(K35,$A$4:$H$22,8,FALSE)) -> 6 | R35: =IF(L35="","",VLOOKUP(L35,$A$4:$H$22,8,FALSE)) -> 16 | S35: =IF(M35="","",VLOOKUP(M35,$A$4:$H$22,8,FALSE)) -> 9 | T35: =IF(N35="","",VLOOKUP(N35,$A$4:$H$22,8,FALSE)) -> 9 | U35: =IF(O35="","",VLOOKUP(O35,$A$4:$H$22,8,FALSE)) -> 9 | W35: 10416 | X35: 8833 | Y35: 10748 | Z35: 8933 | AA35: 8531
... J203: 199 | K203: M1 | L203: A | M203: J | N203: K | O203: M3 | Q203: =IF(K203="","",VLOOKUP(K203,$A$4:$H$22,8,FALSE)) -> 3 | R203: =IF(L203="","",VLOOKUP(L203,$A$4:$H$22,8,FALSE)) -> 7 | S203: =IF(M203="","",VLOOKUP(M203,$A$4:$H$22,8,FALSE)) -> 10 | T203: =IF(N203="","",VLOOKUP(N203,$A$4:$H$22,8,FALSE)) -> 8 | U203: =IF(O203="","",VLOOKUP(O203,$A$4:$H$22,8,FALSE)) -> 5 | W203: 10415 | X203: 8833 | Y203: 14188 | Z203: 10719 | AA203: 10237
Q204: =IF(K204="","",VLOOKUP(K204,$A$4:$H$22,8,FALSE)) | R204: =IF(L204="","",VLOOKUP(L204,$A$4:$H$22,8,FALSE)) | S204: =IF(M204="","",VLOOKUP(M204,$A$4:$H$22,8,FALSE)) | T204: =IF(N204="","",VLOOKUP(N204,$A$4:$H$22,8,FALSE)) | U204: =IF(O204="","",VLOOKUP(O204,$A$4:$H$22,8,FALSE))
Q205: =IF(K205="","",VLOOKUP(K205,$A$4:$H$22,8,FALSE)) | R205: =IF(L205="","",VLOOKUP(L205,$A$4:$H$22,8,FALSE)) | S205: =IF(M205="","",VLOOKUP(M205,$A$4:$H$22,8,FALSE)) | T205: =IF(N205="","",VLOOKUP(N205,$A$4:$H$22,8,FALSE)) | U205: =IF(O205="","",VLOOKUP(O205,$A$4:$H$22,8,FALSE))
Q206: =IF(K206="","",VLOOKUP(K206,$A$4:$H$22,8,FALSE)) | R206: =IF(L206="","",VLOOKUP(L206,$A$4:$H$22,8,FALSE)) | S206: =IF(M206="","",VLOOKUP(M206,$A$4:$H$22,8,FALSE)) | T206: =IF(N206="","",VLOOKUP(N206,$A$4:$H$22,8,FALSE)) | U206: =IF(O206="","",VLOOKUP(O206,$A$4:$H$22,8,FALSE))
Q207: =IF(K207="","",VLOOKUP(K207,$A$4:$H$22,8,FALSE)) | R207: =IF(L207="","",VLOOKUP(L207,$A$4:$H$22,8,FALSE)) | S207: =IF(M207="","",VLOOKUP(M207,$A$4:$H$22,8,FALSE)) | T207: =IF(N207="","",VLOOKUP(N207,$A$4:$H$22,8,FALSE)) | U207: =IF(O207="","",VLOOKUP(O207,$A$4:$H$22,8,FALSE))
Q208: =IF(K208="","",VLOOKUP(K208,$A$4:$H$22,8,FALSE)) | R208: =IF(L208="","",VLOOKUP(L208,$A$4:$H$22,8,FALSE)) | S208: =IF(M208="","",VLOOKUP(M208,$A$4:$H$22,8,FALSE)) | T208: =IF(N208="","",VLOOKUP(N208,$A$4:$H$22,8,FALSE)) | U208: =IF(O208="","",VLOOKUP(O208,$A$4:$H$22,8,FALSE))
Q209: =IF(K209="","",VLOOKUP(K209,$A$4:$H$22,8,FALSE)) | R209: =IF(L209="","",VLOOKUP(L209,$A$4:$H$22,8,FALSE)) | S209: =IF(M209="","",VLOOKUP(M209,$A$4:$H$22,8,FALSE)) | T209: =IF(N209="","",VLOOKUP(N209,$A$4:$H$22,8,FALSE)) | U209: =IF(O209="","",VLOOKUP(O209,$A$4:$H$22,8,FALSE))
Q210: =IF(K210="","",VLOOKUP(K210,$A$4:$H$22,8,FALSE)) | R210: =IF(L210="","",VLOOKUP(L210,$A$4:$H$22,8,FALSE)) | S210: =IF(M210="","",VLOOKUP(M210,$A$4:$H$22,8,FALSE)) | T210: =IF(N210="","",VLOOKUP(N210,$A$4:$H$22,8,FALSE)) | U210: =IF(O210="","",VLOOKUP(O210,$A$4:$H$22,8,FALSE))
...

Sheet FG_Symbol
J2: Symbol | Q2: Symbol ID | W2: Symbol Weight | AC2: Random Wild Trigger Weight | AF2: Symbol Drop Weight
A3: Symbol | B3: Description | C3: R1 | D3: R2 | E3: R3 | F3: R4 | G3: R5 | H3: ID | J3: Line # | K3: R1 | L3: R2 | M3: R3 | N3: R4 | O3: R5 | Q3: R1 | R3: R2 | S3: R3 | T3: R4 | U3: R5 | W3: R1 | X3: R2 | Y3: R3 | Z3: R4 | AA3: R5 | AC3: Random Wild | AD3: Weight | AF3: Symbol | AG3: R1 | AH3: R2 | AI3: R3 | AJ3: R4 | AK3: R5
A4: {=Overview!A30:A48} -> WW | B4: {=Overview!B30:B48} -> Wild | C4: =COUNTIF(K:K,$A4) -> 0 | D4: =COUNTIF(L:L,$A4) -> 0 | E4: =COUNTIF(M:M,$A4) -> 0 | F4: =COUNTIF(N:N,$A4) -> 0 | G4: =COUNTIF(O:O,$A4) -> 0 | H4: {=Overview!H30:H48} -> 0 | J4: 0 | K4: J | L4: G2 | M4: GQ | N4: GQ | O4: A | Q4: =IF(K4="","",VLOOKUP(K4,$A$4:$H$22,8,FALSE)) -> 10 | R4: =IF(L4="","",VLOOKUP(L4,$A$4:$H$22,8,FALSE)) -> 12 | S4: =IF(M4="","",VLOOKUP(M4,$A$4:$H$22,8,FALSE)) -> 17 | T4: =IF(N4="","",VLOOKUP(N4,$A$4:$H$22,8,FALSE)) -> 17 | U4: =IF(O4="","",VLOOKUP(O4,$A$4:$H$22,8,FALSE)) -> 7 | W4: 3410 | X4: 13266 | Y4: 7364 | Z4: 5550 | AA4: 13285 | AC4: 0 | AD4: 23656 | AF4: WW | AG4: 0 | AH4: 0 | AI4: 0 | AJ4: 0 | AK4: 0
