Workbook
Name Bet_1: Overview!$A$5
Name Bet_2: Overview!$A$6
Name Bet_3: Overview!$A$7
Name Bet_4: Overview!$A$8

Sheet Overview
A1: Model: | B1: =C1&"-"&B2 -> H020192-2.2.1.0 | C1: H020192
A2: Version: | B2: 2.2.1.0
A3: Hold: | B3: =1-D5 -> -19.935096 | G3: Real value
A4: Coin | B4: Payline | C4: Lines Pay Back | D4: Pay Back | E4: Hit% | G4: Hit% | H4: Big win | I4: Mega win | J4: Jumbo win
A5: 1 | B5: 5 | C5: ='Pay Combo Normal Bet'!$I$1 -> 0.70171319 | D5: ='Pay Combo Normal Bet'!$I$2 -> 20.935096 | E5: =SUM('Pay Combo Normal Bet'!$J$13:$J$20) -> 0.071900065 | F5: Normal Bet | G5: =1-'Multiplier Weight'!$N$4 -> 0.1082682 | H5: =SUM('Multiplier Weight'!$N$12:$N$61)-I5-J5 -> 0.01677213 | I5: =SUM('Multiplier Weight'!$N$15:$N$61)-J5 -> 0.019243787 | J5: =SUM('Multiplier Weight'!$N$19:$N$61) -> 0.003500854
A6: 1.5 | B6: 5 | C6: ='Pay Combo Extra Bet (1)'!$I$1 -> 0.46780879 | D6: ='Pay Combo Extra Bet (1)'!$I$2 -> 20.462976 | E6: =SUM('Pay Combo Extra Bet (1)'!$J$13:$J$20) -> 0.071900065 | F6: Extra Bet 1 | G6: =1-'Multiplier Weight'!$N$69 -> 0.10958912 | H6: =SUM('Multiplier Weight'!N79:N126)-I6-J6 -> 0.021788657 | I6: =SUM('Multiplier Weight'!N81:N126)-J6 -> 0.020021288 | J6: =SUM('Multiplier Weight'!N87:N126) -> 0.003469783
A7: 8 | B7: 5 | C7: ='Pay Combo Extra Bet (2)'!$I$1 -> 0.087714148 | D7: ='Pay Combo Extra Bet (2)'!$I$2 -> 22.081394 | E7: =SUM('Pay Combo Extra Bet (2)'!$J$13:$J$20) -> 0.071900065 | F7: Extra Bet 2 | G7: =1-'Multiplier Weight'!$N$134 -> 0.13880396 | H7: =SUM('Multiplier Weight'!N153:N191)-I7-J7 -> 0.0052119 | I7: =SUM('Multiplier Weight'!N156:N191)-J7 -> 0.021861725 | J7: =SUM('Multiplier Weight'!N164:N191) -> 0.003936103
A8: 250 | B8: 5 | C8: ='Pay Combo Super Feature Buy'!$I$1 -> 0.010396634 | D8: ='Pay Combo Super Feature Buy'!$I$2 -> 3.7430546 | E8: =SUM('Pay Combo Super Feature Buy'!$J$23:$J$32) -> 0.23861416 | F8: Super Feature Buy
A11: Reel # | B11: 1 | C11: 2 | D11: 3 | E11: 4
A12: Visible Window Size | B12: 3 | C12: 3 | D12: 3 | E12: 3
A14: Volatility：
A15: Bonus Hit Freq.：
A17: Feature:
A18: Normal Bet : x1, multiple : 1x, 2x, 3x, 5x, 10x, 15x, 20x, 25x, 50x, 100x, 500x Extra Bet 1 : x1.5, multiple : 1x, 2x, 3x, 5x, 10x, 15x, 20x, 25x, 50x, 100x, 500x Extra Bet 2 : x8, multiple : 1x, 2x, 3x, 5x, 10x, 15x, 20x, 25x, 50x, 100x, 500x Super Feature Buy : x250, 5 Spins multiplier stay, multiple : 1x, 2x, 3x, 5x, 10x, 15x, 20x, 25x, 50x, 100x, 500x
A24: Pay Table： | B24: All wins show for 1 credit bet.
B25: WW | C25: C1*
A26: 5 | B26: 0 | C26: 0
A27: 4 | B27: 0 | C27: 0
A28: 3 | B28: 5 | C28: 0
B29: W1 | C29: W2 | D29: W3
A30: 5 | B30: 0 | C30: 0 | D30: 0
A31: 4 | B31: 0 | C31: 0 | D31: 0
A32: 3 | B32: 4 | C32: 3 | D32: 2.4
B33: WA | C33: WK | D33: WQ | E33: WJ
A34: 5 | B34: 0 | C34: 0 | D34: 0 | E34: 0
A35: 4 | B35: 0 | C35: 0 | D35: 0 | E35: 0
A36: 3 | B36: 2 | C36: 1.6 | D36: 1 | E36: 0.4
A39: For Pay Combo | B39: All wins show for 1 credit bet.
A40: WW | B40: =B28 -> 5
A41: W1 | B41: =B32 -> 4
A42: W2 | B42: =C32 -> 3
A43: W3 | B43: =D32 -> 2.4
A44: WA | B44: =B36 -> 2
A45: WK | B45: =C36 -> 1.6
A46: WQ | B46: =D36 -> 1
A47: WJ | B47: =E36 -> 0.4

Sheet Parameter
B1: Strip Table | F1: Normal Bet Weight | J1: Extra Bet 1 Weight | N1: Extra Bet 2 Weight | R1: Super Feature Buy Weight | V1: Normal Bet R4 | Y1: Extra Bet 1 R4 | AB1: Extra Bet 2 R4 | AE1: Super Feature Buy R4 | AH1: Reel 4 Multiple
B2: {=_xlfn.LET(_xlpm.x, 'Regular Symbol'!BW2:BY211, IF(_xlpm.x="", "", _xlpm.x))} -> R1 | C2: R2 | D2: R3 | F2: {=_xlfn.LET(_xlpm.x, 'Regular Symbol'!AA2:AC211, IF(_xlpm.x="", "", _xlpm.x))} -> R1 | G2: R2 | H2: R3 | J2: {=_xlfn.LET(_xlpm.x, 'Regular Symbol'!AM2:AO211, IF(_xlpm.x="", "", _xlpm.x))} -> R1 | K2: R2 | L2: R3 | N2: {=_xlfn.LET(_xlpm.x, 'Regular Symbol'!AY2:BA211, IF(_xlpm.x="", "", _xlpm.x))} -> R1 | O2: R2 | P2: R3 | R2: {=_xlfn.LET(_xlpm.x, 'Regular Symbol'!BK2:BM211, IF(_xlpm.x="", "", _xlpm.x))} -> R1 | S2: R2 | T2: R3 | V2: Normal | W2: Re-spin | Y2: Normal | Z2: Re-spin | AB2: Normal | AC2: Re-spin | AE2: Normal | AF2: Re-spin | AH2: {='Pay Combo Normal Bet'!$L$2:$N$14} -> 倍數 | AI2: 比例 | AJ2: 權重
B3: 7 | C3: 0 | D3: 1 | F3: 1 | G3: 1 | H3: 1 | J3: 1 | K3: 1 | L3: 1 | N3: 1 | O3: 1 | P3: 1 | R3: 100 | S3: 467 | T3: 100 | V3: {='Reel 4 Symbol'!AC3:AD211} -> 18 | W3: 30 | Y3: {='Reel 4 Symbol'!AM3:AN211} -> 18 | Z3: 30 | AB3: {='Reel 4 Symbol'!AW3:AX211} -> 18 | AC3: 30 | AE3: {='Reel 4 Symbol'!BG3:BH211} -> 18 | AF3: 30 | AH3: 1 | AI3: 0.2247191 | AJ3: 220000000
B4: 5 | C4: 0 | D4: 1 | F4: 1 | G4: 1 | H4: 1 | J4: 1 | K4: 1 | L4: 1 | N4: 1 | O4: 1 | P4: 1 | R4: 447 | S4: 584 | T4: 677 | V4: 17 | W4: 17 | Y4: 17 | Z4: 17 | AB4: 17 | AC4: 17 | AE4: 17 | AF4: 17 | AH4: 2 | AI4: 0.2247191 | AJ4: 220000000
B5: 5 | C5: 0 | D5: 1 | F5: 1 | G5: 1 | H5: 1 | J5: 1 | K5: 1 | L5: 1 | N5: 1 | O5: 1 | P5: 1 | R5: 373 | S5: 701 | T5: 564 | V5: 16 | W5: 28 | Y5: 16 | Z5: 28 | AB5: 16 | AC5: 28 | AE5: 16 | AF5: 28 | AH5: 3 | AI5: 0.2247191 | AJ5: 220000000
B6: 0 | C6: 7 | D6: 0 | F6: 1 | G6: 1 | H6: 1 | J6: 1 | K6: 1 | L6: 1 | N6: 1 | O6: 1 | P6: 1 | R6: 298 | S6: 100 | T6: 451 | V6: 12 | W6: 12 | Y6: 12 | Z6: 12 | AB6: 12 | AC6: 12 | AE6: 12 | AF6: 12 | AH6: 5 | AI6: 0.06639428 | AJ6: 65000000
B7: 0 | C7: 7 | D7: 0 | F7: 1 | G7: 1 | H7: 1 | J7: 1 | K7: 1 | L7: 1 | N7: 1 | O7: 1 | P7: 1 | R7: 373 | S7: 100 | T7: 564 | V7: 13 | W7: 25 | Y7: 13 | Z7: 25 | AB7: 13 | AC7: 25 | AE7: 13 | AF7: 25 | AH7: 10 | AI7: 0.030643514 | AJ7: 30000000
B8: 0 | C8: 4 | D8: 0 | F8: 1 | G8: 1 | H8: 1 | J8: 1 | K8: 1 | L8: 1 | N8: 1 | O8: 1 | P8: 1 | R8: 447 | S8: 100 | T8: 677 | V8: 15 | W8: 15 | Y8: 15 | Z8: 15 | AB8: 15 | AC8: 15 | AE8: 15 | AF8: 15 | AH8: 15 | AI8: 0.010214505 | AJ8: 10000000
B9: 4 | C9: 4 | D9: 4 | F9: 1 | G9: 1 | H9: 1 | J9: 1 | K9: 1 | L9: 1 | N9: 1 | O9: 1 | P9: 1 | R9: 100 | S9: 100 | T9: 100 | V9: 14 | W9: 26 | Y9: 14 | Z9: 26 | AB9: 14 | AC9: 26 | AE9: 14 | AF9: 26 | AH9: 20 | AI9: 0.0051072523 | AJ9: 5000000
B10: 4 | C10: 4 | D10: 4 | F10: 1 | G10: 1 | H10: 1 | J10: 1 | K10: 1 | L10: 1 | N10: 1 | O10: 1 | P10: 1 | R10: 100 | S10: 100 | T10: 100 | V10: 11 | W10: 11 | Y10: 11 | Z10: 11 | AB10: 13 | AC10: 13 | AE10: 11 | AF10: 11 | AH10: 25 | AI10: 0.0020429009 | AJ10: 2000000
B11: 4 | C11: 2 | D11: 4 | F11: 1 | G11: 1 | H11: 1 | J11: 1 | K11: 1 | L11: 1 | N11: 1 | O11: 1 | P11: 1 | R11: 100 | S11: 100 | T11: 100 | V11: 10 | W11: 22 | Y11: 10 | Z11: 22 | AB11: 12 | AC11: 24 | AE11: 10 | AF11: 22 | AH11: 50 | AI11: 0.0020429009 | AJ11: 2000000
B12: 2 | C12: 2 | D12: 2 | F12: 1 | G12: 1 | H12: 1 | J12: 1 | K12: 1 | L12: 1 | N12: 1 | O12: 1 | P12: 1 | R12: 100 | S12: 100 | T12: 100 | V12: 19 | W12: 11 | Y12: 19 | Z12: 11 | AB12: 19 | AC12: 12 | AE12: 19 | AF12: 11 | AH12: 100 | AI12: 0.0020429009 | AJ12: 2000000
B13: 2 | C13: 2 | D13: 2 | F13: 1 | G13: 1 | H13: 1 | J13: 1 | K13: 1 | L13: 1 | N13: 1 | O13: 1 | P13: 1 | R13: 100 | S13: 100 | T13: 100 | V13: 9 | W13: 21 | Y13: 9 | Z13: 21 | AB13: 12 | AC13: 24 | AE13: 9 | AF13: 21 | AH13: 500 | AI13: 0.0030643514 | AJ13: 3000000
B14: 5 | C14: 5 | D14: 2 | F14: 1 | G14: 1 | H14: 1 | J14: 1 | K14: 1 | L14: 1 | N14: 1 | O14: 1 | P14: 1 | R14: 100 | S14: 100 | T14: 100 | V14: 8 | W14: 8 | Y14: 9 | Z14: 9 | AB14: 13 | AC14: 13 | AE14: 9 | AF14: 9 | AH14: Re-spin | AI14: 0.20429009 | AJ14: 200000000
B15: 5 | C15: 5 | D15: 5 | F15: 1 | G15: 1 | H15: 1 | J15: 1 | K15: 1 | L15: 1 | N15: 1 | O15: 1 | P15: 1 | R15: 100 | S15: 100 | T15: 100 | V15: 11 | W15: 23 | Y15: 11 | Z15: 23 | AB15: 14 | AC15: 26 | AE15: 11 | AF15: 23
B16: 1 | C16: 5 | D16: 5 | F16: 1 | G16: 1 | H16: 1 | J16: 1 | K16: 1 | L16: 1 | N16: 1 | O16: 1 | P16: 1 | R16: 100 | S16: 100 | T16: 100 | V16: 12 | W16: 12 | Y16: 12 | Z16: 12 | AB16: 12 | AC16: 12 | AE16: 12 | AF16: 12
B17: 1 | C17: 4 | D17: 5 | F17: 1 | G17: 1 | H17: 1 | J17: 1 | K17: 1 | L17: 1 | N17: 1 | O17: 1 | P17: 1 | R17: 100 | S17: 100 | T17: 100 | V17: 13 | W17: 25 | Y17: 13 | Z17: 25 | AB17: 13 | AC17: 25 | AE17: 13 | AF17: 25 | AH17: Re-spin times
B18: 1 | C18: 4 | D18: 1 | F18: 1 | G18: 1 | H18: 1 | J18: 1 | K18: 1 | L18: 1 | N18: 1 | O18: 1 | P18: 1 | R18: 100 | S18: 100 | T18: 100 | V18: 14 | W18: 14 | Y18: 14 | Z18: 14 | AB18: 14 | AC18: 14 | AE18: 14 | AF18: 14 | AH18: {='Pay Combo Normal Bet'!$Q$2:$S$13} -> Re-spin數 | AI18: 比例 | AJ18: 權重
B19: 7 | C19: 4 | D19: 1 | F19: 1 | G19: 1 | H19: 1 | J19: 1 | K19: 1 | L19: 1 | N19: 1 | O19: 1 | P19: 1 | R19: 100 | S19: 100 | T19: 100 | V19: 15 | W19: 27 | Y19: 15 | Z19: 27 | AB19: 15 | AC19: 27 | AE19: 15 | AF19: 27 | AH19: 2 | AI19: 0.11111111 | AJ19: 120000000
B20: 7 | C20: 2 | D20: 1 | F20: 1 | G20: 1 | H20: 1 | J20: 1 | K20: 1 | L20: 1 | N20: 1 | O20: 1 | P20: 1 | R20: 100 | S20: 100 | T20: 100 | V20: 16 | W20: 16 | Y20: 16 | Z20: 16 | AB20: 16 | AC20: 16 | AE20: 16 | AF20: 16 | AH20: 3 | AI20: 0.11111111 | AJ20: 120000000
B21: 2 | C21: 2 | D21: 3 | F21: 1 | G21: 1 | H21: 1 | J21: 1 | K21: 1 | L21: 1 | N21: 1 | O21: 1 | P21: 1 | R21: 100 | S21: 100 | T21: 100 | V21: 17 | W21: 29 | Y21: 17 | Z21: 29 | AB21: 17 | AC21: 29 | AE21: 17 | AF21: 29 | AH21: 4 | AI21: 0.11111111 | AJ21: 120000000
B22: 2 | C22: 2 | D22: 3 | F22: 1 | G22: 1 | H22: 1 | J22: 1 | K22: 1 | L22: 1 | N22: 1 | O22: 1 | P22: 1 | R22: 100 | S22: 100 | T22: 100 | V22: 13 | W22: 13 | Y22: 13 | Z22: 13 | AB22: 13 | AC22: 13 | AE22: 13 | AF22: 13 | AH22: 5 | AI22: 0.11111111 | AJ22: 120000000
B23: 4 | C23: 4 | D23: 6 | F23: 1 | G23: 1 | H23: 1 | J23: 1 | K23: 1 | L23: 1 | N23: 1 | O23: 1 | P23: 1 | R23: 100 | S23: 701 | T23: 100 | V23: 12 | W23: 24 | Y23: 12 | Z23: 24 | AB23: 12 | AC23: 24 | AE23: 12 | AF23: 24 | AH23: 6 | AI23: 0.11111111 | AJ23: 120000000
B24: 4 | C24: 4 | D24: 6 | F24: 1 | G24: 1 | H24: 1 | J24: 1 | K24: 1 | L24: 1 | N24: 1 | O24: 1 | P24: 1 | R24: 100 | S24: 584 | T24: 100 | V24: 16 | W24: 16 | Y24: 16 | Z24: 16 | AB24: 16 | AC24: 16 | AE24: 16 | AF24: 16 | AH24: 7 | AI24: 0.074074074 | AJ24: 80000000
B25: 4 | C25: 0 | D25: 6 | F25: 1 | G25: 1 | H25: 1 | J25: 1 | K25: 1 | L25: 1 | N25: 1 | O25: 1 | P25: 1 | R25: 100 | S25: 467 | T25: 100 | V25: 15 | W25: 15 | Y25: 15 | Z25: 15 | AB25: 15 | AC25: 15 | AE25: 15 | AF25: 15 | AH25: 8 | AI25: 0.074074074 | AJ25: 80000000
B26: 3 | C26: 0 | D26: 4 | F26: 1 | G26: 1 | H26: 1 | J26: 1 | K26: 1 | L26: 1 | N26: 1 | O26: 1 | P26: 1 | R26: 100 | S26: 584 | T26: 100 | V26: 14 | W26: 14 | Y26: 14 | Z26: 14 | AB26: 14 | AC26: 14 | AE26: 14 | AF26: 14 | AH26: 9 | AI26: 0.074074074 | AJ26: 80000000
B27: 3 | C27: 0 | D27: 4 | F27: 1 | G27: 1 | H27: 1 | J27: 1 | K27: 1 | L27: 1 | N27: 1 | O27: 1 | P27: 1 | R27: 100 | S27: 701 | T27: 100 | V27: 11 | W27: 23 | Y27: 11 | Z27: 23 | AB27: 13 | AC27: 25 | AE27: 11 | AF27: 23 | AH27: 10 | AI27: 0.074074074 | AJ27: 80000000
B28: 6 | C28: 6 | D28: 4 | F28: 1 | G28: 1 | H28: 1 | J28: 1 | K28: 1 | L28: 1 | N28: 1 | O28: 1 | P28: 1 | R28: 100 | S28: 100 | T28: 100 | V28: 9 | W28: 9 | Y28: 9 | Z28: 9 | AB28: 12 | AC28: 12 | AE28: 9 | AF28: 9 | AH28: 20 | AI28: 0.074074074 | AJ28: 80000000
B29: 6 | C29: 6 | D29: 2 | F29: 1 | G29: 1 | H29: 1 | J29: 1 | K29: 1 | L29: 1 | N29: 1 | O29: 1 | P29: 1 | R29: 100 | S29: 100 | T29: 100 | V29: 19 | W29: 22 | Y29: 19 | Z29: 22 | AB29: 19 | AC29: 25 | AE29: 19 | AF29: 22 | AH29: 50 | AI29: 0.074074074 | AJ29: 80000000
B30: 1 | C30: 3 | D30: 2 | F30: 1 | G30: 1 | H30: 1 | J30: 1 | K30: 1 | L30: 1 | N30: 1 | O30: 1 | P30: 1 | R30: 100 | S30: 100 | T30: 100 | V30: 8 | W30: 8 | Y30: 9 | Z30: 9 | AB30: 12 | AC30: 12 | AE30: 9 | AF30: 9
B31: 1 | C31: 3 | D31: 7 | F31: 1 | G31: 1 | H31: 1 | J31: 1 | K31: 1 | L31: 1 | N31: 1 | O31: 1 | P31: 1 | R31: 100 | S31: 100 | T31: 100 | V31: 10 | W31: 22 | Y31: 10 | Z31: 22 | AB31: 13 | AC31: 13 | AE31: 10 | AF31: 22
B32: 7 | C32: 3 | D32: 7 | F32: 1 | G32: 1 | H32: 1 | J32: 1 | K32: 1 | L32: 1 | N32: 1 | O32: 1 | P32: 1 | R32: 100 | S32: 100 | T32: 677 | V32: 11 | W32: 11 | Y32: 11 | Z32: 11 | AB32: 12 | AC32: 12 | AE32: 11 | AF32: 11 | AH32: Multiple per Re-spin
B33: 7 | C33: 6 | D33: 7 | F33: 1 | G33: 1 | H33: 1 | J33: 1 | K33: 1 | L33: 1 | N33: 1 | O33: 1 | P33: 1 | R33: 100 | S33: 100 | T33: 564 | V33: 12 | W33: 24 | Y33: 12 | Z33: 24 | AB33: 12 | AC33: 24 | AE33: 12 | AF33: 24 | AH33: 倍數\nudge次數 | AI33: {='Pay Combo Normal Bet'!$AH$2:$AR$13} -> 2 | AJ33: 3 | AK33: 4 | AL33: 5 | AM33: 6 | AN33: 7 | AO33: 8 | AP33: 9 | AQ33: 10 | AR33: 20 | AS33: 50
B34: 2 | C34: 6 | D34: 0 | F34: 1 | G34: 1 | H34: 1 | J34: 1 | K34: 1 | L34: 1 | N34: 1 | O34: 1 | P34: 1 | R34: 100 | S34: 100 | T34: 451 | V34: 13 | W34: 13 | Y34: 13 | Z34: 13 | AB34: 13 | AC34: 13 | AE34: 13 | AF34: 13 | AH34: {='Pay Combo Normal Bet'!$V$3:$V$13} -> 1 | AI34: 0 | AJ34: 0 | AK34: 0 | AL34: 0 | AM34: 0 | AN34: 0 | AO34: 0 | AP34: 0 | AQ34: 265000000 | AR34: 265000000 | AS34: 265000000
B35: 2 | C35: 6 | D35: 0 | F35: 1 | G35: 1 | H35: 1 | J35: 1 | K35: 1 | L35: 1 | N35: 1 | O35: 1 | P35: 1 | R35: 100 | S35: 100 | T35: 564 | V35: 14 | W35: 26 | Y35: 14 | Z35: 26 | AB35: 14 | AC35: 26 | AE35: 14 | AF35: 26 | AH35: 2 | AI35: 0 | AJ35: 0 | AK35: 0 | AL35: 250000000 | AM35: 250000000 | AN35: 250000000 | AO35: 240000000 | AP35: 240000000 | AQ35: 240000000 | AR35: 240000000 | AS35: 240000000
B36: 5 | C36: 2 | D36: 0 | F36: 1 | G36: 1 | H36: 1 | J36: 1 | K36: 1 | L36: 1 | N36: 1 | O36: 1 | P36: 1 | R36: 100 | S36: 100 | T36: 677 | V36: 15 | W36: 15 | Y36: 15 | Z36: 15 | AB36: 15 | AC36: 15 | AE36: 15 | AF36: 15 | AH36: 3 | AI36: 0 | AJ36: 250000000 | AK36: 250000000 | AL36: 200000000 | AM36: 200000000 | AN36: 200000000 | AO36: 170000000 | AP36: 170000000 | AQ36: 170000000 | AR36: 170000000 | AS36: 170000000
B37: 5 | C37: 2 | D37: 6 | F37: 1 | G37: 1 | H37: 1 | J37: 1 | K37: 1 | L37: 1 | N37: 1 | O37: 1 | P37: 1 | R37: 100 | S37: 100 | T37: 100 | V37: 16 | W37: 28 | Y37: 16 | Z37: 28 | AB37: 16 | AC37: 28 | AE37: 16 | AF37: 28 | AH37: 5 | AI37: 150000000 | AJ37: 150000000 | AK37: 150000000 | AL37: 160000000 | AM37: 160000000 | AN37: 160000000 | AO37: 130000000 | AP37: 130000000 | AQ37: 130000000 | AR37: 130000000 | AS37: 130000000
B38: 1 | C38: 2 | D38: 6 | F38: 1 | G38: 1 | H38: 1 | J38: 1 | K38: 1 | L38: 1 | N38: 1 | O38: 1 | P38: 1 | R38: 100 | S38: 100 | T38: 100 | V38: 18 | W38: 18 | Y38: 18 | Z38: 18 | AB38: 18 | AC38: 18 | AE38: 18 | AF38: 18 | AH38: 10 | AI38: 100000000 | AJ38: 100000000 | AK38: 100000000 | AL38: 80000000 | AM38: 80000000 | AN38: 80000000 | AO38: 80000000 | AP38: 80000000 | AQ38: 80000000 | AR38: 80000000 | AS38: 80000000
B39: 1 | C39: 5 | D39: 6 | F39: 1 | G39: 1 | H39: 1 | J39: 1 | K39: 1 | L39: 1 | N39: 1 | O39: 1 | P39: 1 | R39: 100 | S39: 100 | T39: 100 | V39: 17 | W39: 17 | Y39: 17 | Z39: 17 | AB39: 17 | AC39: 17 | AE39: 17 | AF39: 17 | AH39: 15 | AI39: 80000000 | AJ39: 80000000 | AK39: 80000000 | AL39: 50000000 | AM39: 50000000 | AN39: 50000000 | AO39: 50000000 | AP39: 50000000 | AQ39: 50000000 | AR39: 50000000 | AS39: 50000000
B40: 7 | C40: 5 | D40: 6 | F40: 1 | G40: 1 | H40: 1 | J40: 1 | K40: 1 | L40: 1 | N40: 1 | O40: 1 | P40: 1 | R40: 100 | S40: 100 | T40: 100 | V40: 9 | W40: 9 | Y40: 9 | Z40: 9 | AB40: 15 | AC40: 27 | AE40: 9 | AF40: 9 | AH40: 20 | AI40: 20000000 | AJ40: 20000000 | AK40: 20000000 | AL40: 20000000 | AM40: 20000000 | AN40: 20000000 | AO40: 20000000 | AP40: 20000000 | AQ40: 20000000 | AR40: 20000000 | AS40: 20000000
...

Sheet Parameter-卡片
C1: Normal Bet Weight | D1: Extra Bet 1 Weight | E1: Extra Bet 2 Weight | F1: Super Feature Buy Weight | G1: Normal Bet Weight | H1: Extra Bet 1 Weight | I1: Extra Bet 2 Weight | J1: Super Feature Buy Weight
A2: {='Multiplier Weight'!A3:B61} -> Lower | B2: Upper | C2: {='Multiplier Weight'!M3:M61} -> Fixed Weight | D2: {='Multiplier Weight'!M68:M126} -> Fixed Weight | E2: {='Multiplier Weight'!M133:M191} -> Fixed Weight | F2: {='Multiplier Weight'!M198:M256} -> Fixed Weight | G2: {='Multiplier Weight (new_player)'!M3:M61} -> Fixed Weight | H2: {='Multiplier Weight (new_player)'!M68:M126} -> Fixed Weight | I2: {='Multiplier Weight (new_player)'!M133:M191} -> Fixed Weight | J2: {='Multiplier Weight (new_player)'!#REF!} -> #REF! | L2: Scatter Combo Rate
A3: -1 | B3: 0 | C3: 891731804 | D3: 890410885 | E3: 861196036 | F3: 0 | G3: 903421347 | H3: 873706924 | I3: 877653596 | M3: Normal | N3: EX1 | O3: EX2 | P3: Super Buy
A4: 0 | B4: 1 | C4: 11248722 | D4: 3868065 | E4: 0 | F4: 0 | G4: 5420629 | H4: 9749585 | I4: 0 | L4: 老手 | M4: 3738112000 | N4: 4093821000 | O4: 3103576000 | P4: 31318315000
A5: 1 | B5: 2 | C5: 15597397 | D5: 11187304 | E5: 0 | F5: 0 | G5: 8786560 | H5: 15807150 | I5: 0 | L5: 新手 | M5: 3728958000 | N5: 4085750000 | O5: 3137415000 | P5: --
A6: 2 | B6: 3 | C6: 11058852 | D6: 5723855 | E6: 0 | F6: 0 | G6: 6195594 | H6: 11144138 | I6: 0
A7: 3 | B7: 4 | C7: 11752892 | D7: 10551459 | E7: 0 | F7: 0 | G7: 8149042 | H7: 12156995 | I7: 0
A8: 4 | B8: 5 | C8: 9584854 | D8: 9843433 | E8: 0 | F8: 0 | G8: 5570825 | H8: 8310214 | I8: 0
A9: 5 | B9: 6 | C9: 7649926 | D9: 8695263 | E9: 0 | F9: 0 | G9: 5538782 | H9: 8262271 | I9: 0
A10: 6 | B10: 7 | C10: 1858782 | D10: 1984051 | E10: 0 | F10: 0 | G10: 1395012 | H10: 2081010 | I10: 0
A11: 7 | B11: 8 | C11: 7980106 | D11: 9042157 | E11: 32115336 | F11: 0 | G11: 14520405 | H11: 8664105 | I11: 31496205
A12: 8 | B12: 9 | C12: 2919421 | D12: 3413800 | E12: 0 | F12: 0 | G12: 3165427 | H12: 3777460 | I12: 0
A13: 9 | B13: 10 | C13: 5872603 | D13: 7940841 | E13: 24198962 | F13: 0 | G13: 3934521 | H13: 4695242 | I13: 4747076
A14: 10 | B14: 15 | C14: 9351940 | D14: 13847816 | E14: 3861211 | F14: 0 | G14: 19729627 | H14: 7097136 | I14: 3788888
A15: 15 | B15: 20 | C15: 5550221 | D15: 8714720 | E15: 13261839 | F15: 0 | G15: 4951515 | H15: 17811261 | I15: 13016438
A16: 20 | B16: 25 | C16: 2325916 | D16: 4863903 | E16: 8352121 | F16: 0 | G16: 6840815 | H16: 2460698 | I16: 8200227
A17: 25 | B17: 30 | C17: 2015710 | D17: 3240963 | E17: 6624296 | F17: 0 | G17: 2379899 | H17: 1712116 | I17: 6505143
... A60: 100000 | B60: 999999 | C60: 0 | D60: 0 | E60: 0 | F60: 0 | G60: 0 | H60: 0 | I60: 0

Sheet Multiplier Weight
A1: Normal Game | C1: (後端報表) | D1: scale | E1: 100 | O1: Total RTP | P1: Target | Q1: Error
C2: Simulator | I2: Fixed Game | J2: 3000 | M2: =10^9 -> 1000000000 | O2: =SUM(_xlfn.ANCHORARRAY(O4)) -> 0.87 | P2: 0.92 | Q2: =P2-O2 -> 0.05
A3: Lower | B3: Upper | C3: Count | D3: Pay | E3: Multi. | F3: Prob. | G3: RTP | I3: Range | J3: Fix freq | K3: Fix num | L3: Fixed Prob. | M3: Fixed Weight | N3: Real Prob. | O3: Real RTP | P3: =SUM(_xlfn.ANCHORARRAY(Q4)) -> 0.96564291 | R3: =1-SUM(_xlfn.ANCHORARRAY(R4)) -> 0.047266861 | W3: 參考修正值 | Y3: 180 | Z3: 200 | AB3: {=_xlfn._xlws.SORT(_xlfn.UNIQUE(Y3:Y153))} -> 30 | AC3: {=COUNTIF(Y3:Y153,_xlfn.ANCHORARRAY(AB3))} -> 1 | AD3: {=_xlfn.ANCHORARRAY(AC3)/10000000} -> 1e-07 | AF3: BaseGame 00 | AG3: 79527545
A4: -1 | B4: 0 | C4: 795188919 | D4: 0 | E4: =IFERROR((D4/$E$1)/(C4),0) -> 0 | F4: {=C4:C61/SUM(C4:C61)} -> 0.79518892 | G4: {=E4:E61*_xlfn.ANCHORARRAY(F4)} -> 0 | I4: ="("&$A4&", "&$B4&"]" -> (-1, 0] | J4: {=IFERROR(IF(1/_xlfn.ANCHORARRAY(F4)<$J$2,1,0),0)} -> 1 | K4: 1.1214087 | L4: {=K4:K61*_xlfn.ANCHORARRAY(J4)*_xlfn.ANCHORARRAY(F4)} -> 0.8917318 | M4: {=INT(_xlfn.ANCHORARRAY(L4)*$M$2)} -> 891731804 | N4: {=_xlfn.ANCHORARRAY(M4)/SUM(_xlfn.ANCHORARRAY(M4))} -> 0.8917318 | O4: {=_xlfn.ANCHORARRAY(N4)*E4:E61} -> 0 | P4: 0.88031431 | Q4: {=P4:P55*E4:E55} -> 0 | R4: {=P2*P4:P55/P3} -> 0.83870462 | S4: =R4+R3 -> 0.88597148 | T4: {=S4:S55/_xlfn.ANCHORARRAY(F4)} -> 1.1141648 | W4: 1.0286652 | Y4: 45 | Z4: 50 | AB4: 40 | AC4: 3 | AD4: 3e-07 | AF4: BaseGame 0x | AG4: 1221030 | AH4: Pay | AI4: 91661240 | AJ4: 1C1 | AK4: null | AL4: 2C1 | AM4: null | AN4: 3C1 | AO4: null | AP4: 4C1 | AQ4: null | AR4: 5C1 | AS4: null
A5: 0 | B5: 1 | C5: 12223533 | D5: 917729700 | E5: =IFERROR((D5/$E$1)/(C5),0) -> 0.75078924 | F5: 0.012223533 | G5: 0.009177297 | I5: ="("&$A5&", "&$B5&"]" -> (0, 1] | J5: 1 | K5: 0.92025133 | L5: 0.011248723 | M5: 11248722 | N5: 0.011248722 | O5: 0.0084454194 | P5: 0.012357339 | Q5: 0.0092777571 | R5: 0.011773246 | S5: {=R5:R55} -> 0.011773246 | T5: 0.96316231 | W5: 1.0484973 | Y5: 160 | Z5: 180 | AB5: 45 | AC5: 2 | AD5: 2e-07 | AF5: BaseGame 1x | AG5: 1983581 | AH5: Pay | AI5: 340592420 | AJ5: 1C1 | AK5: null | AL5: 2C1 | AM5: null | AN5: 3C1 | AO5: null | AP5: 4C1 | AQ5: null | AR5: 5C1 | AS5: null
A6: 1 | B6: 2 | C6: 19854235 | D6: 3409420460 | E6: =IFERROR((D6/$E$1)/(C6),0) -> 1.7172258 | F6: 0.019854235 | G6: 0.034094205 | I6: ="("&$A6&", "&$B6&"]" -> (1, 2] | J6: 1 | K6: 0.78559549 | L6: 0.015597398 | M6: 15597397 | N6: 0.015597397 | O6: 0.026784253 | P6: 0.017178728 | Q6: 0.029499755 | R6: 0.016366744 | S6: 0.016366744 | T6: 0.82434521 | W6: 0.87200957 | Y6: 160 | Z6: 180 | AB6: 60 | AC6: 5 | AD6: 5e-07 | AF6: BaseGame 2x | AG6: 1400402 | AH6: Pay | AI6: 385097500 | AJ6: 1C1 | AK6: null | AL6: 2C1 | AM6: null | AN6: 3C1 | AO6: null | AP6: 4C1 | AQ6: null | AR6: 5C1 | AS6: null
A7: 2 | B7: 3 | C7: 14020917 | D7: 3854712400 | E7: =IFERROR((D7/$E$1)/(C7),0) -> 2.7492584 | F7: 0.014020917 | G7: 0.038547124 | I7: ="("&$A7&", "&$B7&"]" -> (2, 3] | J7: 1 | K7: 0.7887396 | L7: 0.011058853 | M7: 11058852 | N7: 0.011058852 | O7: 0.030403642 | P7: 0.012210325 | Q7: 0.033569339 | R7: 0.011633181 | S7: 0.011633181 | T7: 0.82970188 | W7: 0.93129385 | Y7: 120 | Z7: 140 | AB7: 80 | AC7: 10 | AD7: 1e-06 | AF7: BaseGame 3x | AG7: 1843384 | AH7: Pay | AI7: 681736680 | AJ7: 1C1 | AK7: null | AL7: 2C1 | AM7: null | AN7: 3C1 | AO7: null | AP7: 4C1 | AQ7: null | AR7: 5C1 | AS7: null
A8: 3 | B8: 4 | C8: 18463165 | D8: 6828453200 | E8: =IFERROR((D8/$E$1)/(C8),0) -> 3.6984196 | F8: 0.018463165 | G8: 0.068284532 | I8: ="("&$A8&", "&$B8&"]" -> (3, 4] | J8: 1 | K8: 0.63655893 | L8: 0.011752892 | M8: 11752892 | N8: 0.011752892 | O8: 0.043467127 | P8: 0.012996256 | Q8: 0.048065607 | R8: 0.012381963 | S8: 0.012381963 | T8: 0.6706306 | W8: 0.76505623 | Y8: 80 | Z8: 90 | AB8: 90 | AC8: 6 | AD8: 6e-07 | AF8: BaseGame 4x | AG8: 1261039 | AH8: Pay | AI8: 605977340 | AJ8: 1C1 | AK8: null | AL8: 2C1 | AM8: null | AN8: 3C1 | AO8: null | AP8: 4C1 | AQ8: null | AR8: 5C1 | AS8: null
A9: 4 | B9: 5 | C9: 12601097 | D9: 6055478580 | E9: =IFERROR((D9/$E$1)/(C9),0) -> 4.805517 | F9: 0.012601097 | G9: 0.060554786 | I9: ="("&$A9&", "&$B9&"]" -> (4, 5] | J9: 1 | K9: 0.76063651 | L9: 0.0095848545 | M9: 9584854 | N9: 0.009584854 | O9: 0.046060179 | P9: 0.010587974 | Q9: 0.05088069 | R9: 0.010087514 | S9: 0.010087514 | T9: 0.80052664 | W9: 0.97221486 | Y9: 120 | Z9: 140 | AB9: 120 | AC9: 9 | AD9: 9e-07 | AF9: BaseGame 5x | AG9: 1254493 | AH9: Pay | AI9: 746676720 | AJ9: 1C1 | AK9: null | AL9: 2C1 | AM9: null | AN9: 3C1 | AO9: null | AP9: 4C1 | AQ9: null | AR9: 5C1 | AS9: null
A10: 5 | B10: 6 | C10: 12543731 | D10: 7466041340 | E10: =IFERROR((D10/$E$1)/(C10),0) -> 5.9520101 | F10: 0.012543731 | G10: 0.074660413 | I10: ="("&$A10&", "&$B10&"]" -> (5, 6] | J10: 1 | K10: 0.60986054 | L10: 0.0076499265 | M10: 7649926 | N10: 0.007649926 | O10: 0.045532437 | P10: 0.0083771962 | Q10: 0.049861156 | R10: 0.0079812324 | S10: 0.0079812324 | T10: 0.63627261 | W10: 0.7310748 | Y10: 60 | Z10: 70 | AB10: 140 | AC10: 6 | AD10: 6e-07 | AF10: BaseGame 6x | AG10: 316037 | AH10: Pay | AI10: 206311540 | AJ10: 1C1 | AK10: null | AL10: 2C1 | AM10: null | AN10: 3C1 | AO10: null | AP10: 4C1 | AQ10: null | AR10: 5C1 | AS10: null
A11: 6 | B11: 7 | C11: 3159125 | D11: 2062217360 | E11: =IFERROR((D11/$E$1)/(C11),0) -> 6.5278118 | F11: 0.003159125 | G11: 0.020622174 | I11: ="("&$A11&", "&$B11&"]" -> (6, 7] | J11: 1 | K11: 0.58838523 | L11: 0.0018587825 | M11: 1858782 | N11: 0.001858782 | O11: 0.012133779 | P11: 0.0021346722 | Q11: 0.013934738 | R11: 0.0020337729 | S11: 0.0020337729 | T11: 0.64377729 | W11: 0.92193727 | Y11: 120 | Z11: 140 | AB11: 160 | AC11: 6 | AD11: 6e-07 | AF11: BaseGame 7x | AG11: 1316405 | AH11: Pay | AI11: 1015442580 | AJ11: 1C1 | AK11: null | AL11: 2C1 | AM11: null | AN11: 3C1 | AO11: null | AP11: 4C1 | AQ11: null | AR11: 5C1 | AS11: null
A12: 7 | B12: 8 | C12: 13147608 | D12: 10142167660 | E12: =IFERROR((D12/$E$1)/(C12),0) -> 7.7140782 | F12: 0.013147608 | G12: 0.10142168 | I12: ="("&$A12&", "&$B12&"]" -> (7, 8] | J12: 1 | K12: 0.60696261 | L12: 0.0079801065 | M12: 7980106 | N12: 0.007980106 | O12: 0.061559162 | P12: 0.0088375429 | Q12: 0.068173497 | R12: 0.00841982 | S12: 0.00841982 | T12: 0.64040698 | W12: 0.83718336 | Y12: 90 | Z12: 100 | AB12: 180 | AC12: 1 | AD12: 1e-07 | AF12: BaseGame 8x | AG12: 574169 | AH12: Pay | AI12: 512208280 | AJ12: 1C1 | AK12: null | AL12: 2C1 | AM12: null | AN12: 3C1 | AO12: null | AP12: 4C1 | AQ12: null | AR12: 5C1 | AS12: null
A13: 8 | B13: 9 | C13: 5760279 | D13: 5138867060 | E13: =IFERROR((D13/$E$1)/(C13),0) -> 8.9212121 | F13: 0.005760279 | G13: 0.051388671 | I13: ="("&$A13&", "&$B13&"]" -> (8, 9] | J13: 1 | K13: 0.50681946 | L13: 0.0029194215 | M13: 2919421 | N13: 0.002919421 | O13: 0.026044774 | P13: 0.0032443305 | Q13: 0.02894336 | R13: 0.0030909812 | S13: 0.0030909812 | T13: 0.53660268 | W13: 0.73011297 | Y13: 90 | Z13: 100 | AB13: 200 | AC13: 4 | AD13: 4e-07 | AF13: BaseGame 9x | AG13: 713840 | AH13: Pay | AI13: 696013360 | AJ13: 1C1 | AK13: null | AL13: 2C1 | AM13: null | AN13: 3C1 | AO13: null | AP13: 4C1 | AQ13: null | AR13: 5C1 | AS13: null
A14: 9 | B14: 10 | C14: 7136369 | D14: 6958218440 | E14: =IFERROR((D14/$E$1)/(C14),0) -> 9.7503625 | F14: 0.007136369 | G14: 0.069582184 | I14: ="("&$A14&", "&$B14&"]" -> (9, 10] | J14: 1 | K14: 0.82291197 | L14: 0.0058726035 | M14: 5872603 | N14: 0.005872603 | O14: 0.057260008 | P14: 0.0064938585 | Q14: 0.063317474 | R14: 0.0061869142 | S14: 0.0061869142 | T14: 0.86695547 | W14: 1.0527638 | Y14: 80 | Z14: 90 | AB14: 0 | AC14: 0 | AD14: 0 | AF14: BaseGame 10x | AG14: 1791031 | AH14: Pay | AI14: 2280142320 | AJ14: 1C1 | AK14: null | AL14: 2C1 | AM14: null | AN14: 3C1 | AO14: null | AP14: 4C1 | AQ14: null | AR14: 5C1 | AS14: null
A15: 10 | B15: 15 | C15: 17909726 | D15: 22799765820 | E15: =IFERROR((D15/$E$1)/(C15),0) -> 12.730382 | F15: 0.017909726 | G15: 0.22799766 | I15: ="("&$A15&", "&$B15&"]" -> (10, 15] | J15: 1 | K15: 0.52217105 | L15: 0.0093519405 | M15: 9351940 | N15: 0.00935194 | O15: 0.11905377 | P15: 0.010357801 | Q15: 0.13185876 | R15: 0.00986822 | S15: 0.00986822 | T15: 0.55099782 | W15: 0.81707965 | Y15: 40 | Z15: 45 | AF15: BaseGame 15x | AG15: 1124732 | AH15: Pay | AI15: 2007398080 | AJ15: 1C1 | AK15: null | AL15: 2C1 | AM15: null | AN15: 3C1 | AO15: null | AP15: 4C1 | AQ15: null | AR15: 5C1 | AS15: null
A16: 15 | B16: 20 | C16: 11269242 | D16: 20112711300 | E16: =IFERROR((D16/$E$1)/(C16),0) -> 17.847439 | F16: 0.011269242 | G16: 0.20112711 | I16: ="("&$A16&", "&$B16&"]" -> (15, 20] | J16: 1 | K16: 0.49251063 | L16: 0.0055502215 | M16: 5550221 | N16: 0.005550221 | O16: 0.099057233 | P16: 0.006169017 | Q16: 0.11010116 | R16: 0.005877427 | S16: 0.005877427 | T16: 0.5215459 | W16: 0.79998561 | Y16: 80 | Z16: 90 | AF16: BaseGame 20x | AG16: 621987 | AH16: Pay | AI16: 1445763680 | AJ16: 1C1 | AK16: null | AL16: 2C1 | AM16: null | AN16: 3C1 | AO16: null | AP16: 4C1 | AQ16: null | AR16: 5C1 | AS16: null
A17: 20 | B17: 25 | C17: 6214274 | D17: 14443908240 | E17: =IFERROR((D17/$E$1)/(C17),0) -> 23.243115 | F17: 0.006214274 | G17: 0.14443908 | I17: ="("&$A17&", "&$B17&"]" -> (20, 25] | J17: 1 | K17: 0.37428612 | L17: 0.0023259165 | M17: 2325916 | N17: 0.002325916 | O17: 0.054061532 | P17: 0.002581654 | Q17: 0.06000568 | R17: 0.0024596273 | S17: 0.0024596273 | T17: 0.39580284 | W17: 0.68578908 | Y17: 80 | Z17: 90 | AF17: BaseGame 25x | AG17: 433005 | AH17: Pay | AI17: 1231300120 | AJ17: 1C1 | AK17: null | AL17: 2C1 | AM17: null | AN17: 3C1 | AO17: null | AP17: 4C1 | AQ17: null | AR17: 5C1 | AS17: null
A18: 25 | B18: 30 | C18: 4327912 | D18: 12306435380 | E18: =IFERROR((D18/$E$1)/(C18),0) -> 28.435041 | F18: 0.004327912 | G18: 0.12306435 | I18: ="("&$A18&", "&$B18&"]" -> (25, 30] | J18: 1 | K18: 0.46574665 | L18: 0.0020157105 | M18: 2015710 | N18: 0.00201571 | O18: 0.057316796 | P18: 0.0022505014 | Q18: 0.063993098 | R18: 0.0021441272 | S18: 0.0021441272 | T18: 0.4954184 | W18: 0.98311644 | Y18: 90 | Z18: 100 | AF18: BaseGame 30x | AG18: 214207 | AH18: Pay | AI18: 697834840 | AJ18: 1C1 | AK18: null | AL18: 2C1 | AM18: null | AN18: 3C1 | AO18: null | AP18: 4C1 | AQ18: null | AR18: 5C1 | AS18: null
A19: 30 | B19: 35 | C19: 2145347 | D19: 6990216720 | E19: =IFERROR((D19/$E$1)/(C19),0) -> 32.583152 | F19: 0.002145347 | G19: 0.069902167 | I19: ="("&$A19&", "&$B19&"]" -> (30, 35] | J19: 1 | K19: 0.17951292 | L19: 0.0003851175 | M19: 385117 | N19: 0.000385117 | O19: 0.012548326 | P19: 0.00042879068 | Q19: 0.013971352 | R19: 0.00040852309 | S19: 0.00040852309 | T19: 0.19042285 | W19: 0.49864521 | Y19: 60 | Z19: 70 | AF19: BaseGame 35x | AG19: 376411 | AH19: Pay | AI19: 1440717120 | AJ19: 1C1 | AK19: null | AL19: 2C1 | AM19: null | AN19: 3C1 | AO19: null | AP19: 4C1 | AQ19: null | AR19: 5C1 | AS19: null
A20: 35 | B20: 40 | C20: 3778148 | D20: 14458614080 | E20: =IFERROR((D20/$E$1)/(C20),0) -> 38.269052 | F20: 0.003778148 | G20: 0.14458614 | I20: ="("&$A20&", "&$B20&"]" -> (35, 40] | J20: 1 | K20: 0.23779918 | L20: 0.0008984405 | M20: 898440 | N20: 0.00089844 | O20: 0.034382447 | P20: 0.0010049665 | Q20: 0.038459117 | R20: 0.00095746493 | S20: 0.00095746493 | T20: 0.25342176 | W20: 0.49441416 | Y20: 80 | Z20: 90 | AF20: BaseGame 40x | AG20: 165201 | AH20: Pay | AI20: 718988620 | AJ20: 1C1 | AK20: null | AL20: 2C1 | AM20: null | AN20: 3C1 | AO20: null | AP20: 4C1 | AQ20: null | AR20: 5C1 | AS20: null
A21: 40 | B21: 45 | C21: 1647988 | D21: 7173008520 | E21: =IFERROR((D21/$E$1)/(C21),0) -> 43.525854 | F21: 0.001647988 | G21: 0.071730085 | I21: ="("&$A21&", "&$B21&"]" -> (40, 45] | J21: 1 | K21: 0.12660135 | L21: 0.0002086375 | M21: 208637 | N21: 0.000208637 | O21: 0.0090811036 | P21: 0.00023202959 | Q21: 0.010099286 | R21: 0.00022106228 | S21: 0.00022106228 | T21: 0.13414071 | W21: 0.41782936 | Y21: 140 | Z21: 160 | AF21: BaseGame 45x | AG21: 203218 | AH21: Pay | AI21: 977981300 | AJ21: 1C1 | AK21: null | AL21: 2C1 | AM21: null | AN21: 3C1 | AO21: null | AP21: 4C1 | AQ21: null | AR21: 5C1 | AS21: null
A22: 45 | B22: 50 | C22: 2034040 | D22: 9788723540 | E22: =IFERROR((D22/$E$1)/(C22),0) -> 48.124538 | F22: 0.00203404 | G22: 0.097887235 | I22: ="("&$A22&", "&$B22&"]" -> (45, 50] | J22: 1 | K22: 0.51277433 | L22: 0.0010430035 | M22: 1043003 | N22: 0.001043003 | O22: 0.050194038 | P22: 0.0011646029 | Q22: 0.056045977 | R22: 0.0011095558 | S22: 0.0011095558 | T22: 0.54549359 | W22: 1.4185856 | Y22: 80 | Z22: 90 | AF22: BaseGame 50x | AG22: 324269 | AH22: Pay | AI22: 1840796800 | AJ22: 1C1 | AK22: null | AL22: 2C1 | AM22: null | AN22: 3C1 | AO22: null | AP22: 4C1 | AQ22: null | AR22: 5C1 | AS22: null
A23: 50 | B23: 60 | C23: 3238075 | D23: 18382953720 | E23: =IFERROR((D23/$E$1)/(C23),0) -> 56.771241 | F23: 0.003238075 | G23: 0.18382954 | I23: ="("&$A23&", "&$B23&"]" -> (50, 60] | J23: 1 | K23: 0.12556673 | L23: 0.0004065945 | M23: 406594 | N23: 0.000406594 | O23: 0.023082846 | P23: 0.00045292175 | Q23: 0.02571293 | R23: 0.00043151356 | S23: 0.00043151356 | T23: 0.13326237 | W23: 0.42154538 | Y23: 140 | Z23: 160 | AF23: BaseGame 60x | AG23: 197124 | AH23: Pay | AI23: 1291443040 | AJ23: 1C1 | AK23: null | AL23: 2C1 | AM23: null | AN23: 3C1 | AO23: null | AP23: 4C1 | AQ23: null | AR23: 5C1 | AS23: null
A24: 60 | B24: 70 | C24: 1975180 | D24: 12940084160 | E24: =IFERROR((D24/$E$1)/(C24),0) -> 65.513443 | F24: 0.00197518 | G24: 0.12940084 | I24: ="("&$A24&", "&$B24&"]" -> (60, 70] | J24: 1 | K24: 0.02116035 | L24: 4.17955e-05 | M24: 41795 | N24: 4.1795e-05 | O24: 0.0027381343 | P24: 4.6777165e-05 | Q24: 0.0030645331 | R24: 4.4566155e-05 | S24: 4.4566155e-05 | T24: 0.022563085 | W24: 0.12078965 | Y24: 160 | Z24: 180 | AF24: BaseGame 70x | AG24: 255967 | AH24: Pay | AI24: 1949434600 | AJ24: 1C1 | AK24: null | AL24: 2C1 | AM24: null | AN24: 3C1 | AO24: null | AP24: 4C1 | AQ24: null | AR24: 5C1 | AS24: null
A25: 70 | B25: 80 | C25: 2561154 | D25: 19504057100 | E25: =IFERROR((D25/$E$1)/(C25),0) -> 76.153395 | F25: 0.002561154 | G25: 0.19504057 | I25: ="("&$A25&", "&$B25&"]" -> (70, 80] | J25: 1 | K25: 0.069944056 | L25: 0.0001791375 | M25: 179137 | N25: 0.000179137 | O25: 0.013641891 | P25: 0.00020010232 | Q25: 0.015238471 | R25: 0.00019064411 | S25: 0.00019064411 | T25: 0.0744368 | W25: 0.2628356 | Y25: 30 | Z25: 35 | AF25: BaseGame 80x | AG25: 168742 | AH25: Pay | AI25: 1456119240 | AJ25: 1C1 | AK25: null | AL25: 2C1 | AM25: null | AN25: 3C1 | AO25: null | AP25: 4C1 | AQ25: null | AR25: 5C1 | AS25: null
A26: 80 | B26: 90 | C26: 1688794 | D26: 14572354840 | E26: =IFERROR((D26/$E$1)/(C26),0) -> 86.288528 | F26: 0.001688794 | G26: 0.14572355 | I26: ="("&$A26&", "&$B26&"]" -> (80, 90] | J26: 1 | K26: 0.040809299 | L26: 6.89185e-05 | M26: 68918 | N26: 6.8918e-05 | O26: 0.0059468328 | P26: 7.7219447e-05 | Q26: 0.0066631524 | R26: 7.3569526e-05 | S26: 7.3569526e-05 | T26: 0.043563351 | W26: 0.22967491 | Y26: 80 | Z26: 90 | AF26: BaseGame 90x | AG26: 167385 | AH26: Pay | AI26: 1609603760 | AJ26: 1C1 | AK26: null | AL26: 2C1 | AM26: null | AN26: 3C1 | AO26: null | AP26: 4C1 | AQ26: null | AR26: 5C1 | AS26: null
... A35: 300 | B35: 350 | C35: 1196831 | D35: 38851996520 | E35: =IFERROR((D35/$E$1)/(C35),0) -> 324.62392 | F35: 0.001196831 | G35: 0.38851997 | I35: ="("&$A35&", "&$B35&"]" -> (300, 350] | J35: 1 | K35: 0.00027614592 | L35: 3.305e-07 | M35: 330 | N35: 3.3e-07 | O35: 0.00010712589 | P35: 3.7124734e-07 | Q35: 0.00012051576 | R35: 3.5369964e-07 | S35: 3.5369964e-07 | T35: 0.00029553015 | W35: 0.0034030453 | Y35: 60 | Z35: 70 | AF35: BaseGame 350x | AG35: 101299 | AH35: Pay | AI35: 3810751320 | AJ35: 1C1 | AK35: null | AL35: 2C1 | AM35: null | AN35: 3C1 | AO35: null | AP35: 4C1 | AQ35: null | AR35: 5C1 | AS35: null
A36: 350 | B36: 400 | C36: 1011971 | D36: 38072554780 | E36: =IFERROR((D36/$E$1)/(C36),0) -> 376.2218 | F36: 0.001011971 | G36: 0.38072555 | I36: ="("&$A36&", "&$B36&"]" -> (350, 400] | J36: 1 | K36: 0 | L36: 0 | M36: 0 | N36: 0 | O36: 0 | P36: 0 | Q36: 0 | R36: 0 | S36: 0 | T36: 0 | Y36: 120 | Z36: 140 | AF36: BaseGame 400x | AG36: 76969 | AH36: Pay | AI36: 3273311860 | AJ36: 1C1 | AK36: null | AL36: 2C1 | AM36: null | AN36: 3C1 | AO36: null | AP36: 4C1 | AQ36: null | AR36: 5C1 | AS36: null
A37: 400 | B37: 450 | C37: 771708 | D37: 32822608040 | E37: =IFERROR((D37/$E$1)/(C37),0) -> 425.32419 | F37: 0.000771708 | G37: 0.32822608 | I37: ="("&$A37&", "&$B37&"]" -> (400, 450] | J37: 1 | K37: 0 | L37: 0 | M37: 0 | N37: 0 | O37: 0 | P37: 0 | Q37: 0 | R37: 0 | S37: 0 | T37: 0 | Y37: 60 | Z37: 70 | AF37: BaseGame 450x | AG37: 66958 | AH37: Pay | AI37: 3195883300 | AJ37: 1C1 | AK37: null | AL37: 2C1 | AM37: null | AN37: 3C1 | AO37: null | AP37: 4C1 | AQ37: null | AR37: 5C1 | AS37: null
A38: 450 | B38: 500 | C38: 669795 | D38: 31972690140 | E38: =IFERROR((D38/$E$1)/(C38),0) -> 477.35039 | F38: 0.000669795 | G38: 0.3197269 | I38: ="("&$A38&", "&$B38&"]" -> (450, 500] | J38: 1 | K38: 0 | L38: 0 | M38: 0 | N38: 0 | O38: 0 | P38: 0 | Q38: 0 | R38: 0 | S38: 0 | T38: 0 | Y38: 40 | Z38: 45 | AF38: BaseGame 500x | AG38: 63841 | AH38: Pay | AI38: 3349902500 | AJ38: 1C1 | AK38: null | AL38: 2C1 | AM38: null | AN38: 3C1 | AO38: null | AP38: 4C1 | AQ38: null | AR38: 5C1 | AS38: null
A39: 500 | B39: 550 | C39: 639553 | D39: 33561838540 | E39: =IFERROR((D39/$E$1)/(C39),0) -> 524.77025 | F39: 0.000639553 | G39: 0.33561839 | I39: ="("&$A39&", "&$B39&"]" -> (500, 550] | J39: 1 | K39: 9.7724504e-05 | L39: 6.25e-08 | M39: 62 | N39: 6.2e-08 | O39: 3.2535755e-05 | P39: 0 | Q39: 0 | R39: 0 | S39: 0 | T39: 0 | Y39: 80 | Z39: 90 | AF39: BaseGame 550x | AG39: 49241 | AH39: Pay | AI39: 2836792460 | AJ39: 1C1 | AK39: null | AL39: 2C1 | AM39: null | AN39: 3C1 | AO39: null | AP39: 4C1 | AQ39: null | AR39: 5C1 | AS39: null
A40: 550 | B40: 600 | C40: 494411 | D40: 28481302480 | E40: =IFERROR((D40/$E$1)/(C40),0) -> 576.06531 | F40: 0.000494411 | G40: 0.28481302 | I40: ="("&$A40&", "&$B40&"]" -> (550, 600] | J40: 1 | K40: 0 | L40: 0 | M40: 0 | N40: 0 | O40: 0 | P40: 0 | Q40: 0 | R40: 0 | S40: 0 | T40: 0 | Y40: 90 | Z40: 100 | AF40: BaseGame 600x | AG40: 36244 | AH40: Pay | AI40: 2268304480 | AJ40: 1C1 | AK40: null | AL40: 2C1 | AM40: null | AN40: 3C1 | AO40: null | AP40: 4C1 | AQ40: null | AR40: 5C1 | AS40: null
A41: 600 | B41: 650 | C41: 362215 | D41: 22669344380 | E41: =IFERROR((D41/$E$1)/(C41),0) -> 625.85327 | F41: 0.000362215 | G41: 0.22669344 | I41: ="("&$A41&", "&$B41&"]" -> (600, 650] | J41: 1 | K41: 0 | L41: 0 | M41: 0 | N41: 0 | O41: 0 | P41: 0 | Q41: 0 | R41: 0 | S41: 0 | T41: 0 | Y41: 120 | Z41: 140 | AF41: BaseGame 650x | AG41: 30702 | AH41: Pay | AI41: 2073268860 | AJ41: 1C1 | AK41: null | AL41: 2C1 | AM41: null | AN41: 3C1 | AO41: null | AP41: 4C1 | AQ41: null | AR41: 5C1 | AS41: null
A42: 650 | B42: 700 | C42: 305416 | D42: 20621962840 | E42: =IFERROR((D42/$E$1)/(C42),0) -> 675.20899 | F42: 0.000305416 | G42: 0.20621963 | I42: ="("&$A42&", "&$B42&"]" -> (650, 700] | J42: 0 | K42: 0 | L42: 0 | M42: 0 | N42: 0 | O42: 0 | P42: 0 | Q42: 0 | R42: 0 | S42: 0 | T42: 0 | Y42: 80 | Z42: 90 | AF42: BaseGame 700x | AG42: 26624 | AH42: Pay | AI42: 1929990420 | AJ42: 1C1 | AK42: null | AL42: 2C1 | AM42: null | AN42: 3C1 | AO42: null | AP42: 4C1 | AQ42: null | AR42: 5C1 | AS42: null
A43: 700 | B43: 750 | C43: 264605 | D43: 19182810820 | E43: =IFERROR((D43/$E$1)/(C43),0) -> 724.96025 | F43: 0.000264605 | G43: 0.19182811 | I43: ="("&$A43&", "&$B43&"]" -> (700, 750] | J43: 0 | K43: 0 | L43: 0 | M43: 0 | N43: 0 | O43: 0 | P43: 0 | Q43: 0 | R43: 0 | S43: 0 | T43: 0 | Y43: 120 | Z43: 140 | AF43: BaseGame 750x | AG43: 29582 | AH43: Pay | AI43: 2311927880 | AJ43: 1C1 | AK43: null | AL43: 2C1 | AM43: null | AN43: 3C1 | AO43: null | AP43: 4C1 | AQ43: null | AR43: 5C1 | AS43: null
A44: 750 | B44: 800 | C44: 296013 | D44: 23135180720 | E44: =IFERROR((D44/$E$1)/(C44),0) -> 781.55962 | F44: 0.000296013 | G44: 0.23135181 | I44: ="("&$A44&", "&$B44&"]" -> (750, 800] | J44: 0 | K44: 0 | L44: 0 | M44: 0 | N44: 0 | O44: 0 | P44: 0 | Q44: 0 | R44: 0 | S44: 0 | T44: 0 | Y44: 120 | Z44: 140 | AF44: BaseGame 800x | AG44: 31660 | AH44: Pay | AI44: 2618094520 | AJ44: 1C1 | AK44: null | AL44: 2C1 | AM44: null | AN44: 3C1 | AO44: null | AP44: 4C1 | AQ44: null | AR44: 5C1 | AS44: null
A45: 800 | B45: 850 | C45: 315973 | D45: 26126987440 | E45: =IFERROR((D45/$E$1)/(C45),0) -> 826.87405 | F45: 0.000315973 | G45: 0.26126987 | I45: ="("&$A45&", "&$B45&"]" -> (800, 850] | J45: 0 | K45: 0 | L45: 0 | M45: 0 | N45: 0 | O45: 0 | P45: 0 | Q45: 0 | R45: 0 | S45: 0 | T45: 0 | Y45: 140 | Z45: 160 | AF45: BaseGame 850x | AG45: 25319 | AH45: Pay | AI45: 2214041620 | AJ45: 1C1 | AK45: null | AL45: 2C1 | AM45: null | AN45: 3C1 | AO45: null | AP45: 4C1 | AQ45: null | AR45: 5C1 | AS45: null
A46: 850 | B46: 900 | C46: 251982 | D46: 22037131900 | E46: =IFERROR((D46/$E$1)/(C46),0) -> 874.55183 | F46: 0.000251982 | G46: 0.22037132 | I46: ="("&$A46&", "&$B46&"]" -> (850, 900] | J46: 0 | K46: 0 | L46: 0 | M46: 0 | N46: 0 | O46: 0 | P46: 0 | Q46: 0 | R46: 0 | S46: 0 | T46: 0 | Y46: 200 | Z46: 250 | AF46: BaseGame 900x | AG46: 17351 | AH46: Pay | AI46: 1604425740 | AJ46: 1C1 | AK46: null | AL46: 2C1 | AM46: null | AN46: 3C1 | AO46: null | AP46: 4C1 | AQ46: null | AR46: 5C1 | AS46: null
A47: 900 | B47: 950 | C47: 175474 | D47: 16223611180 | E47: =IFERROR((D47/$E$1)/(C47),0) -> 924.55926 | F47: 0.000175474 | G47: 0.16223611 | I47: ="("&$A47&", "&$B47&"]" -> (900, 950] | J47: 0 | K47: 0 | L47: 0 | M47: 0 | N47: 0 | O47: 0 | P47: 0 | Q47: 0 | R47: 0 | S47: 0 | T47: 0 | Y47: 200 | Z47: 250 | AF47: BaseGame 950x | AG47: 22344 | AH47: Pay | AI47: 2195989840 | AJ47: 1C1 | AK47: null | AL47: 2C1 | AM47: null | AN47: 3C1 | AO47: null | AP47: 4C1 | AQ47: null | AR47: 5C1 | AS47: null
... A54: 6000 | B54: 7000 | C54: 101847 | D54: 65655424880 | E54: =IFERROR((D54/$E$1)/(C54),0) -> 6446.4761 | F54: 0.000101847 | G54: 0.65655425 | I54: ="("&$A54&", "&$B54&"]" -> (6000, 7000] | J54: 0 | K54: 0 | L54: 0 | M54: 0 | N54: 0 | O54: 0 | P54: 0 | Q54: 0 | R54: 0 | S54: 0 | T54: 0 | Y54: 160 | Z54: 180 | AF54: BaseGame 7000x | AG54: 16379 | AH54: Pay | AI54: 15875619560 | AJ54: 1C1 | AK54: null | AL54: 2C1 | AM54: null | AN54: 3C1 | AO54: null | AP54: 4C1 | AQ54: null | AR54: 5C1 | AS54: null
...

Sheet Multiplier Weight (new_player)
A1: Normal Game | C1: (後端報表) | D1: scale | E1: 100 | O1: Total RTP
C2: Simulator | I2: Fixed Game | J2: 3000 | M2: =10^9 -> 1000000000 | O2: =SUM(_xlfn.ANCHORARRAY(O4)) -> 0.88
A3: Lower | B3: Upper | C3: Count | D3: Pay | E3: Multi. | F3: Prob. | G3: RTP | I3: Range | J3: Fix freq | K3: Fix num | L3: Fixed Prob. | M3: Fixed Weight | N3: Real Prob. | O3: Real RTP
A4: -1 | B4: 0 | C4: {='Multiplier Weight'!C4:D61} -> 795188919 | D4: 0 | E4: =IFERROR((D4/$E$1)/(C4),0) -> 0 | F4: {=C4:C61/SUM(C4:C61)} -> 0.79518892 | G4: {=E4:E61*_xlfn.ANCHORARRAY(F4)} -> 0 | H4: {=18*(K4:K18/SUM(K4:K18))} -> 2.1240993 | I4: ="("&$A4&", "&$B4&"]" -> (-1, 0] | J4: {=IFERROR(IF(1/_xlfn.ANCHORARRAY(F4)<$J$2,1,0),0)} -> 1 | K4: 1.1361091 | L4: {=K4:K61*_xlfn.ANCHORARRAY(J4)*_xlfn.ANCHORARRAY(F4)} -> 0.90342135 | M4: {=INT(_xlfn.ANCHORARRAY(L4)*$M$2)} -> 903421347 | N4: {=_xlfn.ANCHORARRAY(M4)/SUM(_xlfn.ANCHORARRAY(M4))} -> 0.90342135 | O4: {=_xlfn.ANCHORARRAY(N4)*E4:E61} -> 0
A5: 0 | B5: 1 | C5: 12223533 | D5: 917729700 | E5: =IFERROR((D5/$E$1)/(C5),0) -> 0.75078924 | F5: 0.012223533 | G5: 0.009177297 | H5: 0.82910162 | I5: ="("&$A5&", "&$B5&"]" -> (0, 1] | J5: 1 | K5: 0.44345849 | L5: 0.0054206295 | M5: 5420629 | N5: 0.005420629 | O5: 0.0040697499
A6: 1 | B6: 2 | C6: 19854235 | D6: 3409420460 | E6: =IFERROR((D6/$E$1)/(C6),0) -> 1.7172258 | F6: 0.019854235 | G6: 0.034094205 | H6: 0.82740956 | I6: ="("&$A6&", "&$B6&"]" -> (1, 2] | J6: 1 | K6: 0.44255347 | L6: 0.0087865605 | M6: 8786560 | N6: 0.00878656 | O6: 0.015088508
A7: 2 | B7: 3 | C7: 14020917 | D7: 3854712400 | E7: =IFERROR((D7/$E$1)/(C7),0) -> 2.7492584 | F7: 0.014020917 | G7: 0.038547124 | H7: 0.82615465 | I7: ="("&$A7&", "&$B7&"]" -> (2, 3] | J7: 1 | K7: 0.44188226 | L7: 0.0061955945 | M7: 6195594 | N7: 0.006195594 | O7: 0.017033289
A8: 3 | B8: 4 | C8: 18463165 | D8: 6828453200 | E8: =IFERROR((D8/$E$1)/(C8),0) -> 3.6984196 | F8: 0.018463165 | G8: 0.068284532 | H8: 0.8251924 | I8: ="("&$A8&", "&$B8&"]" -> (3, 4] | J8: 1 | K8: 0.44136758 | L8: 0.0081490425 | M8: 8149042 | N8: 0.008149042 | O8: 0.030138577
A9: 4 | B9: 5 | C9: 12601097 | D9: 6055478580 | E9: =IFERROR((D9/$E$1)/(C9),0) -> 4.805517 | F9: 0.012601097 | G9: 0.060554786 | H9: 0.82654402 | I9: ="("&$A9&", "&$B9&"]" -> (4, 5] | J9: 1 | K9: 0.44209052 | L9: 0.0055708255 | M9: 5570825 | N9: 0.005570825 | O9: 0.026770694
A10: 5 | B10: 6 | C10: 12543731 | D10: 7466041340 | E10: =IFERROR((D10/$E$1)/(C10),0) -> 5.9520101 | F10: 0.012543731 | G10: 0.074660413 | H10: 0.82554807 | I10: ="("&$A10&", "&$B10&"]" -> (5, 6] | J10: 1 | K10: 0.44155782 | L10: 0.0055387825 | M10: 5538782 | N10: 0.005538782 | O10: 0.032966886
A11: 6 | B11: 7 | C11: 3159125 | D11: 2062217360 | E11: =IFERROR((D11/$E$1)/(C11),0) -> 6.5278118 | F11: 0.003159125 | G11: 0.020622174 | H11: 0.82559314 | I11: ="("&$A11&", "&$B11&"]" -> (6, 7] | J11: 1 | K11: 0.44158193 | L11: 0.0013950125 | M11: 1395012 | N11: 0.001395012 | O11: 0.0091063759
A12: 7 | B12: 8 | C12: 13147608 | D12: 10142167660 | E12: =IFERROR((D12/$E$1)/(C12),0) -> 7.7140782 | F12: 0.013147608 | G12: 0.10142168 | H12: 2.0648418 | I12: ="("&$A12&", "&$B12&"]" -> (7, 8] | J12: 1 | K12: 1.1044142 | L12: 0.014520405 | M12: 14520405 | N12: 0.014520405 | O12: 0.11201154
A13: 8 | B13: 9 | C13: 5760279 | D13: 5138867060 | E13: =IFERROR((D13/$E$1)/(C13),0) -> 8.9212121 | F13: 0.005760279 | G13: 0.051388671 | H13: 1.0274096 | I13: ="("&$A13&", "&$B13&"]" -> (8, 9] | J13: 1 | K13: 0.54952677 | L13: 0.0031654275 | M13: 3165427 | N13: 0.003165427 | O13: 0.028239446
A14: 9 | B14: 10 | C14: 7136369 | D14: 6958218440 | E14: =IFERROR((D14/$E$1)/(C14),0) -> 9.7503625 | F14: 0.007136369 | G14: 0.069582184 | H14: 1.0307881 | I14: ="("&$A14&", "&$B14&"]" -> (9, 10] | J14: 1 | K14: 0.55133381 | L14: 0.0039345215 | M14: 3934521 | N14: 0.003934521 | O14: 0.038363006
A15: 10 | B15: 15 | C15: 17909726 | D15: 22799765820 | E15: =IFERROR((D15/$E$1)/(C15),0) -> 12.730382 | F15: 0.017909726 | G15: 0.22799766 | H15: 2.0596088 | I15: ="("&$A15&", "&$B15&"]" -> (10, 15] | J15: 1 | K15: 1.1016153 | L15: 0.019729628 | M15: 19729627 | N15: 0.019729627 | O15: 0.25116569
A16: 15 | B16: 20 | C16: 11269242 | D16: 20112711300 | E16: =IFERROR((D16/$E$1)/(C16),0) -> 17.847439 | F16: 0.011269242 | G16: 0.20112711 | H16: 0.82148233 | I16: ="("&$A16&", "&$B16&"]" -> (15, 20] | J16: 1 | K16: 0.43938319 | L16: 0.0049515155 | M16: 4951515 | N16: 0.004951515 | O16: 0.088371864
... A18: 25 | B18: 30 | C18: 4327912 | D18: 12306435380 | E18: =IFERROR((D18/$E$1)/(C18),0) -> 28.435041 | F18: 0.004327912 | G18: 0.12306435 | H18: 1.0280991 | I18: ="("&$A18&", "&$B18&"]" -> (25, 30] | J18: 1 | K18: 0.54989554 | L18: 0.0023798995 | M18: 2379899 | N18: 0.002379899 | O18: 0.067672525
A19: 30 | B19: 35 | C19: 2145347 | D19: 6990216720 | E19: =IFERROR((D19/$E$1)/(C19),0) -> 32.583152 | F19: 0.002145347 | G19: 0.069902167 | I19: ="("&$A19&", "&$B19&"]" -> (30, 35] | J19: 1 | K19: 0 | L19: 0 | M19: 0 | N19: 0 | O19: 0
A20: 35 | B20: 40 | C20: 3778148 | D20: 14458614080 | E20: =IFERROR((D20/$E$1)/(C20),0) -> 38.269052 | F20: 0.003778148 | G20: 0.14458614 | I20: ="("&$A20&", "&$B20&"]" -> (35, 40] | J20: 1 | K20: 0 | L20: 0 | M20: 0 | N20: 0 | O20: 0
A21: 40 | B21: 45 | C21: 1647988 | D21: 7173008520 | E21: =IFERROR((D21/$E$1)/(C21),0) -> 43.525854 | F21: 0.001647988 | G21: 0.071730085 | I21: ="("&$A21&", "&$B21&"]" -> (40, 45] | J21: 1 | K21: 0 | L21: 0 | M21: 0 | N21: 0 | O21: 0
A22: 45 | B22: 50 | C22: 2034040 | D22: 9788723540 | E22: =IFERROR((D22/$E$1)/(C22),0) -> 48.124538 | F22: 0.00203404 | G22: 0.097887235 | I22: ="("&$A22&", "&$B22&"]" -> (45, 50] | J22: 1 | K22: 0 | L22: 0 | M22: 0 | N22: 0 | O22: 0
A23: 50 | B23: 60 | C23: 3238075 | D23: 18382953720 | E23: =IFERROR((D23/$E$1)/(C23),0) -> 56.771241 | F23: 0.003238075 | G23: 0.18382954 | I23: ="("&$A23&", "&$B23&"]" -> (50, 60] | J23: 1 | K23: 0 | L23: 0 | M23: 0 | N23: 0 | O23: 0
A24: 60 | B24: 70 | C24: 1975180 | D24: 12940084160 | E24: =IFERROR((D24/$E$1)/(C24),0) -> 65.513443 | F24: 0.00197518 | G24: 0.12940084 | I24: ="("&$A24&", "&$B24&"]" -> (60, 70] | J24: 1 | K24: 0 | L24: 0 | M24: 0 | N24: 0 | O24: 0
A25: 70 | B25: 80 | C25: 2561154 | D25: 19504057100 | E25: =IFERROR((D25/$E$1)/(C25),0) -> 76.153395 | F25: 0.002561154 | G25: 0.19504057 | I25: ="("&$A25&", "&$B25&"]" -> (70, 80] | J25: 1 | K25: 0 | L25: 0 | M25: 0 | N25: 0 | O25: 0
A26: 80 | B26: 90 | C26: 1688794 | D26: 14572354840 | E26: =IFERROR((D26/$E$1)/(C26),0) -> 86.288528 | F26: 0.001688794 | G26: 0.14572355 | I26: ="("&$A26&", "&$B26&"]" -> (80, 90] | J26: 1 | K26: 0 | L26: 0 | M26: 0 | N26: 0 | O26: 0
A27: 90 | B27: 100 | C27: 1673182 | D27: 16090695940 | E27: =IFERROR((D27/$E$1)/(C27),0) -> 96.168235 | F27: 0.001673182 | G27: 0.16090696 | I27: ="("&$A27&", "&$B27&"]" -> (90, 100] | J27: 1 | K27: 0 | L27: 0 | M27: 0 | N27: 0 | O27: 0
A28: 100 | B28: 120 | C28: 2856332 | D28: 31917444000 | E28: =IFERROR((D28/$E$1)/(C28),0) -> 111.74277 | F28: 0.002856332 | G28: 0.31917444 | I28: ="("&$A28&", "&$B28&"]" -> (100, 120] | J28: 1 | K28: 0 | L28: 0 | M28: 0 | N28: 0 | O28: 0
A29: 120 | B29: 140 | C29: 1970295 | D29: 25808802160 | E29: =IFERROR((D29/$E$1)/(C29),0) -> 130.98953 | F29: 0.001970295 | G29: 0.25808802 | I29: ="("&$A29&", "&$B29&"]" -> (120, 140] | J29: 1 | K29: 0 | L29: 0 | M29: 0 | N29: 0 | O29: 0
A30: 140 | B30: 160 | C30: 1848146 | D30: 27932335060 | E30: =IFERROR((D30/$E$1)/(C30),0) -> 151.13706 | F30: 0.001848146 | G30: 0.27932335 | I30: ="("&$A30&", "&$B30&"]" -> (140, 160] | J30: 1 | K30: 0 | L30: 0 | M30: 0 | N30: 0 | O30: 0
... A61: 100000 | B61: 999999 | C61: 0 | D61: 0 | E61: =IFERROR((D61/$E$1)/(C61),0) -> 0 | F61: 0 | G61: 0 | I61: ="("&$A61&", "&$B61&"]" -> (100000, 999999] | J61: 0 | K61: 0 | L61: 0 | M61: 0 | N61: 0 | O61: 0
O62: =SUM(O28:O55) -> 0
N63: Spin 數 | O63: 一天幾個
M64: >300 | N64: =1/SUM(N35:N55) -> #DIV/0! | O64: {=N66/N64:N65} -> #DIV/0!
M65: >1000 | N65: =1/N49 -> #DIV/0! | O65: #DIV/0!
D66: scale | E66: 150 | M66: total spin/day | N66: 3500000
A67: Extra Bet 1 | C67: (後端報表) | O67: =SUM(_xlfn.ANCHORARRAY(O69)) -> 0.88
A68: {=A3:G3} -> Lower | B68: Upper | C68: Count | D68: Pay | E68: Multi. | F68: Prob. | G68: RTP | I68: Range | J68: Fix freq | K68: Fix num | L68: Fixed Prob. | M68: Fixed Weight | N68: Real Prob. | O68: Real RTP
A69: {=A4:B61} -> -1 | B69: 0 | C69: {='Multiplier Weight'!C69:D126} -> 795217879 | D69: 0 | E69: =IFERROR((D69/$E$66)/(C69),0) -> 0 | F69: {=C69:C126/SUM(C69:C126)} -> 0.79521788 | G69: {=E69:E126*_xlfn.ANCHORARRAY(F69)} -> 0 | H69: {=A69:A126/1.5} -> -0.66666667 | I69: ="("&$A69&", "&$B69&"]" -> (-1, 0] | J69: {=IFERROR(IF(1/_xlfn.ANCHORARRAY(F69)<$J$2,1,0),0)} -> 1 | K69: 1.0987013 | L69: {=K69:K126*_xlfn.ANCHORARRAY(J69)*_xlfn.ANCHORARRAY(F69)} -> 0.87370692 | M69: {=INT(_xlfn.ANCHORARRAY(L69)*$M$2)} -> 873706924 | N69: {=_xlfn.ANCHORARRAY(M69)/SUM(_xlfn.ANCHORARRAY(M69))} -> 0.87370692 | O69: {=_xlfn.ANCHORARRAY(N69)*E69:E126} -> 0
A70: 0 | B70: 1 | C70: 4452589 | D70: 356207120 | E70: =IFERROR((D70/$E$66)/(C70),0) -> 0.53333333 | F70: 0.004452589 | G70: 0.0023747141 | H70: 0 | I70: ="("&$A70&", "&$B70&"]" -> (0, 1] | J70: 1 | K70: 2.1896442 | L70: 0.0097495855 | M70: 9749585 | N70: 0.009749585 | O70: 0.0051997787
A71: 1 | B71: 2 | C71: 12633880 | D71: 2096846880 | E71: =IFERROR((D71/$E$66)/(C71),0) -> 1.1064676 | F71: 0.01263388 | G71: 0.013978979 | H71: 0.66666667 | I71: ="("&$A71&", "&$B71&"]" -> (1, 2] | J71: 1 | K71: 1.2511715 | L71: 0.01580715 | M71: 15807150 | N71: 0.01580715 | O71: 0.0174901
...

Sheet OP Jackpot
B4: Bet Type | C4: SCR | D4: Source Report
B5: NB_Newbie | C5: 1885411900 | D5: H020192A_02020000_2610200354_betmode0_108_8807_newbie.xlsx｜Newbie 獨立值
B6: NB | C6: 1867514800 | D6: H020192A_02020000_2610200441_betmode0_108_8693_oldhand.xlsx｜Oldhand
B7: EB1_Newbie | C7: 2401322900 | D7: H020192A_02020000_2610200356_betmode1_108_8810_newbie.xlsx｜Newbie 獨立值
B8: EB1 | C8: 2427009600 | D8: H020192A_02020000_2610200442_betmode1_108_8701_oldhand.xlsx｜Oldhand
B9: EB2_Newbie | C9: 2718761700 | D9: H020192A_02020000_2610200359_betmode2_108_8802_newbie.xlsx｜Newbie 獨立值
B10: EB2 | C10: 2658855200 | D10: H020192A_02020000_2610200445_betmode2_108_8686_oldhand.xlsx｜Oldhand
B11: SF_Newbie | C11: 18021846400 | D11: H020192A_02020000_2610200423_betmode3_108_8801_newbie.xlsx｜Newbie 獨立值
B12: SF | C12: 18023844300 | D12: H020192A_02020000_2610200353_betmode3_108_8799_oldhand.xlsx｜Oldhand

Sheet Multiplier Weight (bet100)
A1: Normal Game | C1: (後端報表) | D1: scale | E1: 100 | O1: Total RTP | P1: Target | Q1: Error
C2: Simulator | I2: Fixed Game | J2: 3000 | M2: =10^9 -> 1000000000 | O2: =SUM(_xlfn.ANCHORARRAY(O4)) -> 0.92000001 | P2: 0.92 | Q2: =P2-O2 -> -1.4911549e-08
A3: Lower | B3: Upper | C3: Count | D3: Pay | E3: Multi. | F3: Prob. | G3: RTP | I3: Range | J3: Fix freq | K3: Fix num | L3: Fixed Prob. | M3: Fixed Weight | N3: Real Prob. | O3: Real RTP | P3: =SUM(_xlfn.ANCHORARRAY(Q4)) -> 0.96565564 | R3: =1-SUM(_xlfn.ANCHORARRAY(R4)) -> 0.047279424 | W3: 參考修正值 | Y3: 180 | Z3: 200 | AB3: {=_xlfn._xlws.SORT(_xlfn.UNIQUE(Y3:Y153))} -> 30 | AC3: {=COUNTIF(Y3:Y153,_xlfn.ANCHORARRAY(AB3))} -> 1 | AD3: {=_xlfn.ANCHORARRAY(AC3)/10000000} -> 1e-07 | AF3: BaseGame 00 | AG3: 79527545
A4: -1 | B4: 0 | C4: 79527545 | D4: 0 | E4: =IFERROR((D4/$E$1)/(C4),0) -> 0 | F4: {=C4:C61/SUM(C4:C61)} -> 0.79527545 | G4: {=E4:E61*_xlfn.ANCHORARRAY(F4)} -> 0 | I4: ="("&$A4&", "&$B4&"]" -> (-1, 0] | J4: {=IFERROR(IF(1/_xlfn.ANCHORARRAY(F4)<$J$2,1,0),0)} -> 1 | K4: 1.1139704 | L4: {=K4:K61*_xlfn.ANCHORARRAY(J4)*_xlfn.ANCHORARRAY(F4)} -> 0.88591331 | M4: {=INT(_xlfn.ANCHORARRAY(L4)*$M$2)} -> 885913313 | N4: {=_xlfn.ANCHORARRAY(M4)/SUM(_xlfn.ANCHORARRAY(M4))} -> 0.88596776 | O4: {=_xlfn.ANCHORARRAY(N4)*E4:E61} -> 0 | P4: 0.88031431 | Q4: {=P4:P55*E4:E55} -> 0 | R4: {=P2*P4:P55/P3} -> 0.83869356 | S4: =R4+R3 -> 0.88597298 | T4: {=S4:S55/_xlfn.ANCHORARRAY(F4)} -> 1.1140454 | W4: 1.0286652 | Y4: 45 | Z4: 50 | AB4: 40 | AC4: 3 | AD4: 3e-07 | AF4: BaseGame 0x | AG4: 1221030 | AH4: Pay | AI4: 91661240 | AJ4: 1C1 | AK4: null | AL4: 2C1 | AM4: null | AN4: 3C1 | AO4: null | AP4: 4C1 | AQ4: null | AR4: 5C1 | AS4: null
A5: 0 | B5: 1 | C5: 1221030 | D5: 91661240 | E5: =IFERROR((D5/$E$1)/(C5),0) -> 0.75068786 | F5: 0.0122103 | G5: 0.009166124 | I5: ="("&$A5&", "&$B5&"]" -> (0, 1] | J5: 1 | K5: 0.9635 | L5: 0.011764624 | M5: 11764624 | N5: 0.011765347 | O5: 0.0088321032 | P5: 0.012357339 | Q5: 0.0092765043 | R5: 0.011773091 | S5: {=R5:R55} -> 0.011773091 | T5: 0.96419343 | W5: 1.0484973 | Y5: 160 | Z5: 180 | AB5: 45 | AC5: 2 | AD5: 2e-07 | AF5: BaseGame 1x | AG5: 1983581 | AH5: Pay | AI5: 340592420 | AJ5: 1C1 | AK5: null | AL5: 2C1 | AM5: null | AN5: 3C1 | AO5: null | AP5: 4C1 | AQ5: null | AR5: 5C1 | AS5: null
A6: 1 | B6: 2 | C6: 1983581 | D6: 340592420 | E6: =IFERROR((D6/$E$1)/(C6),0) -> 1.7170583 | F6: 0.01983581 | G6: 0.034059242 | I6: ="("&$A6&", "&$B6&"]" -> (1, 2] | J6: 1 | K6: 0.82506116 | L6: 0.016365756 | M6: 16365756 | N6: 0.016366762 | O6: 0.028102684 | P6: 0.017178728 | Q6: 0.029496878 | R6: 0.016366528 | S6: 0.016366528 | T6: 0.82510005 | W6: 0.87200957 | Y6: 160 | Z6: 180 | AB6: 60 | AC6: 5 | AD6: 5e-07 | AF6: BaseGame 2x | AG6: 1400402 | AH6: Pay | AI6: 385097500 | AJ6: 1C1 | AK6: null | AL6: 2C1 | AM6: null | AN6: 3C1 | AO6: null | AP6: 4C1 | AQ6: null | AR6: 5C1 | AS6: null
A7: 2 | B7: 3 | C7: 1400402 | D7: 385097500 | E7: =IFERROR((D7/$E$1)/(C7),0) -> 2.7499068 | F7: 0.01400402 | G7: 0.03850975 | I7: ="("&$A7&", "&$B7&"]" -> (2, 3] | J7: 1 | K7: 0.83004214 | L7: 0.011623927 | M7: 11623926 | N7: 0.01162464 | O7: 0.031966678 | P7: 0.012210325 | Q7: 0.033577256 | R7: 0.011633028 | S7: 0.011633028 | T7: 0.83069203 | W7: 0.93129385 | Y7: 120 | Z7: 140 | AB7: 80 | AC7: 10 | AD7: 1e-06 | AF7: BaseGame 3x | AG7: 1843384 | AH7: Pay | AI7: 681736680 | AJ7: 1C1 | AK7: null | AL7: 2C1 | AM7: null | AN7: 3C1 | AO7: null | AP7: 4C1 | AQ7: null | AR7: 5C1 | AS7: null
A8: 3 | B8: 4 | C8: 1843384 | D8: 681736680 | E8: =IFERROR((D8/$E$1)/(C8),0) -> 3.698289 | F8: 0.01843384 | G8: 0.068173668 | I8: ="("&$A8&", "&$B8&"]" -> (3, 4] | J8: 1 | K8: 0.67088783 | L8: 0.012367039 | M8: 12367038 | N8: 0.012367798 | O8: 0.045739692 | P8: 0.012996256 | Q8: 0.048063909 | R8: 0.0123818 | S8: 0.0123818 | T8: 0.6716886 | W8: 0.76505623 | Y8: 80 | Z8: 90 | AB8: 90 | AC8: 6 | AD8: 6e-07 | AF8: BaseGame 4x | AG8: 1261039 | AH8: Pay | AI8: 605977340 | AJ8: 1C1 | AK8: null | AL8: 2C1 | AM8: null | AN8: 3C1 | AO8: null | AP8: 4C1 | AQ8: null | AR8: 5C1 | AS8: null
A9: 4 | B9: 5 | C9: 1261039 | D9: 605977340 | E9: =IFERROR((D9/$E$1)/(C9),0) -> 4.8053814 | F9: 0.01261039 | G9: 0.060597734 | I9: ="("&$A9&", "&$B9&"]" -> (4, 5] | J9: 1 | K9: 0.80057166 | L9: 0.010095521 | M9: 10095520 | N9: 0.01009614 | O9: 0.048515806 | P9: 0.010587974 | Q9: 0.050879254 | R9: 0.010087381 | S9: 0.010087381 | T9: 0.79992616 | W9: 0.97221486 | Y9: 120 | Z9: 140 | AB9: 120 | AC9: 9 | AD9: 9e-07 | AF9: BaseGame 5x | AG9: 1254493 | AH9: Pay | AI9: 746676720 | AJ9: 1C1 | AK9: null | AL9: 2C1 | AM9: null | AN9: 3C1 | AO9: null | AP9: 4C1 | AQ9: null | AR9: 5C1 | AS9: null
A10: 5 | B10: 6 | C10: 1254493 | D10: 746676720 | E10: =IFERROR((D10/$E$1)/(C10),0) -> 5.9520198 | F10: 0.01254493 | G10: 0.074667672 | I10: ="("&$A10&", "&$B10&"]" -> (5, 6] | J10: 1 | K10: 0.642802 | L10: 0.0080639061 | M10: 8063906 | N10: 0.0080644016 | O10: 0.047999478 | P10: 0.0083771962 | Q10: 0.049861238 | R10: 0.0079811272 | S10: 0.0079811272 | T10: 0.63620341 | W10: 0.7310748 | Y10: 60 | Z10: 70 | AB10: 140 | AC10: 6 | AD10: 6e-07 | AF10: BaseGame 6x | AG10: 316037 | AH10: Pay | AI10: 206311540 | AJ10: 1C1 | AK10: null | AL10: 2C1 | AM10: null | AN10: 3C1 | AO10: null | AP10: 4C1 | AQ10: null | AR10: 5C1 | AS10: null
A11: 6 | B11: 7 | C11: 316037 | D11: 206311540 | E11: =IFERROR((D11/$E$1)/(C11),0) -> 6.5280818 | F11: 0.00316037 | G11: 0.020631154 | I11: ="("&$A11&", "&$B11&"]" -> (6, 7] | J11: 1 | K11: 0.62019473 | L11: 0.0019600448 | M11: 1960044 | N11: 0.0019601645 | O11: 0.012796114 | P11: 0.0021346722 | Q11: 0.013935315 | R11: 0.0020337461 | S11: 0.0020337461 | T11: 0.6435152 | W11: 0.92193727 | Y11: 120 | Z11: 140 | AB11: 160 | AC11: 6 | AD11: 6e-07 | AF11: BaseGame 7x | AG11: 1316405 | AH11: Pay | AI11: 1015442580 | AJ11: 1C1 | AK11: null | AL11: 2C1 | AM11: null | AN11: 3C1 | AO11: null | AP11: 4C1 | AQ11: null | AR11: 5C1 | AS11: null
A12: 7 | B12: 8 | C12: 1316405 | D12: 1015442580 | E12: =IFERROR((D12/$E$1)/(C12),0) -> 7.7137551 | F12: 0.01316405 | G12: 0.10154426 | I12: ="("&$A12&", "&$B12&"]" -> (7, 8] | J12: 1 | K12: 0.6396 | L12: 0.0084197264 | M12: 8419726 | N12: 0.0084202435 | O12: 0.064951696 | P12: 0.0088375429 | Q12: 0.068170642 | R12: 0.008419709 | S12: 0.008419709 | T12: 0.63959868 | W12: 0.83718336 | Y12: 90 | Z12: 100 | AB12: 180 | AC12: 1 | AD12: 1e-07 | AF12: BaseGame 8x | AG12: 574169 | AH12: Pay | AI12: 512208280 | AJ12: 1C1 | AK12: null | AL12: 2C1 | AM12: null | AN12: 3C1 | AO12: null | AP12: 4C1 | AQ12: null | AR12: 5C1 | AS12: null
A13: 8 | B13: 9 | C13: 574169 | D13: 512208280 | E13: =IFERROR((D13/$E$1)/(C13),0) -> 8.9208627 | F13: 0.00574169 | G13: 0.051220828 | I13: ="("&$A13&", "&$B13&"]" -> (8, 9] | J13: 1 | K13: 0.53678188 | L13: 0.0030820351 | M13: 3082035 | N13: 0.0030822244 | O13: 0.027496101 | P13: 0.0032443305 | Q13: 0.028942227 | R13: 0.0030909404 | S13: 0.0030909404 | T13: 0.53833286 | W13: 0.73011297 | Y13: 90 | Z13: 100 | AB13: 200 | AC13: 4 | AD13: 4e-07 | AF13: BaseGame 9x | AG13: 713840 | AH13: Pay | AI13: 696013360 | AJ13: 1C1 | AK13: null | AL13: 2C1 | AM13: null | AN13: 3C1 | AO13: null | AP13: 4C1 | AQ13: null | AR13: 5C1 | AS13: null
A14: 9 | B14: 10 | C14: 713840 | D14: 696013360 | E14: =IFERROR((D14/$E$1)/(C14),0) -> 9.7502712 | F14: 0.0071384 | G14: 0.069601336 | I14: ="("&$A14&", "&$B14&"]" -> (9, 10] | J14: 1 | K14: 0.86878799 | L14: 0.0062017562 | M14: 6201756 | N14: 0.0062021372 | O14: 0.060472519 | P14: 0.0064938585 | Q14: 0.063316881 | R14: 0.0061868326 | S14: 0.0061868326 | T14: 0.86669738 | W14: 1.0527638 | Y14: 80 | Z14: 90 | AB14: 0 | AC14: 0 | AD14: 0 | AF14: BaseGame 10x | AG14: 1791031 | AH14: Pay | AI14: 2280142320 | AJ14: 1C1 | AK14: null | AL14: 2C1 | AM14: null | AN14: 3C1 | AO14: null | AP14: 4C1 | AQ14: null | AR14: 5C1 | AS14: null
A15: 10 | B15: 15 | C15: 1791031 | D15: 2280142320 | E15: =IFERROR((D15/$E$1)/(C15),0) -> 12.730893 | F15: 0.01791031 | G15: 0.22801423 | I15: ="("&$A15&", "&$B15&"]" -> (10, 15] | J15: 1 | K15: 0.5519581 | L15: 0.0098857407 | M15: 9885740 | N15: 0.0098863476 | O15: 0.12586203 | P15: 0.010357801 | Q15: 0.13186405 | R15: 0.0098680899 | S15: 0.0098680899 | T15: 0.55097259 | W15: 0.81707965 | Y15: 40 | Z15: 45 | AF15: BaseGame 15x | AG15: 1124732 | AH15: Pay | AI15: 2007398080 | AJ15: 1C1 | AK15: null | AL15: 2C1 | AM15: null | AN15: 3C1 | AO15: null | AP15: 4C1 | AQ15: null | AR15: 5C1 | AS15: null
A16: 15 | B16: 20 | C16: 1124732 | D16: 2007398080 | E16: =IFERROR((D16/$E$1)/(C16),0) -> 17.84779 | F16: 0.01124732 | G16: 0.20073981 | I16: ="("&$A16&", "&$B16&"]" -> (15, 20] | J16: 1 | K16: 0.52230015 | L16: 0.0058744769 | M16: 5874476 | N16: 0.005874837 | O16: 0.10485286 | P16: 0.006169017 | Q16: 0.11010332 | R16: 0.0058773495 | S16: 0.0058773495 | T16: 0.52255555 | W16: 0.79998561 | Y16: 80 | Z16: 90 | AF16: BaseGame 20x | AG16: 621987 | AH16: Pay | AI16: 1445763680 | AJ16: 1C1 | AK16: null | AL16: 2C1 | AM16: null | AN16: 3C1 | AO16: null | AP16: 4C1 | AQ16: null | AR16: 5C1 | AS16: null
