Workbook

Sheet Overview
A2: Model: | B2: H027194
A3: Version: | B3: 3.0.0.5
A6: Base Bet | B6: Board Cells
A7: 100 | B7: 30
A10: Coin in | B10: Price(x) | C10: Bet Type | D10: Bet Type
A11: 100 | B11: 1 | C11: Normal Bet | D11: Normal Bet
A12: 200 | B12: 2 | C12: Extra Bet | D12: Buy Feature
A13: 10000 | B13: 100 | C13: Buy Feature | D13: Super Feature
A15: Reel # | B15: 1 | C15: 2 | D15: 3 | E15: 4 | F15: 5 | G15: 6
A16: Visible Window Size | B16: 5 | C16: 5 | D16: 5 | E16: 5 | F16: 5 | G16: 5
A17: =D11 | B17: =Detail!C7 | C17: =1/D17 | D17: =Detail!G7 | E17: Base Game
B18: =Detail!D7 | E18: Free Game
A20: Bet Type | B20: Pay Back | C20: Hit% | D20: Pulls/Hit | E20: Description
A21: =D12 | B21: =Detail!C8 | C21: =1/D21 | D21: 1 | E21: Base Game
B22: =Detail!D8 | E22: Free Game
A24: Bet Type | B24: Pay Back | C24: Hit% | D24: Pulls/Hit | E24: Description
A25: =D13 | B25: =Detail!C9 | C25: =IFERROR(1/D25,0) | D25: 1 | E25: Base Game
B26: =Detail!D9 | E26: Free Game

Sheet Multiplier_Weight
A1: H027 Card Range Weight Summary
A2: Range | B2: Weight_NB_BG_Newbie | C2: Weight_NB_FG_Newbie | D2: Weight_NB_BG | E2: Weight_NB_FG | F2: Weight_BF | G2: Weight_SF
A3: (-1, 0] | B3: =Detail_Newbie!K15 | C3: =Detail_Newbie!K86 | D3: =Detail!K15 | E3: =Detail!K86 | F3: =Detail!K163 | G3: =Detail!K234
A4: (-1, 0] | B4: 676050363 | C4: 0 | D4: 676050363 | E4: 0 | F4: 0 | G4: 0
A5: (0, 1] | B5: 173598347 | C5: 0 | D5: 173598347 | E5: 0 | F5: 0 | G5: 0
A6: (1, 2] | B6: 60225774 | C6: 0 | D6: 60225774 | E6: 0 | F6: 0 | G6: 0
A7: (2, 3] | B7: 26162370 | C7: 0 | D7: 26162370 | E7: 0 | F7: 0 | G7: 0
A8: (3, 4] | B8: 17944906 | C8: 0 | D8: 17944906 | E8: 0 | F8: 0 | G8: 0
A9: (4, 5] | B9: 10096690 | C9: 0 | D9: 10096690 | E9: 0 | F9: 0 | G9: 0
A10: (5, 6] | B10: 4908945 | C10: 0 | D10: 4908945 | E10: 0 | F10: 0 | G10: 0
A11: (6, 7] | B11: 4380743 | C11: 0 | D11: 4380743 | E11: 0 | F11: 0 | G11: 0
A12: (7, 8] | B12: 3278096 | C12: 0 | D12: 3278096 | E12: 0 | F12: 0 | G12: 0
A13: (8, 9] | B13: 2691069 | C13: 0 | D13: 2691069 | E13: 0 | F13: 0 | G13: 82640010
A14: (9, 10] | B14: 3673493 | C14: 0 | D14: 3673493 | E14: 0 | F14: 0 | G14: 0
A15: (10, 15] | B15: 11221093 | C15: 0 | D15: 11221093 | E15: 0 | F15: 0 | G15: 39166084
... A67: (100000, 9999999] | B67: 0 | C67: 0 | D67: 0 | E67: 0 | F67: 0 | G67: 0

Sheet Detail
A2: Threshold | B2: 1000000000
A3: Coin in | B3: 100
C5: RTP
B6: Bet | C6: Base Game | D6: Free Game | E6: Total | F6: Hit Rate | G6: FG Period | H6: Avg Multi | I6: BG | J6: FG
A7: Normal Bet | B7: 1 | C7: =SUM(M15:M79) -> 0.74 | D7: =SUM(M86:M149)*F7 -> 0.2 | E7: =SUM(C7:D7) -> 0.94 | F7: 0.0033333337 | G7: =1/F7 -> 299.99996 | H7: =D7*G7 -> 59.999993 | I7: =IFERROR(LOOKUP(2,1/(K15:K78<>0),P15:P78),0) -> 20 | J7: =IFERROR(LOOKUP(2,1/(K86:K149<>0),P86:P149),0) -> 250
A8: Buy Feature | B8: 100 | C8: 0 | D8: =SUM(M163:M226)/B8 -> 0.94 | E8: =SUM(C8:D8) -> 0.94 | F8: =D156 -> 1 | G8: =1/F8 -> 1 | H8: =D8*G8*B8 -> 94 | J8: =IFERROR(LOOKUP(2,1/(K163:K226<>0),P163:P226),0) -> 600
A9: Super Buy | B9: 250 | C9: =0 | D9: =IFERROR(SUM(M234:M297)/B9,0) | E9: =SUM(C9:D9) | F9: =1 | G9: =IFERROR(1/F9,0) | H9: =D9*G9*B9 | J9: =IFERROR(LOOKUP(2,1/(K234:K297<>0),P234:P297),0)
A11: Oldhand Normal Bet BG (94 Game RTP family) | B11: Base Game | G11: Normal Bet | H11: Base Game | O11: Normal Bet | P11: Base Game
A13: Simulate | B13: 10000000 | G13: Calculate
A14: Range | B14: Cnt | C14: Pay | D14: Hit Rate | E14: Avg. Multi. | G14: Range | H14: Fix Num | I14: Fix Rate | J14: Final Rate | K14: Weight | L14: Hit Rate | M14: Simulator RTP | O14: Lower | P14: Upper | Q14: 目前 | R14: 競品 | T14: 目前 | U14: 差異
A15: (-1, 0] | B15: 7157620 | C15: 0 | D15: =IFERROR(B15/$B$13,0) -> 0.715762 | E15: =IFERROR(C15/B15/500.0,0) -> 0 | G15: (-1, 0] | H15: 0.94451838 | I15: =IFERROR(B15/$B$13,0) -> 0.67605036 | J15: =IFERROR(K15/$B$2,0) -> 0.67605036 | K15: 676050363 | L15: =IFERROR(K15/SUM($K$15:$K$79),0) -> 0.67379686 | M15: =IFERROR(L15*E15,0) -> 0 | O15: -1 | P15: 0 | Q15: =L15 | R15: 0.76387345 | U15: =IFERROR(ROUND(T15/L15,2),0)
A16: (0, 1] | B16: 1667211 | C16: 416306550 | D16: =IFERROR(B16/$B$13,0) -> 0.1667211 | E16: =IFERROR(C16/B16/500.0,0) -> 0.49940475 | G16: (0, 1] | H16: 1.04125 | I16: =IFERROR(B16/$B$13,0) -> 0.17359835 | J16: =IFERROR(K16/$B$2,0) -> 0.17359835 | K16: 173598347 | L16: =IFERROR(K16/SUM($K$15:$K$79),0) -> 0.17301969 | M16: =IFERROR(L16*E16,0) -> 0.086406854 | O16: 0 | P16: 1 | Q16: =L16 | R16: 0.13400021 | U16: =IFERROR(ROUND(T16/L16,2),0)
A17: (1, 2] | B17: 538090 | C17: 401573875 | D17: =IFERROR(B17/$B$13,0) -> 0.053809 | E17: =IFERROR(C17/B17/500.0,0) -> 1.49259 | G17: (1, 2] | H17: 1.1192509 | I17: =IFERROR(B17/$B$13,0) -> 0.060225774 | J17: =IFERROR(K17/$B$2,0) -> 0.060225774 | K17: 60225774 | L17: =IFERROR(K17/SUM($K$15:$K$79),0) -> 0.060025021 | M17: =IFERROR(L17*E17,0) -> 0.089592746 | O17: 1 | P17: 2 | Q17: =L17 | R17: 0.033580526 | U17: =IFERROR(ROUND(T17/L17,2),0)
A18: (2, 3] | B18: 224385 | C18: 287523200 | D18: =IFERROR(B18/$B$13,0) -> 0.0224385 | E18: =IFERROR(C18/B18/500.0,0) -> 2.5627667 | G18: (2, 3] | H18: 1.165959 | I18: =IFERROR(B18/$B$13,0) -> 0.02616237 | J18: =IFERROR(K18/$B$2,0) -> 0.02616237 | K18: 26162370 | L18: =IFERROR(K18/SUM($K$15:$K$79),0) -> 0.026075162 | M18: =IFERROR(L18*E18,0) -> 0.066824556 | O18: 2 | P18: 3 | Q18: =L18 | R18: 0.01870646 | U18: =IFERROR(ROUND(T18/L18,2),0)
A19: (3, 4] | B19: 132955 | C19: 232983725 | D19: =IFERROR(B19/$B$13,0) -> 0.0132955 | E19: =IFERROR(C19/B19/500.0,0) -> 3.5047005 | G19: (3, 4] | H19: 1.3496977 | I19: =IFERROR(B19/$B$13,0) -> 0.017944906 | J19: =IFERROR(K19/$B$2,0) -> 0.017944906 | K19: 17944906 | L19: =IFERROR(K19/SUM($K$15:$K$79),0) -> 0.01788509 | M19: =IFERROR(L19*E19,0) -> 0.062681882 | O19: 3 | P19: 4 | Q19: =L19 | R19: 0.011806935 | U19: =IFERROR(ROUND(T19/L19,2),0)
A20: (4, 5] | B20: 69633 | C20: 158342550 | D20: =IFERROR(B20/$B$13,0) -> 0.0069633 | E20: =IFERROR(C20/B20/500.0,0) -> 4.5479169 | G20: (4, 5] | H20: 1.4499864 | I20: =IFERROR(B20/$B$13,0) -> 0.01009669 | J20: =IFERROR(K20/$B$2,0) -> 0.01009669 | K20: 10096690 | L20: =IFERROR(K20/SUM($K$15:$K$79),0) -> 0.010063034 | M20: =IFERROR(L20*E20,0) -> 0.045765844 | O20: 4 | P20: 5 | Q20: =L20 | R20: 0.0095597301 | U20: =IFERROR(ROUND(T20/L20,2),0)
A21: (5, 6] | B21: 36941 | C21: 102200425 | D21: =IFERROR(B21/$B$13,0) -> 0.0036941 | E21: =IFERROR(C21/B21/500.0,0) -> 5.5331705 | G21: (5, 6] | H21: 1.3288609 | I21: =IFERROR(B21/$B$13,0) -> 0.004908945 | J21: =IFERROR(K21/$B$2,0) -> 0.004908945 | K21: 4908945 | L21: =IFERROR(K21/SUM($K$15:$K$79),0) -> 0.0048925818 | M21: =IFERROR(L21*E21,0) -> 0.027071489 | O21: 5 | P21: 6 | Q21: =L21 | R21: 0.0039174243 | U21: =IFERROR(ROUND(T21/L21,2),0)
A22: (6, 7] | B22: 22473 | C22: 72923550 | D22: =IFERROR(B22/$B$13,0) -> 0.0022473 | E22: =IFERROR(C22/B22/500.0,0) -> 6.4898812 | G22: (6, 7] | H22: 1.9493361 | I22: =IFERROR(B22/$B$13,0) -> 0.004380743 | J22: =IFERROR(K22/$B$2,0) -> 0.004380743 | K22: 4380743 | L22: =IFERROR(K22/SUM($K$15:$K$79),0) -> 0.0043661405 | M22: =IFERROR(L22*E22,0) -> 0.028335733 | O22: 6 | P22: 7 | Q22: =L22 | R22: 0.0033525864 | U22: =IFERROR(ROUND(T22/L22,2),0)
A23: (7, 8] | B23: 17491 | C23: 66123350 | D23: =IFERROR(B23/$B$13,0) -> 0.0017491 | E23: =IFERROR(C23/B23/500.0,0) -> 7.5608427 | G23: (7, 8] | H23: 1.8741616 | I23: =IFERROR(B23/$B$13,0) -> 0.003278096 | J23: =IFERROR(K23/$B$2,0) -> 0.003278096 | K23: 3278096 | L23: =IFERROR(K23/SUM($K$15:$K$79),0) -> 0.003267169 | M23: =IFERROR(L23*E23,0) -> 0.024702551 | O23: 7 | P23: 8 | Q23: =L23 | R23: 0.0029152925 | U23: =IFERROR(ROUND(T23/L23,2),0)
A24: (8, 9] | B24: 10394 | C24: 44647150 | D24: =IFERROR(B24/$B$13,0) -> 0.0010394 | E24: =IFERROR(C24/B24/500.0,0) -> 8.5909467 | G24: (8, 9] | H24: 2.58906 | I24: =IFERROR(B24/$B$13,0) -> 0.002691069 | J24: =IFERROR(K24/$B$2,0) -> 0.002691069 | K24: 2691069 | L24: =IFERROR(K24/SUM($K$15:$K$79),0) -> 0.0026820988 | M24: =IFERROR(L24*E24,0) -> 0.023041768 | O24: 8 | P24: 9 | Q24: =L24 | R24: 0.0024840722 | U24: =IFERROR(ROUND(T24/L24,2),0)
A25: (9, 10] | B25: 14993 | C25: 73230375 | D25: =IFERROR(B25/$B$13,0) -> 0.0014993 | E25: =IFERROR(C25/B25/500.0,0) -> 9.7686087 | G25: (9, 10] | H25: 2.4501387 | I25: =IFERROR(B25/$B$13,0) -> 0.003673493 | J25: =IFERROR(K25/$B$2,0) -> 0.003673493 | K25: 3673493 | L25: =IFERROR(K25/SUM($K$15:$K$79),0) -> 0.003661248 | M25: =IFERROR(L25*E25,0) -> 0.035765299 | O25: 9 | P25: 10 | Q25: =L25 | R25: 0.0024415575 | U25: =IFERROR(ROUND(T25/L25,2),0)
A26: (10, 15] | B26: 40743 | C26: 248220825 | D26: =IFERROR(B26/$B$13,0) -> 0.0040743 | E26: =IFERROR(C26/B26/500.0,0) -> 12.18471 | G26: (10, 15] | H26: 2.7541156 | I26: =IFERROR(B26/$B$13,0) -> 0.011221093 | J26: =IFERROR(K26/$B$2,0) -> 0.011221093 | K26: 11221093 | L26: =IFERROR(K26/SUM($K$15:$K$79),0) -> 0.011183689 | M26: =IFERROR(L26*E26,0) -> 0.13627001 | O26: 10 | P26: 15 | Q26: =L26 | R26: 0.0045490711 | U26: =IFERROR(ROUND(T26/L26,2),0)
... A78: (100000, 9999999] | B78: 0 | C78: 0 | D78: =IFERROR(B78/$B$13,0) -> 0 | E78: =IFERROR(C78/B78/500.0,0) -> 0 | G78: (100000, 9999999] | H78: 0 | I78: =IFERROR(B78/$B$13,0) -> 0 | J78: =IFERROR(K78/$B$2,0) -> 0 | K78: 0 | L78: =IFERROR(K78/SUM($K$15:$K$79),0) -> 0 | M78: =IFERROR(L78*E78,0) -> 0 | O78: 100000 | P78: 9999999 | Q78: =L78 | R78: 0 | U78: =IFERROR(ROUND(T78/L78,2),0)
A79: Free Game | B79: 22040 | C79: 44813925 | D79: =B79/B13 -> 0.002204 | E79: =IFERROR(C79/B79/$B$3,0) -> 4.0665994 | G79: Free Game | H79: 1.5124019 | I79: =D79*H79 -> 0.0033333337 | J79: =I79 -> 0.0033333337 | K79: 3344482 | L79: =IFERROR(K79/SUM($K$15:$K$79),0) -> 0.0033333337 | M79: =L79*E79 -> 0.013555333
A82: Oldhand Normal Bet FG | B82: Free Game | G82: Normal Bet | H82: Free Game | O82: Normal Bet | P82: Free Game
A84: Simulate | B84: 22143 | G84: Calculate
A85: Range | B85: Cnt | C85: Pay | D85: Hit Rate | E85: Avg. Multi. | G85: Range | H85: Fix Num | I85: Fix Rate | J85: Final Rate | K85: Weight | L85: Hit Rate | M85: Simulator RTP | O85: Lower | P85: Upper | Q85: 目前 | R85: 競品 | T85: 目前 | U85: 差異
A86: (-1, 0] | B86: 4 | C86: 0 | D86: =IFERROR(B86/$B$84,0) -> 0.000180644 | E86: =IFERROR(C86/B86/500.0,0) -> 0 | G86: (-1, 0] | H86: 0 | I86: =IFERROR(B86/$B$84,0) -> 0 | J86: =IFERROR(K86/$B$2,0) -> 0 | K86: 0 | L86: =IFERROR(K86/$B$2,0) -> 0 | M86: =IFERROR(L86*E86,0) -> 0 | O86: -1 | P86: 0 | Q86: =L86 | R86: 0 | U86: =IFERROR(ROUND(T86/L86,2),0)
A87: (0, 1] | B87: 27 | C87: 9150 | D87: =IFERROR(B87/$B$84,0) -> 0.001219347 | E87: =IFERROR(C87/B87/500.0,0) -> 0.67777778 | G87: (0, 1] | H87: 0 | I87: =IFERROR(B87/$B$84,0) -> 0 | J87: =IFERROR(K87/$B$2,0) -> 0 | K87: 0 | L87: =IFERROR(K87/$B$2,0) -> 0 | M87: =IFERROR(L87*E87,0) -> 0 | O87: 0 | P87: 1 | Q87: =L87 | R87: 0 | U87: =IFERROR(ROUND(T87/L87,2),0)
A88: (1, 2] | B88: 49 | C88: 38975 | D88: =IFERROR(B88/$B$84,0) -> 0.0022128889 | E88: =IFERROR(C88/B88/500.0,0) -> 1.5908163 | G88: (1, 2] | H88: 0 | I88: =IFERROR(B88/$B$84,0) -> 0 | J88: =IFERROR(K88/$B$2,0) -> 0 | K88: 0 | L88: =IFERROR(K88/$B$2,0) -> 0 | M88: =IFERROR(L88*E88,0) -> 0 | O88: 1 | P88: 2 | Q88: =L88 | R88: 0 | U88: =IFERROR(ROUND(T88/L88,2),0)
A89: (2, 3] | B89: 70 | C89: 90475 | D89: =IFERROR(B89/$B$84,0) -> 0.0031612699 | E89: =IFERROR(C89/B89/500.0,0) -> 2.585 | G89: (2, 3] | H89: 0 | I89: =IFERROR(B89/$B$84,0) -> 0 | J89: =IFERROR(K89/$B$2,0) -> 0 | K89: 0 | L89: =IFERROR(K89/$B$2,0) -> 0 | M89: =IFERROR(L89*E89,0) -> 0 | O89: 2 | P89: 3 | Q89: =L89 | R89: 0 | U89: =IFERROR(ROUND(T89/L89,2),0)
A90: (3, 4] | B90: 116 | C90: 205200 | D90: =IFERROR(B90/$B$84,0) -> 0.0052386759 | E90: =IFERROR(C90/B90/500.0,0) -> 3.537931 | G90: (3, 4] | H90: 0 | I90: =IFERROR(B90/$B$84,0) -> 0 | J90: =IFERROR(K90/$B$2,0) -> 0 | K90: 0 | L90: =IFERROR(K90/$B$2,0) -> 0 | M90: =IFERROR(L90*E90,0) -> 0 | O90: 3 | P90: 4 | Q90: =L90 | R90: 0 | U90: =IFERROR(ROUND(T90/L90,2),0)
A91: (4, 5] | B91: 140 | C91: 316600 | D91: =IFERROR(B91/$B$84,0) -> 0.0063225399 | E91: =IFERROR(C91/B91/500.0,0) -> 4.5228571 | G91: (4, 5] | H91: 0 | I91: =IFERROR(B91/$B$84,0) -> 0 | J91: =IFERROR(K91/$B$2,0) -> 0 | K91: 0 | L91: =IFERROR(K91/$B$2,0) -> 0 | M91: =IFERROR(L91*E91,0) -> 0 | O91: 4 | P91: 5 | Q91: =L91 | R91: 0.0035688794 | U91: =IFERROR(ROUND(T91/L91,2),0)
A92: (5, 6] | B92: 136 | C92: 375325 | D92: =IFERROR(B92/$B$84,0) -> 0.0061418959 | E92: =IFERROR(C92/B92/500.0,0) -> 5.5194853 | G92: (5, 6] | H92: 0 | I92: =IFERROR(B92/$B$84,0) -> 0 | J92: =IFERROR(K92/$B$2,0) -> 0 | K92: 0 | L92: =IFERROR(K92/$B$2,0) -> 0 | M92: =IFERROR(L92*E92,0) -> 0 | O92: 5 | P92: 6 | Q92: =L92 | R92: 0.035688794 | U92: =IFERROR(ROUND(T92/L92,2),0)
A93: (6, 7] | B93: 165 | C93: 539050 | D93: =IFERROR(B93/$B$84,0) -> 0.0074515648 | E93: =IFERROR(C93/B93/500.0,0) -> 6.5339394 | G93: (6, 7] | H93: 0 | I93: =IFERROR(B93/$B$84,0) -> 0 | J93: =IFERROR(K93/$B$2,0) -> 0 | K93: 0 | L93: =IFERROR(K93/$B$2,0) -> 0 | M93: =IFERROR(L93*E93,0) -> 0 | O93: 6 | P93: 7 | Q93: =L93 | R93: 0.030692363 | U93: =IFERROR(ROUND(T93/L93,2),0)
A94: (7, 8] | B94: 177 | C94: 664400 | D94: =IFERROR(B94/$B$84,0) -> 0.0079934968 | E94: =IFERROR(C94/B94/500.0,0) -> 7.5073446 | G94: (7, 8] | H94: 0 | I94: =IFERROR(B94/$B$84,0) -> 0 | J94: =IFERROR(K94/$B$2,0) -> 0 | K94: 0 | L94: =IFERROR(K94/$B$2,0) -> 0 | M94: =IFERROR(L94*E94,0) -> 0 | O94: 7 | P94: 8 | Q94: =L94 | R94: 0.03283369 | U94: =IFERROR(ROUND(T94/L94,2),0)
A95: (8, 9] | B95: 199 | C95: 848525 | D95: =IFERROR(B95/$B$84,0) -> 0.0089870388 | E95: =IFERROR(C95/B95/500.0,0) -> 8.5278894 | G95: (8, 9] | H95: 0 | I95: =IFERROR(B95/$B$84,0) -> 0 | J95: =IFERROR(K95/$B$2,0) -> 0 | K95: 0 | L95: =IFERROR(K95/$B$2,0) -> 0 | M95: =IFERROR(L95*E95,0) -> 0 | O95: 8 | P95: 9 | Q95: =L95 | R95: 0.031406138 | U95: =IFERROR(ROUND(T95/L95,2),0)
A96: (9, 10] | B96: 189 | C96: 903125 | D96: =IFERROR(B96/$B$84,0) -> 0.0085354288 | E96: =IFERROR(C96/B96/500.0,0) -> 9.5568783 | G96: (9, 10] | H96: 0 | I96: =IFERROR(B96/$B$84,0) -> 0 | J96: =IFERROR(K96/$B$2,0) -> 0 | K96: 0 | L96: =IFERROR(K96/$B$2,0) -> 0 | M96: =IFERROR(L96*E96,0) -> 0 | O96: 9 | P96: 10 | Q96: =L96 | R96: 0.033547466 | U96: =IFERROR(ROUND(T96/L96,2),0)
A97: (10, 15] | B97: 897 | C97: 5616400 | D97: =IFERROR(B97/$B$84,0) -> 0.040509416 | E97: =IFERROR(C97/B97/500.0,0) -> 12.522631 | G97: (10, 15] | H97: 0 | I97: =IFERROR(B97/$B$84,0) -> 0 | J97: =IFERROR(K97/$B$2,0) -> 0 | K97: 0 | L97: =IFERROR(K97/$B$2,0) -> 0 | M97: =IFERROR(L97*E97,0) -> 0 | O97: 10 | P97: 15 | Q97: =L97 | R97: 0.14561028 | U97: =IFERROR(ROUND(T97/L97,2),0)
... A149: (100000, 9999999] | B149: 0 | C149: 0 | D149: =IFERROR(B149/$B$84,0) -> 0 | E149: =IFERROR(C149/B149/500.0,0) -> 0 | G149: (100000, 9999999] | H149: 0 | I149: =IFERROR(B149/$B$84,0) -> 0 | J149: =IFERROR(K149/$B$2,0) -> 0 | K149: 0 | L149: =IFERROR(K149/$B$2,0) -> 0 | M149: =IFERROR(L149*E149,0) -> 0 | O149: 100000 | P149: 9999999 | Q149: =L149 | R149: 0 | U149: =IFERROR(ROUND(T149/L149,2),0)
...

Sheet Detail_Newbie
A2: Threshold | B2: 1000000000
A3: Coin in | B3: 100
C5: RTP
B6: Bet | C6: Base Game | D6: Free Game | E6: Total | F6: Hit Rate | G6: FG Period | H6: Avg Multi | I6: BG | J6: FG
A7: Normal Bet | B7: 1 | C7: =SUM(M15:M79) -> 0.74 | D7: =SUM(M86:M149)*F7 -> 0.2 | E7: =SUM(C7:D7) -> 0.94 | F7: 0.0033333337 | G7: =1/F7 -> 299.99996 | H7: =D7*G7 -> 59.999993 | I7: =IFERROR(LOOKUP(2,1/(K15:K78<>0),P15:P78),0) -> 20 | J7: =IFERROR(LOOKUP(2,1/(K86:K149<>0),P86:P149),0) -> 120
A11: Newbie Normal Bet BG | B11: Base Game | G11: Normal Bet | H11: Base Game | O11: Normal Bet | P11: Base Game
A13: Simulate | B13: 10000000 | G13: Calculate
A14: Range | B14: Cnt | C14: Pay | D14: Hit Rate | E14: Avg. Multi. | G14: Range | H14: Fix Num | I14: Fix Rate | J14: Final Rate | K14: Weight | L14: Hit Rate | M14: Simulator RTP | O14: Lower | P14: Upper | Q14: 目前 | R14: 競品 | T14: 目前 | U14: 差異
A15: (-1, 0] | B15: 7157620 | C15: 0 | D15: =IFERROR(B15/$B$13,0) -> 0.715762 | E15: =IFERROR(C15/B15/500.0,0) -> 0 | G15: (-1, 0] | H15: 0.94451838 | I15: =IFERROR(B15/$B$13,0) -> 0.67605036 | J15: =IFERROR(K15/$B$2,0) -> 0.67605036 | K15: 676050363 | L15: =IFERROR(K15/SUM($K$15:$K$79),0) -> 0.67379686 | M15: =IFERROR(L15*E15,0) -> 0 | O15: -1 | P15: 0 | Q15: =L15 | R15: 0.723799 | U15: =IFERROR(ROUND(T15/L15,2),0)
A16: (0, 1] | B16: 1667211 | C16: 416306550 | D16: =IFERROR(B16/$B$13,0) -> 0.1667211 | E16: =IFERROR(C16/B16/500.0,0) -> 0.49940475 | G16: (0, 1] | H16: 1.04125 | I16: =IFERROR(B16/$B$13,0) -> 0.17359835 | J16: =IFERROR(K16/$B$2,0) -> 0.17359835 | K16: 173598347 | L16: =IFERROR(K16/SUM($K$15:$K$79),0) -> 0.17301969 | M16: =IFERROR(L16*E16,0) -> 0.086406854 | O16: 0 | P16: 1 | Q16: =L16 | R16: 0.154266 | U16: =IFERROR(ROUND(T16/L16,2),0)
A17: (1, 2] | B17: 538090 | C17: 401573875 | D17: =IFERROR(B17/$B$13,0) -> 0.053809 | E17: =IFERROR(C17/B17/500.0,0) -> 1.49259 | G17: (1, 2] | H17: 1.1192509 | I17: =IFERROR(B17/$B$13,0) -> 0.060225774 | J17: =IFERROR(K17/$B$2,0) -> 0.060225774 | K17: 60225774 | L17: =IFERROR(K17/SUM($K$15:$K$79),0) -> 0.060025021 | M17: =IFERROR(L17*E17,0) -> 0.089592746 | O17: 1 | P17: 2 | Q17: =L17 | R17: 0.045428 | U17: =IFERROR(ROUND(T17/L17,2),0)
A18: (2, 3] | B18: 224385 | C18: 287523200 | D18: =IFERROR(B18/$B$13,0) -> 0.0224385 | E18: =IFERROR(C18/B18/500.0,0) -> 2.5627667 | G18: (2, 3] | H18: 1.165959 | I18: =IFERROR(B18/$B$13,0) -> 0.02616237 | J18: =IFERROR(K18/$B$2,0) -> 0.02616237 | K18: 26162370 | L18: =IFERROR(K18/SUM($K$15:$K$79),0) -> 0.026075162 | M18: =IFERROR(L18*E18,0) -> 0.066824556 | O18: 2 | P18: 3 | Q18: =L18 | R18: 0.02091 | U18: =IFERROR(ROUND(T18/L18,2),0)
A19: (3, 4] | B19: 132955 | C19: 232983725 | D19: =IFERROR(B19/$B$13,0) -> 0.0132955 | E19: =IFERROR(C19/B19/500.0,0) -> 3.5047005 | G19: (3, 4] | H19: 1.3496977 | I19: =IFERROR(B19/$B$13,0) -> 0.017944906 | J19: =IFERROR(K19/$B$2,0) -> 0.017944906 | K19: 17944906 | L19: =IFERROR(K19/SUM($K$15:$K$79),0) -> 0.01788509 | M19: =IFERROR(L19*E19,0) -> 0.062681882 | O19: 3 | P19: 4 | Q19: =L19 | R19: 0.012886 | U19: =IFERROR(ROUND(T19/L19,2),0)
A20: (4, 5] | B20: 69633 | C20: 158342550 | D20: =IFERROR(B20/$B$13,0) -> 0.0069633 | E20: =IFERROR(C20/B20/500.0,0) -> 4.5479169 | G20: (4, 5] | H20: 1.4499864 | I20: =IFERROR(B20/$B$13,0) -> 0.01009669 | J20: =IFERROR(K20/$B$2,0) -> 0.01009669 | K20: 10096690 | L20: =IFERROR(K20/SUM($K$15:$K$79),0) -> 0.010063034 | M20: =IFERROR(L20*E20,0) -> 0.045765844 | O20: 4 | P20: 5 | Q20: =L20 | R20: 0.008406 | U20: =IFERROR(ROUND(T20/L20,2),0)
A21: (5, 6] | B21: 36941 | C21: 102200425 | D21: =IFERROR(B21/$B$13,0) -> 0.0036941 | E21: =IFERROR(C21/B21/500.0,0) -> 5.5331705 | G21: (5, 6] | H21: 1.3288609 | I21: =IFERROR(B21/$B$13,0) -> 0.004908945 | J21: =IFERROR(K21/$B$2,0) -> 0.004908945 | K21: 4908945 | L21: =IFERROR(K21/SUM($K$15:$K$79),0) -> 0.0048925818 | M21: =IFERROR(L21*E21,0) -> 0.027071489 | O21: 5 | P21: 6 | Q21: =L21 | R21: 0.006517 | U21: =IFERROR(ROUND(T21/L21,2),0)
A22: (6, 7] | B22: 22473 | C22: 72923550 | D22: =IFERROR(B22/$B$13,0) -> 0.0022473 | E22: =IFERROR(C22/B22/500.0,0) -> 6.4898812 | G22: (6, 7] | H22: 1.9493361 | I22: =IFERROR(B22/$B$13,0) -> 0.004380743 | J22: =IFERROR(K22/$B$2,0) -> 0.004380743 | K22: 4380743 | L22: =IFERROR(K22/SUM($K$15:$K$79),0) -> 0.0043661405 | M22: =IFERROR(L22*E22,0) -> 0.028335733 | O22: 6 | P22: 7 | Q22: =L22 | R22: 0.003524 | U22: =IFERROR(ROUND(T22/L22,2),0)
A23: (7, 8] | B23: 17491 | C23: 66123350 | D23: =IFERROR(B23/$B$13,0) -> 0.0017491 | E23: =IFERROR(C23/B23/500.0,0) -> 7.5608427 | G23: (7, 8] | H23: 1.8741616 | I23: =IFERROR(B23/$B$13,0) -> 0.003278096 | J23: =IFERROR(K23/$B$2,0) -> 0.003278096 | K23: 3278096 | L23: =IFERROR(K23/SUM($K$15:$K$79),0) -> 0.003267169 | M23: =IFERROR(L23*E23,0) -> 0.024702551 | O23: 7 | P23: 8 | Q23: =L23 | R23: 0.00397 | U23: =IFERROR(ROUND(T23/L23,2),0)
A24: (8, 9] | B24: 10394 | C24: 44647150 | D24: =IFERROR(B24/$B$13,0) -> 0.0010394 | E24: =IFERROR(C24/B24/500.0,0) -> 8.5909467 | G24: (8, 9] | H24: 2.58906 | I24: =IFERROR(B24/$B$13,0) -> 0.002691069 | J24: =IFERROR(K24/$B$2,0) -> 0.002691069 | K24: 2691069 | L24: =IFERROR(K24/SUM($K$15:$K$79),0) -> 0.0026820988 | M24: =IFERROR(L24*E24,0) -> 0.023041768 | O24: 8 | P24: 9 | Q24: =L24 | R24: 0.003227 | U24: =IFERROR(ROUND(T24/L24,2),0)
A25: (9, 10] | B25: 14993 | C25: 73230375 | D25: =IFERROR(B25/$B$13,0) -> 0.0014993 | E25: =IFERROR(C25/B25/500.0,0) -> 9.7686087 | G25: (9, 10] | H25: 2.4501387 | I25: =IFERROR(B25/$B$13,0) -> 0.003673493 | J25: =IFERROR(K25/$B$2,0) -> 0.003673493 | K25: 3673493 | L25: =IFERROR(K25/SUM($K$15:$K$79),0) -> 0.003661248 | M25: =IFERROR(L25*E25,0) -> 0.035765299 | O25: 9 | P25: 10 | Q25: =L25 | R25: 0.002102 | U25: =IFERROR(ROUND(T25/L25,2),0)
A26: (10, 15] | B26: 40743 | C26: 248220825 | D26: =IFERROR(B26/$B$13,0) -> 0.0040743 | E26: =IFERROR(C26/B26/500.0,0) -> 12.18471 | G26: (10, 15] | H26: 2.7541156 | I26: =IFERROR(B26/$B$13,0) -> 0.011221093 | J26: =IFERROR(K26/$B$2,0) -> 0.011221093 | K26: 11221093 | L26: =IFERROR(K26/SUM($K$15:$K$79),0) -> 0.011183689 | M26: =IFERROR(L26*E26,0) -> 0.13627001 | O26: 10 | P26: 15 | Q26: =L26 | R26: 0.006432 | U26: =IFERROR(ROUND(T26/L26,2),0)
... A78: (100000, 9999999] | B78: 0 | C78: 0 | D78: =IFERROR(B78/$B$13,0) -> 0 | E78: =IFERROR(C78/B78/500.0,0) -> 0 | G78: (100000, 9999999] | H78: 0 | I78: =IFERROR(B78/$B$13,0) -> 0 | J78: =IFERROR(K78/$B$2,0) -> 0 | K78: 0 | L78: =IFERROR(K78/SUM($K$15:$K$79),0) -> 0 | M78: =IFERROR(L78*E78,0) -> 0 | O78: 100000 | P78: 9999999 | Q78: =L78 | R78: 0 | U78: =IFERROR(ROUND(T78/L78,2),0)
A79: Free Game | B79: 22040 | C79: 44813925 | D79: =B79/B13 -> 0.002204 | E79: =IFERROR(C79/B79/$B$3,0) -> 4.0665994 | G79: Free Game | H79: 1.5124019 | I79: =D79*H79 -> 0.0033333337 | J79: =I79 -> 0.0033333337 | K79: 3344482 | L79: =IFERROR(K79/SUM($K$15:$K$79),0) -> 0.0033333337 | M79: =L79*E79 -> 0.013555333
A82: Newbie Normal Bet FG | B82: Free Game | G82: Normal Bet | H82: Free Game | O82: Normal Bet | P82: Free Game
A84: Simulate | B84: 22143 | G84: Calculate
A85: Range | B85: Cnt | C85: Pay | D85: Hit Rate | E85: Avg. Multi. | G85: Range | H85: Fix Num | I85: Fix Rate | J85: Final Rate | K85: Weight | L85: Hit Rate | M85: Simulator RTP | O85: Lower | P85: Upper | Q85: 目前 | R85: 競品 | T85: 目前 | U85: 差異
A86: (-1, 0] | B86: 4 | C86: 0 | D86: =IFERROR(B86/$B$84,0) -> 0.000180644 | E86: =IFERROR(C86/B86/500.0,0) -> 0 | G86: (-1, 0] | H86: 0 | I86: =IFERROR(B86/$B$84,0) -> 0 | J86: =IFERROR(K86/$B$2,0) -> 0 | K86: 0 | L86: =IFERROR(K86/$B$2,0) -> 0 | M86: =IFERROR(L86*E86,0) -> 0 | O86: -1 | P86: 0 | Q86: =L86 | R86: 0.02069 | U86: =IFERROR(ROUND(T86/L86,2),0)
A87: (0, 1] | B87: 27 | C87: 9150 | D87: =IFERROR(B87/$B$84,0) -> 0.001219347 | E87: =IFERROR(C87/B87/500.0,0) -> 0.67777778 | G87: (0, 1] | H87: 0 | I87: =IFERROR(B87/$B$84,0) -> 0 | J87: =IFERROR(K87/$B$2,0) -> 0 | K87: 0 | L87: =IFERROR(K87/$B$2,0) -> 0 | M87: =IFERROR(L87*E87,0) -> 0 | O87: 0 | P87: 1 | Q87: =L87 | R87: 0.006897 | U87: =IFERROR(ROUND(T87/L87,2),0)
A88: (1, 2] | B88: 49 | C88: 38975 | D88: =IFERROR(B88/$B$84,0) -> 0.0022128889 | E88: =IFERROR(C88/B88/500.0,0) -> 1.5908163 | G88: (1, 2] | H88: 0 | I88: =IFERROR(B88/$B$84,0) -> 0 | J88: =IFERROR(K88/$B$2,0) -> 0 | K88: 0 | L88: =IFERROR(K88/$B$2,0) -> 0 | M88: =IFERROR(L88*E88,0) -> 0 | O88: 1 | P88: 2 | Q88: =L88 | R88: 0.006897 | U88: =IFERROR(ROUND(T88/L88,2),0)
A89: (2, 3] | B89: 70 | C89: 90475 | D89: =IFERROR(B89/$B$84,0) -> 0.0031612699 | E89: =IFERROR(C89/B89/500.0,0) -> 2.585 | G89: (2, 3] | H89: 0 | I89: =IFERROR(B89/$B$84,0) -> 0 | J89: =IFERROR(K89/$B$2,0) -> 0 | K89: 0 | L89: =IFERROR(K89/$B$2,0) -> 0 | M89: =IFERROR(L89*E89,0) -> 0 | O89: 2 | P89: 3 | Q89: =L89 | R89: 0.006897 | U89: =IFERROR(ROUND(T89/L89,2),0)
A90: (3, 4] | B90: 116 | C90: 205200 | D90: =IFERROR(B90/$B$84,0) -> 0.0052386759 | E90: =IFERROR(C90/B90/500.0,0) -> 3.537931 | G90: (3, 4] | H90: 0 | I90: =IFERROR(B90/$B$84,0) -> 0 | J90: =IFERROR(K90/$B$2,0) -> 0 | K90: 0 | L90: =IFERROR(K90/$B$2,0) -> 0 | M90: =IFERROR(L90*E90,0) -> 0 | O90: 3 | P90: 4 | Q90: =L90 | R90: 0.006897 | U90: =IFERROR(ROUND(T90/L90,2),0)
A91: (4, 5] | B91: 140 | C91: 316600 | D91: =IFERROR(B91/$B$84,0) -> 0.0063225399 | E91: =IFERROR(C91/B91/500.0,0) -> 4.5228571 | G91: (4, 5] | H91: 0 | I91: =IFERROR(B91/$B$84,0) -> 0 | J91: =IFERROR(K91/$B$2,0) -> 0 | K91: 0 | L91: =IFERROR(K91/$B$2,0) -> 0 | M91: =IFERROR(L91*E91,0) -> 0 | O91: 4 | P91: 5 | Q91: =L91 | R91: 0.006897 | U91: =IFERROR(ROUND(T91/L91,2),0)
A92: (5, 6] | B92: 136 | C92: 375325 | D92: =IFERROR(B92/$B$84,0) -> 0.0061418959 | E92: =IFERROR(C92/B92/500.0,0) -> 5.5194853 | G92: (5, 6] | H92: 0 | I92: =IFERROR(B92/$B$84,0) -> 0 | J92: =IFERROR(K92/$B$2,0) -> 0 | K92: 0 | L92: =IFERROR(K92/$B$2,0) -> 0 | M92: =IFERROR(L92*E92,0) -> 0 | O92: 5 | P92: 6 | Q92: =L92 | R92: 0.006897 | U92: =IFERROR(ROUND(T92/L92,2),0)
A93: (6, 7] | B93: 165 | C93: 539050 | D93: =IFERROR(B93/$B$84,0) -> 0.0074515648 | E93: =IFERROR(C93/B93/500.0,0) -> 6.5339394 | G93: (6, 7] | H93: 0 | I93: =IFERROR(B93/$B$84,0) -> 0 | J93: =IFERROR(K93/$B$2,0) -> 0 | K93: 0 | L93: =IFERROR(K93/$B$2,0) -> 0 | M93: =IFERROR(L93*E93,0) -> 0 | O93: 6 | P93: 7 | Q93: =L93 | R93: 0.02069 | U93: =IFERROR(ROUND(T93/L93,2),0)
A94: (7, 8] | B94: 177 | C94: 664400 | D94: =IFERROR(B94/$B$84,0) -> 0.0079934968 | E94: =IFERROR(C94/B94/500.0,0) -> 7.5073446 | G94: (7, 8] | H94: 0 | I94: =IFERROR(B94/$B$84,0) -> 0 | J94: =IFERROR(K94/$B$2,0) -> 0 | K94: 0 | L94: =IFERROR(K94/$B$2,0) -> 0 | M94: =IFERROR(L94*E94,0) -> 0 | O94: 7 | P94: 8 | Q94: =L94 | R94: 0 | U94: =IFERROR(ROUND(T94/L94,2),0)
A95: (8, 9] | B95: 199 | C95: 848525 | D95: =IFERROR(B95/$B$84,0) -> 0.0089870388 | E95: =IFERROR(C95/B95/500.0,0) -> 8.5278894 | G95: (8, 9] | H95: 0 | I95: =IFERROR(B95/$B$84,0) -> 0 | J95: =IFERROR(K95/$B$2,0) -> 0 | K95: 0 | L95: =IFERROR(K95/$B$2,0) -> 0 | M95: =IFERROR(L95*E95,0) -> 0 | O95: 8 | P95: 9 | Q95: =L95 | R95: 0.006897 | U95: =IFERROR(ROUND(T95/L95,2),0)
A96: (9, 10] | B96: 189 | C96: 903125 | D96: =IFERROR(B96/$B$84,0) -> 0.0085354288 | E96: =IFERROR(C96/B96/500.0,0) -> 9.5568783 | G96: (9, 10] | H96: 0 | I96: =IFERROR(B96/$B$84,0) -> 0 | J96: =IFERROR(K96/$B$2,0) -> 0 | K96: 0 | L96: =IFERROR(K96/$B$2,0) -> 0 | M96: =IFERROR(L96*E96,0) -> 0 | O96: 9 | P96: 10 | Q96: =L96 | R96: 0 | U96: =IFERROR(ROUND(T96/L96,2),0)
A97: (10, 15] | B97: 897 | C97: 5616400 | D97: =IFERROR(B97/$B$84,0) -> 0.040509416 | E97: =IFERROR(C97/B97/500.0,0) -> 12.522631 | G97: (10, 15] | H97: 0 | I97: =IFERROR(B97/$B$84,0) -> 0 | J97: =IFERROR(K97/$B$2,0) -> 0 | K97: 0 | L97: =IFERROR(K97/$B$2,0) -> 0 | M97: =IFERROR(L97*E97,0) -> 0 | O97: 10 | P97: 15 | Q97: =L97 | R97: 0.062069 | U97: =IFERROR(ROUND(T97/L97,2),0)
... A149: (100000, 9999999] | B149: 0 | C149: 0 | D149: =IFERROR(B149/$B$84,0) -> 0 | E149: =IFERROR(C149/B149/500.0,0) -> 0 | G149: (100000, 9999999] | H149: 0 | I149: =IFERROR(B149/$B$84,0) -> 0 | J149: =IFERROR(K149/$B$2,0) -> 0 | K149: 0 | L149: =IFERROR(K149/$B$2,0) -> 0 | M149: =IFERROR(L149*E149,0) -> 0 | O149: 100000 | P149: 9999999 | Q149: =L149 | R149: 0 | U149: =IFERROR(ROUND(T149/L149,2),0)
K150: =SUM(K86:K149) -> 1000000000 | M150: =SUM(M86:M149) -> 59.999993

Sheet OP Jackpot
B2: Threshold | C2: 10000000000
B4: Bet Type | C4: SCR
B5: NB_Newbie | C5: 3615908800
B6: NB | C6: 3617019900
B7: BF | C7: 38131173000
B8: SF | C8: 40534502000
