Workbook

Sheet Overview
A3: Model: | B3: 5.0.1.0
A5: Reel # | B5: 1 | C5: 2 | D5: 3 | E5: 4
A6: Visible Window Size | B6: 3 | C6: 3 | D6: 3 | E6: 3
E7: 用模擬各張表的RTP+權重得出的理論RTP
A8: OverAll
A9: Coin | B9: Bet | C9: Reels | D9: Line | E9: Pay Back %
A10: 1 | B10: 1 | C10: 4 | D10: 1 | E10: =Card_Info_NoExtra_testA!A2 -> 0.42607907
A11: 5 | B11: 5 | C11: 4 | D11: 1 | E11: =Card_Info_NoExtra_testA!D2 -> 0.71959919
A12: 10 | B12: 10 | C12: 4 | D12: 1 | E12: =Card_Info_NoExtra_testA!G2 -> 0.62352587
A13: 50 | B13: 50 | C13: 4 | D13: 1 | E13: =Card_Info_NoExtra_testA!J2 -> 0.8042406
A14: 100 | B14: 100 | C14: 4 | D14: 1 | E14: =Card_Info_NoExtra_testA!M2 -> 0.71356018
A16: Parameter A
A17: Coin | B17: Bet | C17: Reels | D17: Line | E17: Pay Back % | F17: Hit%
A18: 1 | B18: 1 | C18: 4 | D18: 1 | E18: 0.96493765
A19: 5 | B19: 5 | C19: 4 | D19: 1 | E19: 0.96522031
A20: 10 | B20: 10 | C20: 4 | D20: 1 | E20: 0.96503114
A21: 50 | B21: 50 | C21: 4 | D21: 1 | E21: 0.96509082
A22: 100 | B22: 100 | C22: 4 | D22: 1 | E22: 0.96593576
A24: Total payback percentage includes the following adjustments:
A25: Feature or Adjustment | B25: Respin | E25: Bonus
A26: Bet | B26: Pay Back | C26: Hit Freq | D26: Pulls/Hit | E26: Pay Back | F26: Hit Freq | G26: Pulls/Hit
A27: 1 | B27: 0.32865826 | E27: --
A28: 5 | B28: 0.13083013 | E28: 0.26798905
A29: 10 | B29: 0.11786942 | E29: 0.26657935
A30: 50 | B30: 0.14234767 | E30: 0.289615
A31: 100 | B31: 0.25152971 | E31: 0.20275845
A34: Parameter B
A35: Coin | B35: Bet | C35: Reels | D35: Line | E35: Pay Back % | F35: Hit%
A36: 1 | B36: 1 | C36: 4 | D36: 1 | E36: 32.640336
A37: 5 | B37: 5 | C37: 4 | D37: 1 | E37: 38.068061
A38: 10 | B38: 10 | C38: 4 | D38: 1 | E38: 27.668223
A39: 50 | B39: 50 | C39: 4 | D39: 1 | E39: 42.487217
A40: 100 | B40: 100 | C40: 4 | D40: 1 | E40: 37.440117
A42: Total payback percentage includes the following adjustments:
A43: Feature or Adjustment | B43: Respin | E43: Bonus
A44: Bet | B44: Pay Back | C44: Hit Freq | D44: Pulls/Hit | E44: Pay Back | F44: Hit Freq | G44: Pulls/Hit
A45: 1 | B45: 3.9167467 | E45: --
A46: 5 | B46: 3.0193534 | E46: 6.7185061
A47: 10 | B47: 1.3730078 | E47: 5.3740768
A48: 50 | B48: 1.5781948 | E48: 23.879206
...

Sheet Extra_info
B2: 1 | C2: 卡片系統使用"Card_Info_NoExtra" | D2: Interval:倍率區間
D3: Weight:倍率區間權重
D4: Sheet:使用表

Sheet Description
B2: 1. 前三輪使用權重輪帶(first 3 reel)，共有A、B、C三張表，並依照多表權重選擇使用哪一張表
B4: 2. 第四輪使用權重輪帶(R4)，並依照前三輪分數來判斷要用哪一組的R4權重
B5: EX : 共有12組權重輪帶，分別對應分數1、5、10、11、15、50、51、55、>=100、>=3001、>= 6001，依照前三輪分數選擇對應的R4權重
B7: 3. 當R4轉到scatter時，使用權重輪帶(scatter) weight 1。
B9: 4. 當R4轉到respin時，使用權重輪帶(respin):
C10: a. 遇到Respin時，前三輪分數 + respin分數須大於等於一倍，respin分數重轉至符合條件
C11: b. 若respin後的分數小於respin前的分數，則互換，前三輪先表演分數小的
C12: c. 當respin分數為0時，respin分數重骰到大於0
B14: 5. bet100時 :
C15: a. bet100時，前三輪分數不能大於500000分(5000倍)，若大於時重轉
C16: b. bet100時，respin後分數不能大於500000分(5000倍)，若大於時重轉
C17: c. 當respin R3轉到Symbol "10"、"00"，依照switch權重決定R2、R3的Symbol是否互換
B19: 6. 重轉超過10次依照狀況使用固定組合[重轉超過]
B21: 7. R1、R4有機會觸發假表演，當有贏分且R1的Symbol不為0、E時，依照假表演權重表決定是否觸發，若觸發則依照假表演方向權重表來決定方向；當有贏分且R4的Symbol不為E時，依照假表演權重表決定是否觸發，若觸發則依照假表演方向權重表來決定方向
B23: 8. 若前三輪分數為0，第二、三輪轉到Symbol 0的RNG依照表格[0換E]有機率往下跳一個RNG
B24: EX：如果前三輪RNG為(1,0,1)，結果為EE0，0分，若第三輪觸發0換E，則RNG變為(1,0,2)
B26: 9. 初始盤面使用選擇的RNG
C28: bet1起始盤面
C29: R1 | D29: R2 | E29: R3 | F29: R4
B30: Bet1 | C30: 1 | D30: 0 | E30: 2 | F30: 3
B31: Bet5 | C31: 3 | D31: 2 | E31: 4 | F31: 5
B32: Bet10 | C32: 3 | D32: 4 | E32: 0 | F32: 7
B33: Bet50 | C33: 3 | D33: 8 | E33: 0 | F33: 5
B34: Bet100 | C34: 1 | D34: 8 | E34: 8 | F34: 7
E35: (此處為RNG)
B37: 10. 任務系統第四輪使用FreeGameCard_R4輪帶
B39: V2（3.0.0.0，2026-10-07；4.0.0.0，2026-10-12）：Normal Bet 全部押注改為對齊 JILI Money Coming 的調性。Bet1／Bet5／Bet10：bet{n}p_A 的子表、R4 分組、Respin、轉盤權重改為競品擬合值。Bet50／Bet100：以 Bet10 為範本外推（R4 分組與 Respin 同 Bet10，R2／R3 的 10／00 與 Respin 的 10／00 沿用 1.0.0.2 占比，紅轉盤依金額對應 Bet10 綠轉盤機率，500x／1000x 沿用 1.0.0.2 占比）。Card_Bet{n} 的 Hit%_Weight_Final 以多目標非負最小平方擬合（Bet50／Bet100 用 Bet10 的競品目標），RTP 固定 92%；≥200x 區間沿用 1.0.0.2 的權重與 B 表，A 表自然機率不足的區間改用 B 表。Card_Bet 的 Mul／Avg Mul／RTP 欄仍為 1.0.0.2 模擬值，V2 的 RTP 以 Simulator 驗證。Extra Bet 內容沿用 1.0.0.2。4.0.0.0（2026-10-12）：沒得分盤面演出調整——R1 幾乎全空白的子表調整 R2、R3 的空白／0 比例，讓 E 0 E、E E 0 各為 E E E 的 1.5 倍（E 0 0 為 2.25 倍；Bet1 為 E 0 _＝1.5 × E E _）；R4 數字分 0 分組（AX 欄）把空白權重移給 2X／5X／10X，沒得分時 R4 出現倍數的占比加 20 個百分點（倍數間比例、RESPIN／BONUS 權重不變）；派彩不變，Card_Bet 非零區間等比微調維持 RTP 92%。
B40: 4.0.0.0 補充（2026-10-12）：(1) 自然機率 ≥0.05%（數學模型規範 §1.5）但卡片 0 權重的區間補上權重，彼此比例依自然機率（各區間取自然機率最高的子表），最小者 1 ppm；其他區間以原目標重擬，RTP 92%。(2) Bet100 前三輪／respin 數字分上限 30000 分（300 倍）改為 500000 分（5000 倍）。
B41: 4.0.0.0 精度（2026-10-12）：依數學模型規範 §1.4.7，各押注卡片微調 2～3 格整數權重，RTP 精確到 92.0000%。
B42: 4.1.0.0（2026-10-13）：畫面組合可出現檢查——①自然機率 ≥0.05% 但卡片 0 權重的區間補權重（照自然機率，比例尺同 4.0.0.0 補區間）：Bet5 3x／120x、Bet10 7x／50x、Bet50 3x；②Bet100 (100,120] 子表 C→B（C 表缺 1100～11010 搭配空白／2X 的組合）；其餘區間等比微調，RTP 92.0000%。自然機率 <0.05% 而無法給權重的組合列為已知例外（見數值報告）。
B43: 5.0.0.0（2026-10-13）：依測試反饋只改 bet{n}p_A 權重——①R1 幾乎全空白的子表調 R2／R3 空白／0 比例，沒得分畫面 EEE／E0E／EE0／E00 取 4.1.0.0 與競品的中間值（00 放回空白）；②Bet10 該子表 R2 的 1／5 權重 ×2.94，E X 0／1／5／空 合計 2.43%→3.13%（同競品）；③R4：沒得分時出倍數（每局）約 30%→16%，有得分時 R4 是倍數 Bet1 15.3%→21.5%、Bet5 41.2%→42.1%、Bet10 22.9%→28.0%（同競品）。卡片等比調回 RTP 92.0000%。
B44: 5.0.1.0（2026-10-27）：新增 OP Jackpot 頁，填入 SCR（scatterComboRate；Oldhand／Newbie 共用同一套卡片故不分）；權重不變。

Sheet Card_Info_NoExtra_testA
A1: Bet 1 | D1: Bet 5 | G1: Bet 10 | J1: Bet 50 | M1: Bet 100 | R1: Simulation
A2: =Card_Bet1!$V$1 -> 0.42607907 | D2: =Card_Bet5!$V$1 -> 0.71959919 | G2: =Card_Bet10!$V$1 -> 0.62352587 | J2: =Card_Bet50!$V$1 -> 0.8042406 | M2: =Card_Bet100!$V$1 -> 0.71356018
A3: Interval | B3: Weight | C3: Sheet | D3: Interval | E3: Weight | F3: Sheet | G3: Interval | H3: Weight | I3: Sheet | J3: Interval | K3: Weight | L3: Sheet | M3: Interval | N3: Weight | O3: Sheet | R3: Bet | S3: RTP | T3: Respin | U3: Scatter | V3: rounds | W3: Scatter+Respin | X3: Scatter+Respin PROB.
A4: {=Card_Bet1!$K$3:$K$54} -> -1 | B4: {=Card_Bet1!$T$3:$T$54} -> 856097 | C4: {=Card_Bet1!$L$3:$L$54} -> A | D4: {=Card_Bet5!$K$3:$K$54} -> -1 | E4: {=Card_Bet5!$T$3:$T$54} -> 868433 | F4: {=Card_Bet5!$L$3:$L$54} -> A | G4: {=Card_Bet10!$K$3:$K$54} -> -1 | H4: {=Card_Bet10!$T$3:$T$54} -> 876426 | I4: {=Card_Bet10!$L$3:$L$54} -> A | J4: {=Card_Bet50!$K$3:$K$54} -> -1 | K4: {=Card_Bet50!$T$3:$T$54} -> 869589 | L4: {=Card_Bet50!$L$3:$L$54} -> A | M4: {=Card_Bet100!$K$3:$K$54} -> -1 | N4: {=Card_Bet100!$T$3:$T$54} -> 868278 | O4: {=Card_Bet100!$L$3:$L$54} -> A | R4: 1 | S4: 0.924421 | T4: 0.122159 | U4: - | V4: 100000000 | W4: =SUM(AA13:AA28,AD13:AD28) -> 2224546 | X4: =W4/V4 -> 0.02224546
A5: 0 | B5: 87908 | C5: A | D5: 0 | E5: 73842 | F5: A | G5: 0 | H5: 16356 | I5: A | J5: 0 | K5: 21320 | L5: A | M5: 0 | N5: 22965 | O5: A | R5: 5 | S5: 0.925082 | T5: 0.06123 | U5: 0.224109 | V5: 100000000 | W5: =SUM(AA30:AA48,AD30:AD48) -> 2214506 | X5: =W5/V5 -> 0.02214506
A6: 1 | B6: 1029 | C6: B | D6: 1 | E6: 1738 | F6: A | G6: 1 | H6: 51040 | I6: A | J6: 1 | K6: 51342 | L6: A | M6: 1 | N6: 38444 | O6: A | R6: 10 | S6: 0.925132 | T6: 0.081793 | U6: 0.16207 | V6: 300000000 | W6: =SUM(AA50:AA67,AD50:AD67) -> 9076233 | X6: =W6/V6 -> 0.03025411 | Y6: =W6/3 -> 3025411
A7: 2 | B7: 0 | C7: A | D7: 2 | E7: 4558 | F7: A | G7: 2 | H7: 307 | I7: B | J7: 2 | K7: 345 | L7: A | M7: 2 | N7: 318 | O7: A | R7: 50 | S7: 0.924556 | T7: 0.049855 | U7: 0.337065 | V7: 100000000 | W7: =SUM(AA69:AA84,AD69:AD84) -> 2021182 | X7: =W7/V7 -> 0.02021182
A8: 3 | B8: 0 | C8: A | D8: 3 | E8: 32 | F8: B | G8: 3 | H8: 0 | I8: A | J8: 3 | K8: 21 | L8: B | M8: 3 | N8: 0 | O8: A | R8: 100 | S8: 0.924881 | T8: 0.131463 | U8: 0.220799 | V8: 100000000 | W8: =SUM(AA86:AA108,AD86:AD108) -> 3811545 | X8: =W8/V8 -> 0.03811545
A9: 4 | B9: 25990 | C9: A | D9: 4 | E9: 22510 | F9: A | G9: 4 | H9: 11118 | I9: A | J9: 4 | K9: 10531 | L9: A | M9: 4 | N9: 15875 | O9: A
A10: 5 | B10: 196 | C10: B | D10: 5 | E10: 1062 | F10: A | G10: 5 | H10: 14768 | I10: A | J10: 5 | K10: 12823 | L10: B | M10: 5 | N10: 26258 | O10: A
A11: 6 | B11: 0 | C11: A | D11: 6 | E11: 2 | F11: B | G11: 6 | H11: 102 | I11: B | J11: 6 | K11: 1 | L11: B | M11: 6 | N11: 42 | O11: B
A12: 7 | B12: 0 | C12: A | D12: 7 | E12: 2 | F12: B | G12: 7 | H12: 5 | I12: B | J12: 7 | K12: 0 | L12: A | M12: 7 | N12: 1 | O12: B | Q12: Bet
A13: 8 | B13: 0 | C13: A | D13: 8 | E13: 0 | F13: A | G13: 8 | H13: 0 | I13: A | J13: 8 | K13: 0 | L13: A | M13: 8 | N13: 0 | O13: A | Q13: 1 | R13: BaseGame | S13: 0x | T13: = | U13: 6507225 | V13: Pay | W13: = | X13: 650722500 | Y13: 1C1 | Z13: = | AA13: null | AB13: 2C1 | AC13: = | AD13: 930217 | AE13: 3C1 | AF13: = | AG13: null | AH13: 4C1 | AI13: = | AJ13: null | AK13: 5C1 | AL13: = | AM13: null
A14: 9 | B14: 6515 | C14: A | D14: 9 | E14: 4499 | F14: A | G14: 9 | H14: 4597 | I14: A | J14: 9 | K14: 3918 | L14: A | M14: 9 | N14: 4632 | O14: A | Q14: 1 | R14: BaseGame | S14: 1x | T14: = | U14: 101518 | V14: Pay | W14: = | X14: 20303600 | Y14: 1C1 | Z14: = | AA14: null | AB14: 2C1 | AC14: = | AD14: 20601 | AE14: 3C1 | AF14: = | AG14: null | AH14: 4C1 | AI14: = | AJ14: null | AK14: 5C1 | AL14: = | AM14: null
A15: 10 | B15: 6207 | C15: A | D15: 10 | E15: 6243 | F15: A | G15: 10 | H15: 9440 | I15: A | J15: 10 | K15: 13948 | L15: A | M15: 10 | N15: 7501 | O15: A | Q15: 1 | R15: BaseGame | S15: 4x | T15: = | U15: 4280147 | V15: Pay | W15: = | X15: 2140073500 | Y15: 1C1 | Z15: = | AA15: null | AB15: 2C1 | AC15: = | AD15: 476797 | AE15: 3C1 | AF15: = | AG15: null | AH15: 4C1 | AI15: = | AJ15: null | AK15: 5C1 | AL15: = | AM15: null
A16: 15 | B16: 5365 | C16: A | D16: 15 | E16: 3093 | F16: A | G16: 15 | H16: 5477 | I16: A | J16: 15 | K16: 4075 | L16: A | M16: 15 | N16: 7188 | O16: A | Q16: 1 | R16: BaseGame | S16: 5x | T16: = | U16: 115234 | V16: Pay | W16: = | X16: 69140400 | Y16: 1C1 | Z16: = | AA16: null | AB16: 2C1 | AC16: = | AD16: 115234 | AE16: 3C1 | AF16: = | AG16: null | AH16: 4C1 | AI16: = | AJ16: null | AK16: 5C1 | AL16: = | AM16: null
A17: 20 | B17: 5135 | C17: A | D17: 20 | E17: 1940 | F17: A | G17: 20 | H17: 1493 | I17: A | J17: 20 | K17: 7763 | L17: A | M17: 20 | N17: 2650 | O17: A | Q17: 1 | R17: BaseGame | S17: 9x | T17: = | U17: 842034 | V17: Pay | W17: = | X17: 842034000 | Y17: 1C1 | Z17: = | AA17: null | AB17: 2C1 | AC17: = | AD17: 137814 | AE17: 3C1 | AF17: = | AG17: null | AH17: 4C1 | AI17: = | AJ17: null | AK17: 5C1 | AL17: = | AM17: null
A18: 25 | B18: 1 | C18: B | D18: 25 | E18: 201 | F18: B | G18: 25 | H18: 3904 | I18: A | J18: 25 | K18: 6 | L18: B | M18: 25 | N18: 934 | O18: B | Q18: 1 | R18: BaseGame | S18: 10x | T18: = | U18: 499261 | V18: Pay | W18: = | X18: 646741400 | Y18: 1C1 | Z18: = | AA18: null | AB18: 2C1 | AC18: = | AD18: 238575 | AE18: 3C1 | AF18: = | AG18: null | AH18: 4C1 | AI18: = | AJ18: null | AK18: 5C1 | AL18: = | AM18: null
A19: 30 | B19: 0 | C19: A | D19: 30 | E19: 7072 | F19: A | G19: 30 | H19: 9 | I19: B | J19: 30 | K19: 1514 | L19: A | M19: 30 | N19: 16 | O19: B | Q19: 1 | R19: BaseGame | S19: 15x | T19: = | U19: 499490 | V19: Pay | W19: = | X19: 966704800 | Y19: 1C1 | Z19: = | AA19: null | AB19: 2C1 | AC19: = | AD19: 175041 | AE19: 3C1 | AF19: = | AG19: null | AH19: 4C1 | AI19: = | AJ19: null | AK19: 5C1 | AL19: = | AM19: null
A20: 35 | B20: 0 | C20: A | D20: 35 | E20: 12 | F20: B | G20: 35 | H20: 2 | I20: B | J20: 35 | K20: 3 | L20: B | M20: 35 | N20: 17 | O20: C | Q20: 1 | R20: BaseGame | S20: 20x | T20: = | U20: 299500 | V20: Pay | W20: = | X20: 731488300 | Y20: 1C1 | Z20: = | AA20: null | AB20: 2C1 | AC20: = | AD20: 27310 | AE20: 3C1 | AF20: = | AG20: null | AH20: 4C1 | AI20: = | AJ20: null | AK20: 5C1 | AL20: = | AM20: null
A21: 40 | B21: 0 | C21: A | D21: 40 | E21: 25 | F21: B | G21: 40 | H21: 1 | I21: B | J21: 40 | K21: 318 | L21: B | M21: 40 | N21: 7 | O21: C | Q21: 1 | R21: BaseGame | S21: 25x | T21: = | U21: 119271 | V21: Pay | W21: = | X21: 354280200 | Y21: 1C1 | Z21: = | AA21: null | AB21: 2C1 | AC21: = | AD21: 13343 | AE21: 3C1 | AF21: = | AG21: null | AH21: 4C1 | AI21: = | AJ21: null | AK21: 5C1 | AL21: = | AM21: null
A22: 45 | B22: 2877 | C22: A | D22: 45 | E22: 4527 | F22: A | G22: 45 | H22: 2281 | I22: A | J22: 45 | K22: 2047 | L22: B | M22: 45 | N22: 1915 | O22: B | Q22: 1 | R22: BaseGame | S22: 45x | T22: = | U22: 350160 | V22: Pay | W22: = | X22: 1750800000 | Y22: 1C1 | Z22: = | AA22: null | AB22: 2C1 | AC22: = | AD22: 23402 | AE22: 3C1 | AF22: = | AG22: null | AH22: 4C1 | AI22: = | AJ22: null | AK22: 5C1 | AL22: = | AM22: null
A23: 50 | B23: 2327 | C23: A | D23: 50 | E23: 35 | F23: B | G23: 50 | H23: 55 | I23: B | J23: 50 | K23: 21 | L23: B | M23: 50 | N23: 2489 | O23: A | Q23: 1 | R23: BaseGame | S23: 50x | T23: = | U23: 160369 | V23: Pay | W23: = | X23: 864679400 | Y23: 1C1 | Z23: = | AA23: null | AB23: 2C1 | AC23: = | AD23: 61554 | AE23: 3C1 | AF23: = | AG23: null | AH23: 4C1 | AI23: = | AJ23: null | AK23: 5C1 | AL23: = | AM23: null
A24: 60 | B24: 1 | C24: B | D24: 60 | E24: 5 | F24: B | G24: 60 | H24: 1887 | I24: A | J24: 60 | K24: 1 | L24: B | M24: 60 | N24: 26 | O24: C | Q24: 1 | R24: BaseGame | S24: 90x | T24: = | U24: 6502 | V24: Pay | W24: = | X24: 65020000 | Y24: 1C1 | Z24: = | AA24: null | AB24: 2C1 | AC24: = | AD24: 759 | AE24: 3C1 | AF24: = | AG24: null | AH24: 4C1 | AI24: = | AJ24: null | AK24: 5C1 | AL24: = | AM24: null
... A26: 80 | B26: 0 | C26: A | D26: 80 | E26: 0 | F26: A | G26: 80 | H26: 0 | I26: A | J26: 80 | K26: 0 | L26: A | M26: 80 | N26: 0 | O26: A | Q26: 1 | R26: BaseGame | S26: 140x | T26: = | U26: 270 | V26: Pay | W26: = | X26: 4153200 | Y26: 1C1 | Z26: = | AA26: null | AB26: 2C1 | AC26: = | AD26: 270 | AE26: 3C1 | AF26: = | AG26: null | AH26: 4C1 | AI26: = | AJ26: null | AK26: 5C1 | AL26: = | AM26: null
A27: 90 | B27: 5 | C27: B | D27: 90 | E27: 17 | F27: B | G27: 90 | H27: 10 | I27: B | J27: 90 | K27: 13 | L27: B | M27: 90 | N27: 317 | O27: B | Q27: 1 | R27: BaseGame | S27: 450x | T27: = | U27: 504 | V27: Pay | W27: = | X27: 25200000 | Y27: 1C1 | Z27: = | AA27: null | AB27: 2C1 | AC27: = | AD27: null | AE27: 3C1 | AF27: = | AG27: null | AH27: 4C1 | AI27: = | AJ27: null | AK27: 5C1 | AL27: = | AM27: null
A28: 100 | B28: 87 | C28: B | D28: 100 | E28: 84 | F28: B | G28: 100 | H28: 55 | I28: B | J28: 100 | K28: 51 | L28: B | M28: 100 | N28: 83 | O28: B | Q28: 1 | R28: BaseGame | S28: 500x | T28: = | U28: 406 | V28: Pay | W28: = | X28: 20929000 | Y28: 1C1 | Z28: = | AA28: null | AB28: 2C1 | AC28: = | AD28: null | AE28: 3C1 | AF28: = | AG28: null | AH28: 4C1 | AI28: = | AJ28: null | AK28: 5C1 | AL28: = | AM28: null
A29: 120 | B29: 0 | C29: A | D29: 120 | E29: 8 | F29: B | G29: 120 | H29: 1 | I29: B | J29: 120 | K29: 260 | L29: B | M29: 120 | N29: 1 | O29: B
A30: 140 | B30: 244 | C30: B | D30: 140 | E30: 4 | F30: B | G30: 140 | H30: 83 | I30: B | J30: 140 | K30: 0 | L30: A | M30: 140 | N30: 2 | O30: B | Q30: 5 | R30: BaseGame | S30: 0x | T30: = | U30: 6522384 | V30: Pay | W30: = | X30: 2063871100 | Y30: 1C1 | Z30: = | AA30: null | AB30: 2C1 | AC30: = | AD30: 219258 | AE30: 3C1 | AF30: = | AG30: null | AH30: 4C1 | AI30: = | AJ30: null | AK30: 5C1 | AL30: = | AM30: null
A31: 160 | B31: 0 | C31: A | D31: 160 | E31: 0 | F31: A | G31: 160 | H31: 0 | I31: A | J31: 160 | K31: 0 | L31: A | M31: 160 | N31: 0 | O31: A | Q31: 5 | R31: BaseGame | S31: 1x | T31: = | U31: 206419 | V31: Pay | W31: = | X31: 198670600 | Y31: 1C1 | Z31: = | AA31: null | AB31: 2C1 | AC31: = | AD31: 38321 | AE31: 3C1 | AF31: = | AG31: null | AH31: 4C1 | AI31: = | AJ31: null | AK31: 5C1 | AL31: = | AM31: null
A32: 180 | B32: 1 | C32: B | D32: 180 | E32: 11 | F32: B | G32: 180 | H32: 4 | I32: B | J32: 180 | K32: 11 | L32: B | M32: 180 | N32: 7 | O32: B | Q32: 5 | R32: BaseGame | S32: 2x | T32: = | U32: 407222 | V32: Pay | W32: = | X32: 527238000 | Y32: 1C1 | Z32: = | AA32: null | AB32: 2C1 | AC32: = | AD32: 99848 | AE32: 3C1 | AF32: = | AG32: null | AH32: 4C1 | AI32: = | AJ32: null | AK32: 5C1 | AL32: = | AM32: null
A33: 200 | B33: 3 | C33: B | D33: 200 | E33: 12 | F33: B | G33: 200 | H33: 3 | I33: B | J33: 200 | K33: 29 | L33: B | M33: 200 | N33: 16 | O33: B | Q33: 5 | R33: BaseGame | S33: 4x | T33: = | U33: 2985734 | V33: Pay | W33: = | X33: 7245865400 | Y33: 1C1 | Z33: = | AA33: 363205 | AB33: 2C1 | AC33: = | AD33: 263153 | AE33: 3C1 | AF33: = | AG33: null | AH33: 4C1 | AI33: = | AJ33: null | AK33: 5C1 | AL33: = | AM33: null
A34: 250 | B34: 2 | C34: B | D34: 250 | E34: 3 | F34: B | G34: 250 | H34: 5 | I34: B | J34: 250 | K34: 0 | L34: A | M34: 250 | N34: 4 | O34: B | Q34: 5 | R34: BaseGame | S34: 5x | T34: = | U34: 103219 | V34: Pay | W34: = | X34: 298722600 | Y34: 1C1 | Z34: = | AA34: 43356 | AB34: 2C1 | AC34: = | AD34: 8339 | AE34: 3C1 | AF34: = | AG34: null | AH34: 4C1 | AI34: = | AJ34: null | AK34: 5C1 | AL34: = | AM34: null
A35: 300 | B35: 0 | C35: A | D35: 300 | E35: 3 | F35: B | G35: 300 | H35: 0 | I35: A | J35: 300 | K35: 0 | L35: A | M35: 300 | N35: 0 | O35: A | Q35: 5 | R35: BaseGame | S35: 9x | T35: = | U35: 501004 | V35: Pay | W35: = | X35: 2505020000 | Y35: 1C1 | Z35: = | AA35: 47452 | AB35: 2C1 | AC35: = | AD35: 24574 | AE35: 3C1 | AF35: = | AG35: null | AH35: 4C1 | AI35: = | AJ35: null | AK35: 5C1 | AL35: = | AM35: null
A36: 350 | B36: 0 | C36: A | D36: 350 | E36: 1 | F36: B | G36: 350 | H36: 0 | I36: A | J36: 350 | K36: 0 | L36: A | M36: 350 | N36: 0 | O36: A | Q36: 5 | R36: BaseGame | S36: 10x | T36: = | U36: 587768 | V36: Pay | W36: = | X36: 3342746500 | Y36: 1C1 | Z36: = | AA36: 76349 | AB36: 2C1 | AC36: = | AD36: 152306 | AE36: 3C1 | AF36: = | AG36: null | AH36: 4C1 | AI36: = | AJ36: null | AK36: 5C1 | AL36: = | AM36: null
A37: 400 | B37: 0 | C37: A | D37: 400 | E37: 9 | F37: B | G37: 400 | H37: 0 | I37: A | J37: 400 | K37: 3 | L37: B | M37: 400 | N37: 0 | O37: A | Q37: 5 | R37: BaseGame | S37: 15x | T37: = | U37: 287784 | V37: Pay | W37: = | X37: 2749054600 | Y37: 1C1 | Z37: = | AA37: 99877 | AB37: 2C1 | AC37: = | AD37: 13608 | AE37: 3C1 | AF37: = | AG37: null | AH37: 4C1 | AI37: = | AJ37: null | AK37: 5C1 | AL37: = | AM37: null
A38: 450 | B38: 5 | C38: B | D38: 450 | E38: 1 | F38: B | G38: 450 | H38: 1 | I38: B | J38: 450 | K38: 6 | L38: B | M38: 450 | N38: 2 | O38: B | Q38: 5 | R38: BaseGame | S38: 20x | T38: = | U38: 630529 | V38: Pay | W38: = | X38: 6688011700 | Y38: 1C1 | Z38: = | AA38: 73280 | AB38: 2C1 | AC38: = | AD38: 170391 | AE38: 3C1 | AF38: = | AG38: null | AH38: 4C1 | AI38: = | AJ38: null | AK38: 5C1 | AL38: = | AM38: null
A39: 500 | B39: 4 | C39: B | D39: 500 | E39: 3 | F39: B | G39: 500 | H39: 1 | I39: B | J39: 500 | K39: 5 | L39: B | M39: 500 | N39: 3 | O39: B | Q39: 5 | R39: BaseGame | S39: 25x | T39: = | U39: 169605 | V39: Pay | W39: = | X39: 2448682500 | Y39: 1C1 | Z39: = | AA39: 117947 | AB39: 2C1 | AC39: = | AD39: 13619 | AE39: 3C1 | AF39: = | AG39: null | AH39: 4C1 | AI39: = | AJ39: null | AK39: 5C1 | AL39: = | AM39: null
A40: 550 | B40: 0 | C40: A | D40: 550 | E40: 2 | F40: B | G40: 550 | H40: 1 | I40: B | J40: 550 | K40: 0 | L40: A | M40: 550 | N40: 1 | O40: B | Q40: 5 | R40: BaseGame | S40: 30x | T40: = | U40: 180614 | V40: Pay | W40: = | X40: 2813035200 | Y40: 1C1 | Z40: = | AA40: 85597 | AB40: 2C1 | AC40: = | AD40: 55187 | AE40: 3C1 | AF40: = | AG40: null | AH40: 4C1 | AI40: = | AJ40: null | AK40: 5C1 | AL40: = | AM40: null
A41: 600 | B41: 0 | C41: A | D41: 600 | E41: 0 | F41: A | G41: 600 | H41: 0 | I41: A | J41: 600 | K41: 0 | L41: A | M41: 600 | N41: 0 | O41: A | Q41: 5 | R41: BaseGame | S41: 45x | T41: = | U41: 569828 | V41: Pay | W41: = | X41: 14160106800 | Y41: 1C1 | Z41: = | AA41: 237721 | AB41: 2C1 | AC41: = | AD41: 3328 | AE41: 3C1 | AF41: = | AG41: null | AH41: 4C1 | AI41: = | AJ41: null | AK41: 5C1 | AL41: = | AM41: null
...

Sheet Card_Info_NoExtra_testB
A1: Bet 1 | D1: Bet 5 | G1: Bet 10 | J1: Bet 50 | M1: Bet 100 | R1: Simulation
A2: =Card_Bet1!$AF$1 -> 0.28665382 | D2: =Card_Bet5!$AF$1 -> 0.68318487 | G2: =Card_Bet10!$AF$1 -> 0.65349895 | J2: =Card_Bet50!$AF$1 -> 0.75172061 | M2: =Card_Bet100!$AF$1 -> 0.52646065
A3: Interval | B3: Weight | C3: Sheet | D3: Interval | E3: Weight | F3: Sheet | G3: Interval | H3: Weight | I3: Sheet | J3: Interval | K3: Weight | L3: Sheet | M3: Interval | N3: Weight | O3: Sheet | R3: Bet | S3: RTP | T3: Respin | U3: Scatter | V3: rounds | W3: Scatter+Respin | X3: Scatter+Respin PROB.
A4: {=Card_Bet1!$K$3:$K$54} -> -1 | B4: {=Card_Bet1!$AD$3:$AD$54} -> 870432 | C4: {=Card_Bet1!$L$3:$L$54} -> A | D4: {=Card_Bet5!$K$3:$K$54} -> -1 | E4: {=Card_Bet5!$AD$3:$AD$54} -> 871198 | F4: {=Card_Bet5!$L$3:$L$54} -> A | G4: {=Card_Bet10!$K$3:$K$54} -> -1 | H4: {=Card_Bet10!$AD$3:$AD$54} -> 871188 | I4: {=Card_Bet10!$L$3:$L$54} -> A | J4: {=Card_Bet50!$K$3:$K$54} -> -1 | K4: {=Card_Bet50!$AD$3:$AD$54} -> 863135 | L4: {=Card_Bet50!$L$3:$L$54} -> A | M4: {=Card_Bet100!$K$3:$K$54} -> -1 | N4: {=Card_Bet100!$AD$3:$AD$54} -> 892770 | O4: {=Card_Bet100!$L$3:$L$54} -> A | R4: 1 | S4: 0.924421 | T4: 0.122159 | U4: - | V4: 100000000 | W4: =SUM(AA13:AA28,AD13:AD28) -> 0 | X4: =W4/V4 -> 0
A5: 0 | B5: 65000 | C5: A | D5: 0 | E5: 65255 | F5: A | G5: 0 | H5: 24707 | I5: A | J5: 0 | K5: 49753 | L5: A | M5: 0 | N5: 300 | O5: A | R5: 5 | S5: 0.925082 | T5: 0.06123 | U5: 0.224109 | V5: 100000000 | W5: =SUM(AA30:AA48,AD30:AD48) -> 0 | X5: =W5/V5 -> 0
A6: 1 | B6: 1000 | C6: B | D6: 1 | E6: 2054 | F6: A | G6: 1 | H6: 39300 | I6: A | J6: 1 | K6: 15839 | L6: A | M6: 1 | N6: 26494 | O6: A | R6: 10 | S6: 0.925132 | T6: 0.081793 | U6: 0.16207 | V6: 300000000 | W6: =SUM(AA50:AA67,AD50:AD67) -> 0 | X6: =W6/V6 -> 0
A7: 2 | B7: 0 | C7: A | D7: 2 | E7: 300 | F7: A | G7: 2 | H7: 333 | I7: B | J7: 2 | K7: 2988 | L7: A | M7: 2 | N7: 629 | O7: A | R7: 50 | S7: 0.925361 | T7: 0.049855 | U7: 0.337065 | V7: 100000000 | W7: =SUM(AA50:AA67,AD50:AD67) -> 0 | X7: =W7/V7 -> 0
A8: 3 | B8: 0 | C8: A | D8: 3 | E8: 0 | F8: B | G8: 3 | H8: 0 | I8: A | J8: 3 | K8: 812 | L8: B | M8: 3 | N8: 0 | O8: A | R8: 100 | S8: 0.924687 | T8: 0.131463 | U8: 0.220799 | V8: 100000000 | W8: =SUM(AA84:AA102,AD84:AD102) -> 0 | X8: =W8/V8 -> 0
A9: 4 | B9: 32000 | C9: A | D9: 4 | E9: 31700 | F9: A | G9: 4 | H9: 15365 | I9: A | J9: 4 | K9: 30000 | L9: A | M9: 4 | N9: 50000 | O9: A
A10: 5 | B10: 0 | C10: B | D10: 5 | E10: 0 | F10: A | G10: 5 | H10: 18320 | I10: A | J10: 5 | K10: 993 | L10: B | M10: 5 | N10: 500 | O10: A
A11: 6 | B11: 0 | C11: A | D11: 6 | E11: 0 | F11: B | G11: 6 | H11: 70 | I11: B | J11: 6 | K11: 0 | L11: B | M11: 6 | N11: 30 | O11: B
A12: 7 | B12: 0 | C12: A | D12: 7 | E12: 0 | F12: B | G12: 7 | H12: 0 | I12: B | J12: 7 | K12: 0 | L12: A | M12: 7 | N12: 0 | O12: B
A13: 8 | B13: 0 | C13: A | D13: 8 | E13: 0 | F13: A | G13: 8 | H13: 0 | I13: A | J13: 8 | K13: 0 | L13: A | M13: 8 | N13: 0 | O13: A
A14: 9 | B14: 10000 | C14: A | D14: 9 | E14: 10000 | F14: A | G14: 9 | H14: 4515 | I14: A | J14: 9 | K14: 10000 | L14: A | M14: 9 | N14: 10630 | O14: A
A15: 10 | B15: 3000 | C15: A | D15: 10 | E15: 300 | F15: A | G15: 10 | H15: 9523 | I15: A | J15: 10 | K15: 6500 | L15: A | M15: 10 | N15: 300 | O15: A
A16: 15 | B16: 10000 | C16: A | D16: 15 | E16: 10000 | F16: A | G16: 15 | H16: 4912 | I16: A | J16: 15 | K16: 7400 | L16: A | M16: 15 | N16: 10000 | O16: A
A17: 20 | B17: 3000 | C17: A | D17: 20 | E17: 300 | F17: A | G17: 20 | H17: 4400 | I17: A | J17: 20 | K17: 5000 | L17: A | M17: 20 | N17: 3000 | O17: A
A18: 25 | B18: 100 | C18: B | D18: 25 | E18: 1600 | F18: B | G18: 25 | H18: 1838 | I18: A | J18: 25 | K18: 3000 | L18: B | M18: 25 | N18: 100 | O18: B
A19: 30 | B19: 0 | C19: A | D19: 30 | E19: 100 | F19: A | G19: 30 | H19: 0 | I19: B | J19: 30 | K19: 100 | L19: A | M19: 30 | N19: 250 | O19: B
A20: 35 | B20: 0 | C20: A | D20: 35 | E20: 0 | F20: B | G20: 35 | H20: 0 | I20: B | J20: 35 | K20: 300 | L20: B | M20: 35 | N20: 180 | O20: C
... A55: 7000 | B55: 0 | C55: A | D55: 7000 | E55: 0 | F55: A | G55: 7000 | H55: 0 | I55: A | J55: 7000 | K55: 0 | L55: A | M55: 7000 | N55: 0 | O55: B

Sheet Card_Bet1
C1: Hit% | F1: Mul | R1: =SUM(R3:R54) -> 0.33112245 | V1: =SUM(V3:V54) -> 0.42607907 | AB1: =SUM(AB3:AB54) -> 0.2866455 | AF1: =SUM(AF3:AF54) -> 0.28665382
B2: Interval | C2: A | D2: B | E2: C | F2: A | G2: B | H2: C | J2: Index | K2: Interval | L2: Sheet | M2: Mul Prob. | N2: Avg Mul | O2: Hit%_tune | P2: Hit%_ori | Q2: Jili Hit% | R2: RTP_tune | T2: Hit%_Weight_Final | U2: Hit%_Final | V2: RTP_Final | Y2: Hit%_tune | Z2: Hit%_ori | AA2: Jili Hit% | AB2: RTP_tune | AD2: Hit%_Weight_Final | AE2: Hit%_Final | AF2: RTP_Final
B3: -1 | C3: {=_xlfn.IFNA( _xlfn._xlws.FILTER( Sim_Mul_Bet1!$H$3:$H$48, (Sim_Mul_Bet1!$A$3:$A$48=C$2) * (Sim_Mul_Bet1!$C$3:$C$48=$B3),0 ), 0 )} -> 0 | D3: {=_xlfn.IFNA( _xlfn._xlws.FILTER( Sim_Mul_Bet1!$H$3:$H$48, (Sim_Mul_Bet1!$A$3:$A$48=D$2) * (Sim_Mul_Bet1!$C$3:$C$48=$B3),0 ), 0 )} -> 0.2776551 | G3: {=_xlfn.IFNA( _xlfn._xlws.FILTER( Sim_Mul_Bet1!$O$3:$O$48, (Sim_Mul_Bet1!$A$3:$A$48=D$2) * (Sim_Mul_Bet1!$C$3:$C$48=$B3),0 ), 0 )} -> 0 | J3: 0 | K3: -1 | L3: A | M3: =HLOOKUP(L3,$C$2:$E$54,J3+2,FALSE) -> 0 | N3: =HLOOKUP(L3,$F$2:$H$54,J3+2,FALSE) -> 0 | O3: =1-SUM(O4:O53) -> 0.86211727 | P3: =1-SUM(P4:P53) -> 0.86206787 | Q3: =1-SUM(Q4:Q54) -> 0.85905995 | R3: =N3*O3 -> 0 | S3: {=Q3:Q54=P3:P54} -> FALSE | T3: =1000000-SUM(T4:T54) -> 856097 | U3: {=T3:T54/SUM($T$3:$T$54)} -> 0.856097 | V3: =U3*N3 -> 0 | Y3: =1-SUM(Y4:Y53) -> 0.87043205 | Z3: =1-SUM(Z4:Z53) -> 0.87043205 | AA3: =1-SUM(AA4:AA54) -> 0.85905995 | AB3: =N3*Y3 -> 0 | AD3: =1000000-SUM(AD4:AD54) -> 870432 | AE3: {=AD3:AD54/SUM($T$3:$T$54)} -> 0.870432 | AF3: =AE3*N3 -> 0
B4: 0 | C4: {=_xlfn.IFNA( _xlfn._xlws.FILTER( Sim_Mul_Bet1!$H$3:$H$48, (Sim_Mul_Bet1!$A$3:$A$48=C$2) * (Sim_Mul_Bet1!$C$3:$C$48=$B4),0 ), 0 )} -> 0.87009169 | D4: {=_xlfn.IFNA( _xlfn._xlws.FILTER( Sim_Mul_Bet1!$H$3:$H$48, (Sim_Mul_Bet1!$A$3:$A$48=D$2) * (Sim_Mul_Bet1!$C$3:$C$48=$B4),0 ), 0 )} -> 0.09718529 | E4: {=_xlfn.IFNA( _xlfn._xlws.FILTER( Sim_Mul_Bet1!$H$3:$H$48, (Sim_Mul_Bet1!$A$3:$A$48=E$2) * (Sim_Mul_Bet1!$C$3:$C$48=$B4),0 ), 0 )} -> 0 | F4: {=_xlfn.IFNA( _xlfn._xlws.FILTER( Sim_Mul_Bet1!$O$3:$O$48, (Sim_Mul_Bet1!$A$3:$A$48=C$2) * (Sim_Mul_Bet1!$C$3:$C$48=$B4),0 ), 0 )} -> 0 | G4: {=_xlfn.IFNA( _xlfn._xlws.FILTER( Sim_Mul_Bet1!$O$3:$O$48, (Sim_Mul_Bet1!$A$3:$A$48=D$2) * (Sim_Mul_Bet1!$C$3:$C$48=$B4),0 ), 0 )} -> 1 | H4: {=_xlfn.IFNA( _xlfn._xlws.FILTER( Sim_Mul_Bet1!$O$3:$O$48, (Sim_Mul_Bet1!$A$3:$A$48=E$2) * (Sim_Mul_Bet1!$C$3:$C$48=$B4),0 ), 0 )} -> 0 | J4: 1 | K4: 0 | L4: A | M4: =HLOOKUP(L4,$C$2:$E$54,J4+2,FALSE) -> 0.87009169 | N4: =HLOOKUP(L4,$F$2:$H$54,J4+2,FALSE) -> 0 | O4: 0.065046727 | P4: 0.065046727 | Q4: 0.065046727 | R4: =N4*O4 -> 0 | S4: TRUE | T4: 87908 | U4: 0.087908 | V4: =U4*N4 -> 0 | Y4: =Z4 -> 0.065 | Z4: 0.065 | AA4: 0.065046727 | AB4: =N4*Y4 -> 0 | AD4: =ROUND(Y4*1000000,0) -> 65000 | AE4: 0.065 | AF4: =AE4*N4 -> 0
B5: 1 | C5: {=_xlfn.IFNA( _xlfn._xlws.FILTER( Sim_Mul_Bet1!$H$3:$H$48, (Sim_Mul_Bet1!$A$3:$A$48=C$2) * (Sim_Mul_Bet1!$C$3:$C$48=$B5),0 ), 0 )} -> 0.04525812 | D5: {=_xlfn.IFNA( _xlfn._xlws.FILTER( Sim_Mul_Bet1!$H$3:$H$48, (Sim_Mul_Bet1!$A$3:$A$48=D$2) * (Sim_Mul_Bet1!$C$3:$C$48=$B5),0 ), 0 )} -> 0.03470722 | E5: {=_xlfn.IFNA( _xlfn._xlws.FILTER( Sim_Mul_Bet1!$H$3:$H$48, (Sim_Mul_Bet1!$A$3:$A$48=E$2) * (Sim_Mul_Bet1!$C$3:$C$48=$B5),0 ), 0 )} -> 0 | F5: {=_xlfn.IFNA( _xlfn._xlws.FILTER( Sim_Mul_Bet1!$O$3:$O$48, (Sim_Mul_Bet1!$A$3:$A$48=C$2) * (Sim_Mul_Bet1!$C$3:$C$48=$B5),0 ), 0 )} -> 1 | G5: {=_xlfn.IFNA( _xlfn._xlws.FILTER( Sim_Mul_Bet1!$O$3:$O$48, (Sim_Mul_Bet1!$A$3:$A$48=D$2) * (Sim_Mul_Bet1!$C$3:$C$48=$B5),0 ), 0 )} -> 2 | H5: {=_xlfn.IFNA( _xlfn._xlws.FILTER( Sim_Mul_Bet1!$O$3:$O$48, (Sim_Mul_Bet1!$A$3:$A$48=E$2) * (Sim_Mul_Bet1!$C$3:$C$48=$B5),0 ), 0 )} -> 0 | J5: 2 | K5: 1 | L5: B | M5: =HLOOKUP(L5,$C$2:$E$54,J5+2,FALSE) -> 0.03470722 | N5: =HLOOKUP(L5,$F$2:$H$54,J5+2,FALSE) -> 2 | O5: 0.0010155134 | P5: 0.0010155134 | Q5: 0.0010155134 | R5: =N5*O5 -> 0.0020310268 | S5: TRUE | T5: 1029 | U5: 0.001029 | V5: =U5*N5 -> 0.002058 | Y5: =Z5 -> 0.001 | Z5: 0.001 | AA5: 0.0010155134 | AB5: =N5*Y5 -> 0.002 | AD5: =ROUND(Y5*1000000,0) -> 1000 | AE5: 0.001 | AF5: =AE5*N5 -> 0.002
B6: 2 | C6: {=_xlfn.IFNA( _xlfn._xlws.FILTER( Sim_Mul_Bet1!$H$3:$H$48, (Sim_Mul_Bet1!$A$3:$A$48=C$2) * (Sim_Mul_Bet1!$C$3:$C$48=$B6),0 ), 0 )} -> 0.00138889 | D6: {=_xlfn.IFNA( _xlfn._xlws.FILTER( Sim_Mul_Bet1!$H$3:$H$48, (Sim_Mul_Bet1!$A$3:$A$48=D$2) * (Sim_Mul_Bet1!$C$3:$C$48=$B6),0 ), 0 )} -> 0 | E6: {=_xlfn.IFNA( _xlfn._xlws.FILTER( Sim_Mul_Bet1!$H$3:$H$48, (Sim_Mul_Bet1!$A$3:$A$48=E$2) * (Sim_Mul_Bet1!$C$3:$C$48=$B6),0 ), 0 )} -> 0 | F6: {=_xlfn.IFNA( _xlfn._xlws.FILTER( Sim_Mul_Bet1!$O$3:$O$48, (Sim_Mul_Bet1!$A$3:$A$48=C$2) * (Sim_Mul_Bet1!$C$3:$C$48=$B6),0 ), 0 )} -> 2 | G6: {=_xlfn.IFNA( _xlfn._xlws.FILTER( Sim_Mul_Bet1!$O$3:$O$48, (Sim_Mul_Bet1!$A$3:$A$48=D$2) * (Sim_Mul_Bet1!$C$3:$C$48=$B6),0 ), 0 )} -> 0 | H6: {=_xlfn.IFNA( _xlfn._xlws.FILTER( Sim_Mul_Bet1!$O$3:$O$48, (Sim_Mul_Bet1!$A$3:$A$48=E$2) * (Sim_Mul_Bet1!$C$3:$C$48=$B6),0 ), 0 )} -> 0 | J6: 3 | K6: 2 | L6: A | M6: =HLOOKUP(L6,$C$2:$E$54,J6+2,FALSE) -> 0.00138889 | N6: =HLOOKUP(L6,$F$2:$H$54,J6+2,FALSE) -> 2 | O6: 0 | P6: 0 | Q6: 0 | R6: =N6*O6 -> 0 | S6: TRUE | T6: 0 | U6: 0 | V6: =U6*N6 -> 0 | Y6: =Z6 -> 0 | Z6: 0 | AA6: 0 | AB6: =N6*Y6 -> 0 | AD6: =ROUND(Y6*1000000,0) -> 0 | AE6: 0 | AF6: =AE6*N6 -> 0
B7: 3 | C7: {=_xlfn.IFNA( _xlfn._xlws.FILTER( Sim_Mul_Bet1!$H$3:$H$48, (Sim_Mul_Bet1!$A$3:$A$48=C$2) * (Sim_Mul_Bet1!$C$3:$C$48=$B7),0 ), 0 )} -> 0 | D7: {=_xlfn.IFNA( _xlfn._xlws.FILTER( Sim_Mul_Bet1!$H$3:$H$48, (Sim_Mul_Bet1!$A$3:$A$48=D$2) * (Sim_Mul_Bet1!$C$3:$C$48=$B7),0 ), 0 )} -> 0 | E7: {=_xlfn.IFNA( _xlfn._xlws.FILTER( Sim_Mul_Bet1!$H$3:$H$48, (Sim_Mul_Bet1!$A$3:$A$48=E$2) * (Sim_Mul_Bet1!$C$3:$C$48=$B7),0 ), 0 )} -> 0 | F7: {=_xlfn.IFNA( _xlfn._xlws.FILTER( Sim_Mul_Bet1!$O$3:$O$48, (Sim_Mul_Bet1!$A$3:$A$48=C$2) * (Sim_Mul_Bet1!$C$3:$C$48=$B7),0 ), 0 )} -> 0 | G7: {=_xlfn.IFNA( _xlfn._xlws.FILTER( Sim_Mul_Bet1!$O$3:$O$48, (Sim_Mul_Bet1!$A$3:$A$48=D$2) * (Sim_Mul_Bet1!$C$3:$C$48=$B7),0 ), 0 )} -> 0 | H7: {=_xlfn.IFNA( _xlfn._xlws.FILTER( Sim_Mul_Bet1!$O$3:$O$48, (Sim_Mul_Bet1!$A$3:$A$48=E$2) * (Sim_Mul_Bet1!$C$3:$C$48=$B7),0 ), 0 )} -> 0 | J7: 4 | K7: 3 | L7: A | M7: =HLOOKUP(L7,$C$2:$E$54,J7+2,FALSE) -> 0 | N7: =HLOOKUP(L7,$F$2:$H$54,J7+2,FALSE) -> 0 | O7: 0 | P7: 0 | Q7: 0 | R7: =N7*O7 -> 0 | S7: TRUE | T7: 0 | U7: 0 | V7: =U7*N7 -> 0 | Y7: =Z7 -> 0 | Z7: 0 | AA7: 0 | AB7: =N7*Y7 -> 0 | AD7: =ROUND(Y7*1000000,0) -> 0 | AE7: 0 | AF7: =AE7*N7 -> 0
B8: 4 | C8: {=_xlfn.IFNA( _xlfn._xlws.FILTER( Sim_Mul_Bet1!$H$3:$H$48, (Sim_Mul_Bet1!$A$3:$A$48=C$2) * (Sim_Mul_Bet1!$C$3:$C$48=$B8),0 ), 0 )} -> 0 | D8: {=_xlfn.IFNA( _xlfn._xlws.FILTER( Sim_Mul_Bet1!$H$3:$H$48, (Sim_Mul_Bet1!$A$3:$A$48=D$2) * (Sim_Mul_Bet1!$C$3:$C$48=$B8),0 ), 0 )} -> 0.12505433 | E8: {=_xlfn.IFNA( _xlfn._xlws.FILTER( Sim_Mul_Bet1!$H$3:$H$48, (Sim_Mul_Bet1!$A$3:$A$48=E$2) * (Sim_Mul_Bet1!$C$3:$C$48=$B8),0 ), 0 )} -> 0 | F8: {=_xlfn.IFNA( _xlfn._xlws.FILTER( Sim_Mul_Bet1!$O$3:$O$48, (Sim_Mul_Bet1!$A$3:$A$48=C$2) * (Sim_Mul_Bet1!$C$3:$C$48=$B8),0 ), 0 )} -> 0 | G8: {=_xlfn.IFNA( _xlfn._xlws.FILTER( Sim_Mul_Bet1!$O$3:$O$48, (Sim_Mul_Bet1!$A$3:$A$48=D$2) * (Sim_Mul_Bet1!$C$3:$C$48=$B8),0 ), 0 )} -> 5 | H8: {=_xlfn.IFNA( _xlfn._xlws.FILTER( Sim_Mul_Bet1!$O$3:$O$48, (Sim_Mul_Bet1!$A$3:$A$48=E$2) * (Sim_Mul_Bet1!$C$3:$C$48=$B8),0 ), 0 )} -> 0 | J8: 5 | K8: 4 | L8: A | M8: =HLOOKUP(L8,$C$2:$E$54,J8+2,FALSE) -> 0 | N8: =HLOOKUP(L8,$F$2:$H$54,J8+2,FALSE) -> 0 | O8: 0.042829583 | P8: 0.042829583 | Q8: 0.042829583 | R8: =N8*O8 -> 0 | S8: TRUE | T8: 25990 | U8: 0.02599 | V8: =U8*N8 -> 0 | Y8: =Z8 -> 0.032 | Z8: 0.032 | AA8: 0.042829583 | AB8: =N8*Y8 -> 0 | AD8: =ROUND(Y8*1000000,0) -> 32000 | AE8: 0.032 | AF8: =AE8*N8 -> 0
B9: 5 | C9: {=_xlfn.IFNA( _xlfn._xlws.FILTER( Sim_Mul_Bet1!$H$3:$H$48, (Sim_Mul_Bet1!$A$3:$A$48=C$2) * (Sim_Mul_Bet1!$C$3:$C$48=$B9),0 ), 0 )} -> 0.05049721 | D9: {=_xlfn.IFNA( _xlfn._xlws.FILTER( Sim_Mul_Bet1!$H$3:$H$48, (Sim_Mul_Bet1!$A$3:$A$48=D$2) * (Sim_Mul_Bet1!$C$3:$C$48=$B9),0 ), 0 )} -> 0.01388947 | E9: {=_xlfn.IFNA( _xlfn._xlws.FILTER( Sim_Mul_Bet1!$H$3:$H$48, (Sim_Mul_Bet1!$A$3:$A$48=E$2) * (Sim_Mul_Bet1!$C$3:$C$48=$B9),0 ), 0 )} -> 0 | F9: {=_xlfn.IFNA( _xlfn._xlws.FILTER( Sim_Mul_Bet1!$O$3:$O$48, (Sim_Mul_Bet1!$A$3:$A$48=C$2) * (Sim_Mul_Bet1!$C$3:$C$48=$B9),0 ), 0 )} -> 5 | G9: {=_xlfn.IFNA( _xlfn._xlws.FILTER( Sim_Mul_Bet1!$O$3:$O$48, (Sim_Mul_Bet1!$A$3:$A$48=D$2) * (Sim_Mul_Bet1!$C$3:$C$48=$B9),0 ), 0 )} -> 6 | H9: {=_xlfn.IFNA( _xlfn._xlws.FILTER( Sim_Mul_Bet1!$O$3:$O$48, (Sim_Mul_Bet1!$A$3:$A$48=E$2) * (Sim_Mul_Bet1!$C$3:$C$48=$B9),0 ), 0 )} -> 0 | J9: 6 | K9: 5 | L9: B | M9: =HLOOKUP(L9,$C$2:$E$54,J9+2,FALSE) -> 0.01388947 | N9: =HLOOKUP(L9,$F$2:$H$54,J9+2,FALSE) -> 6 | O9: 0.0011527108 | P9: 0.0011527108 | Q9: 0.0011527108 | R9: =N9*O9 -> 0.006916265 | S9: TRUE | T9: 196 | U9: 0.000196 | V9: =U9*N9 -> 0.001176 | Y9: =Z9 -> 0 | Z9: 0 | AA9: 0.0011527108 | AB9: =N9*Y9 -> 0 | AD9: =ROUND(Y9*1000000,0) -> 0 | AE9: 0 | AF9: =AE9*N9 -> 0
B10: 6 | C10: {=_xlfn.IFNA( _xlfn._xlws.FILTER( Sim_Mul_Bet1!$H$3:$H$48, (Sim_Mul_Bet1!$A$3:$A$48=C$2) * (Sim_Mul_Bet1!$C$3:$C$48=$B10),0 ), 0 )} -> 2.457e-05 | D10: {=_xlfn.IFNA( _xlfn._xlws.FILTER( Sim_Mul_Bet1!$H$3:$H$48, (Sim_Mul_Bet1!$A$3:$A$48=D$2) * (Sim_Mul_Bet1!$C$3:$C$48=$B10),0 ), 0 )} -> 0 | E10: {=_xlfn.IFNA( _xlfn._xlws.FILTER( Sim_Mul_Bet1!$H$3:$H$48, (Sim_Mul_Bet1!$A$3:$A$48=E$2) * (Sim_Mul_Bet1!$C$3:$C$48=$B10),0 ), 0 )} -> 0 | F10: {=_xlfn.IFNA( _xlfn._xlws.FILTER( Sim_Mul_Bet1!$O$3:$O$48, (Sim_Mul_Bet1!$A$3:$A$48=C$2) * (Sim_Mul_Bet1!$C$3:$C$48=$B10),0 ), 0 )} -> 6 | G10: {=_xlfn.IFNA( _xlfn._xlws.FILTER( Sim_Mul_Bet1!$O$3:$O$48, (Sim_Mul_Bet1!$A$3:$A$48=D$2) * (Sim_Mul_Bet1!$C$3:$C$48=$B10),0 ), 0 )} -> 0 | H10: {=_xlfn.IFNA( _xlfn._xlws.FILTER( Sim_Mul_Bet1!$O$3:$O$48, (Sim_Mul_Bet1!$A$3:$A$48=E$2) * (Sim_Mul_Bet1!$C$3:$C$48=$B10),0 ), 0 )} -> 0 | J10: 7 | K10: 6 | L10: A | M10: =HLOOKUP(L10,$C$2:$E$54,J10+2,FALSE) -> 2.457e-05 | N10: =HLOOKUP(L10,$F$2:$H$54,J10+2,FALSE) -> 6 | O10: 0 | P10: 0 | Q10: 0 | R10: =N10*O10 -> 0 | S10: TRUE | T10: 0 | U10: 0 | V10: =U10*N10 -> 0 | Y10: =Z10 -> 0 | Z10: 0 | AA10: 0 | AB10: =N10*Y10 -> 0 | AD10: =ROUND(Y10*1000000,0) -> 0 | AE10: 0 | AF10: =AE10*N10 -> 0
B11: 7 | C11: {=_xlfn.IFNA( _xlfn._xlws.FILTER( Sim_Mul_Bet1!$H$3:$H$48, (Sim_Mul_Bet1!$A$3:$A$48=C$2) * (Sim_Mul_Bet1!$C$3:$C$48=$B11),0 ), 0 )} -> 0 | D11: {=_xlfn.IFNA( _xlfn._xlws.FILTER( Sim_Mul_Bet1!$H$3:$H$48, (Sim_Mul_Bet1!$A$3:$A$48=D$2) * (Sim_Mul_Bet1!$C$3:$C$48=$B11),0 ), 0 )} -> 0 | E11: {=_xlfn.IFNA( _xlfn._xlws.FILTER( Sim_Mul_Bet1!$H$3:$H$48, (Sim_Mul_Bet1!$A$3:$A$48=E$2) * (Sim_Mul_Bet1!$C$3:$C$48=$B11),0 ), 0 )} -> 0 | F11: {=_xlfn.IFNA( _xlfn._xlws.FILTER( Sim_Mul_Bet1!$O$3:$O$48, (Sim_Mul_Bet1!$A$3:$A$48=C$2) * (Sim_Mul_Bet1!$C$3:$C$48=$B11),0 ), 0 )} -> 0 | G11: {=_xlfn.IFNA( _xlfn._xlws.FILTER( Sim_Mul_Bet1!$O$3:$O$48, (Sim_Mul_Bet1!$A$3:$A$48=D$2) * (Sim_Mul_Bet1!$C$3:$C$48=$B11),0 ), 0 )} -> 0 | H11: {=_xlfn.IFNA( _xlfn._xlws.FILTER( Sim_Mul_Bet1!$O$3:$O$48, (Sim_Mul_Bet1!$A$3:$A$48=E$2) * (Sim_Mul_Bet1!$C$3:$C$48=$B11),0 ), 0 )} -> 0 | J11: 8 | K11: 7 | L11: A | M11: =HLOOKUP(L11,$C$2:$E$54,J11+2,FALSE) -> 0 | N11: =HLOOKUP(L11,$F$2:$H$54,J11+2,FALSE) -> 0 | O11: 0 | P11: 0 | Q11: 0 | R11: =N11*O11 -> 0 | S11: TRUE | T11: 0 | U11: 0 | V11: =U11*N11 -> 0 | Y11: =Z11 -> 0 | Z11: 0 | AA11: 0 | AB11: =N11*Y11 -> 0 | AD11: =ROUND(Y11*1000000,0) -> 0 | AE11: 0 | AF11: =AE11*N11 -> 0
B12: 8 | C12: {=_xlfn.IFNA( _xlfn._xlws.FILTER( Sim_Mul_Bet1!$H$3:$H$48, (Sim_Mul_Bet1!$A$3:$A$48=C$2) * (Sim_Mul_Bet1!$C$3:$C$48=$B12),0 ), 0 )} -> 0 | D12: {=_xlfn.IFNA( _xlfn._xlws.FILTER( Sim_Mul_Bet1!$H$3:$H$48, (Sim_Mul_Bet1!$A$3:$A$48=D$2) * (Sim_Mul_Bet1!$C$3:$C$48=$B12),0 ), 0 )} -> 0 | E12: {=_xlfn.IFNA( _xlfn._xlws.FILTER( Sim_Mul_Bet1!$H$3:$H$48, (Sim_Mul_Bet1!$A$3:$A$48=E$2) * (Sim_Mul_Bet1!$C$3:$C$48=$B12),0 ), 0 )} -> 0 | F12: {=_xlfn.IFNA( _xlfn._xlws.FILTER( Sim_Mul_Bet1!$O$3:$O$48, (Sim_Mul_Bet1!$A$3:$A$48=C$2) * (Sim_Mul_Bet1!$C$3:$C$48=$B12),0 ), 0 )} -> 0 | G12: {=_xlfn.IFNA( _xlfn._xlws.FILTER( Sim_Mul_Bet1!$O$3:$O$48, (Sim_Mul_Bet1!$A$3:$A$48=D$2) * (Sim_Mul_Bet1!$C$3:$C$48=$B12),0 ), 0 )} -> 0 | H12: {=_xlfn.IFNA( _xlfn._xlws.FILTER( Sim_Mul_Bet1!$O$3:$O$48, (Sim_Mul_Bet1!$A$3:$A$48=E$2) * (Sim_Mul_Bet1!$C$3:$C$48=$B12),0 ), 0 )} -> 0 | J12: 9 | K12: 8 | L12: A | M12: =HLOOKUP(L12,$C$2:$E$54,J12+2,FALSE) -> 0 | N12: =HLOOKUP(L12,$F$2:$H$54,J12+2,FALSE) -> 0 | O12: 0 | P12: 0 | Q12: 0 | R12: =N12*O12 -> 0 | S12: TRUE | T12: 0 | U12: 0 | V12: =U12*N12 -> 0 | Y12: =Z12 -> 0 | Z12: 0 | AA12: 0 | AB12: =N12*Y12 -> 0 | AD12: =ROUND(Y12*1000000,0) -> 0 | AE12: 0 | AF12: =AE12*N12 -> 0
B13: 9 | C13: {=_xlfn.IFNA( _xlfn._xlws.FILTER( Sim_Mul_Bet1!$H$3:$H$48, (Sim_Mul_Bet1!$A$3:$A$48=C$2) * (Sim_Mul_Bet1!$C$3:$C$48=$B13),0 ), 0 )} -> 0 | D13: {=_xlfn.IFNA( _xlfn._xlws.FILTER( Sim_Mul_Bet1!$H$3:$H$48, (Sim_Mul_Bet1!$A$3:$A$48=D$2) * (Sim_Mul_Bet1!$C$3:$C$48=$B13),0 ), 0 )} -> 0.09957442 | E13: {=_xlfn.IFNA( _xlfn._xlws.FILTER( Sim_Mul_Bet1!$H$3:$H$48, (Sim_Mul_Bet1!$A$3:$A$48=E$2) * (Sim_Mul_Bet1!$C$3:$C$48=$B13),0 ), 0 )} -> 0 | F13: {=_xlfn.IFNA( _xlfn._xlws.FILTER( Sim_Mul_Bet1!$O$3:$O$48, (Sim_Mul_Bet1!$A$3:$A$48=C$2) * (Sim_Mul_Bet1!$C$3:$C$48=$B13),0 ), 0 )} -> 0 | G13: {=_xlfn.IFNA( _xlfn._xlws.FILTER( Sim_Mul_Bet1!$O$3:$O$48, (Sim_Mul_Bet1!$A$3:$A$48=D$2) * (Sim_Mul_Bet1!$C$3:$C$48=$B13),0 ), 0 )} -> 10 | H13: {=_xlfn.IFNA( _xlfn._xlws.FILTER( Sim_Mul_Bet1!$O$3:$O$48, (Sim_Mul_Bet1!$A$3:$A$48=E$2) * (Sim_Mul_Bet1!$C$3:$C$48=$B13),0 ), 0 )} -> 0 | J13: 10 | K13: 9 | L13: A | M13: =HLOOKUP(L13,$C$2:$E$54,J13+2,FALSE) -> 0 | N13: =HLOOKUP(L13,$F$2:$H$54,J13+2,FALSE) -> 0 | O13: 0.0084216489 | P13: 0.0084216489 | Q13: 0.0084216489 | R13: =N13*O13 -> 0 | S13: TRUE | T13: 6515 | U13: 0.006515 | V13: =U13*N13 -> 0 | Y13: =Z13 -> 0.01 | Z13: 0.01 | AA13: 0.0084216489 | AB13: =N13*Y13 -> 0 | AD13: =ROUND(Y13*1000000,0) -> 10000 | AE13: 0.01 | AF13: =AE13*N13 -> 0
B14: 10 | C14: {=_xlfn.IFNA( _xlfn._xlws.FILTER( Sim_Mul_Bet1!$H$3:$H$48, (Sim_Mul_Bet1!$A$3:$A$48=C$2) * (Sim_Mul_Bet1!$C$3:$C$48=$B14),0 ), 0 )} -> 0.01949318 | D14: {=_xlfn.IFNA( _xlfn._xlws.FILTER( Sim_Mul_Bet1!$H$3:$H$48, (Sim_Mul_Bet1!$A$3:$A$48=D$2) * (Sim_Mul_Bet1!$C$3:$C$48=$B14),0 ), 0 )} -> 0.0532554 | E14: {=_xlfn.IFNA( _xlfn._xlws.FILTER( Sim_Mul_Bet1!$H$3:$H$48, (Sim_Mul_Bet1!$A$3:$A$48=E$2) * (Sim_Mul_Bet1!$C$3:$C$48=$B14),0 ), 0 )} -> 0 | F14: {=_xlfn.IFNA( _xlfn._xlws.FILTER( Sim_Mul_Bet1!$O$3:$O$48, (Sim_Mul_Bet1!$A$3:$A$48=C$2) * (Sim_Mul_Bet1!$C$3:$C$48=$B14),0 ), 0 )} -> 10.263407 | G14: {=_xlfn.IFNA( _xlfn._xlws.FILTER( Sim_Mul_Bet1!$O$3:$O$48, (Sim_Mul_Bet1!$A$3:$A$48=D$2) * (Sim_Mul_Bet1!$C$3:$C$48=$B14),0 ), 0 )} -> 12.956681 | H14: {=_xlfn.IFNA( _xlfn._xlws.FILTER( Sim_Mul_Bet1!$O$3:$O$48, (Sim_Mul_Bet1!$A$3:$A$48=E$2) * (Sim_Mul_Bet1!$C$3:$C$48=$B14),0 ), 0 )} -> 0 | J14: 11 | K14: 10 | L14: A | M14: =HLOOKUP(L14,$C$2:$E$54,J14+2,FALSE) -> 0.01949318 | N14: =HLOOKUP(L14,$F$2:$H$54,J14+2,FALSE) -> 10.263407 | O14: 0.005 | P14: 0.005 | Q14: 0.0061793549 | R14: =N14*O14 -> 0.051317035 | S14: FALSE | T14: 6207 | U14: 0.006207 | V14: =U14*N14 -> 0.063704967 | Y14: =Z14 -> 0.003 | Z14: 0.003 | AA14: 0.0061793549 | AB14: =N14*Y14 -> 0.030790221 | AD14: =ROUND(Y14*1000000,0) -> 3000 | AE14: 0.003 | AF14: =AE14*N14 -> 0.030790221
B15: 15 | C15: {=_xlfn.IFNA( _xlfn._xlws.FILTER( Sim_Mul_Bet1!$H$3:$H$48, (Sim_Mul_Bet1!$A$3:$A$48=C$2) * (Sim_Mul_Bet1!$C$3:$C$48=$B15),0 ), 0 )} -> 0.00314108 | D15: {=_xlfn.IFNA( _xlfn._xlws.FILTER( Sim_Mul_Bet1!$H$3:$H$48, (Sim_Mul_Bet1!$A$3:$A$48=D$2) * (Sim_Mul_Bet1!$C$3:$C$48=$B15),0 ), 0 )} -> 0.02856435 | E15: {=_xlfn.IFNA( _xlfn._xlws.FILTER( Sim_Mul_Bet1!$H$3:$H$48, (Sim_Mul_Bet1!$A$3:$A$48=E$2) * (Sim_Mul_Bet1!$C$3:$C$48=$B15),0 ), 0 )} -> 0 | F15: {=_xlfn.IFNA( _xlfn._xlws.FILTER( Sim_Mul_Bet1!$O$3:$O$48, (Sim_Mul_Bet1!$A$3:$A$48=C$2) * (Sim_Mul_Bet1!$C$3:$C$48=$B15),0 ), 0 )} -> 15.115594 | G15: {=_xlfn.IFNA( _xlfn._xlws.FILTER( Sim_Mul_Bet1!$O$3:$O$48, (Sim_Mul_Bet1!$A$3:$A$48=D$2) * (Sim_Mul_Bet1!$C$3:$C$48=$B15),0 ), 0 )} -> 19.351512 | H15: {=_xlfn.IFNA( _xlfn._xlws.FILTER( Sim_Mul_Bet1!$O$3:$O$48, (Sim_Mul_Bet1!$A$3:$A$48=E$2) * (Sim_Mul_Bet1!$C$3:$C$48=$B15),0 ), 0 )} -> 0 | J15: 12 | K15: 15 | L15: A | M15: =HLOOKUP(L15,$C$2:$E$54,J15+2,FALSE) -> 0.00314108 | N15: =HLOOKUP(L15,$F$2:$H$54,J15+2,FALSE) -> 15.115594 | O15: 0.005 | P15: 0.005 | Q15: 0.0059882886 | R15: =N15*O15 -> 0.07557797 | S15: FALSE | T15: 5365 | U15: 0.005365 | V15: =U15*N15 -> 0.081095162 | Y15: =Z15 -> 0.01 | Z15: 0.01 | AA15: 0.0059882886 | AB15: =N15*Y15 -> 0.15115594 | AD15: =ROUND(Y15*1000000,0) -> 10000 | AE15: 0.01 | AF15: =AE15*N15 -> 0.15115594
... B54: 7000 | C54: {=_xlfn.IFNA( _xlfn._xlws.FILTER( Sim_Mul_Bet1!$H$3:$H$48, (Sim_Mul_Bet1!$A$3:$A$48=C$2) * (Sim_Mul_Bet1!$C$3:$C$48=$B54),0 ), 0 )} -> 0 | D54: {=_xlfn.IFNA( _xlfn._xlws.FILTER( Sim_Mul_Bet1!$H$3:$H$48, (Sim_Mul_Bet1!$A$3:$A$48=D$2) * (Sim_Mul_Bet1!$C$3:$C$48=$B54),0 ), 0 )} -> 0 | E54: {=_xlfn.IFNA( _xlfn._xlws.FILTER( Sim_Mul_Bet1!$H$3:$H$48, (Sim_Mul_Bet1!$A$3:$A$48=E$2) * (Sim_Mul_Bet1!$C$3:$C$48=$B54),0 ), 0 )} -> 0 | F54: {=_xlfn.IFNA( _xlfn._xlws.FILTER( Sim_Mul_Bet1!$O$3:$O$48, (Sim_Mul_Bet1!$A$3:$A$48=C$2) * (Sim_Mul_Bet1!$C$3:$C$48=$B54),0 ), 0 )} -> 0 | G54: {=_xlfn.IFNA( _xlfn._xlws.FILTER( Sim_Mul_Bet1!$O$3:$O$48, (Sim_Mul_Bet1!$A$3:$A$48=D$2) * (Sim_Mul_Bet1!$C$3:$C$48=$B54),0 ), 0 )} -> 0 | H54: {=_xlfn.IFNA( _xlfn._xlws.FILTER( Sim_Mul_Bet1!$O$3:$O$48, (Sim_Mul_Bet1!$A$3:$A$48=E$2) * (Sim_Mul_Bet1!$C$3:$C$48=$B54),0 ), 0 )} -> 0 | J54: 51 | K54: 7000 | L54: A | M54: =HLOOKUP(L54,$C$2:$E$54,J54+2,FALSE) -> 0 | N54: =HLOOKUP(L54,$F$2:$H$54,J54+2,FALSE) -> 0 | O54: 0 | P54: 0 | Q54: 0 | R54: =N54*O54 -> 0 | S54: TRUE | T54: 0 | U54: 0 | V54: =U54*N54 -> 0 | Y54: =Z54 -> 0 | Z54: 0 | AA54: 0 | AB54: =N54*Y54 -> 0 | AD54: =ROUND(Y54*1000000,0) -> 0 | AE54: 0 | AF54: =AE54*N54 -> 0

Sheet Sim_Mul_Bet1
O1: 1
H3: Hit% | O3: AVG Mul | U3: Hit%
A4: A | B4: BaseGame | C4: 0 | F4: = | G4: 87009169 | H4: {=G4:G19/SUM($G$4:$G$19)} -> 0.87009169 | K4: Pay | L4: = | M4: 0 | O4: =M4/G4/$O$1 -> 0 | R4: 1C1 | S4: = | T4: null, | U4: {=_xlfn.IFS(T4="null,",0,T4="","",T4/G4>=0,T4/G4)} -> 0 | X4: 2C1 | Y4: = | Z4: null, | AA4: 3C1 | AB4: = | AC4: null, | AD4: 4C1 | AE4: = | AF4: null, | AG4: 5C1 | AH4: = | AI4: null
A5: A | B5: BaseGame | C5: 1 | F5: = | G5: 4525812 | H5: 0.04525812 | K5: Pay | L5: = | M5: 4525812 | O5: =M5/G5/$O$1 -> 1 | R5: 1C1 | S5: = | T5: null, | U5: {=_xlfn.IFS(T5="null,",0,T5="","",T5/G5>=0,T5/G5)} -> 0 | X5: 2C1 | Y5: = | Z5: null, | AA5: 3C1 | AB5: = | AC5: null, | AD5: 4C1 | AE5: = | AF5: null, | AG5: 5C1 | AH5: = | AI5: null
A6: A | B6: BaseGame | C6: 2 | F6: = | G6: 138889 | H6: 0.00138889 | K6: Pay | L6: = | M6: 277778 | O6: =M6/G6/$O$1 -> 2 | R6: 1C1 | S6: = | T6: null, | U6: {=_xlfn.IFS(T6="null,",0,T6="","",T6/G6>=0,T6/G6)} -> 0 | X6: 2C1 | Y6: = | Z6: null, | AA6: 3C1 | AB6: = | AC6: null, | AD6: 4C1 | AE6: = | AF6: null, | AG6: 5C1 | AH6: = | AI6: null
A7: A | B7: BaseGame | C7: 5 | F7: = | G7: 5049721 | H7: 0.05049721 | K7: Pay | L7: = | M7: 25248605 | O7: =M7/G7/$O$1 -> 5 | R7: 1C1 | S7: = | T7: null, | U7: {=_xlfn.IFS(T7="null,",0,T7="","",T7/G7>=0,T7/G7)} -> 0 | X7: 2C1 | Y7: = | Z7: null, | AA7: 3C1 | AB7: = | AC7: null, | AD7: 4C1 | AE7: = | AF7: null, | AG7: 5C1 | AH7: = | AI7: null
A8: A | B8: BaseGame | C8: 6 | F8: = | G8: 2457 | H8: 2.457e-05 | K8: Pay | L8: = | M8: 14742 | O8: =M8/G8/$O$1 -> 6 | R8: 1C1 | S8: = | T8: null, | U8: {=_xlfn.IFS(T8="null,",0,T8="","",T8/G8>=0,T8/G8)} -> 0 | X8: 2C1 | Y8: = | Z8: null, | AA8: 3C1 | AB8: = | AC8: null, | AD8: 4C1 | AE8: = | AF8: null, | AG8: 5C1 | AH8: = | AI8: null
A9: A | B9: BaseGame | C9: 10 | F9: = | G9: 1949318 | H9: 0.01949318 | K9: Pay | L9: = | M9: 20006644 | O9: =M9/G9/$O$1 -> 10.263407 | R9: 1C1 | S9: = | T9: null, | U9: {=_xlfn.IFS(T9="null,",0,T9="","",T9/G9>=0,T9/G9)} -> 0 | X9: 2C1 | Y9: = | Z9: null, | AA9: 3C1 | AB9: = | AC9: null, | AD9: 4C1 | AE9: = | AF9: null, | AG9: 5C1 | AH9: = | AI9: null
A10: A | B10: BaseGame | C10: 15 | F10: = | G10: 314108 | H10: 0.00314108 | K10: Pay | L10: = | M10: 4747929 | O10: =M10/G10/$O$1 -> 15.115594 | R10: 1C1 | S10: = | T10: null, | U10: {=_xlfn.IFS(T10="null,",0,T10="","",T10/G10>=0,T10/G10)} -> 0 | X10: 2C1 | Y10: = | Z10: null, | AA10: 3C1 | AB10: = | AC10: null, | AD10: 4C1 | AE10: = | AF10: null, | AG10: 5C1 | AH10: = | AI10: null
A11: A | B11: BaseGame | C11: 20 | F11: = | G11: 161855 | H11: 0.00161855 | K11: Pay | L11: = | M11: 3292133 | O11: =M11/G11/$O$1 -> 20.340014 | R11: 1C1 | S11: = | T11: null, | U11: {=_xlfn.IFS(T11="null,",0,T11="","",T11/G11>=0,T11/G11)} -> 0 | X11: 2C1 | Y11: = | Z11: null, | AA11: 3C1 | AB11: = | AC11: null, | AD11: 4C1 | AE11: = | AF11: null, | AG11: 5C1 | AH11: = | AI11: null
A12: A | B12: BaseGame | C12: 25 | F12: = | G12: 294850 | H12: 0.0029485 | K12: Pay | L12: = | M12: 7371672 | O12: =M12/G12/$O$1 -> 25.001431 | R12: 1C1 | S12: = | T12: null, | U12: {=_xlfn.IFS(T12="null,",0,T12="","",T12/G12>=0,T12/G12)} -> 0 | X12: 2C1 | Y12: = | Z12: null, | AA12: 3C1 | AB12: = | AC12: null, | AD12: 4C1 | AE12: = | AF12: null, | AG12: 5C1 | AH12: = | AI12: null
A13: A | B13: BaseGame | C13: 30 | F13: = | G13: 22816 | H13: 0.00022816 | K13: Pay | L13: = | M13: 684480 | O13: =M13/G13/$O$1 -> 30 | R13: 1C1 | S13: = | T13: null, | U13: {=_xlfn.IFS(T13="null,",0,T13="","",T13/G13>=0,T13/G13)} -> 0 | X13: 2C1 | Y13: = | Z13: null, | AA13: 3C1 | AB13: = | AC13: null, | AD13: 4C1 | AE13: = | AF13: null, | AG13: 5C1 | AH13: = | AI13: null
A14: A | B14: BaseGame | C14: 50 | F14: = | G14: 465196 | H14: 0.00465196 | K14: Pay | L14: = | M14: 24043774 | O14: =M14/G14/$O$1 -> 51.685255 | R14: 1C1 | S14: = | T14: null, | U14: {=_xlfn.IFS(T14="null,",0,T14="","",T14/G14>=0,T14/G14)} -> 0 | X14: 2C1 | Y14: = | Z14: null, | AA14: 3C1 | AB14: = | AC14: null, | AD14: 4C1 | AE14: = | AF14: null, | AG14: 5C1 | AH14: = | AI14: null
A15: A | B15: BaseGame | C15: 60 | F15: = | G15: 7544 | H15: 7.544e-05 | K15: Pay | L15: = | M15: 459470 | O15: =M15/G15/$O$1 -> 60.905355 | R15: 1C1 | S15: = | T15: null, | U15: {=_xlfn.IFS(T15="null,",0,T15="","",T15/G15>=0,T15/G15)} -> 0 | X15: 2C1 | Y15: = | Z15: null, | AA15: 3C1 | AB15: = | AC15: null, | AD15: 4C1 | AE15: = | AF15: null, | AG15: 5C1 | AH15: = | AI15: null
A16: A | B16: BaseGame | C16: 70 | F16: = | G16: 63 | H16: 6.3e-07 | K16: Pay | L16: = | M16: 4410 | O16: =M16/G16/$O$1 -> 70 | R16: 1C1 | S16: = | T16: null, | U16: {=_xlfn.IFS(T16="null,",0,T16="","",T16/G16>=0,T16/G16)} -> 0 | X16: 2C1 | Y16: = | Z16: null, | AA16: 3C1 | AB16: = | AC16: null, | AD16: 4C1 | AE16: = | AF16: null, | AG16: 5C1 | AH16: = | AI16: null
... A19: A | B19: BaseGame | C19: 500 | F19: = | G19: 14 | H19: 1.4e-07 | K19: Pay | L19: = | M19: 7040 | O19: =M19/G19/$O$1 -> 502.85714 | R19: 1C1 | S19: = | T19: null, | U19: {=_xlfn.IFS(T19="null,",0,T19="","",T19/G19>=0,T19/G19)} -> 0 | X19: 2C1 | Y19: = | Z19: null, | AA19: 3C1 | AB19: = | AC19: null, | AD19: 4C1 | AE19: = | AF19: null, | AG19: 5C1 | AH19: = | AI19: null
U20: {=_xlfn.IFS(T20="null,",0,T20="","",T20/G20>=0,T20/G20)}
A22: B | B22: BaseGame | C22: -1 | F22: = | G22: 27765510 | H22: {=G22:G43/SUM(G22:G43)} -> 0.2776551
A23: B | B23: BaseGame | C23: 0 | F23: = | G23: 9718529 | H23: 0.09718529 | K23: Pay | L23: = | M23: 971852900 | O23: =M23/G23/$O$1/100 -> 1 | R23: 1C1 | S23: = | T23: null | U23: 2C1 | V23: = | W23: 1388023 | X23: 3C1 | Y23: = | Z23: null | AA23: 4C1 | AB23: = | AC23: null | AD23: 5C1 | AE23: = | AF23: null
A24: B | B24: BaseGame | C24: 1 | F24: = | G24: 3470722 | H24: 0.03470722 | K24: Pay | L24: = | M24: 694144400 | O24: =M24/G24/$O$1/100 -> 2 | R24: 1C1 | S24: = | T24: null | U24: 2C1 | V24: = | W24: 694221 | X24: 3C1 | Y24: = | Z24: null | AA24: 4C1 | AB24: = | AC24: null | AD24: 5C1 | AE24: = | AF24: null
A25: B | B25: BaseGame | C25: 4 | F25: = | G25: 12505433 | H25: 0.12505433 | K25: Pay | L25: = | M25: 6252716500 | O25: =M25/G25/$O$1/100 -> 5 | R25: 1C1 | S25: = | T25: null | U25: 2C1 | V25: = | W25: 1389964 | X25: 3C1 | Y25: = | Z25: null | AA25: 4C1 | AB25: = | AC25: null | AD25: 5C1 | AE25: = | AF25: null
A26: B | B26: BaseGame | C26: 5 | F26: = | G26: 1388947 | H26: 0.01388947 | K26: Pay | L26: = | M26: 833368200 | O26: =M26/G26/$O$1/100 -> 6 | R26: 1C1 | S26: = | T26: null | U26: 2C1 | V26: = | W26: 1388947 | X26: 3C1 | Y26: = | Z26: null | AA26: 4C1 | AB26: = | AC26: null | AD26: 5C1 | AE26: = | AF26: null
A27: B | B27: BaseGame | C27: 9 | F27: = | G27: 9957442 | H27: 0.09957442 | K27: Pay | L27: = | M27: 9957442000 | O27: =M27/G27/$O$1/100 -> 10 | R27: 1C1 | S27: = | T27: null | U27: 2C1 | V27: = | W27: 1621508 | X27: 3C1 | Y27: = | Z27: null | AA27: 4C1 | AB27: = | AC27: null | AD27: 5C1 | AE27: = | AF27: null
A28: B | B28: BaseGame | C28: 10 | F28: = | G28: 5325540 | H28: 0.0532554 | K28: Pay | L28: = | M28: 6900132300 | O28: =M28/G28/$O$1/100 -> 12.956681 | R28: 1C1 | S28: = | T28: null | U28: 2C1 | V28: = | W28: 2546798 | X28: 3C1 | Y28: = | Z28: null | AA28: 4C1 | AB28: = | AC28: null | AD28: 5C1 | AE28: = | AF28: null
A29: B | B29: BaseGame | C29: 15 | F29: = | G29: 2856435 | H29: 0.02856435 | K29: Pay | L29: = | M29: 5527633600 | O29: =M29/G29/$O$1/100 -> 19.351512 | R29: 1C1 | S29: = | T29: null | U29: 2C1 | V29: = | W29: 1002205 | X29: 3C1 | Y29: = | Z29: null | AA29: 4C1 | AB29: = | AC29: null | AD29: 5C1 | AE29: = | AF29: null
A30: B | B30: BaseGame | C30: 20 | F30: = | G30: 3568880 | H30: 0.0356888 | K30: Pay | L30: = | M30: 8716099000 | O30: =M30/G30/$O$1/100 -> 24.422505 | R30: 1C1 | S30: = | T30: null | U30: 2C1 | V30: = | W30: 327626 | X30: 3C1 | Y30: = | Z30: null | AA30: 4C1 | AB30: = | AC30: null | AD30: 5C1 | AE30: = | AF30: null
A31: B | B31: BaseGame | C31: 25 | F31: = | G31: 521546 | H31: 0.00521546 | K31: Pay | L31: = | M31: 1549244400 | O31: =M31/G31/$O$1/100 -> 29.704847 | R31: 1C1 | S31: = | T31: null | U31: 2C1 | V31: = | W31: 57981 | X31: 3C1 | Y31: = | Z31: null | AA31: 4C1 | AB31: = | AC31: null | AD31: 5C1 | AE31: = | AF31: null
A32: B | B32: BaseGame | C32: 45 | F32: = | G32: 3474008 | H32: 0.03474008 | K32: Pay | L32: = | M32: 17370040000 | O32: =M32/G32/$O$1/100 -> 50 | R32: 1C1 | S32: = | T32: null | U32: 2C1 | V32: = | W32: 231594 | X32: 3C1 | Y32: = | Z32: null | AA32: 4C1 | AB32: = | AC32: null | AD32: 5C1 | AE32: = | AF32: null
A33: B | B33: BaseGame | C33: 50 | F33: = | G33: 5248740 | H33: 0.0524874 | K33: Pay | L33: = | M33: 28296905400 | O33: =M33/G33/$O$1/100 -> 53.911806 | R33: 1C1 | S33: = | T33: null | U33: 2C1 | V33: = | W33: 2005532 | X33: 3C1 | Y33: = | Z33: null | AA33: 4C1 | AB33: = | AC33: null | AD33: 5C1 | AE33: = | AF33: null
A34: B | B34: BaseGame | C34: 60 | F34: = | G34: 540279 | H34: 0.00540279 | K34: Pay | L34: = | M34: 3449977900 | O34: =M34/G34/$O$1/100 -> 63.855488 | R34: 1C1 | S34: = | T34: null | U34: 2C1 | V34: = | W34: 540279 | X34: 3C1 | Y34: = | Z34: null | AA34: 4C1 | AB34: = | AC34: null | AD34: 5C1 | AE34: = | AF34: null
A35: B | B35: BaseGame | C35: 70 | F35: = | G35: 463106 | H35: 0.00463106 | K35: Pay | L35: = | M35: 3473295000 | O35: =M35/G35/$O$1/100 -> 75 | R35: 1C1 | S35: = | T35: null | U35: 2C1 | V35: = | W35: null | X35: 3C1 | Y35: = | Z35: null | AA35: 4C1 | AB35: = | AC35: null | AD35: 5C1 | AE35: = | AF35: null
A36: B | B36: BaseGame | C36: 90 | F36: = | G36: 2103874 | H36: 0.02103874 | K36: Pay | L36: = | M36: 21038740000 | O36: =M36/G36/$O$1/100 -> 100 | R36: 1C1 | S36: = | T36: null | U36: 2C1 | V36: = | W36: 251027 | X36: 3C1 | Y36: = | Z36: null | AA36: 4C1 | AB36: = | AC36: null | AD36: 5C1 | AE36: = | AF36: null
A37: B | B37: BaseGame | C37: 100 | F37: = | G37: 6406460 | H37: 0.0640646 | K37: Pay | L37: = | M37: 67261879400 | O37: =M37/G37/$O$1/100 -> 104.99071 | R37: 1C1 | S37: = | T37: null | U37: 2C1 | V37: = | W37: 2702663 | X37: 3C1 | Y37: = | Z37: null | AA37: 4C1 | AB37: = | AC37: null | AD37: 5C1 | AE37: = | AF37: null
A38: B | B38: BaseGame | C38: 140 | F38: = | G38: 347015 | H38: 0.00347015 | K38: Pay | L38: = | M38: 5344243100 | O38: =M38/G38/$O$1/100 -> 154.00611 | R38: 1C1 | S38: = | T38: null | U38: 2C1 | V38: = | W38: 347015 | X38: 3C1 | Y38: = | Z38: null | AA38: 4C1 | AB38: = | AC38: null | AD38: 5C1 | AE38: = | AF38: null
A39: B | B39: BaseGame | C39: 180 | F39: = | G39: 481474 | H39: 0.00481474 | K39: Pay | L39: = | M39: 9629480000 | O39: =M39/G39/$O$1/100 -> 200 | R39: 1C1 | S39: = | T39: null | U39: 2C1 | V39: = | W39: 19281 | X39: 3C1 | Y39: = | Z39: null | AA39: 4C1 | AB39: = | AC39: null | AD39: 5C1 | AE39: = | AF39: null
A40: B | B40: BaseGame | C40: 200 | F40: = | G40: 1543054 | H40: 0.01543054 | K40: Pay | L40: = | M40: 33797303700 | O40: =M40/G40/$O$1/100 -> 219.02865 | R40: 1C1 | S40: = | T40: null | U40: 2C1 | V40: = | W40: 154231 | X40: 3C1 | Y40: = | Z40: null | AA40: 4C1 | AB40: = | AC40: null | AD40: 5C1 | AE40: = | AF40: null
A41: B | B41: BaseGame | C41: 250 | F41: = | G41: 925631 | H41: 0.00925631 | K41: Pay | L41: = | M41: 24530590500 | O41: =M41/G41/$O$1/100 -> 265.01479 | R41: 1C1 | S41: = | T41: null | U41: 2C1 | V41: = | W41: null | X41: 3C1 | Y41: = | Z41: null | AA41: 4C1 | AB41: = | AC41: null | AD41: 5C1 | AE41: = | AF41: null
A42: B | B42: BaseGame | C42: 450 | F42: = | G42: 462326 | H42: 0.00462326 | K42: Pay | L42: = | M42: 23116300000 | O42: =M42/G42/$O$1/100 -> 500 | R42: 1C1 | S42: = | T42: null | U42: 2C1 | V42: = | W42: null | X42: 3C1 | Y42: = | Z42: null | AA42: 4C1 | AB42: = | AC42: null | AD42: 5C1 | AE42: = | AF42: null
A43: B | B43: BaseGame | C43: 500 | F43: = | G43: 925049 | H43: 0.00925049 | K43: Pay | L43: = | M43: 47640528500 | O43: =M43/G43/$O$1/100 -> 515.00546 | R43: 1C1 | S43: = | T43: null | U43: 2C1 | V43: = | W43: null | X43: 3C1 | Y43: = | Z43: null | AA43: 4C1 | AB43: = | AC43: null | AD43: 5C1 | AE43: = | AF43: null
Y44: {=_xlfn.IFS(X44="null,",0,X44="","",X44/G44>=0,X44/G44)}
...

Sheet Card_Bet5
C1: Hit% | F1: Mul | R1: =SUM(R3:R54) -> 0.74609386 | V1: =SUM(V3:V54) -> 0.71959919 | AB1: =SUM(AB3:AB54) -> 0.68318517 | AF1: =SUM(AF3:AF54) -> 0.68318487
B2: Interval | C2: A | D2: B | E2: C | F2: A | G2: B | H2: C | J2: Index | K2: Interval | L2: Sheet | M2: Mul | N2: Avg Mul | O2: Hit%_tune | P2: Hit%_ori | Q2: Jili Hit% | R2: RTP_tune | T2: Hit%_Weight_Final | U2: Hit%_Final | V2: RTP_Final | Y2: Hit%_tune | Z2: Hit%_ori | AA2: Jili Hit% | AB2: RTP_tune | AD2: Hit%_Weight_Final | AE2: Hit%_Final | AF2: RTP_Final
B3: -1 | C3: {=_xlfn.IFNA( _xlfn._xlws.FILTER( Sim_Mul_Bet5!$H$3:$H$72, (Sim_Mul_Bet5!$A$3:$A$72=C$2) * (Sim_Mul_Bet5!$C$3:$C$72=$B3),0 ), 0 )} -> 0 | D3: {=_xlfn.IFNA( _xlfn._xlws.FILTER( Sim_Mul_Bet5!$H$3:$H$72, (Sim_Mul_Bet5!$A$3:$A$72=D$2) * (Sim_Mul_Bet5!$C$3:$C$72=$B3),0 ), 0 )} -> 0.16667922 | G3: {=_xlfn.IFNA( _xlfn._xlws.FILTER( Sim_Mul_Bet5!$O$3:$O$72, (Sim_Mul_Bet5!$A$3:$A$72=D$2) * (Sim_Mul_Bet5!$C$3:$C$72=$B3),0 ), 0 )} -> 0 | J3: 0 | K3: -1 | L3: A | M3: =HLOOKUP(L3,$C$2:$E$54,J3+2,FALSE) -> 0 | N3: =HLOOKUP(L3,$F$2:$H$54,J3+2,FALSE) -> 0 | O3: =1-SUM(O4:O53) -> 0.86831201 | P3: =1-SUM(P4:P53) -> 0.86826291 | Q3: =1-SUM(Q4:Q54) -> 0.86813985 | R3: =N3*O3 -> 0 | T3: =1000000-SUM(T4:T54) -> 868433 | U3: {=T3:T54/SUM($T$3:$T$54)} -> 0.868433 | V3: =U3*N3 -> 0 | Y3: =1-SUM(Y4:Y53) -> 0.87119768 | Z3: =1-SUM(Z4:Z53) -> 0.87119768 | AA3: =1-SUM(AA4:AA54) -> 0.86813985 | AB3: =N3*Y3 -> 0 | AD3: =1000000-SUM(AD4:AD54) -> 871198 | AE3: {=AD3:AD54/SUM($T$3:$T$54)} -> 0.871198 | AF3: =AE3*N3 -> 0
B4: 0 | C4: {=_xlfn.IFNA( _xlfn._xlws.FILTER( Sim_Mul_Bet5!$H$3:$H$72, (Sim_Mul_Bet5!$A$3:$A$72=C$2) * (Sim_Mul_Bet5!$C$3:$C$72=$B4),0 ), 0 )} -> 0.8701443 | D4: {=_xlfn.IFNA( _xlfn._xlws.FILTER( Sim_Mul_Bet5!$H$3:$H$72, (Sim_Mul_Bet5!$A$3:$A$72=D$2) * (Sim_Mul_Bet5!$C$3:$C$72=$B4),0 ), 0 )} -> 0.17968134 | E4: {=_xlfn.IFNA( _xlfn._xlws.FILTER( Sim_Mul_Bet5!$H$3:$H$72, (Sim_Mul_Bet5!$A$3:$A$72=E$2) * (Sim_Mul_Bet5!$C$3:$C$72=$B4),0 ), 0 )} -> 0 | F4: {=_xlfn.IFNA( _xlfn._xlws.FILTER( Sim_Mul_Bet5!$O$3:$O$72, (Sim_Mul_Bet5!$A$3:$A$72=C$2) * (Sim_Mul_Bet5!$C$3:$C$72=$B4),0 ), 0 )} -> 0 | G4: {=_xlfn.IFNA( _xlfn._xlws.FILTER( Sim_Mul_Bet5!$O$3:$O$72, (Sim_Mul_Bet5!$A$3:$A$72=D$2) * (Sim_Mul_Bet5!$C$3:$C$72=$B4),0 ), 0 )} -> 0.6327848 | H4: {=_xlfn.IFNA( _xlfn._xlws.FILTER( Sim_Mul_Bet5!$O$3:$O$72, (Sim_Mul_Bet5!$A$3:$A$72=E$2) * (Sim_Mul_Bet5!$C$3:$C$72=$B4),0 ), 0 )} -> 0 | J4: 1 | K4: 0 | L4: A | M4: =HLOOKUP(L4,$C$2:$E$54,J4+2,FALSE) -> 0.8701443 | N4: =HLOOKUP(L4,$F$2:$H$54,J4+2,FALSE) -> 0 | O4: 0.065255022 | P4: 0.065255022 | Q4: 0.065255022 | R4: =N4*O4 -> 0 | T4: 73842 | U4: 0.073842 | V4: =U4*N4 -> 0 | Y4: =Z4 -> 0.065255022 | Z4: 0.065255022 | AA4: 0.065255022 | AB4: =N4*Y4 -> 0 | AD4: =ROUND(Y4*1000000,0) -> 65255 | AE4: 0.065255 | AF4: =AE4*N4 -> 0
B5: 1 | C5: {=_xlfn.IFNA( _xlfn._xlws.FILTER( Sim_Mul_Bet5!$H$3:$H$72, (Sim_Mul_Bet5!$A$3:$A$72=C$2) * (Sim_Mul_Bet5!$C$3:$C$72=$B5),0 ), 0 )} -> 0.05555461 | D5: {=_xlfn.IFNA( _xlfn._xlws.FILTER( Sim_Mul_Bet5!$H$3:$H$72, (Sim_Mul_Bet5!$A$3:$A$72=D$2) * (Sim_Mul_Bet5!$C$3:$C$72=$B5),0 ), 0 )} -> 0.07261635 | E5: {=_xlfn.IFNA( _xlfn._xlws.FILTER( Sim_Mul_Bet5!$H$3:$H$72, (Sim_Mul_Bet5!$A$3:$A$72=E$2) * (Sim_Mul_Bet5!$C$3:$C$72=$B5),0 ), 0 )} -> 0 | F5: {=_xlfn.IFNA( _xlfn._xlws.FILTER( Sim_Mul_Bet5!$O$3:$O$72, (Sim_Mul_Bet5!$A$3:$A$72=C$2) * (Sim_Mul_Bet5!$C$3:$C$72=$B5),0 ), 0 )} -> 1.0000036 | G5: {=_xlfn.IFNA( _xlfn._xlws.FILTER( Sim_Mul_Bet5!$O$3:$O$72, (Sim_Mul_Bet5!$A$3:$A$72=D$2) * (Sim_Mul_Bet5!$C$3:$C$72=$B5),0 ), 0 )} -> 1.9243169 | H5: {=_xlfn.IFNA( _xlfn._xlws.FILTER( Sim_Mul_Bet5!$O$3:$O$72, (Sim_Mul_Bet5!$A$3:$A$72=E$2) * (Sim_Mul_Bet5!$C$3:$C$72=$B5),0 ), 0 )} -> 0 | J5: 2 | K5: 1 | L5: A | M5: =HLOOKUP(L5,$C$2:$E$54,J5+2,FALSE) -> 0.05555461 | N5: =HLOOKUP(L5,$F$2:$H$54,J5+2,FALSE) -> 1.0000036 | O5: 0.0020542997 | P5: 0.0020542997 | Q5: 0.0020542997 | R5: =N5*O5 -> 0.0020543071 | T5: 1738 | U5: 0.001738 | V5: =U5*N5 -> 0.0017380063 | Y5: =Z5 -> 0.0020542997 | Z5: 0.0020542997 | AA5: 0.0020542997 | AB5: =N5*Y5 -> 0.0020543071 | AD5: =ROUND(Y5*1000000,0) -> 2054 | AE5: 0.002054 | AF5: =AE5*N5 -> 0.0020540074
B6: 2 | C6: {=_xlfn.IFNA( _xlfn._xlws.FILTER( Sim_Mul_Bet5!$H$3:$H$72, (Sim_Mul_Bet5!$A$3:$A$72=C$2) * (Sim_Mul_Bet5!$C$3:$C$72=$B6),0 ), 0 )} -> 0.01539024 | D6: {=_xlfn.IFNA( _xlfn._xlws.FILTER( Sim_Mul_Bet5!$H$3:$H$72, (Sim_Mul_Bet5!$A$3:$A$72=D$2) * (Sim_Mul_Bet5!$C$3:$C$72=$B6),0 ), 0 )} -> 0.05516408 | E6: {=_xlfn.IFNA( _xlfn._xlws.FILTER( Sim_Mul_Bet5!$H$3:$H$72, (Sim_Mul_Bet5!$A$3:$A$72=E$2) * (Sim_Mul_Bet5!$C$3:$C$72=$B6),0 ), 0 )} -> 0 | F6: {=_xlfn.IFNA( _xlfn._xlws.FILTER( Sim_Mul_Bet5!$O$3:$O$72, (Sim_Mul_Bet5!$A$3:$A$72=C$2) * (Sim_Mul_Bet5!$C$3:$C$72=$B6),0 ), 0 )} -> 2.0097588 | G6: {=_xlfn.IFNA( _xlfn._xlws.FILTER( Sim_Mul_Bet5!$O$3:$O$72, (Sim_Mul_Bet5!$A$3:$A$72=D$2) * (Sim_Mul_Bet5!$C$3:$C$72=$B6),0 ), 0 )} -> 2.5894956 | H6: {=_xlfn.IFNA( _xlfn._xlws.FILTER( Sim_Mul_Bet5!$O$3:$O$72, (Sim_Mul_Bet5!$A$3:$A$72=E$2) * (Sim_Mul_Bet5!$C$3:$C$72=$B6),0 ), 0 )} -> 0 | J6: 3 | K6: 2 | L6: A | M6: =HLOOKUP(L6,$C$2:$E$54,J6+2,FALSE) -> 0.01539024 | N6: =HLOOKUP(L6,$F$2:$H$54,J6+2,FALSE) -> 2.0097588 | O6: 0.0040659003 | P6: 0.0040659003 | Q6: 0.0040659003 | R6: =N6*O6 -> 0.0081714787 | T6: 4558 | U6: 0.004558 | V6: =U6*N6 -> 0.0091604805 | Y6: =Z6 -> 0.0003 | Z6: 0.0003 | AA6: 0.0040659003 | AB6: =N6*Y6 -> 0.00060292763 | AD6: =ROUND(Y6*1000000,0) -> 300 | AE6: 0.0003 | AF6: =AE6*N6 -> 0.00060292763
