Workbook

Sheet Overview
A2: Model: | B2: H0281
A3: Version: | B3: 3.3.0.0
A6: Base Bet | B6: Multiway
A7: 100 | B7: 32400
A10: Coin in | B10: Price(x) | C10: Total RTP | D10: Bet Type
A11: {=B11:B12*A7} -> 100 | B11: 1 | C11: =B17+B18 -> 0.93999977 | D11: Normal Bet
A12: 7500 | B12: 75 | C12: =B21+B22 -> 0.92499987 | D12: Buy Feature
A15: Total Pay Back Percentage includes the following adjustments.
A16: Bet Type | B16: Pay Back | C16: Hit% | D16: Pulls/Hit | E16: Description
A17: =D11 -> Normal Bet | B17: =Detail!C7 -> 0.71999983 | C17: =1/D17 -> 0.0033333327 | D17: =Detail!G7 -> 300.00005 | E17: Base Game
B18: =Detail!D7 -> 0.21999994 | E18: Free Game
A20: Bet Type | B20: Pay Back | C20: Hit% | D20: Pulls/Hit | E20: Description
A21: =D12 -> Buy Feature | B21: =Detail!C8 -> 0 | C21: =1/D21 -> 1 | D21: 1 | E21: Base Game
B22: =Detail!D8 -> 0.92499987 | E22: Free Game

Sheet Multiplier_Weight
A2: Range | B2: Weight_NB_BG_Newbie | C2: Weight_NB_FG_Newbie | D2: Weight_NB_BG | E2: Weight_NB_FG | F2: Weight_BF
A3: (-1, 0] | B3: =Detail_Newbie!K15 -> 733362425 | C3: =Detail_Newbie!K86 -> 0 | D3: =Detail!K15 -> 725330287 | E3: =Detail!K86 -> 0 | F3: =Detail!K163 -> 0
A4: (0, 1] | B4: =Detail_Newbie!K16 -> 147073504 | C4: =Detail_Newbie!K87 -> 0 | D4: =Detail!K16 -> 154427750 | E4: =Detail!K87 -> 0 | F4: =Detail!K164 -> 0
A5: (1, 2] | B5: =Detail_Newbie!K17 -> 43093495 | C5: =Detail_Newbie!K88 -> 0 | D5: =Detail!K17 -> 45355881 | E5: =Detail!K88 -> 0 | F5: =Detail!K165 -> 0
A6: (2, 3] | B6: =Detail_Newbie!K18 -> 19740552 | C6: =Detail_Newbie!K89 -> 0 | D6: =Detail!K18 -> 20824186 | E6: =Detail!K89 -> 0 | F6: =Detail!K166 -> 0
A7: (3, 4] | B7: =Detail_Newbie!K19 -> 12108868 | C7: =Detail_Newbie!K90 -> 0 | D7: =Detail!K19 -> 12801763 | E7: =Detail!K90 -> 0 | F7: =Detail!K167 -> 0
A8: (4, 5] | B8: =Detail_Newbie!K20 -> 7862117 | C8: =Detail_Newbie!K91 -> 0 | D8: =Detail!K20 -> 8330490 | E8: =Detail!K91 -> 0 | F8: =Detail!K168 -> 0
A9: (5, 6] | B9: =Detail_Newbie!K21 -> 6066338 | C9: =Detail_Newbie!K92 -> 0 | D9: =Detail!K21 -> 6442268 | E9: =Detail!K92 -> 0 | F9: =Detail!K169 -> 0
A10: (6, 7] | B10: =Detail_Newbie!K22 -> 3265440 | C10: =Detail_Newbie!K93 -> 0 | D10: =Detail!K22 -> 3475271 | E10: =Detail!K93 -> 0 | F10: =Detail!K170 -> 0
A11: (7, 8] | B11: =Detail_Newbie!K23 -> 3661420 | C11: =Detail_Newbie!K94 -> 0 | D11: =Detail!K23 -> 3905407 | E11: =Detail!K94 -> 0 | F11: =Detail!K171 -> 0
A12: (8, 9] | B12: =Detail_Newbie!K24 -> 2962011 | C12: =Detail_Newbie!K95 -> 0 | D12: =Detail!K24 -> 3166537 | E12: =Detail!K95 -> 0 | F12: =Detail!K172 -> 0
A13: (9, 10] | B13: =Detail_Newbie!K25 -> 1920529 | C13: =Detail_Newbie!K96 -> 0 | D13: =Detail!K25 -> 2057627 | E13: =Detail!K96 -> 0 | F13: =Detail!K173 -> 0
A14: (10, 15] | B14: =Detail_Newbie!K26 -> 10160353 | C14: =Detail_Newbie!K97 -> 0 | D14: =Detail!K26 -> 6253983 | E14: =Detail!K97 -> 0 | F14: =Detail!K174 -> 0
... A66: (100000, 9999999] | B66: =Detail_Newbie!K78 -> 0 | C66: =Detail_Newbie!K149 -> 0 | D66: =Detail!K78 -> 0 | E66: =Detail!K149 -> 0 | F66: =Detail!K226 -> 0
A67: Free Game | B67: =Detail_Newbie!K79 -> 3590649 | C67: 0 | D67: =Detail!K79 -> 3344481 | E67: 0 | F67: 0

Sheet Detail
A2: Threshold | B2: 1000000000
A3: Coin in | B3: =Overview!A7 -> 100
C5: RTP
B6: Bet | C6: Base Game | D6: Free Game | E6: Total | F6: Hit Rate | G6: FG Period | H6: Avg Multi | I6: BG | J6: FG
A7: Normal Bet | B7: {=Overview!B11:B12} -> 1 | C7: =SUM(M15:M79) -> 0.72 | D7: =SUM(_xlfn.ANCHORARRAY(M86))*F7 -> 0.21999998 | E7: =SUM(C7:D7) -> 0.93999998 | F7: =L79 -> 0.003333333 | G7: =1/F7 -> 300.00003 | H7: =D7*G7 -> 66 | I7: {=LOOKUP(2,1/(K15:K78<>0),P15:P78)} -> 70 | J7: {=LOOKUP(2,1/(_xlfn.ANCHORARRAY(K86)<>0),P15:P78)} -> 20000
A8: Buy Feature | B8: 75 | C8: =M156/B8 -> 0 | D8: =SUM(_xlfn.ANCHORARRAY(M163))/B8 -> 0.92499999 | E8: =SUM(C8:D8) -> 0.92499999 | F8: =D156 -> 1 | G8: =1/F8 -> 1 | H8: =D8*G8*B8 -> 69.374999 | J8: {=LOOKUP(2,1/(_xlfn.ANCHORARRAY(K163)<>0),P15:P78)} -> 20000
A11: Normal Bet | B11: Base Game | G11: Normal Bet | H11: Base Game | O11: Normal Bet | P11: Base Game
A13: Simulate | B13: 1000000000 | G13: Calculate
A14: Range | B14: Cnt | C14: Pay | D14: Hit Rate | E14: Avg. Multi. | G14: Range | H14: Fix Num | I14: Fix Rate | J14: Final Rate | K14: Weight | L14: Hit Rate | M14: Simulator RTP | O14: Lower | P14: Upper | Q14: 目前 | R14: 競品 | T14: 目前 | U14: 差異
A15: ="("&$O15&", "&$P15&"]" -> (-1, 0] | B15: 624769021 | C15: 0 | D15: {=_xlfn.LET(_xlpm.x, B15:B78, _xlpm.x/SUM(_xlpm.x))} -> 0.62476902 | E15: {=_xlfn.LET(_xlpm.x, C15:C79/B15:B79/B3, IF(ISERR(_xlpm.x), 0, _xlpm.x))} -> 0 | G15: ="("&$O15&", "&$P15&"]" -> (-1, 0] | H15: 1.1609575 | I15: {=D15:D79*H15:H79} -> 0.72533029 | J15: {=I15:I78/SUM(I15:I78)} -> 0.72533029 | K15: {=INT(J15:J79*$B$2)} -> 725330287 | L15: {=_xlfn.LET(_xlpm.x, K15:K79, _xlpm.x/SUM(_xlpm.x))} -> 0.72291252 | M15: {=L15:L79*E15:E79} -> 0 | O15: -1 | P15: 0 | Q15: {=L15:L78} -> 0.72291313 | R15: 0.723799 | U15: {=_xlfn.LET(_xlpm.x, T15:T78/L15:L78, IF(ISERR(_xlpm.x), 0, ROUND(_xlpm.x,2)))} -> 0
A16: ="("&$O16&", "&$P16&"]" -> (0, 1] | B16: 143263411 | C16: 6213982290 | D16: 0.14326341 | E16: 0.43374524 | G16: ="("&$O16&", "&$P16&"]" -> (0, 1] | H16: 1.0779288 | I16: 0.15442775 | J16: 0.15442775 | K16: 154427750 | L16: 0.15391299 | M16: 0.066759028 | O16: 0 | P16: 1 | Q16: 0.15391304 | R16: 0.154266 | U16: 0
A17: ="("&$O17&", "&$P17&"]" -> (1, 2] | B17: 54932044 | C17: 8270002480 | D17: 0.054932044 | E17: 1.505497 | G17: ="("&$O17&", "&$P17&"]" -> (1, 2] | H17: 0.82567255 | I17: 0.045355881 | J17: 0.045355881 | K17: 45355881 | L17: 0.045204695 | M17: 0.068055531 | O17: 1 | P17: 2 | Q17: 0.04520465 | R17: 0.045428 | U17: 0
A18: ="("&$O18&", "&$P18&"]" -> (2, 3] | B18: 33042473 | C18: 8364971370 | D18: 0.033042473 | E18: 2.5315815 | G18: ="("&$O18&", "&$P18&"]" -> (2, 3] | H18: 0.6302248 | I18: 0.020824186 | J18: 0.020824186 | K18: 20824186 | L18: 0.020754772 | M18: 0.052542397 | O18: 2 | P18: 3 | Q18: 0.020754725 | R18: 0.02091 | U18: 0
A19: ="("&$O19&", "&$P19&"]" -> (3, 4] | B19: 22877263 | C19: 8071800230 | D19: 0.022877263 | E19: 3.5283068 | G19: ="("&$O19&", "&$P19&"]" -> (3, 4] | H19: 0.55958455 | I19: 0.012801763 | J19: 0.012801763 | K19: 12801763 | L19: 0.012759091 | M19: 0.045017987 | O19: 3 | P19: 4 | Q19: 0.012759047 | R19: 0.012886 | U19: 0
A20: ="("&$O20&", "&$P20&"]" -> (4, 5] | B20: 16969191 | C20: 7691363560 | D20: 0.016969191 | E20: 4.5325458 | G20: ="("&$O20&", "&$P20&"]" -> (4, 5] | H20: 0.49091851 | I20: 0.00833049 | J20: 0.00833049 | K20: 8330490 | L20: 0.008302722 | M20: 0.037632468 | O20: 4 | P20: 5 | Q20: 0.0083026828 | R20: 0.008406 | U20: 0
A21: ="("&$O21&", "&$P21&"]" -> (5, 6] | B21: 13473297 | C21: 7480889915 | D21: 0.013473297 | E21: 5.5523825 | G21: ="("&$O21&", "&$P21&"]" -> (5, 6] | H21: 0.47815082 | I21: 0.006442268 | J21: 0.006442268 | K21: 6442268 | L21: 0.006420794 | M21: 0.035650705 | O21: 5 | P21: 6 | Q21: 0.0064207559 | R21: 0.006517 | U21: 0
A22: ="("&$O22&", "&$P22&"]" -> (6, 7] | B22: 10639718 | C22: 6941964595 | D22: 0.010639718 | E22: 6.5245757 | G22: ="("&$O22&", "&$P22&"]" -> (6, 7] | H22: 0.32663187 | I22: 0.003475271 | J22: 0.003475271 | K22: 3475271 | L22: 0.003463687 | M22: 0.022599088 | O22: 6 | P22: 7 | Q22: 0.0034636618 | R22: 0.003524 | U22: 0
A23: ="("&$O23&", "&$P23&"]" -> (7, 8] | B23: 8953686 | C23: 6744293590 | D23: 0.008953686 | E23: 7.5324214 | G23: ="("&$O23&", "&$P23&"]" -> (7, 8] | H23: 0.43617869 | I23: 0.003905407 | J23: 0.003905407 | K23: 3905407 | L23: 0.003892389 | M23: 0.029319114 | O23: 7 | P23: 8 | Q23: 0.0038923561 | R23: 0.00397 | U23: 0
A24: ="("&$O24&", "&$P24&"]" -> (8, 9] | B24: 7527858 | C24: 6438090340 | D24: 0.007527858 | E24: 8.5523536 | G24: ="("&$O24&", "&$P24&"]" -> (8, 9] | H24: 0.4206425 | I24: 0.003166537 | J24: 0.003166537 | K24: 3166537 | L24: 0.003155982 | M24: 0.026991074 | O24: 8 | P24: 9 | Q24: 0.003155952 | R24: 0.003227 | U24: 0
A25: ="("&$O25&", "&$P25&"]" -> (9, 10] | B25: 6225071 | C25: 5937388995 | D25: 0.006225071 | E25: 9.5378655 | G25: ="("&$O25&", "&$P25&"]" -> (9, 10] | H25: 0.33053872 | I25: 0.002057627 | J25: 0.002057627 | K25: 2057627 | L25: 0.002050768 | M25: 0.019559949 | O25: 9 | P25: 10 | Q25: 0.0020507463 | R25: 0.002102 | U25: 0
A26: ="("&$O26&", "&$P26&"]" -> (10, 15] | B26: 20709880 | C26: 25432216970 | D26: 0.02070988 | E26: 12.280234 | G26: ="("&$O26&", "&$P26&"]" -> (10, 15] | H26: 0.30198065 | I26: 0.006253983 | J26: 0.006253983 | K26: 6253983 | L26: 0.006233136 | M26: 0.076544368 | O26: 10 | P26: 15 | Q26: 0.0062330477 | R26: 0.006432 | U26: 0
A27: ="("&$O27&", "&$P27&"]" -> (15, 20] | B27: 11154375 | C27: 19338114770 | D27: 0.011154375 | E27: 17.336798 | G27: ="("&$O27&", "&$P27&"]" -> (15, 20] | H27: 0.24304141 | I27: 0.002710975 | J27: 0.002710975 | K27: 2710975 | L27: 0.002701938 | M27: 0.046842954 | O27: 15 | P27: 20 | Q27: 0.0027018826 | R27: 0.002823 | U27: 0
... A78: ="("&$O78&", "&$P78&"]" -> (100000, 9999999] | B78: 0 | C78: 0 | D78: 0 | E78: 0 | G78: ="("&$O78&", "&$P78&"]" -> (100000, 9999999] | H78: 0 | I78: 0 | J78: 0 | K78: 0 | L78: 0 | M78: 0 | O78: 100000 | P78: 9999999 | Q78: 0 | R78: 0 | U78: 0
A79: Free Game | B79: 6997315 | C79: 6167760230 | D79: =B79/B13 -> 0.006997315 | E79: 8.814467 | G79: Free Game | H79: 0.47796633 | I79: 0.003344481 | J79: =I79 -> 0.003344481 | K79: 3344481 | L79: 0.003333333 | M79: 0.029381554
A82: Normal Bet | B82: Free Game | G82: Normal Bet | H82: Free Game | O82: Normal Bet | P82: Free Game
A84: Simulate | G84: Calculate
A85: Range | B85: Cnt | C85: Pay | D85: Hit Rate | E85: Avg. Multi. | G85: Range | H85: Fix Num | I85: Fix Rate | J85: Final Rate | K85: Weight | L85: Hit Rate | M85: Simulator RTP | O85: Lower | P85: Upper | Q85: 目前 | R85: 競品 | T85: 目前 | U85: 差異
A86: ="("&$O86&", "&$P86&"]" -> (-1, 0] | B86: 25321 | C86: 0 | D86: {=_xlfn.LET(_xlpm.x, B86:B149, _xlpm.x/SUM(_xlpm.x))} -> 0.0036186737 | E86: {=_xlfn.LET(_xlpm.x, C86:C149/B86:B149/B3, IF(ISERR(_xlpm.x), 0, _xlpm.x))} -> 0 | G86: ="("&$O86&", "&$P86&"]" -> (-1, 0] | H86: 0 | I86: {=_xlfn.ANCHORARRAY(D86)*H86:H149} -> 0 | J86: {=I86:I149/SUM(_xlfn.ANCHORARRAY(I86))} -> 0 | K86: {=INT(_xlfn.ANCHORARRAY(J86)*$B$2)} -> 0 | L86: {=_xlfn.LET(_xlpm.x, K86:K149, _xlpm.x/SUM(_xlpm.x))} -> 0 | M86: {=L86:L149*_xlfn.ANCHORARRAY(E86)} -> 0 | O86: -1 | P86: 0 | Q86: {=_xlfn.ANCHORARRAY(L86)} -> 0 | R86: 0.02069 | U86: {=_xlfn.LET(_xlpm.x, T86:T149/L86:L149, IF(ISERR(_xlpm.x), 0, ROUND(_xlpm.x,2)))} -> 0
A87: ="("&$O87&", "&$P87&"]" -> (0, 1] | B87: 13519 | C87: 830135 | D87: 0.0019320268 | E87: 0.6140506 | G87: ="("&$O87&", "&$P87&"]" -> (0, 1] | H87: 0 | I87: 0 | J87: 0 | K87: 0 | L87: 0 | M87: 0 | O87: 0 | P87: 1 | Q87: 0 | R87: 0.006897 | U87: 0
A88: ="("&$O88&", "&$P88&"]" -> (1, 2] | B88: 18233 | C88: 2846325 | D88: 0.0026057138 | E88: 1.5610843 | G88: ="("&$O88&", "&$P88&"]" -> (1, 2] | H88: 0 | I88: 0 | J88: 0 | K88: 0 | L88: 0 | M88: 0 | O88: 1 | P88: 2 | Q88: 0 | R88: 0.006897 | U88: 0
A89: ="("&$O89&", "&$P89&"]" -> (2, 3] | B89: 19401 | C89: 5010400 | D89: 0.0027726349 | E89: 2.5825473 | G89: ="("&$O89&", "&$P89&"]" -> (2, 3] | H89: 0 | I89: 0 | J89: 0 | K89: 0 | L89: 0 | M89: 0 | O89: 2 | P89: 3 | Q89: 0 | R89: 0.006897 | U89: 0
A90: ="("&$O90&", "&$P90&"]" -> (3, 4] | B90: 21192 | C90: 7594100 | D90: 0.0030285903 | E90: 3.5834749 | G90: ="("&$O90&", "&$P90&"]" -> (3, 4] | H90: 0 | I90: 0 | J90: 0 | K90: 0 | L90: 0 | M90: 0 | O90: 3 | P90: 4 | Q90: 0 | R90: 0.006897 | U90: 0
A91: ="("&$O91&", "&$P91&"]" -> (4, 5] | B91: 22042 | C91: 10092500 | D91: 0.0031500654 | E91: 4.5787587 | G91: ="("&$O91&", "&$P91&"]" -> (4, 5] | H91: 0 | I91: 0 | J91: 0 | K91: 0 | L91: 0 | M91: 0 | O91: 4 | P91: 5 | Q91: 0 | R91: 0.006897 | U91: 0
A92: ="("&$O92&", "&$P92&"]" -> (5, 6] | B92: 24704 | C92: 13812490 | D92: 0.0035304971 | E92: 5.5911958 | G92: ="("&$O92&", "&$P92&"]" -> (5, 6] | H92: 0 | I92: 0 | J92: 0 | K92: 0 | L92: 0 | M92: 0 | O92: 5 | P92: 6 | Q92: 0 | R92: 0.006897 | U92: 0
A93: ="("&$O93&", "&$P93&"]" -> (6, 7] | B93: 23371 | C93: 15361185 | D93: 0.0033399954 | E93: 6.5727547 | G93: ="("&$O93&", "&$P93&"]" -> (6, 7] | H93: 0 | I93: 0 | J93: 0 | K93: 0 | L93: 0 | M93: 0 | O93: 6 | P93: 7 | Q93: 0 | R93: 0.02069 | U93: 0
A94: ="("&$O94&", "&$P94&"]" -> (7, 8] | B94: 26882 | C94: 20329515 | D94: 0.0038417593 | E94: 7.5625009 | G94: ="("&$O94&", "&$P94&"]" -> (7, 8] | H94: 0 | I94: 0 | J94: 0 | K94: 0 | L94: 0 | M94: 0 | O94: 7 | P94: 8 | Q94: 0 | R94: 0 | U94: 0
A95: ="("&$O95&", "&$P95&"]" -> (8, 9] | B95: 27171 | C95: 23310120 | D95: 0.0038830609 | E95: 8.5790438 | G95: ="("&$O95&", "&$P95&"]" -> (8, 9] | H95: 0 | I95: 0 | J95: 0 | K95: 0 | L95: 0 | M95: 0 | O95: 8 | P95: 9 | Q95: 0 | R95: 0.006897 | U95: 0
A96: ="("&$O96&", "&$P96&"]" -> (9, 10] | B96: 27734 | C96: 26563225 | D96: 0.0039635203 | E96: 9.5778557 | G96: ="("&$O96&", "&$P96&"]" -> (9, 10] | H96: 0 | I96: 0 | J96: 0 | K96: 0 | L96: 0 | M96: 0 | O96: 9 | P96: 10 | Q96: 0 | R96: 0 | U96: 0
A97: ="("&$O97&", "&$P97&"]" -> (10, 15] | B97: 148515 | C97: 187358865 | D97: 0.02122457 | E97: 12.615484 | G97: ="("&$O97&", "&$P97&"]" -> (10, 15] | H97: 0 | I97: 0 | J97: 0 | K97: 0 | L97: 0 | M97: 0 | O97: 10 | P97: 15 | Q97: 0 | R97: 0.062069 | U97: 0
A98: ="("&$O98&", "&$P98&"]" -> (15, 20] | B98: 161740 | C98: 284486210 | D98: 0.02311458 | E98: 17.589107 | G98: ="("&$O98&", "&$P98&"]" -> (15, 20] | H98: 0 | I98: 0 | J98: 0 | K98: 0 | L98: 0 | M98: 0 | O98: 15 | P98: 20 | Q98: 0 | R98: 0.027586 | U98: 0
...

Sheet Detail_Newbie
A2: Threshold | B2: 1000000000
A3: Coin in | B3: =Overview!A7 -> 100
C5: RTP
B6: Bet | C6: Base Game | D6: Free Game | E6: Total | F6: Hit Rate | G6: FG Period | H6: Avg Multi | I6: BG | J6: FG
A7: Normal Bet | B7: =Overview!B11 -> 1 | C7: =SUM(M15:M79) -> 0.72000002 | D7: =SUM(_xlfn.ANCHORARRAY(M86))*F7 -> 0.20999994 | E7: =SUM(C7:D7) -> 0.92999996 | F7: =L79 -> 0.003577802 | G7: =1/F7 -> 279.50121 | H7: =D7*G7 -> 58.695238 | I7: {=LOOKUP(2,1/(K15:K78<>0),P15:P78)} -> 30 | J7: {=LOOKUP(2,1/(_xlfn.ANCHORARRAY(K86)<>0),P15:P78)} -> 100
A11: Normal Bet | B11: Base Game | G11: Normal Bet | H11: Base Game | O11: Normal Bet | P11: Base Game
A13: Simulate | B13: 1000000000 | G13: Calculate
A14: Range | B14: Cnt | C14: Pay | D14: Hit Rate | E14: Avg. Multi. | G14: Range | H14: Fix Num | I14: Fix Rate | J14: Final Rate | K14: Weight | L14: Hit Rate | M14: Simulator RTP | O14: Lower | P14: Upper | Q14: 目前 | R14: 競品 | T14: 目前 | U14: 差異
A15: ="("&$O15&", "&$P15&"]" -> (-1, 0] | B15: 624769021 | C15: 0 | D15: {=_xlfn.LET(_xlpm.x, B15:B78, _xlpm.x/SUM(_xlpm.x))} -> 0.62476902 | E15: {=_xlfn.LET(_xlpm.x, C15:C79/B15:B79/B3, IF(ISERR(_xlpm.x), 0, _xlpm.x))} -> 0 | G15: ="("&$O15&", "&$P15&"]" -> (-1, 0] | H15: 1.1738137 | I15: {=D15:D79*H15:H79} -> 0.73336243 | J15: {=I15:I78/SUM(I15:I78)} -> 0.73336243 | K15: {=INT(J15:J79*$B$2)} -> 733362425 | L15: {=_xlfn.LET(_xlpm.x, K15:K79, _xlpm.x/SUM(_xlpm.x))} -> 0.7307386 | M15: {=L15:L79*E15:E79} -> 0 | O15: -1 | P15: 0 | Q15: {=L15:L78} -> 0.73073984 | R15: 0.723799 | U15: {=_xlfn.LET(_xlpm.x, T15:T78/L15:L78, IF(ISERR(_xlpm.x), 0, ROUND(_xlpm.x,2)))} -> 0
A16: ="("&$O16&", "&$P16&"]" -> (0, 1] | B16: 143263411 | C16: 6213982290 | D16: 0.14326341 | E16: 0.43374524 | G16: ="("&$O16&", "&$P16&"]" -> (0, 1] | H16: 1.026595 | I16: 0.1470735 | J16: 0.1470735 | K16: 147073504 | L16: 0.1465473 | M16: 0.063564196 | O16: 0 | P16: 1 | Q16: 0.1465474 | R16: 0.154266 | U16: 0
A17: ="("&$O17&", "&$P17&"]" -> (1, 2] | B17: 54932044 | C17: 8270002480 | D17: 0.054932044 | E17: 1.505497 | G17: ="("&$O17&", "&$P17&"]" -> (1, 2] | H17: 0.78448737 | I17: 0.043093495 | J17: 0.043093495 | K17: 43093495 | L17: 0.042939315 | M17: 0.064645008 | O17: 1 | P17: 2 | Q17: 0.042939229 | R17: 0.045428 | U17: 0
A18: ="("&$O18&", "&$P18&"]" -> (2, 3] | B18: 33042473 | C18: 8364971370 | D18: 0.033042473 | E18: 2.5315815 | G18: ="("&$O18&", "&$P18&"]" -> (2, 3] | H18: 0.59742962 | I18: 0.019740552 | J18: 0.019740552 | K18: 19740552 | L18: 0.019669924 | M18: 0.049796016 | O18: 2 | P18: 3 | Q18: 0.019669835 | R18: 0.02091 | U18: 0
A19: ="("&$O19&", "&$P19&"]" -> (3, 4] | B19: 22877263 | C19: 8071800230 | D19: 0.022877263 | E19: 3.5283068 | G19: ="("&$O19&", "&$P19&"]" -> (3, 4] | H19: 0.52929706 | I19: 0.012108868 | J19: 0.012108868 | K19: 12108868 | L19: 0.012065545 | M19: 0.042570944 | O19: 3 | P19: 4 | Q19: 0.012065461 | R19: 0.012886 | U19: 0
A20: ="("&$O20&", "&$P20&"]" -> (4, 5] | B20: 16969191 | C20: 7691363560 | D20: 0.016969191 | E20: 4.5325458 | G20: ="("&$O20&", "&$P20&"]" -> (4, 5] | H20: 0.46331714 | I20: 0.007862117 | J20: 0.007862117 | K20: 7862117 | L20: 0.007833988 | M20: 0.03550791 | O20: 4 | P20: 5 | Q20: 0.0078339142 | R20: 0.008406 | U20: 0
A21: ="("&$O21&", "&$P21&"]" -> (5, 6] | B21: 13473297 | C21: 7480889915 | D21: 0.013473297 | E21: 5.5523825 | G21: ="("&$O21&", "&$P21&"]" -> (5, 6] | H21: 0.45024896 | I21: 0.006066338 | J21: 0.006066338 | K21: 6066338 | L21: 0.006044634 | M21: 0.03356212 | O21: 5 | P21: 6 | Q21: 0.0060445621 | R21: 0.006517 | U21: 0
A22: ="("&$O22&", "&$P22&"]" -> (6, 7] | B22: 10639718 | C22: 6941964595 | D22: 0.010639718 | E22: 6.5245757 | G22: ="("&$O22&", "&$P22&"]" -> (6, 7] | H22: 0.30691039 | I22: 0.00326544 | J22: 0.00326544 | K22: 3265440 | L22: 0.003253757 | M22: 0.021229384 | O22: 6 | P22: 7 | Q22: 0.0032537101 | R22: 0.003524 | U22: 0
A23: ="("&$O23&", "&$P23&"]" -> (7, 8] | B23: 8953686 | C23: 6744293590 | D23: 0.008953686 | E23: 7.5324214 | G23: ="("&$O23&", "&$P23&"]" -> (7, 8] | H23: 0.40892879 | I23: 0.00366142 | J23: 0.00366142 | K23: 3661420 | L23: 0.00364832 | M23: 0.027480684 | O23: 7 | P23: 8 | Q23: 0.0036482584 | R23: 0.00397 | U23: 0
A24: ="("&$O24&", "&$P24&"]" -> (8, 9] | B24: 7527858 | C24: 6438090340 | D24: 0.007527858 | E24: 8.5523536 | G24: ="("&$O24&", "&$P24&"]" -> (8, 9] | H24: 0.39347328 | I24: 0.002962011 | J24: 0.002962011 | K24: 2962011 | L24: 0.002951413 | M24: 0.025241528 | O24: 8 | P24: 9 | Q24: 0.0029513557 | R24: 0.003227 | U24: 0
A25: ="("&$O25&", "&$P25&"]" -> (9, 10] | B25: 6225071 | C25: 5937388995 | D25: 0.006225071 | E25: 9.5378655 | G25: ="("&$O25&", "&$P25&"]" -> (9, 10] | H25: 0.3085152 | I25: 0.001920529 | J25: 0.001920529 | K25: 1920529 | L25: 0.001913658 | M25: 0.018252213 | O25: 9 | P25: 10 | Q25: 0.0019136159 | R25: 0.002102 | U25: 0
A26: ="("&$O26&", "&$P26&"]" -> (10, 15] | B26: 20709880 | C26: 25432216970 | D26: 0.02070988 | E26: 12.280234 | G26: ="("&$O26&", "&$P26&"]" -> (10, 15] | H26: 0.49060415 | I26: 0.010160353 | J26: 0.010160353 | K26: 10160353 | L26: 0.010124001 | M26: 0.1243251 | O26: 10 | P26: 15 | Q26: 0.010123712 | R26: 0.006432 | U26: 0
A27: ="("&$O27&", "&$P27&"]" -> (15, 20] | B27: 11154375 | C27: 19338114770 | D27: 0.011154375 | E27: 17.336798 | G27: ="("&$O27&", "&$P27&"]" -> (15, 20] | H27: 0.39045558 | I27: 0.004355288 | J27: 0.004355288 | K27: 4355288 | L27: 0.004339706 | M27: 0.075236607 | O27: 15 | P27: 20 | Q27: 0.0043395273 | R27: 0.002823 | U27: 0
... A78: ="("&$O78&", "&$P78&"]" -> (100000, 9999999] | B78: 0 | C78: 0 | D78: 0 | E78: 0 | G78: ="("&$O78&", "&$P78&"]" -> (100000, 9999999] | H78: 0 | I78: 0 | J78: 0 | K78: 0 | L78: 0 | M78: 0 | O78: 100000 | P78: 9999999 | Q78: 0 | R78: 0 | U78: 0
A79: Free Game | B79: 6997315 | C79: 6167760230 | D79: =B79/B13 -> 0.006997315 | E79: 8.814467 | G79: Free Game | H79: 0.51314669 | I79: 0.003590649 | J79: =I79 -> 0.003590649 | K79: 3590649 | L79: 0.003577802 | M79: 0.031536418
A82: Normal Bet | B82: Free Game | G82: Normal Bet | H82: Free Game | O82: Normal Bet | P82: Free Game
A84: Simulate | G84: Calculate
A85: Range | B85: Cnt | C85: Pay | D85: Hit Rate | E85: Avg. Multi. | G85: Range | H85: Fix Num | I85: Fix Rate | J85: Final Rate | K85: Weight | L85: Hit Rate | M85: Simulator RTP | O85: Lower | P85: Upper | Q85: 目前 | R85: 競品 | T85: 目前 | U85: 差異
A86: ="("&$O86&", "&$P86&"]" -> (-1, 0] | B86: 25321 | C86: 0 | D86: {=_xlfn.LET(_xlpm.x, B86:B149, _xlpm.x/SUM(_xlpm.x))} -> 0.0036186737 | E86: {=_xlfn.LET(_xlpm.x, C86:C149/B86:B149/B3, IF(ISERR(_xlpm.x), 0, _xlpm.x))} -> 0 | G86: ="("&$O86&", "&$P86&"]" -> (-1, 0] | H86: 0 | I86: {=_xlfn.ANCHORARRAY(D86)*H86:H149} -> 0 | J86: {=I86:I149/SUM(_xlfn.ANCHORARRAY(I86))} -> 0 | K86: {=INT(_xlfn.ANCHORARRAY(J86)*$B$2)} -> 0 | L86: {=_xlfn.LET(_xlpm.x, K86:K149, _xlpm.x/SUM(_xlpm.x))} -> 0 | M86: {=L86:L149*_xlfn.ANCHORARRAY(E86)} -> 0 | O86: -1 | P86: 0 | Q86: {=_xlfn.ANCHORARRAY(L86)} -> 0 | R86: 0.02069 | U86: {=_xlfn.LET(_xlpm.x, T86:T149/L86:L149, IF(ISERR(_xlpm.x), 0, ROUND(_xlpm.x,2)))} -> 0
A87: ="("&$O87&", "&$P87&"]" -> (0, 1] | B87: 13519 | C87: 830135 | D87: 0.0019320268 | E87: 0.6140506 | G87: ="("&$O87&", "&$P87&"]" -> (0, 1] | H87: 0 | I87: 0 | J87: 0 | K87: 0 | L87: 0 | M87: 0 | O87: 0 | P87: 1 | Q87: 0 | R87: 0.006897 | U87: 0
A88: ="("&$O88&", "&$P88&"]" -> (1, 2] | B88: 18233 | C88: 2846325 | D88: 0.0026057138 | E88: 1.5610843 | G88: ="("&$O88&", "&$P88&"]" -> (1, 2] | H88: 0 | I88: 0 | J88: 0 | K88: 0 | L88: 0 | M88: 0 | O88: 1 | P88: 2 | Q88: 0 | R88: 0.006897 | U88: 0
A89: ="("&$O89&", "&$P89&"]" -> (2, 3] | B89: 19401 | C89: 5010400 | D89: 0.0027726349 | E89: 2.5825473 | G89: ="("&$O89&", "&$P89&"]" -> (2, 3] | H89: 0 | I89: 0 | J89: 0 | K89: 0 | L89: 0 | M89: 0 | O89: 2 | P89: 3 | Q89: 0 | R89: 0.006897 | U89: 0
A90: ="("&$O90&", "&$P90&"]" -> (3, 4] | B90: 21192 | C90: 7594100 | D90: 0.0030285903 | E90: 3.5834749 | G90: ="("&$O90&", "&$P90&"]" -> (3, 4] | H90: 0 | I90: 0 | J90: 0 | K90: 0 | L90: 0 | M90: 0 | O90: 3 | P90: 4 | Q90: 0 | R90: 0.006897 | U90: 0
A91: ="("&$O91&", "&$P91&"]" -> (4, 5] | B91: 22042 | C91: 10092500 | D91: 0.0031500654 | E91: 4.5787587 | G91: ="("&$O91&", "&$P91&"]" -> (4, 5] | H91: 0 | I91: 0 | J91: 0 | K91: 0 | L91: 0 | M91: 0 | O91: 4 | P91: 5 | Q91: 0 | R91: 0.006897 | U91: 0
A92: ="("&$O92&", "&$P92&"]" -> (5, 6] | B92: 24704 | C92: 13812490 | D92: 0.0035304971 | E92: 5.5911958 | G92: ="("&$O92&", "&$P92&"]" -> (5, 6] | H92: 0 | I92: 0 | J92: 0 | K92: 0 | L92: 0 | M92: 0 | O92: 5 | P92: 6 | Q92: 0 | R92: 0.006897 | U92: 0
A93: ="("&$O93&", "&$P93&"]" -> (6, 7] | B93: 23371 | C93: 15361185 | D93: 0.0033399954 | E93: 6.5727547 | G93: ="("&$O93&", "&$P93&"]" -> (6, 7] | H93: 0 | I93: 0 | J93: 0 | K93: 0 | L93: 0 | M93: 0 | O93: 6 | P93: 7 | Q93: 0 | R93: 0.02069 | U93: 0
A94: ="("&$O94&", "&$P94&"]" -> (7, 8] | B94: 26882 | C94: 20329515 | D94: 0.0038417593 | E94: 7.5625009 | G94: ="("&$O94&", "&$P94&"]" -> (7, 8] | H94: 0 | I94: 0 | J94: 0 | K94: 0 | L94: 0 | M94: 0 | O94: 7 | P94: 8 | Q94: 0 | R94: 0 | U94: 0
A95: ="("&$O95&", "&$P95&"]" -> (8, 9] | B95: 27171 | C95: 23310120 | D95: 0.0038830609 | E95: 8.5790438 | G95: ="("&$O95&", "&$P95&"]" -> (8, 9] | H95: 0 | I95: 0 | J95: 0 | K95: 0 | L95: 0 | M95: 0 | O95: 8 | P95: 9 | Q95: 0 | R95: 0.006897 | U95: 0
A96: ="("&$O96&", "&$P96&"]" -> (9, 10] | B96: 27734 | C96: 26563225 | D96: 0.0039635203 | E96: 9.5778557 | G96: ="("&$O96&", "&$P96&"]" -> (9, 10] | H96: 0 | I96: 0 | J96: 0 | K96: 0 | L96: 0 | M96: 0 | O96: 9 | P96: 10 | Q96: 0 | R96: 0 | U96: 0
A97: ="("&$O97&", "&$P97&"]" -> (10, 15] | B97: 148515 | C97: 187358865 | D97: 0.02122457 | E97: 12.615484 | G97: ="("&$O97&", "&$P97&"]" -> (10, 15] | H97: 0 | I97: 0 | J97: 0 | K97: 0 | L97: 0 | M97: 0 | O97: 10 | P97: 15 | Q97: 0 | R97: 0.062069 | U97: 0
A98: ="("&$O98&", "&$P98&"]" -> (15, 20] | B98: 161740 | C98: 284486210 | D98: 0.02311458 | E98: 17.589107 | G98: ="("&$O98&", "&$P98&"]" -> (15, 20] | H98: 0 | I98: 0 | J98: 0 | K98: 0 | L98: 0 | M98: 0 | O98: 15 | P98: 20 | Q98: 0 | R98: 0.027586 | U98: 0
... A149: ="("&$O149&", "&$P149&"]" -> (100000, 9999999] | B149: 0 | C149: 0 | D149: 0 | E149: 0 | G149: ="("&$O149&", "&$P149&"]" -> (100000, 9999999] | H149: 0 | I149: 0 | J149: 0 | K149: 0 | L149: 0 | M149: 0 | O149: 100000 | P149: 9999999 | Q149: 0 | R149: 0 | U149: 0

Sheet OP Jackpot
B2: Threshold | C2: 10000000000
B4: Bet Type | C4: SCR
B5: NB_Newbie | C5: 3864674550
B6: NB | C6: 3836181680
B7: BF | C7: 51240310600
