Workbook

Sheet Overview
A2: Model: | B2: H045194
A3: Version: | B3: 1.0.0.0
A6: Base Bet
A7: 100
A10: Coin in | B10: Price(x) | C10: Total RTP | D10: Bet Type
A11: 100 | B11: 1 | C11: =SUM(B18:B19) -> 0.92997309 | D11: Normal Bet
A12: 100 | B12: 1 | C12: =SUM(B22:B23) -> 0.93993928 | D12: Normal Bet
A13: 4050 | B13: 40.5 | C13: =SUM(B26:B27) -> 0.9249974 | D13: Buy Feature
A14: 4050 | B14: 40.5 | C14: =SUM(B30:B31) -> 0.98529689 | D14: Buy Feature
A16: Total Pay Back Percentage includes the following adjustments.
A17: Bet Type | B17: Pay Back | C17: Hit% | D17: Pulls/Hit | E17: Description
A18: Normal Bet | B18: =Multiplier_Weight_Newbie!$C$7 -> 0.66318572 | C18: =IF(D18=0,0,1/D18) -> 0.00849 | D18: =Multiplier_Weight_Newbie!$G$7 -> 117.78563 | E18: Base Game
B19: =Multiplier_Weight_Newbie!$D$7 -> 0.26678737 | E19: Free Game
A21: Bet Type | B21: Pay Back | C21: Hit% | D21: Pulls/Hit | E21: Description
A22: Normal Bet | B22: =Multiplier_Weight_Oldhand!$C$7 -> 0.66712158 | C22: =IF(D22=0,0,1/D22) -> 0.00849 | D22: =Multiplier_Weight_Oldhand!$G$7 -> 117.78563 | E22: Base Game
B23: =Multiplier_Weight_Oldhand!$D$7 -> 0.2728177 | E23: Free Game
A25: Bet Type | B25: Pay Back | C25: Hit% | D25: Pulls/Hit | E25: Description
A26: Buy Feature | B26: =Multiplier_Weight_Newbie!$C$8 -> 0 | C26: =IF(D26=0,0,1/D26) -> 1 | D26: =Multiplier_Weight_Newbie!$G$8 -> 1 | E26: Base Game
B27: =Multiplier_Weight_Newbie!$D$8 -> 0.9249974 | E27: Free Game
A29: Bet Type | B29: Pay Back | C29: Hit% | D29: Pulls/Hit | E29: Description
A30: Buy Feature | B30: =Multiplier_Weight_Oldhand!$C$8 -> 0 | C30: =IF(D30=0,0,1/D30) -> 1 | D30: =Multiplier_Weight_Oldhand!$G$8 -> 1 | E30: Base Game
B31: =Multiplier_Weight_Oldhand!$D$8 -> 0.98529689 | E31: Free Game
A34: Reel # | B34: 1 | C34: 2 | D34: 3 | E34: 4 | F34: 5
A35: Visible Window Size | B35: 4 | C35: 4 | D35: 4 | E35: 4 | F35: 4
A38: Free Spins Setting
A39: C1 Num. | B39: Base Game | C39: Free Game
A40: 3 | B40: 10 | C40: 5
A41: 4 | B41: 10 | C41: 5
A42: 5 | B42: 10 | C42: 5
A43: 6 | B43: 10 | C43: 5
A44: The maximum of free spins is 50.
A46: Pay Table: | B46: All wins show for 100 credit bet.
A47: Symbol | B47: Description | C47: 3 | D47: 4 | E47: 5 | F47: Id
A48: WW1 | B48: Wild 1 | C48: 0 | D48: 0 | E48: 0 | F48: 0
A49: WW2 | B49: Wild 2 (Copy Wild) | C49: 0 | D49: 0 | E49: 0 | F49: 1
A50: C1 | B50: Scatter | C50: 0 | D50: 0 | E50: 0 | F50: 2
A51: M1 | B51: M1 | C51: 50 | D51: 150 | E51: 250 | F51: 3
A52: M2 | B52: M2 | C52: 40 | D52: 120 | E52: 200 | F52: 4
A53: M3 | B53: M3 | C53: 30 | D53: 90 | E53: 150 | F53: 5
A54: M4 | B54: M4 | C54: 20 | D54: 60 | E54: 100 | F54: 6
...

Sheet Description
B2: Base Game
B3: 1. Every Base Game spin draws repeatedly from the table selected by the card system (Multiplier_Weight) until the win falls inside the drawn range.
C4: Worksheet | F4: ID
C5: BG_Symbol | F5: B
C6: BG_Symbol (2) | F6: A
B7: 2. The starting board uses the 5 strips of the selected BG worksheet; the stop positions are drawn using that worksheet's Symbol Weight R1-R5.
B8: 3. On a win the winning symbols are removed and the gaps are refilled by drawing new symbols with the same reel's weights.
B9: 4. The win multiplier rises with the combo count: X1, X2, X3, X5, X10. It stays at X10 thereafter.
B10: 5. Random wild evaluation:
C11: (1) The following is evaluated whenever at least one golden symbol (M1G-JG) is part of a win.
C12: (2) Each spin carries a flag for whether a random wild has already occurred. Until it is set, every combo that removes a golden symbol is evaluated once; after it is set no further combo in that spin is evaluated.
C13: (3) When a golden symbol is removed the Random Wild Weight in Parameter is rolled. On a 2-4 the cell becomes a WW2 and a further 2-4 WW2 replace random positions on R2-R5, never overwriting an existing C1, WW1 or WW2.
C14: (4) If several golden symbols are removed together the same evaluation applies, but at most one of them triggers the random wild; the rest become WW1.
C15: (5) Order of play: remove -> refill -> reveal all golden symbols -> golden cells become WW1 or WW2 -> if WW2 copies were rolled, resolve which positions they overwrite last.
B16: 6. C1 may drop in on any refill, and more than one C1 may appear on the same reel.
B17: 7. C1 never takes part in a win. Only once no further win is possible are the C1 on the board counted to decide whether the Free Spins are entered.
B19: Free Game
B20: 1. On entering the Free Game the card system's group decides how many high- and low-table spins are awarded; their order is shuffled.
C21: Group | D21: High Spins | E21: Low Spins | F21: Weight
C22: D | D22: 0 | E22: 10 | F22: 1
C23: D | D23: 3 | E23: 7 | F23: 0
C24: D | D24: 4 | E24: 6 | F24: 0
C25: D | D25: 5 | E25: 5 | F25: 0
C26: D | D26: 6 | E26: 4 | F26: 0
C27: D | D27: 10 | E27: 0 | F27: 0
C28: E | D28: 0 | E28: 10 | F28: 0
C29: E | D29: 3 | E29: 7 | F29: 0
C30: E | D30: 4 | E30: 6 | F30: 0
C31: E | D31: 5 | E31: 5 | F31: 0
C32: E | D32: 6 | E32: 4 | F32: 0
C33: E | D33: 10 | E33: 0 | F33: 1
B34: * Every Free Game and Buy Feature card in Multiplier_Weight currently uses group E, i.e. a fixed 10 high-table spins.
B35: 2. Each high-table spin picks its worksheet with the weights below; low-table spins always use FG_Symbol (5).
C36: Worksheet | D36: High Strip | E36: Weight
C37: FG_Symbol | D37: A | E37: 1
C38: FG_Symbol (2) | D38: K | E38: 1
C39: FG_Symbol (3) | D39: Q | E39: 1
C40: FG_Symbol (4) | D40: J | E40: 1
B41: 3. 3 or more C1 on a Free Game final board adds a fixed 5 spins - 1 high table and 4 low table - shuffled into the remaining order.
B42: 4. On a win the winning symbols are removed and the gaps refilled with the same reel's weights.
...

Sheet Parameter
B2: Table Selection - Base Game
B3: Worksheet Name | C3: ID | D3: Description
B4: BG_Symbol | C4: B | D4: Base Game high table
B5: BG_Symbol (2) | C5: A | D5: Base Game low table
B6: * The table actually used is set by the Table column of Multiplier_Weight_*; there is no separate table-selection draw.
B8: Random Wild Weight (Weight/Total)
B9: Worksheet Name \ Copies | C9: 0 | D9: 2 | E9: 3 | F9: 4
B10: BG_Symbol | C10: 26128 | D10: 4404 | E10: 1101 | F10: 367
B11: BG_Symbol (2) | C11: 1 | D11: 0 | E11: 0 | F11: 0
B12: FG_Symbol | C12: 13128 | D12: 2000 | E12: 500 | F12: 200
B13: FG_Symbol (2) | C13: 13128 | D13: 2000 | E13: 500 | F13: 200
B14: FG_Symbol (3) | C14: 13128 | D14: 2000 | E14: 500 | F14: 200
B15: FG_Symbol (4) | C15: 13128 | D15: 2000 | E15: 500 | F15: 200
B16: FG_Symbol (5) | C16: 13128 | D16: 2000 | E16: 500 | F16: 200
B17: BF_Symbol | C17: 1 | D17: 0 | E17: 0 | F17: 0
B18: * Rolling 0 means the golden symbol only becomes a WW1, with no WW2 copies.
B20: Win Multiplier Ladder
B21: Worksheet Name \ Cascade N | C21: 1 | D21: 2 | E21: 3 | F21: 4 | G21: 5+
B22: BG_Symbol | C22: X1 | D22: X2 | E22: X3 | F22: X5 | G22: X10
B23: BG_Symbol (2) | C23: X1 | D23: X2 | E23: X3 | F23: X5 | G23: X10
B24: FG_Symbol | C24: X2 | D24: X4 | E24: X6 | F24: X10 | G24: X20
B25: FG_Symbol (2) | C25: X2 | D25: X4 | E25: X6 | F25: X10 | G25: X20
B26: FG_Symbol (3) | C26: X2 | D26: X4 | E26: X6 | F26: X10 | G26: X20
B27: FG_Symbol (4) | C27: X2 | D27: X4 | E27: X6 | F27: X10 | G27: X20
B28: FG_Symbol (5) | C28: X2 | D28: X4 | E28: X6 | F28: X10 | G28: X20
B29: BF_Symbol | C29: X1 | D29: X2 | E29: X3 | F29: X5 | G29: X10
B30: * The multiplier only advances within a spin; a new spin returns to that mode's first step.
B32: Free Game Table Mix Weight
B33: Group | C33: High Spins | D33: Low Spins | E33: Weight
B34: D | C34: 0 | D34: 10 | E34: 1
B35: D | C35: 3 | D35: 7 | E35: 0
B36: D | C36: 4 | D36: 6 | E36: 0
B37: D | C37: 5 | D37: 5 | E37: 0
B38: D | C38: 6 | D38: 4 | E38: 0
B39: D | C39: 10 | D39: 0 | E39: 0
B40: E | C40: 0 | D40: 10 | E40: 0
B41: E | C41: 3 | D41: 7 | E41: 0
B42: E | C42: 4 | D42: 6 | E42: 0
B43: E | C43: 5 | D43: 5 | E43: 0
B44: E | C44: 6 | D44: 4 | E44: 0
...

Sheet Multiplier_Weight
B2: Threshold | C2: =Multiplier_Weight_Newbie!$C$2 -> 1000000000
B3: Coin in | C3: =Multiplier_Weight_Newbie!$C$3 -> 100
B5: Base Game (Normal Bet)
B6: Lower | C6: Upper | D6: Range | E6: Table | F6: Rate | G6: Weight_Newbie | H6: Weight_Oldhand
B7: =Multiplier_Weight_Newbie!B12 -> -1 | C7: =Multiplier_Weight_Newbie!C12 -> 0 | D7: =Multiplier_Weight_Newbie!P12 -> (-1, 0] | E7: =Multiplier_Weight_Newbie!Q12 -> B | F7: =Multiplier_Weight_Newbie!R12 -> 0.44990451 | G7: =Multiplier_Weight_Newbie!V12 -> 708422750 | H7: =Multiplier_Weight_Oldhand!V12 -> 745922560
B8: =Multiplier_Weight_Newbie!B13 -> 0 | C8: =Multiplier_Weight_Newbie!C13 -> 1 | D8: =Multiplier_Weight_Newbie!P13 -> (0, 1] | E8: =Multiplier_Weight_Newbie!Q13 -> B | F8: =Multiplier_Weight_Newbie!R13 -> 0.185693 | G8: =Multiplier_Weight_Newbie!V13 -> 147589383 | H8: =Multiplier_Weight_Oldhand!V13 -> 155717266
B9: =Multiplier_Weight_Newbie!B14 -> 1 | C9: =Multiplier_Weight_Newbie!C14 -> 2 | D9: =Multiplier_Weight_Newbie!P14 -> (1, 2] | E9: =Multiplier_Weight_Newbie!Q14 -> B | F9: =Multiplier_Weight_Newbie!R14 -> 0.046192621 | G9: =Multiplier_Weight_Newbie!V14 -> 36714042 | H9: =Multiplier_Weight_Oldhand!V14 -> 25973216
B10: =Multiplier_Weight_Newbie!B15 -> 2 | C10: =Multiplier_Weight_Newbie!C15 -> 3 | D10: =Multiplier_Weight_Newbie!P15 -> (2, 3] | E10: =Multiplier_Weight_Newbie!Q15 -> B | F10: =Multiplier_Weight_Newbie!R15 -> 0.029371641 | G10: =Multiplier_Weight_Newbie!V15 -> 23344673 | H10: =Multiplier_Weight_Oldhand!V15 -> 14806646
B11: =Multiplier_Weight_Newbie!B16 -> 3 | C11: =Multiplier_Weight_Newbie!C16 -> 4 | D11: =Multiplier_Weight_Newbie!P16 -> (3, 4] | E11: =Multiplier_Weight_Newbie!Q16 -> B | F11: =Multiplier_Weight_Newbie!R16 -> 0.020127639 | G11: =Multiplier_Weight_Newbie!V16 -> 16669406 | H11: =Multiplier_Weight_Oldhand!V16 -> 10341745
B12: =Multiplier_Weight_Newbie!B17 -> 4 | C12: =Multiplier_Weight_Newbie!C17 -> 5 | D12: =Multiplier_Weight_Newbie!P17 -> (4, 5] | E12: =Multiplier_Weight_Newbie!Q17 -> B | F12: =Multiplier_Weight_Newbie!R17 -> 0.01841617 | G12: =Multiplier_Weight_Newbie!V17 -> 11709784 | H12: =Multiplier_Weight_Oldhand!V17 -> 8926772
B13: =Multiplier_Weight_Newbie!B18 -> 5 | C13: =Multiplier_Weight_Newbie!C18 -> 6 | D13: =Multiplier_Weight_Newbie!P18 -> (5, 6] | E13: =Multiplier_Weight_Newbie!Q18 -> B | F13: =Multiplier_Weight_Newbie!R18 -> 0.014739624 | G13: =Multiplier_Weight_Newbie!V18 -> 11715099 | H13: =Multiplier_Weight_Oldhand!V18 -> 4286795
B14: =Multiplier_Weight_Newbie!B19 -> 6 | C14: =Multiplier_Weight_Newbie!C19 -> 7 | D14: =Multiplier_Weight_Newbie!P19 -> (6, 7] | E14: =Multiplier_Weight_Newbie!Q19 -> B | F14: =Multiplier_Weight_Newbie!R19 -> 0.013343814 | G14: =Multiplier_Weight_Newbie!V19 -> 8484564 | H14: =Multiplier_Weight_Oldhand!V19 -> 3880845
B15: =Multiplier_Weight_Newbie!B20 -> 7 | C15: =Multiplier_Weight_Newbie!C20 -> 8 | D15: =Multiplier_Weight_Newbie!P20 -> (7, 8] | E15: =Multiplier_Weight_Newbie!Q20 -> B | F15: =Multiplier_Weight_Newbie!R20 -> 0.011312157 | G15: =Multiplier_Weight_Newbie!V20 -> 8091844 | H15: =Multiplier_Weight_Oldhand!V20 -> 3289969
B16: =Multiplier_Weight_Newbie!B21 -> 8 | C16: =Multiplier_Weight_Newbie!C21 -> 9 | D16: =Multiplier_Weight_Newbie!P21 -> (8, 9] | E16: =Multiplier_Weight_Newbie!Q21 -> B | F16: =Multiplier_Weight_Newbie!R21 -> 0.010990033 | G16: =Multiplier_Weight_Newbie!V21 -> 6114439 | H16: =Multiplier_Weight_Oldhand!V21 -> 2983198
B17: =Multiplier_Weight_Newbie!B22 -> 9 | C17: =Multiplier_Weight_Newbie!C22 -> 10 | D17: =Multiplier_Weight_Newbie!P22 -> (9, 10] | E17: =Multiplier_Weight_Newbie!Q22 -> B | F17: =Multiplier_Weight_Newbie!R22 -> 0.0095209457 | G17: =Multiplier_Weight_Newbie!V22 -> 3329602 | H17: =Multiplier_Weight_Oldhand!V22 -> 2953623
B18: =Multiplier_Weight_Newbie!B23 -> 10 | C18: =Multiplier_Weight_Newbie!C23 -> 15 | D18: =Multiplier_Weight_Newbie!P23 -> (10, 15] | E18: =Multiplier_Weight_Newbie!Q23 -> B | F18: =Multiplier_Weight_Newbie!R23 -> 0.037302793 | G18: =Multiplier_Weight_Newbie!V23 -> 9324414 | H18: =Multiplier_Weight_Oldhand!V23 -> 5001366
... B59: =Multiplier_Weight_Newbie!B64 -> FG Trigger | C59: =Multiplier_Weight_Newbie!C64 -> 0.01010016 | D59: =Multiplier_Weight_Newbie!P64 -> (FG Trigger, 0.01010016] | E59: =Multiplier_Weight_Newbie!Q64 -> A | F59: =Multiplier_Weight_Newbie!R64 -> 0.00849 | G59: =Multiplier_Weight_Newbie!V64 -> 8490000 | H59: =Multiplier_Weight_Oldhand!V64 -> 8490000
B60: Total | G60: =SUM(G7:G59) -> 1000000000 | H60: =SUM(H7:H59) -> 1000000000
B63: Free Game
B64: Lower | C64: Upper | D64: Range | E64: Table | F64: Rate | G64: Weight_Newbie | H64: Weight_Oldhand
B65: =Multiplier_Weight_Newbie!B70 -> -1 | C65: =Multiplier_Weight_Newbie!C70 -> 0 | D65: =Multiplier_Weight_Newbie!P70 -> (-1, 0] | E65: =Multiplier_Weight_Newbie!Q70 -> E | F65: =Multiplier_Weight_Newbie!R70 -> 0.00031286633 | G65: =Multiplier_Weight_Newbie!V70 -> 0 | H65: =Multiplier_Weight_Oldhand!V70 -> 0
B66: =Multiplier_Weight_Newbie!B71 -> 0 | C66: =Multiplier_Weight_Newbie!C71 -> 1 | D66: =Multiplier_Weight_Newbie!P71 -> (0, 1] | E66: =Multiplier_Weight_Newbie!Q71 -> E | F66: =Multiplier_Weight_Newbie!R71 -> 0.0021999651 | G66: =Multiplier_Weight_Newbie!V71 -> 0 | H66: =Multiplier_Weight_Oldhand!V71 -> 0
B67: =Multiplier_Weight_Newbie!B72 -> 1 | C67: =Multiplier_Weight_Newbie!C72 -> 2 | D67: =Multiplier_Weight_Newbie!P72 -> (1, 2] | E67: =Multiplier_Weight_Newbie!Q72 -> E | F67: =Multiplier_Weight_Newbie!R72 -> 0.0027286696 | G67: =Multiplier_Weight_Newbie!V72 -> 0 | H67: =Multiplier_Weight_Oldhand!V72 -> 0
B68: =Multiplier_Weight_Newbie!B73 -> 2 | C68: =Multiplier_Weight_Newbie!C73 -> 3 | D68: =Multiplier_Weight_Newbie!P73 -> (2, 3] | E68: =Multiplier_Weight_Newbie!Q73 -> E | F68: =Multiplier_Weight_Newbie!R73 -> 0.0029930219 | G68: =Multiplier_Weight_Newbie!V73 -> 0 | H68: =Multiplier_Weight_Oldhand!V73 -> 0
B69: =Multiplier_Weight_Newbie!B74 -> 3 | C69: =Multiplier_Weight_Newbie!C74 -> 4 | D69: =Multiplier_Weight_Newbie!P74 -> (3, 4] | E69: =Multiplier_Weight_Newbie!Q74 -> E | F69: =Multiplier_Weight_Newbie!R74 -> 0.0030643079 | G69: =Multiplier_Weight_Newbie!V74 -> 0 | H69: =Multiplier_Weight_Oldhand!V74 -> 0
B70: =Multiplier_Weight_Newbie!B75 -> 4 | C70: =Multiplier_Weight_Newbie!C75 -> 5 | D70: =Multiplier_Weight_Newbie!P75 -> (4, 5] | E70: =Multiplier_Weight_Newbie!Q75 -> E | F70: =Multiplier_Weight_Newbie!R75 -> 0.0030375756 | G70: =Multiplier_Weight_Newbie!V75 -> 0 | H70: =Multiplier_Weight_Oldhand!V75 -> 0
B71: =Multiplier_Weight_Newbie!B76 -> 5 | C71: =Multiplier_Weight_Newbie!C76 -> 6 | D71: =Multiplier_Weight_Newbie!P76 -> (5, 6] | E71: =Multiplier_Weight_Newbie!Q76 -> E | F71: =Multiplier_Weight_Newbie!R76 -> 0.0031534154 | G71: =Multiplier_Weight_Newbie!V76 -> 0 | H71: =Multiplier_Weight_Oldhand!V76 -> 0
B72: =Multiplier_Weight_Newbie!B77 -> 6 | C72: =Multiplier_Weight_Newbie!C77 -> 7 | D72: =Multiplier_Weight_Newbie!P77 -> (6, 7] | E72: =Multiplier_Weight_Newbie!Q77 -> E | F72: =Multiplier_Weight_Newbie!R77 -> 0.0031831179 | G72: =Multiplier_Weight_Newbie!V77 -> 0 | H72: =Multiplier_Weight_Oldhand!V77 -> 0
B73: =Multiplier_Weight_Newbie!B78 -> 7 | C73: =Multiplier_Weight_Newbie!C78 -> 8 | D73: =Multiplier_Weight_Newbie!P78 -> (7, 8] | E73: =Multiplier_Weight_Newbie!Q78 -> E | F73: =Multiplier_Weight_Newbie!R78 -> 0.0030247046 | G73: =Multiplier_Weight_Newbie!V78 -> 0 | H73: =Multiplier_Weight_Oldhand!V78 -> 0
B74: =Multiplier_Weight_Newbie!B79 -> 8 | C74: =Multiplier_Weight_Newbie!C79 -> 9 | D74: =Multiplier_Weight_Newbie!P79 -> (8, 9] | E74: =Multiplier_Weight_Newbie!Q79 -> E | F74: =Multiplier_Weight_Newbie!R79 -> 0.0031237129 | G74: =Multiplier_Weight_Newbie!V79 -> 0 | H74: =Multiplier_Weight_Oldhand!V79 -> 0
B75: =Multiplier_Weight_Newbie!B80 -> 9 | C75: =Multiplier_Weight_Newbie!C80 -> 10 | D75: =Multiplier_Weight_Newbie!P80 -> (9, 10] | E75: =Multiplier_Weight_Newbie!Q80 -> E | F75: =Multiplier_Weight_Newbie!R80 -> 0.0032563841 | G75: =Multiplier_Weight_Newbie!V80 -> 0 | H75: =Multiplier_Weight_Oldhand!V80 -> 0
B76: =Multiplier_Weight_Newbie!B81 -> 10 | C76: =Multiplier_Weight_Newbie!C81 -> 15 | D76: =Multiplier_Weight_Newbie!P81 -> (10, 15] | E76: =Multiplier_Weight_Newbie!Q81 -> E | F76: =Multiplier_Weight_Newbie!R81 -> 0.016261129 | G76: =Multiplier_Weight_Newbie!V81 -> 0 | H76: =Multiplier_Weight_Oldhand!V81 -> 106801961
... B123: =Multiplier_Weight_Newbie!B128 -> 0 | C123: =Multiplier_Weight_Newbie!C128 -> 0 | D123: =Multiplier_Weight_Newbie!P128 -> (, ] | E123: =Multiplier_Weight_Newbie!Q128 -> E | F123: =Multiplier_Weight_Newbie!R128 -> 0 | G123: =Multiplier_Weight_Newbie!V128 -> 0 | H123: =Multiplier_Weight_Oldhand!V128 -> 0
B124: Total | G124: =SUM(G65:G123) -> 999999997 | H124: =SUM(H65:H123) -> 999999990
B127: Buy Feature
B128: Lower | C128: Upper | D128: Range | E128: Table | F128: Rate | G128: Weight_Newbie | H128: Weight_Oldhand
B129: =Multiplier_Weight_Newbie!B134 -> -1 | C129: =Multiplier_Weight_Newbie!C134 -> 0 | D129: =Multiplier_Weight_Newbie!P134 -> (-1, 0] | E129: =Multiplier_Weight_Newbie!Q134 -> E | F129: =Multiplier_Weight_Newbie!R134 -> 0.00031286633 | G129: =Multiplier_Weight_Newbie!V134 -> 0 | H129: =Multiplier_Weight_Oldhand!V134 -> 0
B130: =Multiplier_Weight_Newbie!B135 -> 0 | C130: =Multiplier_Weight_Newbie!C135 -> 1 | D130: =Multiplier_Weight_Newbie!P135 -> (0, 1] | E130: =Multiplier_Weight_Newbie!Q135 -> E | F130: =Multiplier_Weight_Newbie!R135 -> 0.0021999651 | G130: =Multiplier_Weight_Newbie!V135 -> 0 | H130: =Multiplier_Weight_Oldhand!V135 -> 0
B131: =Multiplier_Weight_Newbie!B136 -> 1 | C131: =Multiplier_Weight_Newbie!C136 -> 2 | D131: =Multiplier_Weight_Newbie!P136 -> (1, 2] | E131: =Multiplier_Weight_Newbie!Q136 -> E | F131: =Multiplier_Weight_Newbie!R136 -> 0.0027286696 | G131: =Multiplier_Weight_Newbie!V136 -> 0 | H131: =Multiplier_Weight_Oldhand!V136 -> 0
B132: =Multiplier_Weight_Newbie!B137 -> 2 | C132: =Multiplier_Weight_Newbie!C137 -> 3 | D132: =Multiplier_Weight_Newbie!P137 -> (2, 3] | E132: =Multiplier_Weight_Newbie!Q137 -> E | F132: =Multiplier_Weight_Newbie!R137 -> 0.0029930219 | G132: =Multiplier_Weight_Newbie!V137 -> 0 | H132: =Multiplier_Weight_Oldhand!V137 -> 0
...

Sheet Multiplier_Weight_Newbie
B2: Threshold | C2: =10^9 -> 1000000000
B3: Coin in | C3: 100
B4: Profile | C4: Newbie
B6: Bet | C6: Base Game | D6: Free Game | E6: Total | F6: Hit Rate | G6: Pulls/Hit
B7: Normal Bet | C7: =SUM(X12:X64) -> 0.66318572 | D7: =SUM(X70:X128)*W64 -> 0.26678737 | E7: =C7+W64*(SUM(X70:X128)+X64) -> 0.92999946 | F7: =W64 -> 0.00849 | G7: =IF(F7=0,0,1/F7) -> 117.78563
B8: Buy Feature | C8: 0 | D8: =SUM(X134:X192)/Parameter!$C$61 -> 0.9249974 | E8: =C8+D8 -> 0.9249974 | F8: 1 | G8: 1
B10: Base Game (Normal Bet) | D10: Simulator Cnt | G10: Simulator Pay | J10: Simulator Rate | M10: Simulator RTP
B11: Lower | C11: Upper | D11: A | E11: B | F11: C | G11: A | H11: B | I11: C | J11: A | K11: B | L11: C | M11: A | N11: B | O11: C | P11: Range | Q11: Table | R11: Rate | S11: Fix Num | T11: Fix Rate | U11: Final Rate | V11: Weight | W11: Hit Rate | X11: RTP
B12: -1 | C12: 0 | D12: 81444439 | E12: 44611398 | F12: 0 | G12: 0 | H12: 0 | I12: 0 | J12: =IF(SUM(D$12:D$63)=0,0,D12/SUM(D$12:D$63)) -> 0.82275434 | K12: =IF(SUM(E$12:E$63)=0,0,E12/SUM(E$12:E$63)) -> 0.44990451 | L12: =IF(SUM(F$12:F$63)=0,0,F12/SUM(F$12:F$63)) -> 0 | M12: =IF(D12=0,0,G12/D12/$C$3/5) -> 0 | N12: =IF(E12=0,0,H12/E12/$C$3/5) -> 0 | O12: =IF(F12=0,0,I12/F12/$C$3/5) -> 0 | P12: ="("&B12&", "&C12&"]" -> (-1, 0] | Q12: B | R12: =IFERROR(INDEX($J12:$L12,MATCH($Q12,$J$11:$L$11,0)),0) -> 0.44990451 | S12: 1.986 | T12: =$R12*$S12 -> 0.89351035 | U12: =IF(SUM(T$12:T$64)=0,0,T12/SUM(T$12:T$64)) -> 0.71016486 | V12: =INT($C$2-SUM(V13:V$64)) -> 708422750 | W12: =IF(SUM(V$12:V$64)=0,0,V12/SUM(V$12:V$64)) -> 0.70842275 | X12: =IFERROR(INDEX($M12:$O12,MATCH($Q12,$M$11:$O$11,0)),0)*V12/$C$2 -> 0
B13: 0 | C13: 1 | D13: 13113310 | E13: 18412850 | F13: 0 | G13: 2531346475 | H13: 3398022375 | I13: 0 | J13: =IF(SUM(D$12:D$63)=0,0,D13/SUM(D$12:D$63)) -> 0.13247108 | K13: =IF(SUM(E$12:E$63)=0,0,E13/SUM(E$12:E$63)) -> 0.185693 | L13: =IF(SUM(F$12:F$63)=0,0,F13/SUM(F$12:F$63)) -> 0 | M13: =IF(D13=0,0,G13/D13/$C$3/5) -> 0.38607285 | N13: =IF(E13=0,0,H13/E13/$C$3/5) -> 0.3690925 | O13: =IF(F13=0,0,I13/F13/$C$3/5) -> 0 | P13: ="("&B13&", "&C13&"]" -> (0, 1] | Q13: B | R13: =IFERROR(INDEX($J13:$L13,MATCH($Q13,$J$11:$L$11,0)),0) -> 0.185693 | S13: 1 | T13: =$R13*$S13 -> 0.185693 | U13: =IF(SUM(T$12:T$64)=0,0,T13/SUM(T$12:T$64)) -> 0.14758938 | V13: =INT(U13*$C$2) -> 147589383 | W13: =IF(SUM(V$12:V$64)=0,0,V13/SUM(V$12:V$64)) -> 0.14758938 | X13: =IFERROR(INDEX($M13:$O13,MATCH($Q13,$M$11:$O$11,0)),0)*V13/$C$2 -> 0.054474134
B14: 1 | C14: 2 | D14: 2076337 | E14: 4580344 | F14: 0 | G14: 1560262150 | H14: 3412133350 | I14: 0 | J14: =IF(SUM(D$12:D$63)=0,0,D14/SUM(D$12:D$63)) -> 0.020975223 | K14: =IF(SUM(E$12:E$63)=0,0,E14/SUM(E$12:E$63)) -> 0.046192621 | L14: =IF(SUM(F$12:F$63)=0,0,F14/SUM(F$12:F$63)) -> 0 | M14: =IF(D14=0,0,G14/D14/$C$3/5) -> 1.5028988 | N14: =IF(E14=0,0,H14/E14/$C$3/5) -> 1.4899027 | O14: =IF(F14=0,0,I14/F14/$C$3/5) -> 0 | P14: ="("&B14&", "&C14&"]" -> (1, 2] | Q14: B | R14: =IFERROR(INDEX($J14:$L14,MATCH($Q14,$J$11:$L$11,0)),0) -> 0.046192621 | S14: 1 | T14: =$R14*$S14 -> 0.046192621 | U14: =IF(SUM(T$12:T$64)=0,0,T14/SUM(T$12:T$64)) -> 0.036714042 | V14: =INT(U14*$C$2) -> 36714042 | W14: =IF(SUM(V$12:V$64)=0,0,V14/SUM(V$12:V$64)) -> 0.036714042 | X14: =IFERROR(INDEX($M14:$O14,MATCH($Q14,$M$11:$O$11,0)),0)*V14/$C$2 -> 0.054700349
B15: 2 | C15: 3 | D15: 894630 | E15: 2912418 | F15: 0 | G15: 1126665375 | H15: 3666796450 | I15: 0 | J15: =IF(SUM(D$12:D$63)=0,0,D15/SUM(D$12:D$63)) -> 0.009037581 | K15: =IF(SUM(E$12:E$63)=0,0,E15/SUM(E$12:E$63)) -> 0.029371641 | L15: =IF(SUM(F$12:F$63)=0,0,F15/SUM(F$12:F$63)) -> 0 | M15: =IF(D15=0,0,G15/D15/$C$3/5) -> 2.5187293 | N15: =IF(E15=0,0,H15/E15/$C$3/5) -> 2.5180427 | O15: =IF(F15=0,0,I15/F15/$C$3/5) -> 0 | P15: ="("&B15&", "&C15&"]" -> (2, 3] | Q15: B | R15: =IFERROR(INDEX($J15:$L15,MATCH($Q15,$J$11:$L$11,0)),0) -> 0.029371641 | S15: 1 | T15: =$R15*$S15 -> 0.029371641 | U15: =IF(SUM(T$12:T$64)=0,0,T15/SUM(T$12:T$64)) -> 0.023344674 | V15: =INT(U15*$C$2) -> 23344673 | W15: =IF(SUM(V$12:V$64)=0,0,V15/SUM(V$12:V$64)) -> 0.023344673 | X15: =IFERROR(INDEX($M15:$O15,MATCH($Q15,$M$11:$O$11,0)),0)*V15/$C$2 -> 0.058782884
B16: 3 | C16: 4 | D16: 457771 | E16: 1995806 | F16: 0 | G16: 815422300 | H16: 3530115825 | I16: 0 | J16: =IF(SUM(D$12:D$63)=0,0,D16/SUM(D$12:D$63)) -> 0.0046244174 | K16: =IF(SUM(E$12:E$63)=0,0,E16/SUM(E$12:E$63)) -> 0.020127639 | L16: =IF(SUM(F$12:F$63)=0,0,F16/SUM(F$12:F$63)) -> 0 | M16: =IF(D16=0,0,G16/D16/$C$3/5) -> 3.5625774 | N16: =IF(E16=0,0,H16/E16/$C$3/5) -> 3.537534 | O16: =IF(F16=0,0,I16/F16/$C$3/5) -> 0 | P16: ="("&B16&", "&C16&"]" -> (3, 4] | Q16: B | R16: =IFERROR(INDEX($J16:$L16,MATCH($Q16,$J$11:$L$11,0)),0) -> 0.020127639 | S16: 1.042 | T16: =$R16*$S16 -> 0.020973 | U16: =IF(SUM(T$12:T$64)=0,0,T16/SUM(T$12:T$64)) -> 0.016669407 | V16: =INT(U16*$C$2) -> 16669406 | W16: =IF(SUM(V$12:V$64)=0,0,V16/SUM(V$12:V$64)) -> 0.016669406 | X16: =IFERROR(INDEX($M16:$O16,MATCH($Q16,$M$11:$O$11,0)),0)*V16/$C$2 -> 0.058968591
B17: 4 | C17: 5 | D17: 297012 | E17: 1826101 | F17: 0 | G17: 670352000 | H17: 4129988800 | I17: 0 | J17: =IF(SUM(D$12:D$63)=0,0,D17/SUM(D$12:D$63)) -> 0.0030004248 | K17: =IF(SUM(E$12:E$63)=0,0,E17/SUM(E$12:E$63)) -> 0.01841617 | L17: =IF(SUM(F$12:F$63)=0,0,F17/SUM(F$12:F$63)) -> 0 | M17: =IF(D17=0,0,G17/D17/$C$3/5) -> 4.5139725 | N17: =IF(E17=0,0,H17/E17/$C$3/5) -> 4.5232863 | O17: =IF(F17=0,0,I17/F17/$C$3/5) -> 0 | P17: ="("&B17&", "&C17&"]" -> (4, 5] | Q17: B | R17: =IFERROR(INDEX($J17:$L17,MATCH($Q17,$J$11:$L$11,0)),0) -> 0.01841617 | S17: 0.8 | T17: =$R17*$S17 -> 0.014732936 | U17: =IF(SUM(T$12:T$64)=0,0,T17/SUM(T$12:T$64)) -> 0.011709784 | V17: =INT(U17*$C$2) -> 11709784 | W17: =IF(SUM(V$12:V$64)=0,0,V17/SUM(V$12:V$64)) -> 0.011709784 | X17: =IFERROR(INDEX($M17:$O17,MATCH($Q17,$M$11:$O$11,0)),0)*V17/$C$2 -> 0.052966705
B18: 5 | C18: 6 | D18: 177151 | E18: 1461544 | F18: 0 | G18: 491783775 | H18: 4037335500 | I18: 0 | J18: =IF(SUM(D$12:D$63)=0,0,D18/SUM(D$12:D$63)) -> 0.0017895851 | K18: =IF(SUM(E$12:E$63)=0,0,E18/SUM(E$12:E$63)) -> 0.014739624 | L18: =IF(SUM(F$12:F$63)=0,0,F18/SUM(F$12:F$63)) -> 0 | M18: =IF(D18=0,0,G18/D18/$C$3/5) -> 5.5521422 | N18: =IF(E18=0,0,H18/E18/$C$3/5) -> 5.524754 | O18: =IF(F18=0,0,I18/F18/$C$3/5) -> 0 | P18: ="("&B18&", "&C18&"]" -> (5, 6] | Q18: B | R18: =IFERROR(INDEX($J18:$L18,MATCH($Q18,$J$11:$L$11,0)),0) -> 0.014739624 | S18: 1 | T18: =$R18*$S18 -> 0.014739624 | U18: =IF(SUM(T$12:T$64)=0,0,T18/SUM(T$12:T$64)) -> 0.0117151 | V18: =INT(U18*$C$2) -> 11715099 | W18: =IF(SUM(V$12:V$64)=0,0,V18/SUM(V$12:V$64)) -> 0.011715099 | X18: =IFERROR(INDEX($M18:$O18,MATCH($Q18,$M$11:$O$11,0)),0)*V18/$C$2 -> 0.06472304
B19: 6 | C19: 7 | D19: 124646 | E19: 1323139 | F19: 0 | G19: 405090625 | H19: 4311237575 | I19: 0 | J19: =IF(SUM(D$12:D$63)=0,0,D19/SUM(D$12:D$63)) -> 0.0012591779 | K19: =IF(SUM(E$12:E$63)=0,0,E19/SUM(E$12:E$63)) -> 0.013343814 | L19: =IF(SUM(F$12:F$63)=0,0,F19/SUM(F$12:F$63)) -> 0 | M19: =IF(D19=0,0,G19/D19/$C$3/5) -> 6.4998576 | N19: =IF(E19=0,0,H19/E19/$C$3/5) -> 6.5166813 | O19: =IF(F19=0,0,I19/F19/$C$3/5) -> 0 | P19: ="("&B19&", "&C19&"]" -> (6, 7] | Q19: B | R19: =IFERROR(INDEX($J19:$L19,MATCH($Q19,$J$11:$L$11,0)),0) -> 0.013343814 | S19: 0.8 | T19: =$R19*$S19 -> 0.010675051 | U19: =IF(SUM(T$12:T$64)=0,0,T19/SUM(T$12:T$64)) -> 0.0084845646 | V19: =INT(U19*$C$2) -> 8484564 | W19: =IF(SUM(V$12:V$64)=0,0,V19/SUM(V$12:V$64)) -> 0.008484564 | X19: =IFERROR(INDEX($M19:$O19,MATCH($Q19,$M$11:$O$11,0)),0)*V19/$C$2 -> 0.055291199
B20: 7 | C20: 8 | D20: 84482 | E20: 1121685 | F20: 0 | G20: 319837600 | H20: 4225509550 | I20: 0 | J20: =IF(SUM(D$12:D$63)=0,0,D20/SUM(D$12:D$63)) -> 0.00085343988 | K20: =IF(SUM(E$12:E$63)=0,0,E20/SUM(E$12:E$63)) -> 0.011312157 | L20: =IF(SUM(F$12:F$63)=0,0,F20/SUM(F$12:F$63)) -> 0 | M20: =IF(D20=0,0,G20/D20/$C$3/5) -> 7.5717336 | N20: =IF(E20=0,0,H20/E20/$C$3/5) -> 7.5342178 | O20: =IF(F20=0,0,I20/F20/$C$3/5) -> 0 | P20: ="("&B20&", "&C20&"]" -> (7, 8] | Q20: B | R20: =IFERROR(INDEX($J20:$L20,MATCH($Q20,$J$11:$L$11,0)),0) -> 0.011312157 | S20: 0.9 | T20: =$R20*$S20 -> 0.010180941 | U20: =IF(SUM(T$12:T$64)=0,0,T20/SUM(T$12:T$64)) -> 0.0080918445 | V20: =INT(U20*$C$2) -> 8091844 | W20: =IF(SUM(V$12:V$64)=0,0,V20/SUM(V$12:V$64)) -> 0.008091844 | X20: =IFERROR(INDEX($M20:$O20,MATCH($Q20,$M$11:$O$11,0)),0)*V20/$C$2 -> 0.060965715
B21: 8 | C21: 9 | D21: 71204 | E21: 1089744 | F21: 0 | G21: 303032850 | H21: 4639783525 | I21: 0 | J21: =IF(SUM(D$12:D$63)=0,0,D21/SUM(D$12:D$63)) -> 0.0007193051 | K21: =IF(SUM(E$12:E$63)=0,0,E21/SUM(E$12:E$63)) -> 0.010990033 | L21: =IF(SUM(F$12:F$63)=0,0,F21/SUM(F$12:F$63)) -> 0 | M21: =IF(D21=0,0,G21/D21/$C$3/5) -> 8.5116805 | N21: =IF(E21=0,0,H21/E21/$C$3/5) -> 8.5153642 | O21: =IF(F21=0,0,I21/F21/$C$3/5) -> 0 | P21: ="("&B21&", "&C21&"]" -> (8, 9] | Q21: B | R21: =IFERROR(INDEX($J21:$L21,MATCH($Q21,$J$11:$L$11,0)),0) -> 0.010990033 | S21: 0.7 | T21: =$R21*$S21 -> 0.0076930231 | U21: =IF(SUM(T$12:T$64)=0,0,T21/SUM(T$12:T$64)) -> 0.0061144392 | V21: =INT(U21*$C$2) -> 6114439 | W21: =IF(SUM(V$12:V$64)=0,0,V21/SUM(V$12:V$64)) -> 0.006114439 | X21: =IFERROR(INDEX($M21:$O21,MATCH($Q21,$M$11:$O$11,0)),0)*V21/$C$2 -> 0.052066675
B22: 9 | C22: 10 | D22: 48023 | E22: 944073 | F22: 0 | G22: 228958500 | H22: 4499878525 | I22: 0 | J22: =IF(SUM(D$12:D$63)=0,0,D22/SUM(D$12:D$63)) -> 0.00048512989 | K22: =IF(SUM(E$12:E$63)=0,0,E22/SUM(E$12:E$63)) -> 0.0095209457 | L22: =IF(SUM(F$12:F$63)=0,0,F22/SUM(F$12:F$63)) -> 0 | M22: =IF(D22=0,0,G22/D22/$C$3/5) -> 9.5353685 | N22: =IF(E22=0,0,H22/E22/$C$3/5) -> 9.5329038 | O22: =IF(F22=0,0,I22/F22/$C$3/5) -> 0 | P22: ="("&B22&", "&C22&"]" -> (9, 10] | Q22: B | R22: =IFERROR(INDEX($J22:$L22,MATCH($Q22,$J$11:$L$11,0)),0) -> 0.0095209457 | S22: 0.44 | T22: =$R22*$S22 -> 0.0041892161 | U22: =IF(SUM(T$12:T$64)=0,0,T22/SUM(T$12:T$64)) -> 0.0033296023 | V22: =INT(U22*$C$2) -> 3329602 | W22: =IF(SUM(V$12:V$64)=0,0,V22/SUM(V$12:V$64)) -> 0.003329602 | X22: =IFERROR(INDEX($M22:$O22,MATCH($Q22,$M$11:$O$11,0)),0)*V22/$C$2 -> 0.031740775
B23: 10 | C23: 15 | D23: 117843 | E23: 3698851 | F23: 0 | G23: 711361275 | H23: 22888608900 | I23: 0 | J23: =IF(SUM(D$12:D$63)=0,0,D23/SUM(D$12:D$63)) -> 0.0011904538 | K23: =IF(SUM(E$12:E$63)=0,0,E23/SUM(E$12:E$63)) -> 0.037302793 | L23: =IF(SUM(F$12:F$63)=0,0,F23/SUM(F$12:F$63)) -> 0 | M23: =IF(D23=0,0,G23/D23/$C$3/5) -> 12.073034 | N23: =IF(E23=0,0,H23/E23/$C$3/5) -> 12.376064 | O23: =IF(F23=0,0,I23/F23/$C$3/5) -> 0 | P23: ="("&B23&", "&C23&"]" -> (10, 15] | Q23: B | R23: =IFERROR(INDEX($J23:$L23,MATCH($Q23,$J$11:$L$11,0)),0) -> 0.037302793 | S23: 0.3145 | T23: =$R23*$S23 -> 0.011731728 | U23: =IF(SUM(T$12:T$64)=0,0,T23/SUM(T$12:T$64)) -> 0.0093244149 | V23: =INT(U23*$C$2) -> 9324414 | W23: =IF(SUM(V$12:V$64)=0,0,V23/SUM(V$12:V$64)) -> 0.009324414 | X23: =IFERROR(INDEX($M23:$O23,MATCH($Q23,$M$11:$O$11,0)),0)*V23/$C$2 -> 0.11539955
B24: 15 | C24: 20 | D24: 45036 | E24: 2622561 | F24: 0 | G24: 386935925 | H24: 22832281425 | I24: 0 | J24: =IF(SUM(D$12:D$63)=0,0,D24/SUM(D$12:D$63)) -> 0.00045495512 | K24: =IF(SUM(E$12:E$63)=0,0,E24/SUM(E$12:E$63)) -> 0.026448443 | L24: =IF(SUM(F$12:F$63)=0,0,F24/SUM(F$12:F$63)) -> 0 | M24: =IF(D24=0,0,G24/D24/$C$3/5) -> 17.183405 | N24: =IF(E24=0,0,H24/E24/$C$3/5) -> 17.412202 | O24: =IF(F24=0,0,I24/F24/$C$3/5) -> 0 | P24: ="("&B24&", "&C24&"]" -> (15, 20] | Q24: B | R24: =IFERROR(INDEX($J24:$L24,MATCH($Q24,$J$11:$L$11,0)),0) -> 0.026448443 | S24: 0 | T24: =$R24*$S24 -> 0 | U24: =IF(SUM(T$12:T$64)=0,0,T24/SUM(T$12:T$64)) -> 0 | V24: =INT(U24*$C$2) -> 0 | W24: =IF(SUM(V$12:V$64)=0,0,V24/SUM(V$12:V$64)) -> 0 | X24: =IFERROR(INDEX($M24:$O24,MATCH($Q24,$M$11:$O$11,0)),0)*V24/$C$2 -> 0
... B63: 7000 | C63: 8000 | D63: 0 | E63: 0 | F63: 0 | G63: 0 | H63: 0 | I63: 0 | J63: =IF(SUM(D$12:D$63)=0,0,D63/SUM(D$12:D$63)) -> 0 | K63: =IF(SUM(E$12:E$63)=0,0,E63/SUM(E$12:E$63)) -> 0 | L63: =IF(SUM(F$12:F$63)=0,0,F63/SUM(F$12:F$63)) -> 0 | M63: =IF(D63=0,0,G63/D63/$C$3/5) -> 0 | N63: =IF(E63=0,0,H63/E63/$C$3/5) -> 0 | O63: =IF(F63=0,0,I63/F63/$C$3/5) -> 0 | P63: ="("&B63&", "&C63&"]" -> (7000, 8000] | Q63: B | R63: =IFERROR(INDEX($J63:$L63,MATCH($Q63,$J$11:$L$11,0)),0) -> 0 | S63: 0 | T63: =$R63*$S63 -> 0 | U63: =IF(SUM(T$12:T$64)=0,0,T63/SUM(T$12:T$64)) -> 0 | V63: =INT(U63*$C$2) -> 0 | W63: =IF(SUM(V$12:V$64)=0,0,V63/SUM(V$12:V$64)) -> 0 | X63: =IFERROR(INDEX($M63:$O63,MATCH($Q63,$M$11:$O$11,0)),0)*V63/$C$2 -> 0
B64: FG Trigger | C64: 0.01010016 | D64: 1010016 | E64: 842518 | F64: 0 | G64: 184759625 | H64: 12104979525 | I64: 0 | J64: =IF(SUM(D$12:D$63)=0,0,D64/SUM(D$12:D$63)) -> 0.010203214 | K64: =IF(SUM(E$12:E$63)=0,0,E64/SUM(E$12:E$63)) -> 0.0084967668 | L64: =IF(SUM(F$12:F$63)=0,0,F64/SUM(F$12:F$63)) -> 0 | M64: =IF(D64=0,0,G64/D64/$C$3/5) -> 0.36585485 | N64: =IF(E64=0,0,H64/E64/$C$3/5) -> 28.735243 | O64: =IF(F64=0,0,I64/F64/$C$3/5) -> 0 | P64: ="("&B64&", "&C64&"]" -> (FG Trigger, 0.01010016] | Q64: A | R64: 0.00849 | S64: 1 | T64: =$R64*$S64 -> 0.00849 | U64: =T64 -> 0.00849 | V64: =INT(U64*$C$2) -> 8490000 | W64: =IF(SUM(V$12:V$64)=0,0,V64/SUM(V$12:V$64)) -> 0.00849 | X64: =IFERROR(INDEX($M64:$O64,MATCH($Q64,$M$11:$O$11,0)),0)*V64/$C$2 -> 0.0031061077
B65: Total | V65: =SUM(V12:V64) -> 1000000000
B68: Free Game | D68: Simulator Cnt | G68: Simulator Pay | J68: Simulator Rate | M68: Simulator RTP
B69: Lower | C69: Upper | D69: D | E69: E | F69: F | G69: D | H69: E | I69: F | J69: D | K69: E | L69: F | M69: D | N69: E | O69: F | P69: Range | Q69: Table | R69: Rate | S69: Fix Num | T69: Fix Rate | U69: Final Rate | V69: Weight | W69: Hit Rate | X69: RTP
B70: -1 | C70: 0 | D70: 0 | E70: 316 | F70: 0 | G70: 0 | H70: 0 | I70: 0 | J70: =IF(SUM(D$70:D$128)=0,0,D70/SUM(D$70:D$128)) -> 0 | K70: =IF(SUM(E$70:E$128)=0,0,E70/SUM(E$70:E$128)) -> 0.00031286633 | L70: =IF(SUM(F$70:F$128)=0,0,F70/SUM(F$70:F$128)) -> 0 | M70: =IF(D70=0,0,G70/D70/$C$3/5) -> 0 | N70: =IF(E70=0,0,H70/E70/$C$3/5) -> 0 | O70: =IF(F70=0,0,I70/F70/$C$3/5) -> 0 | P70: ="("&B70&", "&C70&"]" -> (-1, 0] | Q70: E | R70: =IFERROR(INDEX($J70:$L70,MATCH($Q70,$J$69:$L$69,0)),0) -> 0.00031286633 | S70: 0 | T70: =$R70*$S70 -> 0 | U70: =IF(SUM(T$70:T$128)=0,0,T70/SUM(T$70:T$128)) -> 0 | V70: =INT(U70*$C$2) -> 0 | W70: =IF(SUM(V$70:V$128)=0,0,V70/SUM(V$70:V$128)) -> 0 | X70: =IFERROR(INDEX($M70:$O70,MATCH($Q70,$M$69:$O$69,0)),0)*V70/$C$2 -> 0
B71: 0 | C71: 1 | D71: 0 | E71: 2222 | F71: 0 | G71: 0 | H71: 676000 | I71: 0 | J71: =IF(SUM(D$70:D$128)=0,0,D71/SUM(D$70:D$128)) -> 0 | K71: =IF(SUM(E$70:E$128)=0,0,E71/SUM(E$70:E$128)) -> 0.0021999651 | L71: =IF(SUM(F$70:F$128)=0,0,F71/SUM(F$70:F$128)) -> 0 | M71: =IF(D71=0,0,G71/D71/$C$3/5) -> 0 | N71: =IF(E71=0,0,H71/E71/$C$3/5) -> 0.60846085 | O71: =IF(F71=0,0,I71/F71/$C$3/5) -> 0 | P71: ="("&B71&", "&C71&"]" -> (0, 1] | Q71: E | R71: =IFERROR(INDEX($J71:$L71,MATCH($Q71,$J$69:$L$69,0)),0) -> 0.0021999651 | S71: 0 | T71: =$R71*$S71 -> 0 | U71: =IF(SUM(T$70:T$128)=0,0,T71/SUM(T$70:T$128)) -> 0 | V71: =INT(U71*$C$2) -> 0 | W71: =IF(SUM(V$70:V$128)=0,0,V71/SUM(V$70:V$128)) -> 0 | X71: =IFERROR(INDEX($M71:$O71,MATCH($Q71,$M$69:$O$69,0)),0)*V71/$C$2 -> 0
B72: 1 | C72: 2 | D72: 0 | E72: 2756 | F72: 0 | G72: 0 | H72: 2169950 | I72: 0 | J72: =IF(SUM(D$70:D$128)=0,0,D72/SUM(D$70:D$128)) -> 0 | K72: =IF(SUM(E$70:E$128)=0,0,E72/SUM(E$70:E$128)) -> 0.0027286696 | L72: =IF(SUM(F$70:F$128)=0,0,F72/SUM(F$70:F$128)) -> 0 | M72: =IF(D72=0,0,G72/D72/$C$3/5) -> 0 | N72: =IF(E72=0,0,H72/E72/$C$3/5) -> 1.5747097 | O72: =IF(F72=0,0,I72/F72/$C$3/5) -> 0 | P72: ="("&B72&", "&C72&"]" -> (1, 2] | Q72: E | R72: =IFERROR(INDEX($J72:$L72,MATCH($Q72,$J$69:$L$69,0)),0) -> 0.0027286696 | S72: 0 | T72: =$R72*$S72 -> 0 | U72: =IF(SUM(T$70:T$128)=0,0,T72/SUM(T$70:T$128)) -> 0 | V72: =INT(U72*$C$2) -> 0 | W72: =IF(SUM(V$70:V$128)=0,0,V72/SUM(V$70:V$128)) -> 0 | X72: =IFERROR(INDEX($M72:$O72,MATCH($Q72,$M$69:$O$69,0)),0)*V72/$C$2 -> 0
B73: 2 | C73: 3 | D73: 0 | E73: 3023 | F73: 0 | G73: 0 | H73: 3886500 | I73: 0 | J73: =IF(SUM(D$70:D$128)=0,0,D73/SUM(D$70:D$128)) -> 0 | K73: =IF(SUM(E$70:E$128)=0,0,E73/SUM(E$70:E$128)) -> 0.0029930219 | L73: =IF(SUM(F$70:F$128)=0,0,F73/SUM(F$70:F$128)) -> 0 | M73: =IF(D73=0,0,G73/D73/$C$3/5) -> 0 | N73: =IF(E73=0,0,H73/E73/$C$3/5) -> 2.5712868 | O73: =IF(F73=0,0,I73/F73/$C$3/5) -> 0 | P73: ="("&B73&", "&C73&"]" -> (2, 3] | Q73: E | R73: =IFERROR(INDEX($J73:$L73,MATCH($Q73,$J$69:$L$69,0)),0) -> 0.0029930219 | S73: 0 | T73: =$R73*$S73 -> 0 | U73: =IF(SUM(T$70:T$128)=0,0,T73/SUM(T$70:T$128)) -> 0 | V73: =INT(U73*$C$2) -> 0 | W73: =IF(SUM(V$70:V$128)=0,0,V73/SUM(V$70:V$128)) -> 0 | X73: =IFERROR(INDEX($M73:$O73,MATCH($Q73,$M$69:$O$69,0)),0)*V73/$C$2 -> 0
B74: 3 | C74: 4 | D74: 0 | E74: 3095 | F74: 0 | G74: 0 | H74: 5503800 | I74: 0 | J74: =IF(SUM(D$70:D$128)=0,0,D74/SUM(D$70:D$128)) -> 0 | K74: =IF(SUM(E$70:E$128)=0,0,E74/SUM(E$70:E$128)) -> 0.0030643079 | L74: =IF(SUM(F$70:F$128)=0,0,F74/SUM(F$70:F$128)) -> 0 | M74: =IF(D74=0,0,G74/D74/$C$3/5) -> 0 | N74: =IF(E74=0,0,H74/E74/$C$3/5) -> 3.5565751 | O74: =IF(F74=0,0,I74/F74/$C$3/5) -> 0 | P74: ="("&B74&", "&C74&"]" -> (3, 4] | Q74: E | R74: =IFERROR(INDEX($J74:$L74,MATCH($Q74,$J$69:$L$69,0)),0) -> 0.0030643079 | S74: 0 | T74: =$R74*$S74 -> 0 | U74: =IF(SUM(T$70:T$128)=0,0,T74/SUM(T$70:T$128)) -> 0 | V74: =INT(U74*$C$2) -> 0 | W74: =IF(SUM(V$70:V$128)=0,0,V74/SUM(V$70:V$128)) -> 0 | X74: =IFERROR(INDEX($M74:$O74,MATCH($Q74,$M$69:$O$69,0)),0)*V74/$C$2 -> 0
B75: 4 | C75: 5 | D75: 0 | E75: 3068 | F75: 0 | G75: 0 | H75: 7011850 | I75: 0 | J75: =IF(SUM(D$70:D$128)=0,0,D75/SUM(D$70:D$128)) -> 0 | K75: =IF(SUM(E$70:E$128)=0,0,E75/SUM(E$70:E$128)) -> 0.0030375756 | L75: =IF(SUM(F$70:F$128)=0,0,F75/SUM(F$70:F$128)) -> 0 | M75: =IF(D75=0,0,G75/D75/$C$3/5) -> 0 | N75: =IF(E75=0,0,H75/E75/$C$3/5) -> 4.5709583 | O75: =IF(F75=0,0,I75/F75/$C$3/5) -> 0 | P75: ="("&B75&", "&C75&"]" -> (4, 5] | Q75: E | R75: =IFERROR(INDEX($J75:$L75,MATCH($Q75,$J$69:$L$69,0)),0) -> 0.0030375756 | S75: 0 | T75: =$R75*$S75 -> 0 | U75: =IF(SUM(T$70:T$128)=0,0,T75/SUM(T$70:T$128)) -> 0 | V75: =INT(U75*$C$2) -> 0 | W75: =IF(SUM(V$70:V$128)=0,0,V75/SUM(V$70:V$128)) -> 0 | X75: =IFERROR(INDEX($M75:$O75,MATCH($Q75,$M$69:$O$69,0)),0)*V75/$C$2 -> 0
B76: 5 | C76: 6 | D76: 0 | E76: 3185 | F76: 0 | G76: 0 | H76: 8850050 | I76: 0 | J76: =IF(SUM(D$70:D$128)=0,0,D76/SUM(D$70:D$128)) -> 0 | K76: =IF(SUM(E$70:E$128)=0,0,E76/SUM(E$70:E$128)) -> 0.0031534154 | L76: =IF(SUM(F$70:F$128)=0,0,F76/SUM(F$70:F$128)) -> 0 | M76: =IF(D76=0,0,G76/D76/$C$3/5) -> 0 | N76: =IF(E76=0,0,H76/E76/$C$3/5) -> 5.5573312 | O76: =IF(F76=0,0,I76/F76/$C$3/5) -> 0 | P76: ="("&B76&", "&C76&"]" -> (5, 6] | Q76: E | R76: =IFERROR(INDEX($J76:$L76,MATCH($Q76,$J$69:$L$69,0)),0) -> 0.0031534154 | S76: 0 | T76: =$R76*$S76 -> 0 | U76: =IF(SUM(T$70:T$128)=0,0,T76/SUM(T$70:T$128)) -> 0 | V76: =INT(U76*$C$2) -> 0 | W76: =IF(SUM(V$70:V$128)=0,0,V76/SUM(V$70:V$128)) -> 0 | X76: =IFERROR(INDEX($M76:$O76,MATCH($Q76,$M$69:$O$69,0)),0)*V76/$C$2 -> 0
B77: 6 | C77: 7 | D77: 0 | E77: 3215 | F77: 0 | G77: 0 | H77: 10540600 | I77: 0 | J77: =IF(SUM(D$70:D$128)=0,0,D77/SUM(D$70:D$128)) -> 0 | K77: =IF(SUM(E$70:E$128)=0,0,E77/SUM(E$70:E$128)) -> 0.0031831179 | L77: =IF(SUM(F$70:F$128)=0,0,F77/SUM(F$70:F$128)) -> 0 | M77: =IF(D77=0,0,G77/D77/$C$3/5) -> 0 | N77: =IF(E77=0,0,H77/E77/$C$3/5) -> 6.5571384 | O77: =IF(F77=0,0,I77/F77/$C$3/5) -> 0 | P77: ="("&B77&", "&C77&"]" -> (6, 7] | Q77: E | R77: =IFERROR(INDEX($J77:$L77,MATCH($Q77,$J$69:$L$69,0)),0) -> 0.0031831179 | S77: 0 | T77: =$R77*$S77 -> 0 | U77: =IF(SUM(T$70:T$128)=0,0,T77/SUM(T$70:T$128)) -> 0 | V77: =INT(U77*$C$2) -> 0 | W77: =IF(SUM(V$70:V$128)=0,0,V77/SUM(V$70:V$128)) -> 0 | X77: =IFERROR(INDEX($M77:$O77,MATCH($Q77,$M$69:$O$69,0)),0)*V77/$C$2 -> 0
B78: 7 | C78: 8 | D78: 0 | E78: 3055 | F78: 0 | G78: 0 | H78: 11542100 | I78: 0 | J78: =IF(SUM(D$70:D$128)=0,0,D78/SUM(D$70:D$128)) -> 0 | K78: =IF(SUM(E$70:E$128)=0,0,E78/SUM(E$70:E$128)) -> 0.0030247046 | L78: =IF(SUM(F$70:F$128)=0,0,F78/SUM(F$70:F$128)) -> 0 | M78: =IF(D78=0,0,G78/D78/$C$3/5) -> 0 | N78: =IF(E78=0,0,H78/E78/$C$3/5) -> 7.5562029 | O78: =IF(F78=0,0,I78/F78/$C$3/5) -> 0 | P78: ="("&B78&", "&C78&"]" -> (7, 8] | Q78: E | R78: =IFERROR(INDEX($J78:$L78,MATCH($Q78,$J$69:$L$69,0)),0) -> 0.0030247046 | S78: 0 | T78: =$R78*$S78 -> 0 | U78: =IF(SUM(T$70:T$128)=0,0,T78/SUM(T$70:T$128)) -> 0 | V78: =INT(U78*$C$2) -> 0 | W78: =IF(SUM(V$70:V$128)=0,0,V78/SUM(V$70:V$128)) -> 0 | X78: =IFERROR(INDEX($M78:$O78,MATCH($Q78,$M$69:$O$69,0)),0)*V78/$C$2 -> 0
B79: 8 | C79: 9 | D79: 0 | E79: 3155 | F79: 0 | G79: 0 | H79: 13497550 | I79: 0 | J79: =IF(SUM(D$70:D$128)=0,0,D79/SUM(D$70:D$128)) -> 0 | K79: =IF(SUM(E$70:E$128)=0,0,E79/SUM(E$70:E$128)) -> 0.0031237129 | L79: =IF(SUM(F$70:F$128)=0,0,F79/SUM(F$70:F$128)) -> 0 | M79: =IF(D79=0,0,G79/D79/$C$3/5) -> 0 | N79: =IF(E79=0,0,H79/E79/$C$3/5) -> 8.5562916 | O79: =IF(F79=0,0,I79/F79/$C$3/5) -> 0 | P79: ="("&B79&", "&C79&"]" -> (8, 9] | Q79: E | R79: =IFERROR(INDEX($J79:$L79,MATCH($Q79,$J$69:$L$69,0)),0) -> 0.0031237129 | S79: 0 | T79: =$R79*$S79 -> 0 | U79: =IF(SUM(T$70:T$128)=0,0,T79/SUM(T$70:T$128)) -> 0 | V79: =INT(U79*$C$2) -> 0 | W79: =IF(SUM(V$70:V$128)=0,0,V79/SUM(V$70:V$128)) -> 0 | X79: =IFERROR(INDEX($M79:$O79,MATCH($Q79,$M$69:$O$69,0)),0)*V79/$C$2 -> 0
B80: 9 | C80: 10 | D80: 0 | E80: 3289 | F80: 0 | G80: 0 | H80: 15750950 | I80: 0 | J80: =IF(SUM(D$70:D$128)=0,0,D80/SUM(D$70:D$128)) -> 0 | K80: =IF(SUM(E$70:E$128)=0,0,E80/SUM(E$70:E$128)) -> 0.0032563841 | L80: =IF(SUM(F$70:F$128)=0,0,F80/SUM(F$70:F$128)) -> 0 | M80: =IF(D80=0,0,G80/D80/$C$3/5) -> 0 | N80: =IF(E80=0,0,H80/E80/$C$3/5) -> 9.5779568 | O80: =IF(F80=0,0,I80/F80/$C$3/5) -> 0 | P80: ="("&B80&", "&C80&"]" -> (9, 10] | Q80: E | R80: =IFERROR(INDEX($J80:$L80,MATCH($Q80,$J$69:$L$69,0)),0) -> 0.0032563841 | S80: 0 | T80: =$R80*$S80 -> 0 | U80: =IF(SUM(T$70:T$128)=0,0,T80/SUM(T$70:T$128)) -> 0 | V80: =INT(U80*$C$2) -> 0 | W80: =IF(SUM(V$70:V$128)=0,0,V80/SUM(V$70:V$128)) -> 0 | X80: =IFERROR(INDEX($M80:$O80,MATCH($Q80,$M$69:$O$69,0)),0)*V80/$C$2 -> 0
B81: 10 | C81: 15 | D81: 0 | E81: 16424 | F81: 0 | G81: 0 | H81: 103238050 | I81: 0 | J81: =IF(SUM(D$70:D$128)=0,0,D81/SUM(D$70:D$128)) -> 0 | K81: =IF(SUM(E$70:E$128)=0,0,E81/SUM(E$70:E$128)) -> 0.016261129 | L81: =IF(SUM(F$70:F$128)=0,0,F81/SUM(F$70:F$128)) -> 0 | M81: =IF(D81=0,0,G81/D81/$C$3/5) -> 0 | N81: =IF(E81=0,0,H81/E81/$C$3/5) -> 12.571609 | O81: =IF(F81=0,0,I81/F81/$C$3/5) -> 0 | P81: ="("&B81&", "&C81&"]" -> (10, 15] | Q81: E | R81: =IFERROR(INDEX($J81:$L81,MATCH($Q81,$J$69:$L$69,0)),0) -> 0.016261129 | S81: 0 | T81: =$R81*$S81 -> 0 | U81: =IF(SUM(T$70:T$128)=0,0,T81/SUM(T$70:T$128)) -> 0 | V81: =INT(U81*$C$2) -> 0 | W81: =IF(SUM(V$70:V$128)=0,0,V81/SUM(V$70:V$128)) -> 0 | X81: =IFERROR(INDEX($M81:$O81,MATCH($Q81,$M$69:$O$69,0)),0)*V81/$C$2 -> 0
... B121: 7000 | C121: 8000 | D121: 0 | E121: 0 | F121: 0 | G121: 0 | H121: 0 | I121: 0 | J121: =IF(SUM(D$70:D$128)=0,0,D121/SUM(D$70:D$128)) -> 0 | K121: =IF(SUM(E$70:E$128)=0,0,E121/SUM(E$70:E$128)) -> 0 | L121: =IF(SUM(F$70:F$128)=0,0,F121/SUM(F$70:F$128)) -> 0 | M121: =IF(D121=0,0,G121/D121/$C$3/5) -> 0 | N121: =IF(E121=0,0,H121/E121/$C$3/5) -> 0 | O121: =IF(F121=0,0,I121/F121/$C$3/5) -> 0 | P121: ="("&B121&", "&C121&"]" -> (7000, 8000] | Q121: E | R121: =IFERROR(INDEX($J121:$L121,MATCH($Q121,$J$69:$L$69,0)),0) -> 0 | S121: 0 | T121: =$R121*$S121 -> 0 | U121: =IF(SUM(T$70:T$128)=0,0,T121/SUM(T$70:T$128)) -> 0 | V121: =INT(U121*$C$2) -> 0 | W121: =IF(SUM(V$70:V$128)=0,0,V121/SUM(V$70:V$128)) -> 0 | X121: =IFERROR(INDEX($M121:$O121,MATCH($Q121,$M$69:$O$69,0)),0)*V121/$C$2 -> 0
D122: 0 | E122: 0 | F122: 0 | G122: 0 | H122: 0 | I122: 0 | J122: =IF(SUM(D$70:D$128)=0,0,D122/SUM(D$70:D$128)) -> 0 | K122: =IF(SUM(E$70:E$128)=0,0,E122/SUM(E$70:E$128)) -> 0 | L122: =IF(SUM(F$70:F$128)=0,0,F122/SUM(F$70:F$128)) -> 0 | M122: =IF(D122=0,0,G122/D122/$C$3/5) -> 0 | N122: =IF(E122=0,0,H122/E122/$C$3/5) -> 0 | O122: =IF(F122=0,0,I122/F122/$C$3/5) -> 0 | P122: ="("&B122&", "&C122&"]" -> (, ] | Q122: E | R122: =IFERROR(INDEX($J122:$L122,MATCH($Q122,$J$69:$L$69,0)),0) -> 0 | S122: 0 | T122: =$R122*$S122 -> 0 | U122: =IF(SUM(T$70:T$128)=0,0,T122/SUM(T$70:T$128)) -> 0 | V122: =INT(U122*$C$2) -> 0 | W122: =IF(SUM(V$70:V$128)=0,0,V122/SUM(V$70:V$128)) -> 0 | X122: =IFERROR(INDEX($M122:$O122,MATCH($Q122,$M$69:$O$69,0)),0)*V122/$C$2 -> 0
...

Sheet Multiplier_Weight_Oldhand
B2: Threshold | C2: =10^9 -> 1000000000
B3: Coin in | C3: 100
B4: Profile | C4: Oldhand
B6: Bet | C6: Base Game | D6: Free Game | E6: Total | F6: Hit Rate | G6: Pulls/Hit
B7: Normal Bet | C7: =SUM(X12:X64) -> 0.66712158 | D7: =SUM(X70:X128)*W64 -> 0.2728177 | E7: =C7+W64*(SUM(X70:X128)+X64) -> 0.93996565 | F7: =W64 -> 0.00849 | G7: =IF(F7=0,0,1/F7) -> 117.78563
B8: Buy Feature | C8: 0 | D8: =SUM(X134:X192)/Parameter!$C$61 -> 0.98529689 | E8: =C8+D8 -> 0.98529689 | F8: 1 | G8: 1
B10: Base Game (Normal Bet) | D10: Simulator Cnt | G10: Simulator Pay | J10: Simulator Rate | M10: Simulator RTP
B11: Lower | C11: Upper | D11: A | E11: B | F11: C | G11: A | H11: B | I11: C | J11: A | K11: B | L11: C | M11: A | N11: B | O11: C | P11: Range | Q11: Table | R11: Rate | S11: Fix Num | T11: Fix Rate | U11: Final Rate | V11: Weight | W11: Hit Rate | X11: RTP
B12: -1 | C12: 0 | D12: 81444439 | E12: 44611398 | F12: 0 | G12: 0 | H12: 0 | I12: 0 | J12: =IF(SUM(D$12:D$63)=0,0,D12/SUM(D$12:D$63)) -> 0.82275434 | K12: =IF(SUM(E$12:E$63)=0,0,E12/SUM(E$12:E$63)) -> 0.44990451 | L12: =IF(SUM(F$12:F$63)=0,0,F12/SUM(F$12:F$63)) -> 0 | M12: =IF(D12=0,0,G12/D12/$C$3/5) -> 0 | N12: =IF(E12=0,0,H12/E12/$C$3/5) -> 0 | O12: =IF(F12=0,0,I12/F12/$C$3/5) -> 0 | P12: ="("&B12&", "&C12&"]" -> (-1, 0] | Q12: B | R12: =IFERROR(INDEX($J12:$L12,MATCH($Q12,$J$11:$L$11,0)),0) -> 0.44990451 | S12: 1.7108 | T12: =$R12*$S12 -> 0.76969663 | U12: =IF(SUM(T$12:T$64)=0,0,T12/SUM(T$12:T$64)) -> 0.74618192 | V12: =INT($C$2-SUM(V13:V$64)) -> 745922560 | W12: =IF(SUM(V$12:V$64)=0,0,V12/SUM(V$12:V$64)) -> 0.74592256 | X12: =IFERROR(INDEX($M12:$O12,MATCH($Q12,$M$11:$O$11,0)),0)*V12/$C$2 -> 0
B13: 0 | C13: 1 | D13: 13113310 | E13: 18412850 | F13: 0 | G13: 2531346475 | H13: 3398022375 | I13: 0 | J13: =IF(SUM(D$12:D$63)=0,0,D13/SUM(D$12:D$63)) -> 0.13247108 | K13: =IF(SUM(E$12:E$63)=0,0,E13/SUM(E$12:E$63)) -> 0.185693 | L13: =IF(SUM(F$12:F$63)=0,0,F13/SUM(F$12:F$63)) -> 0 | M13: =IF(D13=0,0,G13/D13/$C$3/5) -> 0.38607285 | N13: =IF(E13=0,0,H13/E13/$C$3/5) -> 0.3690925 | O13: =IF(F13=0,0,I13/F13/$C$3/5) -> 0 | P13: ="("&B13&", "&C13&"]" -> (0, 1] | Q13: B | R13: =IFERROR(INDEX($J13:$L13,MATCH($Q13,$J$11:$L$11,0)),0) -> 0.185693 | S13: 0.865 | T13: =$R13*$S13 -> 0.16062444 | U13: =IF(SUM(T$12:T$64)=0,0,T13/SUM(T$12:T$64)) -> 0.15571727 | V13: =INT(U13*$C$2) -> 155717266 | W13: =IF(SUM(V$12:V$64)=0,0,V13/SUM(V$12:V$64)) -> 0.15571727 | X13: =IFERROR(INDEX($M13:$O13,MATCH($Q13,$M$11:$O$11,0)),0)*V13/$C$2 -> 0.057474074
B14: 1 | C14: 2 | D14: 2076337 | E14: 4580344 | F14: 0 | G14: 1560262150 | H14: 3412133350 | I14: 0 | J14: =IF(SUM(D$12:D$63)=0,0,D14/SUM(D$12:D$63)) -> 0.020975223 | K14: =IF(SUM(E$12:E$63)=0,0,E14/SUM(E$12:E$63)) -> 0.046192621 | L14: =IF(SUM(F$12:F$63)=0,0,F14/SUM(F$12:F$63)) -> 0 | M14: =IF(D14=0,0,G14/D14/$C$3/5) -> 1.5028988 | N14: =IF(E14=0,0,H14/E14/$C$3/5) -> 1.4899027 | O14: =IF(F14=0,0,I14/F14/$C$3/5) -> 0 | P14: ="("&B14&", "&C14&"]" -> (1, 2] | Q14: B | R14: =IFERROR(INDEX($J14:$L14,MATCH($Q14,$J$11:$L$11,0)),0) -> 0.046192621 | S14: 0.58 | T14: =$R14*$S14 -> 0.02679172 | U14: =IF(SUM(T$12:T$64)=0,0,T14/SUM(T$12:T$64)) -> 0.025973217 | V14: =INT(U14*$C$2) -> 25973216 | W14: =IF(SUM(V$12:V$64)=0,0,V14/SUM(V$12:V$64)) -> 0.025973216 | X14: =IFERROR(INDEX($M14:$O14,MATCH($Q14,$M$11:$O$11,0)),0)*V14/$C$2 -> 0.038697564
B15: 2 | C15: 3 | D15: 894630 | E15: 2912418 | F15: 0 | G15: 1126665375 | H15: 3666796450 | I15: 0 | J15: =IF(SUM(D$12:D$63)=0,0,D15/SUM(D$12:D$63)) -> 0.009037581 | K15: =IF(SUM(E$12:E$63)=0,0,E15/SUM(E$12:E$63)) -> 0.029371641 | L15: =IF(SUM(F$12:F$63)=0,0,F15/SUM(F$12:F$63)) -> 0 | M15: =IF(D15=0,0,G15/D15/$C$3/5) -> 2.5187293 | N15: =IF(E15=0,0,H15/E15/$C$3/5) -> 2.5180427 | O15: =IF(F15=0,0,I15/F15/$C$3/5) -> 0 | P15: ="("&B15&", "&C15&"]" -> (2, 3] | Q15: B | R15: =IFERROR(INDEX($J15:$L15,MATCH($Q15,$J$11:$L$11,0)),0) -> 0.029371641 | S15: 0.52 | T15: =$R15*$S15 -> 0.015273254 | U15: =IF(SUM(T$12:T$64)=0,0,T15/SUM(T$12:T$64)) -> 0.014806646 | V15: =INT(U15*$C$2) -> 14806646 | W15: =IF(SUM(V$12:V$64)=0,0,V15/SUM(V$12:V$64)) -> 0.014806646 | X15: =IFERROR(INDEX($M15:$O15,MATCH($Q15,$M$11:$O$11,0)),0)*V15/$C$2 -> 0.037283767
B16: 3 | C16: 4 | D16: 457771 | E16: 1995806 | F16: 0 | G16: 815422300 | H16: 3530115825 | I16: 0 | J16: =IF(SUM(D$12:D$63)=0,0,D16/SUM(D$12:D$63)) -> 0.0046244174 | K16: =IF(SUM(E$12:E$63)=0,0,E16/SUM(E$12:E$63)) -> 0.020127639 | L16: =IF(SUM(F$12:F$63)=0,0,F16/SUM(F$12:F$63)) -> 0 | M16: =IF(D16=0,0,G16/D16/$C$3/5) -> 3.5625774 | N16: =IF(E16=0,0,H16/E16/$C$3/5) -> 3.537534 | O16: =IF(F16=0,0,I16/F16/$C$3/5) -> 0 | P16: ="("&B16&", "&C16&"]" -> (3, 4] | Q16: B | R16: =IFERROR(INDEX($J16:$L16,MATCH($Q16,$J$11:$L$11,0)),0) -> 0.020127639 | S16: 0.53 | T16: =$R16*$S16 -> 0.010667649 | U16: =IF(SUM(T$12:T$64)=0,0,T16/SUM(T$12:T$64)) -> 0.010341745 | V16: =INT(U16*$C$2) -> 10341745 | W16: =IF(SUM(V$12:V$64)=0,0,V16/SUM(V$12:V$64)) -> 0.010341745 | X16: =IFERROR(INDEX($M16:$O16,MATCH($Q16,$M$11:$O$11,0)),0)*V16/$C$2 -> 0.036584275
B17: 4 | C17: 5 | D17: 297012 | E17: 1826101 | F17: 0 | G17: 670352000 | H17: 4129988800 | I17: 0 | J17: =IF(SUM(D$12:D$63)=0,0,D17/SUM(D$12:D$63)) -> 0.0030004248 | K17: =IF(SUM(E$12:E$63)=0,0,E17/SUM(E$12:E$63)) -> 0.01841617 | L17: =IF(SUM(F$12:F$63)=0,0,F17/SUM(F$12:F$63)) -> 0 | M17: =IF(D17=0,0,G17/D17/$C$3/5) -> 4.5139725 | N17: =IF(E17=0,0,H17/E17/$C$3/5) -> 4.5232863 | O17: =IF(F17=0,0,I17/F17/$C$3/5) -> 0 | P17: ="("&B17&", "&C17&"]" -> (4, 5] | Q17: B | R17: =IFERROR(INDEX($J17:$L17,MATCH($Q17,$J$11:$L$11,0)),0) -> 0.01841617 | S17: 0.5 | T17: =$R17*$S17 -> 0.0092080848 | U17: =IF(SUM(T$12:T$64)=0,0,T17/SUM(T$12:T$64)) -> 0.0089267721 | V17: =INT(U17*$C$2) -> 8926772 | W17: =IF(SUM(V$12:V$64)=0,0,V17/SUM(V$12:V$64)) -> 0.008926772 | X17: =IFERROR(INDEX($M17:$O17,MATCH($Q17,$M$11:$O$11,0)),0)*V17/$C$2 -> 0.040378345
B18: 5 | C18: 6 | D18: 177151 | E18: 1461544 | F18: 0 | G18: 491783775 | H18: 4037335500 | I18: 0 | J18: =IF(SUM(D$12:D$63)=0,0,D18/SUM(D$12:D$63)) -> 0.0017895851 | K18: =IF(SUM(E$12:E$63)=0,0,E18/SUM(E$12:E$63)) -> 0.014739624 | L18: =IF(SUM(F$12:F$63)=0,0,F18/SUM(F$12:F$63)) -> 0 | M18: =IF(D18=0,0,G18/D18/$C$3/5) -> 5.5521422 | N18: =IF(E18=0,0,H18/E18/$C$3/5) -> 5.524754 | O18: =IF(F18=0,0,I18/F18/$C$3/5) -> 0 | P18: ="("&B18&", "&C18&"]" -> (5, 6] | Q18: B | R18: =IFERROR(INDEX($J18:$L18,MATCH($Q18,$J$11:$L$11,0)),0) -> 0.014739624 | S18: 0.3 | T18: =$R18*$S18 -> 0.0044218872 | U18: =IF(SUM(T$12:T$64)=0,0,T18/SUM(T$12:T$64)) -> 0.0042867958 | V18: =INT(U18*$C$2) -> 4286795 | W18: =IF(SUM(V$12:V$64)=0,0,V18/SUM(V$12:V$64)) -> 0.004286795 | X18: =IFERROR(INDEX($M18:$O18,MATCH($Q18,$M$11:$O$11,0)),0)*V18/$C$2 -> 0.023683488
B19: 6 | C19: 7 | D19: 124646 | E19: 1323139 | F19: 0 | G19: 405090625 | H19: 4311237575 | I19: 0 | J19: =IF(SUM(D$12:D$63)=0,0,D19/SUM(D$12:D$63)) -> 0.0012591779 | K19: =IF(SUM(E$12:E$63)=0,0,E19/SUM(E$12:E$63)) -> 0.013343814 | L19: =IF(SUM(F$12:F$63)=0,0,F19/SUM(F$12:F$63)) -> 0 | M19: =IF(D19=0,0,G19/D19/$C$3/5) -> 6.4998576 | N19: =IF(E19=0,0,H19/E19/$C$3/5) -> 6.5166813 | O19: =IF(F19=0,0,I19/F19/$C$3/5) -> 0 | P19: ="("&B19&", "&C19&"]" -> (6, 7] | Q19: B | R19: =IFERROR(INDEX($J19:$L19,MATCH($Q19,$J$11:$L$11,0)),0) -> 0.013343814 | S19: 0.3 | T19: =$R19*$S19 -> 0.0040031442 | U19: =IF(SUM(T$12:T$64)=0,0,T19/SUM(T$12:T$64)) -> 0.0038808457 | V19: =INT(U19*$C$2) -> 3880845 | W19: =IF(SUM(V$12:V$64)=0,0,V19/SUM(V$12:V$64)) -> 0.003880845 | X19: =IFERROR(INDEX($M19:$O19,MATCH($Q19,$M$11:$O$11,0)),0)*V19/$C$2 -> 0.02529023
B20: 7 | C20: 8 | D20: 84482 | E20: 1121685 | F20: 0 | G20: 319837600 | H20: 4225509550 | I20: 0 | J20: =IF(SUM(D$12:D$63)=0,0,D20/SUM(D$12:D$63)) -> 0.00085343988 | K20: =IF(SUM(E$12:E$63)=0,0,E20/SUM(E$12:E$63)) -> 0.011312157 | L20: =IF(SUM(F$12:F$63)=0,0,F20/SUM(F$12:F$63)) -> 0 | M20: =IF(D20=0,0,G20/D20/$C$3/5) -> 7.5717336 | N20: =IF(E20=0,0,H20/E20/$C$3/5) -> 7.5342178 | O20: =IF(F20=0,0,I20/F20/$C$3/5) -> 0 | P20: ="("&B20&", "&C20&"]" -> (7, 8] | Q20: B | R20: =IFERROR(INDEX($J20:$L20,MATCH($Q20,$J$11:$L$11,0)),0) -> 0.011312157 | S20: 0.3 | T20: =$R20*$S20 -> 0.0033936471 | U20: =IF(SUM(T$12:T$64)=0,0,T20/SUM(T$12:T$64)) -> 0.0032899691 | V20: =INT(U20*$C$2) -> 3289969 | W20: =IF(SUM(V$12:V$64)=0,0,V20/SUM(V$12:V$64)) -> 0.003289969 | X20: =IFERROR(INDEX($M20:$O20,MATCH($Q20,$M$11:$O$11,0)),0)*V20/$C$2 -> 0.024787343
B21: 8 | C21: 9 | D21: 71204 | E21: 1089744 | F21: 0 | G21: 303032850 | H21: 4639783525 | I21: 0 | J21: =IF(SUM(D$12:D$63)=0,0,D21/SUM(D$12:D$63)) -> 0.0007193051 | K21: =IF(SUM(E$12:E$63)=0,0,E21/SUM(E$12:E$63)) -> 0.010990033 | L21: =IF(SUM(F$12:F$63)=0,0,F21/SUM(F$12:F$63)) -> 0 | M21: =IF(D21=0,0,G21/D21/$C$3/5) -> 8.5116805 | N21: =IF(E21=0,0,H21/E21/$C$3/5) -> 8.5153642 | O21: =IF(F21=0,0,I21/F21/$C$3/5) -> 0 | P21: ="("&B21&", "&C21&"]" -> (8, 9] | Q21: B | R21: =IFERROR(INDEX($J21:$L21,MATCH($Q21,$J$11:$L$11,0)),0) -> 0.010990033 | S21: 0.28 | T21: =$R21*$S21 -> 0.0030772092 | U21: =IF(SUM(T$12:T$64)=0,0,T21/SUM(T$12:T$64)) -> 0.0029831986 | V21: =INT(U21*$C$2) -> 2983198 | W21: =IF(SUM(V$12:V$64)=0,0,V21/SUM(V$12:V$64)) -> 0.002983198 | X21: =IFERROR(INDEX($M21:$O21,MATCH($Q21,$M$11:$O$11,0)),0)*V21/$C$2 -> 0.025403017
B22: 9 | C22: 10 | D22: 48023 | E22: 944073 | F22: 0 | G22: 228958500 | H22: 4499878525 | I22: 0 | J22: =IF(SUM(D$12:D$63)=0,0,D22/SUM(D$12:D$63)) -> 0.00048512989 | K22: =IF(SUM(E$12:E$63)=0,0,E22/SUM(E$12:E$63)) -> 0.0095209457 | L22: =IF(SUM(F$12:F$63)=0,0,F22/SUM(F$12:F$63)) -> 0 | M22: =IF(D22=0,0,G22/D22/$C$3/5) -> 9.5353685 | N22: =IF(E22=0,0,H22/E22/$C$3/5) -> 9.5329038 | O22: =IF(F22=0,0,I22/F22/$C$3/5) -> 0 | P22: ="("&B22&", "&C22&"]" -> (9, 10] | Q22: B | R22: =IFERROR(INDEX($J22:$L22,MATCH($Q22,$J$11:$L$11,0)),0) -> 0.0095209457 | S22: 0.32 | T22: =$R22*$S22 -> 0.0030467026 | U22: =IF(SUM(T$12:T$64)=0,0,T22/SUM(T$12:T$64)) -> 0.002953624 | V22: =INT(U22*$C$2) -> 2953623 | W22: =IF(SUM(V$12:V$64)=0,0,V22/SUM(V$12:V$64)) -> 0.002953623 | X22: =IFERROR(INDEX($M22:$O22,MATCH($Q22,$M$11:$O$11,0)),0)*V22/$C$2 -> 0.028156604
B23: 10 | C23: 15 | D23: 117843 | E23: 3698851 | F23: 0 | G23: 711361275 | H23: 22888608900 | I23: 0 | J23: =IF(SUM(D$12:D$63)=0,0,D23/SUM(D$12:D$63)) -> 0.0011904538 | K23: =IF(SUM(E$12:E$63)=0,0,E23/SUM(E$12:E$63)) -> 0.037302793 | L23: =IF(SUM(F$12:F$63)=0,0,F23/SUM(F$12:F$63)) -> 0 | M23: =IF(D23=0,0,G23/D23/$C$3/5) -> 12.073034 | N23: =IF(E23=0,0,H23/E23/$C$3/5) -> 12.376064 | O23: =IF(F23=0,0,I23/F23/$C$3/5) -> 0 | P23: ="("&B23&", "&C23&"]" -> (10, 15] | Q23: B | R23: =IFERROR(INDEX($J23:$L23,MATCH($Q23,$J$11:$L$11,0)),0) -> 0.037302793 | S23: 0.1383 | T23: =$R23*$S23 -> 0.0051589762 | U23: =IF(SUM(T$12:T$64)=0,0,T23/SUM(T$12:T$64)) -> 0.0050013663 | V23: =INT(U23*$C$2) -> 5001366 | W23: =IF(SUM(V$12:V$64)=0,0,V23/SUM(V$12:V$64)) -> 0.005001366 | X23: =IFERROR(INDEX($M23:$O23,MATCH($Q23,$M$11:$O$11,0)),0)*V23/$C$2 -> 0.061897227
B24: 15 | C24: 20 | D24: 45036 | E24: 2622561 | F24: 0 | G24: 386935925 | H24: 22832281425 | I24: 0 | J24: =IF(SUM(D$12:D$63)=0,0,D24/SUM(D$12:D$63)) -> 0.00045495512 | K24: =IF(SUM(E$12:E$63)=0,0,E24/SUM(E$12:E$63)) -> 0.026448443 | L24: =IF(SUM(F$12:F$63)=0,0,F24/SUM(F$12:F$63)) -> 0 | M24: =IF(D24=0,0,G24/D24/$C$3/5) -> 17.183405 | N24: =IF(E24=0,0,H24/E24/$C$3/5) -> 17.412202 | O24: =IF(F24=0,0,I24/F24/$C$3/5) -> 0 | P24: ="("&B24&", "&C24&"]" -> (15, 20] | Q24: B | R24: =IFERROR(INDEX($J24:$L24,MATCH($Q24,$J$11:$L$11,0)),0) -> 0.026448443 | S24: 0.1 | T24: =$R24*$S24 -> 0.0026448443 | U24: =IF(SUM(T$12:T$64)=0,0,T24/SUM(T$12:T$64)) -> 0.0025640427 | V24: =INT(U24*$C$2) -> 2564042 | W24: =IF(SUM(V$12:V$64)=0,0,V24/SUM(V$12:V$64)) -> 0.002564042 | X24: =IFERROR(INDEX($M24:$O24,MATCH($Q24,$M$11:$O$11,0)),0)*V24/$C$2 -> 0.044645618
... B63: 7000 | C63: 8000 | D63: 0 | E63: 0 | F63: 0 | G63: 0 | H63: 0 | I63: 0 | J63: =IF(SUM(D$12:D$63)=0,0,D63/SUM(D$12:D$63)) -> 0 | K63: =IF(SUM(E$12:E$63)=0,0,E63/SUM(E$12:E$63)) -> 0 | L63: =IF(SUM(F$12:F$63)=0,0,F63/SUM(F$12:F$63)) -> 0 | M63: =IF(D63=0,0,G63/D63/$C$3/5) -> 0 | N63: =IF(E63=0,0,H63/E63/$C$3/5) -> 0 | O63: =IF(F63=0,0,I63/F63/$C$3/5) -> 0 | P63: ="("&B63&", "&C63&"]" -> (7000, 8000] | Q63: B | R63: =IFERROR(INDEX($J63:$L63,MATCH($Q63,$J$11:$L$11,0)),0) -> 0 | S63: 0 | T63: =$R63*$S63 -> 0 | U63: =IF(SUM(T$12:T$64)=0,0,T63/SUM(T$12:T$64)) -> 0 | V63: =INT(U63*$C$2) -> 0 | W63: =IF(SUM(V$12:V$64)=0,0,V63/SUM(V$12:V$64)) -> 0 | X63: =IFERROR(INDEX($M63:$O63,MATCH($Q63,$M$11:$O$11,0)),0)*V63/$C$2 -> 0
B64: FG Trigger | C64: 0.01010016 | D64: 1010016 | E64: 842518 | F64: 0 | G64: 184759625 | H64: 12104979525 | I64: 0 | J64: =IF(SUM(D$12:D$63)=0,0,D64/SUM(D$12:D$63)) -> 0.010203214 | K64: =IF(SUM(E$12:E$63)=0,0,E64/SUM(E$12:E$63)) -> 0.0084967668 | L64: =IF(SUM(F$12:F$63)=0,0,F64/SUM(F$12:F$63)) -> 0 | M64: =IF(D64=0,0,G64/D64/$C$3/5) -> 0.36585485 | N64: =IF(E64=0,0,H64/E64/$C$3/5) -> 28.735243 | O64: =IF(F64=0,0,I64/F64/$C$3/5) -> 0 | P64: ="("&B64&", "&C64&"]" -> (FG Trigger, 0.01010016] | Q64: A | R64: 0.00849 | S64: 1 | T64: =$R64*$S64 -> 0.00849 | U64: =T64 -> 0.00849 | V64: =INT(U64*$C$2) -> 8490000 | W64: =IF(SUM(V$12:V$64)=0,0,V64/SUM(V$12:V$64)) -> 0.00849 | X64: =IFERROR(INDEX($M64:$O64,MATCH($Q64,$M$11:$O$11,0)),0)*V64/$C$2 -> 0.0031061077
B65: Total | V65: =SUM(V12:V64) -> 1000000000
B68: Free Game | D68: Simulator Cnt | G68: Simulator Pay | J68: Simulator Rate | M68: Simulator RTP
B69: Lower | C69: Upper | D69: D | E69: E | F69: F | G69: D | H69: E | I69: F | J69: D | K69: E | L69: F | M69: D | N69: E | O69: F | P69: Range | Q69: Table | R69: Rate | S69: Fix Num | T69: Fix Rate | U69: Final Rate | V69: Weight | W69: Hit Rate | X69: RTP
B70: -1 | C70: 0 | D70: 0 | E70: 316 | F70: 0 | G70: 0 | H70: 0 | I70: 0 | J70: =IF(SUM(D$70:D$128)=0,0,D70/SUM(D$70:D$128)) -> 0 | K70: =IF(SUM(E$70:E$128)=0,0,E70/SUM(E$70:E$128)) -> 0.00031286633 | L70: =IF(SUM(F$70:F$128)=0,0,F70/SUM(F$70:F$128)) -> 0 | M70: =IF(D70=0,0,G70/D70/$C$3/5) -> 0 | N70: =IF(E70=0,0,H70/E70/$C$3/5) -> 0 | O70: =IF(F70=0,0,I70/F70/$C$3/5) -> 0 | P70: ="("&B70&", "&C70&"]" -> (-1, 0] | Q70: E | R70: =IFERROR(INDEX($J70:$L70,MATCH($Q70,$J$69:$L$69,0)),0) -> 0.00031286633 | S70: 0 | T70: =$R70*$S70 -> 0 | U70: =IF(SUM(T$70:T$128)=0,0,T70/SUM(T$70:T$128)) -> 0 | V70: =INT(U70*$C$2) -> 0 | W70: =IF(SUM(V$70:V$128)=0,0,V70/SUM(V$70:V$128)) -> 0 | X70: =IFERROR(INDEX($M70:$O70,MATCH($Q70,$M$69:$O$69,0)),0)*V70/$C$2 -> 0
B71: 0 | C71: 1 | D71: 0 | E71: 2222 | F71: 0 | G71: 0 | H71: 676000 | I71: 0 | J71: =IF(SUM(D$70:D$128)=0,0,D71/SUM(D$70:D$128)) -> 0 | K71: =IF(SUM(E$70:E$128)=0,0,E71/SUM(E$70:E$128)) -> 0.0021999651 | L71: =IF(SUM(F$70:F$128)=0,0,F71/SUM(F$70:F$128)) -> 0 | M71: =IF(D71=0,0,G71/D71/$C$3/5) -> 0 | N71: =IF(E71=0,0,H71/E71/$C$3/5) -> 0.60846085 | O71: =IF(F71=0,0,I71/F71/$C$3/5) -> 0 | P71: ="("&B71&", "&C71&"]" -> (0, 1] | Q71: E | R71: =IFERROR(INDEX($J71:$L71,MATCH($Q71,$J$69:$L$69,0)),0) -> 0.0021999651 | S71: 0 | T71: =$R71*$S71 -> 0 | U71: =IF(SUM(T$70:T$128)=0,0,T71/SUM(T$70:T$128)) -> 0 | V71: =INT(U71*$C$2) -> 0 | W71: =IF(SUM(V$70:V$128)=0,0,V71/SUM(V$70:V$128)) -> 0 | X71: =IFERROR(INDEX($M71:$O71,MATCH($Q71,$M$69:$O$69,0)),0)*V71/$C$2 -> 0
B72: 1 | C72: 2 | D72: 0 | E72: 2756 | F72: 0 | G72: 0 | H72: 2169950 | I72: 0 | J72: =IF(SUM(D$70:D$128)=0,0,D72/SUM(D$70:D$128)) -> 0 | K72: =IF(SUM(E$70:E$128)=0,0,E72/SUM(E$70:E$128)) -> 0.0027286696 | L72: =IF(SUM(F$70:F$128)=0,0,F72/SUM(F$70:F$128)) -> 0 | M72: =IF(D72=0,0,G72/D72/$C$3/5) -> 0 | N72: =IF(E72=0,0,H72/E72/$C$3/5) -> 1.5747097 | O72: =IF(F72=0,0,I72/F72/$C$3/5) -> 0 | P72: ="("&B72&", "&C72&"]" -> (1, 2] | Q72: E | R72: =IFERROR(INDEX($J72:$L72,MATCH($Q72,$J$69:$L$69,0)),0) -> 0.0027286696 | S72: 0 | T72: =$R72*$S72 -> 0 | U72: =IF(SUM(T$70:T$128)=0,0,T72/SUM(T$70:T$128)) -> 0 | V72: =INT(U72*$C$2) -> 0 | W72: =IF(SUM(V$70:V$128)=0,0,V72/SUM(V$70:V$128)) -> 0 | X72: =IFERROR(INDEX($M72:$O72,MATCH($Q72,$M$69:$O$69,0)),0)*V72/$C$2 -> 0
B73: 2 | C73: 3 | D73: 0 | E73: 3023 | F73: 0 | G73: 0 | H73: 3886500 | I73: 0 | J73: =IF(SUM(D$70:D$128)=0,0,D73/SUM(D$70:D$128)) -> 0 | K73: =IF(SUM(E$70:E$128)=0,0,E73/SUM(E$70:E$128)) -> 0.0029930219 | L73: =IF(SUM(F$70:F$128)=0,0,F73/SUM(F$70:F$128)) -> 0 | M73: =IF(D73=0,0,G73/D73/$C$3/5) -> 0 | N73: =IF(E73=0,0,H73/E73/$C$3/5) -> 2.5712868 | O73: =IF(F73=0,0,I73/F73/$C$3/5) -> 0 | P73: ="("&B73&", "&C73&"]" -> (2, 3] | Q73: E | R73: =IFERROR(INDEX($J73:$L73,MATCH($Q73,$J$69:$L$69,0)),0) -> 0.0029930219 | S73: 0 | T73: =$R73*$S73 -> 0 | U73: =IF(SUM(T$70:T$128)=0,0,T73/SUM(T$70:T$128)) -> 0 | V73: =INT(U73*$C$2) -> 0 | W73: =IF(SUM(V$70:V$128)=0,0,V73/SUM(V$70:V$128)) -> 0 | X73: =IFERROR(INDEX($M73:$O73,MATCH($Q73,$M$69:$O$69,0)),0)*V73/$C$2 -> 0
B74: 3 | C74: 4 | D74: 0 | E74: 3095 | F74: 0 | G74: 0 | H74: 5503800 | I74: 0 | J74: =IF(SUM(D$70:D$128)=0,0,D74/SUM(D$70:D$128)) -> 0 | K74: =IF(SUM(E$70:E$128)=0,0,E74/SUM(E$70:E$128)) -> 0.0030643079 | L74: =IF(SUM(F$70:F$128)=0,0,F74/SUM(F$70:F$128)) -> 0 | M74: =IF(D74=0,0,G74/D74/$C$3/5) -> 0 | N74: =IF(E74=0,0,H74/E74/$C$3/5) -> 3.5565751 | O74: =IF(F74=0,0,I74/F74/$C$3/5) -> 0 | P74: ="("&B74&", "&C74&"]" -> (3, 4] | Q74: E | R74: =IFERROR(INDEX($J74:$L74,MATCH($Q74,$J$69:$L$69,0)),0) -> 0.0030643079 | S74: 0 | T74: =$R74*$S74 -> 0 | U74: =IF(SUM(T$70:T$128)=0,0,T74/SUM(T$70:T$128)) -> 0 | V74: =INT(U74*$C$2) -> 0 | W74: =IF(SUM(V$70:V$128)=0,0,V74/SUM(V$70:V$128)) -> 0 | X74: =IFERROR(INDEX($M74:$O74,MATCH($Q74,$M$69:$O$69,0)),0)*V74/$C$2 -> 0
