Workbook

Sheet Overview
A2: Model: | B2: H026192
A3: Version: | B3: 1.0.0.9
A6: Base Bet
A7: 100
A10: Coin in | B10: Price(x) | C10: Total RTP | D10: Bet Type
A11: {=B11:B13*A7} -> 100 | B11: 1 | C11: =SUM(B18:B19) -> 0.93999978 | D11: Normal Bet
A12: 200 | B12: 2 | C12: =B22+B23 -> 0.94000017 | D12: Extra Bet
A13: 7500 | B13: 75 | C13: =SUM(B26:B27) -> 0.92499989 | D13: Buy Feature
A16: Total Pay Back Percentage includes the following adjustments.
A17: Bet Type | B17: Pay Back | C17: Hit% | D17: Pulls/Hit | E17: Description
A18: =D11 -> Normal Bet | B18: =Multiplier_Weight_Oldhand!C7 -> 0.6999997 | C18: =1/D18 -> 0.0041782419 | D18: =Multiplier_Weight_Oldhand!G7 -> 239.33511 | E18: Base Game
B19: =Multiplier_Weight_Oldhand!D7 -> 0.24000008 | E19: Free Game
A21: Bet Type | B21: Pay Back | C21: Hit% | D21: Pulls/Hit | E21: Description
A22: =D12 -> Extra Bet | B22: =Multiplier_Weight_Oldhand!C8 -> 0.34020708 | C22: =1/D22 -> 0.020883998 | D22: =Multiplier_Weight_Oldhand!G8 -> 47.883551 | E22: Base Game
B23: =Multiplier_Weight_Oldhand!D8 -> 0.59979309 | E23: Free Game
A25: Bet Type | B25: Pay Back | C25: Hit% | D25: Pulls/Hit | E25: Description
A26: =D13 -> Buy Feature | B26: =Multiplier_Weight_Oldhand!C9 -> 0 | C26: =1/D26 -> 1 | D26: 1 | E26: Base Game
B27: =Multiplier_Weight_Oldhand!D9 -> 0.92499989 | E27: Free Game
A30: Reel # | B30: 1 | C30: 2 | D30: 3 | E30: 4 | F30: 5
A31: Visible Window Size | B31: 3 | C31: 3 | D31: 3 | E31: 3 | F31: 3
A34: Free Spins Setting
A35: C1 Num. | B35: Base Game | C35: Free Game
A36: 3 | B36: 15 | C36: 15
A37: 4 | B37: 17 | C37: 17
A38: 5 | B38: 19 | C38: 19
A39: The maximum of free spins is 50.
A41: Pay Table： | B41: ="All wins show for "&A7&" credit bet." -> All wins show for 100 credit bet.
A42: Symbol | B42: Description | C42: 3 | D42: 4 | E42: 5 | F42: Id
A43: WW | B43: Wild | C43: 0 | D43: 0 | E43: 0 | F43: 0
A44: C1 | B44: Scatter | C44: 0 | D44: 0 | E44: 0 | F44: 1
A45: M1 | B45: M1 | C45: 250 | D45: 1250 | E45: 5000 | F45: 2
A46: M2 | B46: M2 | C46: 100 | D46: 500 | E46: 2000 | F46: 3
A47: M3 | B47: M3 | C47: 75 | D47: 250 | E47: 1000 | F47: 4
A48: M4 | B48: M4 | C48: 50 | D48: 200 | E48: 750 | F48: 5
A49: M5 | B49: M5 | C49: 25 | D49: 100 | E49: 500 | F49: 6
A50: A | B50: A | C50: 10 | D50: 50 | E50: 250 | F50: 7
A51: K | B51: K | C51: 10 | D51: 50 | E51: 250 | F51: 8
A52: Q | B52: Q | C52: 10 | D52: 50 | E52: 250 | F52: 9
A53: J | B53: J | C53: 10 | D53: 50 | E53: 250 | F53: 10
A54: G1 | B54: Rainbow M1 | C54: 250 | D54: 1250 | E54: 5000 | F54: 11
...

Sheet Description
B3: 7. BG 流程對應
B5: 7.1 BG 開局流程
B7: BG 每局的主要參數流程如下：
B8: 1. 先用 Table Selection Weight - Base Game 選出 BG table。
B9: 2. 再用該 strip 的 Symbol Weight R1~R5 抽停輪位置。
B10: 3. 依 Symbol ID R1~R5 生成初始盤面。
B11: 4. 盤面上的彩虹框會先判定是否觸發 Used Special Pool Weight。
B12: 5. 若命中特殊池，該彩虹框用 Multiple Selection Weight - Special Pool 抽倍率。
B13: 6. 若沒命中特殊池：
B14: - 且是 BG_Symbol (2) 則第 3 輪彩虹框用 Multiple Selection Weight - Reel3 Before Eliminate
B15: - 其他輪彩虹框用 Multiple Selection Weight - Before Eliminate
B16: 7. 再用 Eliminate Table Weight 決定本局是掉落表 A 或 B。
... B83: 5. BG_Symbol (3): 觸發 FG 用的表。得分少、C1 多，盡量不要有倍數百搭參與 → 控制進 FG 時的得分

Sheet Parameter
B3: Line | I3: Table Selection Weight - Base Game (Weight/Total) | N3: Multiple Selection Weight - Special Pool (Weight/Total) | Y3: =10000/SUM(Y8:AA8) -> 4.7619048 | AA3: =10000/AA8 -> 10 | AC3: Used Special Pool Weight (Weight/10000)
B4: ID | C4: R1 | D4: R2 | E4: R3 | F4: R4 | G4: R5 | I4: Worksheet Name | J4: Weight | K4: RTP | N4: Worksheet Name \ Multiple | O4: {=TRANSPOSE(I26:I38)} -> 0 | P4: 2 | Q4: 3 | R4: 5 | S4: 8 | T4: 10 | U4: 15 | V4: 20 | W4: 25 | X4: 50 | Y4: 100 | Z4: 500 | AA4: 1000 | AC4: Worksheet Name \ Multiple | AD4: 1 | AE4: 2 | AF4: 3 | AG4: 4 | AH4: 5 | AI4: 6 | AJ4: 7 | AK4: 8 | AL4: 9
B5: {=_xlfn.SEQUENCE(20,,0)} -> 0 | C5: 1 | D5: 1 | E5: 1 | F5: 1 | G5: 1 | I5: BG_Symbol | J5: =10000-J6-J7 -> 7000 | L5: {=J5:J7/J8} -> 0.7 | N5: BG_Symbol | O5: =10000-SUM(P5:AA5) -> 0 | P5: 0 | Q5: 0 | R5: 0 | S5: 0 | T5: =10000-SUM(U5:AA5) -> 2680 | U5: 3000 | V5: 2000 | W5: 500 | X5: 100 | Y5: 1200 | Z5: 20 | AA5: 500 | AB5: {=SUMPRODUCT(O5:AA5/SUM(O5:AA5),$O$4:$AA$4)} -> 75.93 | AC5: BG_Symbol | AD5: 300 | AE5: 600 | AF5: 1080 | AG5: 1440 | AH5: 2250 | AI5: 2700 | AJ5: 3150 | AK5: 3600 | AL5: 4050
B6: 1 | C6: 0 | D6: 0 | E6: 0 | F6: 0 | G6: 0 | I6: BG_Symbol (2) | J6: 1000 | L6: 0.1 | N6: BG_Symbol (2) | O6: =10000-SUM(P6:AA6) -> 0 | P6: 0 | Q6: 0 | R6: 0 | S6: 0 | T6: =10000-SUM(U6:AA6) -> 2680 | U6: 3000 | V6: 2000 | W6: 500 | X6: 100 | Y6: 1200 | Z6: 20 | AA6: 500 | AB6: {=SUMPRODUCT(O6:AA6/SUM(O6:AA6),$O$4:$AA$4)} -> 75.93 | AC6: BG_Symbol (2) | AD6: 0 | AE6: 0 | AF6: 525 | AG6: 700 | AH6: 1750 | AI6: 2100 | AJ6: 3675 | AK6: 4200 | AL6: 4725
B7: 2 | C7: 2 | D7: 2 | E7: 2 | F7: 2 | G7: 2 | I7: BG_Symbol (3) | J7: 2000 | L7: 0.2 | N7: BG_Symbol (3) | O7: =10000-SUM(P7:AA7) -> 10000 | P7: 0 | Q7: 0 | R7: 0 | S7: 0 | T7: 0 | U7: 0 | V7: 0 | W7: 0 | X7: 0 | Y7: 0 | Z7: 0 | AA7: 0 | AB7: {=SUMPRODUCT(O7:AA7/SUM(O7:AA7),$O$4:$AA$4)} -> 0 | AC7: BG_Symbol (3) | AD7: 0 | AE7: 0 | AF7: 0 | AG7: 0 | AH7: 0 | AI7: 0 | AJ7: 0 | AK7: 0 | AL7: 0
B8: 3 | C8: 0 | D8: 1 | E8: 2 | F8: 1 | G8: 0 | J8: =SUM(J5:J7) -> 10000 | K8: =SUMPRODUCT(K5:K7,_xlfn.ANCHORARRAY(L5)) -> 0 | N8: FG_Symbol | O8: =10000-SUM(P8:AA8) -> 0 | P8: 0 | Q8: 0 | R8: 0 | S8: 0 | T8: =10000-SUM(U8:AA8) -> 3600 | U8: 2500 | V8: 1500 | W8: 250 | X8: 50 | Y8: 1000 | Z8: 100 | AA8: 1000 | AB8: {=SUMPRODUCT(O8:AA8/SUM(O8:AA8),$O$4:$AA$4)} -> 126.225 | AC8: FG_Symbol | AD8: 0 | AE8: 0 | AF8: 525 | AG8: 700 | AH8: 1750 | AI8: 2100 | AJ8: 3675 | AK8: 4200 | AL8: 4725
B9: 4 | C9: 2 | D9: 1 | E9: 0 | F9: 1 | G9: 2 | N9: FG_Symbol (2) | O9: =10000-SUM(P9:AA9) -> 0 | P9: 0 | Q9: 0 | R9: 0 | S9: 0 | T9: =10000-SUM(U9:AA9) -> 3430 | U9: 2500 | V9: 2000 | W9: 500 | X9: 100 | Y9: 700 | Z9: 70 | AA9: 700 | AB9: {=SUMPRODUCT(O9:AA9/SUM(O9:AA9),$O$4:$AA$4)} -> 93.43 | AC9: FG_Symbol (2) | AD9: 0 | AE9: 0 | AF9: 525 | AG9: 700 | AH9: 1750 | AI9: 2100 | AJ9: 3675 | AK9: 4200 | AL9: 4725
B10: 5 | C10: 0 | D10: 0 | E10: 1 | F10: 0 | G10: 0 | I10: Table Selection Weight - Free Game (Weight/Total) | N10: FG_Symbol (3) | O10: =10000-SUM(P10:AA10) -> 0 | P10: 0 | Q10: 0 | R10: 0 | S10: 0 | T10: =10000-SUM(U10:AA10) -> 4480 | U10: 2500 | V10: 2000 | W10: 500 | X10: 100 | Y10: 200 | Z10: 20 | AA10: 200 | AB10: {=SUMPRODUCT(O10:AA10/SUM(O10:AA10),$O$4:$AA$4)} -> 36.98 | AC10: FG_Symbol (3) | AD10: 0 | AE10: 0 | AF10: 525 | AG10: 700 | AH10: 1750 | AI10: 2100 | AJ10: 3675 | AK10: 4200 | AL10: 4725
B11: 6 | C11: 2 | D11: 2 | E11: 1 | F11: 2 | G11: 2 | I11: Worksheet Name | J11: Weight | K11: RTP | N11: BF_Symbol | O11: =10000-SUM(P11:AA11) -> 10000 | P11: 0 | Q11: 0 | R11: 0 | S11: 0 | T11: 0 | U11: 0 | V11: 0 | W11: 0 | X11: 0 | Y11: 0 | Z11: 0 | AA11: 0 | AB11: {=SUMPRODUCT(O11:AA11/SUM(O11:AA11),$O$4:$AA$4)} -> 0 | AC11: BF_Symbol | AD11: 0 | AE11: 0 | AF11: 0 | AG11: 0 | AH11: 0 | AI11: 0 | AJ11: 0 | AK11: 0 | AL11: 0
B12: 7 | C12: 1 | D12: 2 | E12: 2 | F12: 2 | G12: 1 | I12: FG_Symbol | J12: =10000-SUM(J13:J14) -> 10000 | L12: {=J12:J14/SUM(J15)} -> 1
B13: 8 | C13: 1 | D13: 0 | E13: 0 | F13: 0 | G13: 1 | I13: FG_Symbol (2) | J13: 0 | L13: 0
B14: 9 | C14: 0 | D14: 1 | E14: 1 | F14: 1 | G14: 0 | I14: FG_Symbol (3) | J14: 0 | L14: 0 | N14: Multiple Selection Weight - Reel3 Before Eliminate (Weight/Total)
B15: 10 | C15: 2 | D15: 1 | E15: 1 | F15: 1 | G15: 2 | J15: =SUM(J12:J14) -> 10000 | K15: =SUMPRODUCT(K12:K14,_xlfn.ANCHORARRAY(L12)) -> 0 | N15: Worksheet Name \ Multiple | O15: {=TRANSPOSE(I26:I38)} -> 0 | P15: 2 | Q15: 3 | R15: 5 | S15: 8 | T15: 10 | U15: 15 | V15: 20 | W15: 25 | X15: 50 | Y15: 100 | Z15: 500 | AA15: 1000
B16: 11 | C16: 1 | D16: 1 | E16: 0 | F16: 1 | G16: 1 | N16: BG_Symbol | O16: =10000-SUM(P16:AA16) -> 10000 | P16: 0 | Q16: 0 | R16: 0 | S16: 0 | T16: 0 | U16: 0 | V16: 0 | W16: 0 | X16: 0 | Y16: 0 | Z16: 0 | AA16: 0 | AB16: {=SUMPRODUCT(O16:AA16/SUM(O16:AA16),$O$4:$AA$4)} -> 0
B17: 12 | C17: 1 | D17: 1 | E17: 2 | F17: 1 | G17: 1 | I17: Table Selection Weight - Buy Feature (Weight/Total) | N17: BG_Symbol (2) | O17: =10000-SUM(P17:AA17) -> 0 | P17: =10000-SUM(Q17:AA17) -> 3600 | Q17: 3400 | R17: 1500 | S17: 1500 | T17: 0 | U17: 0 | V17: 0 | W17: 0 | X17: 0 | Y17: 0 | Z17: 0 | AA17: 0 | AB17: {=SUMPRODUCT(O17:AA17/SUM(O17:AA17),$O$4:$AA$4)} -> 3.69
B18: 13 | C18: 1 | D18: 0 | E18: 1 | F18: 0 | G18: 1 | I18: Worksheet Name | J18: Weight | K18: RTP | N18: BG_Symbol (3) | O18: =10000-SUM(P18:AA18) -> 10000 | P18: 0 | Q18: 0 | R18: 0 | S18: 0 | T18: 0 | U18: 0 | V18: 0 | W18: 0 | X18: 0 | Y18: 0 | Z18: 0 | AA18: 0 | AB18: {=SUMPRODUCT(O18:AA18/SUM(O18:AA18),$O$4:$AA$4)} -> 0
B19: 14 | C19: 1 | D19: 2 | E19: 1 | F19: 2 | G19: 1 | I19: FG_Symbol | J19: =10000-SUM(J20:J21) -> 10000 | L19: {=J19:J21/SUM(J22)} -> 1 | N19: FG_Symbol | O19: =10000-SUM(P19:AA19) -> 0 | P19: =10000-SUM(Q19:AA19) -> 6000 | Q19: 2800 | R19: 900 | S19: 300 | T19: 0 | U19: 0 | V19: 0 | W19: 0 | X19: 0 | Y19: 0 | Z19: 0 | AA19: 0 | AB19: {=SUMPRODUCT(O19:AA19/SUM(O19:AA19),$O$4:$AA$4)} -> 2.73
B20: 15 | C20: 0 | D20: 1 | E20: 0 | F20: 1 | G20: 0 | I20: FG_Symbol (2) | J20: 0 | L20: 0 | N20: FG_Symbol (2) | O20: =10000-SUM(P20:AA20) -> 0 | P20: =10000-SUM(Q20:AA20) -> 6000 | Q20: 2800 | R20: 900 | S20: 300 | T20: 0 | U20: 0 | V20: 0 | W20: 0 | X20: 0 | Y20: 0 | Z20: 0 | AA20: 0 | AB20: {=SUMPRODUCT(O20:AA20/SUM(O20:AA20),$O$4:$AA$4)} -> 2.73
B21: 16 | C21: 2 | D21: 1 | E21: 2 | F21: 1 | G21: 2 | I21: FG_Symbol (3) | J21: 0 | L21: 0 | N21: FG_Symbol (3) | O21: =10000-SUM(P21:AA21) -> 0 | P21: =10000-SUM(Q21:AA21) -> 6000 | Q21: 2800 | R21: 900 | S21: 300 | T21: 0 | U21: 0 | V21: 0 | W21: 0 | X21: 0 | Y21: 0 | Z21: 0 | AA21: 0 | AB21: {=SUMPRODUCT(O21:AA21/SUM(O21:AA21),$O$4:$AA$4)} -> 2.73
B22: 17 | C22: 0 | D22: 0 | E22: 1 | F22: 2 | G22: 2 | J22: =SUM(J19:J21) -> 10000 | K22: =SUMPRODUCT(K19:K21,_xlfn.ANCHORARRAY(L19)) -> 0 | N22: BF_Symbol | O22: =10000-SUM(P22:AA22) -> 10000 | P22: 0 | Q22: 0 | R22: 0 | S22: 0 | T22: 0 | U22: 0 | V22: 0 | W22: 0 | X22: 0 | Y22: 0 | Z22: 0 | AA22: 0 | AB22: {=SUMPRODUCT(O22:AA22/SUM(O22:AA22),$O$4:$AA$4)} -> 0
B23: 18 | C23: 2 | D23: 2 | E23: 1 | F23: 0 | G23: 0
B24: 19 | C24: 0 | D24: 2 | E24: 0 | F24: 2 | G24: 0 | I24: Multiplier Range
I25: Multiplier | N25: Multiple Selection Weight - Reel3 After Eliminate (Weight/Total)
I26: 0 | N26: Worksheet Name \ Multiple | O26: {=TRANSPOSE(I26:I38)} -> 0 | P26: 2 | Q26: 3 | R26: 5 | S26: 8 | T26: 10 | U26: 15 | V26: 20 | W26: 25 | X26: 50 | Y26: 100 | Z26: 500 | AA26: 1000
I27: 2 | N27: BG_Symbol | O27: =10000-SUM(P27:AA27) -> 10000 | P27: 0 | Q27: 0 | R27: 0 | S27: 0 | T27: 0 | U27: 0 | V27: 0 | W27: 0 | X27: 0 | Y27: 0 | Z27: 0 | AA27: 0 | AB27: {=SUMPRODUCT(O27:AA27/SUM(O27:AA27),$O$4:$AA$4)} -> 0
I28: 3 | N28: BG_Symbol (2) | O28: =10000-SUM(P28:AA28) -> 0 | P28: =10000-SUM(Q28:AA28) -> 3500 | Q28: 3400 | R28: 1500 | S28: 1500 | T28: 20 | U28: 20 | V28: 5 | W28: 5 | X28: 5 | Y28: 20 | Z28: 5 | AA28: 20 | AB28: {=SUMPRODUCT(O28:AA28/SUM(O28:AA28),$O$4:$AA$4)} -> 6.2175
I29: 5 | N29: BG_Symbol (3) | O29: =10000-SUM(P29:AA29) -> 10000 | P29: 0 | Q29: 0 | R29: 0 | S29: 0 | T29: 0 | U29: 0 | V29: 0 | W29: 0 | X29: 0 | Y29: 0 | Z29: 0 | AA29: 0 | AB29: {=SUMPRODUCT(O29:AA29/SUM(O29:AA29),$O$4:$AA$4)} -> 0
I30: 8 | N30: FG_Symbol | O30: =10000-SUM(P30:AA30) -> 0 | P30: =10000-SUM(Q30:AA30) -> 5800 | Q30: 2800 | R30: 900 | S30: 300 | T30: 20 | U30: 20 | V30: 5 | W30: 5 | X30: 5 | Y30: 70 | Z30: 5 | AA30: 70 | AB30: {=SUMPRODUCT(O30:AA30/SUM(O30:AA30),$O$4:$AA$4)} -> 10.7375
I31: 10 | N31: FG_Symbol (2) | O31: =10000-SUM(P31:AA31) -> 0 | P31: =10000-SUM(Q31:AA31) -> 5880 | Q31: 2800 | R31: 900 | S31: 300 | T31: 20 | U31: 20 | V31: 5 | W31: 5 | X31: 5 | Y31: 30 | Z31: 5 | AA31: 30 | AB31: {=SUMPRODUCT(O31:AA31/SUM(O31:AA31),$O$4:$AA$4)} -> 6.3535
I32: 15 | N32: FG_Symbol (3) | O32: =10000-SUM(P32:AA32) -> 0 | P32: =10000-SUM(Q32:AA32) -> 5900 | Q32: 2800 | R32: 900 | S32: 300 | T32: 20 | U32: 20 | V32: 5 | W32: 5 | X32: 5 | Y32: 20 | Z32: 5 | AA32: 20 | AB32: {=SUMPRODUCT(O32:AA32/SUM(O32:AA32),$O$4:$AA$4)} -> 5.2575
I33: 20 | N33: BF_Symbol | O33: =10000-SUM(P33:AA33) -> 10000 | P33: 0 | Q33: 0 | R33: 0 | S33: 0 | T33: 0 | U33: 0 | V33: 0 | W33: 0 | X33: 0 | Y33: 0 | Z33: 0 | AA33: 0 | AB33: {=SUMPRODUCT(O33:AA33/SUM(O33:AA33),$O$4:$AA$4)} -> 0
I34: 25
I35: 50
I36: 100 | N36: Multiple Selection Weight - Before Eliminate (Weight/Total)
I37: 500 | N37: Worksheet Name \ Multiple | O37: {=TRANSPOSE(I26:I38)} -> 0 | P37: 2 | Q37: 3 | R37: 5 | S37: 8 | T37: 10 | U37: 15 | V37: 20 | W37: 25 | X37: 50 | Y37: 100 | Z37: 500 | AA37: 1000
I38: 1000 | N38: BG_Symbol | O38: =10000-SUM(P38:AA38) -> 8500 | P38: 500 | Q38: 400 | R38: 300 | S38: 300 | T38: 0 | U38: 0 | V38: 0 | W38: 0 | X38: 0 | Y38: 0 | Z38: 0 | AA38: 0 | AB38: {=SUMPRODUCT(P38:AA38/SUM(P38:AA38),$P$4:$AA$4)} -> 4.0666667
N39: BG_Symbol (2) | O39: =10000-SUM(P39:AA39) -> 8500 | P39: 500 | Q39: 400 | R39: 300 | S39: 300 | T39: 0 | U39: 0 | V39: 0 | W39: 0 | X39: 0 | Y39: 0 | Z39: 0 | AA39: 0 | AB39: {=SUMPRODUCT(P39:AA39/SUM(P39:AA39),$P$4:$AA$4)} -> 4.0666667
N40: BG_Symbol (3) | O40: =10000-SUM(P40:AA40) -> 8500 | P40: 500 | Q40: 400 | R40: 300 | S40: 300 | T40: 0 | U40: 0 | V40: 0 | W40: 0 | X40: 0 | Y40: 0 | Z40: 0 | AA40: 0 | AB40: {=SUMPRODUCT(P40:AA40/SUM(P40:AA40),$P$4:$AA$4)} -> 4.0666667
I41: Eliminate Table Weight | N41: FG_Symbol | O41: =10000-SUM(P41:AA41) -> 6710 | P41: 2100 | Q41: 860 | R41: 220 | S41: 110 | T41: 0 | U41: 0 | V41: 0 | W41: 0 | X41: 0 | Y41: 0 | Z41: 0 | AA41: 0 | AB41: {=SUMPRODUCT(P41:AA41/SUM(P41:AA41),$P$4:$AA$4)} -> 2.662614
J42: A | K42: B | N42: FG_Symbol (2) | O42: =10000-SUM(P42:AA42) -> 6710 | P42: 2100 | Q42: 860 | R42: 220 | S42: 110 | T42: 0 | U42: 0 | V42: 0 | W42: 0 | X42: 0 | Y42: 0 | Z42: 0 | AA42: 0 | AB42: {=SUMPRODUCT(P42:AA42/SUM(P42:AA42),$P$4:$AA$4)} -> 2.662614
...

Sheet Multiplier_Weight
B2: A | C2: Newbie | D2: Newbie | E2: Newbie | F2: Newbie | G2: Oldhand | H2: Oldhand | I2: Oldhand | J2: Oldhand | K2: Oldhand
B3: Range | C3: Weight_NB_BG | D3: Weight_NB_FG | E3: Weight_EB_BG | F3: Weight_EB_FG | G3: Weight_NB_BG | H3: Weight_NB_FG | I3: Weight_EB_BG | J3: Weight_EB_FG | K3: Weight_BF_FG
B4: (-1, 0] | C4: {=_xlfn.ANCHORARRAY(Multiplier_Weight_Newbie!L16)} -> 702890290 | D4: {=_xlfn.ANCHORARRAY(Multiplier_Weight_Newbie!L159)} -> 0 | E4: {=_xlfn.ANCHORARRAY(Multiplier_Weight_Newbie!L88)} -> 676821089 | F4: {=_xlfn.ANCHORARRAY(Multiplier_Weight_Newbie!L159)} -> 0 | G4: {=_xlfn.ANCHORARRAY(Multiplier_Weight_Oldhand!L16)} -> 716014122 | H4: {=_xlfn.ANCHORARRAY(Multiplier_Weight_Oldhand!L159)} -> 0 | I4: {=_xlfn.ANCHORARRAY(Multiplier_Weight_Oldhand!L88)} -> 711575053 | J4: {=_xlfn.ANCHORARRAY(Multiplier_Weight_Oldhand!L159)} -> 0 | K4: {=_xlfn.ANCHORARRAY(Multiplier_Weight_Oldhand!L229)} -> 0
B5: (0, 1] | C5: 157569794 | D5: 0 | E5: 150531064 | F5: 0 | G5: 160511817 | H5: 0 | I5: 158260656 | J5: 0 | K5: 0
B6: (1, 2] | C6: 44480229 | D6: 0 | E6: 42186452 | F6: 0 | G6: 45310730 | H6: 0 | I6: 44352677 | J6: 0 | K6: 0
B7: (2, 3] | C7: 21086801 | D7: 0 | E7: 20003911 | F7: 0 | G7: 21480518 | H7: 0 | I7: 21031088 | J7: 0 | K7: 0
B8: (3, 4] | C8: 15808669 | D8: 0 | E8: 17629219 | F8: 0 | G8: 11611521 | H8: 0 | I8: 8505556 | J8: 0 | K8: 0
B9: (4, 5] | C9: 12456935 | D9: 0 | E9: 13891495 | F9: 0 | G9: 9149661 | H9: 0 | I9: 6702219 | J9: 0 | K9: 0
B10: (5, 6] | C10: 10250037 | D10: 0 | E10: 11430446 | F10: 0 | G10: 7528687 | H10: 0 | I10: 5514839 | J10: 0 | K10: 0
B11: (6, 7] | C11: 4734005 | D11: 0 | E11: 6994938 | F11: 0 | G11: 3477143 | H11: 0 | I11: 3374842 | J11: 0 | K11: 0
B12: (7, 8] | C12: 4031052 | D12: 0 | E12: 5956258 | F12: 0 | G12: 2960821 | H12: 0 | I12: 2873711 | J12: 0 | K12: 0
B13: (8, 9] | C13: 3634587 | D13: 0 | E13: 5370444 | F13: 0 | G13: 2669616 | H13: 0 | I13: 2591074 | J13: 0 | K13: 0
B14: (9, 10] | C14: 3254240 | D14: 0 | E14: 4808446 | F14: 0 | G14: 2390250 | H14: 0 | I14: 2319927 | J14: 0 | K14: 0
B15: (10, 15] | C15: 4432286 | D15: 157609524 | E15: 6403584 | F15: 157609524 | G15: 3255529 | H15: 136185892 | I15: 3089532 | J15: 136185892 | K15: 121915312
B16: (15, 20] | C16: 7015122 | D16: 156285227 | E16: 8292402 | F16: 156285227 | G16: 5152631 | H16: 135041605 | I16: 4000829 | J16: 135041605 | K16: 120910585
... B67: (100000, 9999999] | C67: 0 | D67: 0 | E67: 0 | F67: 0 | G67: 0 | H67: 0 | I67: 0 | J67: 0 | K67: 0
B68: Free Game | C68: 4178469 | E68: 20892345 | G68: 4178469 | I68: 20892345

Sheet Multiplier_Weight_Newbie
A2: Threshold | B2: 1000000000
A3: Coin in | B3: =Overview!A7 -> 100
C5: RTP
B6: Bet | C6: Base Game | D6: Free Game | E6: Total | F6: Hit Rate | G6: FG Period | H6: Avg Multi | I6: BG | J6: FG
A7: Normal Bet | B7: {=Overview!B11:B12} -> 1 | C7: =SUM(N16:N80) -> 0.78250645 | D7: =SUM(_xlfn.ANCHORARRAY(N159))*F7 -> 0.14749347 | E7: =SUM(C7:D7) -> 0.92999992 | F7: =M80 -> 0.0041779261 | G7: =1/F7 -> 239.3532 | H7: =D7*G7 -> 35.303034 | I7: {=LOOKUP(2,1/(L16:L79<>0),B16:B79)} -> 40 | J7: {=LOOKUP(2,1/(_xlfn.ANCHORARRAY(L159)<>0),B16:B79)} -> 100
A8: Extra Bet | B8: 2 | C8: =SUM(_xlfn.ANCHORARRAY(N88))/B8 -> 0.56173379 | D8: =SUM(_xlfn.ANCHORARRAY(N159))*F8/B8 -> 0.36826581 | E8: =SUM(C8:D8) -> 0.9299996 | F8: =M152 -> 0.020863125 | G8: =1/F8 -> 47.931457 | H8: =D8*G8 -> 17.651517 | I8: {=LOOKUP(2,1/(L88:L151<>0),B16:B79)} -> 60
A12: Base Game
G13: 1e-06
A14: Simulator | B14: =Multiplier_Weight_Oldhand!B14 -> 1000000000 | G14: 450154 | H14: Calculate | P14: Compare
A15: Lower | B15: Upper | C15: Cnt | D15: Pay | E15: Hit Rate | F15: Avg. Multi. | G15: =1+G14*G13 -> 1.450154 | H15: Range | I15: Fix Num | J15: Fix Rate | K15: Final Rate | L15: Weight | M15: Hit Rate | N15: Simulator RTP | O15: 0.9 | P15: 目前 | Q15: 目標 | R15: 墨西哥狂歡 | S15: 差異
A16: -1 | B16: 0 | C16: {=Multiplier_Weight_Oldhand!C16:D79} -> 737428057 | D16: 0 | E16: {=_xlfn.LET(_xlpm.x, C16:C79, _xlpm.x/SUM(_xlpm.x))} -> 0.75568026 | F16: {=_xlfn.LET(_xlpm.x, D16:D81/C16:C81/B3, IF(ISERR(_xlpm.x), 0, _xlpm.x))} -> 0 | H16: ="("&$A16&", "&$B16&"]" -> (-1, 0] | I16: 0.96 | J16: {=E16:E80*I16:I80} -> 0.72545305 | K16: {=J16:J79/SUM(_xlfn.ANCHORARRAY(J16))} -> 0.70289029 | L16: {=INT(K16:K80*$B$2)} -> 702890290 | M16: {=_xlfn.LET(_xlpm.x, L16:L80, _xlpm.x/SUM(_xlpm.x))} -> 0.70279896 | N16: {=M16:M80*F16:F80} -> 0 | O16: {=I16:I79*O15} -> 0.864 | P16: {=M16:M79} -> 0.70279896 | Q16: 0.72294875 | R16: 0.72554635 | S16: {=_xlfn.LET(_xlpm.x, Q16:Q79/M16:M79, IF(ISERR(_xlpm.x), 0, ROUND(_xlpm.x,2)))} -> 1.03
A17: 0 | B17: 1 | C17: 124960454 | D17: 5670928890 | E17: 0.12805337 | F17: 0.45381788 | H17: ="("&$A17&", "&$B17&"]" -> (0, 1] | I17: 1.27 | J17: 0.16262778 | K17: 0.15756979 | L17: 157569794 | M17: 0.15754932 | N17: 0.0714987 | O17: 1.143 | P17: 0.15754932 | Q17: 0.16136085 | R17: 0.15905886 | S17: 1.02
A18: 1 | B18: 2 | C18: 33683617 | D18: 5063260970 | E18: 0.034517326 | F18: 1.5031821 | H18: ="("&$A18&", "&$B18&"]" -> (1, 2] | I18: 1.33 | J18: 0.045908043 | K18: 0.044480229 | L18: 44480229 | M18: 0.04447445 | N18: 0.066853196 | O18: 1.197 | P18: 0.04447445 | Q18: 0.045756935 | R18: 0.049788509 | S18: 1.03
A19: 2 | B19: 3 | C19: 15731868 | D19: 3966955370 | E19: 0.01612125 | F19: 2.5216048 | H19: ="("&$A19&", "&$B19&"]" -> (2, 3] | I19: 1.35 | J19: 0.021763687 | K19: 0.021086802 | L19: 21086801 | M19: 0.021084061 | N19: 0.05316567 | O19: 1.215 | P19: 0.021084061 | Q19: 0.021758 | R19: 0.021457526 | S19: 1.03
A20: 3 | B20: 4 | C20: 7891833 | D20: 2817483325 | E20: 0.008087165 | F20: 3.5701254 | G20: 1.3912547 | H20: ="("&$A20&", "&$B20&"]" -> (3, 4] | I20: {=G20:G79*G15} -> 2.0175336 | J20: 0.016316127 | K20: 0.015808669 | L20: 15808669 | M20: 0.015806615 | N20: 0.056431597 | O20: 1.8157803 | P20: 0.015806615 | Q20: 0.0085068855 | R20: 0.0094289743 | S20: 0.54
A21: 4 | B21: 5 | C21: 5580810 | D21: 2567489145 | E21: 0.0057189415 | F21: 4.6005672 | G21: 1.5502553 | H21: ="("&$A21&", "&$B21&"]" -> (4, 5] | I21: 2.2481089 | J21: 0.012856803 | K21: 0.012456936 | L21: 12456935 | M21: 0.012455316 | N21: 0.05730152 | O21: 2.023298 | P21: 0.012455316 | Q21: 0.0066698354 | R21: 0.0062566091 | S21: 0.54
A22: 5 | B22: 6 | C22: 4164929 | D22: 2327993340 | E22: 0.0042680158 | F22: 5.5895151 | G22: 1.7092558 | H22: ="("&$A22&", "&$B22&"]" -> (5, 6] | I22: 2.4786842 | J22: 0.010579063 | K22: 0.010250037 | L22: 10250037 | M22: 0.010248705 | N22: 0.057285292 | O22: 2.2308157 | P22: 0.010248705 | Q22: 0.0054541949 | R22: 0.0053753965 | S22: 0.53
A23: 6 | B23: 7 | C23: 2786352 | D23: 1828894325 | E23: 0.0028553174 | F23: 6.5637591 | G23: 1.18 | H23: ="("&$A23&", "&$B23&"]" -> (6, 7] | I23: 1.7111817 | J23: 0.004885967 | K23: 0.0047340056 | L23: 4734005 | M23: 0.0047333899 | N23: 0.031068831 | O23: 1.5400635 | P23: 0.0047333899 | Q23: 0.0033318405 | R23: 0.0025114558 | S23: 0.7
A24: 7 | B24: 8 | C24: 2886263 | D24: 2199517210 | E24: 0.0029577014 | F24: 7.6206403 | G24: 0.97 | H24: ="("&$A24&", "&$B24&"]" -> (7, 8] | I24: 1.4066494 | J24: 0.0041604488 | K24: 0.0040310521 | L24: 4031052 | M24: 0.0040305282 | N24: 0.030715206 | O24: 1.2659844 | P24: 0.0040305282 | Q24: 0.00281562 | R24: 0.0030842439 | S24: 0.7
A25: 8 | B25: 9 | C25: 2121277 | D25: 1824061555 | E25: 0.0021737811 | F25: 8.5988843 | G25: 1.19 | H25: ="("&$A25&", "&$B25&"]" -> (8, 9] | I25: 1.7256833 | J25: 0.0037512576 | K25: 0.0036345875 | L25: 3634587 | M25: 0.0036341148 | N25: 0.031249332 | O25: 1.5531149 | P25: 0.0036341148 | Q25: 0.0025445965 | R25: 0.0026876983 | S25: 0.7
A26: 9 | B26: 10 | C26: 1982595 | D26: 1912247295 | E26: 0.0020316665 | F26: 9.6451736 | G26: 1.14 | H26: ="("&$A26&", "&$B26&"]" -> (9, 10] | I26: 1.6531756 | J26: 0.0033587014 | K26: 0.0032542404 | L26: 3254240 | M26: 0.0032538172 | N26: 0.031383632 | O26: 1.487858 | P26: 0.0032538172 | Q26: 0.0022718729 | R26: 0.002247092 | S26: 0.7
A27: 10 | B27: 15 | C27: 6840763 | D27: 8514472135 | E27: 0.0070100798 | F27: 12.44667 | G27: 0.45 | H27: ="("&$A27&", "&$B27&"]" -> (10, 15] | I27: 0.6525693 | J27: 0.0045745629 | K27: 0.0044322866 | L27: 4432286 | M27: 0.0044317101 | N27: 0.055160034 | O27: 0.58731237 | P27: 0.0044317101 | Q27: 0.0030238589 | R27: 0.0049788509 | S27: 0.68
A28: 15 | B28: 20 | C28: 4640184 | D28: 8115369895 | E28: 0.0047550339 | F28: 17.489328 | G28: 1.05 | H28: ="("&$A28&", "&$B28&"]" -> (15, 20] | I28: 1.5226617 | J28: 0.0072403081 | K28: 0.0070151228 | L28: 7015122 | M28: 0.0070142105 | N28: 0.12267383 | O28: 1.3703955 | P28: 0.0070142105 | Q28: 0.0039646257 | R28: 0.0023352133 | S28: 0.57
A29: 20 | B29: 25 | C29: 3240350 | D29: 7303039190 | E29: 0.0033205524 | F29: 22.53781 | G29: 0.5 | H29: ="("&$A29&", "&$B29&"]" -> (20, 25] | I29: 0.725077 | J29: 0.0024076562 | K29: 0.0023327742 | L29: 2332774 | M29: 0.0023324709 | N29: 0.052568786 | O29: 0.6525693 | P29: 0.0023324709 | Q29: 0.0016558467 | R29: 0.0018064857 | S29: 0.71
A30: 25 | B30: 30 | C30: 2609813 | D30: 7187928000 | E30: 0.0026744089 | F30: 27.541927 | G30: 0.18 | H30: ="("&$A30&", "&$B30&"]" -> (25, 30] | I30: 0.26102772 | J30: 0.00069809486 | K30: 0.00067638299 | L30: 676382 | M30: 0.00067629412 | N30: 0.018626443 | O30: 0.23492495 | P30: 0.00067629412 | Q30: 0.00067090937 | R30: 0.00088121255 | S30: 0.99
A31: 30 | B31: 35 | C31: 1960951 | D31: 6379124260 | E31: 0.0020094868 | F31: 32.530768 | G31: 0.2 | H31: ="("&$A31&", "&$B31&"]" -> (30, 35] | I31: 0.2900308 | J31: 0.00058281307 | K31: 0.00056468664 | L31: 564686 | M31: 0.00056461263 | N31: 0.018367283 | O31: 0.26102772 | P31: 0.00056461263 | Q31: 0.00056786647 | R31: 0.0004846669 | S31: 1.01
A32: 35 | B32: 40 | C32: 1698327 | D32: 6375630385 | E32: 0.0017403626 | F32: 37.540653 | G32: 0.3 | H32: ="("&$A32&", "&$B32&"]" -> (35, 40] | I32: 0.4350462 | J32: 0.00075713812 | K32: 0.00073358991 | L32: 733589 | M32: 0.00073349368 | N32: 0.027535832 | O32: 0.39154158 | P32: 0.00073349368 | Q32: 0.00097218159 | R32: 0.00070497004 | S32: 1.33
... A79: 100000 | B79: 9999999 | C79: 166 | D79: 1996773875 | E79: 1.7010869e-07 | F79: 120287.58 | G79: 0 | H79: ="("&$A79&", "&$B79&"]" -> (100000, 9999999] | I79: 0 | J79: 0 | K79: 0 | L79: 0 | M79: 0 | N79: 0 | O79: 0 | P79: 0 | Q79: 0 | R79: 0 | S79: 0
A80: Free Game | C80: =E80*B14 -> 24153000 | D80: {=Multiplier_Weight_Oldhand!D80:D81} -> 359164335 | E80: =Multiplier_Weight_Oldhand!E80 -> 0.024153 | F80: 0.14870382 | H80: Free Game | I80: 0.173 | J80: 0.004178469 | K80: =J80 -> 0.004178469 | L80: 4178469 | M80: 0.0041779261 | N80: 0.00062127357
A81: Buy Feature | C81: 10000000 | D81: 0 | E81: 1 | F81: 0 | H81: Buy Feature | M81: =E81 -> 1 | N81: =F81/B9 -> #DIV/0!
A84: Extra Bet
G85: 1e-06
A86: Simulator | B86: 1000000000 | G86: 1225271 | H86: Calculate | P86: Compare
A87: Lower | B87: Upper | C87: Cnt | D87: Pay | E87: Hit Rate | F87: Avg. Multi. | G87: =1+G86*G85 -> 2.225271 | H87: Range | I87: Fix Num | J87: Fix Rate | K87: Final Rate | L87: Weight | M87: Hit Rate | N87: Simulator RTP | O87: 0.9 | P87: 目前 | Q87: 目標 | R87: 墨西哥狂歡 | S87: 差異
A88: -1 | B88: 0 | C88: {=C16:D79} -> 737428057 | D88: 0 | E88: {=_xlfn.LET(_xlpm.x, C88:C151, _xlpm.x/SUM(_xlpm.x))} -> 0.75568026 | F88: {=_xlfn.LET(_xlpm.x, D88:D152/C88:C152/B3, IF(ISERR(_xlpm.x), 0, _xlpm.x))} -> 0 | H88: ="("&$A88&", "&$B88&"]" -> (-1, 0] | I88: 0.96 | J88: {=E88:E152*I88:I152} -> 0.72545305 | K88: {=J88:J151/SUM(_xlfn.ANCHORARRAY(J88))} -> 0.67682109 | L88: {=INT(K88:K152*$B$2)} -> 676821089 | M88: {=_xlfn.LET(_xlpm.x, L88:L152, _xlpm.x/SUM(_xlpm.x))} -> 0.6758745 | N88: {=M88:M152*F88:F152} -> 0 | O88: {=I88:I151*O87} -> 0.864 | P88: {=M88:M151} -> 0.6758745 | Q88: 0.72294875 | S88: {=_xlfn.LET(_xlpm.x, Q88:Q151/M88:M151, IF(ISERR(_xlpm.x), 0, ROUND(_xlpm.x,2)))} -> 1.07
A89: 0 | B89: 1 | C89: 124960454 | D89: 5670928890 | E89: 0.12805337 | F89: 0.45381788 | H89: ="("&$A89&", "&$B89&"]" -> (0, 1] | I89: 1.26 | J89: 0.16134725 | K89: 0.15053106 | L89: 150531064 | M89: 0.15032053 | N89: 0.068218147 | O89: 1.134 | P89: 0.15032053 | Q89: 0.16136085 | S89: 1.07
A90: 1 | B90: 2 | C90: 33683617 | D90: 5063260970 | E90: 0.034517326 | F90: 1.5031821 | H90: ="("&$A90&", "&$B90&"]" -> (1, 2] | I90: 1.31 | J90: 0.045217696 | K90: 0.042186453 | L90: 42186452 | M90: 0.042127451 | N90: 0.063325229 | O90: 1.179 | P90: 0.042127451 | Q90: 0.045756935 | S90: 1.09
A91: 2 | B91: 3 | C91: 15731868 | D91: 3966955370 | E91: 0.01612125 | F91: 2.5216048 | H91: ="("&$A91&", "&$B91&"]" -> (2, 3] | I91: 1.33 | J91: 0.021441262 | K91: 0.020003912 | L91: 20003911 | M91: 0.019975934 | N91: 0.05037141 | O91: 1.197 | P91: 0.019975934 | Q91: 0.021758 | S91: 1.09
A92: 3 | B92: 4 | C92: 7891833 | D92: 2817483325 | E92: 0.008087165 | F92: 3.5701254 | G92: 1.05 | H92: ="("&$A92&", "&$B92&"]" -> (3, 4] | I92: {=G92:G151*G87} -> 2.3365346 | J92: 0.01889594 | K92: 0.01762922 | L92: 17629219 | M92: 0.017604563 | N92: 0.062850497 | O92: 2.1028811 | P92: 0.017604563 | Q92: 0.0085068855 | S92: 0.48
A93: 4 | B93: 5 | C93: 5580810 | D93: 2567489145 | E93: 0.0057189415 | F93: 4.6005672 | G93: 1.17 | H93: ="("&$A93&", "&$B93&"]" -> (4, 5] | I93: 2.6035671 | J93: 0.014889648 | K93: 0.013891495 | L93: 13891495 | M93: 0.013872067 | N93: 0.063819374 | O93: 2.3432104 | P93: 0.013872067 | Q93: 0.0066698354 | S93: 0.48
...

Sheet Multiplier_Weight_Oldhand
A2: Threshold | B2: 1000000000
A3: Coin in | B3: =Overview!A7 -> 100
C5: RTP
B6: Bet | C6: Base Game | D6: Free Game | E6: Total | F6: Hit Rate | G6: FG Period | H6: Avg Multi | I6: BG | J6: FG
A7: Normal Bet | B7: {=Overview!B11:B13} -> 1 | C7: =SUM(N16:N80) -> 0.6999997 | D7: =SUM(_xlfn.ANCHORARRAY(N159))*F7 -> 0.24000008 | E7: =SUM(C7:D7) -> 0.93999978 | F7: =M80 -> 0.0041782419 | G7: =1/F7 -> 239.33511 | H7: =D7*G7 -> 57.440446 | I7: {=LOOKUP(2,1/(L16:L79<>0),B16:B79)} -> 120 | J7: {=LOOKUP(2,1/(_xlfn.ANCHORARRAY(L159)<>0),B16:B79)} -> 20000
A8: Extra Bet | B8: 2 | C8: =SUM(_xlfn.ANCHORARRAY(N88))/B8 -> 0.34020708 | D8: =SUM(_xlfn.ANCHORARRAY(N159))*F8/B8 -> 0.59979309 | E8: =SUM(C8:D8) -> 0.94000017 | F8: =M152 -> 0.020883998 | G8: =1/F8 -> 47.883551 | H8: =D8*G8 -> 28.720223 | I8: {=LOOKUP(2,1/(L88:L151<>0),B16:B79)} -> 120 | J8: =J7 -> 20000
A9: Buy Feature | B9: 75 | C9: =N81 -> 0 | D9: =SUM(_xlfn.ANCHORARRAY(N229))/B9 -> 0.92499989 | E9: =SUM(C9:D9) -> 0.92499989 | F9: =E81 -> 1 | G9: =1/F9 -> 1 | H9: =D9*G9*B9 -> 69.374992 | J9: {=LOOKUP(2,1/(_xlfn.ANCHORARRAY(L229)<>0),B16:B79)} -> 20000
A12: Base Game
G13: 1e-05
A14: Simulator | B14: 1000000000 | C14: H026192_2606171759_betmode0 | G14: 4562 | H14: Calculate
A15: Lower | B15: Upper | C15: Cnt | D15: Pay | E15: Hit Rate | F15: Avg. Multi. | G15: =1+G14*G13 -> 1.04562 | H15: Range | I15: Fix Num | J15: Fix Rate | K15: Final Rate | L15: Weight | M15: Hit Rate | N15: Simulator RTP | O15: 1.1 | P15: 目前 | Q15: 目前 | R15: 墨西哥狂歡 | S15: 差異
A16: -1 | B16: 0 | C16: 737428057 | D16: 0 | E16: {=_xlfn.LET(_xlpm.x, C16:C79, _xlpm.x/SUM(_xlpm.x))} -> 0.75568026 | F16: {=_xlfn.LET(_xlpm.x, D16:D81/C16:C81/B3, IF(ISERR(_xlpm.x), 0, _xlpm.x))} -> 0 | H16: ="("&$A16&", "&$B16&"]" -> (-1, 0] | I16: 0.96 | J16: {=E16:E80*I16:I80} -> 0.72545305 | K16: {=J16:J79/SUM(_xlfn.ANCHORARRAY(J16))} -> 0.71601412 | L16: {=INT(K16:K80*$B$2)} -> 716014122 | M16: {=_xlfn.LET(_xlpm.x, L16:L80, _xlpm.x/SUM(_xlpm.x))} -> 0.7159752 | N16: {=M16:M80*F16:F80} -> 0 | O16: {=I16:I79*O15} -> 1.056 | P16: {=M16:M79} -> 0.7159752 | Q16: 0.72110724 | R16: 0.72554635 | S16: {=_xlfn.LET(_xlpm.x, Q16:Q79/M16:M79, IF(ISERR(_xlpm.x), 0, ROUND(_xlpm.x,2)))} -> 1.01
A17: 0 | B17: 1 | C17: 124960454 | D17: 5670928890 | E17: 0.12805337 | F17: 0.45381788 | H17: ="("&$A17&", "&$B17&"]" -> (0, 1] | I17: 1.27 | J17: 0.16262778 | K17: 0.16051182 | L17: 160511817 | M17: 0.16050309 | N17: 0.072839174 | O17: 1.397 | P17: 0.16050309 | Q17: 0.16136824 | R17: 0.15905886 | S17: 1.01
A18: 1 | B18: 2 | C18: 33683617 | D18: 5063260970 | E18: 0.034517326 | F18: 1.5031821 | H18: ="("&$A18&", "&$B18&"]" -> (1, 2] | I18: 1.33 | J18: 0.045908043 | K18: 0.04531073 | L18: 45310730 | M18: 0.045308267 | N18: 0.068106576 | O18: 1.463 | P18: 0.045308267 | Q18: 0.045833905 | R18: 0.049788509 | S18: 1.01
A19: 2 | B19: 3 | C19: 15731868 | D19: 3966955370 | E19: 0.01612125 | F19: 2.5216048 | H19: ="("&$A19&", "&$B19&"]" -> (2, 3] | I19: 1.35 | J19: 0.021763687 | K19: 0.021480518 | L19: 21480518 | M19: 0.02147935 | N19: 0.054162433 | O19: 1.485 | P19: 0.02147935 | Q19: 0.021685674 | R19: 0.021457526 | S19: 1.01
A20: 3 | B20: 4 | C20: 7891833 | D20: 2817483325 | E20: 0.008087165 | F20: 3.5701254 | G20: 1.3912547 | H20: ="("&$A20&", "&$B20&"]" -> (3, 4] | I20: {=G20:G79*G15} -> 1.4547238 | J20: 0.011764591 | K20: 0.011611521 | L20: 11611521 | M20: 0.01161089 | N20: 0.041452333 | O20: 1.6001961 | P20: 0.01161089 | Q20: 0.0088791811 | R20: 0.0094289743 | S20: 0.76
A21: 4 | B21: 5 | C21: 5580810 | D21: 2567489145 | E21: 0.0057189415 | F21: 4.6005672 | G21: 1.5502553 | H21: ="("&$A21&", "&$B21&"]" -> (4, 5] | I21: 1.6209779 | J21: 0.0092702779 | K21: 0.0091496616 | L21: 9149661 | M21: 0.0091491637 | N21: 0.042091342 | O21: 1.7830757 | P21: 0.0091491637 | Q21: 0.0069693579 | R21: 0.0062566091 | S21: 0.76
A22: 5 | B22: 6 | C22: 4164929 | D22: 2327993340 | E22: 0.0042680158 | F22: 5.5895151 | G22: 1.7092558 | H22: ="("&$A22&", "&$B22&"]" -> (5, 6] | I22: 1.7872321 | J22: 0.0076279347 | K22: 0.0075286871 | L22: 7528687 | M22: 0.0075282778 | N22: 0.042079422 | O22: 1.9659553 | P22: 0.0075282778 | Q22: 0.0056976824 | R22: 0.0053753965 | S22: 0.76
A23: 6 | B23: 7 | C23: 2786352 | D23: 1828894325 | E23: 0.0028553174 | F23: 6.5637591 | G23: 1.18 | H23: ="("&$A23&", "&$B23&"]" -> (6, 7] | I23: 1.2338316 | J23: 0.0035229809 | K23: 0.0034771431 | L23: 3477143 | M23: 0.003476954 | N23: 0.022821888 | O23: 1.3572148 | P23: 0.003476954 | Q23: 0.0034668704 | R23: 0.0025114558 | S23: 1
A24: 7 | B24: 8 | C24: 2886263 | D24: 2199517210 | E24: 0.0029577014 | F24: 7.6206403 | G24: 0.97 | H24: ="("&$A24&", "&$B24&"]" -> (7, 8] | I24: 1.0142514 | J24: 0.0029998527 | K24: 0.0029608214 | L24: 2960821 | M24: 0.0029606601 | N24: 0.022562125 | O24: 1.1156765 | P24: 0.0029606601 | Q24: 0.0029416568 | R24: 0.0030842439 | S24: 0.99
A25: 8 | B25: 9 | C25: 2121277 | D25: 1824061555 | E25: 0.0021737811 | F25: 8.5988843 | G25: 1.19 | H25: ="("&$A25&", "&$B25&"]" -> (8, 9] | I25: 1.2442878 | J25: 0.0027048093 | K25: 0.0026696168 | L25: 2669616 | M25: 0.0026694709 | N25: 0.022954471 | O25: 1.3687166 | P25: 0.0026694709 | Q25: 0.0026585781 | R25: 0.0026876983 | S25: 1
A26: 9 | B26: 10 | C26: 1982595 | D26: 1912247295 | E26: 0.0020316665 | F26: 9.6451736 | G26: 1.14 | H26: ="("&$A26&", "&$B26&"]" -> (9, 10] | I26: 1.1920068 | J26: 0.0024217603 | K26: 0.0023902506 | L26: 2390250 | M26: 0.0023901201 | N26: 0.023053123 | O26: 1.3112075 | P26: 0.0023901201 | Q26: 0.0023601447 | R26: 0.002247092 | S26: 0.99
A27: 10 | B27: 15 | C27: 6840763 | D27: 8514472135 | E27: 0.0070100798 | F27: 12.44667 | G27: 0.45 | H27: ="("&$A27&", "&$B27&"]" -> (10, 15] | I27: 0.470529 | J27: 0.0032984458 | K27: 0.0032555295 | L27: 3255529 | M27: 0.003255352 | N27: 0.040518293 | O27: 0.5175819 | P27: 0.003255352 | Q27: 0.0031733789 | R27: 0.0049788509 | S27: 0.97
A28: 15 | B28: 20 | C28: 4640184 | D28: 8115369895 | E28: 0.0047550339 | F28: 17.489328 | G28: 1.05 | H28: ="("&$A28&", "&$B28&"]" -> (15, 20] | I28: 1.097901 | J28: 0.0052205565 | K28: 0.0051526315 | L28: 5152631 | M28: 0.0051523509 | N28: 0.090111154 | O28: 1.2076911 | P28: 0.0051523509 | Q28: 0.0041214347 | R28: 0.0023352133 | S28: 0.8
A29: 20 | B29: 25 | C29: 3240350 | D29: 7303039190 | E29: 0.0033205524 | F29: 22.53781 | G29: 0.5 | H29: ="("&$A29&", "&$B29&"]" -> (20, 25] | I29: 0.52281 | J29: 0.001736018 | K29: 0.0017134305 | L29: 1713430 | M29: 0.0017133369 | N29: 0.03861486 | O29: 0.575091 | P29: 0.0017133369 | Q29: 0.00172308 | R29: 0.0018064857 | S29: 1.01
A30: 25 | B30: 30 | C30: 2609813 | D30: 7187928000 | E30: 0.0026744089 | F30: 27.541927 | G30: 0.18 | H30: ="("&$A30&", "&$B30&"]" -> (25, 30] | I30: 0.1882116 | J30: 0.00050335478 | K30: 0.00049680559 | L30: 496805 | M30: 0.000496778 | N30: 0.013682223 | O30: 0.20703276 | P30: 0.000496778 | Q30: 0.00069959412 | R30: 0.00088121255 | S30: 1.41
A31: 30 | B31: 35 | C31: 1960951 | D31: 6379124260 | E31: 0.0020094868 | F31: 32.530768 | G31: 0.2 | H31: ="("&$A31&", "&$B31&"]" -> (30, 35] | I31: 0.209124 | J31: 0.00042023192 | K31: 0.00041476425 | L31: 414764 | M31: 0.00041474146 | N31: 0.013491858 | O31: 0.2300364 | P31: 0.00041474146 | Q31: 0.00059151288 | R31: 0.0004846669 | S31: 1.43
A32: 35 | B32: 40 | C32: 1698327 | D32: 6375630385 | E32: 0.0017403626 | F32: 37.540653 | G32: 0.3 | H32: ="("&$A32&", "&$B32&"]" -> (35, 40] | I32: 0.313686 | J32: 0.00054592737 | K32: 0.00053882427 | L32: 538824 | M32: 0.00053879471 | N32: 0.020226705 | O32: 0.3450546 | P32: 0.00053879471 | Q32: 0.0010098732 | R32: 0.00070497004 | S32: 1.87
... A79: 100000 | B79: 9999999 | C79: 166 | D79: 1996773875 | E79: 1.7010869e-07 | F79: 120287.58 | G79: 0 | H79: ="("&$A79&", "&$B79&"]" -> (100000, 9999999] | I79: 0 | J79: 0 | K79: 0 | L79: 0 | M79: 0 | N79: 0 | O79: 0 | P79: 0 | Q79: 0 | R79: 0 | S79: 0
A80: Free Game | C80: =E80*B14 -> 24153000 | D80: 359164335 | E80: 0.024153 | F80: 0.14870382 | H80: Free Game | I80: 0.173 | J80: 0.004178469 | K80: =J80 -> 0.004178469 | L80: 4178469 | M80: 0.0041782419 | N80: 0.00062132053
A81: Buy Feature | C81: 10000000 | D81: 0 | E81: 1 | F81: 0 | H81: Buy Feature | M81: =E81 -> 1 | N81: =F81/B9 -> 0
A84: Extra Bet
G85: 1e-06
A86: Simulator | B86: 1000000000 | G86: 21188 | H86: Calculate
A87: Lower | B87: Upper | C87: Cnt | D87: Pay | E87: Hit Rate | F87: Avg. Multi. | G87: =1+G86*G85 -> 1.021188 | H87: Range | I87: Fix Num | J87: Fix Rate | K87: Final Rate | L87: Weight | M87: Hit Rate | N87: Simulator RTP | O87: 0.9 | P87: 目前 | Q87: 目前 | R87: 墨西哥狂歡 | S87: 差異
A88: -1 | B88: 0 | C88: {=C16:D79} -> 737428057 | D88: 0 | E88: {=_xlfn.LET(_xlpm.x, C88:C151, _xlpm.x/SUM(_xlpm.x))} -> 0.75568026 | F88: {=_xlfn.LET(_xlpm.x, D88:D152/C88:C152/B3, IF(ISERR(_xlpm.x), 0, _xlpm.x))} -> 0 | H88: ="("&$A88&", "&$B88&"]" -> (-1, 0] | I88: 0.96 | J88: {=E88:E152*I88:I152} -> 0.72545305 | K88: {=J88:J151/SUM(_xlfn.ANCHORARRAY(J88))} -> 0.71157505 | L88: {=INT(K88:K152*$B$2)} -> 711575053 | M88: {=_xlfn.LET(_xlpm.x, L88:L152, _xlpm.x/SUM(_xlpm.x))} -> 0.71129078 | N88: {=M88:M152*F88:F152} -> 0 | O88: {=I88:I151*O87} -> 0.864 | P88: {=M88:M151} -> 0.71129078 | Q88: 0.70964431 | S88: {=_xlfn.LET(_xlpm.x, Q88:Q151/M88:M151, IF(ISERR(_xlpm.x), 0, ROUND(_xlpm.x,2)))} -> 1
A89: 0 | B89: 1 | C89: 124960454 | D89: 5670928890 | E89: 0.12805337 | F89: 0.45381788 | H89: ="("&$A89&", "&$B89&"]" -> (0, 1] | I89: 1.26 | J89: 0.16134725 | K89: 0.15826066 | L89: 158260656 | M89: 0.15819743 | N89: 0.071792823 | O89: 1.134 | P89: 0.15819743 | Q89: 0.15880308 | S89: 1
A90: 1 | B90: 2 | C90: 33683617 | D90: 5063260970 | E90: 0.034517326 | F90: 1.5031821 | H90: ="("&$A90&", "&$B90&"]" -> (1, 2] | I90: 1.31 | J90: 0.045217696 | K90: 0.044352677 | L90: 44352677 | M90: 0.044334958 | N90: 0.066643515 | O90: 1.179 | P90: 0.044334958 | Q90: 0.045105316 | S90: 1.02
A91: 2 | B91: 3 | C91: 15731868 | D91: 3966955370 | E91: 0.01612125 | F91: 2.5216048 | H91: ="("&$A91&", "&$B91&"]" -> (2, 3] | I91: 1.33 | J91: 0.021441262 | K91: 0.021031089 | L91: 21031088 | M91: 0.021022686 | N91: 0.053010906 | O91: 1.197 | P91: 0.021022686 | Q91: 0.021340951 | S91: 1.02
A92: 3 | B92: 4 | C92: 7891833 | D92: 2817483325 | E92: 0.008087165 | F92: 3.5701254 | G92: 1.05 | H92: ="("&$A92&", "&$B92&"]" -> (3, 4] | I92: {=G92:G151*G87} -> 1.0722474 | J92: 0.0086714417 | K92: 0.0085055561 | L92: 8505556 | M92: 0.008502158 | N92: 0.03035377 | O92: 0.96502266 | P92: 0.008502158 | Q92: 0.0085535449 | S92: 1.01
...

Sheet OP Jackpot
B2: Threshold | C2: 10000000000
B4: Status | C4: Bet Type | D4: AB | E4: Screen | F4: Spin | G4: C1 cnt | H4: SCR
B5: Newbie | C5: Normal Bet | D5: A | E5: BG | H5: =SUM(G5:G6)/F5*$C$2 -> #DIV/0!
E6: FG
B7: Newbie | C7: Extra Bet | D7: A | E7: BG | H7: =SUM(G7:G8)/F7*$C$2 -> #DIV/0!
E8: FG
B9: Oldhand | C9: Normal Bet | D9: A | E9: BG | F9: 10000000 | G9: 3435016 | H9: =SUM(G9:G10)/F9*$C$2 -> 3562401000
E10: FG | G10: 127385
B11: Oldhand | C11: Extra Bet | D11: A | E11: BG | F11: 10000000 | G11: 3546458 | H11: =SUM(G11:G12)/F11*$C$2 -> 4181600000
E12: FG | G12: 635142
B13: Oldhand | C13: But Feature | D13: A | E13: BG | F13: =G13 -> 10000000 | G13: 10000000 | H13: =SUM(G13:G14)/F13*$C$2 -> 41071089000
E14: FG | G14: 31071089
B16: Newbie | C16: Normal Bet | D16: B | E16: BG | H16: =SUM(G16:G17)/F16*$C$2 -> #DIV/0!
E17: FG
B18: Newbie | C18: Extra Bet | D18: B | E18: BG | H18: =SUM(G18:G19)/F18*$C$2 -> #DIV/0!
E19: FG
B20: Oldhand | C20: Normal Bet | D20: B | E20: BG | H20: =SUM(G20:G21)/F20*$C$2 -> #DIV/0!
E21: FG
B22: Oldhand | C22: Extra Bet | D22: B | E22: BG | H22: =SUM(G22:G23)/F22*$C$2 -> #DIV/0!
E23: FG
B24: Oldhand | C24: But Feature | D24: B | E24: BG | F24: =G24 -> 0 | H24: =SUM(G24:G25)/F24*$C$2 -> #DIV/0!
E25: FG

Sheet BG_Symbol
J2: Symbol | Q2: Symbol ID | W2: Symbol Weight | AC2: Eliminate Wheel Weight A | AJ2: Eliminate Wheel Weight B
A3: Symbol | B3: Description | C3: R1 | D3: R2 | E3: R3 | F3: R4 | G3: R5 | H3: ID | K3: R1 | L3: R2 | M3: R3 | N3: R4 | O3: R5 | Q3: R1 | R3: R2 | S3: R3 | T3: R4 | U3: R5 | W3: R1 | X3: R2 | Y3: R3 | Z3: R4 | AA3: R5
A4: {=Overview!A43:B62} -> WW | B4: Wild | C4: =COUNTIF(K:K, $A4) -> 0 | D4: =COUNTIF(L:L, $A4) -> 0 | E4: =COUNTIF(M:M, $A4) -> 0 | F4: =COUNTIF(N:N, $A4) -> 0 | G4: =COUNTIF(O:O, $A4) -> 0 | H4: {=Overview!F43:F62} -> 0 | J4: {=_xlfn.SEQUENCE(MAX(COUNTA(K:K), COUNTA(L:L), COUNTA(M:M), COUNTA(N:N), COUNTA(O:O))-1,,0)} -> 0 | K4: M4 | L4: G5 | M4: M5 | N4: J | O4: A | Q4: {=_xlfn.LET(_xlpm.x, K4:O304, IF(_xlpm.x="", "", _xlfn.XLOOKUP(_xlpm.x, $A$4:$A$23,_xlfn.ANCHORARRAY( H4))))} -> 5 | R4: 15 | S4: 6 | T4: 10 | U4: 7 | W4: 1 | X4: 1 | Y4: 1 | Z4: 1 | AA4: 1 | AC4: 1 Combo | AJ4: 1 Combo
A5: C1 | B5: Scatter | C5: =COUNTIF(K:K, $A5) -> 0 | D5: =COUNTIF(L:L, $A5) -> 6 | E5: =COUNTIF(M:M, $A5) -> 0 | F5: =COUNTIF(N:N, $A5) -> 9 | G5: =COUNTIF(O:O, $A5) -> 0 | H5: 1 | J5: 1 | K5: M5 | L5: GK | M5: M4 | N5: J | O5: M3 | Q5: 6 | R5: 17 | S5: 5 | T5: 10 | U5: 4 | W5: 1 | X5: 1 | Y5: 1 | Z5: 1 | AA5: 1 | AC5: Symbol | AD5: R1 | AE5: R2 | AF5: R3 | AG5: R4 | AH5: R5 | AJ5: Symbol | AK5: R1 | AL5: R2 | AM5: R3 | AN5: R4 | AO5: R5
A6: M1 | B6: M1 | C6: =COUNTIF(K:K, $A6) -> 4 | D6: =COUNTIF(L:L, $A6) -> 22 | E6: =COUNTIF(M:M, $A6) -> 5 | F6: =COUNTIF(N:N, $A6) -> 21 | G6: =COUNTIF(O:O, $A6) -> 23 | H6: 2 | J6: 2 | K6: J | L6: C1 | M6: K | N6: GJ | O6: M1 | Q6: 10 | R6: 1 | S6: 8 | T6: 19 | U6: 2 | W6: 1 | X6: 1 | Y6: 1 | Z6: 1 | AA6: 1 | AC6: {=$A$4:$A$23} -> WW | AD6: 0 | AE6: 0 | AF6: 0 | AG6: 0 | AH6: 0 | AJ6: {=$A$4:$A$23} -> WW | AK6: {=$AD$6:$AH$25} -> 0 | AL6: 0 | AM6: 0 | AN6: 0 | AO6: 0
A7: M2 | B7: M2 | C7: =COUNTIF(K:K, $A7) -> 4 | D7: =COUNTIF(L:L, $A7) -> 10 | E7: =COUNTIF(M:M, $A7) -> 5 | F7: =COUNTIF(N:N, $A7) -> 21 | G7: =COUNTIF(O:O, $A7) -> 23 | H7: 3 | J7: 3 | K7: A | L7: J | M7: M4 | N7: M1 | O7: M4 | Q7: 7 | R7: 10 | S7: 5 | T7: 2 | U7: 5 | W7: 1 | X7: 1 | Y7: 1 | Z7: 1 | AA7: 1 | AC7: C1 | AD7: 0 | AE7: 6 | AF7: 0 | AG7: 9 | AH7: 0 | AJ7: C1 | AK7: 0 | AL7: 6 | AM7: 0 | AN7: 9 | AO7: 0
A8: M3 | B8: M3 | C8: =COUNTIF(K:K, $A8) -> 4 | D8: =COUNTIF(L:L, $A8) -> 9 | E8: =COUNTIF(M:M, $A8) -> 5 | F8: =COUNTIF(N:N, $A8) -> 21 | G8: =COUNTIF(O:O, $A8) -> 22 | H8: 4 | J8: 4 | K8: M5 | L8: G1 | M8: M3 | N8: G2 | O8: A | Q8: 6 | R8: 11 | S8: 4 | T8: 12 | U8: 7 | W8: 1 | X8: 1 | Y8: 1 | Z8: 1 | AA8: 1 | AC8: M1 | AD8: 4 | AE8: 22 | AF8: 5 | AG8: 21 | AH8: 23 | AJ8: M1 | AK8: 4 | AL8: 22 | AM8: 5 | AN8: 21 | AO8: 23
A9: M4 | B9: M4 | C9: =COUNTIF(K:K, $A9) -> 43 | D9: =COUNTIF(L:L, $A9) -> 13 | E9: =COUNTIF(M:M, $A9) -> 41 | F9: =COUNTIF(N:N, $A9) -> 14 | G9: =COUNTIF(O:O, $A9) -> 22 | H9: 5 | J9: 5 | K9: K | L9: K | M9: M4 | N9: M1 | O9: K | Q9: 8 | R9: 8 | S9: 5 | T9: 2 | U9: 8 | W9: 1 | X9: 1 | Y9: 1 | Z9: 1 | AA9: 1 | AC9: M2 | AD9: 4 | AE9: 10 | AF9: 5 | AG9: 21 | AH9: 23 | AJ9: M2 | AK9: 4 | AL9: 10 | AM9: 5 | AN9: 21 | AO9: 23
A10: M5 | B10: M5 | C10: =COUNTIF(K:K, $A10) -> 43 | D10: =COUNTIF(L:L, $A10) -> 14 | E10: =COUNTIF(M:M, $A10) -> 41 | F10: =COUNTIF(N:N, $A10) -> 14 | G10: =COUNTIF(O:O, $A10) -> 22 | H10: 6 | J10: 6 | K10: M5 | L10: G1 | M10: A | N10: M4 | O10: A | Q10: 6 | R10: 11 | S10: 7 | T10: 5 | U10: 7 | W10: 1 | X10: 1 | Y10: 1 | Z10: 1 | AA10: 1 | AC10: M3 | AD10: 4 | AE10: 9 | AF10: 5 | AG10: 21 | AH10: 22 | AJ10: M3 | AK10: 4 | AL10: 9 | AM10: 5 | AN10: 21 | AO10: 22
A11: A | B11: A | C11: =COUNTIF(K:K, $A11) -> 47 | D11: =COUNTIF(L:L, $A11) -> 14 | E11: =COUNTIF(M:M, $A11) -> 41 | F11: =COUNTIF(N:N, $A11) -> 14 | G11: =COUNTIF(O:O, $A11) -> 22 | H11: 7 | J11: 7 | K11: K | L11: G1 | M11: M4 | N11: C1 | O11: A | Q11: 8 | R11: 11 | S11: 5 | T11: 1 | U11: 7 | W11: 1 | X11: 1 | Y11: 1 | Z11: 1 | AA11: 1 | AC11: M4 | AD11: 43 | AE11: 13 | AF11: 41 | AG11: 14 | AH11: 22 | AJ11: M4 | AK11: 43 | AL11: 13 | AM11: 41 | AN11: 14 | AO11: 22
A12: K | B12: K | C12: =COUNTIF(K:K, $A12) -> 47 | D12: =COUNTIF(L:L, $A12) -> 18 | E12: =COUNTIF(M:M, $A12) -> 41 | F12: =COUNTIF(N:N, $A12) -> 14 | G12: =COUNTIF(O:O, $A12) -> 22 | H12: 8 | J12: 8 | K12: M5 | L12: J | M12: M5 | N12: Q | O12: M3 | Q12: 6 | R12: 10 | S12: 6 | T12: 9 | U12: 4 | W12: 1 | X12: 1 | Y12: 1 | Z12: 1 | AA12: 1 | AC12: M5 | AD12: 43 | AE12: 14 | AF12: 41 | AG12: 14 | AH12: 22 | AJ12: M5 | AK12: 43 | AL12: 14 | AM12: 41 | AN12: 14 | AO12: 22
A13: Q | B13: Q | C13: =COUNTIF(K:K, $A13) -> 4 | D13: =COUNTIF(L:L, $A13) -> 5 | E13: =COUNTIF(M:M, $A13) -> 5 | F13: =COUNTIF(N:N, $A13) -> 20 | G13: =COUNTIF(O:O, $A13) -> 22 | H13: 9 | J13: 9 | K13: K | L13: M3 | M13: Q | N13: Q | O13: M5 | Q13: 8 | R13: 4 | S13: 9 | T13: 9 | U13: 6 | W13: 1 | X13: 1 | Y13: 1 | Z13: 1 | AA13: 1 | AC13: A | AD13: 47 | AE13: 14 | AF13: 41 | AG13: 14 | AH13: 22 | AJ13: A | AK13: 47 | AL13: 14 | AM13: 41 | AN13: 14 | AO13: 22
A14: J | B14: J | C14: =COUNTIF(K:K, $A14) -> 4 | D14: =COUNTIF(L:L, $A14) -> 9 | E14: =COUNTIF(M:M, $A14) -> 4 | F14: =COUNTIF(N:N, $A14) -> 20 | G14: =COUNTIF(O:O, $A14) -> 22 | H14: 10 | J14: 10 | K14: M5 | L14: M1 | M14: M5 | N14: J | O14: Q | Q14: 6 | R14: 2 | S14: 6 | T14: 10 | U14: 9 | W14: 1 | X14: 1 | Y14: 1 | Z14: 1 | AA14: 1 | AC14: K | AD14: 47 | AE14: 18 | AF14: 41 | AG14: 14 | AH14: 22 | AJ14: K | AK14: 47 | AL14: 18 | AM14: 41 | AN14: 14 | AO14: 22
A15: G1 | B15: Rainbow M1 | C15: =COUNTIF(K:K, $A15) -> 0 | D15: =COUNTIF(L:L, $A15) -> 16 | E15: =COUNTIF(M:M, $A15) -> 0 | F15: =COUNTIF(N:N, $A15) -> 4 | G15: =COUNTIF(O:O, $A15) -> 0 | H15: 11 | J15: 11 | K15: M5 | L15: GQ | M15: K | N15: M2 | O15: K | Q15: 6 | R15: 18 | S15: 8 | T15: 3 | U15: 8 | W15: 1 | X15: 1 | Y15: 1 | Z15: 1 | AA15: 1 | AC15: Q | AD15: 4 | AE15: 5 | AF15: 5 | AG15: 20 | AH15: 22 | AJ15: Q | AK15: 4 | AL15: 5 | AM15: 5 | AN15: 20 | AO15: 22
A16: G2 | B16: Rainbow M2 | C16: =COUNTIF(K:K, $A16) -> 0 | D16: =COUNTIF(L:L, $A16) -> 5 | E16: =COUNTIF(M:M, $A16) -> 0 | F16: =COUNTIF(N:N, $A16) -> 4 | G16: =COUNTIF(O:O, $A16) -> 0 | H16: 12 | J16: 12 | K16: M5 | L16: M4 | M16: M5 | N16: A | O16: K | Q16: 6 | R16: 5 | S16: 6 | T16: 7 | U16: 8 | W16: 1 | X16: 1 | Y16: 1 | Z16: 1 | AA16: 1 | AC16: J | AD16: 4 | AE16: 9 | AF16: 4 | AG16: 20 | AH16: 22 | AJ16: J | AK16: 4 | AL16: 9 | AM16: 4 | AN16: 20 | AO16: 22 | AQ16: 1.5
A17: G3 | B17: Rainbow M3 | C17: =COUNTIF(K:K, $A17) -> 0 | D17: =COUNTIF(L:L, $A17) -> 7 | E17: =COUNTIF(M:M, $A17) -> 0 | F17: =COUNTIF(N:N, $A17) -> 4 | G17: =COUNTIF(O:O, $A17) -> 0 | H17: 13 | J17: 13 | K17: K | L17: GA | M17: K | N17: M4 | O17: M3 | Q17: 8 | R17: 16 | S17: 8 | T17: 5 | U17: 4 | W17: 1 | X17: 1 | Y17: 1 | Z17: 1 | AA17: 1 | AC17: G1 | AD17: 0 | AE17: 48 | AF17: 0 | AG17: 12 | AH17: 0 | AJ17: G1 | AK17: 0 | AL17: 48 | AM17: 0 | AN17: 12 | AO17: 0 | AQ17: {=INT(AE17:AG25*AQ16)} -> 72 | AR17: 0 | AS17: 18
A18: G4 | B18: Rainbow M4 | C18: =COUNTIF(K:K, $A18) -> 0 | D18: =COUNTIF(L:L, $A18) -> 10 | E18: =COUNTIF(M:M, $A18) -> 3 | F18: =COUNTIF(N:N, $A18) -> 3 | G18: =COUNTIF(O:O, $A18) -> 0 | H18: 14 | J18: 14 | K18: A | L18: M3 | M18: M3 | N18: C1 | O18: J | Q18: 7 | R18: 4 | S18: 4 | T18: 1 | U18: 10 | W18: 1 | X18: 1 | Y18: 1 | Z18: 1 | AA18: 1 | AC18: G2 | AD18: 0 | AE18: 15 | AF18: 0 | AG18: 12 | AH18: 0 | AJ18: G2 | AK18: 0 | AL18: 15 | AM18: 0 | AN18: 12 | AO18: 0 | AQ18: 22 | AR18: 0 | AS18: 18
A19: G5 | B19: Rainbow M5 | C19: =COUNTIF(K:K, $A19) -> 0 | D19: =COUNTIF(L:L, $A19) -> 11 | E19: =COUNTIF(M:M, $A19) -> 3 | F19: =COUNTIF(N:N, $A19) -> 3 | G19: =COUNTIF(O:O, $A19) -> 0 | H19: 15 | J19: 15 | K19: M1 | L19: G1 | M19: K | N19: J | O19: A | Q19: 2 | R19: 11 | S19: 8 | T19: 10 | U19: 7 | W19: 1 | X19: 1 | Y19: 1 | Z19: 1 | AA19: 1 | AC19: G3 | AD19: 0 | AE19: 21 | AF19: 0 | AG19: 12 | AH19: 0 | AJ19: G3 | AK19: 0 | AL19: 21 | AM19: 0 | AN19: 12 | AO19: 0 | AQ19: 31 | AR19: 0 | AS19: 18
A20: GA | B20: Rainbow A | C20: =COUNTIF(K:K, $A20) -> 0 | D20: =COUNTIF(L:L, $A20) -> 11 | E20: =COUNTIF(M:M, $A20) -> 3 | F20: =COUNTIF(N:N, $A20) -> 3 | G20: =COUNTIF(O:O, $A20) -> 0 | H20: 16 | J20: 16 | K20: M3 | L20: G1 | M20: M4 | N20: M1 | O20: M1 | Q20: 4 | R20: 11 | S20: 5 | T20: 2 | U20: 2 | W20: 1 | X20: 1 | Y20: 1 | Z20: 1 | AA20: 1 | AC20: G4 | AD20: 0 | AE20: 30 | AF20: 9 | AG20: 9 | AH20: 0 | AJ20: G4 | AK20: 0 | AL20: 30 | AM20: 9 | AN20: 9 | AO20: 0 | AQ20: 45 | AR20: 13 | AS20: 13
A21: GK | B21: Rainbow K | C21: =COUNTIF(K:K, $A21) -> 0 | D21: =COUNTIF(L:L, $A21) -> 8 | E21: =COUNTIF(M:M, $A21) -> 3 | F21: =COUNTIF(N:N, $A21) -> 3 | G21: =COUNTIF(O:O, $A21) -> 0 | H21: 17 | J21: 17 | K21: M4 | L21: M5 | M21: A | N21: M3 | O21: M3 | Q21: 5 | R21: 6 | S21: 7 | T21: 4 | U21: 4 | W21: 1 | X21: 1 | Y21: 1 | Z21: 1 | AA21: 1 | AC21: G5 | AD21: 0 | AE21: 33 | AF21: 9 | AG21: 9 | AH21: 0 | AJ21: G5 | AK21: 0 | AL21: 33 | AM21: 9 | AN21: 9 | AO21: 0 | AQ21: 49 | AR21: 13 | AS21: 13
A22: GQ | B22: Rainbow Q | C22: =COUNTIF(K:K, $A22) -> 0 | D22: =COUNTIF(L:L, $A22) -> 6 | E22: =COUNTIF(M:M, $A22) -> 0 | F22: =COUNTIF(N:N, $A22) -> 4 | G22: =COUNTIF(O:O, $A22) -> 0 | H22: 18 | J22: 18 | K22: M4 | L22: M3 | M22: M4 | N22: J | O22: M3 | Q22: 5 | R22: 4 | S22: 5 | T22: 10 | U22: 4 | W22: 1 | X22: 1 | Y22: 1 | Z22: 1 | AA22: 1 | AC22: GA | AD22: 0 | AE22: 33 | AF22: 9 | AG22: 9 | AH22: 0 | AJ22: GA | AK22: 0 | AL22: 33 | AM22: 9 | AN22: 9 | AO22: 0 | AQ22: 49 | AR22: 13 | AS22: 13
A23: GJ | B23: Rainbow J | C23: =COUNTIF(K:K, $A23) -> 0 | D23: =COUNTIF(L:L, $A23) -> 6 | E23: =COUNTIF(M:M, $A23) -> 0 | F23: =COUNTIF(N:N, $A23) -> 4 | G23: =COUNTIF(O:O, $A23) -> 0 | H23: 19 | J23: 19 | K23: K | L23: GA | M23: A | N23: Q | O23: M2 | Q23: 8 | R23: 16 | S23: 7 | T23: 9 | U23: 3 | W23: 1 | X23: 1 | Y23: 1 | Z23: 1 | AA23: 1 | AC23: GK | AD23: 0 | AE23: 24 | AF23: 9 | AG23: 9 | AH23: 0 | AJ23: GK | AK23: 0 | AL23: 24 | AM23: 9 | AN23: 9 | AO23: 0 | AQ23: 36 | AR23: 13 | AS23: 13
C24: =SUM(C4:C23) -> 200 | D24: =SUM(D4:D23) -> 200 | E24: =SUM(E4:E23) -> 200 | F24: =SUM(F4:F23) -> 200 | G24: =SUM(G4:G23) -> 200 | J24: 20 | K24: A | L24: A | M24: M4 | N24: GK | O24: A | Q24: 7 | R24: 7 | S24: 5 | T24: 17 | U24: 7 | W24: 1 | X24: 1 | Y24: 1 | Z24: 1 | AA24: 1 | AC24: GQ | AD24: 0 | AE24: 18 | AF24: 0 | AG24: 12 | AH24: 0 | AJ24: GQ | AK24: 0 | AL24: 18 | AM24: 0 | AN24: 12 | AO24: 0 | AQ24: 27 | AR24: 0 | AS24: 18
J25: 21 | K25: M4 | L25: K | M25: M4 | N25: M1 | O25: M2 | Q25: 5 | R25: 8 | S25: 5 | T25: 2 | U25: 3 | W25: 1 | X25: 1 | Y25: 1 | Z25: 1 | AA25: 1 | AC25: GJ | AD25: 0 | AE25: 18 | AF25: 0 | AG25: 12 | AH25: 0 | AJ25: GJ | AK25: 0 | AL25: 18 | AM25: 0 | AN25: 12 | AO25: 0 | AQ25: 27 | AR25: 0 | AS25: 18
B26: Normal Symbol | C26: =SUM(C4:C14)/C24 -> 1 | D26: =SUM(D4:D14)/D24 -> 0.6 | E26: =SUM(E4:E14)/E24 -> 0.94 | F26: =SUM(F4:F14)/F24 -> 0.84 | G26: =SUM(G4:G14)/G24 -> 1 | J26: 22 | K26: Q | L26: G4 | M26: M4 | N26: M1 | O26: M1 | Q26: 9 | R26: 14 | S26: 5 | T26: 2 | U26: 2 | W26: 1 | X26: 1 | Y26: 1 | Z26: 1 | AA26: 1 | AD26: =SUM(AD6:AD25) -> 200 | AE26: =SUM(AE6:AE25) -> 360 | AF26: =SUM(AF6:AF25) -> 224 | AG26: =SUM(AG6:AG25) -> 264 | AH26: =SUM(AH6:AH25) -> 200 | AK26: =SUM(AK6:AK25) -> 200 | AL26: =SUM(AL6:AL25) -> 360 | AM26: =SUM(AM6:AM25) -> 224 | AN26: =SUM(AN6:AN25) -> 264 | AO26: =SUM(AO6:AO25) -> 200
B27: Rainbow Symbol | C27: =SUM(C15:C23)/C24 -> 0 | D27: =SUM(D15:D23)/D24 -> 0.4 | E27: =SUM(E15:E23)/E24 -> 0.06 | F27: =SUM(F15:F23)/F24 -> 0.16 | G27: =SUM(G15:G23)/G24 -> 0 | J27: 23 | K27: A | L27: M5 | M27: M5 | N27: A | O27: M1 | Q27: 7 | R27: 6 | S27: 6 | T27: 7 | U27: 2 | W27: 1 | X27: 1 | Y27: 1 | Z27: 1 | AA27: 1
J28: 24 | K28: K | L28: M4 | M28: A | N28: M4 | O28: J | Q28: 8 | R28: 5 | S28: 7 | T28: 5 | U28: 10 | W28: 1 | X28: 1 | Y28: 1 | Z28: 1 | AA28: 1 | AC28: 2 Combo | AJ28: 2 Combo
J29: 25 | K29: M4 | L29: GQ | M29: K | N29: Q | O29: K | Q29: 5 | R29: 18 | S29: 8 | T29: 9 | U29: 8 | W29: 1 | X29: 1 | Y29: 1 | Z29: 1 | AA29: 1 | AC29: Symbol | AD29: R1 | AE29: R2 | AF29: R3 | AG29: R4 | AH29: R5 | AJ29: Symbol | AK29: R1 | AL29: R2 | AM29: R3 | AN29: R4 | AO29: R5
J30: 26 | K30: A | L30: G4 | M30: A | N30: M2 | O30: M2 | Q30: 7 | R30: 14 | S30: 7 | T30: 3 | U30: 3 | W30: 1 | X30: 1 | Y30: 1 | Z30: 1 | AA30: 1 | AC30: {=$A$4:$A$23} -> WW | AD30: {=$AD$6:$AH$25} -> 0 | AE30: 0 | AF30: 0 | AG30: 0 | AH30: 0 | AJ30: {=$A$4:$A$23} -> WW | AK30: {=$AD$6:$AH$25} -> 0 | AL30: 0 | AM30: 0 | AN30: 0 | AO30: 0
J31: 27 | K31: K | L31: K | M31: A | N31: A | O31: M3 | Q31: 8 | R31: 8 | S31: 7 | T31: 7 | U31: 4 | W31: 1 | X31: 1 | Y31: 1 | Z31: 1 | AA31: 1 | AC31: C1 | AD31: 0 | AE31: 6 | AF31: 0 | AG31: 9 | AH31: 0 | AJ31: C1 | AK31: 0 | AL31: 6 | AM31: 0 | AN31: 9 | AO31: 0
J32: 28 | K32: M4 | L32: M2 | M32: M5 | N32: M2 | O32: M5 | Q32: 5 | R32: 3 | S32: 6 | T32: 3 | U32: 6 | W32: 1 | X32: 1 | Y32: 1 | Z32: 1 | AA32: 1 | AC32: M1 | AD32: 4 | AE32: 22 | AF32: 5 | AG32: 21 | AH32: 23 | AJ32: M1 | AK32: 4 | AL32: 22 | AM32: 5 | AN32: 21 | AO32: 23
J33: 29 | K33: Q | L33: M1 | M33: GK | N33: M2 | O33: Q | Q33: 9 | R33: 2 | S33: 17 | T33: 3 | U33: 9 | W33: 1 | X33: 1 | Y33: 1 | Z33: 1 | AA33: 1 | AC33: M2 | AD33: 4 | AE33: 10 | AF33: 5 | AG33: 21 | AH33: 23 | AJ33: M2 | AK33: 4 | AL33: 10 | AM33: 5 | AN33: 21 | AO33: 23
J34: 30 | K34: M4 | L34: G5 | M34: M4 | N34: M3 | O34: M1 | Q34: 5 | R34: 15 | S34: 5 | T34: 4 | U34: 2 | W34: 1 | X34: 1 | Y34: 1 | Z34: 1 | AA34: 1 | AC34: M3 | AD34: 4 | AE34: 9 | AF34: 5 | AG34: 21 | AH34: 22 | AJ34: M3 | AK34: 4 | AL34: 9 | AM34: 5 | AN34: 21 | AO34: 22
J35: 31 | K35: M4 | L35: G3 | M35: J | N35: J | O35: M1 | Q35: 5 | R35: 13 | S35: 10 | T35: 10 | U35: 2 | W35: 1 | X35: 1 | Y35: 1 | Z35: 1 | AA35: 1 | AC35: M4 | AD35: 43 | AE35: 13 | AF35: 41 | AG35: 14 | AH35: 22 | AJ35: M4 | AK35: 43 | AL35: 13 | AM35: 41 | AN35: 14 | AO35: 22
J36: 32 | K36: M4 | L36: M3 | M36: K | N36: J | O36: M3 | Q36: 5 | R36: 4 | S36: 8 | T36: 10 | U36: 4 | W36: 1 | X36: 1 | Y36: 1 | Z36: 1 | AA36: 1 | AC36: M5 | AD36: 43 | AE36: 14 | AF36: 41 | AG36: 14 | AH36: 22 | AJ36: M5 | AK36: 43 | AL36: 14 | AM36: 41 | AN36: 14 | AO36: 22
J37: 33 | K37: M5 | L37: M1 | M37: G5 | N37: A | O37: M3 | Q37: 6 | R37: 2 | S37: 15 | T37: 7 | U37: 4 | W37: 1 | X37: 1 | Y37: 1 | Z37: 1 | AA37: 1 | AC37: A | AD37: 47 | AE37: 14 | AF37: 41 | AG37: 14 | AH37: 22 | AJ37: A | AK37: 47 | AL37: 14 | AM37: 41 | AN37: 14 | AO37: 22
J38: 34 | K38: K | L38: Q | M38: M4 | N38: A | O38: M2 | Q38: 8 | R38: 9 | S38: 5 | T38: 7 | U38: 3 | W38: 1 | X38: 1 | Y38: 1 | Z38: 1 | AA38: 1 | AC38: K | AD38: 47 | AE38: 18 | AF38: 41 | AG38: 14 | AH38: 22 | AJ38: K | AK38: 47 | AL38: 18 | AM38: 41 | AN38: 14 | AO38: 22
J39: 35 | K39: A | L39: G5 | M39: M4 | N39: M5 | O39: Q | Q39: 7 | R39: 15 | S39: 5 | T39: 6 | U39: 9 | W39: 1 | X39: 1 | Y39: 1 | Z39: 1 | AA39: 1 | AC39: Q | AD39: 4 | AE39: 5 | AF39: 5 | AG39: 20 | AH39: 22 | AJ39: Q | AK39: 4 | AL39: 5 | AM39: 5 | AN39: 20 | AO39: 22
J40: 36 | K40: M5 | L40: M5 | M40: J | N40: G3 | O40: K | Q40: 6 | R40: 6 | S40: 10 | T40: 13 | U40: 8 | W40: 1 | X40: 1 | Y40: 1 | Z40: 1 | AA40: 1 | AC40: J | AD40: 4 | AE40: 9 | AF40: 4 | AG40: 20 | AH40: 22 | AJ40: J | AK40: 4 | AL40: 9 | AM40: 4 | AN40: 20 | AO40: 22
J41: 37 | K41: A | L41: M4 | M41: M5 | N41: M3 | O41: K | Q41: 7 | R41: 5 | S41: 6 | T41: 4 | U41: 8 | W41: 1 | X41: 1 | Y41: 1 | Z41: 1 | AA41: 1 | AC41: G1 | AD41: 0 | AE41: 48 | AF41: 0 | AG41: 12 | AH41: 0 | AJ41: G1 | AK41: 0 | AL41: 48 | AM41: 0 | AN41: 12 | AO41: 0
...

Sheet BG_Symbol (2)
J2: Symbol | Q2: Symbol ID | W2: Symbol Weight | AC2: Eliminate Wheel Weight A | AJ2: Eliminate Wheel Weight B
A3: Symbol | B3: Description | C3: R1 | D3: R2 | E3: R3 | F3: R4 | G3: R5 | H3: ID | K3: R1 | L3: R2 | M3: R3 | N3: R4 | O3: R5 | Q3: R1 | R3: R2 | S3: R3 | T3: R4 | U3: R5 | W3: R1 | X3: R2 | Y3: R3 | Z3: R4 | AA3: R5
A4: {=Overview!A43:B62} -> WW | B4: Wild | C4: =COUNTIF(K:K, $A4) -> 0 | D4: =COUNTIF(L:L, $A4) -> 0 | E4: =COUNTIF(M:M, $A4) -> 0 | F4: =COUNTIF(N:N, $A4) -> 0 | G4: =COUNTIF(O:O, $A4) -> 0 | H4: {=Overview!F43:F62} -> 0 | J4: {=_xlfn.SEQUENCE(MAX(COUNTA(K:K), COUNTA(L:L), COUNTA(M:M), COUNTA(N:N), COUNTA(O:O))-1,,0)} -> 0 | K4: K | L4: A | M4: GA | N4: J | O4: M1 | Q4: {=_xlfn.LET(_xlpm.x, K4:O304, IF(_xlpm.x="", "", _xlfn.XLOOKUP(_xlpm.x, $A$4:$A$23,_xlfn.ANCHORARRAY( H4))))} -> 8 | R4: 7 | S4: 16 | T4: 10 | U4: 2 | W4: {=_xlfn.LET(_xlpm.x, K4:K6, IF(SUM((_xlpm.x="K")*1, (_xlpm.x="A")*1, (_xlpm.x="GK")*1, (_xlpm.x="GA")*1)>0, 3, 1))} -> 3 | X4: {=_xlfn.LET(_xlpm.x, L4:L6, IF(SUM((_xlpm.x="K")*1, (_xlpm.x="A")*1, (_xlpm.x="GK")*1, (_xlpm.x="GA")*1)>0, 3, 1))} -> 3 | Y4: {=_xlfn.LET(_xlpm.x, M4:M6, IF(SUM((_xlpm.x="K")*1, (_xlpm.x="A")*1, (_xlpm.x="GK")*1, (_xlpm.x="GA")*1)>0, 3, 1))} -> 3 | Z4: 1 | AA4: 1 | AC4: 1 Combo | AJ4: 1 Combo
A5: C1 | B5: Scatter | C5: =COUNTIF(K:K, $A5) -> 0 | D5: =COUNTIF(L:L, $A5) -> 6 | E5: =COUNTIF(M:M, $A5) -> 0 | F5: =COUNTIF(N:N, $A5) -> 9 | G5: =COUNTIF(O:O, $A5) -> 0 | H5: 1 | J5: 1 | K5: A | L5: A | M5: GQ | N5: M1 | O5: M3 | Q5: 7 | R5: 7 | S5: 18 | T5: 2 | U5: 4 | W5: {=_xlfn.LET(_xlpm.x, K5:K7, IF(SUM((_xlpm.x="K")*1, (_xlpm.x="A")*1, (_xlpm.x="GK")*1, (_xlpm.x="GA")*1)>0, 3, 1))} -> 3 | X5: {=_xlfn.LET(_xlpm.x, L5:L7, IF(SUM((_xlpm.x="K")*1, (_xlpm.x="A")*1, (_xlpm.x="GK")*1, (_xlpm.x="GA")*1)>0, 3, 1))} -> 3 | Y5: {=_xlfn.LET(_xlpm.x, M5:M7, IF(SUM((_xlpm.x="K")*1, (_xlpm.x="A")*1, (_xlpm.x="GK")*1, (_xlpm.x="GA")*1)>0, 3, 1))} -> 1 | Z5: 1 | AA5: 1 | AC5: Symbol | AD5: R1 | AE5: R2 | AF5: R3 | AG5: R4 | AH5: R5 | AJ5: Symbol | AK5: R1 | AL5: R2 | AM5: R3 | AN5: R4 | AO5: R5
A6: M1 | B6: M1 | C6: =COUNTIF(K:K, $A6) -> 4 | D6: =COUNTIF(L:L, $A6) -> 6 | E6: =COUNTIF(M:M, $A6) -> 0 | F6: =COUNTIF(N:N, $A6) -> 22 | G6: =COUNTIF(O:O, $A6) -> 28 | H6: 2 | J6: 2 | K6: M1 | L6: GA | M6: G4 | N6: M3 | O6: M2 | Q6: 2 | R6: 16 | S6: 14 | T6: 4 | U6: 3 | W6: {=_xlfn.LET(_xlpm.x, K6:K8, IF(SUM((_xlpm.x="K")*1, (_xlpm.x="A")*1, (_xlpm.x="GK")*1, (_xlpm.x="GA")*1)>0, 3, 1))} -> 3 | X6: {=_xlfn.LET(_xlpm.x, L6:L8, IF(SUM((_xlpm.x="K")*1, (_xlpm.x="A")*1, (_xlpm.x="GK")*1, (_xlpm.x="GA")*1)>0, 3, 1))} -> 3 | Y6: {=_xlfn.LET(_xlpm.x, M6:M8, IF(SUM((_xlpm.x="K")*1, (_xlpm.x="A")*1, (_xlpm.x="GK")*1, (_xlpm.x="GA")*1)>0, 3, 1))} -> 1 | Z6: 1 | AA6: 1 | AC6: {=$A$4:$A$23} -> WW | AD6: 0 | AE6: 0 | AF6: 0 | AG6: 0 | AH6: 0 | AJ6: {=$A$4:$A$23} -> WW | AK6: {=$AD$6:$AH$25} -> 0 | AL6: 0 | AM6: 0 | AN6: 0 | AO6: 0
A7: M2 | B7: M2 | C7: =COUNTIF(K:K, $A7) -> 4 | D7: =COUNTIF(L:L, $A7) -> 6 | E7: =COUNTIF(M:M, $A7) -> 0 | F7: =COUNTIF(N:N, $A7) -> 22 | G7: =COUNTIF(O:O, $A7) -> 27 | H7: 3 | J7: 3 | K7: M4 | L7: Q | M7: G5 | N7: M3 | O7: M2 | Q7: 5 | R7: 9 | S7: 15 | T7: 4 | U7: 3 | W7: {=_xlfn.LET(_xlpm.x, K7:K9, IF(SUM((_xlpm.x="K")*1, (_xlpm.x="A")*1, (_xlpm.x="GK")*1, (_xlpm.x="GA")*1)>0, 3, 1))} -> 3 | X7: {=_xlfn.LET(_xlpm.x, L7:L9, IF(SUM((_xlpm.x="K")*1, (_xlpm.x="A")*1, (_xlpm.x="GK")*1, (_xlpm.x="GA")*1)>0, 3, 1))} -> 3 | Y7: {=_xlfn.LET(_xlpm.x, M7:M9, IF(SUM((_xlpm.x="K")*1, (_xlpm.x="A")*1, (_xlpm.x="GK")*1, (_xlpm.x="GA")*1)>0, 3, 1))} -> 3 | Z7: 1 | AA7: 1 | AC7: C1 | AD7: 0 | AE7: 6 | AF7: 0 | AG7: 9 | AH7: 0 | AJ7: C1 | AK7: 0 | AL7: 6 | AM7: 0 | AN7: 9 | AO7: 0
A8: M3 | B8: M3 | C8: =COUNTIF(K:K, $A8) -> 4 | D8: =COUNTIF(L:L, $A8) -> 6 | E8: =COUNTIF(M:M, $A8) -> 0 | F8: =COUNTIF(N:N, $A8) -> 22 | G8: =COUNTIF(O:O, $A8) -> 27 | H8: 4 | J8: 4 | K8: K | L8: GA | M8: G4 | N8: M2 | O8: K | Q8: 8 | R8: 16 | S8: 14 | T8: 3 | U8: 8 | W8: {=_xlfn.LET(_xlpm.x, K8:K10, IF(SUM((_xlpm.x="K")*1, (_xlpm.x="A")*1, (_xlpm.x="GK")*1, (_xlpm.x="GA")*1)>0, 3, 1))} -> 3 | X8: {=_xlfn.LET(_xlpm.x, L8:L10, IF(SUM((_xlpm.x="K")*1, (_xlpm.x="A")*1, (_xlpm.x="GK")*1, (_xlpm.x="GA")*1)>0, 3, 1))} -> 3 | Y8: {=_xlfn.LET(_xlpm.x, M8:M10, IF(SUM((_xlpm.x="K")*1, (_xlpm.x="A")*1, (_xlpm.x="GK")*1, (_xlpm.x="GA")*1)>0, 3, 1))} -> 3 | Z8: 1 | AA8: 1 | AC8: M1 | AD8: 4 | AE8: 11 | AF8: 0 | AG8: 22 | AH8: 28 | AJ8: M1 | AK8: 4 | AL8: 11 | AM8: 0 | AN8: 22 | AO8: 28
A9: M4 | B9: M4 | C9: =COUNTIF(K:K, $A9) -> 43 | D9: =COUNTIF(L:L, $A9) -> 19 | E9: =COUNTIF(M:M, $A9) -> 0 | F9: =COUNTIF(N:N, $A9) -> 12 | G9: =COUNTIF(O:O, $A9) -> 16 | H9: 5 | J9: 5 | K9: M5 | L9: M3 | M9: GK | N9: M2 | O9: M2 | Q9: 6 | R9: 4 | S9: 17 | T9: 3 | U9: 3 | W9: {=_xlfn.LET(_xlpm.x, K9:K11, IF(SUM((_xlpm.x="K")*1, (_xlpm.x="A")*1, (_xlpm.x="GK")*1, (_xlpm.x="GA")*1)>0, 3, 1))} -> 3 | X9: {=_xlfn.LET(_xlpm.x, L9:L11, IF(SUM((_xlpm.x="K")*1, (_xlpm.x="A")*1, (_xlpm.x="GK")*1, (_xlpm.x="GA")*1)>0, 3, 1))} -> 1 | Y9: {=_xlfn.LET(_xlpm.x, M9:M11, IF(SUM((_xlpm.x="K")*1, (_xlpm.x="A")*1, (_xlpm.x="GK")*1, (_xlpm.x="GA")*1)>0, 3, 1))} -> 3 | Z9: 1 | AA9: 1 | AC9: M2 | AD9: 4 | AE9: 11 | AF9: 0 | AG9: 22 | AH9: 27 | AJ9: M2 | AK9: 4 | AL9: 11 | AM9: 0 | AN9: 22 | AO9: 27
