Workbook

Sheet Overview
A2: Model: | B2: H026194
A3: Version: | B3: 1.0.0.0
A6: Base Bet
A7: 100
A10: Coin in | B10: Price(x) | C10: Total RTP | D10: Bet Type
A11: {=B11:B12*A7} -> 100 | B11: 1 | C11: =SUM(B17:B18) -> 0.93999989 | D11: Normal Bet
A12: 7500 | B12: 75 | C12: =SUM(B21:B22) -> 0.92499972 | D12: Buy Feature
A15: Total Pay Back Percentage includes the following adjustments.
A16: Bet Type | B16: Pay Back | C16: Hit% | D16: Pulls/Hit | E16: Description
A17: =D11 -> Normal Bet | B17: =Multiplier_Weight_Oldhand!C7 -> 0.70001109 | C17: =1/D17 -> 0.0041949845 | D17: =Multiplier_Weight_Oldhand!G7 -> 238.3799 | E17: Base Game
B18: =Multiplier_Weight_Oldhand!D7 -> 0.2399888 | E18: Free Game
A20: Bet Type | B20: Pay Back | C20: Hit% | D20: Pulls/Hit | E20: Description
A21: =D12 -> Buy Feature | B21: =Multiplier_Weight_Oldhand!C8 -> 0 | C21: =1/D21 -> 1 | D21: 1 | E21: Base Game
B22: =Multiplier_Weight_Oldhand!D8 -> 0.92499972 | E22: Free Game
A25: Reel # | B25: 1 | C25: 2 | D25: 3 | E25: 4 | F25: 5
A26: Visible Window Size | B26: 3 | C26: 3 | D26: 3 | E26: 3 | F26: 3
A29: Free Spins Setting
A30: C1 Num. | B30: Base Game | C30: Free Game
A31: 3 | B31: 15 | C31: 15
A32: 4 | B32: 17 | C32: 17
A33: 5 | B33: 19 | C33: 19
A34: The maximum of free spins is 50.
A36: Pay Table： | B36: ="All wins show for "&A7&" credit bet." -> All wins show for 100 credit bet.
A37: Symbol | B37: Description | C37: 3 | D37: 4 | E37: 5 | F37: Id
A38: WW | B38: Wild | C38: 0 | D38: 0 | E38: 0 | F38: 0
A39: C1 | B39: Scatter | C39: 0 | D39: 0 | E39: 0 | F39: 1
A40: M1 | B40: M1 | C40: 250 | D40: 1250 | E40: 5000 | F40: 2
A41: M2 | B41: M2 | C41: 100 | D41: 500 | E41: 2000 | F41: 3
A42: M3 | B42: M3 | C42: 75 | D42: 250 | E42: 1000 | F42: 4
A43: M4 | B43: M4 | C43: 50 | D43: 200 | E43: 750 | F43: 5
A44: M5 | B44: M5 | C44: 25 | D44: 100 | E44: 500 | F44: 6
A45: A | B45: A | C45: 10 | D45: 50 | E45: 250 | F45: 7
A46: K | B46: K | C46: 10 | D46: 50 | E46: 250 | F46: 8
A47: Q | B47: Q | C47: 10 | D47: 50 | E47: 250 | F47: 9
A48: J | B48: J | C48: 10 | D48: 50 | E48: 250 | F48: 10
A49: G1 | B49: Gold M1 | C49: 250 | D49: 1250 | E49: 5000 | F49: 11
... A57: GJ | B57: Gold J | C57: 10 | D57: 50 | E57: 250 | F57: 19

Sheet Description
B3: 7. BG 流程對應
B5: 7.1 BG 開局流程
B7: BG 每局的主要參數流程如下：
B8: 1. 先用 Table Selection Weight - Base Game 選出 BG table。
B9: 2. 再用該 strip 的 Symbol Weight R1~R5 抽停輪位置。
B10: 3. 依 Symbol ID R1~R5 生成初始盤面。
B11: 4. 盤面上的金框會先判定是否觸發 Used Special Pool Weight。
B12: 5. 若命中特殊池，該金框用 Multiple Selection Weight - Special Pool 抽倍率。
B13: 6. 若沒命中特殊池：
B14: - 且是 BG_Symbol (2) 則第 3 輪金框用 Multiple Selection Weight - Reel3 Before Eliminate
B15: - 其他輪金框用 Multiple Selection Weight - Before Eliminate
B16: 7. 再用 Eliminate Table Weight 決定本局是掉落表 A 或 B。
... B83: 5. BG_Symbol (3): 觸發 FG 用的表。得分少、C1 多，盡量不要有倍數百搭參與 → 控制進 FG 時的得分

Sheet Parameter
B3: Line | I3: Table Selection Weight - Base Game (Weight/Total) | N3: Multiple Selection Weight - Special Pool (Weight/Total) | AC3: Used Special Pool Weight (Weight/10000)
B4: ID | C4: R1 | D4: R2 | E4: R3 | F4: R4 | G4: R5 | I4: Worksheet Name | J4: Weight | K4: RTP | N4: Worksheet Name \ Multiple | O4: 0 | P4: 2 | Q4: 3 | R4: 5 | S4: 8 | T4: 10 | U4: 15 | V4: 20 | W4: 25 | X4: 35 | Y4: 50 | Z4: 80 | AA4: 100 | AC4: Worksheet Name \ Multiple | AD4: 1 | AE4: 2 | AF4: 3 | AG4: 4 | AH4: 5 | AI4: 6 | AJ4: 7 | AK4: 8 | AL4: 9
B5: {=_xlfn.SEQUENCE(20,,0)} -> 0 | C5: 1 | D5: 1 | E5: 1 | F5: 1 | G5: 1 | I5: BG_Symbol | J5: =10000-J6-J7 -> 7000 | L5: {=J5:J7/J8} -> 0.7 | N5: BG_Symbol | O5: =10000-SUM(P5:AA5) -> 0 | P5: 0 | Q5: 0 | R5: 0 | S5: 0 | T5: =10000-SUM(U5:AA5) -> 4140 | U5: 3000 | V5: 2000 | W5: 500 | X5: 60 | Y5: 120 | Z5: 60 | AA5: 120 | AB5: {=SUMPRODUCT(O5:AA5/SUM(O5:AA5),$O$4:$AA$4)} -> 16.38 | AC5: BG_Symbol | AD5: 300 | AE5: 600 | AF5: 1080 | AG5: 1440 | AH5: 2250 | AI5: 2700 | AJ5: 3150 | AK5: 3600 | AL5: 4050
B6: 1 | C6: 0 | D6: 0 | E6: 0 | F6: 0 | G6: 0 | I6: BG_Symbol (2) | J6: 1000 | L6: 0.1 | N6: BG_Symbol (2) | O6: =10000-SUM(P6:AA6) -> 0 | P6: 0 | Q6: 0 | R6: 0 | S6: 0 | T6: =10000-SUM(U6:AA6) -> 4970 | U6: 3000 | V6: 1350 | W6: 500 | X6: 30 | Y6: 60 | Z6: 30 | AA6: 60 | AB6: {=SUMPRODUCT(O6:AA6/SUM(O6:AA6),$O$4:$AA$4)} -> 14.665 | AC6: BG_Symbol (2) | AD6: 0 | AE6: 0 | AF6: 1050 | AG6: 1400 | AH6: 1750 | AI6: 2100 | AJ6: 3675 | AK6: 4200 | AL6: 4725
B7: 2 | C7: 2 | D7: 2 | E7: 2 | F7: 2 | G7: 2 | I7: BG_Symbol (3) | J7: 2000 | L7: 0.2 | N7: BG_Symbol (3) | O7: =10000-SUM(P7:AA7) -> 10000 | P7: 0 | Q7: 0 | R7: 0 | S7: 0 | T7: 0 | U7: 0 | V7: 0 | W7: 0 | X7: 0 | Y7: 0 | Z7: 0 | AA7: 0 | AB7: {=SUMPRODUCT(O7:AA7/SUM(O7:AA7),$O$4:$AA$4)} -> 0 | AC7: BG_Symbol (3) | AD7: 0 | AE7: 0 | AF7: 0 | AG7: 0 | AH7: 0 | AI7: 0 | AJ7: 0 | AK7: 0 | AL7: 0
B8: 3 | C8: 0 | D8: 1 | E8: 2 | F8: 1 | G8: 0 | J8: =SUM(J5:J7) -> 10000 | K8: =SUMPRODUCT(K5:K7,_xlfn.ANCHORARRAY(L5)) -> 0 | N8: FG_Symbol | O8: =10000-SUM(P8:AA8) -> 0 | P8: 0 | Q8: 0 | R8: 0 | S8: 0 | T8: =10000-SUM(U8:AA8) -> 4370 | U8: 2700 | V8: 1400 | W8: 270 | X8: 270 | Y8: 360 | Z8: 270 | AA8: 360 | AB8: {=SUMPRODUCT(O8:AA8/SUM(O8:AA8),$O$4:$AA$4)} -> 20.4 | AC8: FG_Symbol | AD8: 0 | AE8: 0 | AF8: 525 | AG8: 700 | AH8: 1750 | AI8: 2100 | AJ8: 3675 | AK8: 4200 | AL8: 4725
B9: 4 | C9: 2 | D9: 1 | E9: 0 | F9: 1 | G9: 2 | N9: FG_Symbol (2) | O9: =10000-SUM(P9:AA9) -> 0 | P9: 0 | Q9: 0 | R9: 0 | S9: 0 | T9: =10000-SUM(U9:AA9) -> 4370 | U9: 2700 | V9: 1400 | W9: 270 | X9: 270 | Y9: 360 | Z9: 270 | AA9: 360 | AB9: {=SUMPRODUCT(O9:AA9/SUM(O9:AA9),$O$4:$AA$4)} -> 20.4 | AC9: FG_Symbol (2) | AD9: 0 | AE9: 0 | AF9: 525 | AG9: 700 | AH9: 1750 | AI9: 2100 | AJ9: 3675 | AK9: 4200 | AL9: 4725
B10: 5 | C10: 0 | D10: 0 | E10: 1 | F10: 0 | G10: 0 | I10: Table Selection Weight - Free Game (Weight/Total) | N10: FG_Symbol (3) | O10: =10000-SUM(P10:AA10) -> 0 | P10: 0 | Q10: 0 | R10: 0 | S10: 0 | T10: =10000-SUM(U10:AA10) -> 4370 | U10: 2700 | V10: 1400 | W10: 270 | X10: 270 | Y10: 360 | Z10: 270 | AA10: 360 | AB10: {=SUMPRODUCT(O10:AA10/SUM(O10:AA10),$O$4:$AA$4)} -> 20.4 | AC10: FG_Symbol (3) | AD10: 0 | AE10: 0 | AF10: 525 | AG10: 700 | AH10: 1750 | AI10: 2100 | AJ10: 3675 | AK10: 4200 | AL10: 4725
B11: 6 | C11: 2 | D11: 2 | E11: 1 | F11: 2 | G11: 2 | I11: Worksheet Name | J11: Weight | K11: RTP | N11: BF_Symbol | O11: =10000-SUM(P11:AA11) -> 10000 | P11: 0 | Q11: 0 | R11: 0 | S11: 0 | T11: 0 | U11: 0 | V11: 0 | W11: 0 | X11: 0 | Y11: 0 | Z11: 0 | AA11: 0 | AB11: {=SUMPRODUCT(O11:AA11/SUM(O11:AA11),$O$4:$AA$4)} -> 0 | AC11: BF_Symbol | AD11: 0 | AE11: 0 | AF11: 0 | AG11: 0 | AH11: 0 | AI11: 0 | AJ11: 0 | AK11: 0 | AL11: 0
B12: 7 | C12: 1 | D12: 2 | E12: 2 | F12: 2 | G12: 1 | I12: FG_Symbol | J12: =10000-SUM(J13:J14) -> 10000 | L12: {=J12:J14/SUM(J15)} -> 1
B13: 8 | C13: 1 | D13: 0 | E13: 0 | F13: 0 | G13: 1 | I13: FG_Symbol (2) | J13: 0 | L13: 0
B14: 9 | C14: 0 | D14: 1 | E14: 1 | F14: 1 | G14: 0 | I14: FG_Symbol (3) | J14: 0 | L14: 0 | N14: Multiple Selection Weight - Reel3 Before Eliminate (Weight/Total)
B15: 10 | C15: 2 | D15: 1 | E15: 1 | F15: 1 | G15: 2 | J15: =SUM(J12:J14) -> 10000 | K15: =SUMPRODUCT(K12:K14,_xlfn.ANCHORARRAY(L12)) -> 0 | N15: Worksheet Name \ Multiple | O15: 0 | P15: 2 | Q15: 3 | R15: 5 | S15: 8 | T15: 10 | U15: 15 | V15: 20 | W15: 25 | X15: 35 | Y15: 50 | Z15: 80 | AA15: 100
B16: 11 | C16: 1 | D16: 1 | E16: 0 | F16: 1 | G16: 1 | N16: BG_Symbol | O16: =10000-SUM(P16:AA16) -> 10000 | P16: 0 | Q16: 0 | R16: 0 | S16: 0 | T16: 0 | U16: 0 | V16: 0 | W16: 0 | X16: 0 | Y16: 0 | Z16: 0 | AA16: 0 | AB16: {=SUMPRODUCT(O16:AA16/SUM(O16:AA16),$O$4:$AA$4)} -> 0
B17: 12 | C17: 1 | D17: 1 | E17: 2 | F17: 1 | G17: 1 | I17: Table Selection Weight - Buy Feature (Weight/Total) | N17: BG_Symbol (2) | O17: =10000-SUM(P17:AA17) -> 0 | P17: =10000-SUM(Q17:AA17) -> 3600 | Q17: 3400 | R17: 1500 | S17: 1500 | T17: 0 | U17: 0 | V17: 0 | W17: 0 | X17: 0 | Y17: 0 | Z17: 0 | AA17: 0 | AB17: {=SUMPRODUCT(O17:AA17/SUM(O17:AA17),$O$4:$AA$4)} -> 3.69
B18: 13 | C18: 1 | D18: 0 | E18: 1 | F18: 0 | G18: 1 | I18: Worksheet Name | J18: Weight | K18: RTP | N18: BG_Symbol (3) | O18: =10000-SUM(P18:AA18) -> 10000 | P18: 0 | Q18: 0 | R18: 0 | S18: 0 | T18: 0 | U18: 0 | V18: 0 | W18: 0 | X18: 0 | Y18: 0 | Z18: 0 | AA18: 0 | AB18: {=SUMPRODUCT(O18:AA18/SUM(O18:AA18),$O$4:$AA$4)} -> 0
B19: 14 | C19: 1 | D19: 2 | E19: 1 | F19: 2 | G19: 1 | I19: FG_Symbol | J19: =10000-SUM(J20:J21) -> 10000 | L19: {=J19:J21/SUM(J22)} -> 1 | N19: FG_Symbol | O19: =10000-SUM(P19:AA19) -> 0 | P19: =10000-SUM(Q19:AA19) -> 6300 | Q19: 2800 | R19: 600 | S19: 300 | T19: 0 | U19: 0 | V19: 0 | W19: 0 | X19: 0 | Y19: 0 | Z19: 0 | AA19: 0 | AB19: {=SUMPRODUCT(O19:AA19/SUM(O19:AA19),$O$4:$AA$4)} -> 2.64
B20: 15 | C20: 0 | D20: 1 | E20: 0 | F20: 1 | G20: 0 | I20: FG_Symbol (2) | J20: 0 | L20: 0 | N20: FG_Symbol (2) | O20: =10000-SUM(P20:AA20) -> 0 | P20: =10000-SUM(Q20:AA20) -> 6300 | Q20: 2800 | R20: 600 | S20: 300 | T20: 0 | U20: 0 | V20: 0 | W20: 0 | X20: 0 | Y20: 0 | Z20: 0 | AA20: 0 | AB20: {=SUMPRODUCT(O20:AA20/SUM(O20:AA20),$O$4:$AA$4)} -> 2.64
B21: 16 | C21: 2 | D21: 1 | E21: 2 | F21: 1 | G21: 2 | I21: FG_Symbol (3) | J21: 0 | L21: 0 | N21: FG_Symbol (3) | O21: =10000-SUM(P21:AA21) -> 0 | P21: =10000-SUM(Q21:AA21) -> 6300 | Q21: 2800 | R21: 600 | S21: 300 | T21: 0 | U21: 0 | V21: 0 | W21: 0 | X21: 0 | Y21: 0 | Z21: 0 | AA21: 0 | AB21: {=SUMPRODUCT(O21:AA21/SUM(O21:AA21),$O$4:$AA$4)} -> 2.64
B22: 17 | C22: 0 | D22: 0 | E22: 1 | F22: 2 | G22: 2 | J22: =SUM(J19:J21) -> 10000 | K22: =SUMPRODUCT(K19:K21,_xlfn.ANCHORARRAY(L19)) -> 0 | N22: BF_Symbol | O22: =10000-SUM(P22:AA22) -> 10000 | P22: 0 | Q22: 0 | R22: 0 | S22: 0 | T22: 0 | U22: 0 | V22: 0 | W22: 0 | X22: 0 | Y22: 0 | Z22: 0 | AA22: 0 | AB22: {=SUMPRODUCT(O22:AA22/SUM(O22:AA22),$O$4:$AA$4)} -> 0
B23: 18 | C23: 2 | D23: 2 | E23: 1 | F23: 0 | G23: 0
B24: 19 | C24: 0 | D24: 2 | E24: 0 | F24: 2 | G24: 0 | I24: Multiplier Range
I25: Multiplier | N25: Multiple Selection Weight - Reel3 After Eliminate (Weight/Total)
I26: 0 | N26: Worksheet Name \ Multiple | O26: 0 | P26: 2 | Q26: 3 | R26: 5 | S26: 8 | T26: 10 | U26: 15 | V26: 20 | W26: 25 | X26: 35 | Y26: 50 | Z26: 80 | AA26: 100
I27: 2 | N27: BG_Symbol | O27: =10000-SUM(P27:AA27) -> 10000 | P27: 0 | Q27: 0 | R27: 0 | S27: 0 | T27: 0 | U27: 0 | V27: 0 | W27: 0 | X27: 0 | Y27: 0 | Z27: 0 | AA27: 0 | AB27: {=SUMPRODUCT(O27:AA27/SUM(O27:AA27),$O$4:$AA$4)} -> 0
I28: 3 | N28: BG_Symbol (2) | O28: =10000-SUM(P28:AA28) -> 0 | P28: =10000-SUM(Q28:AA28) -> 4000 | Q28: 4000 | R28: 1000 | S28: 1000 | T28: 0 | U28: 0 | V28: 0 | W28: 0 | X28: 0 | Y28: 0 | Z28: 0 | AA28: 0 | AB28: {=SUMPRODUCT(O28:AA28/SUM(O28:AA28),$O$4:$AA$4)} -> 3.3
I29: 5 | N29: BG_Symbol (3) | O29: =10000-SUM(P29:AA29) -> 10000 | P29: 0 | Q29: 0 | R29: 0 | S29: 0 | T29: 0 | U29: 0 | V29: 0 | W29: 0 | X29: 0 | Y29: 0 | Z29: 0 | AA29: 0 | AB29: {=SUMPRODUCT(O29:AA29/SUM(O29:AA29),$O$4:$AA$4)} -> 0
I30: 8 | N30: FG_Symbol | O30: =10000-SUM(P30:AA30) -> 0 | P30: =10000-SUM(Q30:AA30) -> 6550 | Q30: 3000 | R30: 300 | S30: 150 | T30: 0 | U30: 0 | V30: 0 | W30: 0 | X30: 0 | Y30: 0 | Z30: 0 | AA30: 0 | AB30: {=SUMPRODUCT(O30:AA30/SUM(O30:AA30),$O$4:$AA$4)} -> 2.48
I31: 10 | N31: FG_Symbol (2) | O31: =10000-SUM(P31:AA31) -> 0 | P31: =10000-SUM(Q31:AA31) -> 6550 | Q31: 3000 | R31: 300 | S31: 150 | T31: 0 | U31: 0 | V31: 0 | W31: 0 | X31: 0 | Y31: 0 | Z31: 0 | AA31: 0 | AB31: {=SUMPRODUCT(O31:AA31/SUM(O31:AA31),$O$4:$AA$4)} -> 2.48
I32: 15 | N32: FG_Symbol (3) | O32: =10000-SUM(P32:AA32) -> 0 | P32: =10000-SUM(Q32:AA32) -> 6550 | Q32: 3000 | R32: 300 | S32: 150 | T32: 0 | U32: 0 | V32: 0 | W32: 0 | X32: 0 | Y32: 0 | Z32: 0 | AA32: 0 | AB32: {=SUMPRODUCT(O32:AA32/SUM(O32:AA32),$O$4:$AA$4)} -> 2.48
I33: 20 | N33: BF_Symbol | O33: =10000-SUM(P33:AA33) -> 10000 | P33: 0 | Q33: 0 | R33: 0 | S33: 0 | T33: 0 | U33: 0 | V33: 0 | W33: 0 | X33: 0 | Y33: 0 | Z33: 0 | AA33: 0 | AB33: {=SUMPRODUCT(O33:AA33/SUM(O33:AA33),$O$4:$AA$4)} -> 0
I34: 25
I35: 35
I36: 50 | N36: Multiple Selection Weight - Before Eliminate (Weight/Total)
I37: 80 | N37: Worksheet Name \ Multiple | O37: 0 | P37: 2 | Q37: 3 | R37: 5 | S37: 8 | T37: 10 | U37: 15 | V37: 20 | W37: 25 | X37: 35 | Y37: 50 | Z37: 80 | AA37: 100
I38: 100 | N38: BG_Symbol | O38: =10000-SUM(P38:AA38) -> 8500 | P38: 500 | Q38: 400 | R38: 300 | S38: 300 | T38: 0 | U38: 0 | V38: 0 | W38: 0 | X38: 0 | Y38: 0 | Z38: 0 | AA38: 0 | AB38: {=SUMPRODUCT(P38:AA38/SUM(P38:AA38),$P$4:$AA$4)} -> 4.0666667
N39: BG_Symbol (2) | O39: =10000-SUM(P39:AA39) -> 9100 | P39: 350 | Q39: 250 | R39: 150 | S39: 150 | T39: 0 | U39: 0 | V39: 0 | W39: 0 | X39: 0 | Y39: 0 | Z39: 0 | AA39: 0 | AB39: {=SUMPRODUCT(P39:AA39/SUM(P39:AA39),$P$4:$AA$4)} -> 3.7777778
N40: BG_Symbol (3) | O40: =10000-SUM(P40:AA40) -> 9200 | P40: 400 | Q40: 300 | R40: 50 | S40: 50 | T40: 0 | U40: 0 | V40: 0 | W40: 0 | X40: 0 | Y40: 0 | Z40: 0 | AA40: 0 | AB40: {=SUMPRODUCT(P40:AA40/SUM(P40:AA40),$P$4:$AA$4)} -> 2.9375
I41: Eliminate Table Weight | N41: FG_Symbol | O41: =10000-SUM(P41:AA41) -> 6710 | P41: 2100 | Q41: 860 | R41: 220 | S41: 110 | T41: 0 | U41: 0 | V41: 0 | W41: 0 | X41: 0 | Y41: 0 | Z41: 0 | AA41: 0 | AB41: {=SUMPRODUCT(P41:AA41/SUM(P41:AA41),$P$4:$AA$4)} -> 2.662614
J42: A | K42: B | N42: FG_Symbol (2) | O42: =10000-SUM(P42:AA42) -> 6710 | P42: 2100 | Q42: 860 | R42: 220 | S42: 110 | T42: 0 | U42: 0 | V42: 0 | W42: 0 | X42: 0 | Y42: 0 | Z42: 0 | AA42: 0 | AB42: {=SUMPRODUCT(P42:AA42/SUM(P42:AA42),$P$4:$AA$4)} -> 2.662614
...

Sheet Multiplier_Weight
C2: Newbie | D2: Newbie | E2: Oldhand | F2: Oldhand | G2: Oldhand
B3: Range | C3: Weight_BG | D3: Weight_FG | E3: Weight_BG | F3: Weight_FG | G3: Weight_BF
B4: (-1, 0] | C4: {=IFERROR(Multiplier_Weight_Newbie!$L$15:$L$79, 0)} -> 738241884 | D4: {=IFERROR(Multiplier_Weight_Newbie!$L$87:$L$150, 0)} -> 0 | E4: {=_xlfn.ANCHORARRAY(Multiplier_Weight_Oldhand!L15)} -> 714596215 | F4: {=_xlfn.ANCHORARRAY(Multiplier_Weight_Oldhand!L87)} -> 0 | G4: {=_xlfn.ANCHORARRAY(Multiplier_Weight_Oldhand!L157)} -> 0
B5: (0, 1] | C5: 117071871 | D5: 0 | E5: 166424189 | F5: 0 | G5: 0
B6: (1, 2] | C6: 39540778 | D6: 0 | E6: 47260135 | F6: 0 | G6: 0
B7: (2, 3] | C7: 19079642 | D7: 0 | E7: 22374389 | F7: 0 | G7: 0
B8: (3, 4] | C8: 7549667 | D8: 0 | E8: 8755275 | F8: 0 | G8: 0
B9: (4, 5] | C9: 6156107 | D9: 0 | E9: 6870299 | F9: 0 | G9: 0
B10: (5, 6] | C10: 4856180 | D10: 0 | E10: 5617911 | F10: 0 | G10: 0
B11: (6, 7] | C11: 3038377 | D11: 0 | E11: 3419852 | F11: 0 | G11: 0
B12: (7, 8] | C12: 2570258 | D12: 0 | E12: 2906580 | F12: 0 | G12: 0
B13: (8, 9] | C13: 2311271 | D13: 0 | E13: 2623502 | F13: 0 | G13: 0
B14: (9, 10] | C14: 2141691 | D14: 0 | E14: 2328871 | F14: 0 | G14: 0
B15: (10, 15] | C15: 2933912 | D15: 131426174 | E15: 3135395 | F15: 131313926 | G15: 117420216
B16: (15, 20] | C16: 4065662 | D16: 131018642 | E16: 4083722 | F16: 131298560 | G16: 117425562
... B67: (100000, 9999999] | C67: 0 | D67: 0 | E67: 0 | F67: 0 | G67: 0
B68: Free Game | C68: 44862500 | E68: 4195250

Sheet Multiplier_Weight_Newbie
A2: Threshold | B2: 1000000000
A3: Coin in | B3: =Overview!A7 -> 100
C5: RTP
B6: Bet | C6: Base Game | D6: Free Game | E6: Total | F6: Hit Rate | G6: FG Period | H6: Avg Multi
A7: Normal Bet | B7: {=Overview!B11:B12} -> 1 | C7: =SUM(N15:N79) -> 0.69662748 | D7: =SUM(_xlfn.ANCHORARRAY(N87))*M79 -> 2.6027986 | E7: =SUM(C7:D7) -> 3.2994261 | F7: =M79 -> 0.044815863 | G7: =1/F7 -> 22.313528 | H7: =D7*G7 -> 58.077619
B8: 75
A11: Base Game
A13: Simulator | B13: =Multiplier_Weight_Oldhand!B13 -> 1000000000 | H13: Calculate
A14: Lower | B14: Upper | C14: Cnt | D14: Pay | E14: Hit Rate | F14: Avg. Multi. | H14: Range | I14: Fix Num | J14: Fix Rate | K14: Final Rate | L14: Weight | M14: Hit Rate | N14: Simulator RTP | O14: 1.1
A15: -1 | B15: 0 | C15: {=Multiplier_Weight_Oldhand!C15:D78} -> 737445367 | D15: 0 | E15: {=_xlfn.LET(_xlpm.x, C15:C78, _xlpm.x/SUM(_xlpm.x))} -> 0.75577301 | F15: {=_xlfn.LET(_xlpm.x, D15:D80/C15:C80/B3, IF(ISERR(_xlpm.x), 0, _xlpm.x))} -> 0 | H15: ="("&$A15&", "&$B15&"]" -> (-1, 0] | I15: 1 | J15: {=E15:E79*I15:I79} -> 0.75577301 | K15: {=J15:J78/SUM(_xlfn.ANCHORARRAY(J15))} -> 0.73824188 | L15: {=INT(K15:K79*$B$2)} -> 738241884 | M15: {=_xlfn.LET(_xlpm.x, L15:L79, _xlpm.x/SUM(_xlpm.x))} -> 0.73747445 | N15: {=M15:M79*F15:F79} -> 0 | O15: {=I15:I78*O14} -> 1.1
A16: 0 | B16: 1 | C16: 125747912 | D16: 5718281965 | E16: 0.12887311 | F16: 0.4547417 | H16: ="("&$A16&", "&$B16&"]" -> (0, 1] | I16: 0.93 | J16: 0.11985199 | K16: 0.11707187 | L16: 117071871 | M16: 0.11695017 | N16: 0.053182119 | O16: 1.023
A17: 1 | B17: 2 | C17: 34346188 | D17: 5160882820 | E17: 0.03519979 | F17: 1.5026072 | H17: ="("&$A17&", "&$B17&"]" -> (1, 2] | I17: 1.15 | J17: 0.040479758 | K17: 0.039540778 | L17: 39540778 | M17: 0.039499673 | N17: 0.059352492 | O17: 1.265
A18: 2 | B18: 3 | C18: 16016014 | D18: 4036397390 | E18: 0.016414058 | F18: 2.5202259 | H18: ="("&$A18&", "&$B18&"]" -> (2, 3] | I18: 1.19 | J18: 0.019532729 | K18: 0.019079642 | L18: 19079642 | M18: 0.019059808 | N18: 0.048035022 | O18: 1.309
A19: 3 | B19: 4 | C19: 7938444 | D19: 2831742995 | E19: 0.0081357372 | F19: 3.567126 | H19: ="("&$A19&", "&$B19&"]" -> (3, 4] | I19: 0.95 | J19: 0.0077289504 | K19: 0.0075496674 | L19: 7549667 | M19: 0.0075418188 | N19: 0.026902618 | O19: 1.045
A20: 4 | B20: 5 | C20: 5590423 | D20: 2572145990 | E20: 0.0057293611 | F20: 4.6009863 | H20: ="("&$A20&", "&$B20&"]" -> (4, 5] | I20: 1.1 | J20: 0.0063022972 | K20: 0.0061561074 | L20: 6156107 | M20: 0.0061497074 | N20: 0.02829472 | O20: 1.21
A21: 5 | B21: 6 | C21: 4146103 | D21: 2317578720 | E21: 0.0042491456 | F21: 5.589776 | H21: ="("&$A21&", "&$B21&"]" -> (5, 6] | I21: 1.17 | J21: 0.0049715004 | K21: 0.00485618 | L21: 4856180 | M21: 0.0048511318 | N21: 0.02711674 | O21: 1.287
A22: 6 | B22: 7 | C22: 2759181 | D22: 1811662230 | E22: 0.0028277546 | F22: 6.565942 | H22: ="("&$A22&", "&$B22&"]" -> (6, 7] | I22: 1.1 | J22: 0.0031105301 | K22: 0.0030383773 | L22: 3038377 | M22: 0.0030352185 | N22: 0.019929068 | O22: 1.21
A23: 7 | B23: 8 | C23: 2852762 | D23: 2173439930 | E23: 0.0029236614 | F23: 7.6187215 | H23: ="("&$A23&", "&$B23&"]" -> (7, 8] | I23: 0.9 | J23: 0.0026312952 | K23: 0.002570259 | L23: 2570258 | M23: 0.0025675861 | N23: 0.019561723 | O23: 0.99
A24: 8 | B24: 9 | C24: 2098889 | D24: 1804643600 | E24: 0.0021510524 | F24: 8.5980898 | H24: ="("&$A24&", "&$B24&"]" -> (8, 9] | I24: 1.1 | J24: 0.0023661577 | K24: 0.0023112716 | L24: 2311271 | M24: 0.0023088683 | N24: 0.019851857 | O24: 1.21
A25: 9 | B25: 10 | C25: 1944892 | D25: 1875878775 | E25: 0.0019932282 | F25: 9.6451565 | H25: ="("&$A25&", "&$B25&"]" -> (9, 10] | I25: 1.1 | J25: 0.002192551 | K25: 0.002141692 | L25: 2141691 | M25: 0.0021394646 | N25: 0.020635471 | O25: 1.21
A26: 10 | B26: 15 | C26: 6784136 | D26: 8448491255 | E26: 0.0069527413 | F26: 12.453305 | G26: =SUM($L$15:L25)-1000 -> 942556726 | H26: ="("&$A26&", "&$B26&"]" -> (10, 15] | I26: 0.432 | J26: 0.0030035843 | K26: 0.0029339123 | L26: 2933912 | M26: 0.0029308621 | N26: 0.036498918 | O26: 0.4752
A27: 15 | B27: 20 | C27: 4614038 | D27: 8068968765 | E27: 0.0047287101 | F27: 17.487868 | G27: =SUM($L$15:L26)-1000 -> 945490638 | H27: ="("&$A27&", "&$B27&"]" -> (15, 20] | I27: 0.8802 | J27: 0.0041622107 | K27: 0.0040656628 | L27: 4065662 | M27: 0.0040614356 | N27: 0.071025849 | O27: 0.96822
A28: 20 | B28: 25 | C28: 3239863 | D28: 7300101965 | E28: 0.0033203829 | F28: 22.532132 | G28: =SUM($L$15:L27)-1000 -> 949556300 | H28: ="("&$A28&", "&$B28&"]" -> (20, 25] | I28: 0.549 | J28: 0.0018228902 | K28: 0.001780606 | L28: 1780605 | M28: 0.001778754 | N28: 0.040079119 | O28: 0.6039
A29: 25 | B29: 30 | C29: 2634636 | D29: 7256115885 | E29: 0.0027001143 | F29: 27.541246 | G29: =SUM($L$15:L28)-1000 -> 951336905 | H29: ="("&$A29&", "&$B29&"]" -> (25, 30] | I29: 0.29 | J29: 0.00078303315 | K29: 0.00076486969 | L29: 764869 | M29: 0.00076407388 | N29: 0.021043547 | O29: 0.319
A30: 30 | B30: 35 | C30: 1986295 | D30: 6461335590 | E30: 0.0020356602 | F30: 32.529587 | G30: =SUM($L$15:L29)-1000 -> 952101774 | H30: ="("&$A30&", "&$B30&"]" -> (30, 35] | I30: 0.34 | J30: 0.00069212445 | K30: 0.00067606974 | L30: 676069 | M30: 0.00067536619 | N30: 0.021969383 | O30: 0.374
A31: 35 | B31: 40 | C31: 1726668 | D31: 6481677100 | E31: 0.0017695807 | F31: 37.538641 | G31: =SUM($L$15:L30)-1000 -> 952777843 | H31: ="("&$A31&", "&$B31&"]" -> (35, 40] | I31: 0.7 | J31: 0.0012387065 | K31: 0.0012099731 | L31: 1209973 | M31: 0.0012087152 | N31: 0.045373526 | O31: 0.77
A32: 40 | B32: 45 | C32: 1423811 | D32: 6067164945 | E32: 0.0014591968 | F32: 42.612151 | G32: =SUM($L$15:L31)-1000 -> 953987816 | H32: ="("&$A32&", "&$B32&"]" -> (40, 45] | I32: 0.2 | J32: 0.00029183936 | K32: 0.00028506977 | L32: 285069 | M32: 0.00028477266 | N32: 0.012134775 | O32: 0.22
A33: 45 | B33: 50 | C33: 1177170 | D33: 5604035925 | E33: 0.0012064261 | F33: 47.606004 | G33: =SUM($L$15:L32)-1000 -> 954272885 | H33: ="("&$A33&", "&$B33&"]" -> (45, 50] | I33: 0.24 | J33: 0.00028954226 | K33: 0.00028282595 | L33: 282825 | M33: 0.00028253099 | N33: 0.013450171 | O33: 0.264
A34: 50 | B34: 60 | C34: 1992789 | D34: 10931633025 | E34: 0.0020423156 | F34: 54.855948 | G34: =SUM($L$15:L33)-1000 -> 954555710 | H34: ="("&$A34&", "&$B34&"]" -> (50, 60] | I34: 0.437893 | J34: 0.00089431568 | K34: 0.00087357088 | L34: 873570 | M34: 0.00087266188 | N34: 0.047870695 | O34: 0.4816823
A35: 60 | B35: 70 | C35: 1443638 | D35: 9377454105 | E35: 0.0014795166 | F35: 64.957102 | H35: ="("&$A35&", "&$B35&"]" -> (60, 70] | I35: 0.15 | J35: 0.00022192749 | K35: 0.00021677959 | L35: 216779 | M35: 0.00021655365 | N35: 0.014066697 | O35: 0.165
A36: 70 | B36: 80 | C36: 1152370 | D36: 8638430205 | E36: 0.0011810097 | F36: 74.962297 | H36: ="("&$A36&", "&$B36&"]" -> (70, 80] | I36: 0.17 | J36: 0.00020077165 | K36: 0.0001961145 | L36: 196114 | M36: 0.00019591013 | N36: 0.014685873 | O36: 0.187
A37: 80 | B37: 90 | C37: 911829 | D37: 7750791030 | E37: 0.00093449058 | F37: 85.002682 | H37: ="("&$A37&", "&$B37&"]" -> (80, 90] | I37: 0.19 | J37: 0.00017755321 | K37: 0.00017343464 | L37: 173434 | M37: 0.00017325371 | N37: 0.01472703 | O37: 0.209
A38: 90 | B38: 100 | C38: 733401 | D38: 6968879730 | E38: 0.00075162813 | F38: 95.02141 | H38: ="("&$A38&", "&$B38&"]" -> (90, 100] | I38: 0.22 | J38: 0.00016535819 | K38: 0.00016152249 | L38: 161522 | M38: 0.00016135409 | N38: 0.015332093 | O38: 0.242
A39: 100 | B39: 120 | C39: 1138045 | D39: 12463552425 | E39: 0.0011663287 | F39: 109.51722 | H39: ="("&$A39&", "&$B39&"]" -> (100, 120] | I39: 0 | J39: 0 | K39: 0 | L39: 0 | M39: 0 | N39: 0 | O39: 0
A40: 120 | B40: 140 | C40: 789517 | D40: 10238081405 | E40: 0.00080913877 | F40: 129.67525 | H40: ="("&$A40&", "&$B40&"]" -> (120, 140] | I40: 0 | J40: 0 | K40: 0 | L40: 0 | M40: 0 | N40: 0 | O40: 0
A41: 140 | B41: 160 | C41: 590444 | D41: 8841692580 | E41: 0.00060511824 | F41: 149.74651 | H41: ="("&$A41&", "&$B41&"]" -> (140, 160] | I41: 0 | J41: 0 | K41: 0 | L41: 0 | M41: 0 | N41: 0 | O41: 0
A42: 160 | B42: 180 | C42: 441044 | D42: 7487965275 | E42: 0.00045200522 | F42: 169.77819 | H42: ="("&$A42&", "&$B42&"]" -> (160, 180] | I42: 0 | J42: 0 | K42: 0 | L42: 0 | M42: 0 | N42: 0 | O42: 0
A43: 180 | B43: 200 | C43: 335496 | D43: 6368038515 | E43: 0.00034383404 | F43: 189.80967 | H43: ="("&$A43&", "&$B43&"]" -> (180, 200] | I43: 0 | J43: 0 | K43: 0 | L43: 0 | M43: 0 | N43: 0 | O43: 0
A44: 200 | B44: 250 | C44: 573493 | D44: 12777191060 | E44: 0.00058774595 | F44: 222.79594 | H44: ="("&$A44&", "&$B44&"]" -> (200, 250] | I44: 0 | J44: 0 | K44: 0 | L44: 0 | M44: 0 | N44: 0 | O44: 0
A45: 250 | B45: 300 | C45: 345164 | D45: 9425383575 | E45: 0.00035374232 | F45: 273.06972 | H45: ="("&$A45&", "&$B45&"]" -> (250, 300] | I45: 0 | J45: 0 | K45: 0 | L45: 0 | M45: 0 | N45: 0 | O45: 0
...

Sheet Multiplier_Weight_Oldhand
A2: Threshold | B2: 1000000000
A3: Coin in | B3: =Overview!A7 -> 100
C5: RTP
B6: Bet | C6: Base Game | D6: Free Game | E6: Total | F6: Hit Rate | G6: FG Period | H6: Avg Multi
A7: Normal Bet | B7: {=Overview!B11:B12} -> 1 | C7: =SUM(N15:N79) -> 0.70001109 | D7: =SUM(_xlfn.ANCHORARRAY(N87))*M79 -> 0.2399888 | E7: =SUM(C7:D7) -> 0.93999989 | F7: =M79 -> 0.0041949845 | G7: =1/F7 -> 238.3799 | H7: =D7*G7 -> 57.208506
A8: Buy Feature | B8: 75 | C8: =N80 -> 0 | D8: =SUM(_xlfn.ANCHORARRAY(N157))/B8 -> 0.92499972 | E8: =SUM(C8:D8) -> 0.92499972 | F8: =E80 -> 1 | G8: =1/F8 -> 1 | H8: =D8*G8*B8 -> 69.374979
A11: Base Game
A13: Simulator | B13: 1000000000 | H13: Calculate | P13: Compare
A14: Lower | B14: Upper | C14: Cnt | D14: Pay | E14: Hit Rate | F14: Avg. Multi. | H14: Range | I14: Fix Num | J14: Fix Rate | K14: Final Rate | L14: Weight | M14: Hit Rate | N14: Simulator RTP | O14: 0.9 | P14: 目前 | Q14: 目標 | R14: 墨西哥狂歡 | S14: 差異 | U14: Fix Num A | V14: Fix Num B
A15: -1 | B15: 0 | C15: 737445367 | D15: 0 | E15: {=_xlfn.LET(_xlpm.x, C15:C78, _xlpm.x/SUM(_xlpm.x))} -> 0.75577301 | F15: {=_xlfn.LET(_xlpm.x, D15:D80/C15:C80/B3, IF(ISERR(_xlpm.x), 0, _xlpm.x))} -> 0 | H15: ="("&$A15&", "&$B15&"]" -> (-1, 0] | I15: 0.96 | J15: {=E15:E79*I15:I79} -> 0.72554209 | K15: {=J15:J78/SUM(_xlfn.ANCHORARRAY(J15))} -> 0.71459622 | L15: {=INT(K15:K79*$B$2)} -> 714596215 | M15: {=_xlfn.LET(_xlpm.x, L15:L79, _xlpm.x/SUM(_xlpm.x))} -> 0.714551 | N15: {=M15:M79*F15:F79} -> 0 | O15: {=I15:I78*O14} -> 0.864 | P15: {=M15:M78} -> 0.714551 | Q15: 0.72294875 | R15: 0.72554635 | S15: {=_xlfn.LET(_xlpm.x, Q15:Q78/M15:M78, IF(ISERR(_xlpm.x), 0, ROUND(_xlpm.x,2)))} -> 1.01
A16: 0 | B16: 1 | C16: 125747912 | D16: 5718281965 | E16: 0.12887311 | F16: 0.4547417 | H16: ="("&$A16&", "&$B16&"]" -> (0, 1] | I16: 1.3111611 | J16: 0.1689734 | K16: 0.16642419 | L16: 166424189 | M16: 0.16641366 | N16: 0.07567523 | O16: 1.1800449 | P16: 0.16641366 | Q16: 0.16136085 | R16: 0.15905886 | S16: 0.97
A17: 1 | B17: 2 | C17: 34346188 | D17: 5160882820 | E17: 0.03519979 | F17: 1.5026072 | H17: ="("&$A17&", "&$B17&"]" -> (1, 2] | I17: 1.3631913 | J17: 0.047984046 | K17: 0.047260135 | L17: 47260135 | M17: 0.047257145 | N17: 0.071008924 | O17: 1.2268721 | P17: 0.047257145 | Q17: 0.045756935 | R17: 0.049788509 | S17: 0.97
A18: 2 | B18: 3 | C18: 16016014 | D18: 4036397390 | E18: 0.016414058 | F18: 2.5202259 | H18: ="("&$A18&", "&$B18&"]" -> (2, 3] | I18: 1.3840033 | J18: 0.022717111 | K18: 0.02237439 | L18: 22374389 | M18: 0.022372973 | N18: 0.056384947 | O18: 1.245603 | P18: 0.022372973 | Q18: 0.021758 | R18: 0.021457526 | S18: 0.97
A19: 3 | B19: 4 | C19: 7938444 | D19: 2831742995 | E19: 0.0081357372 | F19: 3.567126 | H19: ="("&$A19&", "&$B19&"]" -> (3, 4] | I19: 1.0926342 | J19: 0.0088893848 | K19: 0.0087552753 | L19: 8755275 | M19: 0.008754721 | N19: 0.031229193 | O19: 0.98337079 | P19: 0.008754721 | Q19: 0.0085068855 | R19: 0.0094289743 | S19: 0.97
A20: 4 | B20: 5 | C20: 5590423 | D20: 2572145990 | E20: 0.0057293611 | F20: 4.6009863 | H20: ="("&$A20&", "&$B20&"]" -> (4, 5] | I20: 1.2175067 | J20: 0.0069755355 | K20: 0.0068702993 | L20: 6870299 | M20: 0.0068698643 | N20: 0.031608152 | O20: 1.095756 | P20: 0.0068698643 | Q20: 0.0066698354 | R20: 0.0062566091 | S20: 0.97
A21: 5 | B21: 6 | C21: 4146103 | D21: 2317578720 | E21: 0.0042491456 | F21: 5.589776 | H21: ="("&$A21&", "&$B21&"]" -> (5, 6] | I21: 1.3423792 | J21: 0.0057039646 | K21: 0.0056179118 | L21: 5617911 | M21: 0.0056175555 | N21: 0.031400877 | O21: 1.2081413 | P21: 0.0056175555 | Q21: 0.0054541949 | R21: 0.0053753965 | S21: 0.97
A22: 6 | B22: 7 | C22: 2759181 | D22: 1811662230 | E22: 0.0028277546 | F22: 6.565942 | H22: ="("&$A22&", "&$B22&"]" -> (6, 7] | I22: 1.2279127 | J22: 0.0034722359 | K22: 0.0034198521 | L22: 3419852 | M22: 0.0034196356 | N22: 0.022453129 | O22: 1.1051215 | P22: 0.0034196356 | Q22: 0.0033318405 | R22: 0.0025114558 | S22: 0.97
A23: 7 | B23: 8 | C23: 2852762 | D23: 2173439930 | E23: 0.0029236614 | F23: 7.6187215 | H23: ="("&$A23&", "&$B23&"]" -> (7, 8] | I23: 1.0093859 | J23: 0.0029511025 | K23: 0.0029065808 | L23: 2906580 | M23: 0.0029063961 | N23: 0.022143022 | O23: 0.9084473 | P23: 0.0029063961 | Q23: 0.00281562 | R23: 0.0030842439 | S23: 0.97
A24: 8 | B24: 9 | C24: 2098889 | D24: 1804643600 | E24: 0.0021510524 | F24: 8.5980898 | H24: ="("&$A24&", "&$B24&"]" -> (8, 9] | I24: 1.2383188 | J24: 0.0026636886 | K24: 0.0026235029 | L24: 2623502 | M24: 0.002623336 | N24: 0.022555678 | O24: 1.1144869 | P24: 0.002623336 | Q24: 0.0025445965 | R24: 0.0026876983 | S24: 0.97
A25: 9 | B25: 10 | C25: 1944892 | D25: 1875878775 | E25: 0.0019932282 | F25: 9.6451565 | H25: ="("&$A25&", "&$B25&"]" -> (9, 10] | I25: 1.1862886 | J25: 0.0023645438 | K25: 0.0023288712 | L25: 2328871 | M25: 0.0023287236 | N25: 0.022460904 | O25: 1.0676597 | P25: 0.0023287236 | Q25: 0.0022718729 | R25: 0.002247092 | S25: 0.98
A26: 10 | B26: 15 | C26: 6784136 | D26: 8448491255 | E26: 0.0069527413 | F26: 12.453305 | H26: ="("&$A26&", "&$B26&"]" -> (10, 15] | I26: 0.45786576 | J26: 0.0031834222 | K26: 0.0031353956 | L26: 3135395 | M26: 0.0031351966 | N26: 0.039043559 | O26: 0.41207919 | P26: 0.0031351966 | Q26: 0.0030238589 | R26: 0.0049788509 | S26: 0.96
A27: 15 | B27: 20 | C27: 4614038 | D27: 8068968765 | E27: 0.0047287101 | F27: 17.487868 | H27: ="("&$A27&", "&$B27&"]" -> (15, 20] | I27: 0.87683 | J27: 0.0041462749 | K27: 0.0040837222 | L27: 4083722 | M27: 0.0040834636 | N27: 0.071411073 | O27: 0.789147 | P27: 0.0040834636 | Q27: 0.0039646257 | R27: 0.0023352133 | S27: 0.97
... A78: 100000 | B78: 9999999 | C78: 0 | D78: 0 | E78: 0 | F78: 0 | H78: ="("&$A78&", "&$B78&"]" -> (100000, 9999999] | I78: 0 | J78: 0 | K78: 0 | L78: 0 | M78: 0 | N78: 0 | O78: 0 | P78: 0 | Q78: 0 | R78: 0 | S78: 0
A79: Free Game | C79: =E79*B13 -> 24250000 | D79: 298038000 | E79: 0.02425 | F79: 0.12290227 | H79: Free Game | I79: 0.173 | J79: 0.00419525 | K79: =J79 -> 0.00419525 | L79: 4195250 | M79: 0.0041949845 | N79: 0.00051557311
A80: Buy Feature | C80: 10000000 | D80: 0 | E80: 1 | F80: 0 | H80: Buy Feature | M80: =E80 -> 1 | N80: =F80/B8 -> 0
A83: Free Game
A85: Simulator | B85: =B13 -> 1000000000 | H85: Calculate | P85: Compare
A86: Lower | B86: Upper | C86: Cnt | D86: Pay | E86: Hit Rate | F86: Avg. Multi. | H86: Range | I86: Fix Num | J86: Fix Rate | K86: Final Rate | L86: Weight | M86: Hit Rate | N86: Simulator RTP | O86: 0.9 | P86: 目前 | Q86: 目標 | R86: 墨西哥狂歡 | S86: 差異 | U86: Fix Num A | V86: Fix Num B
A87: -1 | B87: 0 | C87: 0 | D87: 0 | E87: {=_xlfn.LET(_xlpm.x, C87:C150, _xlpm.x/SUM(_xlpm.x))} -> 0 | F87: {=_xlfn.LET(_xlpm.x, D87:D150/C87:C150/B3, IF(ISERR(_xlpm.x), 0, _xlpm.x))} -> 0 | H87: ="("&$A87&", "&$B87&"]" -> (-1, 0] | I87: 0 | J87: {=_xlfn.ANCHORARRAY(E87)*I87:I150} -> 0 | K87: {=J87:J150/SUM(_xlfn.ANCHORARRAY(J87))} -> 0 | L87: {=INT(_xlfn.ANCHORARRAY(K87)*$B$2)} -> 0 | M87: {=_xlfn.LET(_xlpm.x, L87:L150, _xlpm.x/SUM(_xlpm.x))} -> 0 | N87: {=M87:M150*_xlfn.ANCHORARRAY(F87)} -> 0 | O87: {=I87:I150*O86} -> 0 | P87: {=_xlfn.ANCHORARRAY(M87)} -> 0 | Q87: 0 | R87: 0 | S87: {=_xlfn.LET(_xlpm.x, Q87:Q150/M87:M150, IF(ISERR(_xlpm.x), 0, ROUND(_xlpm.x,2)))} -> 0
A88: 0 | B88: 1 | C88: 15302 | D88: 915955 | E88: 0.00063116012 | F88: 0.59858515 | H88: ="("&$A88&", "&$B88&"]" -> (0, 1] | I88: 0 | J88: 0 | K88: 0 | L88: 0 | M88: 0 | N88: 0 | O88: 0 | P88: 0 | Q88: 0 | R88: 0 | S88: 0
A89: 1 | B89: 2 | C89: 14545 | D89: 2297380 | E89: 0.00059993622 | F89: 1.5794981 | H89: ="("&$A89&", "&$B89&"]" -> (1, 2] | I89: 0 | J89: 0 | K89: 0 | L89: 0 | M89: 0 | N89: 0 | O89: 0 | P89: 0 | Q89: 0 | R89: 0 | S89: 0
A90: 2 | B90: 3 | C90: 15170 | D90: 3916365 | E90: 0.00062571553 | F90: 2.5816513 | H90: ="("&$A90&", "&$B90&"]" -> (2, 3] | I90: 0 | J90: 0 | K90: 0 | L90: 0 | M90: 0 | N90: 0 | O90: 0 | P90: 0 | Q90: 0 | R90: 0 | S90: 0
A91: 3 | B91: 4 | C91: 15165 | D91: 5428355 | E91: 0.0006255093 | F91: 3.5795285 | H91: ="("&$A91&", "&$B91&"]" -> (3, 4] | I91: 0 | J91: 0 | K91: 0 | L91: 0 | M91: 0 | N91: 0 | O91: 0 | P91: 0 | Q91: 0 | R91: 0.036144578 | S91: 0
A92: 4 | B92: 5 | C92: 16128 | D92: 7377445 | E92: 0.00066523006 | F92: 4.5743087 | H92: ="("&$A92&", "&$B92&"]" -> (4, 5] | I92: 0 | J92: 0 | K92: 0 | L92: 0 | M92: 0 | N92: 0 | O92: 0 | P92: 0 | Q92: 0 | R92: 0 | S92: 0
A93: 5 | B93: 6 | C93: 16708 | D93: 9310030 | E93: 0.00068915327 | F93: 5.5721989 | H93: ="("&$A93&", "&$B93&"]" -> (5, 6] | I93: 0 | J93: 0 | K93: 0 | L93: 0 | M93: 0 | N93: 0 | O93: 0 | P93: 0 | Q93: 0 | R93: 0 | S93: 0
A94: 6 | B94: 7 | C94: 16541 | D94: 10856555 | E94: 0.00068226504 | F94: 6.5634212 | H94: ="("&$A94&", "&$B94&"]" -> (6, 7] | I94: 0 | J94: 0 | K94: 0 | L94: 0 | M94: 0 | N94: 0 | O94: 0 | P94: 0 | Q94: 0 | R94: 0.012048193 | S94: 0
A95: 7 | B95: 8 | C95: 16722 | D95: 12639590 | E95: 0.00068973073 | F95: 7.5586593 | H95: ="("&$A95&", "&$B95&"]" -> (7, 8] | I95: 0 | J95: 0 | K95: 0 | L95: 0 | M95: 0 | N95: 0 | O95: 0 | P95: 0 | Q95: 0 | R95: 0.036144578 | S95: 0
A96: 8 | B96: 9 | C96: 17038 | D96: 14586110 | E96: 0.00070276475 | F96: 8.5609285 | H96: ="("&$A96&", "&$B96&"]" -> (8, 9] | I96: 0 | J96: 0 | K96: 0 | L96: 0 | M96: 0 | N96: 0 | O96: 0 | P96: 0 | Q96: 0 | R96: 0.024096386 | S96: 0
A97: 9 | B97: 10 | C97: 17289 | D97: 16528360 | E97: 0.00071311772 | F97: 9.560044 | H97: ="("&$A97&", "&$B97&"]" -> (9, 10] | I97: 0 | J97: 0 | K97: 0 | L97: 0 | M97: 0 | N97: 0 | O97: 0 | P97: 0 | Q97: 0 | R97: 0.012048193 | S97: 0
A98: 10 | B98: 15 | C98: 91411 | D98: 114997815 | E98: 0.0037704207 | F98: 12.580304 | H98: ="("&$A98&", "&$B98&"]" -> (10, 15] | I98: 34.81 | J98: 0.13124835 | K98: 0.13131393 | L98: 131313926 | M98: 0.13131393 | N98: 1.6519691 | O98: 31.329 | P98: 0.13131393 | Q98: 0.13126626 | R98: 0.072289157 | S98: 1
...

Sheet OP Jackpot
B3: NB-Newbie-A
B4: BGC1Screen | E4: =SUM(D4:D5)/C4 -> #DIV/0!
B5: FGC1Screen
B7: NB-Newbie-B
B8: BGC1Screen | E8: =SUM(D8:D9)/C8 -> #DIV/0!
B9: FGC1Screen
B11: NB-Oldhand-A
B12: BGC1Screen | C12: 100000000 | D12: 34373244 | E12: =SUM(D12:D13)/C12 -> 0.35639257
B13: FGC1Screen | D13: 1266013
B15: NB-Oldhand-B
B16: BGC1Screen | E16: =SUM(D16:D17)/C16 -> #DIV/0!
B17: FGC1Screen
B19: BF-A
B20: BGC1Screen | C20: 1000000000 | D20: 1000000000 | E20: =SUM(D20:D21)/C20 -> 5.4156459
B21: FGC1Screen | D21: 4415645859
B23: BF-B
B24: BGC1Screen | E24: =SUM(D24:D25)/C24 -> #DIV/0!
B25: FGC1Screen
B28: Threshold | C28: 10000000000
B30: NB-Newbie-A | C30: =ROUND(E4*$C$28, 0) -> #DIV/0!
B31: NB-Newbie-B | C31: =ROUND(E8*$C$28, 0) -> #DIV/0!
B32: NB-Oldhand-A | C32: =ROUND(E12*$C$28, 0) -> 3563925700
B33: NB-Oldhand-B | C33: =ROUND(E16*$C$28, 0) -> #DIV/0!
B34: BF-A | C34: =ROUND(E20*$C$28, 0) -> 54156458590
B35: BF-B | C35: =ROUND(E24*$C$28, 0) -> #DIV/0!

Sheet BG_Symbol
J2: Symbol | Q2: Symbol ID | W2: Symbol Weight | AC2: Eliminate Wheel Weight A | AJ2: Eliminate Wheel Weight B
A3: Symbol | B3: Description | C3: R1 | D3: R2 | E3: R3 | F3: R4 | G3: R5 | H3: ID | K3: R1 | L3: R2 | M3: R3 | N3: R4 | O3: R5 | Q3: R1 | R3: R2 | S3: R3 | T3: R4 | U3: R5 | W3: R1 | X3: R2 | Y3: R3 | Z3: R4 | AA3: R5
A4: {=Overview!A38:B57} -> WW | B4: Wild | C4: =COUNTIF(K:K, $A4) -> 0 | D4: =COUNTIF(L:L, $A4) -> 0 | E4: =COUNTIF(M:M, $A4) -> 0 | F4: =COUNTIF(N:N, $A4) -> 0 | G4: =COUNTIF(O:O, $A4) -> 0 | H4: {=Overview!F38:F57} -> 0 | J4: {=_xlfn.SEQUENCE(MAX(COUNTA(K:K), COUNTA(L:L), COUNTA(M:M), COUNTA(N:N), COUNTA(O:O))-1,,0)} -> 0 | K4: M4 | L4: G5 | M4: M5 | N4: J | O4: A | Q4: {=_xlfn.LET(_xlpm.x, K4:O304, IF(_xlpm.x="", "", _xlfn.XLOOKUP(_xlpm.x, $A$4:$A$23,_xlfn.ANCHORARRAY( H4))))} -> 5 | R4: 15 | S4: 6 | T4: 10 | U4: 7 | W4: 2 | X4: 1 | Y4: 1 | Z4: 2 | AA4: 1 | AC4: 1 Combo | AJ4: 1 Combo
A5: C1 | B5: Scatter | C5: =COUNTIF(K:K, $A5) -> 0 | D5: =COUNTIF(L:L, $A5) -> 6 | E5: =COUNTIF(M:M, $A5) -> 0 | F5: =COUNTIF(N:N, $A5) -> 9 | G5: =COUNTIF(O:O, $A5) -> 0 | H5: 1 | J5: 1 | K5: M5 | L5: GK | M5: M4 | N5: J | O5: M3 | Q5: 6 | R5: 17 | S5: 5 | T5: 10 | U5: 4 | W5: 1 | X5: 1 | Y5: 1 | Z5: 2 | AA5: 2 | AC5: Symbol | AD5: R1 | AE5: R2 | AF5: R3 | AG5: R4 | AH5: R5 | AJ5: Symbol | AK5: R1 | AL5: R2 | AM5: R3 | AN5: R4 | AO5: R5
A6: M1 | B6: M1 | C6: =COUNTIF(K:K, $A6) -> 4 | D6: =COUNTIF(L:L, $A6) -> 22 | E6: =COUNTIF(M:M, $A6) -> 5 | F6: =COUNTIF(N:N, $A6) -> 21 | G6: =COUNTIF(O:O, $A6) -> 23 | H6: 2 | J6: 2 | K6: J | L6: C1 | M6: K | N6: GJ | O6: M1 | Q6: 10 | R6: 1 | S6: 8 | T6: 19 | U6: 2 | W6: 1 | X6: 2 | Y6: 1 | Z6: 2 | AA6: 1 | AC6: {=$A$4:$A$23} -> WW | AD6: 0 | AE6: 0 | AF6: 0 | AG6: 0 | AH6: 0 | AJ6: {=$A$4:$A$23} -> WW | AK6: 0 | AL6: 0 | AM6: 0 | AN6: 0 | AO6: 0
A7: M2 | B7: M2 | C7: =COUNTIF(K:K, $A7) -> 4 | D7: =COUNTIF(L:L, $A7) -> 10 | E7: =COUNTIF(M:M, $A7) -> 5 | F7: =COUNTIF(N:N, $A7) -> 21 | G7: =COUNTIF(O:O, $A7) -> 23 | H7: 3 | J7: 3 | K7: A | L7: J | M7: M4 | N7: M1 | O7: M4 | Q7: 7 | R7: 10 | S7: 5 | T7: 2 | U7: 5 | W7: 1 | X7: 1 | Y7: 2 | Z7: 2 | AA7: 1 | AC7: C1 | AD7: 0 | AE7: 6 | AF7: 0 | AG7: 9 | AH7: 0 | AJ7: C1 | AK7: 0 | AL7: 6 | AM7: 0 | AN7: 9 | AO7: 0
A8: M3 | B8: M3 | C8: =COUNTIF(K:K, $A8) -> 4 | D8: =COUNTIF(L:L, $A8) -> 9 | E8: =COUNTIF(M:M, $A8) -> 5 | F8: =COUNTIF(N:N, $A8) -> 21 | G8: =COUNTIF(O:O, $A8) -> 22 | H8: 4 | J8: 4 | K8: M5 | L8: G1 | M8: M3 | N8: G2 | O8: A | Q8: 6 | R8: 11 | S8: 4 | T8: 12 | U8: 7 | W8: 1 | X8: 1 | Y8: 1 | Z8: 2 | AA8: 1 | AC8: M1 | AD8: 4 | AE8: 11 | AF8: 5 | AG8: 21 | AH8: 23 | AJ8: M1 | AK8: 4 | AL8: 11 | AM8: 5 | AN8: 21 | AO8: 23
A9: M4 | B9: M4 | C9: =COUNTIF(K:K, $A9) -> 43 | D9: =COUNTIF(L:L, $A9) -> 13 | E9: =COUNTIF(M:M, $A9) -> 41 | F9: =COUNTIF(N:N, $A9) -> 14 | G9: =COUNTIF(O:O, $A9) -> 22 | H9: 5 | J9: 5 | K9: K | L9: K | M9: M4 | N9: M1 | O9: K | Q9: 8 | R9: 8 | S9: 5 | T9: 2 | U9: 8 | W9: 1 | X9: 1 | Y9: 1 | Z9: 2 | AA9: 1 | AC9: M2 | AD9: 4 | AE9: 11 | AF9: 5 | AG9: 21 | AH9: 23 | AJ9: M2 | AK9: 4 | AL9: 11 | AM9: 5 | AN9: 21 | AO9: 23
A10: M5 | B10: M5 | C10: =COUNTIF(K:K, $A10) -> 43 | D10: =COUNTIF(L:L, $A10) -> 14 | E10: =COUNTIF(M:M, $A10) -> 41 | F10: =COUNTIF(N:N, $A10) -> 14 | G10: =COUNTIF(O:O, $A10) -> 22 | H10: 6 | J10: 6 | K10: M5 | L10: G1 | M10: A | N10: M4 | O10: A | Q10: 6 | R10: 11 | S10: 7 | T10: 5 | U10: 7 | W10: 1 | X10: 2 | Y10: 1 | Z10: 2 | AA10: 1 | AC10: M3 | AD10: 4 | AE10: 11 | AF10: 5 | AG10: 21 | AH10: 22 | AJ10: M3 | AK10: 4 | AL10: 11 | AM10: 5 | AN10: 21 | AO10: 22
A11: A | B11: A | C11: =COUNTIF(K:K, $A11) -> 47 | D11: =COUNTIF(L:L, $A11) -> 14 | E11: =COUNTIF(M:M, $A11) -> 41 | F11: =COUNTIF(N:N, $A11) -> 14 | G11: =COUNTIF(O:O, $A11) -> 22 | H11: 7 | J11: 7 | K11: K | L11: G1 | M11: M4 | N11: C1 | O11: A | Q11: 8 | R11: 11 | S11: 5 | T11: 1 | U11: 7 | W11: 1 | X11: 2 | Y11: 2 | Z11: 2 | AA11: 1 | AC11: M4 | AD11: 43 | AE11: 20 | AF11: 41 | AG11: 14 | AH11: 22 | AJ11: M4 | AK11: 43 | AL11: 20 | AM11: 41 | AN11: 14 | AO11: 22
A12: K | B12: K | C12: =COUNTIF(K:K, $A12) -> 47 | D12: =COUNTIF(L:L, $A12) -> 18 | E12: =COUNTIF(M:M, $A12) -> 41 | F12: =COUNTIF(N:N, $A12) -> 14 | G12: =COUNTIF(O:O, $A12) -> 22 | H12: 8 | J12: 8 | K12: M5 | L12: J | M12: M5 | N12: Q | O12: M3 | Q12: 6 | R12: 10 | S12: 6 | T12: 9 | U12: 4 | W12: 1 | X12: 2 | Y12: 2 | Z12: 2 | AA12: 2 | AC12: M5 | AD12: 43 | AE12: 21 | AF12: 41 | AG12: 14 | AH12: 22 | AJ12: M5 | AK12: 43 | AL12: 21 | AM12: 41 | AN12: 14 | AO12: 22
A13: Q | B13: Q | C13: =COUNTIF(K:K, $A13) -> 4 | D13: =COUNTIF(L:L, $A13) -> 5 | E13: =COUNTIF(M:M, $A13) -> 5 | F13: =COUNTIF(N:N, $A13) -> 20 | G13: =COUNTIF(O:O, $A13) -> 22 | H13: 9 | J13: 9 | K13: K | L13: M3 | M13: Q | N13: Q | O13: M5 | Q13: 8 | R13: 4 | S13: 9 | T13: 9 | U13: 6 | W13: 1 | X13: 2 | Y13: 1 | Z13: 2 | AA13: 1 | AC13: A | AD13: 47 | AE13: 21 | AF13: 41 | AG13: 14 | AH13: 22 | AJ13: A | AK13: 47 | AL13: 21 | AM13: 41 | AN13: 14 | AO13: 22
A14: J | B14: J | C14: =COUNTIF(K:K, $A14) -> 4 | D14: =COUNTIF(L:L, $A14) -> 9 | E14: =COUNTIF(M:M, $A14) -> 4 | F14: =COUNTIF(N:N, $A14) -> 20 | G14: =COUNTIF(O:O, $A14) -> 22 | H14: 10 | J14: 10 | K14: M5 | L14: M1 | M14: M5 | N14: J | O14: Q | Q14: 6 | R14: 2 | S14: 6 | T14: 10 | U14: 9 | W14: 2 | X14: 2 | Y14: 1 | Z14: 1 | AA14: 1 | AC14: K | AD14: 47 | AE14: 21 | AF14: 41 | AG14: 14 | AH14: 22 | AJ14: K | AK14: 47 | AL14: 21 | AM14: 41 | AN14: 14 | AO14: 22
A15: G1 | B15: Gold M1 | C15: =COUNTIF(K:K, $A15) -> 0 | D15: =COUNTIF(L:L, $A15) -> 16 | E15: =COUNTIF(M:M, $A15) -> 0 | F15: =COUNTIF(N:N, $A15) -> 4 | G15: =COUNTIF(O:O, $A15) -> 0 | H15: 11 | J15: 11 | K15: M5 | L15: GQ | M15: K | N15: M2 | O15: K | Q15: 6 | R15: 18 | S15: 8 | T15: 3 | U15: 8 | W15: 1 | X15: 1 | Y15: 1 | Z15: 1 | AA15: 1 | AC15: Q | AD15: 4 | AE15: 11 | AF15: 5 | AG15: 20 | AH15: 22 | AJ15: Q | AK15: 4 | AL15: 11 | AM15: 5 | AN15: 20 | AO15: 22
A16: G2 | B16: Gold M2 | C16: =COUNTIF(K:K, $A16) -> 0 | D16: =COUNTIF(L:L, $A16) -> 5 | E16: =COUNTIF(M:M, $A16) -> 0 | F16: =COUNTIF(N:N, $A16) -> 4 | G16: =COUNTIF(O:O, $A16) -> 0 | H16: 12 | J16: 12 | K16: M5 | L16: M4 | M16: M5 | N16: A | O16: K | Q16: 6 | R16: 5 | S16: 6 | T16: 7 | U16: 8 | W16: 1 | X16: 1 | Y16: 1 | Z16: 1 | AA16: 1 | AC16: J | AD16: 4 | AE16: 11 | AF16: 4 | AG16: 20 | AH16: 22 | AJ16: J | AK16: 4 | AL16: 11 | AM16: 4 | AN16: 20 | AO16: 22
A17: G3 | B17: Gold M3 | C17: =COUNTIF(K:K, $A17) -> 0 | D17: =COUNTIF(L:L, $A17) -> 7 | E17: =COUNTIF(M:M, $A17) -> 0 | F17: =COUNTIF(N:N, $A17) -> 4 | G17: =COUNTIF(O:O, $A17) -> 0 | H17: 13 | J17: 13 | K17: K | L17: GA | M17: K | N17: M4 | O17: M3 | Q17: 8 | R17: 16 | S17: 8 | T17: 5 | U17: 4 | W17: 1 | X17: 1 | Y17: 1 | Z17: 2 | AA17: 1 | AC17: G1 | AD17: 0 | AE17: 5 | AF17: 1 | AG17: 5 | AH17: 0 | AJ17: G1 | AK17: 0 | AL17: 5 | AM17: 1 | AN17: 5 | AO17: 0
A18: G4 | B18: Gold M4 | C18: =COUNTIF(K:K, $A18) -> 0 | D18: =COUNTIF(L:L, $A18) -> 10 | E18: =COUNTIF(M:M, $A18) -> 3 | F18: =COUNTIF(N:N, $A18) -> 3 | G18: =COUNTIF(O:O, $A18) -> 0 | H18: 14 | J18: 14 | K18: A | L18: M3 | M18: M3 | N18: C1 | O18: J | Q18: 7 | R18: 4 | S18: 4 | T18: 1 | U18: 10 | W18: 1 | X18: 2 | Y18: 1 | Z18: 2 | AA18: 1 | AC18: G2 | AD18: 0 | AE18: 6 | AF18: 1 | AG18: 5 | AH18: 0 | AJ18: G2 | AK18: 0 | AL18: 6 | AM18: 1 | AN18: 5 | AO18: 0
... A23: GJ | B23: Gold J | C23: =COUNTIF(K:K, $A23) -> 0 | D23: =COUNTIF(L:L, $A23) -> 6 | E23: =COUNTIF(M:M, $A23) -> 0 | F23: =COUNTIF(N:N, $A23) -> 4 | G23: =COUNTIF(O:O, $A23) -> 0 | H23: 19 | J23: 19 | K23: K | L23: GA | M23: A | N23: Q | O23: M2 | Q23: 8 | R23: 16 | S23: 7 | T23: 9 | U23: 3 | W23: 1 | X23: 1 | Y23: 1 | Z23: 1 | AA23: 1 | AC23: GK | AD23: 0 | AE23: 9 | AF23: 4 | AG23: 4 | AH23: 0 | AJ23: GK | AK23: 0 | AL23: 9 | AM23: 4 | AN23: 4 | AO23: 0
C24: =SUM(C4:C23) -> 200 | D24: =SUM(D4:D23) -> 200 | E24: =SUM(E4:E23) -> 200 | F24: =SUM(F4:F23) -> 200 | G24: =SUM(G4:G23) -> 200 | J24: 20 | K24: A | L24: A | M24: M4 | N24: GK | O24: A | Q24: 7 | R24: 7 | S24: 5 | T24: 17 | U24: 7 | W24: 1 | X24: 1 | Y24: 2 | Z24: 1 | AA24: 1 | AC24: GQ | AD24: 0 | AE24: 6 | AF24: 1 | AG24: 5 | AH24: 0 | AJ24: GQ | AK24: 0 | AL24: 6 | AM24: 1 | AN24: 5 | AO24: 0
J25: 21 | K25: M4 | L25: K | M25: M4 | N25: M1 | O25: M2 | Q25: 5 | R25: 8 | S25: 5 | T25: 2 | U25: 3 | W25: 1 | X25: 1 | Y25: 2 | Z25: 1 | AA25: 2 | AC25: GJ | AD25: 0 | AE25: 6 | AF25: 1 | AG25: 5 | AH25: 0 | AJ25: GJ | AK25: 0 | AL25: 6 | AM25: 1 | AN25: 5 | AO25: 0
B26: Normal Symbol | C26: =SUM(C4:C14)/C24 -> 1 | D26: =SUM(D4:D14)/D24 -> 0.6 | E26: =SUM(E4:E14)/E24 -> 0.94 | F26: =SUM(F4:F14)/F24 -> 0.84 | G26: =SUM(G4:G14)/G24 -> 1 | J26: 22 | K26: Q | L26: G4 | M26: M4 | N26: M1 | O26: M1 | Q26: 9 | R26: 14 | S26: 5 | T26: 2 | U26: 2 | W26: 1 | X26: 2 | Y26: 1 | Z26: 1 | AA26: 2 | AD26: =SUM(AD6:AD25) -> 200 | AE26: =SUM(AE6:AE25) -> 209 | AF26: =SUM(AF6:AF25) -> 209 | AG26: =SUM(AG6:AG25) -> 209 | AH26: =SUM(AH6:AH25) -> 200 | AK26: =SUM(AK6:AK25) -> 200 | AL26: =SUM(AL6:AL25) -> 209 | AM26: =SUM(AM6:AM25) -> 209 | AN26: =SUM(AN6:AN25) -> 209 | AO26: =SUM(AO6:AO25) -> 200
B27: Golden Symbol | C27: =SUM(C15:C23)/C24 -> 0 | D27: =SUM(D15:D23)/D24 -> 0.4 | E27: =SUM(E15:E23)/E24 -> 0.06 | F27: =SUM(F15:F23)/F24 -> 0.16 | G27: =SUM(G15:G23)/G24 -> 0 | J27: 23 | K27: A | L27: M5 | M27: M5 | N27: A | O27: M1 | Q27: 7 | R27: 6 | S27: 6 | T27: 7 | U27: 2 | W27: 1 | X27: 2 | Y27: 1 | Z27: 1 | AA27: 1
J28: 24 | K28: K | L28: M4 | M28: A | N28: M4 | O28: J | Q28: 8 | R28: 5 | S28: 7 | T28: 5 | U28: 10 | W28: 1 | X28: 2 | Y28: 1 | Z28: 2 | AA28: 1 | AC28: 2 Combo | AJ28: 2 Combo
J29: 25 | K29: M4 | L29: GQ | M29: K | N29: Q | O29: K | Q29: 5 | R29: 18 | S29: 8 | T29: 9 | U29: 8 | W29: 1 | X29: 1 | Y29: 1 | Z29: 1 | AA29: 1 | AC29: Symbol | AD29: R1 | AE29: R2 | AF29: R3 | AG29: R4 | AH29: R5 | AJ29: Symbol | AK29: R1 | AL29: R2 | AM29: R3 | AN29: R4 | AO29: R5
J30: 26 | K30: A | L30: G4 | M30: A | N30: M2 | O30: M2 | Q30: 7 | R30: 14 | S30: 7 | T30: 3 | U30: 3 | W30: 1 | X30: 1 | Y30: 1 | Z30: 1 | AA30: 2 | AC30: {=$A$4:$A$23} -> WW | AD30: 0 | AE30: 0 | AF30: 0 | AG30: 0 | AH30: 0 | AJ30: {=$A$4:$A$23} -> WW | AK30: 0 | AL30: 0 | AM30: 0 | AN30: 0 | AO30: 0
J31: 27 | K31: K | L31: K | M31: A | N31: A | O31: M3 | Q31: 8 | R31: 8 | S31: 7 | T31: 7 | U31: 4 | W31: 1 | X31: 1 | Y31: 1 | Z31: 1 | AA31: 2 | AC31: C1 | AD31: 0 | AE31: 6 | AF31: 0 | AG31: 9 | AH31: 0 | AJ31: C1 | AK31: 0 | AL31: 6 | AM31: 0 | AN31: 9 | AO31: 0
J32: 28 | K32: M4 | L32: M2 | M32: M5 | N32: M2 | O32: M5 | Q32: 5 | R32: 3 | S32: 6 | T32: 3 | U32: 6 | W32: 2 | X32: 2 | Y32: 1 | Z32: 2 | AA32: 2 | AC32: M1 | AD32: 4 | AE32: 11 | AF32: 5 | AG32: 21 | AH32: 23 | AJ32: M1 | AK32: 4 | AL32: 11 | AM32: 5 | AN32: 21 | AO32: 23
J33: 29 | K33: Q | L33: M1 | M33: GK | N33: M2 | O33: Q | Q33: 9 | R33: 2 | S33: 17 | T33: 3 | U33: 9 | W33: 2 | X33: 2 | Y33: 1 | Z33: 2 | AA33: 2 | AC33: M2 | AD33: 4 | AE33: 11 | AF33: 5 | AG33: 21 | AH33: 23 | AJ33: M2 | AK33: 4 | AL33: 11 | AM33: 5 | AN33: 21 | AO33: 23
J34: 30 | K34: M4 | L34: G5 | M34: M4 | N34: M3 | O34: M1 | Q34: 5 | R34: 15 | S34: 5 | T34: 4 | U34: 2 | W34: 2 | X34: 2 | Y34: 1 | Z34: 2 | AA34: 2 | AC34: M3 | AD34: 4 | AE34: 11 | AF34: 5 | AG34: 21 | AH34: 22 | AJ34: M3 | AK34: 4 | AL34: 11 | AM34: 5 | AN34: 21 | AO34: 22
J35: 31 | K35: M4 | L35: G3 | M35: J | N35: J | O35: M1 | Q35: 5 | R35: 13 | S35: 10 | T35: 10 | U35: 2 | W35: 2 | X35: 2 | Y35: 1 | Z35: 1 | AA35: 2 | AC35: M4 | AD35: 43 | AE35: 20 | AF35: 41 | AG35: 14 | AH35: 22 | AJ35: M4 | AK35: 43 | AL35: 20 | AM35: 41 | AN35: 14 | AO35: 22
J36: 32 | K36: M4 | L36: M3 | M36: K | N36: J | O36: M3 | Q36: 5 | R36: 4 | S36: 8 | T36: 10 | U36: 4 | W36: 1 | X36: 2 | Y36: 1 | Z36: 1 | AA36: 2 | AC36: M5 | AD36: 43 | AE36: 21 | AF36: 41 | AG36: 14 | AH36: 22 | AJ36: M5 | AK36: 43 | AL36: 21 | AM36: 41 | AN36: 14 | AO36: 22
J37: 33 | K37: M5 | L37: M1 | M37: G5 | N37: A | O37: M3 | Q37: 6 | R37: 2 | S37: 15 | T37: 7 | U37: 4 | W37: 1 | X37: 2 | Y37: 2 | Z37: 1 | AA37: 2 | AC37: A | AD37: 47 | AE37: 21 | AF37: 41 | AG37: 14 | AH37: 22 | AJ37: A | AK37: 47 | AL37: 21 | AM37: 41 | AN37: 14 | AO37: 22
J38: 34 | K38: K | L38: Q | M38: M4 | N38: A | O38: M2 | Q38: 8 | R38: 9 | S38: 5 | T38: 7 | U38: 3 | W38: 1 | X38: 2 | Y38: 2 | Z38: 1 | AA38: 1 | AC38: K | AD38: 47 | AE38: 21 | AF38: 41 | AG38: 14 | AH38: 22 | AJ38: K | AK38: 47 | AL38: 21 | AM38: 41 | AN38: 14 | AO38: 22
J39: 35 | K39: A | L39: G5 | M39: M4 | N39: M5 | O39: Q | Q39: 7 | R39: 15 | S39: 5 | T39: 6 | U39: 9 | W39: 1 | X39: 2 | Y39: 2 | Z39: 2 | AA39: 1 | AC39: Q | AD39: 4 | AE39: 11 | AF39: 5 | AG39: 20 | AH39: 22 | AJ39: Q | AK39: 4 | AL39: 11 | AM39: 5 | AN39: 20 | AO39: 22
J40: 36 | K40: M5 | L40: M5 | M40: J | N40: G3 | O40: K | Q40: 6 | R40: 6 | S40: 10 | T40: 13 | U40: 8 | W40: 1 | X40: 2 | Y40: 2 | Z40: 2 | AA40: 1 | AC40: J | AD40: 4 | AE40: 11 | AF40: 4 | AG40: 20 | AH40: 22 | AJ40: J | AK40: 4 | AL40: 11 | AM40: 4 | AN40: 20 | AO40: 22
J41: 37 | K41: A | L41: M4 | M41: M5 | N41: M3 | O41: K | Q41: 7 | R41: 5 | S41: 6 | T41: 4 | U41: 8 | W41: 1 | X41: 2 | Y41: 2 | Z41: 2 | AA41: 1 | AC41: G1 | AD41: 0 | AE41: 5 | AF41: 1 | AG41: 5 | AH41: 0 | AJ41: G1 | AK41: 0 | AL41: 5 | AM41: 1 | AN41: 5 | AO41: 0
J42: 38 | K42: M5 | L42: M3 | M42: M3 | N42: M5 | O42: M4 | Q42: 6 | R42: 4 | S42: 4 | T42: 6 | U42: 5 | W42: 1 | X42: 1 | Y42: 1 | Z42: 2 | AA42: 2 | AC42: G2 | AD42: 0 | AE42: 6 | AF42: 1 | AG42: 5 | AH42: 0 | AJ42: G2 | AK42: 0 | AL42: 6 | AM42: 1 | AN42: 5 | AO42: 0
... J49: 45 | K49: M4 | L49: GK | M49: M5 | N49: M3 | O49: M5 | Q49: 5 | R49: 17 | S49: 6 | T49: 4 | U49: 6 | W49: 2 | X49: 1 | Y49: 1 | Z49: 2 | AA49: 2 | AC49: GJ | AD49: 0 | AE49: 6 | AF49: 1 | AG49: 5 | AH49: 0 | AJ49: GJ | AK49: 0 | AL49: 6 | AM49: 1 | AN49: 5 | AO49: 0
J50: 46 | K50: M3 | L50: GK | M50: K | N50: Q | O50: M1 | Q50: 4 | R50: 17 | S50: 8 | T50: 9 | U50: 2 | W50: 1 | X50: 1 | Y50: 1 | Z50: 2 | AA50: 2 | AD50: =SUM(AD30:AD49) -> 200 | AE50: =SUM(AE30:AE49) -> 209 | AF50: =SUM(AF30:AF49) -> 209 | AG50: =SUM(AG30:AG49) -> 209 | AH50: =SUM(AH30:AH49) -> 200 | AK50: =SUM(AK30:AK49) -> 200 | AL50: =SUM(AL30:AL49) -> 209 | AM50: =SUM(AM30:AM49) -> 209 | AN50: =SUM(AN30:AN49) -> 209 | AO50: =SUM(AO30:AO49) -> 200
J51: 47 | K51: M1 | L51: K | M51: M4 | N51: G1 | O51: M5 | Q51: 2 | R51: 8 | S51: 5 | T51: 11 | U51: 6 | W51: 1 | X51: 1 | Y51: 1 | Z51: 1 | AA51: 2
...

Sheet BG_Symbol (2)
J2: Symbol | Q2: Symbol ID | W2: Symbol Weight | AC2: Eliminate Wheel Weight A | AJ2: Eliminate Wheel Weight B
A3: Symbol | B3: Description | C3: R1 | D3: R2 | E3: R3 | F3: R4 | G3: R5 | H3: ID | K3: R1 | L3: R2 | M3: R3 | N3: R4 | O3: R5 | Q3: R1 | R3: R2 | S3: R3 | T3: R4 | U3: R5 | W3: R1 | X3: R2 | Y3: R3 | Z3: R4 | AA3: R5
A4: {=Overview!A38:B57} -> WW | B4: Wild | C4: =COUNTIF(K:K, $A4) -> 0 | D4: =COUNTIF(L:L, $A4) -> 0 | E4: =COUNTIF(M:M, $A4) -> 0 | F4: =COUNTIF(N:N, $A4) -> 0 | G4: =COUNTIF(O:O, $A4) -> 0 | H4: {=Overview!F38:F57} -> 0 | J4: {=_xlfn.SEQUENCE(MAX(COUNTA(K:K), COUNTA(L:L), COUNTA(M:M), COUNTA(N:N), COUNTA(O:O))-1,,0)} -> 0 | K4: K | L4: A | M4: GA | N4: J | O4: M1 | Q4: {=_xlfn.LET(_xlpm.x, K4:O304, IF(_xlpm.x="", "", _xlfn.XLOOKUP(_xlpm.x, $A$4:$A$23,_xlfn.ANCHORARRAY( H4))))} -> 8 | R4: 7 | S4: 16 | T4: 10 | U4: 2 | W4: {=_xlfn.LET(_xlpm.x, K4:K6, IF(SUM((_xlpm.x="K")*1, (_xlpm.x="A")*1, (_xlpm.x="GK")*1, (_xlpm.x="GA")*1)>0, 3, 1))} -> 3 | X4: {=_xlfn.LET(_xlpm.x, L4:L6, IF(SUM((_xlpm.x="K")*1, (_xlpm.x="A")*1, (_xlpm.x="GK")*1, (_xlpm.x="GA")*1)>0, 3, 1))} -> 3 | Y4: {=_xlfn.LET(_xlpm.x, M4:M6, IF(SUM((_xlpm.x="K")*1, (_xlpm.x="A")*1, (_xlpm.x="GK")*1, (_xlpm.x="GA")*1)>0, 3, 1))} -> 3 | Z4: 1 | AA4: 1 | AC4: 1 Combo | AJ4: 1 Combo
A5: C1 | B5: Scatter | C5: =COUNTIF(K:K, $A5) -> 0 | D5: =COUNTIF(L:L, $A5) -> 6 | E5: =COUNTIF(M:M, $A5) -> 0 | F5: =COUNTIF(N:N, $A5) -> 9 | G5: =COUNTIF(O:O, $A5) -> 0 | H5: 1 | J5: 1 | K5: A | L5: A | M5: GQ | N5: M1 | O5: M3 | Q5: 7 | R5: 7 | S5: 18 | T5: 2 | U5: 4 | W5: {=_xlfn.LET(_xlpm.x, K5:K7, IF(SUM((_xlpm.x="K")*1, (_xlpm.x="A")*1, (_xlpm.x="GK")*1, (_xlpm.x="GA")*1)>0, 3, 1))} -> 3 | X5: {=_xlfn.LET(_xlpm.x, L5:L7, IF(SUM((_xlpm.x="K")*1, (_xlpm.x="A")*1, (_xlpm.x="GK")*1, (_xlpm.x="GA")*1)>0, 3, 1))} -> 3 | Y5: {=_xlfn.LET(_xlpm.x, M5:M7, IF(SUM((_xlpm.x="K")*1, (_xlpm.x="A")*1, (_xlpm.x="GK")*1, (_xlpm.x="GA")*1)>0, 3, 1))} -> 1 | Z5: 1 | AA5: 1 | AC5: Symbol | AD5: R1 | AE5: R2 | AF5: R3 | AG5: R4 | AH5: R5 | AJ5: Symbol | AK5: R1 | AL5: R2 | AM5: R3 | AN5: R4 | AO5: R5
A6: M1 | B6: M1 | C6: =COUNTIF(K:K, $A6) -> 4 | D6: =COUNTIF(L:L, $A6) -> 6 | E6: =COUNTIF(M:M, $A6) -> 0 | F6: =COUNTIF(N:N, $A6) -> 22 | G6: =COUNTIF(O:O, $A6) -> 28 | H6: 2 | J6: 2 | K6: M1 | L6: GA | M6: G4 | N6: M3 | O6: M2 | Q6: 2 | R6: 16 | S6: 14 | T6: 4 | U6: 3 | W6: {=_xlfn.LET(_xlpm.x, K6:K8, IF(SUM((_xlpm.x="K")*1, (_xlpm.x="A")*1, (_xlpm.x="GK")*1, (_xlpm.x="GA")*1)>0, 3, 1))} -> 3 | X6: {=_xlfn.LET(_xlpm.x, L6:L8, IF(SUM((_xlpm.x="K")*1, (_xlpm.x="A")*1, (_xlpm.x="GK")*1, (_xlpm.x="GA")*1)>0, 3, 1))} -> 3 | Y6: {=_xlfn.LET(_xlpm.x, M6:M8, IF(SUM((_xlpm.x="K")*1, (_xlpm.x="A")*1, (_xlpm.x="GK")*1, (_xlpm.x="GA")*1)>0, 3, 1))} -> 1 | Z6: 1 | AA6: 1 | AC6: {=$A$4:$A$23} -> WW | AD6: 0 | AE6: 0 | AF6: 0 | AG6: 0 | AH6: 0 | AJ6: {=$A$4:$A$23} -> WW | AK6: 0 | AL6: 0 | AM6: 0 | AN6: 0 | AO6: 0
A7: M2 | B7: M2 | C7: =COUNTIF(K:K, $A7) -> 4 | D7: =COUNTIF(L:L, $A7) -> 6 | E7: =COUNTIF(M:M, $A7) -> 0 | F7: =COUNTIF(N:N, $A7) -> 22 | G7: =COUNTIF(O:O, $A7) -> 27 | H7: 3 | J7: 3 | K7: M4 | L7: Q | M7: G5 | N7: M3 | O7: M2 | Q7: 5 | R7: 9 | S7: 15 | T7: 4 | U7: 3 | W7: {=_xlfn.LET(_xlpm.x, K7:K9, IF(SUM((_xlpm.x="K")*1, (_xlpm.x="A")*1, (_xlpm.x="GK")*1, (_xlpm.x="GA")*1)>0, 3, 1))} -> 3 | X7: {=_xlfn.LET(_xlpm.x, L7:L9, IF(SUM((_xlpm.x="K")*1, (_xlpm.x="A")*1, (_xlpm.x="GK")*1, (_xlpm.x="GA")*1)>0, 3, 1))} -> 3 | Y7: {=_xlfn.LET(_xlpm.x, M7:M9, IF(SUM((_xlpm.x="K")*1, (_xlpm.x="A")*1, (_xlpm.x="GK")*1, (_xlpm.x="GA")*1)>0, 3, 1))} -> 3 | Z7: 1 | AA7: 1 | AC7: C1 | AD7: 0 | AE7: 6 | AF7: 0 | AG7: 9 | AH7: 0 | AJ7: C1 | AK7: 0 | AL7: 6 | AM7: 0 | AN7: 9 | AO7: 0
A8: M3 | B8: M3 | C8: =COUNTIF(K:K, $A8) -> 4 | D8: =COUNTIF(L:L, $A8) -> 6 | E8: =COUNTIF(M:M, $A8) -> 0 | F8: =COUNTIF(N:N, $A8) -> 22 | G8: =COUNTIF(O:O, $A8) -> 27 | H8: 4 | J8: 4 | K8: K | L8: GA | M8: G4 | N8: M2 | O8: K | Q8: 8 | R8: 16 | S8: 14 | T8: 3 | U8: 8 | W8: {=_xlfn.LET(_xlpm.x, K8:K10, IF(SUM((_xlpm.x="K")*1, (_xlpm.x="A")*1, (_xlpm.x="GK")*1, (_xlpm.x="GA")*1)>0, 3, 1))} -> 3 | X8: {=_xlfn.LET(_xlpm.x, L8:L10, IF(SUM((_xlpm.x="K")*1, (_xlpm.x="A")*1, (_xlpm.x="GK")*1, (_xlpm.x="GA")*1)>0, 3, 1))} -> 3 | Y8: {=_xlfn.LET(_xlpm.x, M8:M10, IF(SUM((_xlpm.x="K")*1, (_xlpm.x="A")*1, (_xlpm.x="GK")*1, (_xlpm.x="GA")*1)>0, 3, 1))} -> 3 | Z8: 1 | AA8: 1 | AC8: M1 | AD8: 4 | AE8: 11 | AF8: 0 | AG8: 22 | AH8: 28 | AJ8: M1 | AK8: 4 | AL8: 11 | AM8: 0 | AN8: 22 | AO8: 28
A9: M4 | B9: M4 | C9: =COUNTIF(K:K, $A9) -> 43 | D9: =COUNTIF(L:L, $A9) -> 19 | E9: =COUNTIF(M:M, $A9) -> 0 | F9: =COUNTIF(N:N, $A9) -> 12 | G9: =COUNTIF(O:O, $A9) -> 16 | H9: 5 | J9: 5 | K9: M5 | L9: M3 | M9: GK | N9: M2 | O9: M2 | Q9: 6 | R9: 4 | S9: 17 | T9: 3 | U9: 3 | W9: {=_xlfn.LET(_xlpm.x, K9:K11, IF(SUM((_xlpm.x="K")*1, (_xlpm.x="A")*1, (_xlpm.x="GK")*1, (_xlpm.x="GA")*1)>0, 3, 1))} -> 3 | X9: {=_xlfn.LET(_xlpm.x, L9:L11, IF(SUM((_xlpm.x="K")*1, (_xlpm.x="A")*1, (_xlpm.x="GK")*1, (_xlpm.x="GA")*1)>0, 3, 1))} -> 1 | Y9: {=_xlfn.LET(_xlpm.x, M9:M11, IF(SUM((_xlpm.x="K")*1, (_xlpm.x="A")*1, (_xlpm.x="GK")*1, (_xlpm.x="GA")*1)>0, 3, 1))} -> 3 | Z9: 1 | AA9: 1 | AC9: M2 | AD9: 4 | AE9: 11 | AF9: 0 | AG9: 22 | AH9: 27 | AJ9: M2 | AK9: 4 | AL9: 11 | AM9: 0 | AN9: 22 | AO9: 27
A10: M5 | B10: M5 | C10: =COUNTIF(K:K, $A10) -> 43 | D10: =COUNTIF(L:L, $A10) -> 19 | E10: =COUNTIF(M:M, $A10) -> 0 | F10: =COUNTIF(N:N, $A10) -> 12 | G10: =COUNTIF(O:O, $A10) -> 16 | H10: 6 | J10: 6 | K10: K | L10: M4 | M10: GA | N10: J | O10: A | Q10: 8 | R10: 5 | S10: 16 | T10: 10 | U10: 7 | W10: {=_xlfn.LET(_xlpm.x, K10:K12, IF(SUM((_xlpm.x="K")*1, (_xlpm.x="A")*1, (_xlpm.x="GK")*1, (_xlpm.x="GA")*1)>0, 3, 1))} -> 3 | X10: {=_xlfn.LET(_xlpm.x, L10:L12, IF(SUM((_xlpm.x="K")*1, (_xlpm.x="A")*1, (_xlpm.x="GK")*1, (_xlpm.x="GA")*1)>0, 3, 1))} -> 3 | Y10: {=_xlfn.LET(_xlpm.x, M10:M12, IF(SUM((_xlpm.x="K")*1, (_xlpm.x="A")*1, (_xlpm.x="GK")*1, (_xlpm.x="GA")*1)>0, 3, 1))} -> 3 | Z10: 1 | AA10: 1 | AC10: M3 | AD10: 4 | AE10: 11 | AF10: 0 | AG10: 22 | AH10: 27 | AJ10: M3 | AK10: 4 | AL10: 11 | AM10: 0 | AN10: 22 | AO10: 27
A11: A | B11: A | C11: =COUNTIF(K:K, $A11) -> 47 | D11: =COUNTIF(L:L, $A11) -> 22 | E11: =COUNTIF(M:M, $A11) -> 0 | F11: =COUNTIF(N:N, $A11) -> 12 | G11: =COUNTIF(O:O, $A11) -> 16 | H11: 7 | J11: 7 | K11: M5 | L11: G3 | M11: G5 | N11: J | O11: M5 | Q11: 6 | R11: 13 | S11: 15 | T11: 10 | U11: 6 | W11: {=_xlfn.LET(_xlpm.x, K11:K13, IF(SUM((_xlpm.x="K")*1, (_xlpm.x="A")*1, (_xlpm.x="GK")*1, (_xlpm.x="GA")*1)>0, 3, 1))} -> 3 | X11: {=_xlfn.LET(_xlpm.x, L11:L13, IF(SUM((_xlpm.x="K")*1, (_xlpm.x="A")*1, (_xlpm.x="GK")*1, (_xlpm.x="GA")*1)>0, 3, 1))} -> 3 | Y11: {=_xlfn.LET(_xlpm.x, M11:M13, IF(SUM((_xlpm.x="K")*1, (_xlpm.x="A")*1, (_xlpm.x="GK")*1, (_xlpm.x="GA")*1)>0, 3, 1))} -> 3 | Z11: 1 | AA11: 1 | AC11: M4 | AD11: 43 | AE11: 19 | AF11: 0 | AG11: 12 | AH11: 16 | AJ11: M4 | AK11: 43 | AL11: 19 | AM11: 0 | AN11: 12 | AO11: 16
A12: K | B12: K | C12: =COUNTIF(K:K, $A12) -> 47 | D12: =COUNTIF(L:L, $A12) -> 24 | E12: =COUNTIF(M:M, $A12) -> 0 | F12: =COUNTIF(N:N, $A12) -> 12 | G12: =COUNTIF(O:O, $A12) -> 16 | H12: 8 | J12: 8 | K12: M4 | L12: A | M12: GK | N12: M5 | O12: M5 | Q12: 5 | R12: 7 | S12: 17 | T12: 6 | U12: 6 | W12: {=_xlfn.LET(_xlpm.x, K12:K14, IF(SUM((_xlpm.x="K")*1, (_xlpm.x="A")*1, (_xlpm.x="GK")*1, (_xlpm.x="GA")*1)>0, 3, 1))} -> 3 | X12: {=_xlfn.LET(_xlpm.x, L12:L14, IF(SUM((_xlpm.x="K")*1, (_xlpm.x="A")*1, (_xlpm.x="GK")*1, (_xlpm.x="GA")*1)>0, 3, 1))} -> 3 | Y12: {=_xlfn.LET(_xlpm.x, M12:M14, IF(SUM((_xlpm.x="K")*1, (_xlpm.x="A")*1, (_xlpm.x="GK")*1, (_xlpm.x="GA")*1)>0, 3, 1))} -> 3 | Z12: 1 | AA12: 1 | AC12: M5 | AD12: 43 | AE12: 20 | AF12: 0 | AG12: 12 | AH12: 16 | AJ12: M5 | AK12: 43 | AL12: 20 | AM12: 0 | AN12: 12 | AO12: 16
A13: Q | B13: Q | C13: =COUNTIF(K:K, $A13) -> 4 | D13: =COUNTIF(L:L, $A13) -> 5 | E13: =COUNTIF(M:M, $A13) -> 0 | F13: =COUNTIF(N:N, $A13) -> 21 | G13: =COUNTIF(O:O, $A13) -> 27 | H13: 9 | J13: 9 | K13: K | L13: GJ | M13: G5 | N13: GJ | O13: M1 | Q13: 8 | R13: 19 | S13: 15 | T13: 19 | U13: 2 | W13: {=_xlfn.LET(_xlpm.x, K13:K15, IF(SUM((_xlpm.x="K")*1, (_xlpm.x="A")*1, (_xlpm.x="GK")*1, (_xlpm.x="GA")*1)>0, 3, 1))} -> 3 | X13: {=_xlfn.LET(_xlpm.x, L13:L15, IF(SUM((_xlpm.x="K")*1, (_xlpm.x="A")*1, (_xlpm.x="GK")*1, (_xlpm.x="GA")*1)>0, 3, 1))} -> 1 | Y13: {=_xlfn.LET(_xlpm.x, M13:M15, IF(SUM((_xlpm.x="K")*1, (_xlpm.x="A")*1, (_xlpm.x="GK")*1, (_xlpm.x="GA")*1)>0, 3, 1))} -> 3 | Z13: 1 | AA13: 1 | AC13: A | AD13: 47 | AE13: 20 | AF13: 0 | AG13: 12 | AH13: 16 | AJ13: A | AK13: 47 | AL13: 20 | AM13: 0 | AN13: 12 | AO13: 16
A14: J | B14: J | C14: =COUNTIF(K:K, $A14) -> 4 | D14: =COUNTIF(L:L, $A14) -> 7 | E14: =COUNTIF(M:M, $A14) -> 0 | F14: =COUNTIF(N:N, $A14) -> 21 | G14: =COUNTIF(O:O, $A14) -> 27 | H14: 10 | J14: 10 | K14: Q | L14: G5 | M14: GA | N14: M1 | O14: K | Q14: 9 | R14: 15 | S14: 16 | T14: 2 | U14: 8 | W14: {=_xlfn.LET(_xlpm.x, K14:K16, IF(SUM((_xlpm.x="K")*1, (_xlpm.x="A")*1, (_xlpm.x="GK")*1, (_xlpm.x="GA")*1)>0, 3, 1))} -> 3 | X14: {=_xlfn.LET(_xlpm.x, L14:L16, IF(SUM((_xlpm.x="K")*1, (_xlpm.x="A")*1, (_xlpm.x="GK")*1, (_xlpm.x="GA")*1)>0, 3, 1))} -> 1 | Y14: {=_xlfn.LET(_xlpm.x, M14:M16, IF(SUM((_xlpm.x="K")*1, (_xlpm.x="A")*1, (_xlpm.x="GK")*1, (_xlpm.x="GA")*1)>0, 3, 1))} -> 3 | Z14: 1 | AA14: 1 | AC14: K | AD14: 47 | AE14: 20 | AF14: 0 | AG14: 12 | AH14: 16 | AJ14: K | AK14: 47 | AL14: 20 | AM14: 0 | AN14: 12 | AO14: 16
A15: G1 | B15: Gold M1 | C15: =COUNTIF(K:K, $A15) -> 0 | D15: =COUNTIF(L:L, $A15) -> 4 | E15: =COUNTIF(M:M, $A15) -> 5 | F15: =COUNTIF(N:N, $A15) -> 5 | G15: =COUNTIF(O:O, $A15) -> 0 | H15: 11 | J15: 11 | K15: A | L15: M4 | M15: G4 | N15: A | O15: K | Q15: 7 | R15: 5 | S15: 14 | T15: 7 | U15: 8 | W15: {=_xlfn.LET(_xlpm.x, K15:K17, IF(SUM((_xlpm.x="K")*1, (_xlpm.x="A")*1, (_xlpm.x="GK")*1, (_xlpm.x="GA")*1)>0, 3, 1))} -> 3 | X15: {=_xlfn.LET(_xlpm.x, L15:L17, IF(SUM((_xlpm.x="K")*1, (_xlpm.x="A")*1, (_xlpm.x="GK")*1, (_xlpm.x="GA")*1)>0, 3, 1))} -> 1 | Y15: {=_xlfn.LET(_xlpm.x, M15:M17, IF(SUM((_xlpm.x="K")*1, (_xlpm.x="A")*1, (_xlpm.x="GK")*1, (_xlpm.x="GA")*1)>0, 3, 1))} -> 3 | Z15: 1 | AA15: 1 | AC15: Q | AD15: 4 | AE15: 11 | AF15: 0 | AG15: 21 | AH15: 27 | AJ15: Q | AK15: 4 | AL15: 11 | AM15: 0 | AN15: 21 | AO15: 27
A16: G2 | B16: Gold M2 | C16: =COUNTIF(K:K, $A16) -> 0 | D16: =COUNTIF(L:L, $A16) -> 4 | E16: =COUNTIF(M:M, $A16) -> 5 | F16: =COUNTIF(N:N, $A16) -> 5 | G16: =COUNTIF(O:O, $A16) -> 0 | H16: 12 | J16: 12 | K16: Q | L16: M4 | M16: GK | N16: GA | O16: Q | Q16: 9 | R16: 5 | S16: 17 | T16: 16 | U16: 9 | W16: {=_xlfn.LET(_xlpm.x, K16:K18, IF(SUM((_xlpm.x="K")*1, (_xlpm.x="A")*1, (_xlpm.x="GK")*1, (_xlpm.x="GA")*1)>0, 3, 1))} -> 3 | X16: {=_xlfn.LET(_xlpm.x, L16:L18, IF(SUM((_xlpm.x="K")*1, (_xlpm.x="A")*1, (_xlpm.x="GK")*1, (_xlpm.x="GA")*1)>0, 3, 1))} -> 3 | Y16: {=_xlfn.LET(_xlpm.x, M16:M18, IF(SUM((_xlpm.x="K")*1, (_xlpm.x="A")*1, (_xlpm.x="GK")*1, (_xlpm.x="GA")*1)>0, 3, 1))} -> 3 | Z16: 1 | AA16: 1 | AC16: J | AD16: 4 | AE16: 11 | AF16: 0 | AG16: 21 | AH16: 27 | AJ16: J | AK16: 4 | AL16: 11 | AM16: 0 | AN16: 21 | AO16: 27
