Workbook

Sheet Overview
A2: Model: | B2: H026192
A3: Version: | B3: 0.1.0.3
A6: Base Bet
A7: 100
A10: Coin in | B10: Price(x) | C10: Total RTP | D10: Bet Type
A11: {=B11:B12*A7} -> 100 | B11: 1 | C11: =SUM(B17:B18) -> 0 | D11: Normal Bet
A12: 7500 | B12: 75 | C12: =SUM(B21:B22) -> 0 | D12: Buy Feature
A15: Total Pay Back Percentage includes the following adjustments.
A16: Bet Type | B16: Pay Back | C16: Hit% | D16: Pulls/Hit | E16: Description
A17: =D11 -> Normal Bet | C17: =1/D17 -> #DIV/0! | E17: Base Game
E18: Free Game
A20: Bet Type | B20: Pay Back | C20: Hit% | D20: Pulls/Hit | E20: Description
A21: =D12 -> Buy Feature | C21: =1/D21 -> 1 | D21: 1 | E21: Base Game
E22: Free Game
A25: Reel # | B25: 1 | C25: 2 | D25: 3 | E25: 4 | F25: 5
A26: Visible Window Size | B26: 3 | C26: 3 | D26: 3 | E26: 3 | F26: 3
A29: Free Spins Setting
A30: C1 Num. | B30: Base Game | C30: Free Game
A31: 3 | B31: 15 | C31: 15
A32: 4 | B32: 17 | C32: 17
A33: 5 | B33: 19 | C33: 19
A34: The maximum of free spins is 50.
A36: Pay Table： | B36: ="All wins show for "&A7&" credit bet." -> All wins show for 100 credit bet.
A37: Symbol | B37: Description | C37: 3 | D37: 4 | E37: 5 | F37: Id
A38: WW | B38: Wild | C38: 0 | D38: 0 | E38: 0 | F38: 0
A39: C1 | B39: Scatter | C39: 0 | D39: 0 | E39: 0 | F39: 1
A40: M1 | B40: M1 | C40: 250 | D40: 1250 | E40: 5000 | F40: 2
A41: M2 | B41: M2 | C41: 100 | D41: 500 | E41: 2000 | F41: 3
A42: M3 | B42: M3 | C42: 75 | D42: 250 | E42: 1000 | F42: 4
A43: M4 | B43: M4 | C43: 50 | D43: 200 | E43: 750 | F43: 5
A44: M5 | B44: M5 | C44: 25 | D44: 100 | E44: 500 | F44: 6
A45: A | B45: A | C45: 10 | D45: 50 | E45: 250 | F45: 7
A46: K | B46: K | C46: 10 | D46: 50 | E46: 250 | F46: 8
A47: Q | B47: Q | C47: 10 | D47: 50 | E47: 250 | F47: 9
A48: J | B48: J | C48: 10 | D48: 50 | E48: 250 | F48: 10
A49: G1 | B49: Gold M1 | C49: 250 | D49: 1250 | E49: 5000 | F49: 11
... A57: GJ | B57: Gold J | C57: 10 | D57: 50 | E57: 250 | F57: 19

Sheet Description
B3: 7. BG 流程對應
B5: 7.1 BG 開局流程
B7: BG 每局的主要參數流程如下：
B8: 1. 先用 Table Selection Weight - Base Game 選出 BG table。
B9: 2. 再用該 strip 的 Symbol Weight R1~R5 抽停輪位置。
B10: 3. 依 Symbol ID R1~R5 生成初始盤面。
B11: 4. 盤面上的金框會先判定是否觸發 Used Special Pool Weight。
B12: 5. 若命中特殊池，該金框用 Multiple Selection Weight - Special Pool 抽倍率。
B13: 6. 若沒命中特殊池：
B14: - 且是 BG_Symbol (2) 則第 3 輪金框用 Multiple Selection Weight - Reel3 Before Eliminate
B15: - 其他輪金框用 Multiple Selection Weight - Before Eliminate
B16: 7. 再用 Eliminate Table Weight 決定本局是掉落表 A 或 B。
... B83: 5. BG_Symbol (3): 觸發 FG 用的表。得分少、C1 多，盡量不要有倍數百搭參與 → 控制進 FG 時的得分

Sheet Parameter
B3: Line | I3: Table Selection Weight - Base Game (Weight/Total) | N3: Multiple Selection Weight - Special Pool (Weight/Total) | AC3: Used Special Pool Weight (Weight/10000)
B4: ID | C4: R1 | D4: R2 | E4: R3 | F4: R4 | G4: R5 | I4: Worksheet Name | J4: Weight | K4: RTP | N4: Worksheet Name \ Multiple | O4: 0 | P4: 2 | Q4: 3 | R4: 5 | S4: 8 | T4: 10 | U4: 15 | V4: 20 | W4: 25 | X4: 35 | Y4: 50 | Z4: 80 | AA4: 100 | AC4: Worksheet Name \ Multiple | AD4: 1 | AE4: 2 | AF4: 3 | AG4: 4 | AH4: 5 | AI4: 6 | AJ4: 7 | AK4: 8 | AL4: 9
B5: {=_xlfn.SEQUENCE(20,,0)} -> 0 | C5: 1 | D5: 1 | E5: 1 | F5: 1 | G5: 1 | I5: BG_Symbol | J5: =10000-J6-J7 -> 6500 | L5: {=J5:J7/J8} -> 0.65 | N5: BG_Symbol | O5: =10000-SUM(P5:AA5) -> 0 | P5: 0 | Q5: 0 | R5: 0 | S5: 0 | T5: =10000-SUM(U5:AA5) -> 4140 | U5: 3000 | V5: 2000 | W5: 500 | X5: 60 | Y5: 120 | Z5: 60 | AA5: 120 | AB5: {=SUMPRODUCT(O5:AA5/SUM(O5:AA5),$O$4:$AA$4)} -> 16.38 | AC5: BG_Symbol | AD5: 300 | AE5: 600 | AF5: 1080 | AG5: 1440 | AH5: 2250 | AI5: 2700 | AJ5: 3150 | AK5: 3600 | AL5: 4050
B6: 1 | C6: 0 | D6: 0 | E6: 0 | F6: 0 | G6: 0 | I6: BG_Symbol (2) | J6: 1500 | L6: 0.15 | M6: =J6+J5 -> 8000 | N6: BG_Symbol (2) | O6: =10000-SUM(P6:AA6) -> 0 | P6: 0 | Q6: 0 | R6: 0 | S6: 0 | T6: =10000-SUM(U6:AA6) -> 4970 | U6: 3000 | V6: 1350 | W6: 500 | X6: 30 | Y6: 60 | Z6: 30 | AA6: 60 | AB6: {=SUMPRODUCT(O6:AA6/SUM(O6:AA6),$O$4:$AA$4)} -> 14.665 | AC6: BG_Symbol (2) | AD6: 0 | AE6: 0 | AF6: 1050 | AG6: 1400 | AH6: 1750 | AI6: 2100 | AJ6: 3675 | AK6: 4200 | AL6: 4725
B7: 2 | C7: 2 | D7: 2 | E7: 2 | F7: 2 | G7: 2 | I7: BG_Symbol (3) | J7: 2000 | L7: 0.2 | N7: BG_Symbol (3) | O7: =10000-SUM(P7:AA7) -> 10000 | P7: 0 | Q7: 0 | R7: 0 | S7: 0 | T7: 0 | U7: 0 | V7: 0 | W7: 0 | X7: 0 | Y7: 0 | Z7: 0 | AA7: 0 | AB7: {=SUMPRODUCT(O7:AA7/SUM(O7:AA7),$O$4:$AA$4)} -> 0 | AC7: BG_Symbol (3) | AD7: 0 | AE7: 0 | AF7: 0 | AG7: 0 | AH7: 0 | AI7: 0 | AJ7: 0 | AK7: 0 | AL7: 0
B8: 3 | C8: 0 | D8: 1 | E8: 2 | F8: 1 | G8: 0 | J8: =SUM(J5:J7) -> 10000 | K8: =SUMPRODUCT(K5:K7,_xlfn.ANCHORARRAY(L5)) -> 0 | N8: FG_Symbol | O8: =10000-SUM(P8:AA8) -> 0 | P8: 0 | Q8: 0 | R8: 0 | S8: 0 | T8: =10000-SUM(U8:AA8) -> 4370 | U8: 2700 | V8: 1400 | W8: 270 | X8: 270 | Y8: 360 | Z8: 270 | AA8: 360 | AB8: {=SUMPRODUCT(O8:AA8/SUM(O8:AA8),$O$4:$AA$4)} -> 20.4 | AC8: FG_Symbol | AD8: 0 | AE8: 0 | AF8: 525 | AG8: 700 | AH8: 1750 | AI8: 2100 | AJ8: 3675 | AK8: 4200 | AL8: 4725
B9: 4 | C9: 2 | D9: 1 | E9: 0 | F9: 1 | G9: 2 | N9: FG_Symbol (2) | O9: =10000-SUM(P9:AA9) -> 0 | P9: 0 | Q9: 0 | R9: 0 | S9: 0 | T9: =10000-SUM(U9:AA9) -> 4370 | U9: 2700 | V9: 1400 | W9: 270 | X9: 270 | Y9: 360 | Z9: 270 | AA9: 360 | AB9: {=SUMPRODUCT(O9:AA9/SUM(O9:AA9),$O$4:$AA$4)} -> 20.4 | AC9: FG_Symbol (2) | AD9: 0 | AE9: 0 | AF9: 525 | AG9: 700 | AH9: 1750 | AI9: 2100 | AJ9: 3675 | AK9: 4200 | AL9: 4725
B10: 5 | C10: 0 | D10: 0 | E10: 1 | F10: 0 | G10: 0 | I10: Table Selection Weight - Free Game (Weight/Total) | N10: FG_Symbol (3) | O10: =10000-SUM(P10:AA10) -> 0 | P10: 0 | Q10: 0 | R10: 0 | S10: 0 | T10: =10000-SUM(U10:AA10) -> 4370 | U10: 2700 | V10: 1400 | W10: 270 | X10: 270 | Y10: 360 | Z10: 270 | AA10: 360 | AB10: {=SUMPRODUCT(O10:AA10/SUM(O10:AA10),$O$4:$AA$4)} -> 20.4 | AC10: FG_Symbol (3) | AD10: 0 | AE10: 0 | AF10: 525 | AG10: 700 | AH10: 1750 | AI10: 2100 | AJ10: 3675 | AK10: 4200 | AL10: 4725
B11: 6 | C11: 2 | D11: 2 | E11: 1 | F11: 2 | G11: 2 | I11: Worksheet Name | J11: Weight | K11: RTP | N11: BF_Symbol | O11: =10000-SUM(P11:AA11) -> 10000 | P11: 0 | Q11: 0 | R11: 0 | S11: 0 | T11: 0 | U11: 0 | V11: 0 | W11: 0 | X11: 0 | Y11: 0 | Z11: 0 | AA11: 0 | AB11: {=SUMPRODUCT(O11:AA11/SUM(O11:AA11),$O$4:$AA$4)} -> 0 | AC11: BF_Symbol | AD11: 0 | AE11: 0 | AF11: 0 | AG11: 0 | AH11: 0 | AI11: 0 | AJ11: 0 | AK11: 0 | AL11: 0
B12: 7 | C12: 1 | D12: 2 | E12: 2 | F12: 2 | G12: 1 | I12: FG_Symbol | J12: =10000-SUM(J13:J14) -> 10000 | L12: {=J12:J14/SUM(J15)} -> 1
B13: 8 | C13: 1 | D13: 0 | E13: 0 | F13: 0 | G13: 1 | I13: FG_Symbol (2) | J13: 0 | L13: 0
B14: 9 | C14: 0 | D14: 1 | E14: 1 | F14: 1 | G14: 0 | I14: FG_Symbol (3) | J14: 0 | L14: 0 | N14: Multiple Selection Weight - Reel3 Before Eliminate (Weight/Total)
B15: 10 | C15: 2 | D15: 1 | E15: 1 | F15: 1 | G15: 2 | J15: =SUM(J12:J14) -> 10000 | K15: =SUMPRODUCT(K12:K14,_xlfn.ANCHORARRAY(L12)) -> 0 | N15: Worksheet Name \ Multiple | O15: 0 | P15: 2 | Q15: 3 | R15: 5 | S15: 8 | T15: 10 | U15: 15 | V15: 20 | W15: 25 | X15: 35 | Y15: 50 | Z15: 80 | AA15: 100
B16: 11 | C16: 1 | D16: 1 | E16: 0 | F16: 1 | G16: 1 | N16: BG_Symbol | O16: =10000-SUM(P16:AA16) -> 10000 | P16: 0 | Q16: 0 | R16: 0 | S16: 0 | T16: 0 | U16: 0 | V16: 0 | W16: 0 | X16: 0 | Y16: 0 | Z16: 0 | AA16: 0 | AB16: {=SUMPRODUCT(O16:AA16/SUM(O16:AA16),$O$4:$AA$4)} -> 0
B17: 12 | C17: 1 | D17: 1 | E17: 2 | F17: 1 | G17: 1 | I17: Table Selection Weight - Buy Feature (Weight/Total) | N17: BG_Symbol (2) | O17: =10000-SUM(P17:AA17) -> 0 | P17: =10000-SUM(Q17:AA17) -> 4200 | Q17: 3400 | R17: 1200 | S17: 1200 | T17: 0 | U17: 0 | V17: 0 | W17: 0 | X17: 0 | Y17: 0 | Z17: 0 | AA17: 0 | AB17: {=SUMPRODUCT(O17:AA17/SUM(O17:AA17),$O$4:$AA$4)} -> 3.42
B18: 13 | C18: 1 | D18: 0 | E18: 1 | F18: 0 | G18: 1 | I18: Worksheet Name | J18: Weight | K18: RTP | N18: BG_Symbol (3) | O18: =10000-SUM(P18:AA18) -> 10000 | P18: 0 | Q18: 0 | R18: 0 | S18: 0 | T18: 0 | U18: 0 | V18: 0 | W18: 0 | X18: 0 | Y18: 0 | Z18: 0 | AA18: 0 | AB18: {=SUMPRODUCT(O18:AA18/SUM(O18:AA18),$O$4:$AA$4)} -> 0
B19: 14 | C19: 1 | D19: 2 | E19: 1 | F19: 2 | G19: 1 | I19: FG_Symbol | J19: =10000-SUM(J20:J21) -> 10000 | L19: {=J19:J21/SUM(J22)} -> 1 | N19: FG_Symbol | O19: =10000-SUM(P19:AA19) -> 0 | P19: =10000-SUM(Q19:AA19) -> 6300 | Q19: 2800 | R19: 600 | S19: 300 | T19: 0 | U19: 0 | V19: 0 | W19: 0 | X19: 0 | Y19: 0 | Z19: 0 | AA19: 0 | AB19: {=SUMPRODUCT(O19:AA19/SUM(O19:AA19),$O$4:$AA$4)} -> 2.64
B20: 15 | C20: 0 | D20: 1 | E20: 0 | F20: 1 | G20: 0 | I20: FG_Symbol (2) | J20: 0 | L20: 0 | N20: FG_Symbol (2) | O20: =10000-SUM(P20:AA20) -> 0 | P20: =10000-SUM(Q20:AA20) -> 6300 | Q20: 2800 | R20: 600 | S20: 300 | T20: 0 | U20: 0 | V20: 0 | W20: 0 | X20: 0 | Y20: 0 | Z20: 0 | AA20: 0 | AB20: {=SUMPRODUCT(O20:AA20/SUM(O20:AA20),$O$4:$AA$4)} -> 2.64
B21: 16 | C21: 2 | D21: 1 | E21: 2 | F21: 1 | G21: 2 | I21: FG_Symbol (3) | J21: 0 | L21: 0 | N21: FG_Symbol (3) | O21: =10000-SUM(P21:AA21) -> 0 | P21: =10000-SUM(Q21:AA21) -> 6300 | Q21: 2800 | R21: 600 | S21: 300 | T21: 0 | U21: 0 | V21: 0 | W21: 0 | X21: 0 | Y21: 0 | Z21: 0 | AA21: 0 | AB21: {=SUMPRODUCT(O21:AA21/SUM(O21:AA21),$O$4:$AA$4)} -> 2.64
B22: 17 | C22: 0 | D22: 0 | E22: 1 | F22: 2 | G22: 2 | J22: =SUM(J19:J21) -> 10000 | K22: =SUMPRODUCT(K19:K21,_xlfn.ANCHORARRAY(L19)) -> 0 | N22: BF_Symbol | O22: =10000-SUM(P22:AA22) -> 10000 | P22: 0 | Q22: 0 | R22: 0 | S22: 0 | T22: 0 | U22: 0 | V22: 0 | W22: 0 | X22: 0 | Y22: 0 | Z22: 0 | AA22: 0 | AB22: {=SUMPRODUCT(O22:AA22/SUM(O22:AA22),$O$4:$AA$4)} -> 0
B23: 18 | C23: 2 | D23: 2 | E23: 1 | F23: 0 | G23: 0
B24: 19 | C24: 0 | D24: 2 | E24: 0 | F24: 2 | G24: 0 | I24: Multiplier Range
I25: Multiplier | N25: Multiple Selection Weight - Reel3 After Eliminate (Weight/Total)
I26: 0 | N26: Worksheet Name \ Multiple | O26: 0 | P26: 2 | Q26: 3 | R26: 5 | S26: 8 | T26: 10 | U26: 15 | V26: 20 | W26: 25 | X26: 35 | Y26: 50 | Z26: 80 | AA26: 100
I27: 2 | N27: BG_Symbol | O27: =10000-SUM(P27:AA27) -> 10000 | P27: 0 | Q27: 0 | R27: 0 | S27: 0 | T27: 0 | U27: 0 | V27: 0 | W27: 0 | X27: 0 | Y27: 0 | Z27: 0 | AA27: 0 | AB27: {=SUMPRODUCT(O27:AA27/SUM(O27:AA27),$O$4:$AA$4)} -> 0
I28: 3 | N28: BG_Symbol (2) | O28: =10000-SUM(P28:AA28) -> 0 | P28: 4800 | Q28: 4000 | R28: 600 | S28: 600 | T28: 0 | U28: 0 | V28: 0 | W28: 0 | X28: 0 | Y28: 0 | Z28: 0 | AA28: 0 | AB28: {=SUMPRODUCT(O28:AA28/SUM(O28:AA28),$O$4:$AA$4)} -> 2.94
I29: 5 | N29: BG_Symbol (3) | O29: =10000-SUM(P29:AA29) -> 10000 | P29: 0 | Q29: 0 | R29: 0 | S29: 0 | T29: 0 | U29: 0 | V29: 0 | W29: 0 | X29: 0 | Y29: 0 | Z29: 0 | AA29: 0 | AB29: {=SUMPRODUCT(O29:AA29/SUM(O29:AA29),$O$4:$AA$4)} -> 0
I30: 8 | N30: FG_Symbol | O30: =10000-SUM(P30:AA30) -> 0 | P30: 6550 | Q30: 3000 | R30: 300 | S30: 150 | T30: 0 | U30: 0 | V30: 0 | W30: 0 | X30: 0 | Y30: 0 | Z30: 0 | AA30: 0 | AB30: {=SUMPRODUCT(O30:AA30/SUM(O30:AA30),$O$4:$AA$4)} -> 2.48
I31: 10 | N31: FG_Symbol (2) | O31: =10000-SUM(P31:AA31) -> 0 | P31: 6550 | Q31: 3000 | R31: 300 | S31: 150 | T31: 0 | U31: 0 | V31: 0 | W31: 0 | X31: 0 | Y31: 0 | Z31: 0 | AA31: 0 | AB31: {=SUMPRODUCT(O31:AA31/SUM(O31:AA31),$O$4:$AA$4)} -> 2.48
I32: 15 | N32: FG_Symbol (3) | O32: =10000-SUM(P32:AA32) -> 0 | P32: 6550 | Q32: 3000 | R32: 300 | S32: 150 | T32: 0 | U32: 0 | V32: 0 | W32: 0 | X32: 0 | Y32: 0 | Z32: 0 | AA32: 0 | AB32: {=SUMPRODUCT(O32:AA32/SUM(O32:AA32),$O$4:$AA$4)} -> 2.48
I33: 20 | N33: BF_Symbol | O33: =10000-SUM(P33:AA33) -> 10000 | P33: 0 | Q33: 0 | R33: 0 | S33: 0 | T33: 0 | U33: 0 | V33: 0 | W33: 0 | X33: 0 | Y33: 0 | Z33: 0 | AA33: 0 | AB33: {=SUMPRODUCT(O33:AA33/SUM(O33:AA33),$O$4:$AA$4)} -> 0
I34: 25
I35: 35
I36: 50 | N36: Multiple Selection Weight - Before Eliminate (Weight/Total)
I37: 80 | N37: Worksheet Name \ Multiple | O37: 0 | P37: 2 | Q37: 3 | R37: 5 | S37: 8 | T37: 10 | U37: 15 | V37: 20 | W37: 25 | X37: 35 | Y37: 50 | Z37: 80 | AA37: 100
I38: 100 | N38: BG_Symbol | O38: =10000-SUM(P38:AA38) -> 8500 | P38: 500 | Q38: 400 | R38: 300 | S38: 300 | T38: 0 | U38: 0 | V38: 0 | W38: 0 | X38: 0 | Y38: 0 | Z38: 0 | AA38: 0 | AB38: {=SUMPRODUCT(P38:AA38/SUM(P38:AA38),$P$4:$AA$4)} -> 4.0666667
N39: BG_Symbol (2) | O39: =10000-SUM(P39:AA39) -> 9100 | P39: 350 | Q39: 250 | R39: 150 | S39: 150 | T39: 0 | U39: 0 | V39: 0 | W39: 0 | X39: 0 | Y39: 0 | Z39: 0 | AA39: 0 | AB39: {=SUMPRODUCT(P39:AA39/SUM(P39:AA39),$P$4:$AA$4)} -> 3.7777778
N40: BG_Symbol (3) | O40: =10000-SUM(P40:AA40) -> 9200 | P40: 400 | Q40: 300 | R40: 50 | S40: 50 | T40: 0 | U40: 0 | V40: 0 | W40: 0 | X40: 0 | Y40: 0 | Z40: 0 | AA40: 0 | AB40: {=SUMPRODUCT(P40:AA40/SUM(P40:AA40),$P$4:$AA$4)} -> 2.9375
I41: Eliminate Table Weight | N41: FG_Symbol | O41: =10000-SUM(P41:AA41) -> 6710 | P41: 2100 | Q41: 860 | R41: 220 | S41: 110 | T41: 0 | U41: 0 | V41: 0 | W41: 0 | X41: 0 | Y41: 0 | Z41: 0 | AA41: 0 | AB41: {=SUMPRODUCT(P41:AA41/SUM(P41:AA41),$P$4:$AA$4)} -> 2.662614
J42: A | K42: B | N42: FG_Symbol (2) | O42: =10000-SUM(P42:AA42) -> 6710 | P42: 2100 | Q42: 860 | R42: 220 | S42: 110 | T42: 0 | U42: 0 | V42: 0 | W42: 0 | X42: 0 | Y42: 0 | Z42: 0 | AA42: 0 | AB42: {=SUMPRODUCT(P42:AA42/SUM(P42:AA42),$P$4:$AA$4)} -> 2.662614
...

Sheet 工作表1
B2: 金框出現率(B1) | F2: =Parameter!L5+Parameter!L7 -> 0.85 | G2: =Parameter!L6 -> 0.15 | M2: PG | S2: OP (Simulator)
B3: Cnt | C3: PG | D3: OP B1 | E3: OP B2 | M3: 金框分布 | N3: BG | O3: FG | P3: FG10 | Q3: FG20 | S3: 金框分布 | T3: BG | U3: FG | V3: FG10 | W3: FG20 | Y3: B1 | Z3: B2 | AA3: FG
B4: 0 | C4: 0.12890728 | D4: 0.1798 | E4: 0 | F4: {=D4:D13*F2+E4:E13*G2} -> 0.15283 | G4: 0 | H4: {=G4:G13/10000} -> 0 | M4: 0 | N4: 0.12890728 | O4: 0.056827151 | P4: 0.12145749 | Q4: 0.14634146 | S4: 0 | T4: 0.14598407 | U4: 0 | V4: 0 | W4: 0
B5: 1 | C5: 0.30351325 | D5: 0.3534 | E5: 0 | F5: 0.30039 | G5: {=TRANSPOSE(Parameter!AD5:AL5)} -> 300 | H5: 0.03 | M5: 1 | N5: 0.30351325 | O5: 0.14601421 | P5: 0.22672065 | Q5: 0.3902439 | S5: 1 | T5: 0.28520794 | U5: 0 | V5: 0 | W5: 0 | Y5: {=TRANSPOSE(Parameter!AD5:AL5)} -> 300 | Z5: {=TRANSPOSE(Parameter!AD6:AL6)} -> 0 | AA5: {=TRANSPOSE(Parameter!AD8:AL8)} -> 0 | AC5: {=_xlfn.ANCHORARRAY(Y5)/10000} -> 0.03 | AD5: {=_xlfn.ANCHORARRAY(Z5)/10000} -> 0 | AE5: {=_xlfn.ANCHORARRAY(AA5)/10000} -> 0
B6: 2 | C6: 0.30338117 | D6: 0.2963 | E6: 0 | F6: 0.251855 | G6: 600 | H6: 0.06 | M6: 2 | N6: 0.30338117 | O6: 0.23993686 | P6: 0.25506073 | Q6: 0.26829268 | S6: 2 | T6: 0.23496146 | U6: 0 | V6: 0 | W6: 0 | Y6: 600 | Z6: 0 | AA6: 0 | AC6: 0.06 | AD6: 0 | AE6: 0
B7: 3 | C7: 0.18173814 | D7: 0.1327 | E7: 0.1796 | F7: 0.139735 | G7: 1080 | H7: 0.108 | M7: 3 | N7: 0.18173814 | O7: 0.24072612 | P7: 0.20647773 | Q7: 0.12195122 | S7: 3 | T7: 0.1397775 | U7: 0.15779349 | V7: 0.25674906 | W7: 0.33335772 | Y7: 1080 | Z7: 1050 | AA7: 525 | AC7: 0.108 | AD7: 0.105 | AE7: 0.0525
B8: 4 | C8: 0.063705204 | D8: 0.0333 | E8: 0.3822 | F8: 0.085635 | G8: 1440 | H8: 0.144 | M8: 4 | N8: 0.063705204 | O8: 0.17363852 | P8: 0.089068826 | Q8: 0.024390244 | S8: 4 | T8: 0.10258886 | U8: 0.38443021 | V8: 0.40096742 | W8: 0.42492251 | Y8: 1440 | Z8: 1400 | AA8: 700 | AC8: 0.144 | AD8: 0.14 | AE8: 0.07
B9: 5 | C9: 0.014748613 | D9: 0.0044 | E9: 0.2992 | F9: 0.04862 | G9: 2250 | H9: 0.225 | M9: 5 | N9: 0.014748613 | O9: 0.10023678 | P9: 0.076923077 | Q9: 0.048780488 | S9: 5 | T9: 0.06349186 | U9: 0.31827883 | V9: 0.24644354 | W9: 0.19506491 | Y9: 2250 | Z9: 1750 | AA9: 1750 | AC9: 0.225 | AD9: 0.175 | AE9: 0.175
B10: 6 | C10: 0.0036101083 | D10: 0.0002 | E10: 0.1134 | F10: 0.01718 | G10: 2700 | H10: 0.27 | M10: 6 | N10: 0.0036101083 | O10: 0.031570639 | P10: 0.012145749 | Q10: 0 | S10: 6 | T10: 0.02289639 | U10: 0.11316868 | V10: 0.078840214 | W10: 0.042010228 | Y10: 2700 | Z10: 2100 | AA10: 2100 | AC10: 0.27 | AD10: 0.21 | AE10: 0.21
B11: 7 | C11: 0.0003962314 | D11: 0 | E11: 0.023 | F11: 0.00345 | G11: 3150 | H11: 0.315 | M11: 7 | N11: 0.0003962314 | O11: 0.010260458 | P11: 0.012145749 | Q11: 0 | S11: 7 | T11: 0.00458445 | U11: 0.023555527 | V11: 0.015353056 | W11: 0.004321498 | Y11: 3150 | Z11: 3675 | AA11: 3675 | AC11: 0.315 | AD11: 0.3675 | AE11: 0.3675
B12: 8 | C12: 0 | D12: 0 | E12: 0.0024 | F12: 0.00036 | G12: 3600 | H12: 0.36 | M12: 8 | N12: 0 | O12: 0.00078926598 | P12: 0 | Q12: 0 | S12: 8 | T12: 0.00048207 | U12: 0.0026400349 | V12: 0.0016467046 | W12: 0.00032313684 | Y12: 3600 | Z12: 4200 | AA12: 4200 | AC12: 0.36 | AD12: 0.42 | AE12: 0.42
B13: 9 | C13: 0 | D13: 0 | E13: 0.0001 | F13: 1.5e-05 | G13: 4050 | H13: 0.405 | M13: 9 | N13: 0 | O13: 0 | P13: 0 | Q13: 0 | S13: 9 | T13: 2.54e-05 | U13: 0.00013323541 | V13: 0 | W13: 0 | Y13: 4050 | Z13: 4725 | AA13: 4725 | AC13: 0.405 | AD13: 0.4725 | AE13: 0.4725
M14: 平均數量 | N14: =SUMPRODUCT($M$4:$M$13,N4:N13) -> 1.8084882 | O14: =SUMPRODUCT($M$4:$M$13,O4:O13) -> 2.8113654 | P14: =SUMPRODUCT($M$4:$M$13,P4:P13) -> 2.2550607 | Q14: =SUMPRODUCT($M$4:$M$13,Q4:Q13) -> 1.6341463 | S14: 平均數量 | T14: =SUMPRODUCT($M$4:$M$13,T4:T13) -> 2.0758327 | U14: =SUMPRODUCT($M$4:$M$13,U4:U13) -> 4.4687156 | V14: =SUMPRODUCT($M$4:$M$13,V4:V13) -> 4.2000209 | W14: =SUMPRODUCT($M$4:$M$13,W4:W13) -> 3.9599847
G15: Special Appear | T15: {=T14:W14/N14:Q14} -> 1.1478277 | U15: 1.5895179 | V15: 1.8624868 | W15: 2.4232742 | AB15: Special Trigger Rate | AC15: =SUMPRODUCT(T5:T13,AC5:AC13) -> 0.074618319 | AD15: =SUMPRODUCT(U5:U13,AD5:AD13) -> 0.15968119 | AE15: =SUMPRODUCT(U5:U13,AE5:AE13) -> 0.12448691
G16: =SUMPRODUCT(H4:H13,D4:D13) -> 0.0485508 | H16: =1/G16 -> 20.596983 | AC16: {=1-AC15:AE15} -> 0.92538168 | AD16: 0.84031881 | AE16: 0.87551309
B17: 倍數出現率 | M17: PG | S17: OP | Y17: B1 | AC17: B2 | AG17: FG
C18: PG | D18: OP B1 | E18: OP B2 | G18: Special | H18: Normal | M18: 倍數分布 | N18: BG | O18: FG | S18: 倍數分布 | T18: BG | U18: B1 | V18: B2 | W18: FG | Y18: Special | Z18: Normal | AC18: Special | AD18: Normal | AG18: Special | AH18: Normal
B19: 0 | C19: 0.86973562 | D19: {=K19:K31} -> 0 | E19: {=L19:L31} -> 0 | G19: {=TRANSPOSE(Parameter!O5:AA5)} -> 0 | H19: {=TRANSPOSE(Parameter!O17:AA17)} -> 0 | I19: {=_xlfn.ANCHORARRAY(G19)/SUM(_xlfn.ANCHORARRAY(G19))*G16} -> 0 | J19: {=_xlfn.ANCHORARRAY(H19)/SUM(_xlfn.ANCHORARRAY(H19))*(1-G16)} -> 0 | K19: {=J19:J23} -> 0 | M19: 0 | N19: 0.86973562 | O19: 0.64345873 | S19: 0 | T19: {=_xlfn.ANCHORARRAY(U19)*U33+_xlfn.ANCHORARRAY(V19)*V33} -> 0.63909172 | U19: {=_xlfn.ANCHORARRAY(AA19)} -> 0.78657443 | V19: {=_xlfn.ANCHORARRAY(AE19)} -> 0 | W19: {=_xlfn.ANCHORARRAY(AI19)} -> 0 | Y19: {=TRANSPOSE(Parameter!O5:AA5)} -> 0 | Z19: {=TRANSPOSE(Parameter!O38:AA38)} -> 8500 | AA19: {=_xlfn.ANCHORARRAY(Y19)*AC15/SUM(_xlfn.ANCHORARRAY(Y19))+_xlfn.ANCHORARRAY(Z19)*AC16/SUM(_xlfn.ANCHORARRAY(Z19))} -> 0.78657443 | AC19: {=TRANSPOSE(Parameter!O6:AA6)} -> 0 | AD19: {=TRANSPOSE(Parameter!O17:AA17)} -> 0 | AE19: {=_xlfn.ANCHORARRAY(AC19)*AD15/SUM(_xlfn.ANCHORARRAY(AC19))+_xlfn.ANCHORARRAY(AD19)*AD16/SUM(_xlfn.ANCHORARRAY(AD19))} -> 0 | AG19: {=TRANSPOSE(Parameter!O8:AA8)} -> 0 | AH19: {=TRANSPOSE(Parameter!O19:AA19)} -> 0 | AI19: {=_xlfn.ANCHORARRAY(AG19)*AE15/SUM(_xlfn.ANCHORARRAY(AG19))+_xlfn.ANCHORARRAY(AH19)*AE16/SUM(_xlfn.ANCHORARRAY(AH19))} -> 0 | AO19: 50 | AP19: 50 | AQ19: 250 | AR19: 1500 | AS19: 4000 | AT19: 4000 | AU19: 4000 | AV19: 4000 | AW19: 4000
B20: 2 | C20: 0.034690102 | D20: 0.39960866 | E20: 0 | G20: 0 | H20: 4200 | I20: 0 | J20: 0.39960866 | K20: 0.39960866 | M20: 2 | N20: 0.034690102 | O20: 0.21617069 | S20: 2 | T20: 0.10376874 | U20: 0.046269084 | V20: 0.3529339 | W20: 0.55157324 | Y20: 0 | Z20: 500 | AA20: 0.046269084 | AC20: 0 | AD20: 4200 | AE20: 0.3529339 | AG20: 0 | AH20: 6300 | AI20: 0.55157324
B21: 3 | C21: 0.028506743 | D21: 0.32349273 | E21: 0 | G21: 0 | H21: 3400 | I21: 0 | J21: 0.32349273 | K21: 0.32349273 | M21: 3 | N21: 0.028506743 | O21: 0.085906794 | S21: 3 | T21: 0.083645229 | U21: 0.037015267 | V21: 0.2857084 | W21: 0.24514366 | Y21: 0 | Z21: 400 | AA21: 0.037015267 | AC21: 0 | AD21: 3400 | AE21: 0.2857084 | AG21: 0 | AH21: 2800 | AI21: 0.24514366 | AN21: 300 | AO21: {=Parameter!AD4:AL4*AN21} -> 300 | AP21: 600 | AQ21: 900 | AR21: 1200 | AS21: 1500 | AT21: 1800 | AU21: 2100 | AV21: 2400 | AW21: 2700
B22: 5 | C22: 0.019109986 | D22: 0.1141739 | E22: 0 | G22: 0 | H22: 1200 | I22: 0 | J22: 0.1141739 | K22: 0.1141739 | M22: 5 | N22: 0.019109986 | O22: 0.02189781 | S22: 5 | T22: 0.041463352 | U22: 0.02776145 | V22: 0.10083826 | W22: 0.052530785 | Y22: 0 | Z22: 300 | AA22: 0.02776145 | AC22: 0 | AD22: 1200 | AE22: 0.10083826 | AG22: 0 | AH22: 600 | AI22: 0.052530785 | AO22: 1 | AP22: 1 | AQ22: 1.2 | AR22: 1.2 | AS22: 1.5 | AT22: 1.5 | AU22: 1.5 | AV22: 1.5 | AW22: 1.5
B23: 8 | C23: 0.018111885 | D23: 0.1141739 | E23: 0 | G23: 0 | H23: 1200 | I23: 0 | J23: 0.1141739 | K23: 0.1141739 | M23: 8 | N23: 0.018111885 | O23: 0.010668164 | S23: 8 | T23: 0.041463352 | U23: 0.02776145 | V23: 0.10083826 | W23: 0.026265393 | Y23: 0 | Z23: 300 | AA23: 0.02776145 | AC23: 0 | AD23: 1200 | AE23: 0.10083826 | AG23: 0 | AH23: 300 | AI23: 0.026265393 | AO23: {=INT(AO21:AW21*AO22:AW22)} -> 300 | AP23: 600 | AQ23: 1080 | AR23: 1440 | AS23: 2250 | AT23: 2700 | AU23: 3150 | AV23: 3600 | AW23: 4050
B24: 10 | C24: 0.014849798 | D24: 0.020100031 | E24: 0 | G24: 4140 | H24: 0 | I24: 0.020100031 | J24: 0 | K24: {=I24:I31} -> 0.020100031 | M24: 10 | N24: 0.014849798 | O24: 0.010106682 | S24: 10 | T24: 0.039980028 | U24: 0.030891984 | V24: 0.07936155 | W24: 0.054400781 | Y24: 4140 | Z24: 0 | AA24: 0.030891984 | AC24: 4970 | AD24: 0 | AE24: 0.07936155 | AG24: 4370 | AH24: 0 | AI24: 0.054400781
B25: 15 | C25: 0.0087881591 | D25: 0.01456524 | E25: 0 | G25: 3000 | H25: 0 | I25: 0.01456524 | J25: 0 | K25: 0.01456524 | M25: 15 | N25: 0.0087881591 | O25: 0.0058955643 | S25: 15 | T25: 0.027170282 | U25: 0.022385496 | V25: 0.047904356 | W25: 0.033611467 | Y25: 3000 | Z25: 0 | AA25: 0.022385496 | AC25: 3000 | AD25: 0 | AE25: 0.047904356 | AG25: 2700 | AH25: 0 | AI25: 0.033611467
B26: 20 | C26: 0.0045523151 | D26: 0.00971016 | E26: 0 | G26: 2000 | H26: 0 | I26: 0.00971016 | J26: 0 | K26: 0.00971016 | M26: 20 | N26: 0.0045523151 | O26: 0.0028074116 | S26: 20 | T26: 0.016167407 | U26: 0.014923664 | V26: 0.02155696 | W26: 0.017428168 | Y26: 2000 | Z26: 0 | AA26: 0.014923664 | AC26: 1350 | AD26: 0 | AE26: 0.02155696 | AG26: 1400 | AH26: 0 | AI26: 0.017428168 | AN26: 350 | AO26: {=Parameter!AD4:AL4*AN26} -> 350 | AP26: 700 | AQ26: 1050 | AR26: 1400 | AS26: 1750 | AT26: 2100 | AU26: 2450 | AV26: 2800 | AW26: 3150
B27: 25 | C27: 0.0013876041 | D27: 0.00242754 | E27: 0 | G27: 500 | H27: 0 | I27: 0.00242754 | J27: 0 | K27: 0.00242754 | M27: 25 | N27: 0.0013876041 | O27: 0.00056148231 | S27: 25 | T27: 0.0045283804 | U27: 0.003730916 | V27: 0.0079840593 | W27: 0.0033611467 | Y27: 500 | Z27: 0 | AA27: 0.003730916 | AC27: 500 | AD27: 0 | AE27: 0.0079840593 | AG27: 270 | AH27: 0 | AI27: 0.0033611467 | AO27: 0 | AP27: 0 | AQ27: 1 | AR27: 1 | AS27: 1 | AT27: 1 | AU27: 1.5 | AV27: 1.5 | AW27: 1.5
B28: 35 | C28: 0.00019475145 | D28: 0.0002913048 | E28: 0 | G28: 60 | H28: 0 | I28: 0.0002913048 | J28: 0 | K28: 0.0002913048 | M28: 35 | N28: 0.00019475145 | O28: 0.00056148231 | S28: 35 | T28: 0.00045358497 | U28: 0.00044770992 | V28: 0.00047904356 | W28: 0.0033611467 | Y28: 60 | Z28: 0 | AA28: 0.00044770992 | AC28: 30 | AD28: 0 | AE28: 0.00047904356 | AG28: 270 | AH28: 0 | AI28: 0.0033611467 | AO28: {=INT(_xlfn.ANCHORARRAY(AO26)*AO27:AW27)} -> 0 | AP28: 0 | AQ28: 1050 | AR28: 1400 | AS28: 1750 | AT28: 2100 | AU28: 3675 | AV28: 4200 | AW28: 4725
B29: 50 | C29: 2.4343931e-05 | D29: 0.0005826096 | E29: 0 | G29: 120 | H29: 0 | I29: 0.0005826096 | J29: 0 | K29: 0.0005826096 | M29: 50 | N29: 2.4343931e-05 | O29: 0.00084222347 | S29: 50 | T29: 0.00090716995 | U29: 0.00089541983 | V29: 0.00095808712 | W29: 0.0044815289 | Y29: 120 | Z29: 0 | AA29: 0.00089541983 | AC29: 60 | AD29: 0 | AE29: 0.00095808712 | AG29: 360 | AH29: 0 | AI29: 0.0044815289
B30: 80 | C30: 4.8687862e-05 | D30: 0.0002913048 | E30: 0 | G30: 60 | H30: 0 | I30: 0.0002913048 | J30: 0 | K30: 0.0002913048 | M30: 80 | N30: 4.8687862e-05 | O30: 0.00084222347 | S30: 80 | T30: 0.00045358497 | U30: 0.00044770992 | V30: 0.00047904356 | W30: 0.0033611467 | Y30: 60 | Z30: 0 | AA30: 0.00044770992 | AC30: 30 | AD30: 0 | AE30: 0.00047904356 | AG30: 270 | AH30: 0 | AI30: 0.0033611467
B31: 100 | C31: 0 | D31: 0.0005826096 | E31: 0 | G31: 120 | H31: 0 | I31: 0.0005826096 | J31: 0 | K31: 0.0005826096 | M31: 100 | N31: 0 | O31: 0.00028074116 | S31: 100 | T31: 0.00090716995 | U31: 0.00089541983 | V31: 0.00095808712 | W31: 0.0044815289 | Y31: 120 | Z31: 0 | AA31: 0.00089541983 | AC31: 60 | AD31: 0 | AE31: 0.00095808712 | AG31: 360 | AH31: 0 | AI31: 0.0044815289
C32: =SUMPRODUCT(C19:C31,B19:B31) -> 0.81333074 | D32: =SUMPRODUCT(D19:D31,B19:B31) -> 4.0492184 | M32: 平均倍數 | N32: =SUMPRODUCT($M$19:$M$31, N19:N31) -> 0.81333074 | O32: =SUMPRODUCT($M$19:$M$31, O19:O31) -> 1.3017967 | S32: 平均倍數 | U32: =SUMPRODUCT($M$20:$M$31, U20:U31) -> 1.7867309 | V32: =SUMPRODUCT($M$20:$M$31, V20:V31) -> 5.2156149 | W32: =SUMPRODUCT($M$19:$M$31, W19:W31) -> 4.8508876
U33: =Parameter!J5/SUM(Parameter!J5:J6) -> 0.8125 | V33: =Parameter!J6/SUM(Parameter!J5:J6) -> 0.1875
C34: =1/SUM(C24:C31) -> 33.50571 | D34: =1/SUM(D24:D31) -> 20.596983
Q37: {=TRANSPOSE(M19:M31)} -> 0 | R37: 2 | S37: 3 | T37: 5 | U37: 8 | V37: 10 | W37: 15 | X37: 20 | Y37: 25 | Z37: 35 | AA37: 50 | AB37: 80 | AC37: 100
Q38: {=TRANSPOSE(Q19:Q31)} -> 0 | R38: 0 | S38: 0 | T38: 0 | U38: 0 | V38: 0 | W38: 0 | X38: 0 | Y38: 0 | Z38: 0 | AA38: 0 | AB38: 0 | AC38: 0
V39: 5000 | W39: 3000 | X39: 1500 | Y39: 500 | Z39: 65 | AA39: 30 | AB39: 30 | AC39: 30
Q42: {=TRANSPOSE(Q19:Q31)} -> 0 | R42: 0 | S42: 0 | T42: 0 | U42: 0 | V42: 0 | W42: 0 | X42: 0 | Y42: 0 | Z42: 0 | AA42: 0 | AB42: 0 | AC42: 0
B67: 金框出現率(F2)
B68: Cnt | C68: PG | D68: OP
B69: 0 | C69: 0.056827151 | D69: 0 | H69: 0
...

Sheet Multiplier_Weight
C2: Newbie | D2: Newbie | E2: Oldhand | F2: Oldhand | G2: Oldhand
B3: Range | C3: Weight_BG | D3: Weight_FG | E3: Weight_BG | F3: Weight_FG | G3: Weight_BF
B4: (-1, 0] | C4: {=IFERROR(Multiplier_Weight_Newbie!$L$15:$L$79, 0)} -> 722907411 | D4: {=IFERROR(Multiplier_Weight_Newbie!$L$87:$L$150, 0)} -> 0 | E4: {=_xlfn.ANCHORARRAY(Multiplier_Weight_Oldhand!L15)} -> 722907411 | F4: {=_xlfn.ANCHORARRAY(Multiplier_Weight_Oldhand!L87)} -> 0 | G4: {=_xlfn.ANCHORARRAY(Multiplier_Weight_Oldhand!L157)} -> 0
B5: (0, 1] | C5: 161351627 | D5: 0 | E5: 161351627 | F5: 0 | G5: 0
B6: (1, 2] | C6: 45754318 | D6: 0 | E6: 45754318 | F6: 0 | G6: 0
B7: (2, 3] | C7: 21756756 | D7: 0 | E7: 21756756 | F7: 0 | G7: 0
B8: (3, 4] | C8: 8506399 | D8: 0 | E8: 8506399 | F8: 0 | G8: 0
B9: (4, 5] | C9: 6669454 | D9: 0 | E9: 6669454 | F9: 0 | G9: 0
B10: (5, 6] | C10: 5453883 | D10: 0 | E10: 5453883 | F10: 0 | G10: 0
B11: (6, 7] | C11: 3331650 | D11: 0 | E11: 3331650 | F11: 0 | G11: 0
B12: (7, 8] | C12: 2815459 | D12: 0 | E12: 2815459 | F12: 0 | G12: 0
B13: (8, 9] | C13: 2544451 | D13: 0 | E13: 2544451 | F13: 0 | G13: 0
B14: (9, 10] | C14: 2271743 | D14: 0 | E14: 2271743 | F14: 0 | G14: 0
B15: (10, 15] | C15: 3023686 | D15: 131266259 | E15: 3023686 | F15: 131266259 | G15: 117561927
B16: (15, 20] | C16: 3964399 | D16: 131252488 | E16: 3964399 | F16: 131252488 | G16: 117549593
... B67: (100000, 9999999] | C67: 0 | D67: 0 | E67: 0 | F67: 0 | G67: 0
B68: Free Game | C68: 4173600 | E68: 4173600

Sheet Multiplier_Weight_Newbie
A2: Threshold | B2: 1000000000
A3: Coin in | B3: =Overview!A7 -> 100
C5: RTP
B6: Bet | C6: Base Game | D6: Free Game | E6: Total | F6: Hit Rate | G6: FG Period | H6: Avg Multi
A7: Normal Bet | B7: {=Overview!B11:B12} -> 1 | C7: =SUM(N15:N79) -> 0.67999969 | D7: =SUM(_xlfn.ANCHORARRAY(N87))*M79 -> 0.24000022 | E7: =SUM(C7:D7) -> 0.9199999 | F7: =M79 -> 0.0041738387 | G7: =1/F7 -> 239.5876 | H7: =D7*G7 -> 57.501077
B8: 75
A11: Base Game
A13: Simulator | B13: =Multiplier_Weight_Oldhand!B13 -> 1000000000 | H13: Calculate
A14: Lower | B14: Upper | C14: Cnt | D14: Pay | E14: Hit Rate | F14: Avg. Multi. | H14: Range | I14: Fix Num | J14: Fix Rate | K14: Final Rate | L14: Weight | M14: Hit Rate | N14: Simulator RTP | O14: 1.1
A15: -1 | B15: 0 | C15: {=Multiplier_Weight_Oldhand!C15:D78} -> 711529928 | D15: 0 | E15: {=_xlfn.LET(_xlpm.x, C15:C78, _xlpm.x/SUM(_xlpm.x))} -> 0.71313898 | F15: {=_xlfn.LET(_xlpm.x, D15:D80/C15:C80/B3, IF(ISERR(_xlpm.x), 0, _xlpm.x))} -> 0 | H15: ="("&$A15&", "&$B15&"]" -> (-1, 0] | I15: 1 | J15: {=E15:E79*I15:I79} -> 0.71313898 | K15: {=J15:J78/SUM(_xlfn.ANCHORARRAY(J15))} -> 0.72290741 | L15: {=INT(K15:K79*$B$2)} -> 722907411 | M15: {=_xlfn.LET(_xlpm.x, L15:L79, _xlpm.x/SUM(_xlpm.x))} -> 0.72294875 | N15: {=M15:M79*F15:F79} -> 0 | O15: {=I15:I78*O14} -> 1.1
A16: 0 | B16: 1 | C16: 170765800 | D16: 7155857500 | E16: 0.17115197 | F16: 0.41904512 | H16: ="("&$A16&", "&$B16&"]" -> (0, 1] | I16: 0.93 | J16: 0.15917133 | K16: 0.16135163 | L16: 161351627 | M16: 0.16136085 | N16: 0.067617478 | O16: 1.023
A17: 1 | B17: 2 | C17: 39160186 | D17: 5836620540 | E17: 0.039248743 | F17: 1.4904476 | H17: ="("&$A17&", "&$B17&"]" -> (1, 2] | I17: 1.15 | J17: 0.045136054 | K17: 0.045754319 | L17: 45754318 | M17: 0.045756935 | N17: 0.068198314 | O17: 1.265
A18: 2 | B18: 3 | C18: 17995242 | D18: 4540935295 | E18: 0.018035936 | F18: 2.5234089 | H18: ="("&$A18&", "&$B18&"]" -> (2, 3] | I18: 1.19 | J18: 0.021462764 | K18: 0.021756757 | L18: 21756756 | M18: 0.021758 | N18: 0.05490433 | O18: 1.309
A19: 3 | B19: 4 | C19: 8813181 | D19: 3144768180 | E19: 0.0088331111 | F19: 3.5682555 | H19: ="("&$A19&", "&$B19&"]" -> (3, 4] | I19: 0.95 | J19: 0.0083914555 | K19: 0.0085064 | L19: 8506399 | M19: 0.0085068855 | N19: 0.030354741 | O19: 1.045
A20: 4 | B20: 5 | C20: 5967716 | D20: 2740547905 | E20: 0.0059812113 | F20: 4.5922894 | H20: ="("&$A20&", "&$B20&"]" -> (4, 5] | I20: 1.1 | J20: 0.0065793325 | K20: 0.0066694549 | L20: 6669454 | M20: 0.0066698354 | N20: 0.030629815 | O20: 1.21
A21: 5 | B21: 6 | C21: 4588075 | D21: 2565747500 | E21: 0.0045984504 | F21: 5.5922092 | H21: ="("&$A21&", "&$B21&"]" -> (5, 6] | I21: 1.17 | J21: 0.005380187 | K21: 0.0054538837 | L21: 5453883 | M21: 0.0054541949 | N21: 0.030500999 | O21: 1.287
A22: 6 | B22: 7 | C22: 2981105 | D22: 1957208220 | E22: 0.0029878464 | F22: 6.5653783 | H22: ="("&$A22&", "&$B22&"]" -> (6, 7] | I22: 1.1 | J22: 0.0032866311 | K22: 0.0033316507 | L22: 3331650 | M22: 0.0033318405 | N22: 0.021874794 | O22: 1.21
A23: 7 | B23: 8 | C23: 3079054 | D23: 2346593790 | E23: 0.0030860169 | F23: 7.6211518 | H23: ="("&$A23&", "&$B23&"]" -> (7, 8] | I23: 0.9 | J23: 0.0027774153 | K23: 0.0028154597 | L23: 2815459 | M23: 0.00281562 | N23: 0.021458267 | O23: 0.99
A24: 8 | B24: 9 | C24: 2276732 | D24: 1957651370 | E24: 0.0022818806 | F24: 8.5985148 | H24: ="("&$A24&", "&$B24&"]" -> (8, 9] | I24: 1.1 | J24: 0.0025100686 | K24: 0.0025444511 | L24: 2544451 | M24: 0.0025445965 | N24: 0.021879751 | O24: 1.21
A25: 9 | B25: 10 | C25: 2032718 | D25: 1959914600 | E25: 0.0020373148 | F25: 9.6418421 | H25: ="("&$A25&", "&$B25&"]" -> (9, 10] | I25: 1.1 | J25: 0.0022410463 | K25: 0.0022717437 | L25: 2271743 | M25: 0.0022718729 | N25: 0.02190504 | O25: 1.21
A26: 10 | B26: 15 | C26: 6889116 | D26: 8548091680 | E26: 0.006904695 | F26: 12.408111 | G26: =SUM($L$15:L25)-1000 -> 983362151 | H26: ="("&$A26&", "&$B26&"]" -> (10, 15] | I26: 0.432 | J26: 0.0029828282 | K26: 0.0030236864 | L26: 3023686 | M26: 0.0030238589 | N26: 0.037520377 | O26: 0.4752
A27: 15 | B27: 20 | C27: 4433090 | D27: 7740661305 | E27: 0.004443115 | F27: 17.461097 | G27: =SUM($L$15:L26)-1000 -> 986385837 | H27: ="("&$A27&", "&$B27&"]" -> (15, 20] | I27: 0.8802 | J27: 0.0039108298 | K27: 0.0039643996 | L27: 3964399 | M27: 0.0039646257 | N27: 0.069226713 | O27: 0.96822
A28: 20 | B28: 25 | C28: 2968477 | D28: 6681354435 | E28: 0.0029751899 | F28: 22.507685 | G28: =SUM($L$15:L27)-1000 -> 990350236 | H28: ="("&$A28&", "&$B28&"]" -> (20, 25] | I28: 0.549 | J28: 0.0016333793 | K28: 0.001655753 | L28: 1655752 | M28: 0.0016558467 | N28: 0.037269275 | O28: 0.6039
A29: 25 | B29: 30 | C29: 2276941 | D29: 6265204430 | E29: 0.0022820901 | F29: 27.515884 | G29: =SUM($L$15:L28)-1000 -> 992005988 | H29: ="("&$A29&", "&$B29&"]" -> (25, 30] | I29: 0.29 | J29: 0.00066180612 | K29: 0.0006708714 | L29: 670871 | M29: 0.00067090937 | N29: 0.018460664 | O29: 0.319
A30: 30 | B30: 35 | C30: 1643818 | D30: 5344731840 | E30: 0.0016475353 | F30: 32.514134 | G30: =SUM($L$15:L29)-1000 -> 992676859 | H30: ="("&$A30&", "&$B30&"]" -> (30, 35] | I30: 0.34 | J30: 0.00056016201 | K30: 0.000567835 | L30: 567834 | M30: 0.00056786647 | N30: 0.018463686 | O30: 0.374
A31: 35 | B31: 40 | C31: 1366895 | D31: 5130263290 | E31: 0.0013699861 | F31: 37.532241 | G31: =SUM($L$15:L30)-1000 -> 993244693 | H31: ="("&$A31&", "&$B31&"]" -> (35, 40] | I31: 0.7 | J31: 0.00095899026 | K31: 0.00097212632 | L31: 972126 | M31: 0.00097218159 | N31: 0.036488154 | O31: 0.77
A32: 40 | B32: 45 | C32: 1095439 | D32: 4665871255 | E32: 0.0010979162 | F32: 42.59362 | G32: =SUM($L$15:L31)-1000 -> 994216819 | H32: ="("&$A32&", "&$B32&"]" -> (40, 45] | I32: 0.2 | J32: 0.00021958324 | K32: 0.00022259105 | L32: 222591 | M32: 0.00022260373 | N32: 0.0094814987 | O32: 0.22
A33: 45 | B33: 50 | C33: 870009 | D33: 4140550785 | E33: 0.00087197643 | F33: 47.592045 | G33: =SUM($L$15:L32)-1000 -> 994439410 | H33: ="("&$A33&", "&$B33&"]" -> (45, 50] | I33: 0.24 | J33: 0.00020927434 | K33: 0.00021214094 | L33: 212140 | M33: 0.00021215213 | N33: 0.010096754 | O33: 0.264
A34: 50 | B34: 60 | C34: 1399811 | D34: 7676767230 | E34: 0.0014029765 | F34: 54.841455 | G34: =SUM($L$15:L33)-1000 -> 994651550 | H34: ="("&$A34&", "&$B34&"]" -> (50, 60] | I34: 0.437893 | J34: 0.0006143536 | K34: 0.00062276889 | L34: 622768 | M34: 0.00062280362 | N34: 0.034155457 | O34: 0.4816823
A35: 60 | B35: 70 | C35: 989448 | D35: 6424961185 | E35: 0.00099168553 | F35: 64.934804 | H35: ="("&$A35&", "&$B35&"]" -> (60, 70] | I35: 0.15 | J35: 0.00014875283 | K35: 0.00015079042 | L35: 150790 | M35: 0.00015079862 | N35: 0.009792079 | O35: 0.165
A36: 70 | B36: 80 | C36: 751643 | D36: 5635089920 | E36: 0.00075334276 | F36: 74.970297 | H36: ="("&$A36&", "&$B36&"]" -> (70, 80] | I36: 0.17 | J36: 0.00012806827 | K36: 0.00012982252 | L36: 129822 | M36: 0.00012982942 | N36: 0.0097333505 | O36: 0.187
A37: 80 | B37: 90 | C37: 580230 | D37: 4930863345 | E37: 0.00058154213 | F37: 84.981186 | H37: ="("&$A37&", "&$B37&"]" -> (80, 90] | I37: 0.19 | J37: 0.000110493 | K37: 0.00011200652 | L37: 112006 | M37: 0.00011201241 | N37: 0.009518947 | O37: 0.209
A38: 90 | B38: 100 | C38: 453118 | D38: 4304879505 | E38: 0.00045414268 | F38: 95.005705 | H38: ="("&$A38&", "&$B38&"]" -> (90, 100] | I38: 0.22 | J38: 9.9911389e-05 | K38: 0.00010127996 | L38: 101279 | M38: 0.00010128479 | N38: 0.0096226331 | O38: 0.242
A39: 100 | B39: 120 | C39: 690338 | D39: 7554624580 | E39: 0.00069189913 | F39: 109.43371 | H39: ="("&$A39&", "&$B39&"]" -> (100, 120] | I39: 0 | J39: 0 | K39: 0 | L39: 0 | M39: 0 | N39: 0 | O39: 0
A40: 120 | B40: 140 | C40: 464085 | D40: 6016167965 | E40: 0.00046513448 | F40: 129.63504 | H40: ="("&$A40&", "&$B40&"]" -> (120, 140] | I40: 0 | J40: 0 | K40: 0 | L40: 0 | M40: 0 | N40: 0 | O40: 0
A41: 140 | B41: 160 | C41: 337004 | D41: 5047742710 | E41: 0.0003377661 | F41: 149.78287 | H41: ="("&$A41&", "&$B41&"]" -> (140, 160] | I41: 0 | J41: 0 | K41: 0 | L41: 0 | M41: 0 | N41: 0 | O41: 0
A42: 160 | B42: 180 | C42: 247756 | D42: 4204937895 | E42: 0.00024831627 | F42: 169.72093 | H42: ="("&$A42&", "&$B42&"]" -> (160, 180] | I42: 0 | J42: 0 | K42: 0 | L42: 0 | M42: 0 | N42: 0 | O42: 0
A43: 180 | B43: 200 | C43: 183724 | D43: 3486545350 | E43: 0.00018413947 | F43: 189.77082 | H43: ="("&$A43&", "&$B43&"]" -> (180, 200] | I43: 0 | J43: 0 | K43: 0 | L43: 0 | M43: 0 | N43: 0 | O43: 0
A44: 200 | B44: 250 | C44: 309801 | D44: 6896112120 | E44: 0.00031050158 | F44: 222.59812 | H44: ="("&$A44&", "&$B44&"]" -> (200, 250] | I44: 0 | J44: 0 | K44: 0 | L44: 0 | M44: 0 | N44: 0 | O44: 0
A45: 250 | B45: 300 | C45: 182313 | D45: 4972314355 | E45: 0.00018272528 | F45: 272.73504 | H45: ="("&$A45&", "&$B45&"]" -> (250, 300] | I45: 0 | J45: 0 | K45: 0 | L45: 0 | M45: 0 | N45: 0 | O45: 0
...

Sheet Multiplier_Weight_Oldhand
A2: Threshold | B2: 1000000000
A3: Coin in | B3: =Overview!A7 -> 100
C5: RTP
B6: Bet | C6: Base Game | D6: Free Game | E6: Total | F6: Hit Rate | G6: FG Period | H6: Avg Multi
A7: Normal Bet | B7: {=Overview!B11:B12} -> 1 | C7: =SUM(N15:N79) -> 0.67999969 | D7: =SUM(_xlfn.ANCHORARRAY(N87))*M79 -> 0.24000022 | E7: =SUM(C7:D7) -> 0.9199999 | F7: =M79 -> 0.0041738387 | G7: =1/F7 -> 239.5876 | H7: =D7*G7 -> 57.501077
A8: Buy Feature | B8: 75 | C8: =N80 -> 0 | D8: =SUM(_xlfn.ANCHORARRAY(N157))/B8 -> 0.925 | E8: =SUM(C8:D8) -> 0.925 | F8: =E80 -> 1 | G8: =1/F8 -> 1 | H8: =D8*G8*B8 -> 69.375
A11: Base Game
A13: Simulator | B13: 1000000000 | H13: Calculate | P13: Compare
A14: Lower | B14: Upper | C14: Cnt | D14: Pay | E14: Hit Rate | F14: Avg. Multi. | H14: Range | I14: Fix Num | J14: Fix Rate | K14: Final Rate | L14: Weight | M14: Hit Rate | N14: Simulator RTP | O14: 0.9 | P14: 目前 | Q14: 墨西哥狂歡 | R14: 差異 | T14: Fix Num A | U14: Fix Num B
A15: -1 | B15: 0 | C15: 711529928 | D15: 0 | E15: {=_xlfn.LET(_xlpm.x, C15:C78, _xlpm.x/SUM(_xlpm.x))} -> 0.71313898 | F15: {=_xlfn.LET(_xlpm.x, D15:D80/C15:C80/B3, IF(ISERR(_xlpm.x), 0, _xlpm.x))} -> 0 | H15: ="("&$A15&", "&$B15&"]" -> (-1, 0] | I15: 1 | J15: {=E15:E79*I15:I79} -> 0.71313898 | K15: {=J15:J78/SUM(_xlfn.ANCHORARRAY(J15))} -> 0.72290741 | L15: {=INT(K15:K79*$B$2)} -> 722907411 | M15: {=_xlfn.LET(_xlpm.x, L15:L79, _xlpm.x/SUM(_xlpm.x))} -> 0.72294875 | N15: {=M15:M79*F15:F79} -> 0 | O15: {=I15:I78*O14} -> 0.9 | P15: {=M15:M78} -> 0.72294875 | Q15: 0.72554635 | R15: {=_xlfn.LET(_xlpm.x, Q15:Q78/M15:M78, IF(ISERR(_xlpm.x), 0, ROUND(_xlpm.x,2)))} -> 1
A16: 0 | B16: 1 | C16: 170765800 | D16: 7155857500 | E16: 0.17115197 | F16: 0.41904512 | H16: ="("&$A16&", "&$B16&"]" -> (0, 1] | I16: 0.93 | J16: 0.15917133 | K16: 0.16135163 | L16: 161351627 | M16: 0.16136085 | N16: 0.067617478 | O16: 0.837 | P16: 0.16136085 | Q16: 0.15905886 | R16: 0.99
A17: 1 | B17: 2 | C17: 39160186 | D17: 5836620540 | E17: 0.039248743 | F17: 1.4904476 | H17: ="("&$A17&", "&$B17&"]" -> (1, 2] | I17: 1.15 | J17: 0.045136054 | K17: 0.045754319 | L17: 45754318 | M17: 0.045756935 | N17: 0.068198314 | O17: 1.035 | P17: 0.045756935 | Q17: 0.049788509 | R17: 1.09
A18: 2 | B18: 3 | C18: 17995242 | D18: 4540935295 | E18: 0.018035936 | F18: 2.5234089 | H18: ="("&$A18&", "&$B18&"]" -> (2, 3] | I18: 1.19 | J18: 0.021462764 | K18: 0.021756757 | L18: 21756756 | M18: 0.021758 | N18: 0.05490433 | O18: 1.071 | P18: 0.021758 | Q18: 0.021457526 | R18: 0.99
A19: 3 | B19: 4 | C19: 8813181 | D19: 3144768180 | E19: 0.0088331111 | F19: 3.5682555 | H19: ="("&$A19&", "&$B19&"]" -> (3, 4] | I19: 0.95 | J19: 0.0083914555 | K19: 0.0085064 | L19: 8506399 | M19: 0.0085068855 | N19: 0.030354741 | O19: 0.855 | P19: 0.0085068855 | Q19: 0.0094289743 | R19: 1.11
A20: 4 | B20: 5 | C20: 5967716 | D20: 2740547905 | E20: 0.0059812113 | F20: 4.5922894 | H20: ="("&$A20&", "&$B20&"]" -> (4, 5] | I20: 1.1 | J20: 0.0065793325 | K20: 0.0066694549 | L20: 6669454 | M20: 0.0066698354 | N20: 0.030629815 | O20: 0.99 | P20: 0.0066698354 | Q20: 0.0062566091 | R20: 0.94
A21: 5 | B21: 6 | C21: 4588075 | D21: 2565747500 | E21: 0.0045984504 | F21: 5.5922092 | H21: ="("&$A21&", "&$B21&"]" -> (5, 6] | I21: 1.17 | J21: 0.005380187 | K21: 0.0054538837 | L21: 5453883 | M21: 0.0054541949 | N21: 0.030500999 | O21: 1.053 | P21: 0.0054541949 | Q21: 0.0053753965 | R21: 0.99
A22: 6 | B22: 7 | C22: 2981105 | D22: 1957208220 | E22: 0.0029878464 | F22: 6.5653783 | H22: ="("&$A22&", "&$B22&"]" -> (6, 7] | I22: 1.1 | J22: 0.0032866311 | K22: 0.0033316507 | L22: 3331650 | M22: 0.0033318405 | N22: 0.021874794 | O22: 0.99 | P22: 0.0033318405 | Q22: 0.0025114558 | R22: 0.75
A23: 7 | B23: 8 | C23: 3079054 | D23: 2346593790 | E23: 0.0030860169 | F23: 7.6211518 | H23: ="("&$A23&", "&$B23&"]" -> (7, 8] | I23: 0.9 | J23: 0.0027774153 | K23: 0.0028154597 | L23: 2815459 | M23: 0.00281562 | N23: 0.021458267 | O23: 0.81 | P23: 0.00281562 | Q23: 0.0030842439 | R23: 1.1
A24: 8 | B24: 9 | C24: 2276732 | D24: 1957651370 | E24: 0.0022818806 | F24: 8.5985148 | H24: ="("&$A24&", "&$B24&"]" -> (8, 9] | I24: 1.1 | J24: 0.0025100686 | K24: 0.0025444511 | L24: 2544451 | M24: 0.0025445965 | N24: 0.021879751 | O24: 0.99 | P24: 0.0025445965 | Q24: 0.0026876983 | R24: 1.06
A25: 9 | B25: 10 | C25: 2032718 | D25: 1959914600 | E25: 0.0020373148 | F25: 9.6418421 | H25: ="("&$A25&", "&$B25&"]" -> (9, 10] | I25: 1.1 | J25: 0.0022410463 | K25: 0.0022717437 | L25: 2271743 | M25: 0.0022718729 | N25: 0.02190504 | O25: 0.99 | P25: 0.0022718729 | Q25: 0.002247092 | R25: 0.99
A26: 10 | B26: 15 | C26: 6889116 | D26: 8548091680 | E26: 0.006904695 | F26: 12.408111 | H26: ="("&$A26&", "&$B26&"]" -> (10, 15] | I26: 0.432 | J26: 0.0029828282 | K26: 0.0030236864 | L26: 3023686 | M26: 0.0030238589 | N26: 0.037520377 | O26: 0.3888 | P26: 0.0030238589 | Q26: 0.0049788509 | R26: 1.65
A27: 15 | B27: 20 | C27: 4433090 | D27: 7740661305 | E27: 0.004443115 | F27: 17.461097 | H27: ="("&$A27&", "&$B27&"]" -> (15, 20] | I27: 0.8802 | J27: 0.0039108298 | K27: 0.0039643996 | L27: 3964399 | M27: 0.0039646257 | N27: 0.069226713 | O27: 0.79218 | P27: 0.0039646257 | Q27: 0.0023352133 | R27: 0.59
... A78: 100000 | B78: 9999999 | C78: 0 | D78: 0 | E78: 0 | F78: 0 | H78: ="("&$A78&", "&$B78&"]" -> (100000, 9999999] | I78: 0 | J78: 0 | K78: 0 | L78: 0 | M78: 0 | N78: 0 | O78: 0 | P78: 0 | Q78: 0 | R78: 0
A79: Free Game | C79: =E79*B13 -> 2256000 | D79: 45757820 | E79: 0.002256 | F79: 0.20282722 | G79: =SUM($L$15:L79)-1000 -> 999941815 | H79: Free Game | I79: 1.85 | J79: 0.0041736 | K79: =J79 -> 0.0041736 | L79: 4173600 | M79: 0.0041738387 | N79: 0.00084656808
A80: Buy Feature | C80: 10000000 | D80: 0 | E80: 1 | F80: 0 | H80: Buy Feature | M80: =E80 -> 1 | N80: =F80/B8 -> 0
A83: Free Game
A85: Simulator | B85: 10000000 | H85: Calculate | P85: Compare
A86: Lower | B86: Upper | C86: Cnt | D86: Pay | E86: Hit Rate | F86: Avg. Multi. | H86: Range | I86: Fix Num | J86: Fix Rate | K86: Final Rate | L86: Weight | M86: Hit Rate | N86: Simulator RTP | O86: 0.9 | P86: 目前 | Q86: 墨西哥狂歡 | R86: 差異 | T86: Fix Num A | U86: Fix Num B
A87: -1 | B87: 0 | C87: 0 | D87: 0 | E87: {=_xlfn.LET(_xlpm.x, C87:C150, _xlpm.x/SUM(_xlpm.x))} -> 0 | F87: {=_xlfn.LET(_xlpm.x, D87:D150/C87:C150/B3, IF(ISERR(_xlpm.x), 0, _xlpm.x))} -> 0 | H87: ="("&$A87&", "&$B87&"]" -> (-1, 0] | I87: 0 | J87: {=_xlfn.ANCHORARRAY(E87)*I87:I150} -> 0 | K87: {=J87:J150/SUM(_xlfn.ANCHORARRAY(J87))} -> 0 | L87: {=INT(_xlfn.ANCHORARRAY(K87)*$B$2)} -> 0 | M87: {=_xlfn.LET(_xlpm.x, L87:L150, _xlpm.x/SUM(_xlpm.x))} -> 0 | N87: {=M87:M150*_xlfn.ANCHORARRAY(F87)} -> 0 | O87: {=I87:I150*O86} -> 0 | P87: {=_xlfn.ANCHORARRAY(M87)} -> 0 | Q87: 0 | R87: {=_xlfn.LET(_xlpm.x, Q87:Q150/M87:M150, IF(ISERR(_xlpm.x), 0, ROUND(_xlpm.x,2)))} -> 0
A88: 0 | B88: 1 | C88: 1569 | D88: 93610 | E88: 0.00069557153 | F88: 0.59662205 | H88: ="("&$A88&", "&$B88&"]" -> (0, 1] | I88: 0 | J88: 0 | K88: 0 | L88: 0 | M88: 0 | N88: 0 | O88: 0 | P88: 0 | Q88: 0 | R88: 0
A89: 1 | B89: 2 | C89: 1451 | D89: 227480 | E89: 0.00064325958 | F89: 1.5677464 | H89: ="("&$A89&", "&$B89&"]" -> (1, 2] | I89: 0 | J89: 0 | K89: 0 | L89: 0 | M89: 0 | N89: 0 | O89: 0 | P89: 0 | Q89: 0 | R89: 0
A90: 2 | B90: 3 | C90: 1515 | D90: 392500 | E90: 0.00067163216 | F90: 2.5907591 | H90: ="("&$A90&", "&$B90&"]" -> (2, 3] | I90: 0 | J90: 0 | K90: 0 | L90: 0 | M90: 0 | N90: 0 | O90: 0 | P90: 0 | Q90: 0 | R90: 0
A91: 3 | B91: 4 | C91: 1475 | D91: 531360 | E91: 0.0006538993 | F91: 3.6024407 | H91: ="("&$A91&", "&$B91&"]" -> (3, 4] | I91: 0 | J91: 0 | K91: 0 | L91: 0 | M91: 0 | N91: 0 | O91: 0 | P91: 0 | Q91: 0.036144578 | R91: 0
A92: 4 | B92: 5 | C92: 1501 | D92: 685345 | E92: 0.00066542566 | F92: 4.5659227 | H92: ="("&$A92&", "&$B92&"]" -> (4, 5] | I92: 0 | J92: 0 | K92: 0 | L92: 0 | M92: 0 | N92: 0 | O92: 0 | P92: 0 | Q92: 0 | R92: 0
A93: 5 | B93: 6 | C93: 1569 | D93: 876000 | E93: 0.00069557153 | F93: 5.583174 | H93: ="("&$A93&", "&$B93&"]" -> (5, 6] | I93: 0 | J93: 0 | K93: 0 | L93: 0 | M93: 0 | N93: 0 | O93: 0 | P93: 0 | Q93: 0 | R93: 0
A94: 6 | B94: 7 | C94: 1661 | D94: 1089245 | E94: 0.00073635711 | F94: 6.5577664 | H94: ="("&$A94&", "&$B94&"]" -> (6, 7] | I94: 0 | J94: 0 | K94: 0 | L94: 0 | M94: 0 | N94: 0 | O94: 0 | P94: 0 | Q94: 0.012048193 | R94: 0
A95: 7 | B95: 8 | C95: 1679 | D95: 1266615 | E95: 0.0007443369 | F95: 7.5438654 | H95: ="("&$A95&", "&$B95&"]" -> (7, 8] | I95: 0 | J95: 0 | K95: 0 | L95: 0 | M95: 0 | N95: 0 | O95: 0 | P95: 0 | Q95: 0.036144578 | R95: 0
A96: 8 | B96: 9 | C96: 1731 | D96: 1482575 | E96: 0.00076738962 | F96: 8.5648469 | H96: ="("&$A96&", "&$B96&"]" -> (8, 9] | I96: 0 | J96: 0 | K96: 0 | L96: 0 | M96: 0 | N96: 0 | O96: 0 | P96: 0 | Q96: 0.024096386 | R96: 0
A97: 9 | B97: 10 | C97: 1671 | D97: 1596910 | E97: 0.00074079033 | F97: 9.5566128 | H97: ="("&$A97&", "&$B97&"]" -> (9, 10] | I97: 0 | J97: 0 | K97: 0 | L97: 0 | M97: 0 | N97: 0 | O97: 0 | P97: 0 | Q97: 0.012048193 | R97: 0
A98: 10 | B98: 15 | C98: 8825 | D98: 11116765 | E98: 0.0039123128 | F98: 12.596901 | H98: ="("&$A98&", "&$B98&"]" -> (10, 15] | I98: 26.866235 | J98: 0.10510911 | K98: 0.13126626 | L98: 131266259 | M98: 0.13126626 | N98: 1.6535481 | O98: 24.179612 | P98: 0.13126626 | Q98: 0.072289157 | R98: 0.55
...

Sheet OP Jackpot
B3: NB-Newbie-A
B4: BGC1Screen | E4: =SUM(D4:D5)/C4 -> #DIV/0!
B5: FGC1Screen
B7: NB-Newbie-B
B8: BGC1Screen | E8: =SUM(D8:D9)/C8 -> #DIV/0!
B9: FGC1Screen
B11: NB-Oldhand-A
B12: BGC1Screen | C12: 100000000 | D12: 27348674 | E12: =SUM(D12:D13)/C12 -> 0.28590684
B13: FGC1Screen | D13: 1242010
B15: NB-Oldhand-B
B16: BGC1Screen | E16: =SUM(D16:D17)/C16 -> #DIV/0!
B17: FGC1Screen
B19: BF-A
B20: BGC1Screen | C20: 1000000000 | D20: 1000000000 | E20: =SUM(D20:D21)/C20 -> 5.4156459
B21: FGC1Screen | D21: 4415645859
B23: BF-B
B24: BGC1Screen | E24: =SUM(D24:D25)/C24 -> #DIV/0!
B25: FGC1Screen
B28: Threshold | C28: 10000000000
B30: NB-Newbie-A | C30: =ROUND(E4*$C$28, 0) -> #DIV/0!
B31: NB-Newbie-B | C31: =ROUND(E8*$C$28, 0) -> #DIV/0!
B32: NB-Oldhand-A | C32: =ROUND(E12*$C$28, 0) -> 2859068400
B33: NB-Oldhand-B | C33: =ROUND(E16*$C$28, 0) -> #DIV/0!
B34: BF-A | C34: =ROUND(E20*$C$28, 0) -> 54156458590
B35: BF-B | C35: =ROUND(E24*$C$28, 0) -> #DIV/0!

Sheet BG_Symbol
J2: Symbol | Q2: Symbol ID | W2: Symbol Weight | AC2: Eliminate Wheel Weight A | AJ2: Eliminate Wheel Weight B
A3: Symbol | B3: Description | C3: R1 | D3: R2 | E3: R3 | F3: R4 | G3: R5 | H3: ID | K3: R1 | L3: R2 | M3: R3 | N3: R4 | O3: R5 | Q3: R1 | R3: R2 | S3: R3 | T3: R4 | U3: R5 | W3: R1 | X3: R2 | Y3: R3 | Z3: R4 | AA3: R5
A4: {=Overview!A38:B57} -> WW | B4: Wild | C4: =COUNTIF(K:K, $A4) -> 0 | D4: =COUNTIF(L:L, $A4) -> 0 | E4: =COUNTIF(M:M, $A4) -> 0 | F4: =COUNTIF(N:N, $A4) -> 0 | G4: =COUNTIF(O:O, $A4) -> 0 | H4: {=Overview!F38:F57} -> 0 | J4: {=_xlfn.SEQUENCE(MAX(COUNTA(K:K), COUNTA(L:L), COUNTA(M:M), COUNTA(N:N), COUNTA(O:O))-1,,0)} -> 0 | K4: M5 | L4: M5 | M4: M5 | N4: GK | O4: M4 | Q4: {=_xlfn.LET(_xlpm.x, K4:O304, IF(_xlpm.x="", "", _xlfn.XLOOKUP(_xlpm.x, $A$4:$A$23,_xlfn.ANCHORARRAY( H4))))} -> 6 | R4: 6 | S4: 6 | T4: 17 | U4: 5 | W4: 1 | X4: 1 | Y4: 1 | Z4: 1 | AA4: 1 | AC4: 1 Combo | AJ4: 1 Combo
A5: C1 | B5: Scatter | C5: =COUNTIF(K:K, $A5) -> 0 | D5: =COUNTIF(L:L, $A5) -> 6 | E5: =COUNTIF(M:M, $A5) -> 0 | F5: =COUNTIF(N:N, $A5) -> 9 | G5: =COUNTIF(O:O, $A5) -> 0 | H5: 1 | J5: 1 | K5: K | L5: M1 | M5: K | N5: Q | O5: M2 | Q5: 8 | R5: 2 | S5: 8 | T5: 9 | U5: 3 | W5: 1 | X5: 1 | Y5: 1 | Z5: 1 | AA5: 1 | AC5: Symbol | AD5: R1 | AE5: R2 | AF5: R3 | AG5: R4 | AH5: R5 | AJ5: Symbol | AK5: R1 | AL5: R2 | AM5: R3 | AN5: R4 | AO5: R5
A6: M1 | B6: M1 | C6: =COUNTIF(K:K, $A6) -> 4 | D6: =COUNTIF(L:L, $A6) -> 11 | E6: =COUNTIF(M:M, $A6) -> 5 | F6: =COUNTIF(N:N, $A6) -> 21 | G6: =COUNTIF(O:O, $A6) -> 23 | H6: 2 | J6: 2 | K6: M4 | L6: G4 | M6: GK | N6: M3 | O6: M2 | Q6: 5 | R6: 14 | S6: 17 | T6: 4 | U6: 3 | W6: 1 | X6: 1 | Y6: 1 | Z6: 1 | AA6: 1 | AC6: {=$A$4:$A$23} -> WW | AD6: 0 | AE6: 0 | AF6: 0 | AG6: 0 | AH6: 0 | AJ6: {=$A$4:$A$23} -> WW | AK6: 0 | AL6: 0 | AM6: 0 | AN6: 0 | AO6: 0
A7: M2 | B7: M2 | C7: =COUNTIF(K:K, $A7) -> 4 | D7: =COUNTIF(L:L, $A7) -> 11 | E7: =COUNTIF(M:M, $A7) -> 5 | F7: =COUNTIF(N:N, $A7) -> 21 | G7: =COUNTIF(O:O, $A7) -> 23 | H7: 3 | J7: 3 | K7: A | L7: A | M7: M4 | N7: M3 | O7: J | Q7: 7 | R7: 7 | S7: 5 | T7: 4 | U7: 10 | W7: 1 | X7: 1 | Y7: 1 | Z7: 1 | AA7: 1 | AC7: C1 | AD7: 0 | AE7: 6 | AF7: 0 | AG7: 9 | AH7: 0 | AJ7: C1 | AK7: 0 | AL7: 6 | AM7: 0 | AN7: 9 | AO7: 0
A8: M3 | B8: M3 | C8: =COUNTIF(K:K, $A8) -> 4 | D8: =COUNTIF(L:L, $A8) -> 11 | E8: =COUNTIF(M:M, $A8) -> 5 | F8: =COUNTIF(N:N, $A8) -> 21 | G8: =COUNTIF(O:O, $A8) -> 22 | H8: 4 | J8: 4 | K8: K | L8: M5 | M8: M2 | N8: GK | O8: K | Q8: 8 | R8: 6 | S8: 3 | T8: 17 | U8: 8 | W8: 1 | X8: 1 | Y8: 1 | Z8: 1 | AA8: 1 | AC8: M1 | AD8: 4 | AE8: 11 | AF8: 5 | AG8: 21 | AH8: 23 | AJ8: M1 | AK8: 4 | AL8: 11 | AM8: 5 | AN8: 21 | AO8: 23
A9: M4 | B9: M4 | C9: =COUNTIF(K:K, $A9) -> 43 | D9: =COUNTIF(L:L, $A9) -> 20 | E9: =COUNTIF(M:M, $A9) -> 41 | F9: =COUNTIF(N:N, $A9) -> 14 | G9: =COUNTIF(O:O, $A9) -> 22 | H9: 5 | J9: 5 | K9: A | L9: G2 | M9: A | N9: GQ | O9: J | Q9: 7 | R9: 12 | S9: 7 | T9: 18 | U9: 10 | W9: 1 | X9: 1 | Y9: 1 | Z9: 1 | AA9: 1 | AC9: M2 | AD9: 4 | AE9: 11 | AF9: 5 | AG9: 21 | AH9: 23 | AJ9: M2 | AK9: 4 | AL9: 11 | AM9: 5 | AN9: 21 | AO9: 23
A10: M5 | B10: M5 | C10: =COUNTIF(K:K, $A10) -> 43 | D10: =COUNTIF(L:L, $A10) -> 21 | E10: =COUNTIF(M:M, $A10) -> 41 | F10: =COUNTIF(N:N, $A10) -> 14 | G10: =COUNTIF(O:O, $A10) -> 22 | H10: 6 | J10: 6 | K10: K | L10: A | M10: G5 | N10: M5 | O10: A | Q10: 8 | R10: 7 | S10: 15 | T10: 6 | U10: 7 | W10: 1 | X10: 1 | Y10: 1 | Z10: 1 | AA10: 1 | AC10: M3 | AD10: 4 | AE10: 11 | AF10: 5 | AG10: 21 | AH10: 22 | AJ10: M3 | AK10: 4 | AL10: 11 | AM10: 5 | AN10: 21 | AO10: 22
A11: A | B11: A | C11: =COUNTIF(K:K, $A11) -> 47 | D11: =COUNTIF(L:L, $A11) -> 21 | E11: =COUNTIF(M:M, $A11) -> 41 | F11: =COUNTIF(N:N, $A11) -> 14 | G11: =COUNTIF(O:O, $A11) -> 22 | H11: 7 | J11: 7 | K11: K | L11: A | M11: Q | N11: M1 | O11: A | Q11: 8 | R11: 7 | S11: 9 | T11: 2 | U11: 7 | W11: 1 | X11: 1 | Y11: 1 | Z11: 1 | AA11: 1 | AC11: M4 | AD11: 43 | AE11: 20 | AF11: 41 | AG11: 14 | AH11: 22 | AJ11: M4 | AK11: 43 | AL11: 20 | AM11: 41 | AN11: 14 | AO11: 22
A12: K | B12: K | C12: =COUNTIF(K:K, $A12) -> 47 | D12: =COUNTIF(L:L, $A12) -> 21 | E12: =COUNTIF(M:M, $A12) -> 41 | F12: =COUNTIF(N:N, $A12) -> 14 | G12: =COUNTIF(O:O, $A12) -> 22 | H12: 8 | J12: 8 | K12: A | L12: A | M12: K | N12: G2 | O12: M4 | Q12: 7 | R12: 7 | S12: 8 | T12: 12 | U12: 5 | W12: 1 | X12: 1 | Y12: 1 | Z12: 1 | AA12: 1 | AC12: M5 | AD12: 43 | AE12: 21 | AF12: 41 | AG12: 14 | AH12: 22 | AJ12: M5 | AK12: 43 | AL12: 21 | AM12: 41 | AN12: 14 | AO12: 22
A13: Q | B13: Q | C13: =COUNTIF(K:K, $A13) -> 4 | D13: =COUNTIF(L:L, $A13) -> 11 | E13: =COUNTIF(M:M, $A13) -> 5 | F13: =COUNTIF(N:N, $A13) -> 20 | G13: =COUNTIF(O:O, $A13) -> 22 | H13: 9 | J13: 9 | K13: M5 | L13: M4 | M13: K | N13: A | O13: Q | Q13: 6 | R13: 5 | S13: 8 | T13: 7 | U13: 9 | W13: 1 | X13: 1 | Y13: 1 | Z13: 1 | AA13: 1 | AC13: A | AD13: 47 | AE13: 21 | AF13: 41 | AG13: 14 | AH13: 22 | AJ13: A | AK13: 47 | AL13: 21 | AM13: 41 | AN13: 14 | AO13: 22
A14: J | B14: J | C14: =COUNTIF(K:K, $A14) -> 4 | D14: =COUNTIF(L:L, $A14) -> 11 | E14: =COUNTIF(M:M, $A14) -> 4 | F14: =COUNTIF(N:N, $A14) -> 20 | G14: =COUNTIF(O:O, $A14) -> 22 | H14: 10 | J14: 10 | K14: A | L14: J | M14: M5 | N14: G5 | O14: K | Q14: 7 | R14: 10 | S14: 6 | T14: 15 | U14: 8 | W14: 1 | X14: 1 | Y14: 1 | Z14: 1 | AA14: 1 | AC14: K | AD14: 47 | AE14: 21 | AF14: 41 | AG14: 14 | AH14: 22 | AJ14: K | AK14: 47 | AL14: 21 | AM14: 41 | AN14: 14 | AO14: 22
A15: G1 | B15: Gold M1 | C15: =COUNTIF(K:K, $A15) -> 0 | D15: =COUNTIF(L:L, $A15) -> 4 | E15: =COUNTIF(M:M, $A15) -> 0 | F15: =COUNTIF(N:N, $A15) -> 4 | G15: =COUNTIF(O:O, $A15) -> 0 | H15: 11 | J15: 11 | K15: M5 | L15: A | M15: A | N15: K | O15: M1 | Q15: 6 | R15: 7 | S15: 7 | T15: 8 | U15: 2 | W15: 1 | X15: 1 | Y15: 1 | Z15: 1 | AA15: 1 | AC15: Q | AD15: 4 | AE15: 11 | AF15: 5 | AG15: 20 | AH15: 22 | AJ15: Q | AK15: 4 | AL15: 11 | AM15: 5 | AN15: 20 | AO15: 22
A16: G2 | B16: Gold M2 | C16: =COUNTIF(K:K, $A16) -> 0 | D16: =COUNTIF(L:L, $A16) -> 5 | E16: =COUNTIF(M:M, $A16) -> 0 | F16: =COUNTIF(N:N, $A16) -> 4 | G16: =COUNTIF(O:O, $A16) -> 0 | H16: 12 | J16: 12 | K16: A | L16: G1 | M16: A | N16: K | O16: M2 | Q16: 7 | R16: 11 | S16: 7 | T16: 8 | U16: 3 | W16: 1 | X16: 1 | Y16: 1 | Z16: 1 | AA16: 1 | AC16: J | AD16: 4 | AE16: 11 | AF16: 4 | AG16: 20 | AH16: 22 | AJ16: J | AK16: 4 | AL16: 11 | AM16: 4 | AN16: 20 | AO16: 22
A17: G3 | B17: Gold M3 | C17: =COUNTIF(K:K, $A17) -> 0 | D17: =COUNTIF(L:L, $A17) -> 5 | E17: =COUNTIF(M:M, $A17) -> 0 | F17: =COUNTIF(N:N, $A17) -> 4 | G17: =COUNTIF(O:O, $A17) -> 0 | H17: 13 | J17: 13 | K17: K | L17: M1 | M17: A | N17: M3 | O17: Q | Q17: 8 | R17: 2 | S17: 7 | T17: 4 | U17: 9 | W17: 1 | X17: 1 | Y17: 1 | Z17: 1 | AA17: 1 | AC17: G1 | AD17: 0 | AE17: 5 | AF17: 1 | AG17: 5 | AH17: 0 | AJ17: G1 | AK17: 0 | AL17: 5 | AM17: 1 | AN17: 5 | AO17: 0
A18: G4 | B18: Gold M4 | C18: =COUNTIF(K:K, $A18) -> 0 | D18: =COUNTIF(L:L, $A18) -> 8 | E18: =COUNTIF(M:M, $A18) -> 3 | F18: =COUNTIF(N:N, $A18) -> 3 | G18: =COUNTIF(O:O, $A18) -> 0 | H18: 14 | J18: 14 | K18: M5 | L18: A | M18: G4 | N18: K | O18: Q | Q18: 6 | R18: 7 | S18: 14 | T18: 8 | U18: 9 | W18: 1 | X18: 1 | Y18: 1 | Z18: 1 | AA18: 1 | AC18: G2 | AD18: 0 | AE18: 6 | AF18: 1 | AG18: 5 | AH18: 0 | AJ18: G2 | AK18: 0 | AL18: 6 | AM18: 1 | AN18: 5 | AO18: 0
... A23: GJ | B23: Gold J | C23: =COUNTIF(K:K, $A23) -> 0 | D23: =COUNTIF(L:L, $A23) -> 5 | E23: =COUNTIF(M:M, $A23) -> 0 | F23: =COUNTIF(N:N, $A23) -> 4 | G23: =COUNTIF(O:O, $A23) -> 0 | H23: 19 | J23: 19 | K23: M4 | L23: M5 | M23: GA | N23: G4 | O23: M1 | Q23: 5 | R23: 6 | S23: 16 | T23: 14 | U23: 2 | W23: 1 | X23: 1 | Y23: 1 | Z23: 1 | AA23: 1 | AC23: GK | AD23: 0 | AE23: 9 | AF23: 4 | AG23: 4 | AH23: 0 | AJ23: GK | AK23: 0 | AL23: 9 | AM23: 4 | AN23: 4 | AO23: 0
C24: =SUM(C4:C23) -> 200 | D24: =SUM(D4:D23) -> 200 | E24: =SUM(E4:E23) -> 200 | F24: =SUM(F4:F23) -> 200 | G24: =SUM(G4:G23) -> 200 | J24: 20 | K24: A | L24: K | M24: A | N24: M4 | O24: Q | Q24: 7 | R24: 8 | S24: 7 | T24: 5 | U24: 9 | W24: 1 | X24: 1 | Y24: 1 | Z24: 1 | AA24: 1 | AC24: GQ | AD24: 0 | AE24: 6 | AF24: 1 | AG24: 5 | AH24: 0 | AJ24: GQ | AK24: 0 | AL24: 6 | AM24: 1 | AN24: 5 | AO24: 0
J25: 21 | K25: M4 | L25: A | M25: Q | N25: M4 | O25: J | Q25: 5 | R25: 7 | S25: 9 | T25: 5 | U25: 10 | W25: 1 | X25: 1 | Y25: 1 | Z25: 1 | AA25: 1 | AC25: GJ | AD25: 0 | AE25: 6 | AF25: 1 | AG25: 5 | AH25: 0 | AJ25: GJ | AK25: 0 | AL25: 6 | AM25: 1 | AN25: 5 | AO25: 0
B26: Normal Symbol | C26: =SUM(C4:C14)/C24 -> 1 | D26: =SUM(D4:D14)/D24 -> 0.72 | E26: =SUM(E4:E14)/E24 -> 0.94 | F26: =SUM(F4:F14)/F24 -> 0.84 | G26: =SUM(G4:G14)/G24 -> 1 | J26: 22 | K26: Q | L26: Q | M26: M4 | N26: Q | O26: K | Q26: 9 | R26: 9 | S26: 5 | T26: 9 | U26: 8 | W26: 1 | X26: 1 | Y26: 1 | Z26: 1 | AA26: 1 | AD26: =SUM(AD6:AD25) -> 200 | AE26: =SUM(AE6:AE25) -> 209 | AF26: =SUM(AF6:AF25) -> 209 | AG26: =SUM(AG6:AG25) -> 209 | AH26: =SUM(AH6:AH25) -> 200 | AK26: =SUM(AK6:AK25) -> 200 | AL26: =SUM(AL6:AL25) -> 209 | AM26: =SUM(AM6:AM25) -> 209 | AN26: =SUM(AN6:AN25) -> 209 | AO26: =SUM(AO6:AO25) -> 200
B27: Golden Symbol | C27: =SUM(C15:C23)/C24 -> 0 | D27: =SUM(D15:D23)/D24 -> 0.28 | E27: =SUM(E15:E23)/E24 -> 0.06 | F27: =SUM(F15:F23)/F24 -> 0.16 | G27: =SUM(G15:G23)/G24 -> 0 | J27: 23 | K27: M4 | L27: M5 | M27: K | N27: M1 | O27: M2 | Q27: 5 | R27: 6 | S27: 8 | T27: 2 | U27: 3 | W27: 1 | X27: 1 | Y27: 1 | Z27: 1 | AA27: 1
J28: 24 | K28: K | L28: K | M28: M4 | N28: Q | O28: M1 | Q28: 8 | R28: 8 | S28: 5 | T28: 9 | U28: 2 | W28: 1 | X28: 1 | Y28: 1 | Z28: 1 | AA28: 1 | AC28: 2 Combo | AJ28: 2 Combo
J29: 25 | K29: M4 | L29: GJ | M29: A | N29: Q | O29: A | Q29: 5 | R29: 19 | S29: 7 | T29: 9 | U29: 7 | W29: 1 | X29: 1 | Y29: 1 | Z29: 1 | AA29: 1 | AC29: Symbol | AD29: R1 | AE29: R2 | AF29: R3 | AG29: R4 | AH29: R5 | AJ29: Symbol | AK29: R1 | AL29: R2 | AM29: R3 | AN29: R4 | AO29: R5
J30: 26 | K30: M2 | L30: G5 | M30: M4 | N30: Q | O30: M4 | Q30: 3 | R30: 15 | S30: 5 | T30: 9 | U30: 5 | W30: 1 | X30: 1 | Y30: 1 | Z30: 1 | AA30: 1 | AC30: {=$A$4:$A$23} -> WW | AD30: 0 | AE30: 0 | AF30: 0 | AG30: 0 | AH30: 0 | AJ30: {=$A$4:$A$23} -> WW | AK30: 0 | AL30: 0 | AM30: 0 | AN30: 0 | AO30: 0
J31: 27 | K31: M4 | L31: A | M31: K | N31: J | O31: M1 | Q31: 5 | R31: 7 | S31: 8 | T31: 10 | U31: 2 | W31: 1 | X31: 1 | Y31: 1 | Z31: 1 | AA31: 1 | AC31: C1 | AD31: 0 | AE31: 6 | AF31: 0 | AG31: 9 | AH31: 0 | AJ31: C1 | AK31: 0 | AL31: 6 | AM31: 0 | AN31: 9 | AO31: 0
J32: 28 | K32: A | L32: J | M32: M4 | N32: G4 | O32: M5 | Q32: 7 | R32: 10 | S32: 5 | T32: 14 | U32: 6 | W32: 1 | X32: 1 | Y32: 1 | Z32: 1 | AA32: 1 | AC32: M1 | AD32: 4 | AE32: 11 | AF32: 5 | AG32: 21 | AH32: 23 | AJ32: M1 | AK32: 4 | AL32: 11 | AM32: 5 | AN32: 21 | AO32: 23
J33: 29 | K33: M4 | L33: M5 | M33: K | N33: K | O33: M2 | Q33: 5 | R33: 6 | S33: 8 | T33: 8 | U33: 3 | W33: 1 | X33: 1 | Y33: 1 | Z33: 1 | AA33: 1 | AC33: M2 | AD33: 4 | AE33: 11 | AF33: 5 | AG33: 21 | AH33: 23 | AJ33: M2 | AK33: 4 | AL33: 11 | AM33: 5 | AN33: 21 | AO33: 23
J34: 30 | K34: M5 | L34: GQ | M34: A | N34: M1 | O34: Q | Q34: 6 | R34: 18 | S34: 7 | T34: 2 | U34: 9 | W34: 1 | X34: 1 | Y34: 1 | Z34: 1 | AA34: 1 | AC34: M3 | AD34: 4 | AE34: 11 | AF34: 5 | AG34: 21 | AH34: 22 | AJ34: M3 | AK34: 4 | AL34: 11 | AM34: 5 | AN34: 21 | AO34: 22
J35: 31 | K35: M4 | L35: A | M35: K | N35: M2 | O35: J | Q35: 5 | R35: 7 | S35: 8 | T35: 3 | U35: 10 | W35: 1 | X35: 1 | Y35: 1 | Z35: 1 | AA35: 1 | AC35: M4 | AD35: 43 | AE35: 20 | AF35: 41 | AG35: 14 | AH35: 22 | AJ35: M4 | AK35: 43 | AL35: 20 | AM35: 41 | AN35: 14 | AO35: 22
J36: 32 | K36: A | L36: M1 | M36: K | N36: M2 | O36: M4 | Q36: 7 | R36: 2 | S36: 8 | T36: 3 | U36: 5 | W36: 1 | X36: 1 | Y36: 1 | Z36: 1 | AA36: 1 | AC36: M5 | AD36: 43 | AE36: 21 | AF36: 41 | AG36: 14 | AH36: 22 | AJ36: M5 | AK36: 43 | AL36: 21 | AM36: 41 | AN36: 14 | AO36: 22
J37: 33 | K37: M5 | L37: A | M37: K | N37: M2 | O37: M5 | Q37: 6 | R37: 7 | S37: 8 | T37: 3 | U37: 6 | W37: 1 | X37: 1 | Y37: 1 | Z37: 1 | AA37: 1 | AC37: A | AD37: 47 | AE37: 21 | AF37: 41 | AG37: 14 | AH37: 22 | AJ37: A | AK37: 47 | AL37: 21 | AM37: 41 | AN37: 14 | AO37: 22
J38: 34 | K38: K | L38: M5 | M38: A | N38: Q | O38: M3 | Q38: 8 | R38: 6 | S38: 7 | T38: 9 | U38: 4 | W38: 1 | X38: 1 | Y38: 1 | Z38: 1 | AA38: 1 | AC38: K | AD38: 47 | AE38: 21 | AF38: 41 | AG38: 14 | AH38: 22 | AJ38: K | AK38: 47 | AL38: 21 | AM38: 41 | AN38: 14 | AO38: 22
J39: 35 | K39: A | L39: Q | M39: A | N39: M4 | O39: M3 | Q39: 7 | R39: 9 | S39: 7 | T39: 5 | U39: 4 | W39: 1 | X39: 1 | Y39: 1 | Z39: 1 | AA39: 1 | AC39: Q | AD39: 4 | AE39: 11 | AF39: 5 | AG39: 20 | AH39: 22 | AJ39: Q | AK39: 4 | AL39: 11 | AM39: 5 | AN39: 20 | AO39: 22
J40: 36 | K40: M5 | L40: J | M40: M5 | N40: M4 | O40: J | Q40: 6 | R40: 10 | S40: 6 | T40: 5 | U40: 10 | W40: 1 | X40: 1 | Y40: 1 | Z40: 1 | AA40: 1 | AC40: J | AD40: 4 | AE40: 11 | AF40: 4 | AG40: 20 | AH40: 22 | AJ40: J | AK40: 4 | AL40: 11 | AM40: 4 | AN40: 20 | AO40: 22
J41: 37 | K41: M5 | L41: J | M41: K | N41: M3 | O41: J | Q41: 6 | R41: 10 | S41: 8 | T41: 4 | U41: 10 | W41: 1 | X41: 1 | Y41: 1 | Z41: 1 | AA41: 1 | AC41: G1 | AD41: 0 | AE41: 5 | AF41: 1 | AG41: 5 | AH41: 0 | AJ41: G1 | AK41: 0 | AL41: 5 | AM41: 1 | AN41: 5 | AO41: 0
J42: 38 | K42: M5 | L42: M5 | M42: K | N42: GJ | O42: M3 | Q42: 6 | R42: 6 | S42: 8 | T42: 19 | U42: 4 | W42: 1 | X42: 1 | Y42: 1 | Z42: 1 | AA42: 1 | AC42: G2 | AD42: 0 | AE42: 6 | AF42: 1 | AG42: 5 | AH42: 0 | AJ42: G2 | AK42: 0 | AL42: 6 | AM42: 1 | AN42: 5 | AO42: 0
... J49: 45 | K49: A | L49: K | M49: M1 | N49: G1 | O49: A | Q49: 7 | R49: 8 | S49: 2 | T49: 11 | U49: 7 | W49: 1 | X49: 1 | Y49: 1 | Z49: 1 | AA49: 1 | AC49: GJ | AD49: 0 | AE49: 6 | AF49: 1 | AG49: 5 | AH49: 0 | AJ49: GJ | AK49: 0 | AL49: 6 | AM49: 1 | AN49: 5 | AO49: 0
