Workbook

Sheet Overview
A2: Model: | B2: H026194B
A3: Version: | B3: 3.0.0.3
A6: Base Bet
A7: 100
A10: Coin in | B10: Price(x) | C10: Total RTP | D10: Bet Type
A11: {=B11:B13*A7} -> 100 | B11: 1 | C11: =SUM(B18:B19) -> 0.94000021 | D11: Normal Bet
A12: 200 | B12: 2 | C12: =B22+B23 -> 0.9400004 | D12: Extra Bet
A13: 7500 | B13: 75 | C13: =SUM(B26:B27) -> 0.92500032 | D13: Buy Feature
A16: Total Pay Back Percentage includes the following adjustments.
A17: Bet Type | B17: Pay Back | C17: Hit% | D17: Pulls/Hit | E17: Description
A18: =D11 -> Normal Bet | B18: =Multiplier_Weight_Oldhand!C7 -> 0.69999982 | C18: =1/D18 -> 0.0041955921 | D18: =Multiplier_Weight_Oldhand!G7 -> 238.34538 | E18: Base Game
B19: =Multiplier_Weight_Oldhand!D7 -> 0.2400004 | E19: Free Game
A21: Bet Type | B21: Pay Back | C21: Hit% | D21: Pulls/Hit | E21: Description
A22: =D12 -> Extra Bet | B22: =Multiplier_Weight_Oldhand!C8 -> 0.34024087 | C22: =1/D22 -> 0.020969518 | D22: =Multiplier_Weight_Oldhand!G8 -> 47.688268 | E22: Base Game
B23: =Multiplier_Weight_Oldhand!D8 -> 0.59975952 | E23: Free Game
A25: Bet Type | B25: Pay Back | C25: Hit% | D25: Pulls/Hit | E25: Description
A26: =D13 -> Buy Feature | B26: =Multiplier_Weight_Oldhand!C9 -> 0 | C26: =1/D26 -> 1 | D26: 1 | E26: Base Game
B27: =Multiplier_Weight_Oldhand!D9 -> 0.92500032 | E27: Free Game
A30: Reel # | B30: 1 | C30: 2 | D30: 3 | E30: 4 | F30: 5
A31: Visible Window Size | B31: 3 | C31: 3 | D31: 3 | E31: 3 | F31: 3
A34: Free Spins Setting
A35: C1 Num. | B35: Base Game | C35: Free Game
A36: 3 | B36: 15 | C36: 15
A37: 4 | B37: 17 | C37: 17
A38: 5 | B38: 19 | C38: 19
A39: The maximum of free spins is 50.
A41: Pay Table： | B41: ="All wins show for "&A7&" credit bet." -> All wins show for 100 credit bet.
A42: Symbol | B42: Description | C42: 3 | D42: 4 | E42: 5 | F42: Id
A43: WW | B43: Wild | C43: 0 | D43: 0 | E43: 0 | F43: 0
A44: C1 | B44: Scatter | C44: 0 | D44: 0 | E44: 0 | F44: 1
A45: M1 | B45: M1 | C45: 250 | D45: 1250 | E45: 5000 | F45: 2
A46: M2 | B46: M2 | C46: 100 | D46: 500 | E46: 2000 | F46: 3
A47: M3 | B47: M3 | C47: 75 | D47: 250 | E47: 1000 | F47: 4
A48: M4 | B48: M4 | C48: 50 | D48: 200 | E48: 750 | F48: 5
A49: M5 | B49: M5 | C49: 25 | D49: 100 | E49: 500 | F49: 6
A50: A | B50: A | C50: 10 | D50: 50 | E50: 250 | F50: 7
A51: K | B51: K | C51: 10 | D51: 50 | E51: 250 | F51: 8
A52: Q | B52: Q | C52: 10 | D52: 50 | E52: 250 | F52: 9
A53: J | B53: J | C53: 10 | D53: 50 | E53: 250 | F53: 10
A54: G1 | B54: Rainbow M1 | C54: 250 | D54: 1250 | E54: 5000 | F54: 11
...

Sheet Description
B3: 7. BG 流程對應
B5: 7.1 BG 開局流程
B7: BG 每局的主要參數流程如下：
B8: 1. 先用 Table Selection Weight - Base Game 選出 BG table。
B9: 2. 再用該 strip 的 Symbol Weight R1~R5 抽停輪位置。
B10: 3. 依 Symbol ID R1~R5 生成初始盤面。
B11: 4. 盤面上的彩虹框會先判定是否觸發 Used Special Pool Weight。
B12: 5. 若命中特殊池，該彩虹框用 Multiple Selection Weight - Special Pool 抽倍率。
B13: 6. 若沒命中特殊池：
B14: - 且是 BG_Symbol (2) 則第 3 輪彩虹框用 Multiple Selection Weight - Reel3 Before Eliminate
B15: - 其他輪彩虹框用 Multiple Selection Weight - Before Eliminate
B16: 7. 再用 Eliminate Table Weight 決定本局是掉落表 A 或 B。
... B83: 5. BG_Symbol (3): 觸發 FG 用的表。得分少、C1 多，盡量不要有倍數百搭參與 → 控制進 FG 時的得分

Sheet Parameter
B3: Line | I3: Table Selection Weight - Base Game (Weight/Total) | N3: Multiple Selection Weight - Special Pool (Weight/Total) | Y3: 4.7619048 | AA3: 10 | AC3: Used Special Pool Weight (Weight/10000)
B4: ID | C4: R1 | D4: R2 | E4: R3 | F4: R4 | G4: R5 | I4: Worksheet Name | J4: Weight | K4: RTP | N4: Worksheet Name \ Multiple | O4: 0 | P4: 2 | Q4: 3 | R4: 5 | S4: 8 | T4: 10 | U4: 15 | V4: 20 | W4: 25 | X4: 50 | Y4: 100 | Z4: 500 | AA4: 1000 | AC4: Worksheet Name \ Multiple | AD4: 1 | AE4: 2 | AF4: 3 | AG4: 4 | AH4: 5 | AI4: 6 | AJ4: 7 | AK4: 8 | AL4: 9
B5: 0 | C5: 1 | D5: 1 | E5: 1 | F5: 1 | G5: 1 | I5: BG_Symbol | J5: 7000 | L5: 0.7 | N5: BG_Symbol | O5: 0 | P5: 0 | Q5: 0 | R5: 0 | S5: 0 | T5: 2680 | U5: 3000 | V5: 2000 | W5: 500 | X5: 100 | Y5: 1200 | Z5: 20 | AA5: 500 | AB5: 75.93 | AC5: BG_Symbol | AD5: 300 | AE5: 600 | AF5: 1080 | AG5: 1440 | AH5: 2250 | AI5: 2700 | AJ5: 3150 | AK5: 3600 | AL5: 4050
B6: 1 | C6: 0 | D6: 0 | E6: 0 | F6: 0 | G6: 0 | I6: BG_Symbol (2) | J6: 1000 | L6: 0.1 | N6: BG_Symbol (2) | O6: 0 | P6: 0 | Q6: 0 | R6: 0 | S6: 0 | T6: 2680 | U6: 3000 | V6: 2000 | W6: 500 | X6: 100 | Y6: 1200 | Z6: 20 | AA6: 500 | AB6: 75.93 | AC6: BG_Symbol (2) | AD6: 0 | AE6: 0 | AF6: 525 | AG6: 700 | AH6: 1750 | AI6: 2100 | AJ6: 3675 | AK6: 4200 | AL6: 4725
B7: 2 | C7: 2 | D7: 2 | E7: 2 | F7: 2 | G7: 2 | I7: BG_Symbol (3) | J7: 2000 | L7: 0.2 | N7: BG_Symbol (3) | O7: 10000 | P7: 0 | Q7: 0 | R7: 0 | S7: 0 | T7: 0 | U7: 0 | V7: 0 | W7: 0 | X7: 0 | Y7: 0 | Z7: 0 | AA7: 0 | AB7: 0 | AC7: BG_Symbol (3) | AD7: 0 | AE7: 0 | AF7: 0 | AG7: 0 | AH7: 0 | AI7: 0 | AJ7: 0 | AK7: 0 | AL7: 0
B8: 3 | C8: 0 | D8: 1 | E8: 2 | F8: 1 | G8: 0 | J8: 10000 | K8: 0 | N8: FG_Symbol | O8: 0 | P8: 0 | Q8: 0 | R8: 0 | S8: 0 | T8: 3600 | U8: 2500 | V8: 1500 | W8: 250 | X8: 50 | Y8: 1000 | Z8: 100 | AA8: 1000 | AB8: 126.225 | AC8: FG_Symbol | AD8: 0 | AE8: 0 | AF8: 525 | AG8: 700 | AH8: 1750 | AI8: 2100 | AJ8: 3675 | AK8: 4200 | AL8: 4725
B9: 4 | C9: 2 | D9: 1 | E9: 0 | F9: 1 | G9: 2 | N9: FG_Symbol (2) | O9: 0 | P9: 0 | Q9: 0 | R9: 0 | S9: 0 | T9: 3430 | U9: 2500 | V9: 2000 | W9: 500 | X9: 100 | Y9: 700 | Z9: 70 | AA9: 700 | AB9: 93.43 | AC9: FG_Symbol (2) | AD9: 0 | AE9: 0 | AF9: 525 | AG9: 700 | AH9: 1750 | AI9: 2100 | AJ9: 3675 | AK9: 4200 | AL9: 4725
B10: 5 | C10: 0 | D10: 0 | E10: 1 | F10: 0 | G10: 0 | I10: Table Selection Weight - Free Game (Weight/Total) | N10: FG_Symbol (3) | O10: 0 | P10: 0 | Q10: 0 | R10: 0 | S10: 0 | T10: 4480 | U10: 2500 | V10: 2000 | W10: 500 | X10: 100 | Y10: 200 | Z10: 20 | AA10: 200 | AB10: 36.98 | AC10: FG_Symbol (3) | AD10: 0 | AE10: 0 | AF10: 525 | AG10: 700 | AH10: 1750 | AI10: 2100 | AJ10: 3675 | AK10: 4200 | AL10: 4725
B11: 6 | C11: 2 | D11: 2 | E11: 1 | F11: 2 | G11: 2 | I11: Worksheet Name | J11: Weight | K11: RTP | N11: BF_Symbol | O11: 10000 | P11: 0 | Q11: 0 | R11: 0 | S11: 0 | T11: 0 | U11: 0 | V11: 0 | W11: 0 | X11: 0 | Y11: 0 | Z11: 0 | AA11: 0 | AB11: 0 | AC11: BF_Symbol | AD11: 0 | AE11: 0 | AF11: 0 | AG11: 0 | AH11: 0 | AI11: 0 | AJ11: 0 | AK11: 0 | AL11: 0
B12: 7 | C12: 1 | D12: 2 | E12: 2 | F12: 2 | G12: 1 | I12: FG_Symbol | J12: 10000 | L12: 1
B13: 8 | C13: 1 | D13: 0 | E13: 0 | F13: 0 | G13: 1 | I13: FG_Symbol (2) | J13: 0 | L13: 0
B14: 9 | C14: 0 | D14: 1 | E14: 1 | F14: 1 | G14: 0 | I14: FG_Symbol (3) | J14: 0 | L14: 0 | N14: Multiple Selection Weight - Reel3 Before Eliminate (Weight/Total)
B15: 10 | C15: 2 | D15: 1 | E15: 1 | F15: 1 | G15: 2 | J15: 10000 | K15: 0 | N15: Worksheet Name \ Multiple | O15: 0 | P15: 2 | Q15: 3 | R15: 5 | S15: 8 | T15: 10 | U15: 15 | V15: 20 | W15: 25 | X15: 50 | Y15: 100 | Z15: 500 | AA15: 1000
B16: 11 | C16: 1 | D16: 1 | E16: 0 | F16: 1 | G16: 1 | N16: BG_Symbol | O16: 10000 | P16: 0 | Q16: 0 | R16: 0 | S16: 0 | T16: 0 | U16: 0 | V16: 0 | W16: 0 | X16: 0 | Y16: 0 | Z16: 0 | AA16: 0 | AB16: 0
B17: 12 | C17: 1 | D17: 1 | E17: 2 | F17: 1 | G17: 1 | I17: Table Selection Weight - Buy Feature (Weight/Total) | N17: BG_Symbol (2) | O17: 0 | P17: 3600 | Q17: 3400 | R17: 1500 | S17: 1500 | T17: 0 | U17: 0 | V17: 0 | W17: 0 | X17: 0 | Y17: 0 | Z17: 0 | AA17: 0 | AB17: 3.69
B18: 13 | C18: 1 | D18: 0 | E18: 1 | F18: 0 | G18: 1 | I18: Worksheet Name | J18: Weight | K18: RTP | N18: BG_Symbol (3) | O18: 10000 | P18: 0 | Q18: 0 | R18: 0 | S18: 0 | T18: 0 | U18: 0 | V18: 0 | W18: 0 | X18: 0 | Y18: 0 | Z18: 0 | AA18: 0 | AB18: 0
B19: 14 | C19: 1 | D19: 2 | E19: 1 | F19: 2 | G19: 1 | I19: FG_Symbol | J19: 10000 | L19: 1 | N19: FG_Symbol | O19: 0 | P19: 6000 | Q19: 2800 | R19: 900 | S19: 300 | T19: 0 | U19: 0 | V19: 0 | W19: 0 | X19: 0 | Y19: 0 | Z19: 0 | AA19: 0 | AB19: 2.73
B20: 15 | C20: 0 | D20: 1 | E20: 0 | F20: 1 | G20: 0 | I20: FG_Symbol (2) | J20: 0 | L20: 0 | N20: FG_Symbol (2) | O20: 0 | P20: 6000 | Q20: 2800 | R20: 900 | S20: 300 | T20: 0 | U20: 0 | V20: 0 | W20: 0 | X20: 0 | Y20: 0 | Z20: 0 | AA20: 0 | AB20: 2.73
B21: 16 | C21: 2 | D21: 1 | E21: 2 | F21: 1 | G21: 2 | I21: FG_Symbol (3) | J21: 0 | L21: 0 | N21: FG_Symbol (3) | O21: 0 | P21: 6000 | Q21: 2800 | R21: 900 | S21: 300 | T21: 0 | U21: 0 | V21: 0 | W21: 0 | X21: 0 | Y21: 0 | Z21: 0 | AA21: 0 | AB21: 2.73
B22: 17 | C22: 0 | D22: 0 | E22: 1 | F22: 2 | G22: 2 | J22: 10000 | K22: 0 | N22: BF_Symbol | O22: 10000 | P22: 0 | Q22: 0 | R22: 0 | S22: 0 | T22: 0 | U22: 0 | V22: 0 | W22: 0 | X22: 0 | Y22: 0 | Z22: 0 | AA22: 0 | AB22: 0
B23: 18 | C23: 2 | D23: 2 | E23: 1 | F23: 0 | G23: 0
B24: 19 | C24: 0 | D24: 2 | E24: 0 | F24: 2 | G24: 0 | I24: Multiplier Range
I25: Multiplier | N25: Multiple Selection Weight - Reel3 After Eliminate (Weight/Total)
I26: 0 | N26: Worksheet Name \ Multiple | O26: 0 | P26: 2 | Q26: 3 | R26: 5 | S26: 8 | T26: 10 | U26: 15 | V26: 20 | W26: 25 | X26: 50 | Y26: 100 | Z26: 500 | AA26: 1000
I27: 2 | N27: BG_Symbol | O27: 10000 | P27: 0 | Q27: 0 | R27: 0 | S27: 0 | T27: 0 | U27: 0 | V27: 0 | W27: 0 | X27: 0 | Y27: 0 | Z27: 0 | AA27: 0 | AB27: 0
I28: 3 | N28: BG_Symbol (2) | O28: 0 | P28: 3500 | Q28: 3400 | R28: 1500 | S28: 1500 | T28: 20 | U28: 20 | V28: 5 | W28: 5 | X28: 5 | Y28: 20 | Z28: 5 | AA28: 20 | AB28: 6.2175
I29: 5 | N29: BG_Symbol (3) | O29: 10000 | P29: 0 | Q29: 0 | R29: 0 | S29: 0 | T29: 0 | U29: 0 | V29: 0 | W29: 0 | X29: 0 | Y29: 0 | Z29: 0 | AA29: 0 | AB29: 0
I30: 8 | N30: FG_Symbol | O30: 0 | P30: 5800 | Q30: 2800 | R30: 900 | S30: 300 | T30: 20 | U30: 20 | V30: 5 | W30: 5 | X30: 5 | Y30: 70 | Z30: 5 | AA30: 70 | AB30: 10.7375
I31: 10 | N31: FG_Symbol (2) | O31: 0 | P31: 5880 | Q31: 2800 | R31: 900 | S31: 300 | T31: 20 | U31: 20 | V31: 5 | W31: 5 | X31: 5 | Y31: 30 | Z31: 5 | AA31: 30 | AB31: 6.3535
I32: 15 | N32: FG_Symbol (3) | O32: 0 | P32: 5900 | Q32: 2800 | R32: 900 | S32: 300 | T32: 20 | U32: 20 | V32: 5 | W32: 5 | X32: 5 | Y32: 20 | Z32: 5 | AA32: 20 | AB32: 5.2575
I33: 20 | N33: BF_Symbol | O33: 10000 | P33: 0 | Q33: 0 | R33: 0 | S33: 0 | T33: 0 | U33: 0 | V33: 0 | W33: 0 | X33: 0 | Y33: 0 | Z33: 0 | AA33: 0 | AB33: 0
I34: 25
I35: 50
I36: 100 | N36: Multiple Selection Weight - Before Eliminate (Weight/Total)
I37: 500 | N37: Worksheet Name \ Multiple | O37: 0 | P37: 2 | Q37: 3 | R37: 5 | S37: 8 | T37: 10 | U37: 15 | V37: 20 | W37: 25 | X37: 50 | Y37: 100 | Z37: 500 | AA37: 1000
I38: 1000 | N38: BG_Symbol | O38: 8500 | P38: 500 | Q38: 400 | R38: 300 | S38: 300 | T38: 0 | U38: 0 | V38: 0 | W38: 0 | X38: 0 | Y38: 0 | Z38: 0 | AA38: 0 | AB38: 4.0666667
N39: BG_Symbol (2) | O39: 8500 | P39: 500 | Q39: 400 | R39: 300 | S39: 300 | T39: 0 | U39: 0 | V39: 0 | W39: 0 | X39: 0 | Y39: 0 | Z39: 0 | AA39: 0 | AB39: 4.0666667
N40: BG_Symbol (3) | O40: 8500 | P40: 500 | Q40: 400 | R40: 300 | S40: 300 | T40: 0 | U40: 0 | V40: 0 | W40: 0 | X40: 0 | Y40: 0 | Z40: 0 | AA40: 0 | AB40: 4.0666667
I41: Eliminate Table Weight | N41: FG_Symbol | O41: 6710 | P41: 2100 | Q41: 860 | R41: 220 | S41: 110 | T41: 0 | U41: 0 | V41: 0 | W41: 0 | X41: 0 | Y41: 0 | Z41: 0 | AA41: 0 | AB41: 2.662614
J42: A | K42: B | N42: FG_Symbol (2) | O42: 6710 | P42: 2100 | Q42: 860 | R42: 220 | S42: 110 | T42: 0 | U42: 0 | V42: 0 | W42: 0 | X42: 0 | Y42: 0 | Z42: 0 | AA42: 0 | AB42: 2.662614
...

Sheet Multiplier_Weight
B2: A | C2: Newbie | D2: Newbie | E2: Newbie | F2: Newbie | G2: Oldhand | H2: Oldhand | I2: Oldhand | J2: Oldhand | K2: Oldhand
B3: Range | C3: Weight_NB_BG | D3: Weight_NB_FG | E3: Weight_EB_BG | F3: Weight_EB_FG | G3: Weight_NB_BG | H3: Weight_NB_FG | I3: Weight_EB_BG | J3: Weight_EB_FG | K3: Weight_BF_FG
B4: (-1, 0] | C4: {=_xlfn.ANCHORARRAY(Multiplier_Weight_Newbie!L16)} -> 714982560 | D4: {=_xlfn.ANCHORARRAY(Multiplier_Weight_Newbie!L159)} -> 0 | E4: {=_xlfn.ANCHORARRAY(Multiplier_Weight_Newbie!L88)} -> 712373722 | F4: {=_xlfn.ANCHORARRAY(Multiplier_Weight_Newbie!L159)} -> 0 | G4: {=_xlfn.ANCHORARRAY(Multiplier_Weight_Oldhand!L16)} -> 715922996 | H4: {=_xlfn.ANCHORARRAY(Multiplier_Weight_Oldhand!L159)} -> 0 | I4: {=_xlfn.ANCHORARRAY(Multiplier_Weight_Oldhand!L88)} -> 711945709 | J4: {=_xlfn.ANCHORARRAY(Multiplier_Weight_Oldhand!L159)} -> 0 | K4: {=_xlfn.ANCHORARRAY(Multiplier_Weight_Oldhand!L229)} -> 0
B5: (0, 1] | C5: 160158655 | D5: 0 | E5: 157929170 | F5: 0 | G5: 160369316 | H5: 0 | I5: 157834282 | J5: 0 | K5: 0
B6: (1, 2] | C6: 45291493 | D6: 0 | E6: 44320090 | F6: 0 | G6: 45351066 | H6: 0 | I6: 44293462 | J6: 0 | K6: 0
B7: (2, 3] | C7: 21474133 | D7: 0 | E7: 21015991 | F7: 0 | G7: 21502379 | H7: 0 | I7: 21003364 | J7: 0 | K7: 0
B8: (3, 4] | C8: 11563125 | D8: 0 | E8: 8551620 | F8: 0 | G8: 11578334 | H8: 0 | I8: 8546482 | J8: 0 | K8: 0
B9: (4, 5] | C9: 9108389 | D9: 0 | E9: 6708476 | F9: 0 | G9: 9120370 | H9: 0 | I9: 6704446 | J9: 0 | K9: 0
B10: (5, 6] | C10: 7949728 | D10: 0 | E10: 5440871 | F10: 0 | G10: 7554765 | H10: 0 | I10: 5528426 | J10: 0 | K10: 0
B11: (6, 7] | C11: 3671230 | D11: 0 | E11: 3329350 | F11: 0 | G11: 3488834 | H11: 0 | I11: 3382926 | J11: 0 | K11: 0
B12: (7, 8] | C12: 3128381 | D12: 0 | E12: 2832078 | F12: 0 | G12: 2972955 | H12: 0 | I12: 2877652 | J12: 0 | K12: 0
B13: (8, 9] | C13: 2833105 | D13: 0 | E13: 2549049 | F13: 0 | G13: 2692349 | H13: 0 | I13: 2590069 | J13: 0 | K13: 0
B14: (9, 10] | C14: 2525352 | D14: 0 | E14: 2289719 | F14: 0 | G14: 2399886 | H14: 0 | I14: 2326565 | J14: 0 | K14: 0
B15: (10, 15] | C15: 3452326 | D15: 123594578 | E15: 3024773 | F15: 123594578 | G15: 3280806 | H15: 140656533 | I15: 3073448 | J15: 140656533 | K15: 124227685
B16: (15, 20] | C16: 5465497 | D16: 122562797 | E16: 3935552 | F16: 122562797 | G16: 5193957 | H16: 139482317 | I16: 3998883 | J16: 139482317 | K16: 123193249
... B67: (100000, 9999999] | C67: 0 | D67: 0 | E67: 0 | F67: 0 | G67: 0 | H67: 0 | I67: 0 | J67: 0 | K67: 0
B68: Free Game | C68: 4195668 | E68: 20978340 | G68: 4195668 | I68: 20978340

Sheet Multiplier_Weight_Newbie
A2: Threshold | B2: 1000000000
A3: Coin in | B3: =Overview!A7 -> 100
C5: RTP
B6: Bet | C6: Base Game | D6: Free Game | E6: Total | F6: Hit Rate | G6: FG Period | H6: Avg Multi | I6: BG | J6: FG
A7: Normal Bet | B7: {=Overview!B11:B12} -> 1 | C7: =SUM(N16:N80) -> 0.68999993 | D7: =SUM(_xlfn.ANCHORARRAY(N159))*F7 -> 0.23999958 | E7: =SUM(C7:D7) -> 0.92999951 | F7: =M80 -> 0.0041955691 | G7: =1/F7 -> 238.34669 | H7: =D7*G7 -> 57.203107 | I7: {=LOOKUP(2,1/(L16:L79<>0),B16:B79)} -> 60 | J7: {=LOOKUP(2,1/(_xlfn.ANCHORARRAY(L159)<>0),B16:B79)} -> 350
A8: Extra Bet | B8: 2 | C8: =SUM(_xlfn.ANCHORARRAY(N88))/B8 -> 0.33023183 | D8: =SUM(_xlfn.ANCHORARRAY(N159))*F8/B8 -> 0.5997682 | E8: =SUM(C8:D8) -> 0.93000003 | F8: =M152 -> 0.020969777 | G8: =1/F8 -> 47.687679 | H8: =D8*G8 -> 28.601553 | I8: {=LOOKUP(2,1/(L88:L151<>0),B16:B79)} -> 80
A12: Base Game
A14: Simulator | B14: =Multiplier_Weight_Oldhand!B14 -> 1000000000 | H14: Calculate
A15: Lower | B15: Upper | C15: Cnt | D15: Pay | E15: Hit Rate | F15: Avg. Multi. | H15: Range | I15: Fix Num | J15: Fix Rate | K15: Final Rate | L15: Weight | M15: Hit Rate | N15: Simulator RTP | P15: 目前 | Q15: 目前 | R15: 競品 | S15: 差異
A16: -1 | B16: 0 | C16: {=Multiplier_Weight_Oldhand!C16:D79} -> 738977283 | D16: 0 | E16: {=_xlfn.LET(_xlpm.x, C16:C79, _xlpm.x/SUM(_xlpm.x))} -> 0.74898554 | F16: {=_xlfn.LET(_xlpm.x, D16:D81/C16:C81/B3, IF(ISERR(_xlpm.x), 0, _xlpm.x))} -> 0 | G16: 1e-05 | H16: ="("&$A16&", "&$B16&"]" -> (-1, 0] | I16: 0.96 | J16: {=E16:E80*I16:I80} -> 0.71902612 | K16: {=J16:J79/SUM(_xlfn.ANCHORARRAY(J16))} -> 0.71498256 | L16: {=INT(K16:K80*$B$2)} -> 714982560 | M16: {=_xlfn.LET(_xlpm.x, L16:L80, _xlpm.x/SUM(_xlpm.x))} -> 0.7149657 | N16: {=M16:M80*F16:F80} -> 0 | P16: {=M16:M79} -> 0.7149657 | Q16: 0.72294875 | R16: 0.72554635 | S16: {=_xlfn.LET(_xlpm.x, Q16:Q79/M16:M79, IF(ISERR(_xlpm.x), 0, ROUND(_xlpm.x,2)))} -> 1.01
A17: 0 | B17: 1 | C17: 134671370 | D17: 5869389535 | E17: 0.13649528 | F17: 0.43583054 | G17: 5965 | H17: ="("&$A17&", "&$B17&"]" -> (0, 1] | I17: 1.18 | J17: 0.16106443 | K17: 0.16015866 | L17: 160158655 | M17: 0.16015488 | N17: 0.069800386 | P17: 0.16015488 | Q17: 0.16136085 | R17: 0.15905886 | S17: 1.01
A18: 1 | B18: 2 | C18: 34304589 | D18: 5136293060 | E18: 0.034769189 | F18: 1.4972612 | G18: =1+G17*G16 -> 1.05965 | H18: ="("&$A18&", "&$B18&"]" -> (1, 2] | I18: 1.31 | J18: 0.045547638 | K18: 0.045291494 | L18: 45291493 | M18: 0.045290425 | N18: 0.067811597 | P18: 0.045290425 | Q18: 0.045756935 | R18: 0.049788509 | S18: 1.01
A19: 2 | B19: 3 | C19: 16020309 | D19: 4033651395 | E19: 0.016237278 | F19: 2.5178362 | H19: ="("&$A19&", "&$B19&"]" -> (2, 3] | I19: 1.33 | J19: 0.02159558 | K19: 0.021474134 | L19: 21474133 | M19: 0.021473627 | N19: 0.054067074 | P19: 0.021473627 | Q19: 0.021758 | R19: 0.021457526 | S19: 1.01
A20: 3 | B20: 4 | C20: 7967455 | D20: 2842347285 | E20: 0.0080753613 | F20: 3.5674469 | H20: ="("&$A20&", "&$B20&"]" -> (3, 4] | I20: 1.44 | J20: 0.01162852 | K20: 0.011563125 | L20: 11563125 | M20: 0.011562852 | N20: 0.041249862 | P20: 0.011562852 | Q20: 0.0085068855 | R20: 0.0094289743 | S20: 0.74
A21: 4 | B21: 5 | C21: 5578706 | D21: 2564213210 | E21: 0.0056542606 | F21: 4.5964301 | H21: ="("&$A21&", "&$B21&"]" -> (4, 5] | I21: 1.62 | J21: 0.0091599021 | K21: 0.00910839 | L21: 9108389 | M21: 0.0091081742 | N21: 0.041865086 | P21: 0.0091081742 | Q21: 0.0066698354 | R21: 0.0062566091 | S21: 0.73
A22: 5 | B22: 6 | C22: 4158567 | D22: 2322704910 | E22: 0.0042148881 | F22: 5.5853493 | G22: 1.79 | H22: ="("&$A22&", "&$B22&"]" -> (5, 6] | I22: {=G22:G79*G18} -> 1.8967735 | J22: 0.007994688 | K22: 0.0079497286 | L22: 7949728 | M22: 0.0079495405 | N22: 0.04440096 | P22: 0.0079495405 | Q22: 0.0054541949 | R22: 0.0053753965 | S22: 0.69
A23: 6 | B23: 7 | C23: 2772263 | D23: 1818622450 | E23: 0.0028098088 | F23: 6.5600646 | G23: 1.24 | H23: ="("&$A23&", "&$B23&"]" -> (6, 7] | I23: 1.313966 | J23: 0.0036919933 | K23: 0.0036712308 | L23: 3671230 | M23: 0.0036711434 | N23: 0.024082938 | P23: 0.0036711434 | Q23: 0.0033318405 | R23: 0.0025114558 | S23: 0.91
A24: 7 | B24: 8 | C24: 2871865 | D24: 2188753410 | E24: 0.0029107598 | F24: 7.6213659 | G24: 1.02 | H24: ="("&$A24&", "&$B24&"]" -> (7, 8] | I24: 1.080843 | J24: 0.0031460743 | K24: 0.0031283819 | L24: 3128381 | M24: 0.0031283072 | N24: 0.023841974 | P24: 0.0031283072 | Q24: 0.00281562 | R24: 0.0030842439 | S24: 0.9
A25: 8 | B25: 9 | C25: 2105410 | D25: 1810360075 | E25: 0.0021339244 | F25: 8.5986106 | G25: 1.26 | H25: ="("&$A25&", "&$B25&"]" -> (8, 9] | I25: 1.335159 | J25: 0.0028491283 | K25: 0.0028331058 | L25: 2833105 | M25: 0.0028330382 | N25: 0.024360192 | P25: 0.0028330382 | Q25: 0.0025445965 | R25: 0.0026876983 | S25: 0.9
A26: 9 | B26: 10 | C26: 1954254 | D26: 1885134195 | E26: 0.0019807212 | F26: 9.646311 | G26: 1.21 | H26: ="("&$A26&", "&$B26&"]" -> (9, 10] | I26: 1.2821765 | J26: 0.0025396342 | K26: 0.0025253522 | L26: 2525352 | M26: 0.0025252924 | N26: 0.024359756 | P26: 0.0025252924 | Q26: 0.0022718729 | R26: 0.002247092 | S26: 0.9
A27: 10 | B27: 15 | C27: 6734651 | D27: 8382998890 | E27: 0.006825861 | F27: 12.447562 | G27: 0.48 | H27: ="("&$A27&", "&$B27&"]" -> (10, 15] | I27: 0.508632 | J27: 0.0034718513 | K27: 0.0034523268 | L27: 3452326 | M27: 0.0034522446 | N27: 0.04297203 | P27: 0.0034522446 | Q27: 0.0030238589 | R27: 0.0049788509 | S27: 0.88
A28: 15 | B28: 20 | C28: 4528931 | D28: 7919233365 | E28: 0.0045902681 | F28: 17.485878 | G28: 1.13 | H28: ="("&$A28&", "&$B28&"]" -> (15, 20] | I28: 1.1974045 | J28: 0.0054964076 | K28: 0.0054654977 | L28: 5465497 | M28: 0.0054653681 | N28: 0.095566758 | P28: 0.0054653681 | Q28: 0.0039646257 | R28: 0.0023352133 | S28: 0.73
A29: 20 | B29: 25 | C29: 3129796 | D29: 7054318865 | E29: 0.003172184 | F29: 22.539229 | G29: 0.54 | H29: ="("&$A29&", "&$B29&"]" -> (20, 25] | I29: 0.572211 | J29: 0.0018151586 | K29: 0.0018049508 | L29: 1804950 | M29: 0.0018049074 | N29: 0.040681222 | P29: 0.0018049074 | Q29: 0.0016558467 | R29: 0.0018064857 | S29: 0.92
A30: 25 | B30: 30 | C30: 2506990 | D30: 6905395465 | E30: 0.0025409431 | F30: 27.544567 | G30: 0.2 | H30: ="("&$A30&", "&$B30&"]" -> (25, 30] | I30: 0.21193 | J30: 0.00053850208 | K30: 0.00053547373 | L30: 535473 | M30: 0.00053546037 | N30: 0.014749024 | P30: 0.00053546037 | Q30: 0.00067090937 | R30: 0.00088121255 | S30: 1.25
A31: 30 | B31: 35 | C31: 1878754 | D31: 6111962030 | E31: 0.0019041987 | F31: 32.531997 | G31: 0.22 | H31: ="("&$A31&", "&$B31&"]" -> (30, 35] | I31: 0.233123 | J31: 0.00044391251 | K31: 0.0004414161 | L31: 441416 | M31: 0.00044140559 | N31: 0.014359806 | P31: 0.00044140559 | Q31: 0.00056786647 | R31: 0.0004846669 | S31: 1.29
A32: 35 | B32: 40 | C32: 1621830 | D32: 6089148510 | E32: 0.0016437951 | F32: 37.544925 | G32: 0.33 | H32: ="("&$A32&", "&$B32&"]" -> (35, 40] | I32: 0.3496845 | J32: 0.00057480966 | K32: 0.00057157713 | L32: 571577 | M32: 0.00057156352 | N32: 0.021459309 | P32: 0.00057156352 | Q32: 0.00097218159 | R32: 0.00070497004 | S32: 1.7
A33: 40 | B33: 45 | C33: 1336896 | D33: 5698648415 | E33: 0.0013550021 | F33: 42.625967 | G33: 0.16 | H33: ="("&$A33&", "&$B33&"]" -> (40, 45] | I33: 0.169544 | J33: 0.00022973248 | K33: 0.00022844054 | L33: 228440 | M33: 0.00022843461 | N33: 0.0097372462 | P33: 0.00022843461 | Q33: 0.00022260373 | R33: 0.00035248502 | S33: 0.97
A34: 45 | B34: 50 | C34: 1129963 | D34: 5386108480 | E34: 0.0011452665 | F34: 47.666238 | G34: 0.2 | H34: ="("&$A34&", "&$B34&"]" -> (45, 50] | I34: 0.21193 | J34: 0.00024271633 | K34: 0.00024135138 | L34: 241351 | M34: 0.00024134531 | N34: 0.011504023 | P34: 0.00024134531 | Q34: 0.00021215213 | R34: 0.00013218188 | S34: 0.88
... A79: 100000 | B79: 9999999 | C79: 156 | D79: 1792140330 | E79: 1.5811277e-07 | F79: 114880.79 | G79: 0 | H79: ="("&$A79&", "&$B79&"]" -> (100000, 9999999] | I79: 0 | J79: 0 | K79: 0 | L79: 0 | M79: 0 | N79: 0 | P79: 0 | Q79: 0 | R79: 0 | S79: 0
A80: Free Game | C80: =E80*B14 -> 13362000 | D80: {=Multiplier_Weight_Oldhand!D80:D81} -> 360008300 | E80: =Multiplier_Weight_Oldhand!E80 -> 0.013362 | F80: 0.26942696 | H80: Free Game | I80: 0.314 | J80: 0.004195668 | K80: =J80 -> 0.004195668 | L80: 4195668 | M80: 0.0041955691 | N80: 0.0011303994
A81: Buy Feature | C81: 10000000 | D81: 0 | E81: 1 | F81: 0 | H81: Buy Feature | M81: =E81 -> 1 | N81: =F81/B9 -> #DIV/0!
A84: Extra Bet
A86: Simulator | B86: 1000000000 | H86: Calculate
A87: Lower | B87: Upper | C87: Cnt | D87: Pay | E87: Hit Rate | F87: Avg. Multi. | H87: Range | I87: Fix Num | J87: Fix Rate | K87: Final Rate | L87: Weight | M87: Hit Rate | N87: Simulator RTP | P87: 目前 | Q87: 目前 | R87: 競品 | S87: 差異
A88: -1 | B88: 0 | C88: {=C16:D79} -> 738977283 | D88: 0 | E88: {=_xlfn.LET(_xlpm.x, C88:C151, _xlpm.x/SUM(_xlpm.x))} -> 0.74898554 | F88: {=_xlfn.LET(_xlpm.x, D88:D152/C88:C152/B3, IF(ISERR(_xlpm.x), 0, _xlpm.x))} -> 0 | G88: 1e-05 | H88: ="("&$A88&", "&$B88&"]" -> (-1, 0] | I88: 0.97 | J88: {=E88:E152*I88:I152} -> 0.72651597 | K88: {=J88:J151/SUM(_xlfn.ANCHORARRAY(J88))} -> 0.71237372 | L88: {=INT(K88:K152*$B$2)} -> 712373722 | M88: {=_xlfn.LET(_xlpm.x, L88:L152, _xlpm.x/SUM(_xlpm.x))} -> 0.71208294 | N88: {=M88:M152*F88:F152} -> 0 | P88: {=M88:M151} -> 0.71208294 | Q88: 0.72294875 | S88: {=_xlfn.LET(_xlpm.x, Q88:Q151/M88:M151, IF(ISERR(_xlpm.x), 0, ROUND(_xlpm.x,2)))} -> 1.02
A89: 0 | B89: 1 | C89: 134671370 | D89: 5869389535 | E89: 0.13649528 | F89: 0.43583054 | G89: -1754 | H89: ="("&$A89&", "&$B89&"]" -> (0, 1] | I89: 1.18 | J89: 0.16106443 | K89: 0.15792917 | L89: 157929170 | M89: 0.15786471 | N89: 0.06880226 | P89: 0.15786471 | Q89: 0.16136085 | S89: 1.02
A90: 1 | B90: 2 | C90: 34304589 | D90: 5136293060 | E90: 0.034769189 | F90: 1.4972612 | G90: =1+G89*G88 -> 0.98246 | H90: ="("&$A90&", "&$B90&"]" -> (1, 2] | I90: 1.3 | J90: 0.045199946 | K90: 0.044320091 | L90: 44320090 | M90: 0.044301999 | N90: 0.066331665 | P90: 0.044301999 | Q90: 0.045756935 | S90: 1.03
A91: 2 | B91: 3 | C91: 16020309 | D91: 4033651395 | E91: 0.016237278 | F91: 2.5178362 | H91: ="("&$A91&", "&$B91&"]" -> (2, 3] | I91: 1.32 | J91: 0.021433207 | K91: 0.021015992 | L91: 21015991 | M91: 0.021007413 | N91: 0.052893224 | P91: 0.021007413 | Q91: 0.021758 | S91: 1.04
A92: 3 | B92: 4 | C92: 7967455 | D92: 2842347285 | E92: 0.0080753613 | F92: 3.5674469 | H92: ="("&$A92&", "&$B92&"]" -> (3, 4] | I92: 1.08 | J92: 0.0087213902 | K92: 0.008551621 | L92: 8551620 | M92: 0.0085481294 | N92: 0.030494998 | P92: 0.0085481294 | Q92: 0.0085068855 | S92: 1
A93: 4 | B93: 5 | C93: 5578706 | D93: 2564213210 | E93: 0.0056542606 | F93: 4.5964301 | H93: ="("&$A93&", "&$B93&"]" -> (4, 5] | I93: 1.21 | J93: 0.0068416553 | K93: 0.0067084767 | L93: 6708476 | M93: 0.0067057377 | N93: 0.030822455 | P93: 0.0067057377 | Q93: 0.0066698354 | S93: 0.99
...

Sheet Multiplier_Weight_Oldhand
A2: Threshold | B2: 1000000000
A3: Coin in | B3: =Overview!A7 -> 100
C5: RTP
B6: Bet | C6: Base Game | D6: Free Game | E6: Total | F6: Hit Rate | G6: FG Period | H6: Avg Multi | I6: BG | J6: FG
A7: Normal Bet | B7: {=Overview!B11:B13} -> 1 | C7: =SUM(N16:N80) -> 0.69999982 | D7: =SUM(_xlfn.ANCHORARRAY(N159))*F7 -> 0.2400004 | E7: =SUM(C7:D7) -> 0.94000021 | F7: =M80 -> 0.0041955921 | G7: =1/F7 -> 238.34538 | H7: =D7*G7 -> 57.202986 | I7: {=LOOKUP(2,1/(L16:L79<>0),B16:B79)} -> 120 | J7: {=LOOKUP(2,1/(_xlfn.ANCHORARRAY(L159)<>0),B16:B79)} -> 20000
A8: Extra Bet | B8: 2 | C8: =SUM(_xlfn.ANCHORARRAY(N88))/B8 -> 0.34024087 | D8: =SUM(_xlfn.ANCHORARRAY(N159))*F8/B8 -> 0.59975952 | E8: =SUM(C8:D8) -> 0.9400004 | F8: =M152 -> 0.020969518 | G8: =1/F8 -> 47.688268 | H8: =D8*G8 -> 28.601493 | I8: {=LOOKUP(2,1/(L88:L151<>0),B16:B79)} -> 120 | J8: =J7 -> 20000
A9: Buy Feature | B9: 75 | C9: =N81 -> 0 | D9: =SUM(_xlfn.ANCHORARRAY(N229))/B9 -> 0.92500032 | E9: =SUM(C9:D9) -> 0.92500032 | F9: =E81 -> 1 | G9: =1/F9 -> 1 | H9: =D9*G9*B9 -> 69.375024 | J9: {=LOOKUP(2,1/(_xlfn.ANCHORARRAY(L229)<>0),B16:B79)} -> 20000
A12: Base Game
A14: Simulator | B14: 1000000000 | C14: H026192_2606171759_betmode0 | H14: Calculate
A15: Lower | B15: Upper | C15: Cnt | D15: Pay | E15: Hit Rate | F15: Avg. Multi. | H15: Range | I15: Fix Num | J15: Fix Rate | K15: Final Rate | L15: Weight | M15: Hit Rate | N15: Simulator RTP | P15: 目前 | Q15: 目前 | R15: 競品 | S15: 差異
A16: -1 | B16: 0 | C16: 738977283 | D16: 0 | E16: {=_xlfn.LET(_xlpm.x, C16:C79, _xlpm.x/SUM(_xlpm.x))} -> 0.74898554 | F16: {=_xlfn.LET(_xlpm.x, D16:D81/C16:C81/B3, IF(ISERR(_xlpm.x), 0, _xlpm.x))} -> 0 | G16: 1e-06 | H16: ="("&$A16&", "&$B16&"]" -> (-1, 0] | I16: 0.96 | J16: {=E16:E80*I16:I80} -> 0.71902612 | K16: {=J16:J79/SUM(_xlfn.ANCHORARRAY(J16))} -> 0.715923 | L16: {=INT(K16:K80*$B$2)} -> 715922996 | M16: {=_xlfn.LET(_xlpm.x, L16:L80, _xlpm.x/SUM(_xlpm.x))} -> 0.71591004 | N16: {=M16:M80*F16:F80} -> 0 | P16: {=M16:M79} -> 0.71591004 | Q16: 0.7159752 | R16: 0.72554635 | S16: {=_xlfn.LET(_xlpm.x, Q16:Q79/M16:M79, IF(ISERR(_xlpm.x), 0, ROUND(_xlpm.x,2)))} -> 1
A17: 0 | B17: 1 | C17: 134671370 | D17: 5869389535 | E17: 0.13649528 | F17: 0.43583054 | G17: 5681 | H17: ="("&$A17&", "&$B17&"]" -> (0, 1] | I17: 1.18 | J17: 0.16106443 | K17: 0.16036932 | L17: 160369316 | M17: 0.16036641 | N17: 0.06989258 | P17: 0.16036641 | Q17: 0.16050309 | R17: 0.15905886 | S17: 1
A18: 1 | B18: 2 | C18: 34304589 | D18: 5136293060 | E18: 0.034769189 | F18: 1.4972612 | G18: =1+G17*G16 -> 1.005681 | H18: ="("&$A18&", "&$B18&"]" -> (1, 2] | I18: 1.31 | J18: 0.045547638 | K18: 0.045351067 | L18: 45351066 | M18: 0.045350245 | N18: 0.067901163 | P18: 0.045350245 | Q18: 0.045308267 | R18: 0.049788509 | S18: 1
A19: 2 | B19: 3 | C19: 16020309 | D19: 4033651395 | E19: 0.016237278 | F19: 2.5178362 | H19: ="("&$A19&", "&$B19&"]" -> (2, 3] | I19: 1.33 | J19: 0.02159558 | K19: 0.021502379 | L19: 21502379 | M19: 0.02150199 | N19: 0.054138489 | P19: 0.02150199 | Q19: 0.02147935 | R19: 0.021457526 | S19: 1
A20: 3 | B20: 4 | C20: 7967455 | D20: 2842347285 | E20: 0.0080753613 | F20: 3.5674469 | H20: ="("&$A20&", "&$B20&"]" -> (3, 4] | I20: 1.44 | J20: 0.01162852 | K20: 0.011578335 | L20: 11578334 | M20: 0.011578124 | N20: 0.041304345 | P20: 0.011578124 | Q20: 0.01161089 | R20: 0.0094289743 | S20: 1
A21: 4 | B21: 5 | C21: 5578706 | D21: 2564213210 | E21: 0.0056542606 | F21: 4.5964301 | H21: ="("&$A21&", "&$B21&"]" -> (4, 5] | I21: 1.62 | J21: 0.0091599021 | K21: 0.0091203705 | L21: 9120370 | M21: 0.009120205 | N21: 0.041920384 | P21: 0.009120205 | Q21: 0.0091491637 | R21: 0.0062566091 | S21: 1
A22: 5 | B22: 6 | C22: 4158567 | D22: 2322704910 | E22: 0.0042148881 | F22: 5.5853493 | G22: 1.79 | H22: ="("&$A22&", "&$B22&"]" -> (5, 6] | I22: {=G22:G79*G18} -> 1.800169 | J22: 0.0075875108 | K22: 0.0075547652 | L22: 7554765 | M22: 0.0075546283 | N22: 0.042195237 | P22: 0.0075546283 | Q22: 0.0075282778 | R22: 0.0053753965 | S22: 1
A23: 6 | B23: 7 | C23: 2772263 | D23: 1818622450 | E23: 0.0028098088 | F23: 6.5600646 | G23: 1.24 | H23: ="("&$A23&", "&$B23&"]" -> (6, 7] | I23: 1.2470444 | J23: 0.0035039565 | K23: 0.0034888344 | L23: 3488834 | M23: 0.0034887709 | N23: 0.022886562 | P23: 0.0034887709 | Q23: 0.003476954 | R23: 0.0025114558 | S23: 1
A24: 7 | B24: 8 | C24: 2871865 | D24: 2188753410 | E24: 0.0029107598 | F24: 7.6213659 | G24: 1.02 | H24: ="("&$A24&", "&$B24&"]" -> (7, 8] | I24: 1.0257946 | J24: 0.0029858417 | K24: 0.0029729556 | L24: 2972955 | M24: 0.0029729012 | N24: 0.022657568 | P24: 0.0029729012 | Q24: 0.0029606601 | R24: 0.0030842439 | S24: 1
A25: 8 | B25: 9 | C25: 2105410 | D25: 1810360075 | E25: 0.0021339244 | F25: 8.5986106 | G25: 1.26 | H25: ="("&$A25&", "&$B25&"]" -> (8, 9] | I25: 1.2671581 | J25: 0.0027040195 | K25: 0.0026923497 | L25: 2692349 | M25: 0.0026923003 | N25: 0.023150042 | P25: 0.0026923003 | Q25: 0.0026694709 | R25: 0.0026876983 | S25: 0.99
A26: 9 | B26: 10 | C26: 1954254 | D26: 1885134195 | E26: 0.0019807212 | F26: 9.646311 | G26: 1.21 | H26: ="("&$A26&", "&$B26&"]" -> (9, 10] | I26: 1.216874 | J26: 0.0024102882 | K26: 0.002399886 | L26: 2399886 | M26: 0.0023998426 | N26: 0.023149628 | P26: 0.0023998426 | Q26: 0.0023901201 | R26: 0.002247092 | S26: 1
A27: 10 | B27: 15 | C27: 6734651 | D27: 8382998890 | E27: 0.006825861 | F27: 12.447562 | G27: 0.48 | H27: ="("&$A27&", "&$B27&"]" -> (10, 15] | I27: 0.48272688 | J27: 0.0032950266 | K27: 0.0032808061 | L27: 3280806 | M27: 0.0032807466 | N27: 0.040837299 | P27: 0.0032807466 | Q27: 0.003255352 | R27: 0.0049788509 | S27: 0.99
A28: 15 | B28: 20 | C28: 4528931 | D28: 7919233365 | E28: 0.0045902681 | F28: 17.485878 | G28: 1.13 | H28: ="("&$A28&", "&$B28&"]" -> (15, 20] | I28: 1.1364195 | J28: 0.0052164703 | K28: 0.0051939574 | L28: 5193957 | M28: 0.005193863 | N28: 0.090819253 | P28: 0.005193863 | Q28: 0.0051523509 | R28: 0.0023352133 | S28: 0.99
A29: 20 | B29: 25 | C29: 3129796 | D29: 7054318865 | E29: 0.003172184 | F29: 22.539229 | G29: 0.54 | H29: ="("&$A29&", "&$B29&"]" -> (20, 25] | I29: 0.54306774 | J29: 0.0017227108 | K29: 0.0017152761 | L29: 1715276 | M29: 0.001715245 | N29: 0.038660299 | P29: 0.001715245 | Q29: 0.0017133369 | R29: 0.0018064857 | S29: 1
A30: 25 | B30: 30 | C30: 2506990 | D30: 6905395465 | E30: 0.0025409431 | F30: 27.544567 | G30: 0.2 | H30: ="("&$A30&", "&$B30&"]" -> (25, 30] | I30: 0.2011362 | J30: 0.00051107565 | K30: 0.00050886998 | L30: 508869 | M30: 0.00050885979 | N30: 0.014016323 | P30: 0.00050885979 | Q30: 0.000496778 | R30: 0.00088121255 | S30: 0.98
A31: 30 | B31: 35 | C31: 1878754 | D31: 6111962030 | E31: 0.0019041987 | F31: 32.531997 | G31: 0.22 | H31: ="("&$A31&", "&$B31&"]" -> (30, 35] | I31: 0.22124982 | J31: 0.00042130362 | K31: 0.00041948539 | L31: 419485 | M31: 0.00041947741 | N31: 0.013646438 | P31: 0.00041947741 | Q31: 0.00041474146 | R31: 0.0004846669 | S31: 0.99
A32: 35 | B32: 40 | C32: 1621830 | D32: 6089148510 | E32: 0.0016437951 | F32: 37.544925 | G32: 0.33 | H32: ="("&$A32&", "&$B32&"]" -> (35, 40] | I32: 0.33187473 | J32: 0.00054553405 | K32: 0.00054317967 | L32: 543179 | M32: 0.00054316917 | N32: 0.020393246 | P32: 0.00054316917 | Q32: 0.00053879471 | R32: 0.00070497004 | S32: 0.99
A33: 40 | B33: 45 | C33: 1336896 | D33: 5698648415 | E33: 0.0013550021 | F33: 42.625967 | G33: 0.16 | H33: ="("&$A33&", "&$B33&"]" -> (40, 45] | I33: 0.16090896 | J33: 0.00021803198 | K33: 0.00021709101 | L33: 217091 | M33: 0.00021708707 | N33: 0.0092535462 | P33: 0.00021708707 | Q33: 0.00022212093 | R33: 0.00035248502 | S33: 1.02
A34: 45 | B34: 50 | C34: 1129963 | D34: 5386108480 | E34: 0.0011452665 | F34: 47.666238 | G34: 0.2 | H34: ="("&$A34&", "&$B34&"]" -> (45, 50] | I34: 0.2011362 | J34: 0.00023035456 | K34: 0.00022936041 | L34: 229360 | M34: 0.00022935585 | N34: 0.01093253 | P34: 0.00022935585 | Q34: 0.00022429881 | R34: 0.00013218188 | S34: 0.98
... A79: 100000 | B79: 9999999 | C79: 156 | D79: 1792140330 | E79: 1.5811277e-07 | F79: 114880.79 | G79: 0 | H79: ="("&$A79&", "&$B79&"]" -> (100000, 9999999] | I79: 0 | J79: 0 | K79: 0 | L79: 0 | M79: 0 | N79: 0 | P79: 0 | Q79: 0 | R79: 0 | S79: 0
A80: Free Game | C80: =E80*B14 -> 13362000 | D80: 360008300 | E80: 0.013362 | F80: 0.26942696 | H80: Free Game | I80: 0.314 | J80: 0.004195668 | K80: =J80 -> 0.004195668 | L80: 4195668 | M80: 0.0041955921 | N80: 0.0011304056
A81: Buy Feature | C81: 10000000 | D81: 0 | E81: 1 | F81: 0 | H81: Buy Feature | M81: =E81 -> 1 | N81: =F81/B9 -> 0
K82: =1/K80 -> 238.34107
A84: Extra Bet
A86: Simulator | B86: 1000000000 | H86: Calculate
A87: Lower | B87: Upper | C87: Cnt | D87: Pay | E87: Hit Rate | F87: Avg. Multi. | H87: Range | I87: Fix Num | J87: Fix Rate | K87: Final Rate | L87: Weight | M87: Hit Rate | N87: Simulator RTP | P87: 目前 | Q87: 目前 | R87: 競品 | S87: 差異
A88: -1 | B88: 0 | C88: {=C16:D79} -> 738977283 | D88: 0 | E88: {=_xlfn.LET(_xlpm.x, C88:C151, _xlpm.x/SUM(_xlpm.x))} -> 0.74898554 | F88: {=_xlfn.LET(_xlpm.x, D88:D152/C88:C152/B3, IF(ISERR(_xlpm.x), 0, _xlpm.x))} -> 0 | G88: 1e-06 | H88: ="("&$A88&", "&$B88&"]" -> (-1, 0] | I88: 0.97 | J88: {=E88:E152*I88:I152} -> 0.72651597 | K88: {=J88:J151/SUM(_xlfn.ANCHORARRAY(J88))} -> 0.71194571 | L88: {=INT(K88:K152*$B$2)} -> 711945709 | M88: {=_xlfn.LET(_xlpm.x, L88:L152, _xlpm.x/SUM(_xlpm.x))} -> 0.71164631 | N88: {=M88:M152*F88:F152} -> 0 | P88: {=M88:M151} -> 0.71164631 | Q88: 0.71129078 | S88: {=_xlfn.LET(_xlpm.x, Q88:Q151/M88:M151, IF(ISERR(_xlpm.x), 0, ROUND(_xlpm.x,2)))} -> 1
A89: 0 | B89: 1 | C89: 134671370 | D89: 5869389535 | E89: 0.13649528 | F89: 0.43583054 | G89: -1130 | H89: ="("&$A89&", "&$B89&"]" -> (0, 1] | I89: 1.18 | J89: 0.16106443 | K89: 0.15783428 | L89: 157834282 | M89: 0.15776791 | N89: 0.068760072 | P89: 0.15776791 | Q89: 0.15819743 | S89: 1
A90: 1 | B90: 2 | C90: 34304589 | D90: 5136293060 | E90: 0.034769189 | F90: 1.4972612 | G90: =1+G89*G88 -> 0.99887 | H90: ="("&$A90&", "&$B90&"]" -> (1, 2] | I90: 1.3 | J90: 0.045199946 | K90: 0.044293462 | L90: 44293462 | M90: 0.044274835 | N90: 0.066290994 | P90: 0.044274835 | Q90: 0.044334958 | S90: 1
A91: 2 | B91: 3 | C91: 16020309 | D91: 4033651395 | E91: 0.016237278 | F91: 2.5178362 | H91: ="("&$A91&", "&$B91&"]" -> (2, 3] | I91: 1.32 | J91: 0.021433207 | K91: 0.021003365 | L91: 21003364 | M91: 0.020994531 | N91: 0.052860791 | P91: 0.020994531 | Q91: 0.021022686 | S91: 1
...

Sheet OP Jackpot
B2: Threshold | C2: 10000000000
B4: Status | C4: Bet Type | D4: Screen | E4: Spin | F4: C1 cnt | G4: SCR
B5: Newbie | C5: Normal Bet | D5: BG | E5: 100000000 | G5: =SUM(F5:F6)/E5*$C$2 -> 0
D6: FG
B7: Newbie | C7: Extra Bet | D7: BG | E7: 100000000 | G7: =SUM(F7:F8)/E7*$C$2 -> 0
D8: FG
B9: Oldhand | C9: Normal Bet | D9: BG | E9: 100000000 | F9: 32841031 | G9: =SUM(F9:F10)/E9*$C$2 -> 3409747100 | H9: H026194A_2004_2607010001_betmode0_108_9402_oldhand_card.xlsx
D10: FG | F10: 1256440
B11: Oldhand | C11: Extra Bet | D11: BG | E11: 100000000 | F11: 34003101 | G11: =SUM(F11:F12)/E11*$C$2 -> 4.0280099e+09 | H11: H026194A_2004_2607010103_betmode1_108_9393_oldhand_card.xlsx
D12: FG | F12: 6276998
B13: Oldhand | C13: Buy Feature | D13: BG | E13: =F13 -> 10000000 | F13: 10000000 | G13: =SUM(F13:F14)/E13*$C$2 -> 41001664000 | H13: H026194A_2004_2607010454_betmode2_107_9260_card.xlsx
D14: FG | F14: 31001664

Sheet BG_Symbol
J2: Symbol | Q2: Symbol ID | W2: Symbol Weight | AC2: Eliminate Wheel Weight A | AJ2: Eliminate Wheel Weight B
A3: Symbol | B3: Description | C3: R1 | D3: R2 | E3: R3 | F3: R4 | G3: R5 | H3: ID | K3: R1 | L3: R2 | M3: R3 | N3: R4 | O3: R5 | Q3: R1 | R3: R2 | S3: R3 | T3: R4 | U3: R5 | W3: R1 | X3: R2 | Y3: R3 | Z3: R4 | AA3: R5
A4: WW | B4: Wild | C4: 0 | D4: 0 | E4: 0 | F4: 0 | G4: 0 | H4: 0 | J4: 0 | K4: M4 | L4: G5 | M4: M5 | N4: J | O4: A | Q4: 5 | R4: 15 | S4: 6 | T4: 10 | U4: 7 | W4: 2 | X4: 1 | Y4: 1 | Z4: 2 | AA4: 1 | AC4: 1 Combo | AJ4: 1 Combo
A5: C1 | B5: Scatter | C5: 0 | D5: 6 | E5: 0 | F5: 9 | G5: 0 | H5: 1 | J5: 1 | K5: M5 | L5: GK | M5: M4 | N5: J | O5: M3 | Q5: 6 | R5: 17 | S5: 5 | T5: 10 | U5: 4 | W5: 1 | X5: 1 | Y5: 1 | Z5: 2 | AA5: 2 | AC5: Symbol | AD5: R1 | AE5: R2 | AF5: R3 | AG5: R4 | AH5: R5 | AJ5: Symbol | AK5: R1 | AL5: R2 | AM5: R3 | AN5: R4 | AO5: R5
A6: M1 | B6: M1 | C6: 4 | D6: 22 | E6: 5 | F6: 21 | G6: 23 | H6: 2 | J6: 2 | K6: J | L6: C1 | M6: K | N6: GJ | O6: M1 | Q6: 10 | R6: 1 | S6: 8 | T6: 19 | U6: 2 | W6: 1 | X6: 2 | Y6: 1 | Z6: 2 | AA6: 1 | AC6: WW | AD6: 0 | AE6: 0 | AF6: 0 | AG6: 0 | AH6: 0 | AJ6: WW | AK6: 0 | AL6: 0 | AM6: 0 | AN6: 0 | AO6: 0
A7: M2 | B7: M2 | C7: 4 | D7: 10 | E7: 5 | F7: 21 | G7: 23 | H7: 3 | J7: 3 | K7: A | L7: J | M7: M4 | N7: M1 | O7: M4 | Q7: 7 | R7: 10 | S7: 5 | T7: 2 | U7: 5 | W7: 1 | X7: 1 | Y7: 2 | Z7: 2 | AA7: 1 | AC7: C1 | AD7: 0 | AE7: 6 | AF7: 0 | AG7: 9 | AH7: 0 | AJ7: C1 | AK7: 0 | AL7: 6 | AM7: 0 | AN7: 9 | AO7: 0
A8: M3 | B8: M3 | C8: 4 | D8: 9 | E8: 5 | F8: 21 | G8: 22 | H8: 4 | J8: 4 | K8: M5 | L8: G1 | M8: M3 | N8: G2 | O8: A | Q8: 6 | R8: 11 | S8: 4 | T8: 12 | U8: 7 | W8: 1 | X8: 1 | Y8: 1 | Z8: 2 | AA8: 1 | AC8: M1 | AD8: 4 | AE8: 22 | AF8: 5 | AG8: 21 | AH8: 23 | AJ8: M1 | AK8: 4 | AL8: 22 | AM8: 5 | AN8: 21 | AO8: 23
A9: M4 | B9: M4 | C9: 43 | D9: 13 | E9: 41 | F9: 14 | G9: 22 | H9: 5 | J9: 5 | K9: K | L9: K | M9: M4 | N9: M1 | O9: K | Q9: 8 | R9: 8 | S9: 5 | T9: 2 | U9: 8 | W9: 1 | X9: 1 | Y9: 1 | Z9: 2 | AA9: 1 | AC9: M2 | AD9: 4 | AE9: 10 | AF9: 5 | AG9: 21 | AH9: 23 | AJ9: M2 | AK9: 4 | AL9: 10 | AM9: 5 | AN9: 21 | AO9: 23
A10: M5 | B10: M5 | C10: 43 | D10: 14 | E10: 41 | F10: 14 | G10: 22 | H10: 6 | J10: 6 | K10: M5 | L10: G1 | M10: A | N10: M4 | O10: A | Q10: 6 | R10: 11 | S10: 7 | T10: 5 | U10: 7 | W10: 1 | X10: 2 | Y10: 1 | Z10: 2 | AA10: 1 | AC10: M3 | AD10: 4 | AE10: 9 | AF10: 5 | AG10: 21 | AH10: 22 | AJ10: M3 | AK10: 4 | AL10: 9 | AM10: 5 | AN10: 21 | AO10: 22
A11: A | B11: A | C11: 47 | D11: 14 | E11: 41 | F11: 14 | G11: 22 | H11: 7 | J11: 7 | K11: K | L11: G1 | M11: M4 | N11: C1 | O11: A | Q11: 8 | R11: 11 | S11: 5 | T11: 1 | U11: 7 | W11: 1 | X11: 2 | Y11: 2 | Z11: 2 | AA11: 1 | AC11: M4 | AD11: 43 | AE11: 13 | AF11: 41 | AG11: 14 | AH11: 22 | AJ11: M4 | AK11: 43 | AL11: 13 | AM11: 41 | AN11: 14 | AO11: 22
A12: K | B12: K | C12: 47 | D12: 18 | E12: 41 | F12: 14 | G12: 22 | H12: 8 | J12: 8 | K12: M5 | L12: J | M12: M5 | N12: Q | O12: M3 | Q12: 6 | R12: 10 | S12: 6 | T12: 9 | U12: 4 | W12: 1 | X12: 2 | Y12: 2 | Z12: 2 | AA12: 2 | AC12: M5 | AD12: 43 | AE12: 14 | AF12: 41 | AG12: 14 | AH12: 22 | AJ12: M5 | AK12: 43 | AL12: 14 | AM12: 41 | AN12: 14 | AO12: 22
A13: Q | B13: Q | C13: 4 | D13: 5 | E13: 5 | F13: 20 | G13: 22 | H13: 9 | J13: 9 | K13: K | L13: M3 | M13: Q | N13: Q | O13: M5 | Q13: 8 | R13: 4 | S13: 9 | T13: 9 | U13: 6 | W13: 1 | X13: 2 | Y13: 1 | Z13: 2 | AA13: 1 | AC13: A | AD13: 47 | AE13: 14 | AF13: 41 | AG13: 14 | AH13: 22 | AJ13: A | AK13: 47 | AL13: 14 | AM13: 41 | AN13: 14 | AO13: 22
A14: J | B14: J | C14: 4 | D14: 9 | E14: 4 | F14: 20 | G14: 22 | H14: 10 | J14: 10 | K14: M5 | L14: M1 | M14: M5 | N14: J | O14: Q | Q14: 6 | R14: 2 | S14: 6 | T14: 10 | U14: 9 | W14: 2 | X14: 2 | Y14: 1 | Z14: 1 | AA14: 1 | AC14: K | AD14: 47 | AE14: 18 | AF14: 41 | AG14: 14 | AH14: 22 | AJ14: K | AK14: 47 | AL14: 18 | AM14: 41 | AN14: 14 | AO14: 22
A15: G1 | B15: Rainbow M1 | C15: 0 | D15: 16 | E15: 0 | F15: 4 | G15: 0 | H15: 11 | J15: 11 | K15: M5 | L15: GQ | M15: K | N15: M2 | O15: K | Q15: 6 | R15: 18 | S15: 8 | T15: 3 | U15: 8 | W15: 1 | X15: 1 | Y15: 1 | Z15: 1 | AA15: 1 | AC15: Q | AD15: 4 | AE15: 5 | AF15: 5 | AG15: 20 | AH15: 22 | AJ15: Q | AK15: 4 | AL15: 5 | AM15: 5 | AN15: 20 | AO15: 22
A16: G2 | B16: Rainbow M2 | C16: 0 | D16: 5 | E16: 0 | F16: 4 | G16: 0 | H16: 12 | J16: 12 | K16: M5 | L16: M4 | M16: M5 | N16: A | O16: K | Q16: 6 | R16: 5 | S16: 6 | T16: 7 | U16: 8 | W16: 1 | X16: 1 | Y16: 1 | Z16: 1 | AA16: 1 | AC16: J | AD16: 4 | AE16: 9 | AF16: 4 | AG16: 20 | AH16: 22 | AJ16: J | AK16: 4 | AL16: 9 | AM16: 4 | AN16: 20 | AO16: 22
A17: G3 | B17: Rainbow M3 | C17: 0 | D17: 7 | E17: 0 | F17: 4 | G17: 0 | H17: 13 | J17: 13 | K17: K | L17: GA | M17: K | N17: M4 | O17: M3 | Q17: 8 | R17: 16 | S17: 8 | T17: 5 | U17: 4 | W17: 1 | X17: 1 | Y17: 1 | Z17: 2 | AA17: 1 | AC17: G1 | AD17: 0 | AE17: 48 | AF17: 0 | AG17: 12 | AH17: 0 | AJ17: G1 | AK17: 0 | AL17: 48 | AM17: 0 | AN17: 12 | AO17: 0
... A23: GJ | B23: Rainbow J | C23: 0 | D23: 6 | E23: 0 | F23: 4 | G23: 0 | H23: 19 | J23: 19 | K23: K | L23: GA | M23: A | N23: Q | O23: M2 | Q23: 8 | R23: 16 | S23: 7 | T23: 9 | U23: 3 | W23: 1 | X23: 1 | Y23: 1 | Z23: 1 | AA23: 1 | AC23: GK | AD23: 0 | AE23: 24 | AF23: 9 | AG23: 9 | AH23: 0 | AJ23: GK | AK23: 0 | AL23: 24 | AM23: 9 | AN23: 9 | AO23: 0
C24: 200 | D24: 200 | E24: 200 | F24: 200 | G24: 200 | J24: 20 | K24: A | L24: A | M24: M4 | N24: GK | O24: A | Q24: 7 | R24: 7 | S24: 5 | T24: 17 | U24: 7 | W24: 1 | X24: 1 | Y24: 2 | Z24: 1 | AA24: 1 | AC24: GQ | AD24: 0 | AE24: 18 | AF24: 0 | AG24: 12 | AH24: 0 | AJ24: GQ | AK24: 0 | AL24: 18 | AM24: 0 | AN24: 12 | AO24: 0
J25: 21 | K25: M4 | L25: K | M25: M4 | N25: M1 | O25: M2 | Q25: 5 | R25: 8 | S25: 5 | T25: 2 | U25: 3 | W25: 1 | X25: 1 | Y25: 2 | Z25: 1 | AA25: 2 | AC25: GJ | AD25: 0 | AE25: 18 | AF25: 0 | AG25: 12 | AH25: 0 | AJ25: GJ | AK25: 0 | AL25: 18 | AM25: 0 | AN25: 12 | AO25: 0
B26: Normal Symbol | C26: 1 | D26: 0.6 | E26: 0.94 | F26: 0.84 | G26: 1 | J26: 22 | K26: Q | L26: G4 | M26: M4 | N26: M1 | O26: M1 | Q26: 9 | R26: 14 | S26: 5 | T26: 2 | U26: 2 | W26: 1 | X26: 2 | Y26: 1 | Z26: 1 | AA26: 2 | AD26: 200 | AE26: 360 | AF26: 224 | AG26: 264 | AH26: 200 | AK26: 200 | AL26: 360 | AM26: 224 | AN26: 264 | AO26: 200
B27: Rainbow Symbol | C27: 0 | D27: 0.4 | E27: 0.06 | F27: 0.16 | G27: 0 | J27: 23 | K27: A | L27: M5 | M27: M5 | N27: A | O27: M1 | Q27: 7 | R27: 6 | S27: 6 | T27: 7 | U27: 2 | W27: 1 | X27: 2 | Y27: 1 | Z27: 1 | AA27: 1
J28: 24 | K28: K | L28: M4 | M28: A | N28: M4 | O28: J | Q28: 8 | R28: 5 | S28: 7 | T28: 5 | U28: 10 | W28: 1 | X28: 2 | Y28: 1 | Z28: 2 | AA28: 1 | AC28: 2 Combo | AJ28: 2 Combo
J29: 25 | K29: M4 | L29: GQ | M29: K | N29: Q | O29: K | Q29: 5 | R29: 18 | S29: 8 | T29: 9 | U29: 8 | W29: 1 | X29: 1 | Y29: 1 | Z29: 1 | AA29: 1 | AC29: Symbol | AD29: R1 | AE29: R2 | AF29: R3 | AG29: R4 | AH29: R5 | AJ29: Symbol | AK29: R1 | AL29: R2 | AM29: R3 | AN29: R4 | AO29: R5
J30: 26 | K30: A | L30: G4 | M30: A | N30: M2 | O30: M2 | Q30: 7 | R30: 14 | S30: 7 | T30: 3 | U30: 3 | W30: 1 | X30: 1 | Y30: 1 | Z30: 1 | AA30: 2 | AC30: WW | AD30: 0 | AE30: 0 | AF30: 0 | AG30: 0 | AH30: 0 | AJ30: WW | AK30: 0 | AL30: 0 | AM30: 0 | AN30: 0 | AO30: 0
J31: 27 | K31: K | L31: K | M31: A | N31: A | O31: M3 | Q31: 8 | R31: 8 | S31: 7 | T31: 7 | U31: 4 | W31: 1 | X31: 1 | Y31: 1 | Z31: 1 | AA31: 2 | AC31: C1 | AD31: 0 | AE31: 6 | AF31: 0 | AG31: 9 | AH31: 0 | AJ31: C1 | AK31: 0 | AL31: 6 | AM31: 0 | AN31: 9 | AO31: 0
J32: 28 | K32: M4 | L32: M2 | M32: M5 | N32: M2 | O32: M5 | Q32: 5 | R32: 3 | S32: 6 | T32: 3 | U32: 6 | W32: 2 | X32: 2 | Y32: 1 | Z32: 2 | AA32: 2 | AC32: M1 | AD32: 4 | AE32: 22 | AF32: 5 | AG32: 21 | AH32: 23 | AJ32: M1 | AK32: 4 | AL32: 22 | AM32: 5 | AN32: 21 | AO32: 23
J33: 29 | K33: Q | L33: M1 | M33: GK | N33: M2 | O33: Q | Q33: 9 | R33: 2 | S33: 17 | T33: 3 | U33: 9 | W33: 2 | X33: 2 | Y33: 1 | Z33: 2 | AA33: 2 | AC33: M2 | AD33: 4 | AE33: 10 | AF33: 5 | AG33: 21 | AH33: 23 | AJ33: M2 | AK33: 4 | AL33: 10 | AM33: 5 | AN33: 21 | AO33: 23
J34: 30 | K34: M4 | L34: G5 | M34: M4 | N34: M3 | O34: M1 | Q34: 5 | R34: 15 | S34: 5 | T34: 4 | U34: 2 | W34: 2 | X34: 2 | Y34: 1 | Z34: 2 | AA34: 2 | AC34: M3 | AD34: 4 | AE34: 9 | AF34: 5 | AG34: 21 | AH34: 22 | AJ34: M3 | AK34: 4 | AL34: 9 | AM34: 5 | AN34: 21 | AO34: 22
J35: 31 | K35: M4 | L35: G3 | M35: J | N35: J | O35: M1 | Q35: 5 | R35: 13 | S35: 10 | T35: 10 | U35: 2 | W35: 2 | X35: 2 | Y35: 1 | Z35: 1 | AA35: 2 | AC35: M4 | AD35: 43 | AE35: 13 | AF35: 41 | AG35: 14 | AH35: 22 | AJ35: M4 | AK35: 43 | AL35: 13 | AM35: 41 | AN35: 14 | AO35: 22
J36: 32 | K36: M4 | L36: M3 | M36: K | N36: J | O36: M3 | Q36: 5 | R36: 4 | S36: 8 | T36: 10 | U36: 4 | W36: 1 | X36: 2 | Y36: 1 | Z36: 1 | AA36: 2 | AC36: M5 | AD36: 43 | AE36: 14 | AF36: 41 | AG36: 14 | AH36: 22 | AJ36: M5 | AK36: 43 | AL36: 14 | AM36: 41 | AN36: 14 | AO36: 22
J37: 33 | K37: M5 | L37: M1 | M37: G5 | N37: A | O37: M3 | Q37: 6 | R37: 2 | S37: 15 | T37: 7 | U37: 4 | W37: 1 | X37: 2 | Y37: 2 | Z37: 1 | AA37: 2 | AC37: A | AD37: 47 | AE37: 14 | AF37: 41 | AG37: 14 | AH37: 22 | AJ37: A | AK37: 47 | AL37: 14 | AM37: 41 | AN37: 14 | AO37: 22
J38: 34 | K38: K | L38: Q | M38: M4 | N38: A | O38: M2 | Q38: 8 | R38: 9 | S38: 5 | T38: 7 | U38: 3 | W38: 1 | X38: 2 | Y38: 2 | Z38: 1 | AA38: 1 | AC38: K | AD38: 47 | AE38: 18 | AF38: 41 | AG38: 14 | AH38: 22 | AJ38: K | AK38: 47 | AL38: 18 | AM38: 41 | AN38: 14 | AO38: 22
J39: 35 | K39: A | L39: G5 | M39: M4 | N39: M5 | O39: Q | Q39: 7 | R39: 15 | S39: 5 | T39: 6 | U39: 9 | W39: 1 | X39: 2 | Y39: 2 | Z39: 2 | AA39: 1 | AC39: Q | AD39: 4 | AE39: 5 | AF39: 5 | AG39: 20 | AH39: 22 | AJ39: Q | AK39: 4 | AL39: 5 | AM39: 5 | AN39: 20 | AO39: 22
J40: 36 | K40: M5 | L40: M5 | M40: J | N40: G3 | O40: K | Q40: 6 | R40: 6 | S40: 10 | T40: 13 | U40: 8 | W40: 1 | X40: 2 | Y40: 2 | Z40: 2 | AA40: 1 | AC40: J | AD40: 4 | AE40: 9 | AF40: 4 | AG40: 20 | AH40: 22 | AJ40: J | AK40: 4 | AL40: 9 | AM40: 4 | AN40: 20 | AO40: 22
J41: 37 | K41: A | L41: M4 | M41: M5 | N41: M3 | O41: K | Q41: 7 | R41: 5 | S41: 6 | T41: 4 | U41: 8 | W41: 1 | X41: 2 | Y41: 2 | Z41: 2 | AA41: 1 | AC41: G1 | AD41: 0 | AE41: 48 | AF41: 0 | AG41: 12 | AH41: 0 | AJ41: G1 | AK41: 0 | AL41: 48 | AM41: 0 | AN41: 12 | AO41: 0
... J49: 45 | K49: M4 | L49: GK | M49: M5 | N49: M3 | O49: M5 | Q49: 5 | R49: 17 | S49: 6 | T49: 4 | U49: 6 | W49: 2 | X49: 1 | Y49: 1 | Z49: 2 | AA49: 2 | AC49: GJ | AD49: 0 | AE49: 18 | AF49: 0 | AG49: 12 | AH49: 0 | AJ49: GJ | AK49: 0 | AL49: 18 | AM49: 0 | AN49: 12 | AO49: 0
J50: 46 | K50: M3 | L50: GK | M50: K | N50: Q | O50: M1 | Q50: 4 | R50: 17 | S50: 8 | T50: 9 | U50: 2 | W50: 1 | X50: 1 | Y50: 1 | Z50: 2 | AA50: 2 | AD50: 200 | AE50: 360 | AF50: 224 | AG50: 264 | AH50: 200 | AK50: 200 | AL50: 360 | AM50: 224 | AN50: 264 | AO50: 200
J51: 47 | K51: M1 | L51: K | M51: M4 | N51: G1 | O51: M5 | Q51: 2 | R51: 8 | S51: 5 | T51: 11 | U51: 6 | W51: 1 | X51: 1 | Y51: 1 | Z51: 1 | AA51: 2
J52: 48 | K52: A | L52: M4 | M52: A | N52: Q | O52: M5 | Q52: 7 | R52: 5 | S52: 7 | T52: 9 | U52: 6 | W52: 1 | X52: 1 | Y52: 1 | Z52: 1 | AA52: 2 | AC52: 3+ Combo | AJ52: 3+ Combo
J53: 49 | K53: M4 | L53: GQ | M53: M4 | N53: K | O53: M4 | Q53: 5 | R53: 18 | S53: 5 | T53: 8 | U53: 5 | W53: 1 | X53: 1 | Y53: 1 | Z53: 1 | AA53: 2 | AC53: Symbol | AD53: R1 | AE53: R2 | AF53: R3 | AG53: R4 | AH53: R5 | AJ53: Symbol | AK53: R1 | AL53: R2 | AM53: R3 | AN53: R4 | AO53: R5
...

Sheet BG_Symbol (2)
J2: Symbol | Q2: Symbol ID | W2: Symbol Weight | AC2: Eliminate Wheel Weight A | AJ2: Eliminate Wheel Weight B
A3: Symbol | B3: Description | C3: R1 | D3: R2 | E3: R3 | F3: R4 | G3: R5 | H3: ID | K3: R1 | L3: R2 | M3: R3 | N3: R4 | O3: R5 | Q3: R1 | R3: R2 | S3: R3 | T3: R4 | U3: R5 | W3: R1 | X3: R2 | Y3: R3 | Z3: R4 | AA3: R5
A4: WW | B4: Wild | C4: 0 | D4: 0 | E4: 0 | F4: 0 | G4: 0 | H4: 0 | J4: 0 | K4: K | L4: A | M4: GA | N4: J | O4: M1 | Q4: 8 | R4: 7 | S4: 16 | T4: 10 | U4: 2 | W4: {=_xlfn.LET(_xlpm.x, K4:K6, IF(SUM((_xlpm.x="K")*1, (_xlpm.x="A")*1, (_xlpm.x="GK")*1, (_xlpm.x="GA")*1)>0, 3, 1))} -> 3 | X4: {=_xlfn.LET(_xlpm.x, L4:L6, IF(SUM((_xlpm.x="K")*1, (_xlpm.x="A")*1, (_xlpm.x="GK")*1, (_xlpm.x="GA")*1)>0, 3, 1))} -> 3 | Y4: {=_xlfn.LET(_xlpm.x, M4:M6, IF(SUM((_xlpm.x="K")*1, (_xlpm.x="A")*1, (_xlpm.x="GK")*1, (_xlpm.x="GA")*1)>0, 3, 1))} -> 3 | Z4: 1 | AA4: 1 | AC4: 1 Combo | AJ4: 1 Combo
A5: C1 | B5: Scatter | C5: 0 | D5: 6 | E5: 0 | F5: 9 | G5: 0 | H5: 1 | J5: 1 | K5: A | L5: A | M5: GQ | N5: M1 | O5: M3 | Q5: 7 | R5: 7 | S5: 18 | T5: 2 | U5: 4 | W5: {=_xlfn.LET(_xlpm.x, K5:K7, IF(SUM((_xlpm.x="K")*1, (_xlpm.x="A")*1, (_xlpm.x="GK")*1, (_xlpm.x="GA")*1)>0, 3, 1))} -> 3 | X5: {=_xlfn.LET(_xlpm.x, L5:L7, IF(SUM((_xlpm.x="K")*1, (_xlpm.x="A")*1, (_xlpm.x="GK")*1, (_xlpm.x="GA")*1)>0, 3, 1))} -> 3 | Y5: {=_xlfn.LET(_xlpm.x, M5:M7, IF(SUM((_xlpm.x="K")*1, (_xlpm.x="A")*1, (_xlpm.x="GK")*1, (_xlpm.x="GA")*1)>0, 3, 1))} -> 1 | Z5: 1 | AA5: 1 | AC5: Symbol | AD5: R1 | AE5: R2 | AF5: R3 | AG5: R4 | AH5: R5 | AJ5: Symbol | AK5: R1 | AL5: R2 | AM5: R3 | AN5: R4 | AO5: R5
A6: M1 | B6: M1 | C6: 4 | D6: 6 | E6: 0 | F6: 22 | G6: 28 | H6: 2 | J6: 2 | K6: M1 | L6: GA | M6: G4 | N6: M3 | O6: M2 | Q6: 2 | R6: 16 | S6: 14 | T6: 4 | U6: 3 | W6: {=_xlfn.LET(_xlpm.x, K6:K8, IF(SUM((_xlpm.x="K")*1, (_xlpm.x="A")*1, (_xlpm.x="GK")*1, (_xlpm.x="GA")*1)>0, 3, 1))} -> 3 | X6: {=_xlfn.LET(_xlpm.x, L6:L8, IF(SUM((_xlpm.x="K")*1, (_xlpm.x="A")*1, (_xlpm.x="GK")*1, (_xlpm.x="GA")*1)>0, 3, 1))} -> 3 | Y6: {=_xlfn.LET(_xlpm.x, M6:M8, IF(SUM((_xlpm.x="K")*1, (_xlpm.x="A")*1, (_xlpm.x="GK")*1, (_xlpm.x="GA")*1)>0, 3, 1))} -> 1 | Z6: 1 | AA6: 1 | AC6: WW | AD6: 0 | AE6: 0 | AF6: 0 | AG6: 0 | AH6: 0 | AJ6: WW | AK6: 0 | AL6: 0 | AM6: 0 | AN6: 0 | AO6: 0
A7: M2 | B7: M2 | C7: 4 | D7: 6 | E7: 0 | F7: 22 | G7: 27 | H7: 3 | J7: 3 | K7: M4 | L7: Q | M7: G5 | N7: M3 | O7: M2 | Q7: 5 | R7: 9 | S7: 15 | T7: 4 | U7: 3 | W7: {=_xlfn.LET(_xlpm.x, K7:K9, IF(SUM((_xlpm.x="K")*1, (_xlpm.x="A")*1, (_xlpm.x="GK")*1, (_xlpm.x="GA")*1)>0, 3, 1))} -> 3 | X7: {=_xlfn.LET(_xlpm.x, L7:L9, IF(SUM((_xlpm.x="K")*1, (_xlpm.x="A")*1, (_xlpm.x="GK")*1, (_xlpm.x="GA")*1)>0, 3, 1))} -> 3 | Y7: {=_xlfn.LET(_xlpm.x, M7:M9, IF(SUM((_xlpm.x="K")*1, (_xlpm.x="A")*1, (_xlpm.x="GK")*1, (_xlpm.x="GA")*1)>0, 3, 1))} -> 3 | Z7: 1 | AA7: 1 | AC7: C1 | AD7: 0 | AE7: 6 | AF7: 0 | AG7: 9 | AH7: 0 | AJ7: C1 | AK7: 0 | AL7: 6 | AM7: 0 | AN7: 9 | AO7: 0
A8: M3 | B8: M3 | C8: 4 | D8: 6 | E8: 0 | F8: 22 | G8: 27 | H8: 4 | J8: 4 | K8: K | L8: GA | M8: G4 | N8: M2 | O8: K | Q8: 8 | R8: 16 | S8: 14 | T8: 3 | U8: 8 | W8: {=_xlfn.LET(_xlpm.x, K8:K10, IF(SUM((_xlpm.x="K")*1, (_xlpm.x="A")*1, (_xlpm.x="GK")*1, (_xlpm.x="GA")*1)>0, 3, 1))} -> 3 | X8: {=_xlfn.LET(_xlpm.x, L8:L10, IF(SUM((_xlpm.x="K")*1, (_xlpm.x="A")*1, (_xlpm.x="GK")*1, (_xlpm.x="GA")*1)>0, 3, 1))} -> 3 | Y8: {=_xlfn.LET(_xlpm.x, M8:M10, IF(SUM((_xlpm.x="K")*1, (_xlpm.x="A")*1, (_xlpm.x="GK")*1, (_xlpm.x="GA")*1)>0, 3, 1))} -> 3 | Z8: 1 | AA8: 1 | AC8: M1 | AD8: 4 | AE8: 11 | AF8: 0 | AG8: 22 | AH8: 28 | AJ8: M1 | AK8: 4 | AL8: 11 | AM8: 0 | AN8: 22 | AO8: 28
A9: M4 | B9: M4 | C9: 43 | D9: 19 | E9: 0 | F9: 12 | G9: 16 | H9: 5 | J9: 5 | K9: M5 | L9: M3 | M9: GK | N9: M2 | O9: M2 | Q9: 6 | R9: 4 | S9: 17 | T9: 3 | U9: 3 | W9: {=_xlfn.LET(_xlpm.x, K9:K11, IF(SUM((_xlpm.x="K")*1, (_xlpm.x="A")*1, (_xlpm.x="GK")*1, (_xlpm.x="GA")*1)>0, 3, 1))} -> 3 | X9: {=_xlfn.LET(_xlpm.x, L9:L11, IF(SUM((_xlpm.x="K")*1, (_xlpm.x="A")*1, (_xlpm.x="GK")*1, (_xlpm.x="GA")*1)>0, 3, 1))} -> 1 | Y9: {=_xlfn.LET(_xlpm.x, M9:M11, IF(SUM((_xlpm.x="K")*1, (_xlpm.x="A")*1, (_xlpm.x="GK")*1, (_xlpm.x="GA")*1)>0, 3, 1))} -> 3 | Z9: 1 | AA9: 1 | AC9: M2 | AD9: 4 | AE9: 11 | AF9: 0 | AG9: 22 | AH9: 27 | AJ9: M2 | AK9: 4 | AL9: 11 | AM9: 0 | AN9: 22 | AO9: 27
A10: M5 | B10: M5 | C10: 43 | D10: 19 | E10: 0 | F10: 12 | G10: 16 | H10: 6 | J10: 6 | K10: K | L10: M4 | M10: GA | N10: J | O10: A | Q10: 8 | R10: 5 | S10: 16 | T10: 10 | U10: 7 | W10: {=_xlfn.LET(_xlpm.x, K10:K12, IF(SUM((_xlpm.x="K")*1, (_xlpm.x="A")*1, (_xlpm.x="GK")*1, (_xlpm.x="GA")*1)>0, 3, 1))} -> 3 | X10: {=_xlfn.LET(_xlpm.x, L10:L12, IF(SUM((_xlpm.x="K")*1, (_xlpm.x="A")*1, (_xlpm.x="GK")*1, (_xlpm.x="GA")*1)>0, 3, 1))} -> 3 | Y10: {=_xlfn.LET(_xlpm.x, M10:M12, IF(SUM((_xlpm.x="K")*1, (_xlpm.x="A")*1, (_xlpm.x="GK")*1, (_xlpm.x="GA")*1)>0, 3, 1))} -> 3 | Z10: 1 | AA10: 1 | AC10: M3 | AD10: 4 | AE10: 11 | AF10: 0 | AG10: 22 | AH10: 27 | AJ10: M3 | AK10: 4 | AL10: 11 | AM10: 0 | AN10: 22 | AO10: 27
A11: A | B11: A | C11: 47 | D11: 22 | E11: 0 | F11: 12 | G11: 16 | H11: 7 | J11: 7 | K11: M5 | L11: G3 | M11: G5 | N11: J | O11: M5 | Q11: 6 | R11: 13 | S11: 15 | T11: 10 | U11: 6 | W11: {=_xlfn.LET(_xlpm.x, K11:K13, IF(SUM((_xlpm.x="K")*1, (_xlpm.x="A")*1, (_xlpm.x="GK")*1, (_xlpm.x="GA")*1)>0, 3, 1))} -> 3 | X11: {=_xlfn.LET(_xlpm.x, L11:L13, IF(SUM((_xlpm.x="K")*1, (_xlpm.x="A")*1, (_xlpm.x="GK")*1, (_xlpm.x="GA")*1)>0, 3, 1))} -> 3 | Y11: {=_xlfn.LET(_xlpm.x, M11:M13, IF(SUM((_xlpm.x="K")*1, (_xlpm.x="A")*1, (_xlpm.x="GK")*1, (_xlpm.x="GA")*1)>0, 3, 1))} -> 3 | Z11: 1 | AA11: 1 | AC11: M4 | AD11: 43 | AE11: 19 | AF11: 0 | AG11: 12 | AH11: 16 | AJ11: M4 | AK11: 43 | AL11: 19 | AM11: 0 | AN11: 12 | AO11: 16
A12: K | B12: K | C12: 47 | D12: 24 | E12: 0 | F12: 12 | G12: 16 | H12: 8 | J12: 8 | K12: M4 | L12: A | M12: GK | N12: M5 | O12: M5 | Q12: 5 | R12: 7 | S12: 17 | T12: 6 | U12: 6 | W12: {=_xlfn.LET(_xlpm.x, K12:K14, IF(SUM((_xlpm.x="K")*1, (_xlpm.x="A")*1, (_xlpm.x="GK")*1, (_xlpm.x="GA")*1)>0, 3, 1))} -> 3 | X12: {=_xlfn.LET(_xlpm.x, L12:L14, IF(SUM((_xlpm.x="K")*1, (_xlpm.x="A")*1, (_xlpm.x="GK")*1, (_xlpm.x="GA")*1)>0, 3, 1))} -> 3 | Y12: {=_xlfn.LET(_xlpm.x, M12:M14, IF(SUM((_xlpm.x="K")*1, (_xlpm.x="A")*1, (_xlpm.x="GK")*1, (_xlpm.x="GA")*1)>0, 3, 1))} -> 3 | Z12: 1 | AA12: 1 | AC12: M5 | AD12: 43 | AE12: 20 | AF12: 0 | AG12: 12 | AH12: 16 | AJ12: M5 | AK12: 43 | AL12: 20 | AM12: 0 | AN12: 12 | AO12: 16
A13: Q | B13: Q | C13: 4 | D13: 5 | E13: 0 | F13: 21 | G13: 27 | H13: 9 | J13: 9 | K13: K | L13: GJ | M13: G5 | N13: GJ | O13: M1 | Q13: 8 | R13: 19 | S13: 15 | T13: 19 | U13: 2 | W13: {=_xlfn.LET(_xlpm.x, K13:K15, IF(SUM((_xlpm.x="K")*1, (_xlpm.x="A")*1, (_xlpm.x="GK")*1, (_xlpm.x="GA")*1)>0, 3, 1))} -> 3 | X13: {=_xlfn.LET(_xlpm.x, L13:L15, IF(SUM((_xlpm.x="K")*1, (_xlpm.x="A")*1, (_xlpm.x="GK")*1, (_xlpm.x="GA")*1)>0, 3, 1))} -> 1 | Y13: {=_xlfn.LET(_xlpm.x, M13:M15, IF(SUM((_xlpm.x="K")*1, (_xlpm.x="A")*1, (_xlpm.x="GK")*1, (_xlpm.x="GA")*1)>0, 3, 1))} -> 3 | Z13: 1 | AA13: 1 | AC13: A | AD13: 47 | AE13: 20 | AF13: 0 | AG13: 12 | AH13: 16 | AJ13: A | AK13: 47 | AL13: 20 | AM13: 0 | AN13: 12 | AO13: 16
A14: J | B14: J | C14: 4 | D14: 7 | E14: 0 | F14: 21 | G14: 27 | H14: 10 | J14: 10 | K14: Q | L14: G5 | M14: GA | N14: M1 | O14: K | Q14: 9 | R14: 15 | S14: 16 | T14: 2 | U14: 8 | W14: {=_xlfn.LET(_xlpm.x, K14:K16, IF(SUM((_xlpm.x="K")*1, (_xlpm.x="A")*1, (_xlpm.x="GK")*1, (_xlpm.x="GA")*1)>0, 3, 1))} -> 3 | X14: {=_xlfn.LET(_xlpm.x, L14:L16, IF(SUM((_xlpm.x="K")*1, (_xlpm.x="A")*1, (_xlpm.x="GK")*1, (_xlpm.x="GA")*1)>0, 3, 1))} -> 1 | Y14: {=_xlfn.LET(_xlpm.x, M14:M16, IF(SUM((_xlpm.x="K")*1, (_xlpm.x="A")*1, (_xlpm.x="GK")*1, (_xlpm.x="GA")*1)>0, 3, 1))} -> 3 | Z14: 1 | AA14: 1 | AC14: K | AD14: 47 | AE14: 20 | AF14: 0 | AG14: 12 | AH14: 16 | AJ14: K | AK14: 47 | AL14: 20 | AM14: 0 | AN14: 12 | AO14: 16
A15: G1 | B15: Rainbow M1 | C15: 0 | D15: 4 | E15: 5 | F15: 5 | G15: 0 | H15: 11 | J15: 11 | K15: A | L15: M4 | M15: G4 | N15: A | O15: K | Q15: 7 | R15: 5 | S15: 14 | T15: 7 | U15: 8 | W15: {=_xlfn.LET(_xlpm.x, K15:K17, IF(SUM((_xlpm.x="K")*1, (_xlpm.x="A")*1, (_xlpm.x="GK")*1, (_xlpm.x="GA")*1)>0, 3, 1))} -> 3 | X15: {=_xlfn.LET(_xlpm.x, L15:L17, IF(SUM((_xlpm.x="K")*1, (_xlpm.x="A")*1, (_xlpm.x="GK")*1, (_xlpm.x="GA")*1)>0, 3, 1))} -> 1 | Y15: {=_xlfn.LET(_xlpm.x, M15:M17, IF(SUM((_xlpm.x="K")*1, (_xlpm.x="A")*1, (_xlpm.x="GK")*1, (_xlpm.x="GA")*1)>0, 3, 1))} -> 3 | Z15: 1 | AA15: 1 | AC15: Q | AD15: 4 | AE15: 11 | AF15: 0 | AG15: 21 | AH15: 27 | AJ15: Q | AK15: 4 | AL15: 11 | AM15: 0 | AN15: 21 | AO15: 27
A16: G2 | B16: Rainbow M2 | C16: 0 | D16: 4 | E16: 5 | F16: 5 | G16: 0 | H16: 12 | J16: 12 | K16: Q | L16: M4 | M16: GK | N16: GA | O16: Q | Q16: 9 | R16: 5 | S16: 17 | T16: 16 | U16: 9 | W16: {=_xlfn.LET(_xlpm.x, K16:K18, IF(SUM((_xlpm.x="K")*1, (_xlpm.x="A")*1, (_xlpm.x="GK")*1, (_xlpm.x="GA")*1)>0, 3, 1))} -> 3 | X16: {=_xlfn.LET(_xlpm.x, L16:L18, IF(SUM((_xlpm.x="K")*1, (_xlpm.x="A")*1, (_xlpm.x="GK")*1, (_xlpm.x="GA")*1)>0, 3, 1))} -> 3 | Y16: {=_xlfn.LET(_xlpm.x, M16:M18, IF(SUM((_xlpm.x="K")*1, (_xlpm.x="A")*1, (_xlpm.x="GK")*1, (_xlpm.x="GA")*1)>0, 3, 1))} -> 3 | Z16: 1 | AA16: 1 | AC16: J | AD16: 4 | AE16: 11 | AF16: 0 | AG16: 21 | AH16: 27 | AJ16: J | AK16: 4 | AL16: 11 | AM16: 0 | AN16: 21 | AO16: 27
A17: G3 | B17: Rainbow M3 | C17: 0 | D17: 4 | E17: 5 | F17: 5 | G17: 0 | H17: 13 | J17: 13 | K17: K | L17: Q | M17: G5 | N17: K | O17: M2 | Q17: 8 | R17: 9 | S17: 15 | T17: 8 | U17: 3 | W17: {=_xlfn.LET(_xlpm.x, K17:K19, IF(SUM((_xlpm.x="K")*1, (_xlpm.x="A")*1, (_xlpm.x="GK")*1, (_xlpm.x="GA")*1)>0, 3, 1))} -> 3 | X17: {=_xlfn.LET(_xlpm.x, L17:L19, IF(SUM((_xlpm.x="K")*1, (_xlpm.x="A")*1, (_xlpm.x="GK")*1, (_xlpm.x="GA")*1)>0, 3, 1))} -> 3 | Y17: {=_xlfn.LET(_xlpm.x, M17:M19, IF(SUM((_xlpm.x="K")*1, (_xlpm.x="A")*1, (_xlpm.x="GK")*1, (_xlpm.x="GA")*1)>0, 3, 1))} -> 3 | Z17: 1 | AA17: 1 | AC17: G1 | AD17: 0 | AE17: 7 | AF17: 7 | AG17: 9 | AH17: 0 | AJ17: G1 | AK17: 0 | AL17: 7 | AM17: 7 | AN17: 9 | AO17: 0
... A23: GJ | B23: Rainbow J | C23: 0 | D23: 3 | E23: 4 | F23: 4 | G23: 0 | H23: 19 | J23: 19 | K23: M4 | L23: A | M23: GK | N23: Q | O23: M1 | Q23: 5 | R23: 7 | S23: 17 | T23: 9 | U23: 2 | W23: {=_xlfn.LET(_xlpm.x, K23:K25, IF(SUM((_xlpm.x="K")*1, (_xlpm.x="A")*1, (_xlpm.x="GK")*1, (_xlpm.x="GA")*1)>0, 3, 1))} -> 1 | X23: {=_xlfn.LET(_xlpm.x, L23:L25, IF(SUM((_xlpm.x="K")*1, (_xlpm.x="A")*1, (_xlpm.x="GK")*1, (_xlpm.x="GA")*1)>0, 3, 1))} -> 3 | Y23: {=_xlfn.LET(_xlpm.x, M23:M25, IF(SUM((_xlpm.x="K")*1, (_xlpm.x="A")*1, (_xlpm.x="GK")*1, (_xlpm.x="GA")*1)>0, 3, 1))} -> 3 | Z23: 1 | AA23: 1 | AC23: GK | AD23: 0 | AE23: 15 | AF23: 66 | AG23: 6 | AH23: 0 | AJ23: GK | AK23: 0 | AL23: 15 | AM23: 66 | AN23: 6 | AO23: 0
C24: 200 | D24: 200 | E24: 200 | F24: 200 | G24: 200 | J24: 20 | K24: M5 | L24: GK | M24: G4 | N24: M3 | O24: Q | Q24: 6 | R24: 17 | S24: 14 | T24: 4 | U24: 9 | W24: {=_xlfn.LET(_xlpm.x, K24:K26, IF(SUM((_xlpm.x="K")*1, (_xlpm.x="A")*1, (_xlpm.x="GK")*1, (_xlpm.x="GA")*1)>0, 3, 1))} -> 3 | X24: {=_xlfn.LET(_xlpm.x, L24:L26, IF(SUM((_xlpm.x="K")*1, (_xlpm.x="A")*1, (_xlpm.x="GK")*1, (_xlpm.x="GA")*1)>0, 3, 1))} -> 3 | Y24: {=_xlfn.LET(_xlpm.x, M24:M26, IF(SUM((_xlpm.x="K")*1, (_xlpm.x="A")*1, (_xlpm.x="GK")*1, (_xlpm.x="GA")*1)>0, 3, 1))} -> 3 | Z24: 1 | AA24: 1 | AC24: GQ | AD24: 0 | AE24: 9 | AF24: 7 | AG24: 7 | AH24: 0 | AJ24: GQ | AK24: 0 | AL24: 9 | AM24: 7 | AN24: 7 | AO24: 0
J25: 21 | K25: M3 | L25: GK | M25: GK | N25: C1 | O25: J | Q25: 4 | R25: 17 | S25: 17 | T25: 1 | U25: 10 | W25: {=_xlfn.LET(_xlpm.x, K25:K27, IF(SUM((_xlpm.x="K")*1, (_xlpm.x="A")*1, (_xlpm.x="GK")*1, (_xlpm.x="GA")*1)>0, 3, 1))} -> 3 | X25: {=_xlfn.LET(_xlpm.x, L25:L27, IF(SUM((_xlpm.x="K")*1, (_xlpm.x="A")*1, (_xlpm.x="GK")*1, (_xlpm.x="GA")*1)>0, 3, 1))} -> 3 | Y25: {=_xlfn.LET(_xlpm.x, M25:M27, IF(SUM((_xlpm.x="K")*1, (_xlpm.x="A")*1, (_xlpm.x="GK")*1, (_xlpm.x="GA")*1)>0, 3, 1))} -> 3 | Z25: 1 | AA25: 1 | AC25: GJ | AD25: 0 | AE25: 9 | AF25: 6 | AG25: 7 | AH25: 0 | AJ25: GJ | AK25: 0 | AL25: 9 | AM25: 6 | AN25: 7 | AO25: 0
