Workbook

Sheet Overview
A2: Model: | B2: H026192
A3: Version: | B3: =[1]Overview!$B$3 -> 0.1.0.1
A6: Base Bet
A7: 100
A10: Coin in | B10: Price(x) | C10: Total RTP | D10: Bet Type
A11: {=B11:B12*A7} -> 100 | B11: 1 | C11: =SUM(B17:B18) -> 0 | D11: Normal Bet
A12: 7500 | B12: 75 | C12: =SUM(B21:B22) -> 0 | D12: Buy Feature
A15: Total Pay Back Percentage includes the following adjustments.
A16: Bet Type | B16: Pay Back | C16: Hit% | D16: Pulls/Hit | E16: Description
A17: =D11 -> Normal Bet | C17: =1/D17 -> #DIV/0! | E17: Base Game
E18: Free Game
A20: Bet Type | B20: Pay Back | C20: Hit% | D20: Pulls/Hit | E20: Description
A21: =D12 -> Buy Feature | C21: =1/D21 -> 1 | D21: 1 | E21: Base Game
E22: Free Game
A25: Reel # | B25: 1 | C25: 2 | D25: 3 | E25: 4 | F25: 5
A26: Visible Window Size | B26: 3 | C26: 3 | D26: 3 | E26: 3 | F26: 3
A29: Free Spins Setting
A30: C1 Num. | B30: Base Game | C30: Free Game
A31: 3 | B31: 15 | C31: 15
A32: 4 | B32: 17 | C32: 17
A33: 5 | B33: 19 | C33: 19
A34: The maximum of free spins is 50.
A36: Pay Table： | B36: ="All wins show for "&A7&" credit bet." -> All wins show for 100 credit bet.
A37: Symbol | B37: Description | C37: 3 | D37: 4 | E37: 5 | F37: Id
A38: WW | B38: Wild | C38: 0 | D38: 0 | E38: 0 | F38: 0
A39: C1 | B39: Scatter | C39: 0 | D39: 0 | E39: 0 | F39: 1
A40: M1 | B40: M1 | C40: 250 | D40: 1250 | E40: 5000 | F40: 2
A41: M2 | B41: M2 | C41: 100 | D41: 500 | E41: 2000 | F41: 3
A42: M3 | B42: M3 | C42: 75 | D42: 250 | E42: 1000 | F42: 4
A43: M4 | B43: M4 | C43: 50 | D43: 200 | E43: 750 | F43: 5
A44: M5 | B44: M5 | C44: 25 | D44: 100 | E44: 500 | F44: 6
A45: A | B45: A | C45: 10 | D45: 50 | E45: 250 | F45: 7
A46: K | B46: K | C46: 10 | D46: 50 | E46: 250 | F46: 8
A47: Q | B47: Q | C47: 10 | D47: 50 | E47: 250 | F47: 9
A48: J | B48: J | C48: 10 | D48: 50 | E48: 250 | F48: 10
A49: G1 | B49: Gold M1 | C49: 250 | D49: 1250 | E49: 5000 | F49: 11
... A57: GJ | B57: Gold J | C57: 10 | D57: 50 | E57: 250 | F57: 19

Sheet Parameter
A1: {=_xlfn.LET(_xlpm.x, [1]Parameter!$A$1:$AM$56, IF(_xlpm.x="", "", _xlpm.x))}
B3: Line | I3: Table Selection Weight - Base Game (Weight/Total) | N3: Multiple Selection Weight - Special Pool (Weight/Total) | AC3: Used Special Pool Weight (Weight/10000)
B4: ID | C4: R1 | D4: R2 | E4: R3 | F4: R4 | G4: R5 | I4: Worksheet Name | J4: Weight | K4: RTP | N4: Worksheet Name \ Multiple | O4: 0 | P4: 2 | Q4: 3 | R4: 5 | S4: 8 | T4: 10 | U4: 15 | V4: 20 | W4: 25 | X4: 35 | Y4: 50 | Z4: 80 | AA4: 100 | AC4: Worksheet Name \ Multiple | AD4: 1 | AE4: 2 | AF4: 3 | AG4: 4 | AH4: 5 | AI4: 6 | AJ4: 7 | AK4: 8 | AL4: 9
B5: 0 | C5: 1 | D5: 1 | E5: 1 | F5: 1 | G5: 1 | I5: BG_Symbol | J5: 6500 | L5: 0.65 | N5: BG_Symbol | O5: 0 | P5: 0 | Q5: 0 | R5: 0 | S5: 0 | T5: 4140 | U5: 3000 | V5: 2000 | W5: 500 | X5: 60 | Y5: 120 | Z5: 60 | AA5: 120 | AB5: 16.38 | AC5: BG_Symbol | AD5: 300 | AE5: 600 | AF5: 1080 | AG5: 1440 | AH5: 2250 | AI5: 2700 | AJ5: 3150 | AK5: 3600 | AL5: 4050
B6: 1 | C6: 0 | D6: 0 | E6: 0 | F6: 0 | G6: 0 | I6: BG_Symbol (2) | J6: 1500 | L6: 0.15 | M6: 8000 | N6: BG_Symbol (2) | O6: 0 | P6: 0 | Q6: 0 | R6: 0 | S6: 0 | T6: 4970 | U6: 3000 | V6: 1350 | W6: 500 | X6: 30 | Y6: 60 | Z6: 30 | AA6: 60 | AB6: 14.665 | AC6: BG_Symbol (2) | AD6: 0 | AE6: 0 | AF6: 1050 | AG6: 1400 | AH6: 1750 | AI6: 2100 | AJ6: 3675 | AK6: 4200 | AL6: 4725
B7: 2 | C7: 2 | D7: 2 | E7: 2 | F7: 2 | G7: 2 | I7: BG_Symbol (3) | J7: 2000 | L7: 0.2 | N7: BG_Symbol (3) | O7: 10000 | P7: 0 | Q7: 0 | R7: 0 | S7: 0 | T7: 0 | U7: 0 | V7: 0 | W7: 0 | X7: 0 | Y7: 0 | Z7: 0 | AA7: 0 | AB7: 0 | AC7: BG_Symbol (3) | AD7: 0 | AE7: 0 | AF7: 0 | AG7: 0 | AH7: 0 | AI7: 0 | AJ7: 0 | AK7: 0 | AL7: 0
B8: 3 | C8: 0 | D8: 1 | E8: 2 | F8: 1 | G8: 0 | J8: 10000 | K8: 0 | N8: FG_Symbol | O8: 0 | P8: 0 | Q8: 0 | R8: 0 | S8: 0 | T8: 4370 | U8: 2700 | V8: 1400 | W8: 270 | X8: 270 | Y8: 360 | Z8: 270 | AA8: 360 | AB8: 20.4 | AC8: FG_Symbol | AD8: 0 | AE8: 0 | AF8: 525 | AG8: 700 | AH8: 1750 | AI8: 2100 | AJ8: 3675 | AK8: 4200 | AL8: 4725
B9: 4 | C9: 2 | D9: 1 | E9: 0 | F9: 1 | G9: 2 | N9: FG_Symbol (2) | O9: 0 | P9: 0 | Q9: 0 | R9: 0 | S9: 0 | T9: 4370 | U9: 2700 | V9: 1400 | W9: 270 | X9: 270 | Y9: 360 | Z9: 270 | AA9: 360 | AB9: 20.4 | AC9: FG_Symbol (2) | AD9: 0 | AE9: 0 | AF9: 525 | AG9: 700 | AH9: 1750 | AI9: 2100 | AJ9: 3675 | AK9: 4200 | AL9: 4725
B10: 5 | C10: 0 | D10: 0 | E10: 1 | F10: 0 | G10: 0 | I10: Table Selection Weight - Free Game (Weight/Total) | N10: FG_Symbol (3) | O10: 0 | P10: 0 | Q10: 0 | R10: 0 | S10: 0 | T10: 4370 | U10: 2700 | V10: 1400 | W10: 270 | X10: 270 | Y10: 360 | Z10: 270 | AA10: 360 | AB10: 20.4 | AC10: FG_Symbol (3) | AD10: 0 | AE10: 0 | AF10: 525 | AG10: 700 | AH10: 1750 | AI10: 2100 | AJ10: 3675 | AK10: 4200 | AL10: 4725
B11: 6 | C11: 2 | D11: 2 | E11: 1 | F11: 2 | G11: 2 | I11: Worksheet Name | J11: Weight | K11: RTP | N11: BF_Symbol | O11: 10000 | P11: 0 | Q11: 0 | R11: 0 | S11: 0 | T11: 0 | U11: 0 | V11: 0 | W11: 0 | X11: 0 | Y11: 0 | Z11: 0 | AA11: 0 | AB11: 0 | AC11: BF_Symbol | AD11: 0 | AE11: 0 | AF11: 0 | AG11: 0 | AH11: 0 | AI11: 0 | AJ11: 0 | AK11: 0 | AL11: 0
B12: 7 | C12: 1 | D12: 2 | E12: 2 | F12: 2 | G12: 1 | I12: FG_Symbol | J12: 10000 | L12: 1
B13: 8 | C13: 1 | D13: 0 | E13: 0 | F13: 0 | G13: 1 | I13: FG_Symbol (2) | J13: 0 | L13: 0
B14: 9 | C14: 0 | D14: 1 | E14: 1 | F14: 1 | G14: 0 | I14: FG_Symbol (3) | J14: 0 | L14: 0 | N14: Multiple Selection Weight - Reel3 Before Eliminate (Weight/Total)
B15: 10 | C15: 2 | D15: 1 | E15: 1 | F15: 1 | G15: 2 | J15: 10000 | K15: 0 | N15: Worksheet Name \ Multiple | O15: 0 | P15: 2 | Q15: 3 | R15: 5 | S15: 8 | T15: 10 | U15: 15 | V15: 20 | W15: 25 | X15: 35 | Y15: 50 | Z15: 80 | AA15: 100
B16: 11 | C16: 1 | D16: 1 | E16: 0 | F16: 1 | G16: 1 | N16: BG_Symbol | O16: 10000 | P16: 0 | Q16: 0 | R16: 0 | S16: 0 | T16: 0 | U16: 0 | V16: 0 | W16: 0 | X16: 0 | Y16: 0 | Z16: 0 | AA16: 0 | AB16: 0
B17: 12 | C17: 1 | D17: 1 | E17: 2 | F17: 1 | G17: 1 | I17: Table Selection Weight - Buy Feature (Weight/Total) | N17: BG_Symbol (2) | O17: 0 | P17: 4200 | Q17: 3400 | R17: 1200 | S17: 1200 | T17: 0 | U17: 0 | V17: 0 | W17: 0 | X17: 0 | Y17: 0 | Z17: 0 | AA17: 0 | AB17: 3.42
B18: 13 | C18: 1 | D18: 0 | E18: 1 | F18: 0 | G18: 1 | I18: Worksheet Name | J18: Weight | K18: RTP | N18: BG_Symbol (3) | O18: 10000 | P18: 0 | Q18: 0 | R18: 0 | S18: 0 | T18: 0 | U18: 0 | V18: 0 | W18: 0 | X18: 0 | Y18: 0 | Z18: 0 | AA18: 0 | AB18: 0
B19: 14 | C19: 1 | D19: 2 | E19: 1 | F19: 2 | G19: 1 | I19: FG_Symbol | J19: 10000 | L19: 1 | N19: FG_Symbol | O19: 0 | P19: 6300 | Q19: 2800 | R19: 600 | S19: 300 | T19: 0 | U19: 0 | V19: 0 | W19: 0 | X19: 0 | Y19: 0 | Z19: 0 | AA19: 0 | AB19: 2.64
B20: 15 | C20: 0 | D20: 1 | E20: 0 | F20: 1 | G20: 0 | I20: FG_Symbol (2) | J20: 0 | L20: 0 | N20: FG_Symbol (2) | O20: 0 | P20: 6300 | Q20: 2800 | R20: 600 | S20: 300 | T20: 0 | U20: 0 | V20: 0 | W20: 0 | X20: 0 | Y20: 0 | Z20: 0 | AA20: 0 | AB20: 2.64
B21: 16 | C21: 2 | D21: 1 | E21: 2 | F21: 1 | G21: 2 | I21: FG_Symbol (3) | J21: 0 | L21: 0 | N21: FG_Symbol (3) | O21: 0 | P21: 6300 | Q21: 2800 | R21: 600 | S21: 300 | T21: 0 | U21: 0 | V21: 0 | W21: 0 | X21: 0 | Y21: 0 | Z21: 0 | AA21: 0 | AB21: 2.64
B22: 17 | C22: 0 | D22: 0 | E22: 1 | F22: 2 | G22: 2 | J22: 10000 | K22: 0 | N22: BF_Symbol | O22: 10000 | P22: 0 | Q22: 0 | R22: 0 | S22: 0 | T22: 0 | U22: 0 | V22: 0 | W22: 0 | X22: 0 | Y22: 0 | Z22: 0 | AA22: 0 | AB22: 0
B23: 18 | C23: 2 | D23: 2 | E23: 1 | F23: 0 | G23: 0
B24: 19 | C24: 0 | D24: 2 | E24: 0 | F24: 2 | G24: 0 | I24: Multiplier Range
I25: Multiplier | N25: Multiple Selection Weight - Reel3 After Eliminate (Weight/Total)
I26: 0 | N26: Worksheet Name \ Multiple | O26: 0 | P26: 2 | Q26: 3 | R26: 5 | S26: 8 | T26: 10 | U26: 15 | V26: 20 | W26: 25 | X26: 35 | Y26: 50 | Z26: 80 | AA26: 100
I27: 2 | N27: BG_Symbol | O27: 10000 | P27: 0 | Q27: 0 | R27: 0 | S27: 0 | T27: 0 | U27: 0 | V27: 0 | W27: 0 | X27: 0 | Y27: 0 | Z27: 0 | AA27: 0 | AB27: 0
I28: 3 | N28: BG_Symbol (2) | O28: 0 | P28: 4800 | Q28: 4000 | R28: 600 | S28: 600 | T28: 0 | U28: 0 | V28: 0 | W28: 0 | X28: 0 | Y28: 0 | Z28: 0 | AA28: 0 | AB28: 2.94
I29: 5 | N29: BG_Symbol (3) | O29: 10000 | P29: 0 | Q29: 0 | R29: 0 | S29: 0 | T29: 0 | U29: 0 | V29: 0 | W29: 0 | X29: 0 | Y29: 0 | Z29: 0 | AA29: 0 | AB29: 0
I30: 8 | N30: FG_Symbol | O30: 0 | P30: 6550 | Q30: 3000 | R30: 300 | S30: 150 | T30: 0 | U30: 0 | V30: 0 | W30: 0 | X30: 0 | Y30: 0 | Z30: 0 | AA30: 0 | AB30: 2.48
I31: 10 | N31: FG_Symbol (2) | O31: 0 | P31: 6550 | Q31: 3000 | R31: 300 | S31: 150 | T31: 0 | U31: 0 | V31: 0 | W31: 0 | X31: 0 | Y31: 0 | Z31: 0 | AA31: 0 | AB31: 2.48
I32: 15 | N32: FG_Symbol (3) | O32: 0 | P32: 6550 | Q32: 3000 | R32: 300 | S32: 150 | T32: 0 | U32: 0 | V32: 0 | W32: 0 | X32: 0 | Y32: 0 | Z32: 0 | AA32: 0 | AB32: 2.48
I33: 20 | N33: BF_Symbol | O33: 10000 | P33: 0 | Q33: 0 | R33: 0 | S33: 0 | T33: 0 | U33: 0 | V33: 0 | W33: 0 | X33: 0 | Y33: 0 | Z33: 0 | AA33: 0 | AB33: 0
I34: 25
I35: 35
I36: 50 | N36: Multiple Selection Weight - Before Eliminate (Weight/Total)
I37: 80 | N37: Worksheet Name \ Multiple | O37: 0 | P37: 2 | Q37: 3 | R37: 5 | S37: 8 | T37: 10 | U37: 15 | V37: 20 | W37: 25 | X37: 35 | Y37: 50 | Z37: 80 | AA37: 100
I38: 100 | N38: BG_Symbol | O38: 8500 | P38: 500 | Q38: 400 | R38: 300 | S38: 300 | T38: 0 | U38: 0 | V38: 0 | W38: 0 | X38: 0 | Y38: 0 | Z38: 0 | AA38: 0 | AB38: 4.0666667
N39: BG_Symbol (2) | O39: 9100 | P39: 350 | Q39: 250 | R39: 150 | S39: 150 | T39: 0 | U39: 0 | V39: 0 | W39: 0 | X39: 0 | Y39: 0 | Z39: 0 | AA39: 0 | AB39: 3.7777778
N40: BG_Symbol (3) | O40: 9200 | P40: 400 | Q40: 300 | R40: 50 | S40: 50 | T40: 0 | U40: 0 | V40: 0 | W40: 0 | X40: 0 | Y40: 0 | Z40: 0 | AA40: 0 | AB40: 2.9375
I41: Eliminate Table Weight | N41: FG_Symbol | O41: 6710 | P41: 2100 | Q41: 860 | R41: 220 | S41: 110 | T41: 0 | U41: 0 | V41: 0 | W41: 0 | X41: 0 | Y41: 0 | Z41: 0 | AA41: 0 | AB41: 2.662614
...

Sheet Multiplier_Weight
C2: Newbie | D2: Newbie | E2: Oldhand | F2: Oldhand | G2: Oldhand
B3: Range | C3: Weight_BG | D3: Weight_FG | E3: Weight_BG | F3: Weight_FG | G3: Weight_BF
B4: (-1, 0] | C4: {=IFERROR([1]Multiplier_Weight_Newbie!$L$15:$L$79, 0)} -> 0 | D4: {=IFERROR([1]Multiplier_Weight_Newbie!$L$87:$L$150, 0)} -> 0 | E4: {=_xlfn.ANCHORARRAY([1]Multiplier_Weight_Oldhand!L15)} -> 722907411 | F4: {=_xlfn.ANCHORARRAY([1]Multiplier_Weight_Oldhand!L87)} -> 0 | G4: {=_xlfn.ANCHORARRAY([1]Multiplier_Weight_Oldhand!L157)} -> 0
B5: (0, 1] | C5: 0 | D5: 0 | E5: 161351627 | F5: 0 | G5: 0
B6: (1, 2] | C6: 0 | D6: 0 | E6: 45754318 | F6: 0 | G6: 0
B7: (2, 3] | C7: 0 | D7: 0 | E7: 21756756 | F7: 0 | G7: 0
B8: (3, 4] | C8: 0 | D8: 0 | E8: 8506399 | F8: 0 | G8: 0
B9: (4, 5] | C9: 0 | D9: 0 | E9: 6669454 | F9: 0 | G9: 0
B10: (5, 6] | C10: 0 | D10: 0 | E10: 5453883 | F10: 0 | G10: 0
B11: (6, 7] | C11: 0 | D11: 0 | E11: 3331650 | F11: 0 | G11: 0
B12: (7, 8] | C12: 0 | D12: 0 | E12: 2815459 | F12: 0 | G12: 0
B13: (8, 9] | C13: 0 | D13: 0 | E13: 2544451 | F13: 0 | G13: 0
B14: (9, 10] | C14: 0 | D14: 0 | E14: 2271743 | F14: 0 | G14: 0
B15: (10, 15] | C15: 0 | D15: 0 | E15: 3023686 | F15: 131266259 | G15: 117561927
B16: (15, 20] | C16: 0 | D16: 0 | E16: 3964399 | F16: 131252488 | G16: 117549593
... B67: (100000, 9999999] | C67: 0 | D67: 0 | E67: 0 | F67: 0 | G67: 0
B68: Free Game | C68: 0 | E68: 4173600

Sheet OP Jackpot
B3: NB-Newbie-A
B4: BGC1Screen | E4: =SUM(D4:D5)/C4 -> #DIV/0!
B5: FGC1Screen
B7: NB-Newbie-B
B8: BGC1Screen | E8: =SUM(D8:D9)/C8 -> #DIV/0!
B9: FGC1Screen
B11: NB-Oldhand-A
B12: BGC1Screen | E12: =SUM(D12:D13)/C12 -> #DIV/0!
B13: FGC1Screen
B15: NB-Oldhand-B
B16: BGC1Screen | E16: =SUM(D16:D17)/C16 -> #DIV/0!
B17: FGC1Screen
B19: BF-A
B20: BGC1Screen | E20: =SUM(D20:D21)/C20 -> #DIV/0!
B21: FGC1Screen
B23: BF-B
B24: BGC1Screen | E24: =SUM(D24:D25)/C24 -> #DIV/0!
B25: FGC1Screen
B28: Threshold | C28: 10000000000
B30: NB-Newbie-A | C30: =ROUND(E4*$C$28, 0) -> #DIV/0!
B31: NB-Newbie-B | C31: =ROUND(E8*$C$28, 0) -> #DIV/0!
B32: NB-Oldhand-A | C32: =ROUND(E12*$C$28, 0) -> #DIV/0!
B33: NB-Oldhand-B | C33: =ROUND(E16*$C$28, 0) -> #DIV/0!
B34: BF-A | C34: =ROUND(E20*$C$28, 0) -> #DIV/0!
B35: BF-B | C35: =ROUND(E24*$C$28, 0) -> #DIV/0!

Sheet BG_Symbol
J2: Symbol | Q2: Symbol ID | W2: Symbol Weight | AC2: Eliminate Wheel Weight A | AJ2: Eliminate Wheel Weight A
A3: Symbol | B3: Description | C3: R1 | D3: R2 | E3: R3 | F3: R4 | G3: R5 | H3: ID | K3: R1 | L3: R2 | M3: R3 | N3: R4 | O3: R5 | Q3: R1 | R3: R2 | S3: R3 | T3: R4 | U3: R5 | W3: R1 | X3: R2 | Y3: R3 | Z3: R4 | AA3: R5
A4: {=Overview!A38:B57} -> WW | B4: Wild | C4: =COUNTIF(K:K, $A4) -> 0 | D4: =COUNTIF(L:L, $A4) -> 0 | E4: =COUNTIF(M:M, $A4) -> 0 | F4: =COUNTIF(N:N, $A4) -> 0 | G4: =COUNTIF(O:O, $A4) -> 0 | H4: {=Overview!F38:F57} -> 0 | J4: {=_xlfn.SEQUENCE(MAX(COUNTA(K:K), COUNTA(L:L), COUNTA(M:M), COUNTA(N:N), COUNTA(O:O))-1,,0)} -> 0 | K4: M5 | L4: M5 | M4: M5 | N4: GK | O4: M4 | Q4: {=_xlfn.LET(_xlpm.x, K4:O304, IF(_xlpm.x="", "", _xlfn.XLOOKUP(_xlpm.x, $A$4:$A$23,_xlfn.ANCHORARRAY( H4))))} -> 6 | R4: 6 | S4: 6 | T4: 17 | U4: 5 | W4: 1 | X4: 1 | Y4: 1 | Z4: 1 | AA4: 1 | AC4: 1 Combo | AJ4: 1 Combo
A5: C1 | B5: Scatter | C5: =COUNTIF(K:K, $A5) -> 0 | D5: =COUNTIF(L:L, $A5) -> 6 | E5: =COUNTIF(M:M, $A5) -> 0 | F5: =COUNTIF(N:N, $A5) -> 9 | G5: =COUNTIF(O:O, $A5) -> 0 | H5: 1 | J5: 1 | K5: K | L5: M1 | M5: K | N5: Q | O5: M2 | Q5: 8 | R5: 2 | S5: 8 | T5: 9 | U5: 3 | W5: 1 | X5: 1 | Y5: 1 | Z5: 1 | AA5: 1 | AC5: Symbol | AD5: R1 | AE5: R2 | AF5: R3 | AG5: R4 | AH5: R5 | AJ5: Symbol | AK5: R1 | AL5: R2 | AM5: R3 | AN5: R4 | AO5: R5
A6: M1 | B6: M1 | C6: =COUNTIF(K:K, $A6) -> 4 | D6: =COUNTIF(L:L, $A6) -> 11 | E6: =COUNTIF(M:M, $A6) -> 5 | F6: =COUNTIF(N:N, $A6) -> 21 | G6: =COUNTIF(O:O, $A6) -> 23 | H6: 2 | J6: 2 | K6: M4 | L6: G4 | M6: GK | N6: M3 | O6: M2 | Q6: 5 | R6: 14 | S6: 17 | T6: 4 | U6: 3 | W6: 1 | X6: 1 | Y6: 1 | Z6: 1 | AA6: 1 | AC6: {=$A$4:$A$23} -> WW | AD6: 0 | AE6: 0 | AF6: 0 | AG6: 0 | AH6: 0 | AJ6: {=$A$4:$A$23} -> WW | AK6: 0 | AL6: 0 | AM6: 0 | AN6: 0 | AO6: 0
A7: M2 | B7: M2 | C7: =COUNTIF(K:K, $A7) -> 4 | D7: =COUNTIF(L:L, $A7) -> 11 | E7: =COUNTIF(M:M, $A7) -> 5 | F7: =COUNTIF(N:N, $A7) -> 21 | G7: =COUNTIF(O:O, $A7) -> 23 | H7: 3 | J7: 3 | K7: A | L7: A | M7: M4 | N7: M3 | O7: J | Q7: 7 | R7: 7 | S7: 5 | T7: 4 | U7: 10 | W7: 1 | X7: 1 | Y7: 1 | Z7: 1 | AA7: 1 | AC7: C1 | AD7: 0 | AE7: 6 | AF7: 0 | AG7: 9 | AH7: 0 | AJ7: C1 | AK7: 0 | AL7: 6 | AM7: 0 | AN7: 9 | AO7: 0
A8: M3 | B8: M3 | C8: =COUNTIF(K:K, $A8) -> 4 | D8: =COUNTIF(L:L, $A8) -> 11 | E8: =COUNTIF(M:M, $A8) -> 5 | F8: =COUNTIF(N:N, $A8) -> 21 | G8: =COUNTIF(O:O, $A8) -> 22 | H8: 4 | J8: 4 | K8: K | L8: M5 | M8: M2 | N8: GK | O8: K | Q8: 8 | R8: 6 | S8: 3 | T8: 17 | U8: 8 | W8: 1 | X8: 1 | Y8: 1 | Z8: 1 | AA8: 1 | AC8: M1 | AD8: 4 | AE8: 11 | AF8: 5 | AG8: 21 | AH8: 23 | AJ8: M1 | AK8: 4 | AL8: 11 | AM8: 5 | AN8: 21 | AO8: 23
A9: M4 | B9: M4 | C9: =COUNTIF(K:K, $A9) -> 43 | D9: =COUNTIF(L:L, $A9) -> 20 | E9: =COUNTIF(M:M, $A9) -> 41 | F9: =COUNTIF(N:N, $A9) -> 14 | G9: =COUNTIF(O:O, $A9) -> 22 | H9: 5 | J9: 5 | K9: A | L9: G2 | M9: A | N9: GQ | O9: J | Q9: 7 | R9: 12 | S9: 7 | T9: 18 | U9: 10 | W9: 1 | X9: 1 | Y9: 1 | Z9: 1 | AA9: 1 | AC9: M2 | AD9: 4 | AE9: 11 | AF9: 5 | AG9: 21 | AH9: 23 | AJ9: M2 | AK9: 4 | AL9: 11 | AM9: 5 | AN9: 21 | AO9: 23
A10: M5 | B10: M5 | C10: =COUNTIF(K:K, $A10) -> 43 | D10: =COUNTIF(L:L, $A10) -> 21 | E10: =COUNTIF(M:M, $A10) -> 41 | F10: =COUNTIF(N:N, $A10) -> 14 | G10: =COUNTIF(O:O, $A10) -> 22 | H10: 6 | J10: 6 | K10: K | L10: A | M10: G5 | N10: M5 | O10: A | Q10: 8 | R10: 7 | S10: 15 | T10: 6 | U10: 7 | W10: 1 | X10: 1 | Y10: 1 | Z10: 1 | AA10: 1 | AC10: M3 | AD10: 4 | AE10: 11 | AF10: 5 | AG10: 21 | AH10: 22 | AJ10: M3 | AK10: 4 | AL10: 11 | AM10: 5 | AN10: 21 | AO10: 22
A11: A | B11: A | C11: =COUNTIF(K:K, $A11) -> 47 | D11: =COUNTIF(L:L, $A11) -> 21 | E11: =COUNTIF(M:M, $A11) -> 41 | F11: =COUNTIF(N:N, $A11) -> 14 | G11: =COUNTIF(O:O, $A11) -> 22 | H11: 7 | J11: 7 | K11: K | L11: A | M11: Q | N11: M1 | O11: A | Q11: 8 | R11: 7 | S11: 9 | T11: 2 | U11: 7 | W11: 1 | X11: 1 | Y11: 1 | Z11: 1 | AA11: 1 | AC11: M4 | AD11: 43 | AE11: 20 | AF11: 41 | AG11: 14 | AH11: 22 | AJ11: M4 | AK11: 43 | AL11: 20 | AM11: 41 | AN11: 14 | AO11: 22
A12: K | B12: K | C12: =COUNTIF(K:K, $A12) -> 47 | D12: =COUNTIF(L:L, $A12) -> 21 | E12: =COUNTIF(M:M, $A12) -> 41 | F12: =COUNTIF(N:N, $A12) -> 14 | G12: =COUNTIF(O:O, $A12) -> 22 | H12: 8 | J12: 8 | K12: A | L12: A | M12: K | N12: G2 | O12: M4 | Q12: 7 | R12: 7 | S12: 8 | T12: 12 | U12: 5 | W12: 1 | X12: 1 | Y12: 1 | Z12: 1 | AA12: 1 | AC12: M5 | AD12: 43 | AE12: 21 | AF12: 41 | AG12: 14 | AH12: 22 | AJ12: M5 | AK12: 43 | AL12: 21 | AM12: 41 | AN12: 14 | AO12: 22
A13: Q | B13: Q | C13: =COUNTIF(K:K, $A13) -> 4 | D13: =COUNTIF(L:L, $A13) -> 11 | E13: =COUNTIF(M:M, $A13) -> 5 | F13: =COUNTIF(N:N, $A13) -> 20 | G13: =COUNTIF(O:O, $A13) -> 22 | H13: 9 | J13: 9 | K13: M5 | L13: M4 | M13: K | N13: A | O13: Q | Q13: 6 | R13: 5 | S13: 8 | T13: 7 | U13: 9 | W13: 1 | X13: 1 | Y13: 1 | Z13: 1 | AA13: 1 | AC13: A | AD13: 47 | AE13: 21 | AF13: 41 | AG13: 14 | AH13: 22 | AJ13: A | AK13: 47 | AL13: 21 | AM13: 41 | AN13: 14 | AO13: 22
A14: J | B14: J | C14: =COUNTIF(K:K, $A14) -> 4 | D14: =COUNTIF(L:L, $A14) -> 11 | E14: =COUNTIF(M:M, $A14) -> 4 | F14: =COUNTIF(N:N, $A14) -> 20 | G14: =COUNTIF(O:O, $A14) -> 22 | H14: 10 | J14: 10 | K14: A | L14: J | M14: M5 | N14: G5 | O14: K | Q14: 7 | R14: 10 | S14: 6 | T14: 15 | U14: 8 | W14: 1 | X14: 1 | Y14: 1 | Z14: 1 | AA14: 1 | AC14: K | AD14: 47 | AE14: 21 | AF14: 41 | AG14: 14 | AH14: 22 | AJ14: K | AK14: 47 | AL14: 21 | AM14: 41 | AN14: 14 | AO14: 22
A15: G1 | B15: Gold M1 | C15: =COUNTIF(K:K, $A15) -> 0 | D15: =COUNTIF(L:L, $A15) -> 4 | E15: =COUNTIF(M:M, $A15) -> 0 | F15: =COUNTIF(N:N, $A15) -> 4 | G15: =COUNTIF(O:O, $A15) -> 0 | H15: 11 | J15: 11 | K15: M5 | L15: A | M15: A | N15: K | O15: M1 | Q15: 6 | R15: 7 | S15: 7 | T15: 8 | U15: 2 | W15: 1 | X15: 1 | Y15: 1 | Z15: 1 | AA15: 1 | AC15: Q | AD15: 4 | AE15: 11 | AF15: 5 | AG15: 20 | AH15: 22 | AJ15: Q | AK15: 4 | AL15: 11 | AM15: 5 | AN15: 20 | AO15: 22
A16: G2 | B16: Gold M2 | C16: =COUNTIF(K:K, $A16) -> 0 | D16: =COUNTIF(L:L, $A16) -> 5 | E16: =COUNTIF(M:M, $A16) -> 0 | F16: =COUNTIF(N:N, $A16) -> 4 | G16: =COUNTIF(O:O, $A16) -> 0 | H16: 12 | J16: 12 | K16: A | L16: G1 | M16: A | N16: K | O16: M2 | Q16: 7 | R16: 11 | S16: 7 | T16: 8 | U16: 3 | W16: 1 | X16: 1 | Y16: 1 | Z16: 1 | AA16: 1 | AC16: J | AD16: 4 | AE16: 11 | AF16: 4 | AG16: 20 | AH16: 22 | AJ16: J | AK16: 4 | AL16: 11 | AM16: 4 | AN16: 20 | AO16: 22
A17: G3 | B17: Gold M3 | C17: =COUNTIF(K:K, $A17) -> 0 | D17: =COUNTIF(L:L, $A17) -> 5 | E17: =COUNTIF(M:M, $A17) -> 0 | F17: =COUNTIF(N:N, $A17) -> 4 | G17: =COUNTIF(O:O, $A17) -> 0 | H17: 13 | J17: 13 | K17: K | L17: M1 | M17: A | N17: M3 | O17: Q | Q17: 8 | R17: 2 | S17: 7 | T17: 4 | U17: 9 | W17: 1 | X17: 1 | Y17: 1 | Z17: 1 | AA17: 1 | AC17: G1 | AD17: 0 | AE17: 4 | AF17: 0 | AG17: 4 | AH17: 0 | AJ17: G1 | AK17: 0 | AL17: 4 | AM17: 0 | AN17: 4 | AO17: 0
A18: G4 | B18: Gold M4 | C18: =COUNTIF(K:K, $A18) -> 0 | D18: =COUNTIF(L:L, $A18) -> 8 | E18: =COUNTIF(M:M, $A18) -> 3 | F18: =COUNTIF(N:N, $A18) -> 3 | G18: =COUNTIF(O:O, $A18) -> 0 | H18: 14 | J18: 14 | K18: M5 | L18: A | M18: G4 | N18: K | O18: Q | Q18: 6 | R18: 7 | S18: 14 | T18: 8 | U18: 9 | W18: 1 | X18: 1 | Y18: 1 | Z18: 1 | AA18: 1 | AC18: G2 | AD18: 0 | AE18: 5 | AF18: 0 | AG18: 4 | AH18: 0 | AJ18: G2 | AK18: 0 | AL18: 5 | AM18: 0 | AN18: 4 | AO18: 0
... A23: GJ | B23: Gold J | C23: =COUNTIF(K:K, $A23) -> 0 | D23: =COUNTIF(L:L, $A23) -> 5 | E23: =COUNTIF(M:M, $A23) -> 0 | F23: =COUNTIF(N:N, $A23) -> 4 | G23: =COUNTIF(O:O, $A23) -> 0 | H23: 19 | J23: 19 | K23: M4 | L23: M5 | M23: GA | N23: G4 | O23: M1 | Q23: 5 | R23: 6 | S23: 16 | T23: 14 | U23: 2 | W23: 1 | X23: 1 | Y23: 1 | Z23: 1 | AA23: 1 | AC23: GK | AD23: 0 | AE23: 8 | AF23: 3 | AG23: 3 | AH23: 0 | AJ23: GK | AK23: 0 | AL23: 8 | AM23: 3 | AN23: 3 | AO23: 0
C24: =SUM(C4:C23) -> 200 | D24: =SUM(D4:D23) -> 200 | E24: =SUM(E4:E23) -> 200 | F24: =SUM(F4:F23) -> 200 | G24: =SUM(G4:G23) -> 200 | J24: 20 | K24: A | L24: K | M24: A | N24: M4 | O24: Q | Q24: 7 | R24: 8 | S24: 7 | T24: 5 | U24: 9 | W24: 1 | X24: 1 | Y24: 1 | Z24: 1 | AA24: 1 | AC24: GQ | AD24: 0 | AE24: 5 | AF24: 0 | AG24: 4 | AH24: 0 | AJ24: GQ | AK24: 0 | AL24: 5 | AM24: 0 | AN24: 4 | AO24: 0
J25: 21 | K25: M4 | L25: A | M25: Q | N25: M4 | O25: J | Q25: 5 | R25: 7 | S25: 9 | T25: 5 | U25: 10 | W25: 1 | X25: 1 | Y25: 1 | Z25: 1 | AA25: 1 | AC25: GJ | AD25: 0 | AE25: 5 | AF25: 0 | AG25: 4 | AH25: 0 | AJ25: GJ | AK25: 0 | AL25: 5 | AM25: 0 | AN25: 4 | AO25: 0
B26: Normal Symbol | C26: =SUM(C4:C14)/C24 -> 1 | D26: =SUM(D4:D14)/D24 -> 0.72 | E26: =SUM(E4:E14)/E24 -> 0.94 | F26: =SUM(F4:F14)/F24 -> 0.84 | G26: =SUM(G4:G14)/G24 -> 1 | J26: 22 | K26: Q | L26: Q | M26: M4 | N26: Q | O26: K | Q26: 9 | R26: 9 | S26: 5 | T26: 9 | U26: 8 | W26: 1 | X26: 1 | Y26: 1 | Z26: 1 | AA26: 1 | AD26: =SUM(AD6:AD25) -> 200 | AE26: =SUM(AE6:AE25) -> 200 | AF26: =SUM(AF6:AF25) -> 200 | AG26: =SUM(AG6:AG25) -> 200 | AH26: =SUM(AH6:AH25) -> 200 | AK26: =SUM(AK6:AK25) -> 200 | AL26: =SUM(AL6:AL25) -> 200 | AM26: =SUM(AM6:AM25) -> 200 | AN26: =SUM(AN6:AN25) -> 200 | AO26: =SUM(AO6:AO25) -> 200
B27: Golden Symbol | C27: =SUM(C15:C23)/C24 -> 0 | D27: =SUM(D15:D23)/D24 -> 0.28 | E27: =SUM(E15:E23)/E24 -> 0.06 | F27: =SUM(F15:F23)/F24 -> 0.16 | G27: =SUM(G15:G23)/G24 -> 0 | J27: 23 | K27: M4 | L27: M5 | M27: K | N27: M1 | O27: M2 | Q27: 5 | R27: 6 | S27: 8 | T27: 2 | U27: 3 | W27: 1 | X27: 1 | Y27: 1 | Z27: 1 | AA27: 1
J28: 24 | K28: K | L28: K | M28: M4 | N28: Q | O28: M1 | Q28: 8 | R28: 8 | S28: 5 | T28: 9 | U28: 2 | W28: 1 | X28: 1 | Y28: 1 | Z28: 1 | AA28: 1 | AC28: 2 Combo | AJ28: 2 Combo
J29: 25 | K29: M4 | L29: GJ | M29: A | N29: Q | O29: A | Q29: 5 | R29: 19 | S29: 7 | T29: 9 | U29: 7 | W29: 1 | X29: 1 | Y29: 1 | Z29: 1 | AA29: 1 | AC29: Symbol | AD29: R1 | AE29: R2 | AF29: R3 | AG29: R4 | AH29: R5 | AJ29: Symbol | AK29: R1 | AL29: R2 | AM29: R3 | AN29: R4 | AO29: R5
J30: 26 | K30: M2 | L30: G5 | M30: M4 | N30: Q | O30: M4 | Q30: 3 | R30: 15 | S30: 5 | T30: 9 | U30: 5 | W30: 1 | X30: 1 | Y30: 1 | Z30: 1 | AA30: 1 | AC30: {=$A$4:$A$23} -> WW | AD30: 0 | AE30: 0 | AF30: 0 | AG30: 0 | AH30: 0 | AJ30: {=$A$4:$A$23} -> WW | AK30: 0 | AL30: 0 | AM30: 0 | AN30: 0 | AO30: 0
J31: 27 | K31: M4 | L31: A | M31: K | N31: J | O31: M1 | Q31: 5 | R31: 7 | S31: 8 | T31: 10 | U31: 2 | W31: 1 | X31: 1 | Y31: 1 | Z31: 1 | AA31: 1 | AC31: C1 | AD31: 0 | AE31: 6 | AF31: 0 | AG31: 9 | AH31: 0 | AJ31: C1 | AK31: 0 | AL31: 6 | AM31: 0 | AN31: 9 | AO31: 0
J32: 28 | K32: A | L32: J | M32: M4 | N32: G4 | O32: M5 | Q32: 7 | R32: 10 | S32: 5 | T32: 14 | U32: 6 | W32: 1 | X32: 1 | Y32: 1 | Z32: 1 | AA32: 1 | AC32: M1 | AD32: 4 | AE32: 11 | AF32: 5 | AG32: 21 | AH32: 23 | AJ32: M1 | AK32: 4 | AL32: 11 | AM32: 5 | AN32: 21 | AO32: 23
J33: 29 | K33: M4 | L33: M5 | M33: K | N33: K | O33: M2 | Q33: 5 | R33: 6 | S33: 8 | T33: 8 | U33: 3 | W33: 1 | X33: 1 | Y33: 1 | Z33: 1 | AA33: 1 | AC33: M2 | AD33: 4 | AE33: 11 | AF33: 5 | AG33: 21 | AH33: 23 | AJ33: M2 | AK33: 4 | AL33: 11 | AM33: 5 | AN33: 21 | AO33: 23
J34: 30 | K34: M5 | L34: GQ | M34: A | N34: M1 | O34: Q | Q34: 6 | R34: 18 | S34: 7 | T34: 2 | U34: 9 | W34: 1 | X34: 1 | Y34: 1 | Z34: 1 | AA34: 1 | AC34: M3 | AD34: 4 | AE34: 11 | AF34: 5 | AG34: 21 | AH34: 22 | AJ34: M3 | AK34: 4 | AL34: 11 | AM34: 5 | AN34: 21 | AO34: 22
J35: 31 | K35: M4 | L35: A | M35: K | N35: M2 | O35: J | Q35: 5 | R35: 7 | S35: 8 | T35: 3 | U35: 10 | W35: 1 | X35: 1 | Y35: 1 | Z35: 1 | AA35: 1 | AC35: M4 | AD35: 43 | AE35: 20 | AF35: 41 | AG35: 14 | AH35: 22 | AJ35: M4 | AK35: 43 | AL35: 20 | AM35: 41 | AN35: 14 | AO35: 22
J36: 32 | K36: A | L36: M1 | M36: K | N36: M2 | O36: M4 | Q36: 7 | R36: 2 | S36: 8 | T36: 3 | U36: 5 | W36: 1 | X36: 1 | Y36: 1 | Z36: 1 | AA36: 1 | AC36: M5 | AD36: 43 | AE36: 21 | AF36: 41 | AG36: 14 | AH36: 22 | AJ36: M5 | AK36: 43 | AL36: 21 | AM36: 41 | AN36: 14 | AO36: 22
J37: 33 | K37: M5 | L37: A | M37: K | N37: M2 | O37: M5 | Q37: 6 | R37: 7 | S37: 8 | T37: 3 | U37: 6 | W37: 1 | X37: 1 | Y37: 1 | Z37: 1 | AA37: 1 | AC37: A | AD37: 47 | AE37: 21 | AF37: 41 | AG37: 14 | AH37: 22 | AJ37: A | AK37: 47 | AL37: 21 | AM37: 41 | AN37: 14 | AO37: 22
J38: 34 | K38: K | L38: M5 | M38: A | N38: Q | O38: M3 | Q38: 8 | R38: 6 | S38: 7 | T38: 9 | U38: 4 | W38: 1 | X38: 1 | Y38: 1 | Z38: 1 | AA38: 1 | AC38: K | AD38: 47 | AE38: 21 | AF38: 41 | AG38: 14 | AH38: 22 | AJ38: K | AK38: 47 | AL38: 21 | AM38: 41 | AN38: 14 | AO38: 22
J39: 35 | K39: A | L39: Q | M39: A | N39: M4 | O39: M3 | Q39: 7 | R39: 9 | S39: 7 | T39: 5 | U39: 4 | W39: 1 | X39: 1 | Y39: 1 | Z39: 1 | AA39: 1 | AC39: Q | AD39: 4 | AE39: 11 | AF39: 5 | AG39: 20 | AH39: 22 | AJ39: Q | AK39: 4 | AL39: 11 | AM39: 5 | AN39: 20 | AO39: 22
J40: 36 | K40: M5 | L40: J | M40: M5 | N40: M4 | O40: J | Q40: 6 | R40: 10 | S40: 6 | T40: 5 | U40: 10 | W40: 1 | X40: 1 | Y40: 1 | Z40: 1 | AA40: 1 | AC40: J | AD40: 4 | AE40: 11 | AF40: 4 | AG40: 20 | AH40: 22 | AJ40: J | AK40: 4 | AL40: 11 | AM40: 4 | AN40: 20 | AO40: 22
J41: 37 | K41: M5 | L41: J | M41: K | N41: M3 | O41: J | Q41: 6 | R41: 10 | S41: 8 | T41: 4 | U41: 10 | W41: 1 | X41: 1 | Y41: 1 | Z41: 1 | AA41: 1 | AC41: G1 | AD41: 0 | AE41: 4 | AF41: 0 | AG41: 4 | AH41: 0 | AJ41: G1 | AK41: 0 | AL41: 4 | AM41: 0 | AN41: 4 | AO41: 0
J42: 38 | K42: M5 | L42: M5 | M42: K | N42: GJ | O42: M3 | Q42: 6 | R42: 6 | S42: 8 | T42: 19 | U42: 4 | W42: 1 | X42: 1 | Y42: 1 | Z42: 1 | AA42: 1 | AC42: G2 | AD42: 0 | AE42: 5 | AF42: 0 | AG42: 4 | AH42: 0 | AJ42: G2 | AK42: 0 | AL42: 5 | AM42: 0 | AN42: 4 | AO42: 0
... J49: 45 | K49: A | L49: K | M49: M1 | N49: G1 | O49: A | Q49: 7 | R49: 8 | S49: 2 | T49: 11 | U49: 7 | W49: 1 | X49: 1 | Y49: 1 | Z49: 1 | AA49: 1 | AC49: GJ | AD49: 0 | AE49: 5 | AF49: 0 | AG49: 4 | AH49: 0 | AJ49: GJ | AK49: 0 | AL49: 5 | AM49: 0 | AN49: 4 | AO49: 0
J50: 46 | K50: K | L50: M2 | M50: M5 | N50: M3 | O50: M4 | Q50: 8 | R50: 3 | S50: 6 | T50: 4 | U50: 5 | W50: 1 | X50: 1 | Y50: 1 | Z50: 1 | AA50: 1 | AD50: =SUM(AD30:AD49) -> 200 | AE50: =SUM(AE30:AE49) -> 200 | AF50: =SUM(AF30:AF49) -> 200 | AG50: =SUM(AG30:AG49) -> 200 | AH50: =SUM(AH30:AH49) -> 200 | AK50: =SUM(AK30:AK49) -> 200 | AL50: =SUM(AL30:AL49) -> 200 | AM50: =SUM(AM30:AM49) -> 200 | AN50: =SUM(AN30:AN49) -> 200 | AO50: =SUM(AO30:AO49) -> 200
J51: 47 | K51: K | L51: A | M51: M5 | N51: G2 | O51: K | Q51: 8 | R51: 7 | S51: 6 | T51: 12 | U51: 8 | W51: 1 | X51: 1 | Y51: 1 | Z51: 1 | AA51: 1
...

Sheet BG_Symbol (2)
J2: Symbol | Q2: Symbol ID | W2: Symbol Weight | AC2: Eliminate Wheel Weight A | AJ2: Eliminate Wheel Weight B
A3: Symbol | B3: Description | C3: R1 | D3: R2 | E3: R3 | F3: R4 | G3: R5 | H3: ID | K3: R1 | L3: R2 | M3: R3 | N3: R4 | O3: R5 | Q3: R1 | R3: R2 | S3: R3 | T3: R4 | U3: R5 | W3: R1 | X3: R2 | Y3: R3 | Z3: R4 | AA3: R5
A4: {=Overview!A38:B57} -> WW | B4: Wild | C4: =COUNTIF(K:K, $A4) -> 0 | D4: =COUNTIF(L:L, $A4) -> 0 | E4: =COUNTIF(M:M, $A4) -> 0 | F4: =COUNTIF(N:N, $A4) -> 0 | G4: =COUNTIF(O:O, $A4) -> 0 | H4: {=Overview!F38:F57} -> 0 | J4: {=_xlfn.SEQUENCE(MAX(COUNTA(K:K), COUNTA(L:L), COUNTA(M:M), COUNTA(N:N), COUNTA(O:O))-1,,0)} -> 0 | K4: K | L4: Q | M4: GA | N4: J | O4: M1 | Q4: {=_xlfn.LET(_xlpm.x, K4:O304, IF(_xlpm.x="", "", _xlfn.XLOOKUP(_xlpm.x, $A$4:$A$23,_xlfn.ANCHORARRAY( H4))))} -> 8 | R4: 9 | S4: 16 | T4: 10 | U4: 2 | W4: 1 | X4: 1 | Y4: 1 | Z4: 1 | AA4: 1 | AC4: 1 Combo | AJ4: 1 Combo
A5: C1 | B5: Scatter | C5: =COUNTIF(K:K, $A5) -> 0 | D5: =COUNTIF(L:L, $A5) -> 6 | E5: =COUNTIF(M:M, $A5) -> 0 | F5: =COUNTIF(N:N, $A5) -> 9 | G5: =COUNTIF(O:O, $A5) -> 0 | H5: 1 | J5: 1 | K5: A | L5: A | M5: GQ | N5: M1 | O5: M3 | Q5: 7 | R5: 7 | S5: 18 | T5: 2 | U5: 4 | W5: 1 | X5: 1 | Y5: 1 | Z5: 1 | AA5: 1 | AC5: Symbol | AD5: R1 | AE5: R2 | AF5: R3 | AG5: R4 | AH5: R5 | AJ5: Symbol | AK5: R1 | AL5: R2 | AM5: R3 | AN5: R4 | AO5: R5
A6: M1 | B6: M1 | C6: =COUNTIF(K:K, $A6) -> 4 | D6: =COUNTIF(L:L, $A6) -> 11 | E6: =COUNTIF(M:M, $A6) -> 0 | F6: =COUNTIF(N:N, $A6) -> 22 | G6: =COUNTIF(O:O, $A6) -> 28 | H6: 2 | J6: 2 | K6: M1 | L6: GA | M6: G4 | N6: M3 | O6: M2 | Q6: 2 | R6: 16 | S6: 14 | T6: 4 | U6: 3 | W6: 1 | X6: 1 | Y6: 1 | Z6: 1 | AA6: 1 | AC6: {=$A$4:$A$23} -> WW | AD6: 0 | AE6: 0 | AF6: 0 | AG6: 0 | AH6: 0 | AJ6: {=$A$4:$A$23} -> WW | AK6: 0 | AL6: 0 | AM6: 0 | AN6: 0 | AO6: 0
A7: M2 | B7: M2 | C7: =COUNTIF(K:K, $A7) -> 4 | D7: =COUNTIF(L:L, $A7) -> 11 | E7: =COUNTIF(M:M, $A7) -> 0 | F7: =COUNTIF(N:N, $A7) -> 22 | G7: =COUNTIF(O:O, $A7) -> 27 | H7: 3 | J7: 3 | K7: M4 | L7: Q | M7: G5 | N7: M3 | O7: M2 | Q7: 5 | R7: 9 | S7: 15 | T7: 4 | U7: 3 | W7: 1 | X7: 1 | Y7: 1 | Z7: 1 | AA7: 1 | AC7: C1 | AD7: 0 | AE7: 6 | AF7: 0 | AG7: 9 | AH7: 0 | AJ7: C1 | AK7: 0 | AL7: 6 | AM7: 0 | AN7: 9 | AO7: 0
A8: M3 | B8: M3 | C8: =COUNTIF(K:K, $A8) -> 4 | D8: =COUNTIF(L:L, $A8) -> 11 | E8: =COUNTIF(M:M, $A8) -> 0 | F8: =COUNTIF(N:N, $A8) -> 22 | G8: =COUNTIF(O:O, $A8) -> 27 | H8: 4 | J8: 4 | K8: K | L8: GA | M8: G4 | N8: M2 | O8: K | Q8: 8 | R8: 16 | S8: 14 | T8: 3 | U8: 8 | W8: 1 | X8: 1 | Y8: 1 | Z8: 1 | AA8: 1 | AC8: M1 | AD8: 4 | AE8: 11 | AF8: 0 | AG8: 22 | AH8: 28 | AJ8: M1 | AK8: 4 | AL8: 11 | AM8: 0 | AN8: 22 | AO8: 28
A9: M4 | B9: M4 | C9: =COUNTIF(K:K, $A9) -> 43 | D9: =COUNTIF(L:L, $A9) -> 19 | E9: =COUNTIF(M:M, $A9) -> 0 | F9: =COUNTIF(N:N, $A9) -> 12 | G9: =COUNTIF(O:O, $A9) -> 16 | H9: 5 | J9: 5 | K9: M5 | L9: M3 | M9: GK | N9: M2 | O9: M2 | Q9: 6 | R9: 4 | S9: 17 | T9: 3 | U9: 3 | W9: 1 | X9: 1 | Y9: 1 | Z9: 1 | AA9: 1 | AC9: M2 | AD9: 4 | AE9: 11 | AF9: 0 | AG9: 22 | AH9: 27 | AJ9: M2 | AK9: 4 | AL9: 11 | AM9: 0 | AN9: 22 | AO9: 27
A10: M5 | B10: M5 | C10: =COUNTIF(K:K, $A10) -> 43 | D10: =COUNTIF(L:L, $A10) -> 20 | E10: =COUNTIF(M:M, $A10) -> 0 | F10: =COUNTIF(N:N, $A10) -> 12 | G10: =COUNTIF(O:O, $A10) -> 16 | H10: 6 | J10: 6 | K10: K | L10: M4 | M10: GA | N10: J | O10: A | Q10: 8 | R10: 5 | S10: 16 | T10: 10 | U10: 7 | W10: 1 | X10: 1 | Y10: 1 | Z10: 1 | AA10: 1 | AC10: M3 | AD10: 4 | AE10: 11 | AF10: 0 | AG10: 22 | AH10: 27 | AJ10: M3 | AK10: 4 | AL10: 11 | AM10: 0 | AN10: 22 | AO10: 27
A11: A | B11: A | C11: =COUNTIF(K:K, $A11) -> 47 | D11: =COUNTIF(L:L, $A11) -> 20 | E11: =COUNTIF(M:M, $A11) -> 0 | F11: =COUNTIF(N:N, $A11) -> 12 | G11: =COUNTIF(O:O, $A11) -> 16 | H11: 7 | J11: 7 | K11: M5 | L11: G3 | M11: G5 | N11: J | O11: M5 | Q11: 6 | R11: 13 | S11: 15 | T11: 10 | U11: 6 | W11: 1 | X11: 1 | Y11: 1 | Z11: 1 | AA11: 1 | AC11: M4 | AD11: 43 | AE11: 19 | AF11: 0 | AG11: 12 | AH11: 16 | AJ11: M4 | AK11: 43 | AL11: 19 | AM11: 0 | AN11: 12 | AO11: 16
A12: K | B12: K | C12: =COUNTIF(K:K, $A12) -> 47 | D12: =COUNTIF(L:L, $A12) -> 20 | E12: =COUNTIF(M:M, $A12) -> 0 | F12: =COUNTIF(N:N, $A12) -> 12 | G12: =COUNTIF(O:O, $A12) -> 16 | H12: 8 | J12: 8 | K12: M4 | L12: A | M12: GK | N12: M5 | O12: M5 | Q12: 5 | R12: 7 | S12: 17 | T12: 6 | U12: 6 | W12: 1 | X12: 1 | Y12: 1 | Z12: 1 | AA12: 1 | AC12: M5 | AD12: 43 | AE12: 20 | AF12: 0 | AG12: 12 | AH12: 16 | AJ12: M5 | AK12: 43 | AL12: 20 | AM12: 0 | AN12: 12 | AO12: 16
A13: Q | B13: Q | C13: =COUNTIF(K:K, $A13) -> 4 | D13: =COUNTIF(L:L, $A13) -> 11 | E13: =COUNTIF(M:M, $A13) -> 0 | F13: =COUNTIF(N:N, $A13) -> 21 | G13: =COUNTIF(O:O, $A13) -> 27 | H13: 9 | J13: 9 | K13: K | L13: GJ | M13: G5 | N13: GJ | O13: M1 | Q13: 8 | R13: 19 | S13: 15 | T13: 19 | U13: 2 | W13: 1 | X13: 1 | Y13: 1 | Z13: 1 | AA13: 1 | AC13: A | AD13: 47 | AE13: 20 | AF13: 0 | AG13: 12 | AH13: 16 | AJ13: A | AK13: 47 | AL13: 20 | AM13: 0 | AN13: 12 | AO13: 16
A14: J | B14: J | C14: =COUNTIF(K:K, $A14) -> 4 | D14: =COUNTIF(L:L, $A14) -> 11 | E14: =COUNTIF(M:M, $A14) -> 0 | F14: =COUNTIF(N:N, $A14) -> 21 | G14: =COUNTIF(O:O, $A14) -> 27 | H14: 10 | J14: 10 | K14: Q | L14: G2 | M14: GA | N14: M1 | O14: K | Q14: 9 | R14: 12 | S14: 16 | T14: 2 | U14: 8 | W14: 1 | X14: 1 | Y14: 1 | Z14: 1 | AA14: 1 | AC14: K | AD14: 47 | AE14: 20 | AF14: 0 | AG14: 12 | AH14: 16 | AJ14: K | AK14: 47 | AL14: 20 | AM14: 0 | AN14: 12 | AO14: 16
A15: G1 | B15: Gold M1 | C15: =COUNTIF(K:K, $A15) -> 0 | D15: =COUNTIF(L:L, $A15) -> 4 | E15: =COUNTIF(M:M, $A15) -> 5 | F15: =COUNTIF(N:N, $A15) -> 5 | G15: =COUNTIF(O:O, $A15) -> 0 | H15: 11 | J15: 11 | K15: A | L15: G5 | M15: G4 | N15: A | O15: K | Q15: 7 | R15: 15 | S15: 14 | T15: 7 | U15: 8 | W15: 1 | X15: 1 | Y15: 1 | Z15: 1 | AA15: 1 | AC15: Q | AD15: 4 | AE15: 11 | AF15: 0 | AG15: 21 | AH15: 27 | AJ15: Q | AK15: 4 | AL15: 11 | AM15: 0 | AN15: 21 | AO15: 27
A16: G2 | B16: Gold M2 | C16: =COUNTIF(K:K, $A16) -> 0 | D16: =COUNTIF(L:L, $A16) -> 5 | E16: =COUNTIF(M:M, $A16) -> 5 | F16: =COUNTIF(N:N, $A16) -> 5 | G16: =COUNTIF(O:O, $A16) -> 0 | H16: 12 | J16: 12 | K16: Q | L16: M4 | M16: GK | N16: GA | O16: Q | Q16: 9 | R16: 5 | S16: 17 | T16: 16 | U16: 9 | W16: 1 | X16: 1 | Y16: 1 | Z16: 1 | AA16: 1 | AC16: J | AD16: 4 | AE16: 11 | AF16: 0 | AG16: 21 | AH16: 27 | AJ16: J | AK16: 4 | AL16: 11 | AM16: 0 | AN16: 21 | AO16: 27
A17: G3 | B17: Gold M3 | C17: =COUNTIF(K:K, $A17) -> 0 | D17: =COUNTIF(L:L, $A17) -> 5 | E17: =COUNTIF(M:M, $A17) -> 5 | F17: =COUNTIF(N:N, $A17) -> 5 | G17: =COUNTIF(O:O, $A17) -> 0 | H17: 13 | J17: 13 | K17: K | L17: A | M17: G5 | N17: K | O17: M2 | Q17: 8 | R17: 7 | S17: 15 | T17: 8 | U17: 3 | W17: 1 | X17: 1 | Y17: 1 | Z17: 1 | AA17: 1 | AC17: G1 | AD17: 0 | AE17: 4 | AF17: 5 | AG17: 5 | AH17: 0 | AJ17: G1 | AK17: 0 | AL17: 4 | AM17: 5 | AN17: 5 | AO17: 0
A18: G4 | B18: Gold M4 | C18: =COUNTIF(K:K, $A18) -> 0 | D18: =COUNTIF(L:L, $A18) -> 9 | E18: =COUNTIF(M:M, $A18) -> 44 | F18: =COUNTIF(N:N, $A18) -> 3 | G18: =COUNTIF(O:O, $A18) -> 0 | H18: 14 | J18: 14 | K18: A | L18: GA | M18: G4 | N18: A | O18: J | Q18: 7 | R18: 16 | S18: 14 | T18: 7 | U18: 10 | W18: 1 | X18: 1 | Y18: 1 | Z18: 1 | AA18: 1 | AC18: G2 | AD18: 0 | AE18: 5 | AF18: 5 | AG18: 5 | AH18: 0 | AJ18: G2 | AK18: 0 | AL18: 5 | AM18: 5 | AN18: 5 | AO18: 0
... A23: GJ | B23: Gold J | C23: =COUNTIF(K:K, $A23) -> 0 | D23: =COUNTIF(L:L, $A23) -> 5 | E23: =COUNTIF(M:M, $A23) -> 4 | F23: =COUNTIF(N:N, $A23) -> 4 | G23: =COUNTIF(O:O, $A23) -> 0 | H23: 19 | J23: 19 | K23: M4 | L23: M3 | M23: GK | N23: Q | O23: M1 | Q23: 5 | R23: 4 | S23: 17 | T23: 9 | U23: 2 | W23: 1 | X23: 1 | Y23: 1 | Z23: 1 | AA23: 1 | AC23: GK | AD23: 0 | AE23: 9 | AF23: 44 | AG23: 3 | AH23: 0 | AJ23: GK | AK23: 0 | AL23: 9 | AM23: 44 | AN23: 3 | AO23: 0
C24: =SUM(C4:C23) -> 200 | D24: =SUM(D4:D23) -> 200 | E24: =SUM(E4:E23) -> 200 | F24: =SUM(F4:F23) -> 200 | G24: =SUM(G4:G23) -> 200 | J24: 20 | K24: M5 | L24: G1 | M24: G4 | N24: M3 | O24: Q | Q24: 6 | R24: 11 | S24: 14 | T24: 4 | U24: 9 | W24: 1 | X24: 1 | Y24: 1 | Z24: 1 | AA24: 1 | AC24: GQ | AD24: 0 | AE24: 5 | AF24: 5 | AG24: 4 | AH24: 0 | AJ24: GQ | AK24: 0 | AL24: 5 | AM24: 5 | AN24: 4 | AO24: 0
J25: 21 | K25: M3 | L25: GK | M25: GK | N25: C1 | O25: J | Q25: 4 | R25: 17 | S25: 17 | T25: 1 | U25: 10 | W25: 1 | X25: 1 | Y25: 1 | Z25: 1 | AA25: 1 | AC25: GJ | AD25: 0 | AE25: 5 | AF25: 4 | AG25: 4 | AH25: 0 | AJ25: GJ | AK25: 0 | AL25: 5 | AM25: 4 | AN25: 4 | AO25: 0
B26: Normal Symbol | C26: =SUM(C4:C14)/C24 -> 1 | D26: =SUM(D4:D14)/D24 -> 0.7 | E26: =SUM(E4:E14)/E24 -> 0 | F26: =SUM(F4:F14)/F24 -> 0.825 | G26: =SUM(G4:G14)/G24 -> 1 | J26: 22 | K26: K | L26: M2 | M26: GJ | N26: G5 | O26: M3 | Q26: 8 | R26: 3 | S26: 19 | T26: 15 | U26: 4 | W26: 1 | X26: 1 | Y26: 1 | Z26: 1 | AA26: 1 | AD26: =SUM(AD6:AD25) -> 200 | AE26: =SUM(AE6:AE25) -> 200 | AF26: =SUM(AF6:AF25) -> 200 | AG26: =SUM(AG6:AG25) -> 200 | AH26: =SUM(AH6:AH25) -> 200 | AK26: =SUM(AK6:AK25) -> 200 | AL26: =SUM(AL6:AL25) -> 200 | AM26: =SUM(AM6:AM25) -> 200 | AN26: =SUM(AN6:AN25) -> 200 | AO26: =SUM(AO6:AO25) -> 200
B27: Golden Symbol | C27: =SUM(C15:C23)/C24 -> 0 | D27: =SUM(D15:D23)/D24 -> 0.3 | E27: =SUM(E15:E23)/E24 -> 1 | F27: =SUM(F15:F23)/F24 -> 0.175 | G27: =SUM(G15:G23)/G24 -> 0 | J27: 23 | K27: M4 | L27: Q | M27: G4 | N27: J | O27: M2 | Q27: 5 | R27: 9 | S27: 14 | T27: 10 | U27: 3 | W27: 1 | X27: 1 | Y27: 1 | Z27: 1 | AA27: 1
J28: 24 | K28: M5 | L28: G5 | M28: G5 | N28: K | O28: M1 | Q28: 6 | R28: 15 | S28: 15 | T28: 8 | U28: 2 | W28: 1 | X28: 1 | Y28: 1 | Z28: 1 | AA28: 1 | AC28: 2 Combo | AJ28: 2 Combo
J29: 25 | K29: J | L29: M2 | M29: GK | N29: Q | O29: M3 | Q29: 10 | R29: 3 | S29: 17 | T29: 9 | U29: 4 | W29: 1 | X29: 1 | Y29: 1 | Z29: 1 | AA29: 1 | AC29: Symbol | AD29: R1 | AE29: R2 | AF29: R3 | AG29: R4 | AH29: R5 | AJ29: Symbol | AK29: R1 | AL29: R2 | AM29: R3 | AN29: R4 | AO29: R5
J30: 26 | K30: M5 | L30: K | M30: G4 | N30: M5 | O30: M1 | Q30: 6 | R30: 8 | S30: 14 | T30: 6 | U30: 2 | W30: 1 | X30: 1 | Y30: 1 | Z30: 1 | AA30: 1 | AC30: {=$A$4:$A$23} -> WW | AD30: 0 | AE30: 0 | AF30: 0 | AG30: 0 | AH30: 0 | AJ30: {=$A$4:$A$23} -> WW | AK30: 0 | AL30: 0 | AM30: 0 | AN30: 0 | AO30: 0
J31: 27 | K31: M1 | L31: K | M31: GJ | N31: M1 | O31: M3 | Q31: 2 | R31: 8 | S31: 19 | T31: 2 | U31: 4 | W31: 1 | X31: 1 | Y31: 1 | Z31: 1 | AA31: 1 | AC31: C1 | AD31: 0 | AE31: 6 | AF31: 0 | AG31: 9 | AH31: 0 | AJ31: C1 | AK31: 0 | AL31: 6 | AM31: 0 | AN31: 9 | AO31: 0
J32: 28 | K32: M5 | L32: J | M32: GA | N32: C1 | O32: M1 | Q32: 6 | R32: 10 | S32: 16 | T32: 1 | U32: 2 | W32: 1 | X32: 1 | Y32: 1 | Z32: 1 | AA32: 1 | AC32: M1 | AD32: 4 | AE32: 11 | AF32: 0 | AG32: 22 | AH32: 28 | AJ32: M1 | AK32: 4 | AL32: 11 | AM32: 0 | AN32: 22 | AO32: 28
J33: 29 | K33: M5 | L33: J | M33: G4 | N33: M3 | O33: M2 | Q33: 6 | R33: 10 | S33: 14 | T33: 4 | U33: 3 | W33: 1 | X33: 1 | Y33: 1 | Z33: 1 | AA33: 1 | AC33: M2 | AD33: 4 | AE33: 11 | AF33: 0 | AG33: 22 | AH33: 27 | AJ33: M2 | AK33: 4 | AL33: 11 | AM33: 0 | AN33: 22 | AO33: 27
J34: 30 | K34: M5 | L34: M2 | M34: G3 | N34: G1 | O34: M1 | Q34: 6 | R34: 3 | S34: 13 | T34: 11 | U34: 2 | W34: 1 | X34: 1 | Y34: 1 | Z34: 1 | AA34: 1 | AC34: M3 | AD34: 4 | AE34: 11 | AF34: 0 | AG34: 22 | AH34: 27 | AJ34: M3 | AK34: 4 | AL34: 11 | AM34: 0 | AN34: 22 | AO34: 27
J35: 31 | K35: K | L35: K | M35: G4 | N35: A | O35: M1 | Q35: 8 | R35: 8 | S35: 14 | T35: 7 | U35: 2 | W35: 1 | X35: 1 | Y35: 1 | Z35: 1 | AA35: 1 | AC35: M4 | AD35: 43 | AE35: 19 | AF35: 0 | AG35: 12 | AH35: 16 | AJ35: M4 | AK35: 43 | AL35: 19 | AM35: 0 | AN35: 12 | AO35: 16
J36: 32 | K36: A | L36: GJ | M36: G5 | N36: M3 | O36: Q | Q36: 7 | R36: 19 | S36: 15 | T36: 4 | U36: 9 | W36: 1 | X36: 1 | Y36: 1 | Z36: 1 | AA36: 1 | AC36: M5 | AD36: 43 | AE36: 20 | AF36: 0 | AG36: 12 | AH36: 16 | AJ36: M5 | AK36: 43 | AL36: 20 | AM36: 0 | AN36: 12 | AO36: 16
J37: 33 | K37: M5 | L37: K | M37: GK | N37: GK | O37: J | Q37: 6 | R37: 8 | S37: 17 | T37: 17 | U37: 10 | W37: 1 | X37: 1 | Y37: 1 | Z37: 1 | AA37: 1 | AC37: A | AD37: 47 | AE37: 20 | AF37: 0 | AG37: 12 | AH37: 16 | AJ37: A | AK37: 47 | AL37: 20 | AM37: 0 | AN37: 12 | AO37: 16
J38: 34 | K38: M4 | L38: M4 | M38: GA | N38: M1 | O38: K | Q38: 5 | R38: 5 | S38: 16 | T38: 2 | U38: 8 | W38: 1 | X38: 1 | Y38: 1 | Z38: 1 | AA38: 1 | AC38: K | AD38: 47 | AE38: 20 | AF38: 0 | AG38: 12 | AH38: 16 | AJ38: K | AK38: 47 | AL38: 20 | AM38: 0 | AN38: 12 | AO38: 16
J39: 35 | K39: K | L39: M3 | M39: G5 | N39: M4 | O39: M4 | Q39: 8 | R39: 4 | S39: 15 | T39: 5 | U39: 5 | W39: 1 | X39: 1 | Y39: 1 | Z39: 1 | AA39: 1 | AC39: Q | AD39: 4 | AE39: 11 | AF39: 0 | AG39: 21 | AH39: 27 | AJ39: Q | AK39: 4 | AL39: 11 | AM39: 0 | AN39: 21 | AO39: 27
J40: 36 | K40: M4 | L40: M3 | M40: G4 | N40: M4 | O40: M3 | Q40: 5 | R40: 4 | S40: 14 | T40: 5 | U40: 4 | W40: 1 | X40: 1 | Y40: 1 | Z40: 1 | AA40: 1 | AC40: J | AD40: 4 | AE40: 11 | AF40: 0 | AG40: 21 | AH40: 27 | AJ40: J | AK40: 4 | AL40: 11 | AM40: 0 | AN40: 21 | AO40: 27
J41: 37 | K41: M5 | L41: G5 | M41: GK | N41: G1 | O41: M4 | Q41: 6 | R41: 15 | S41: 17 | T41: 11 | U41: 5 | W41: 1 | X41: 1 | Y41: 1 | Z41: 1 | AA41: 1 | AC41: G1 | AD41: 0 | AE41: 4 | AF41: 5 | AG41: 5 | AH41: 0 | AJ41: G1 | AK41: 0 | AL41: 4 | AM41: 5 | AN41: 5 | AO41: 0
J42: 38 | K42: M4 | L42: G3 | M42: GA | N42: Q | O42: M2 | Q42: 5 | R42: 13 | S42: 16 | T42: 9 | U42: 3 | W42: 1 | X42: 1 | Y42: 1 | Z42: 1 | AA42: 1 | AC42: G2 | AD42: 0 | AE42: 5 | AF42: 5 | AG42: 5 | AH42: 0 | AJ42: G2 | AK42: 0 | AL42: 5 | AM42: 5 | AN42: 5 | AO42: 0
... J49: 45 | K49: M4 | L49: G5 | M49: GK | N49: M5 | O49: M2 | Q49: 5 | R49: 15 | S49: 17 | T49: 6 | U49: 3 | W49: 1 | X49: 1 | Y49: 1 | Z49: 1 | AA49: 1 | AC49: GJ | AD49: 0 | AE49: 5 | AF49: 4 | AG49: 4 | AH49: 0 | AJ49: GJ | AK49: 0 | AL49: 5 | AM49: 4 | AN49: 4 | AO49: 0
J50: 46 | K50: M3 | L50: M5 | M50: G4 | N50: M2 | O50: A | Q50: 4 | R50: 6 | S50: 14 | T50: 3 | U50: 7 | W50: 1 | X50: 1 | Y50: 1 | Z50: 1 | AA50: 1 | AD50: =SUM(AD30:AD49) -> 200 | AE50: =SUM(AE30:AE49) -> 200 | AF50: =SUM(AF30:AF49) -> 200 | AG50: =SUM(AG30:AG49) -> 200 | AH50: =SUM(AH30:AH49) -> 200 | AK50: =SUM(AK30:AK49) -> 200 | AL50: =SUM(AL30:AL49) -> 200 | AM50: =SUM(AM30:AM49) -> 200 | AN50: =SUM(AN30:AN49) -> 200 | AO50: =SUM(AO30:AO49) -> 200
J51: 47 | K51: M4 | L51: G4 | M51: GK | N51: Q | O51: A | Q51: 5 | R51: 14 | S51: 17 | T51: 9 | U51: 7 | W51: 1 | X51: 1 | Y51: 1 | Z51: 1 | AA51: 1
...

Sheet BG_Symbol (3)
J2: Symbol | Q2: Symbol ID | W2: Symbol Weight | AC2: Eliminate Wheel Weight A | AJ2: Eliminate Wheel Weight B
A3: Symbol | B3: Description | C3: R1 | D3: R2 | E3: R3 | F3: R4 | G3: R5 | H3: ID | K3: R1 | L3: R2 | M3: R3 | N3: R4 | O3: R5 | Q3: R1 | R3: R2 | S3: R3 | T3: R4 | U3: R5 | W3: R1 | X3: R2 | Y3: R3 | Z3: R4 | AA3: R5
A4: {=Overview!A38:B57} -> WW | B4: Wild | C4: =COUNTIF(K:K, $A4) -> 0 | D4: =COUNTIF(L:L, $A4) -> 0 | E4: =COUNTIF(M:M, $A4) -> 0 | F4: =COUNTIF(N:N, $A4) -> 0 | G4: =COUNTIF(O:O, $A4) -> 0 | H4: {=Overview!F38:F57} -> 0 | J4: {=_xlfn.SEQUENCE(MAX(COUNTA(K:K), COUNTA(L:L), COUNTA(M:M), COUNTA(N:N), COUNTA(O:O))-1,,0)} -> 0 | K4: M2 | L4: M3 | M4: M3 | N4: M5 | O4: K | Q4: {=_xlfn.LET(_xlpm.x, K4:O304, IF(_xlpm.x="", "", _xlfn.XLOOKUP(_xlpm.x, $A$4:$A$23,_xlfn.ANCHORARRAY( H4))))} -> 3 | R4: 4 | S4: 4 | T4: 6 | U4: 8 | W4: 1 | X4: 1 | Y4: 1 | Z4: 1 | AA4: 1 | AC4: 1 Combo | AJ4: 1 Combo
A5: C1 | B5: Scatter | C5: =COUNTIF(K:K, $A5) -> 6 | D5: =COUNTIF(L:L, $A5) -> 6 | E5: =COUNTIF(M:M, $A5) -> 6 | F5: =COUNTIF(N:N, $A5) -> 9 | G5: =COUNTIF(O:O, $A5) -> 9 | H5: 1 | J5: 1 | K5: K | L5: GJ | M5: M2 | N5: A | O5: J | Q5: 8 | R5: 19 | S5: 3 | T5: 7 | U5: 10 | W5: 1 | X5: 1 | Y5: 1 | Z5: 1 | AA5: 1 | AC5: Symbol | AD5: R1 | AE5: R2 | AF5: R3 | AG5: R4 | AH5: R5 | AJ5: Symbol | AK5: R1 | AL5: R2 | AM5: R3 | AN5: R4 | AO5: R5
A6: M1 | B6: M1 | C6: =COUNTIF(K:K, $A6) -> 4 | D6: =COUNTIF(L:L, $A6) -> 17 | E6: =COUNTIF(M:M, $A6) -> 4 | F6: =COUNTIF(N:N, $A6) -> 21 | G6: =COUNTIF(O:O, $A6) -> 22 | H6: 2 | J6: 2 | K6: K | L6: G2 | M6: C1 | N6: J | O6: C1 | Q6: 8 | R6: 12 | S6: 1 | T6: 10 | U6: 1 | W6: 1 | X6: 1 | Y6: 1 | Z6: 1 | AA6: 1 | AC6: {=$A$4:$A$23} -> WW | AD6: 0 | AE6: 0 | AF6: 0 | AG6: 0 | AH6: 0 | AJ6: {=$A$4:$A$23} -> WW | AK6: 0 | AL6: 0 | AM6: 0 | AN6: 0 | AO6: 0
A7: M2 | B7: M2 | C7: =COUNTIF(K:K, $A7) -> 4 | D7: =COUNTIF(L:L, $A7) -> 18 | E7: =COUNTIF(M:M, $A7) -> 4 | F7: =COUNTIF(N:N, $A7) -> 20 | G7: =COUNTIF(O:O, $A7) -> 22 | H7: 3 | J7: 3 | K7: M5 | L7: G5 | M7: K | N7: M2 | O7: M2 | Q7: 6 | R7: 15 | S7: 8 | T7: 3 | U7: 3 | W7: 1 | X7: 1 | Y7: 1 | Z7: 1 | AA7: 1 | AC7: C1 | AD7: 6 | AE7: 6 | AF7: 6 | AG7: 9 | AH7: 9 | AJ7: C1 | AK7: 6 | AL7: 6 | AM7: 6 | AN7: 9 | AO7: 9
A8: M3 | B8: M3 | C8: =COUNTIF(K:K, $A8) -> 4 | D8: =COUNTIF(L:L, $A8) -> 18 | E8: =COUNTIF(M:M, $A8) -> 4 | F8: =COUNTIF(N:N, $A8) -> 20 | G8: =COUNTIF(O:O, $A8) -> 21 | H8: 4 | J8: 4 | K8: K | L8: G5 | M8: M4 | N8: G3 | O8: M2 | Q8: 8 | R8: 15 | S8: 5 | T8: 13 | U8: 3 | W8: 1 | X8: 1 | Y8: 1 | Z8: 1 | AA8: 1 | AC8: M1 | AD8: 4 | AE8: 17 | AF8: 4 | AG8: 21 | AH8: 22 | AJ8: M1 | AK8: 4 | AL8: 17 | AM8: 4 | AN8: 21 | AO8: 22
A9: M4 | B9: M4 | C9: =COUNTIF(K:K, $A9) -> 40 | D9: =COUNTIF(L:L, $A9) -> 14 | E9: =COUNTIF(M:M, $A9) -> 41 | F9: =COUNTIF(N:N, $A9) -> 14 | G9: =COUNTIF(O:O, $A9) -> 21 | H9: 5 | J9: 5 | K9: A | L9: GK | M9: A | N9: J | O9: J | Q9: 7 | R9: 17 | S9: 7 | T9: 10 | U9: 10 | W9: 1 | X9: 1 | Y9: 1 | Z9: 1 | AA9: 1 | AC9: M2 | AD9: 4 | AE9: 18 | AF9: 4 | AG9: 20 | AH9: 22 | AJ9: M2 | AK9: 4 | AL9: 18 | AM9: 4 | AN9: 20 | AO9: 22
A10: M5 | B10: M5 | C10: =COUNTIF(K:K, $A10) -> 40 | D10: =COUNTIF(L:L, $A10) -> 14 | E10: =COUNTIF(M:M, $A10) -> 41 | F10: =COUNTIF(N:N, $A10) -> 14 | G10: =COUNTIF(O:O, $A10) -> 21 | H10: 6 | J10: 6 | K10: M5 | L10: M5 | M10: M4 | N10: J | O10: M4 | Q10: 6 | R10: 6 | S10: 5 | T10: 10 | U10: 5 | W10: 1 | X10: 1 | Y10: 1 | Z10: 1 | AA10: 1 | AC10: M3 | AD10: 4 | AE10: 18 | AF10: 4 | AG10: 20 | AH10: 21 | AJ10: M3 | AK10: 4 | AL10: 18 | AM10: 4 | AN10: 20 | AO10: 21
A11: A | B11: A | C11: =COUNTIF(K:K, $A11) -> 47 | D11: =COUNTIF(L:L, $A11) -> 13 | E11: =COUNTIF(M:M, $A11) -> 41 | F11: =COUNTIF(N:N, $A11) -> 14 | G11: =COUNTIF(O:O, $A11) -> 21 | H11: 7 | J11: 7 | K11: M5 | L11: M5 | M11: A | N11: A | O11: M5 | Q11: 6 | R11: 6 | S11: 7 | T11: 7 | U11: 6 | W11: 1 | X11: 1 | Y11: 1 | Z11: 1 | AA11: 1 | AC11: M4 | AD11: 40 | AE11: 14 | AF11: 41 | AG11: 14 | AH11: 21 | AJ11: M4 | AK11: 40 | AL11: 14 | AM11: 41 | AN11: 14 | AO11: 21
A12: K | B12: K | C12: =COUNTIF(K:K, $A12) -> 47 | D12: =COUNTIF(L:L, $A12) -> 13 | E12: =COUNTIF(M:M, $A12) -> 41 | F12: =COUNTIF(N:N, $A12) -> 14 | G12: =COUNTIF(O:O, $A12) -> 21 | H12: 8 | J12: 8 | K12: A | L12: G2 | M12: G5 | N12: M3 | O12: Q | Q12: 7 | R12: 12 | S12: 15 | T12: 4 | U12: 9 | W12: 1 | X12: 1 | Y12: 1 | Z12: 1 | AA12: 1 | AC12: M5 | AD12: 40 | AE12: 14 | AF12: 41 | AG12: 14 | AH12: 21 | AJ12: M5 | AK12: 40 | AL12: 14 | AM12: 41 | AN12: 14 | AO12: 21
A13: Q | B13: Q | C13: =COUNTIF(K:K, $A13) -> 4 | D13: =COUNTIF(L:L, $A13) -> 17 | E13: =COUNTIF(M:M, $A13) -> 3 | F13: =COUNTIF(N:N, $A13) -> 21 | G13: =COUNTIF(O:O, $A13) -> 21 | H13: 9 | J13: 9 | K13: M5 | L13: C1 | M13: A | N13: M5 | O13: Q | Q13: 6 | R13: 1 | S13: 7 | T13: 6 | U13: 9 | W13: 1 | X13: 1 | Y13: 1 | Z13: 1 | AA13: 1 | AC13: A | AD13: 47 | AE13: 13 | AF13: 41 | AG13: 14 | AH13: 21 | AJ13: A | AK13: 47 | AL13: 13 | AM13: 41 | AN13: 14 | AO13: 21
A14: J | B14: J | C14: =COUNTIF(K:K, $A14) -> 4 | D14: =COUNTIF(L:L, $A14) -> 17 | E14: =COUNTIF(M:M, $A14) -> 3 | F14: =COUNTIF(N:N, $A14) -> 21 | G14: =COUNTIF(O:O, $A14) -> 21 | H14: 10 | J14: 10 | K14: K | L14: A | M14: K | N14: M2 | O14: M1 | Q14: 8 | R14: 7 | S14: 8 | T14: 3 | U14: 2 | W14: 1 | X14: 1 | Y14: 1 | Z14: 1 | AA14: 1 | AC14: K | AD14: 47 | AE14: 13 | AF14: 41 | AG14: 14 | AH14: 21 | AJ14: K | AK14: 47 | AL14: 13 | AM14: 41 | AN14: 14 | AO14: 21
A15: G1 | B15: Gold M1 | C15: =COUNTIF(K:K, $A15) -> 0 | D15: =COUNTIF(L:L, $A15) -> 7 | E15: =COUNTIF(M:M, $A15) -> 0 | F15: =COUNTIF(N:N, $A15) -> 4 | G15: =COUNTIF(O:O, $A15) -> 0 | H15: 11 | J15: 11 | K15: M5 | L15: GJ | M15: M5 | N15: M3 | O15: M3 | Q15: 6 | R15: 19 | S15: 6 | T15: 4 | U15: 4 | W15: 1 | X15: 1 | Y15: 1 | Z15: 1 | AA15: 1 | AC15: Q | AD15: 4 | AE15: 17 | AF15: 3 | AG15: 21 | AH15: 21 | AJ15: Q | AK15: 4 | AL15: 17 | AM15: 3 | AN15: 21 | AO15: 21
A16: G2 | B16: Gold M2 | C16: =COUNTIF(K:K, $A16) -> 0 | D16: =COUNTIF(L:L, $A16) -> 7 | E16: =COUNTIF(M:M, $A16) -> 0 | F16: =COUNTIF(N:N, $A16) -> 4 | G16: =COUNTIF(O:O, $A16) -> 0 | H16: 12 | J16: 12 | K16: M4 | L16: GQ | M16: M5 | N16: J | O16: M3 | Q16: 5 | R16: 18 | S16: 6 | T16: 10 | U16: 4 | W16: 1 | X16: 1 | Y16: 1 | Z16: 1 | AA16: 1 | AC16: J | AD16: 4 | AE16: 17 | AF16: 3 | AG16: 21 | AH16: 21 | AJ16: J | AK16: 4 | AL16: 17 | AM16: 3 | AN16: 21 | AO16: 21
A17: G3 | B17: Gold M3 | C17: =COUNTIF(K:K, $A17) -> 0 | D17: =COUNTIF(L:L, $A17) -> 7 | E17: =COUNTIF(M:M, $A17) -> 0 | F17: =COUNTIF(N:N, $A17) -> 4 | G17: =COUNTIF(O:O, $A17) -> 0 | H17: 13 | J17: 13 | K17: M4 | L17: M5 | M17: M1 | N17: J | O17: M2 | Q17: 5 | R17: 6 | S17: 2 | T17: 10 | U17: 3 | W17: 1 | X17: 1 | Y17: 1 | Z17: 1 | AA17: 1 | AC17: G1 | AD17: 0 | AE17: 7 | AF17: 0 | AG17: 4 | AH17: 0 | AJ17: G1 | AK17: 0 | AL17: 7 | AM17: 0 | AN17: 4 | AO17: 0
A18: G4 | B18: Gold M4 | C18: =COUNTIF(K:K, $A18) -> 0 | D18: =COUNTIF(L:L, $A18) -> 4 | E18: =COUNTIF(M:M, $A18) -> 3 | F18: =COUNTIF(N:N, $A18) -> 3 | G18: =COUNTIF(O:O, $A18) -> 0 | H18: 14 | J18: 14 | K18: M5 | L18: G1 | M18: K | N18: K | O18: M2 | Q18: 6 | R18: 11 | S18: 8 | T18: 8 | U18: 3 | W18: 1 | X18: 1 | Y18: 1 | Z18: 1 | AA18: 1 | AC18: G2 | AD18: 0 | AE18: 7 | AF18: 0 | AG18: 4 | AH18: 0 | AJ18: G2 | AK18: 0 | AL18: 7 | AM18: 0 | AN18: 4 | AO18: 0
... A23: GJ | B23: Gold J | C23: =COUNTIF(K:K, $A23) -> 0 | D23: =COUNTIF(L:L, $A23) -> 8 | E23: =COUNTIF(M:M, $A23) -> 0 | F23: =COUNTIF(N:N, $A23) -> 4 | G23: =COUNTIF(O:O, $A23) -> 0 | H23: 19 | J23: 19 | K23: M5 | L23: M4 | M23: M5 | N23: GA | O23: M1 | Q23: 6 | R23: 5 | S23: 6 | T23: 16 | U23: 2 | W23: 1 | X23: 1 | Y23: 1 | Z23: 1 | AA23: 1 | AC23: GK | AD23: 0 | AE23: 4 | AF23: 3 | AG23: 3 | AH23: 0 | AJ23: GK | AK23: 0 | AL23: 4 | AM23: 3 | AN23: 3 | AO23: 0
C24: =SUM(C4:C23) -> 200 | D24: =SUM(D4:D23) -> 200 | E24: =SUM(E4:E23) -> 200 | F24: =SUM(F4:F23) -> 200 | G24: =SUM(G4:G23) -> 200 | J24: 20 | K24: A | L24: GK | M24: A | N24: Q | O24: M4 | Q24: 7 | R24: 17 | S24: 7 | T24: 9 | U24: 5 | W24: 1 | X24: 1 | Y24: 1 | Z24: 1 | AA24: 1 | AC24: GQ | AD24: 0 | AE24: 8 | AF24: 0 | AG24: 4 | AH24: 0 | AJ24: GQ | AK24: 0 | AL24: 8 | AM24: 0 | AN24: 4 | AO24: 0
J25: 21 | K25: K | L25: GK | M25: M3 | N25: M1 | O25: M1 | Q25: 8 | R25: 17 | S25: 4 | T25: 2 | U25: 2 | W25: 1 | X25: 1 | Y25: 1 | Z25: 1 | AA25: 1 | AC25: GJ | AD25: 0 | AE25: 8 | AF25: 0 | AG25: 4 | AH25: 0 | AJ25: GJ | AK25: 0 | AL25: 8 | AM25: 0 | AN25: 4 | AO25: 0
B26: Normal Symbol | C26: =SUM(C4:C14)/C24 -> 1 | D26: =SUM(D4:D14)/D24 -> 0.735 | E26: =SUM(E4:E14)/E24 -> 0.94 | F26: =SUM(F4:F14)/F24 -> 0.84 | G26: =SUM(G4:G14)/G24 -> 1 | J26: 22 | K26: K | L26: M2 | M26: K | N26: A | O26: M4 | Q26: 8 | R26: 3 | S26: 8 | T26: 7 | U26: 5 | W26: 1 | X26: 1 | Y26: 1 | Z26: 1 | AA26: 1 | AD26: =SUM(AD6:AD25) -> 200 | AE26: =SUM(AE6:AE25) -> 200 | AF26: =SUM(AF6:AF25) -> 200 | AG26: =SUM(AG6:AG25) -> 200 | AH26: =SUM(AH6:AH25) -> 200 | AK26: =SUM(AK6:AK25) -> 200 | AL26: =SUM(AL6:AL25) -> 200 | AM26: =SUM(AM6:AM25) -> 200 | AN26: =SUM(AN6:AN25) -> 200 | AO26: =SUM(AO6:AO25) -> 200
B27: Golden Symbol | C27: =SUM(C15:C23)/C24 -> 0 | D27: =SUM(D15:D23)/D24 -> 0.265 | E27: =SUM(E15:E23)/E24 -> 0.06 | F27: =SUM(F15:F23)/F24 -> 0.16 | G27: =SUM(G15:G23)/G24 -> 0 | J27: 23 | K27: K | L27: M3 | M27: M5 | N27: C1 | O27: M5 | Q27: 8 | R27: 4 | S27: 6 | T27: 1 | U27: 6 | W27: 1 | X27: 1 | Y27: 1 | Z27: 1 | AA27: 1
J28: 24 | K28: M4 | L28: M3 | M28: Q | N28: GJ | O28: K | Q28: 5 | R28: 4 | S28: 9 | T28: 19 | U28: 8 | W28: 1 | X28: 1 | Y28: 1 | Z28: 1 | AA28: 1 | AC28: 2 Combo | AJ28: 2 Combo
J29: 25 | K29: K | L29: K | M29: K | N29: M3 | O29: M3 | Q29: 8 | R29: 8 | S29: 8 | T29: 4 | U29: 4 | W29: 1 | X29: 1 | Y29: 1 | Z29: 1 | AA29: 1 | AC29: Symbol | AD29: R1 | AE29: R2 | AF29: R3 | AG29: R4 | AH29: R5 | AJ29: Symbol | AK29: R1 | AL29: R2 | AM29: R3 | AN29: R4 | AO29: R5
J30: 26 | K30: A | L30: K | M30: M5 | N30: J | O30: M5 | Q30: 7 | R30: 8 | S30: 6 | T30: 10 | U30: 6 | W30: 1 | X30: 1 | Y30: 1 | Z30: 1 | AA30: 1 | AC30: {=$A$4:$A$23} -> WW | AD30: 0 | AE30: 0 | AF30: 0 | AG30: 0 | AH30: 0 | AJ30: {=$A$4:$A$23} -> WW | AK30: 0 | AL30: 0 | AM30: 0 | AN30: 0 | AO30: 0
J31: 27 | K31: M4 | L31: GQ | M31: A | N31: GJ | O31: Q | Q31: 5 | R31: 18 | S31: 7 | T31: 19 | U31: 9 | W31: 1 | X31: 1 | Y31: 1 | Z31: 1 | AA31: 1 | AC31: C1 | AD31: 3 | AE31: 3 | AF31: 3 | AG31: 6 | AH31: 6 | AJ31: C1 | AK31: 3 | AL31: 3 | AM31: 3 | AN31: 6 | AO31: 6
J32: 28 | K32: K | L32: G4 | M32: M5 | N32: G1 | O32: Q | Q32: 8 | R32: 14 | S32: 6 | T32: 11 | U32: 9 | W32: 1 | X32: 1 | Y32: 1 | Z32: 1 | AA32: 1 | AC32: M1 | AD32: 4 | AE32: 17 | AF32: 4 | AG32: 21 | AH32: 22 | AJ32: M1 | AK32: 4 | AL32: 17 | AM32: 4 | AN32: 21 | AO32: 22
J33: 29 | K33: M1 | L33: G3 | M33: M4 | N33: M2 | O33: M1 | Q33: 2 | R33: 13 | S33: 5 | T33: 3 | U33: 2 | W33: 1 | X33: 1 | Y33: 1 | Z33: 1 | AA33: 1 | AC33: M2 | AD33: 4 | AE33: 18 | AF33: 4 | AG33: 20 | AH33: 22 | AJ33: M2 | AK33: 4 | AL33: 18 | AM33: 4 | AN33: 20 | AO33: 22
J34: 30 | K34: K | L34: J | M34: K | N34: M1 | O34: M1 | Q34: 8 | R34: 10 | S34: 8 | T34: 2 | U34: 2 | W34: 1 | X34: 1 | Y34: 1 | Z34: 1 | AA34: 1 | AC34: M3 | AD34: 4 | AE34: 18 | AF34: 4 | AG34: 20 | AH34: 21 | AJ34: M3 | AK34: 4 | AL34: 18 | AM34: 4 | AN34: 20 | AO34: 21
J35: 31 | K35: M4 | L35: J | M35: A | N35: M5 | O35: C1 | Q35: 5 | R35: 10 | S35: 7 | T35: 6 | U35: 1 | W35: 1 | X35: 1 | Y35: 1 | Z35: 1 | AA35: 1 | AC35: M4 | AD35: 40 | AE35: 14 | AF35: 41 | AG35: 14 | AH35: 21 | AJ35: M4 | AK35: 40 | AL35: 14 | AM35: 41 | AN35: 14 | AO35: 21
J36: 32 | K36: A | L36: M4 | M36: M3 | N36: M5 | O36: Q | Q36: 7 | R36: 5 | S36: 4 | T36: 6 | U36: 9 | W36: 1 | X36: 1 | Y36: 1 | Z36: 1 | AA36: 1 | AC36: M5 | AD36: 40 | AE36: 14 | AF36: 41 | AG36: 14 | AH36: 21 | AJ36: M5 | AK36: 40 | AL36: 14 | AM36: 41 | AN36: 14 | AO36: 21
J37: 33 | K37: M4 | L37: K | M37: K | N37: GA | O37: K | Q37: 5 | R37: 8 | S37: 8 | T37: 16 | U37: 8 | W37: 1 | X37: 1 | Y37: 1 | Z37: 1 | AA37: 1 | AC37: A | AD37: 47 | AE37: 13 | AF37: 41 | AG37: 14 | AH37: 21 | AJ37: A | AK37: 47 | AL37: 13 | AM37: 41 | AN37: 14 | AO37: 21
J38: 34 | K38: M5 | L38: G2 | M38: M4 | N38: K | O38: M2 | Q38: 6 | R38: 12 | S38: 5 | T38: 8 | U38: 3 | W38: 1 | X38: 1 | Y38: 1 | Z38: 1 | AA38: 1 | AC38: K | AD38: 47 | AE38: 13 | AF38: 41 | AG38: 14 | AH38: 21 | AJ38: K | AK38: 47 | AL38: 13 | AM38: 41 | AN38: 14 | AO38: 21
J39: 35 | K39: M5 | L39: A | M39: M5 | N39: M1 | O39: J | Q39: 6 | R39: 7 | S39: 6 | T39: 2 | U39: 10 | W39: 1 | X39: 1 | Y39: 1 | Z39: 1 | AA39: 1 | AC39: Q | AD39: 4 | AE39: 17 | AF39: 3 | AG39: 21 | AH39: 21 | AJ39: Q | AK39: 4 | AL39: 17 | AM39: 3 | AN39: 21 | AO39: 21
J40: 36 | K40: A | L40: GA | M40: K | N40: G4 | O40: M1 | Q40: 7 | R40: 16 | S40: 8 | T40: 14 | U40: 2 | W40: 1 | X40: 1 | Y40: 1 | Z40: 1 | AA40: 1 | AC40: J | AD40: 4 | AE40: 17 | AF40: 3 | AG40: 21 | AH40: 21 | AJ40: J | AK40: 4 | AL40: 17 | AM40: 3 | AN40: 21 | AO40: 21
J41: 37 | K41: M4 | L41: GA | M41: A | N41: C1 | O41: Q | Q41: 5 | R41: 16 | S41: 7 | T41: 1 | U41: 9 | W41: 1 | X41: 1 | Y41: 1 | Z41: 1 | AA41: 1 | AC41: G1 | AD41: 0 | AE41: 7 | AF41: 0 | AG41: 4 | AH41: 0 | AJ41: G1 | AK41: 0 | AL41: 7 | AM41: 0 | AN41: 4 | AO41: 0
J42: 38 | K42: M4 | L42: J | M42: J | N42: M5 | O42: M4 | Q42: 5 | R42: 10 | S42: 10 | T42: 6 | U42: 5 | W42: 1 | X42: 1 | Y42: 1 | Z42: 1 | AA42: 1 | AC42: G2 | AD42: 0 | AE42: 7 | AF42: 0 | AG42: 4 | AH42: 0 | AJ42: G2 | AK42: 0 | AL42: 7 | AM42: 0 | AN42: 4 | AO42: 0
... J49: 45 | K49: K | L49: M3 | M49: M5 | N49: J | O49: M3 | Q49: 8 | R49: 4 | S49: 6 | T49: 10 | U49: 4 | W49: 1 | X49: 1 | Y49: 1 | Z49: 1 | AA49: 1 | AC49: GJ | AD49: 0 | AE49: 8 | AF49: 0 | AG49: 4 | AH49: 0 | AJ49: GJ | AK49: 0 | AL49: 8 | AM49: 0 | AN49: 4 | AO49: 0
J50: 46 | K50: A | L50: M1 | M50: A | N50: M2 | O50: J | Q50: 7 | R50: 2 | S50: 7 | T50: 3 | U50: 10 | W50: 1 | X50: 1 | Y50: 1 | Z50: 1 | AA50: 1 | AD50: =SUM(AD30:AD49) -> 197 | AE50: =SUM(AE30:AE49) -> 197 | AF50: =SUM(AF30:AF49) -> 197 | AG50: =SUM(AG30:AG49) -> 197 | AH50: =SUM(AH30:AH49) -> 197 | AK50: =SUM(AK30:AK49) -> 197 | AL50: =SUM(AL30:AL49) -> 197 | AM50: =SUM(AM30:AM49) -> 197 | AN50: =SUM(AN30:AN49) -> 197 | AO50: =SUM(AO30:AO49) -> 197
J51: 47 | K51: C1 | L51: M1 | M51: M2 | N51: M1 | O51: Q | Q51: 1 | R51: 2 | S51: 3 | T51: 2 | U51: 9 | W51: 1 | X51: 1 | Y51: 1 | Z51: 1 | AA51: 1
...

Sheet FG_Symbol
J2: Symbol | Q2: Symbol ID | W2: Symbol Weight | AC2: Eliminate Wheel Weight A | AJ2: Eliminate Wheel Weight B
A3: Symbol | B3: Description | C3: R1 | D3: R2 | E3: R3 | F3: R4 | G3: R5 | H3: ID | K3: R1 | L3: R2 | M3: R3 | N3: R4 | O3: R5 | Q3: R1 | R3: R2 | S3: R3 | T3: R4 | U3: R5 | W3: R1 | X3: R2 | Y3: R3 | Z3: R4 | AA3: R5
A4: {=Overview!A38:B57} -> WW | B4: Wild | C4: =COUNTIF(K:K, $A4) -> 0 | D4: =COUNTIF(L:L, $A4) -> 0 | E4: =COUNTIF(M:M, $A4) -> 0 | F4: =COUNTIF(N:N, $A4) -> 0 | G4: =COUNTIF(O:O, $A4) -> 0 | H4: {=Overview!F38:F57} -> 0 | J4: {=_xlfn.SEQUENCE(MAX(COUNTA(K:K), COUNTA(L:L), COUNTA(M:M), COUNTA(N:N), COUNTA(O:O))-1,,0)} -> 0 | K4: A | L4: M5 | M4: G4 | N4: GK | O4: K | Q4: {=_xlfn.LET(_xlpm.x, K4:O304, IF(_xlpm.x="", "", _xlfn.XLOOKUP(_xlpm.x, $A$4:$A$23,_xlfn.ANCHORARRAY( H4))))} -> 7 | R4: 6 | S4: 14 | T4: 17 | U4: 8 | W4: 1 | X4: 1 | Y4: 1 | Z4: 1 | AA4: 1 | AC4: 1 Combo | AJ4: 1 Combo
A5: C1 | B5: Scatter | C5: =COUNTIF(K:K, $A5) -> 2 | D5: =COUNTIF(L:L, $A5) -> 2 | E5: =COUNTIF(M:M, $A5) -> 0 | F5: =COUNTIF(N:N, $A5) -> 3 | G5: =COUNTIF(O:O, $A5) -> 3 | H5: 1 | J5: 1 | K5: M3 | L5: G5 | M5: G5 | N5: K | O5: A | Q5: 4 | R5: 15 | S5: 15 | T5: 8 | U5: 7 | W5: 1 | X5: 1 | Y5: 1 | Z5: 1 | AA5: 1 | AC5: Symbol | AD5: R1 | AE5: R2 | AF5: R3 | AG5: R4 | AH5: R5 | AJ5: Symbol | AK5: R1 | AL5: R2 | AM5: R3 | AN5: R4 | AO5: R5
A6: M1 | B6: M1 | C6: =COUNTIF(K:K, $A6) -> 3 | D6: =COUNTIF(L:L, $A6) -> 10 | E6: =COUNTIF(M:M, $A6) -> 0 | F6: =COUNTIF(N:N, $A6) -> 3 | G6: =COUNTIF(O:O, $A6) -> 9 | H6: 2 | J6: 2 | K6: M5 | L6: M4 | M6: GK | N6: J | O6: K | Q6: 6 | R6: 5 | S6: 17 | T6: 10 | U6: 8 | W6: 1 | X6: 1 | Y6: 1 | Z6: 1 | AA6: 1 | AC6: {=$A$4:$A$23} -> WW | AD6: 0 | AE6: 0 | AF6: 0 | AG6: 0 | AH6: 0 | AJ6: {=$A$4:$A$23} -> WW | AK6: 0 | AL6: 0 | AM6: 0 | AN6: 0 | AO6: 0
A7: M2 | B7: M2 | C7: =COUNTIF(K:K, $A7) -> 3 | D7: =COUNTIF(L:L, $A7) -> 12 | E7: =COUNTIF(M:M, $A7) -> 0 | F7: =COUNTIF(N:N, $A7) -> 3 | G7: =COUNTIF(O:O, $A7) -> 8 | H7: 3 | J7: 3 | K7: A | L7: A | M7: G4 | N7: M4 | O7: M5 | Q7: 7 | R7: 7 | S7: 14 | T7: 5 | U7: 6 | W7: 1 | X7: 1 | Y7: 1 | Z7: 1 | AA7: 1 | AC7: C1 | AD7: 1 | AE7: 1 | AF7: 0 | AG7: 1 | AH7: 1 | AJ7: C1 | AK7: 1 | AL7: 1 | AM7: 0 | AN7: 1 | AO7: 1
A8: M3 | B8: M3 | C8: =COUNTIF(K:K, $A8) -> 7 | D8: =COUNTIF(L:L, $A8) -> 13 | E8: =COUNTIF(M:M, $A8) -> 0 | F8: =COUNTIF(N:N, $A8) -> 7 | G8: =COUNTIF(O:O, $A8) -> 14 | H8: 4 | J8: 4 | K8: Q | L8: M4 | M8: GA | N8: J | O8: M4 | Q8: 9 | R8: 5 | S8: 16 | T8: 10 | U8: 5 | W8: 1 | X8: 1 | Y8: 1 | Z8: 1 | AA8: 1 | AC8: M1 | AD8: 3 | AE8: 10 | AF8: 0 | AG8: 3 | AH8: 9 | AJ8: M1 | AK8: 3 | AL8: 10 | AM8: 0 | AN8: 3 | AO8: 9
A9: M4 | B9: M4 | C9: =COUNTIF(K:K, $A9) -> 43 | D9: =COUNTIF(L:L, $A9) -> 22 | E9: =COUNTIF(M:M, $A9) -> 0 | F9: =COUNTIF(N:N, $A9) -> 31 | G9: =COUNTIF(O:O, $A9) -> 36 | H9: 5 | J9: 5 | K9: K | L9: A | M9: GK | N9: K | O9: M5 | Q9: 8 | R9: 7 | S9: 17 | T9: 8 | U9: 6 | W9: 1 | X9: 1 | Y9: 1 | Z9: 1 | AA9: 1 | AC9: M2 | AD9: 3 | AE9: 12 | AF9: 0 | AG9: 3 | AH9: 8 | AJ9: M2 | AK9: 3 | AL9: 12 | AM9: 0 | AN9: 3 | AO9: 8
A10: M5 | B10: M5 | C10: =COUNTIF(K:K, $A10) -> 42 | D10: =COUNTIF(L:L, $A10) -> 22 | E10: =COUNTIF(M:M, $A10) -> 0 | F10: =COUNTIF(N:N, $A10) -> 27 | G10: =COUNTIF(O:O, $A10) -> 34 | H10: 6 | J10: 6 | K10: M3 | L10: Q | M10: GA | N10: G4 | O10: M4 | Q10: 4 | R10: 9 | S10: 16 | T10: 14 | U10: 5 | W10: 1 | X10: 1 | Y10: 1 | Z10: 1 | AA10: 1 | AC10: M3 | AD10: 7 | AE10: 13 | AF10: 0 | AG10: 7 | AH10: 14 | AJ10: M3 | AK10: 7 | AL10: 13 | AM10: 0 | AN10: 7 | AO10: 14
A11: A | B11: A | C11: =COUNTIF(K:K, $A11) -> 43 | D11: =COUNTIF(L:L, $A11) -> 27 | E11: =COUNTIF(M:M, $A11) -> 0 | F11: =COUNTIF(N:N, $A11) -> 31 | G11: =COUNTIF(O:O, $A11) -> 35 | H11: 7 | J11: 7 | K11: M5 | L11: GQ | M11: GK | N11: GK | O11: M5 | Q11: 6 | R11: 18 | S11: 17 | T11: 17 | U11: 6 | W11: 1 | X11: 1 | Y11: 1 | Z11: 1 | AA11: 1 | AC11: M4 | AD11: 43 | AE11: 22 | AF11: 0 | AG11: 31 | AH11: 36 | AJ11: M4 | AK11: 43 | AL11: 22 | AM11: 0 | AN11: 31 | AO11: 36
A12: K | B12: K | C12: =COUNTIF(K:K, $A12) -> 43 | D12: =COUNTIF(L:L, $A12) -> 24 | E12: =COUNTIF(M:M, $A12) -> 0 | F12: =COUNTIF(N:N, $A12) -> 32 | G12: =COUNTIF(O:O, $A12) -> 34 | H12: 8 | J12: 8 | K12: J | L12: M2 | M12: GA | N12: A | O12: A | Q12: 10 | R12: 3 | S12: 16 | T12: 7 | U12: 7 | W12: 1 | X12: 1 | Y12: 1 | Z12: 1 | AA12: 1 | AC12: M5 | AD12: 42 | AE12: 22 | AF12: 0 | AG12: 27 | AH12: 34 | AJ12: M5 | AK12: 42 | AL12: 22 | AM12: 0 | AN12: 27 | AO12: 34
