Workbook

Sheet Overview
A3: Model: | B3: 5.0.0.0
A5: Reel # | B5: 1 | C5: 2 | D5: 3 | E5: 4
A6: Visible Window Size | B6: 3 | C6: 3 | D6: 3 | E6: 3
A8: OverAll
A9: Coin | B9: Bet | C9: Reels | D9: Line | E9: Pay Back %
A10: 1 | B10: 1 | C10: 4 | D10: 1 | E10: =Card_Bet1!$V$1 -> 0.9199948
A11: 5 | B11: 5 | C11: 4 | D11: 1 | E11: =Card_Bet5!$V$1 -> 0.91999777
A12: 10 | B12: 10 | C12: 4 | D12: 1 | E12: =Card_Bet10!$V$1 -> 0.91999349
A13: 50 | B13: 50 | C13: 4 | D13: 1 | E13: =Card_Bet50!$V$1 -> 0.91998901
A14: 100 | B14: 100 | C14: 4 | D14: 1 | E14: =Card_Bet100!$V$1 -> 0.91999322
A16: Parameter A
A17: Coin | B17: Bet | C17: Reels | D17: Line | E17: Pay Back % | F17: Pay Back %(RD)
A18: 1 | B18: 1 | C18: 4 | D18: 1 | E18: 0.92022917 | F18: 0.920079
A19: 5 | B19: 5 | C19: 4 | D19: 1 | E19: 0.92693396 | F19: 0.92751
A20: 10 | B20: 10 | C20: 4 | D20: 1 | E20: 0.92342863 | F20: 0.92335
A21: 50 | B21: 50 | C21: 4 | D21: 1 | E21: 0.92028178 | F21: 0.920487
A22: 100 | B22: 100 | C22: 4 | D22: 1 | E22: 0.92359546 | F22: 0.924113
A24: Total payback percentage includes the following adjustments:
A25: Feature or Adjustment | B25: Respin | E25: Bonus
A26: Bet | B26: Pay Back | C26: Pay Back (RD) | D26: Pulls/Hit | E26: Pay Back | F26: Pay Back (RD) | G26: Pulls/Hit
A27: 1 | B27: 0.45551106 | C27: 0.455559
A28: 5 | B28: 0.22229421 | C28: 0.222464 | E28: 0.36011068 | F28: 0.360093
A29: 10 | B29: 0.1925777 | C29: 0.192739 | E29: 0.28457778 | F29: 0.284641
A30: 50 | B30: 0.27733134 | C30: 0.277241 | E30: 0.33122508 | F30: 0.331387
A31: 100 | B31: 0.41873033 | C31: 0.419004 | E31: 0.24884727 | F31: 0.248858
A34: Parameter B
A35: Coin | B35: Bet | C35: Reels | D35: Line | E35: Pay Back % | F35: Pay Back %(RD)
A36: 1 | B36: 1 | C36: 4 | D36: 1 | E36: 33.075364 | F36: 33.071518
A37: 5 | B37: 5 | C37: 4 | D37: 1 | E37: 39.13063 | F37: 39.150795
A38: 10 | B38: 10 | C38: 4 | D38: 1 | E38: 31.078434 | F38: 31.093344
A39: 50 | B39: 50 | C39: 4 | D39: 1 | E39: 51.890255 | F39: 51.890255
A40: 100 | B40: 100 | C40: 4 | D40: 1 | E40: 46.51992 | F40: 46.51992
A42: Total payback percentage includes the following adjustments:
A43: Feature or Adjustment | B43: Respin | E43: Bonus
A44: Bet | B44: Pay Back | C44: Pay Back (RD) | D44: Pulls/Hit | E44: Pay Back | F44: Pay Back (RD) | G44: Pulls/Hit
A45: 1 | B45: 5.2223468 | C45: 5.220887 | D45: - | E45: - | F45: - | G45: -
A46: 5 | B46: 4.02598 | C46: 4.030307 | D46: - | E46: 8.9579175 | F46: 8.958323 | G46: -
A47: 10 | B47: 1.8304766 | C47: 1.830092 | D47: - | E47: 7.1667173 | F47: 7.169445 | G47: -
A48: 50 | C48: 2.104456 | D48: - | F48: 31.831121 | G48: -
A49: 100 | C49: 1.729975 | D49: - | F49: 31.825863 | G49: -
...

Sheet Extra_info
B2: 1 | C2: 卡片系統使用"Card_Info_Extra" | D2: Interval:倍率區間
D3: Weight:倍率區間權重
D4: Sheet:使用表

Sheet Description
B2: 1. 前三輪使用權重輪帶(first 3 reel)，共有A、B、C三張表，並依照多表權重選擇使用哪一張表
B4: 2. 第四輪使用權重輪帶(R4)，並依照前三輪分數來判斷要用哪一組的R4權重
B5: EX : 共有12組權重輪帶，分別對應分數1、5、10、11、15、50、51、55、>=100、>=3001、>= 6001，依照前三輪分數選擇對應的R4權重
B7: 3. 當R4轉到scatter時，使用權重輪帶(scatter) weight 1。
B9: 4. 當R4轉到respin時，使用權重輪帶(respin):
C10: a. 遇到Respin時，前三輪分數 + respin分數須大於等於一倍，respin分數重轉至符合條件
C11: b. 若respin後的分數小於respin前的分數，則互換，前三輪先表演分數小的
C12: c. 當respin分數為0時，respin分數重骰到大於0
B14: 5. bet100時 :
C15: a. bet100時，前三輪分數不能大於30000分(300倍)，若大於時重轉
C16: b. bet100時，respin後分數不能大於30000分(300倍)，若大於時重轉
C17: c. 當respin R3轉到Symbol "10"、"00"，依照switch權重決定R2、R3的Symbol是否互換
B19: 6. 重轉超過10次依照狀況使用固定組合[重轉超過]
B21: 7. R1、R4有機會觸發假表演，當有贏分且R1的Symbol不為0、E時，依照假表演權重表決定是否觸發，若觸發則依照假表演方向權重表來決定方向；當有贏分且R4的Symbol不為E時，依照假表演權重表決定是否觸發，若觸發則依照假表演方向權重表來決定方向
B23: 8. 若前三輪分數為0，第二、三輪轉到Symbol 0的RNG依照表格[0換E]有機率往下跳一個RNG
B24: EX：如果前三輪RNG為(1,0,1)，結果為EE0，0分，若第三輪觸發0換E，則RNG變為(1,0,2)
B26: 9. 初始盤面使用選擇的RNG
C28: bet1起始盤面
C29: R1 | D29: R2 | E29: R3 | F29: R4
B30: Bet1 | C30: 1 | D30: 0 | E30: 2 | F30: 3
B31: Bet5 | C31: 3 | D31: 2 | E31: 4 | F31: 5
B32: Bet10 | C32: 3 | D32: 4 | E32: 0 | F32: 7
B33: Bet50 | C33: 3 | D33: 8 | E33: 0 | F33: 5
B34: Bet100 | C34: 1 | D34: 8 | E34: 8 | F34: 7
E35: (此處為RNG)
B37: 10. 任務系統第四輪使用FreeGameCard_R4輪帶
B39: V2（5.0.0.0）：Extra Bet 內容沿用 1.0.0.2，僅版本號隨 Normal Bet 模型同步第 1 碼。

Sheet Card_Info_Extra_testA
A1: Bet 1 | D1: Bet 5 | G1: Bet 10 | J1: Bet 50 | M1: Bet 100 | R1: Simulation
A2: =Card_Bet1!V1 -> 0.9199948 | D2: =Card_Bet5!V1 -> 0.91999777 | G2: =Card_Bet10!V1 -> 0.91999349 | J2: =Card_Bet50!V1 -> 0.91998901 | M2: =Card_Bet100!V1 -> 0.91999322
A3: Interval | B3: Weight | C3: Sheet | D3: Interval | E3: Weight | F3: Sheet | G3: Interval | H3: Weight | I3: Sheet | J3: Interval | K3: Weight | L3: Sheet | M3: Interval | N3: Weight | O3: Sheet | R3: Bet | S3: RTP | T3: Respin | U3: Scatter | V3: rounds | W3: Scatter+Respin | X3: Scatter+Respin PROB.
A4: -1 | B4: {=Card_Bet1!$T$3:$T$54} -> 791728 | C4: {=Card_Bet1!$L$3:$L$54} -> A | D4: -1 | E4: {=Card_Bet5!$T$3:$T$54} -> 803427 | F4: {=Card_Bet5!$L$3:$L$54} -> A | G4: -1 | H4: {=Card_Bet10!$T$3:$T$54} -> 808528 | I4: {=Card_Bet10!$L$3:$L$54} -> A | J4: -1 | K4: {=Card_Bet50!$T$3:$T$54} -> 806081 | L4: {=Card_Bet50!$L$3:$L$54} -> A | M4: -1 | N4: {=Card_Bet100!$T$3:$T$54} -> 822557 | O4: {=Card_Bet100!$L$3:$L$54} -> A | R4: 1 | S4: 0.92499 | T4: 0.122159 | U4: - | V4: 100000000 | W4: =SUM(AA11:AA24,AD11:AD24) -> 13938446 | X4: =W4/V4 -> 0.13938446
A5: 0 | B5: 97570 | C5: B | D5: 0 | E5: 97883 | F5: B | G5: 0 | H5: 37060 | I5: B | J5: 0 | K5: 74630 | L5: A | M5: 0 | N5: 11212 | O5: A | R5: 5 | S5: 0.924692 | T5: 0.06123 | U5: 0.224109 | V5: 100000000 | W5: =SUM(AA26:AA43,AD26:AD43) -> 6038039 | X5: =W5/V5 -> 0.06038039
A6: 1 | B6: 1523 | C6: B | D6: 1 | E6: 3000 | F6: B | G6: 1 | H6: 58950 | I6: B | J6: 1 | K6: 23758 | L6: B | M6: 1 | N6: 39741 | O6: B | R6: 10 | S6: 0.924693 | T6: 0.081793 | U6: 0.16207 | V6: 100000000 | W6: =SUM(AA45:AA62,AD45:AD62) -> 9640371 | X6: =W6/V6 -> 0.09640371
A7: 2 | B7: 0 | C7: B | D7: 2 | E7: 6000 | F7: B | G7: 2 | H7: 500 | I7: B | J7: 2 | K7: 4482 | L7: B | M7: 2 | N7: 945 | O7: B | R7: 50 | S7: 0.925385 | T7: 0.049855 | U7: 0.337065 | V7: 100000000 | W7: =SUM(AA64:AA85,AD64:AD85) -> 6369513 | X7: =W7/V7 -> 0.06369513
A8: 3 | B8: 0 | C8: B | D8: 3 | E8: 0 | F8: B | G8: 3 | H8: 0 | I8: B | J8: 3 | K8: 1218 | L8: B | M8: 3 | N8: 0 | O8: B | R8: 100 | S8: 0.924616 | T8: 0.131463 | U8: 0.220799 | V8: 100000000 | W8: =SUM(AA87:AA109,AD87:AD109) -> 9715998 | X8: =W8/V8 -> 0.09715998
A9: 4 | B9: 64244 | C9: B | D9: 4 | E9: 45000 | F9: B | G9: 4 | H9: 23100 | I9: B | J9: 4 | K9: 45000 | L9: B | M9: 4 | N9: 30000 | O9: B
A10: 5 | B10: 1729 | C10: B | D10: 5 | E10: 1545 | F10: B | G10: 5 | H10: 27525 | I10: B | J10: 5 | K10: 1490 | L10: B | M10: 5 | N10: 50250 | O10: B
A11: 6 | B11: 0 | C11: B | D11: 6 | E11: 0 | F11: B | G11: 6 | H11: 105 | I11: B | J11: 6 | K11: 0 | L11: B | M11: 6 | N11: 56 | O11: B | Q11: 1 | R11: BaseGame | S11: 0x | T11: = | U11: 9755188 | V11: Pay | W11: = | X11: 975518800 | Y11: 1C1 | Z11: = | AA11: null | AB11: 2C1 | AC11: = | AD11: 9755188 | AE11: 3C1 | AF11: = | AG11: null | AH11: 4C1 | AI11: = | AJ11: null | AK11: 5C1 | AL11: = | AM11: null
A12: 7 | B12: 0 | C12: B | D12: 7 | E12: 0 | F12: B | G12: 7 | H12: 0 | I12: B | J12: 7 | K12: 0 | L12: B | M12: 7 | N12: 0 | O12: B | Q12: 1 | R12: BaseGame | S12: 1x | T12: = | U12: 152207 | V12: Pay | W12: = | X12: 30441400 | Y12: 1C1 | Z12: = | AA12: null | AB12: 2C1 | AC12: = | AD12: 30555 | AE12: 3C1 | AF12: = | AG12: null | AH12: 4C1 | AI12: = | AJ12: null | AK12: 5C1 | AL12: = | AM12: null
A13: 8 | B13: 0 | C13: B | D13: 8 | E13: 0 | F13: B | G13: 8 | H13: 0 | I13: B | J13: 8 | K13: 0 | L13: B | M13: 8 | N13: 0 | O13: B | Q13: 1 | R13: BaseGame | S13: 4x | T13: = | U13: 6417437 | V13: Pay | W13: = | X13: 3208718500 | Y13: 1C1 | Z13: = | AA13: null | AB13: 2C1 | AC13: = | AD13: 2139248 | AE13: 3C1 | AF13: = | AG13: null | AH13: 4C1 | AI13: = | AJ13: null | AK13: 5C1 | AL13: = | AM13: null
A14: 9 | B14: 14006 | C14: B | D14: 9 | E14: 6914 | F14: B | G14: 9 | H14: 6035 | I14: B | J14: 9 | K14: 5394 | L14: B | M14: 9 | N14: 8627 | O14: B | Q14: 1 | R14: BaseGame | S14: 5x | T14: = | U14: 172541 | V14: Pay | W14: = | X14: 103524600 | Y14: 1C1 | Z14: = | AA14: null | AB14: 2C1 | AC14: = | AD14: 172541 | AE14: 3C1 | AF14: = | AG14: null | AH14: 4C1 | AI14: = | AJ14: null | AK14: 5C1 | AL14: = | AM14: null
A15: 10 | B15: 7500 | C15: B | D15: 10 | E15: 8700 | F15: B | G15: 10 | H15: 14284 | I15: B | J15: 10 | K15: 9612 | L15: B | M15: 10 | N15: 15000 | O15: B | Q15: 1 | R15: BaseGame | S15: 9x | T15: = | U15: 1478807 | V15: Pay | W15: = | X15: 1478807000 | Y15: 1C1 | Z15: = | AA15: null | AB15: 2C1 | AC15: = | AD15: 544867 | AE15: 3C1 | AF15: = | AG15: null | AH15: 4C1 | AI15: = | AJ15: null | AK15: 5C1 | AL15: = | AM15: null
A16: 15 | B16: 7500 | C16: B | D16: 15 | E16: 4305 | F16: B | G16: 15 | H16: 7368 | I16: B | J16: 15 | K16: 6825 | L16: B | M16: 15 | N16: 10500 | O16: B | Q16: 1 | R16: BaseGame | S16: 10x | T16: = | U16: 750491 | V16: Pay | W16: = | X16: 968719300 | Y16: 1C1 | Z16: = | AA16: null | AB16: 2C1 | AC16: = | AD16: 750491 | AE16: 3C1 | AF16: = | AG16: null | AH16: 4C1 | AI16: = | AJ16: null | AK16: 5C1 | AL16: = | AM16: null
A17: 20 | B17: 5100 | C17: B | D17: 20 | E17: 9450 | F17: B | G17: 20 | H17: 6600 | I17: B | J17: 20 | K17: 7140 | L17: B | M17: 20 | N17: 2940 | O17: B | Q17: 1 | R17: BaseGame | S17: 15x | T17: = | U17: 749839 | V17: Pay | W17: = | X17: 1451040000 | Y17: 1C1 | Z17: = | AA17: null | AB17: 2C1 | AC17: = | AD17: 262598 | AE17: 3C1 | AF17: = | AG17: null | AH17: 4C1 | AI17: = | AJ17: null | AK17: 5C1 | AL17: = | AM17: null
A18: 25 | B18: 1695 | C18: B | D18: 25 | E18: 2550 | F18: B | G18: 25 | H18: 1650 | I18: B | J18: 25 | K18: 3381 | L18: B | M18: 25 | N18: 765 | O18: B | Q18: 1 | R18: BaseGame | S18: 20x | T18: = | U18: 509765 | V18: Pay | W18: = | X18: 1244903600 | Y18: 1C1 | Z18: = | AA18: null | AB18: 2C1 | AC18: = | AD18: 46891 | AE18: 3C1 | AF18: = | AG18: null | AH18: 4C1 | AI18: = | AJ18: null | AK18: 5C1 | AL18: = | AM18: null
A19: 30 | B19: 0 | C19: B | D19: 30 | E19: 2700 | F19: B | G19: 30 | H19: 0 | I19: B | J19: 30 | K19: 1500 | L19: B | M19: 30 | N19: 389 | O19: B | Q19: 1 | R19: BaseGame | S19: 25x | T19: = | U19: 169621 | V19: Pay | W19: = | X19: 503892600 | Y19: 1C1 | Z19: = | AA19: null | AB19: 2C1 | AC19: = | AD19: 18829 | AE19: 3C1 | AF19: = | AG19: null | AH19: 4C1 | AI19: = | AJ19: null | AK19: 5C1 | AL19: = | AM19: null
A20: 35 | B20: 0 | C20: B | D20: 35 | E20: 0 | F20: B | G20: 35 | H20: 0 | I20: B | J20: 35 | K20: 2550 | L20: B | M20: 35 | N20: 278 | O20: B | Q20: 1 | R20: BaseGame | S20: 45x | T20: = | U20: 539156 | V20: Pay | W20: = | X20: 2695780000 | Y20: 1C1 | Z20: = | AA20: null | AB20: 2C1 | AC20: = | AD20: 59535 | AE20: 3C1 | AF20: = | AG20: null | AH20: 4C1 | AI20: = | AJ20: null | AK20: 5C1 | AL20: = | AM20: null
A21: 40 | B21: 0 | C21: B | D21: 40 | E21: 0 | F21: B | G21: 40 | H21: 0 | I21: B | J21: 40 | K21: 1050 | L21: B | M21: 40 | N21: 777 | O21: B | Q21: 1 | R21: BaseGame | S21: 50x | T21: = | U21: 180209 | V21: Pay | W21: = | X21: 990081500 | Y21: 1C1 | Z21: = | AA21: null | AB21: 2C1 | AC21: = | AD21: 146376 | AE21: 3C1 | AF21: = | AG21: null | AH21: 4C1 | AI21: = | AJ21: null | AK21: 5C1 | AL21: = | AM21: null
A22: 45 | B22: 5400 | C22: B | D22: 45 | E22: 8265 | F22: B | G22: 45 | H22: 2610 | I22: B | J22: 45 | K22: 5700 | L22: B | M22: 45 | N22: 1388 | O22: B | Q22: 1 | R22: BaseGame | S22: 90x | T22: = | U22: 9852 | V22: Pay | W22: = | X22: 98520000 | Y22: 1C1 | Z22: = | AA22: null | AB22: 2C1 | AC22: = | AD22: 3425 | AE22: 3C1 | AF22: = | AG22: null | AH22: 4C1 | AI22: = | AJ22: null | AK22: 5C1 | AL22: = | AM22: null
A23: 50 | B23: 1800 | C23: B | D23: 50 | E23: 0 | F23: B | G23: 50 | H23: 5370 | I23: B | J23: 50 | K23: 0 | L23: B | M23: 50 | N23: 4350 | O23: B | Q23: 1 | R23: BaseGame | S23: 100x | T23: = | U23: 10551 | V23: Pay | W23: = | X23: 112345800 | Y23: 1C1 | Z23: = | AA23: null | AB23: 2C1 | AC23: = | AD23: 7902 | AE23: 3C1 | AF23: = | AG23: null | AH23: 4C1 | AI23: = | AJ23: null | AK23: 5C1 | AL23: = | AM23: null
A24: 60 | B24: 0 | C24: B | D24: 60 | E24: 0 | F24: B | G24: 60 | H24: 0 | I24: B | J24: 60 | K24: 0 | L24: B | M24: 60 | N24: 0 | O24: B | Q24: 1 | R24: BaseGame | S24: 450x | T24: = | U24: 205 | V24: Pay | W24: = | X24: 10250000 | Y24: 1C1 | Z24: = | AA24: null | AB24: 2C1 | AC24: = | AD24: null | AE24: 3C1 | AF24: = | AG24: null | AH24: 4C1 | AI24: = | AJ24: null | AK24: 5C1 | AL24: = | AM24: null
A25: 70 | B25: 0 | C25: B | D25: 70 | E25: 0 | F25: B | G25: 70 | H25: 0 | I25: B | J25: 70 | K25: 0 | L25: B | M25: 70 | N25: 0 | O25: B
A26: 80 | B26: 0 | C26: B | D26: 80 | E26: 0 | F26: B | G26: 80 | H26: 0 | I26: B | J26: 80 | K26: 0 | L26: B | M26: 80 | N26: 0 | O26: B | Q26: 5 | R26: BaseGame | S26: 0x | T26: = | U26: 9789906 | V26: Pay | W26: = | X26: 3645464700 | Y26: 1C1 | Z26: = | AA26: null | AB26: 2C1 | AC26: = | AD26: 1451276 | AE26: 3C1 | AF26: = | AG26: null | AH26: 4C1 | AI26: = | AJ26: null | AK26: 5C1 | AL26: = | AM26: null
A27: 90 | B27: 98 | C27: B | D27: 90 | E27: 138 | F27: B | G27: 90 | H27: 110 | I27: B | J27: 90 | K27: 30 | L27: B | M27: 90 | N27: 56 | O27: B | Q27: 5 | R27: BaseGame | S27: 1x | T27: = | U27: 300187 | V27: Pay | W27: = | X27: 273465800 | Y27: 1C1 | Z27: = | AA27: null | AB27: 2C1 | AC27: = | AD27: 131738 | AE27: 3C1 | AF27: = | AG27: null | AH27: 4C1 | AI27: = | AJ27: null | AK27: 5C1 | AL27: = | AM27: null
A28: 100 | B28: 105 | C28: B | D28: 100 | E28: 68 | F28: B | G28: 100 | H28: 150 | I28: B | J28: 100 | K28: 90 | L28: B | M28: 100 | N28: 111 | O28: B | Q28: 5 | R28: BaseGame | S28: 2x | T28: = | U28: 599434 | V28: Pay | W28: = | X28: 766524100 | Y28: 1C1 | Z28: = | AA28: null | AB28: 2C1 | AC28: = | AD28: 599434 | AE28: 3C1 | AF28: = | AG28: null | AH28: 4C1 | AI28: = | AJ28: null | AK28: 5C1 | AL28: = | AM28: null
A29: 120 | B29: 0 | C29: B | D29: 120 | E29: 0 | F29: B | G29: 120 | H29: 0 | I29: B | J29: 120 | K29: 0 | L29: B | M29: 120 | N29: 0 | O29: B | Q29: 5 | R29: BaseGame | S29: 4x | T29: = | U29: 4500174 | V29: Pay | W29: = | X29: 10920661900 | Y29: 1C1 | Z29: = | AA29: 547632 | AB29: 2C1 | AC29: = | AD29: 395533 | AE29: 3C1 | AF29: = | AG29: null | AH29: 4C1 | AI29: = | AJ29: null | AK29: 5C1 | AL29: = | AM29: null
A30: 140 | B30: 0 | C30: B | D30: 140 | E30: 0 | F30: B | G30: 140 | H30: 2 | I30: B | J30: 140 | K30: 0 | L30: B | M30: 140 | N30: 0 | O30: B | Q30: 5 | R30: BaseGame | S30: 5x | T30: = | U30: 154433 | V30: Pay | W30: = | X30: 447120600 | Y30: 1C1 | Z30: = | AA30: 64460 | AB30: 2C1 | AC30: = | AD30: 12463 | AE30: 3C1 | AF30: = | AG30: null | AH30: 4C1 | AI30: = | AJ30: null | AK30: 5C1 | AL30: = | AM30: null
A31: 160 | B31: 0 | C31: B | D31: 160 | E31: 0 | F31: B | G31: 160 | H31: 0 | I31: B | J31: 160 | K31: 0 | L31: B | M31: 160 | N31: 0 | O31: B | Q31: 5 | R31: BaseGame | S31: 9x | T31: = | U31: 763866 | V31: Pay | W31: = | X31: 3819330000 | Y31: 1C1 | Z31: = | AA31: 168486 | AB31: 2C1 | AC31: = | AD31: 88079 | AE31: 3C1 | AF31: = | AG31: null | AH31: 4C1 | AI31: = | AJ31: null | AK31: 5C1 | AL31: = | AM31: null
A32: 180 | B32: 0 | C32: B | D32: 180 | E32: 30 | F32: B | G32: 180 | H32: 51 | I32: B | J32: 180 | K32: 52 | L32: B | M32: 180 | N32: 45 | O32: B | Q32: 5 | R32: BaseGame | S32: 10x | T32: = | U32: 869364 | V32: Pay | W32: = | X32: 5266796600 | Y32: 1C1 | Z32: = | AA32: 220318 | AB32: 2C1 | AC32: = | AD32: 440883 | AE32: 3C1 | AF32: = | AG32: null | AH32: 4C1 | AI32: = | AJ32: null | AK32: 5C1 | AL32: = | AM32: null
A33: 200 | B33: 0 | C33: B | D33: 200 | E33: 15 | F33: B | G33: 200 | H33: 0 | I33: B | J33: 200 | K33: 0 | L33: B | M33: 200 | N33: 0 | O33: B | Q33: 5 | R33: BaseGame | S33: 15x | T33: = | U33: 431354 | V33: Pay | W33: = | X33: 3955755700 | Y33: 1C1 | Z33: = | AA33: 277720 | AB33: 2C1 | AC33: = | AD33: 37460 | AE33: 3C1 | AF33: = | AG33: null | AH33: 4C1 | AI33: = | AJ33: null | AK33: 5C1 | AL33: = | AM33: null
A34: 250 | B34: 0 | C34: B | D34: 250 | E34: 0 | F34: B | G34: 250 | H34: 0 | I34: B | J34: 250 | K34: 0 | L34: B | M34: 250 | N34: 0 | O34: B | Q34: 5 | R34: BaseGame | S34: 20x | T34: = | U34: 946060 | V34: Pay | W34: = | X34: 10166434700 | Y34: 1C1 | Z34: = | AA34: 213479 | AB34: 2C1 | AC34: = | AD34: 496752 | AE34: 3C1 | AF34: = | AG34: null | AH34: 4C1 | AI34: = | AJ34: null | AK34: 5C1 | AL34: = | AM34: null
A35: 300 | B35: 0 | C35: B | D35: 300 | E35: 5 | F35: B | G35: 300 | H35: 0 | I35: B | J35: 300 | K35: 0 | L35: B | M35: 300 | N35: 0 | O35: B | Q35: 5 | R35: BaseGame | S35: 25x | T35: = | U35: 255080 | V35: Pay | W35: = | X35: 3641477900 | Y35: 1C1 | Z35: = | AA35: 228780 | AB35: 2C1 | AC35: = | AD35: 26300 | AE35: 3C1 | AF35: = | AG35: null | AH35: 4C1 | AI35: = | AJ35: null | AK35: 5C1 | AL35: = | AM35: null
A36: 350 | B36: 0 | C36: B | D36: 350 | E36: 0 | F36: B | G36: 350 | H36: 0 | I36: B | J36: 350 | K36: 0 | L36: B | M36: 350 | N36: 0 | O36: B | Q36: 5 | R36: BaseGame | S36: 30x | T36: = | U36: 270974 | V36: Pay | W36: = | X36: 4241809500 | Y36: 1C1 | Z36: = | AA36: 164626 | AB36: 2C1 | AC36: = | AD36: 106348 | AE36: 3C1 | AF36: = | AG36: null | AH36: 4C1 | AI36: = | AJ36: null | AK36: 5C1 | AL36: = | AM36: null
A37: 400 | B37: 0 | C37: B | D37: 400 | E37: 0 | F37: B | G37: 400 | H37: 0 | I37: B | J37: 400 | K37: 0 | L37: B | M37: 400 | N37: 0 | O37: B | Q37: 5 | R37: BaseGame | S37: 45x | T37: = | U37: 827600 | V37: Pay | W37: = | X37: 20566450800 | Y37: 1C1 | Z37: = | AA37: 345980 | AB37: 2C1 | AC37: = | AD37: 4746 | AE37: 3C1 | AF37: = | AG37: null | AH37: 4C1 | AI37: = | AJ37: null | AK37: 5C1 | AL37: = | AM37: null
A38: 450 | B38: 2 | C38: B | D38: 450 | E38: 0 | F38: B | G38: 450 | H38: 0 | I38: B | J38: 450 | K38: 8 | L38: B | M38: 450 | N38: 6 | O38: B | Q38: 5 | R38: BaseGame | S38: 90x | T38: = | U38: 13756 | V38: Pay | W38: = | X38: 687800000 | Y38: 1C1 | Z38: = | AA38: 6183 | AB38: 2C1 | AC38: = | AD38: 355 | AE38: 3C1 | AF38: = | AG38: null | AH38: 4C1 | AI38: = | AJ38: null | AK38: 5C1 | AL38: = | AM38: null
A39: 500 | B39: 0 | C39: B | D39: 500 | E39: 5 | F39: B | G39: 500 | H39: 2 | I39: B | J39: 500 | K39: 5 | L39: B | M39: 500 | N39: 5 | O39: B | Q39: 5 | R39: BaseGame | S39: 100x | T39: = | U39: 6789 | V39: Pay | W39: = | X39: 358070200 | Y39: 1C1 | Z39: = | AA39: 2584 | AB39: 2C1 | AC39: = | AD39: 2017 | AE39: 3C1 | AF39: = | AG39: null | AH39: 4C1 | AI39: = | AJ39: null | AK39: 5C1 | AL39: = | AM39: null
A40: 550 | B40: 0 | C40: B | D40: 550 | E40: 0 | F40: B | G40: 550 | H40: 0 | I40: B | J40: 550 | K40: 0 | L40: B | M40: 550 | N40: 0 | O40: B | Q40: 5 | R40: BaseGame | S40: 180x | T40: = | U40: 2943 | V40: Pay | W40: = | X40: 294300000 | Y40: 1C1 | Z40: = | AA40: 2440 | AB40: 2C1 | AC40: = | AD40: 154 | AE40: 3C1 | AF40: = | AG40: null | AH40: 4C1 | AI40: = | AJ40: null | AK40: 5C1 | AL40: = | AM40: null
...

Sheet Card_Info_Extra_testB
A1: Bet 1 | D1: Bet 5 | G1: Bet 10 | J1: Bet 50 | M1: Bet 100 | R1: Simulation
A2: 0.92512146 | D2: 0.92490444 | G2: 0.92491349 | J2: 0.92507843 | M2: 0.92465247
A3: Interval | B3: Weight | C3: Sheet | D3: Interval | E3: Weight | F3: Sheet | G3: Interval | H3: Weight | I3: Sheet | J3: Interval | K3: Weight | L3: Sheet | M3: Interval | N3: Weight | O3: Sheet | R3: Bet | S3: RTP | T3: Respin | U3: Scatter | V3: rounds | W3: Scatter+Respin | X3: Scatter+Respin PROB.
A4: -1 | B4: 790959 | C4: A | D4: -1 | E4: 802691 | F4: A | G4: -1 | H4: 807790 | I4: A | J4: -1 | K4: 788711 | L4: A | M4: -1 | N4: 821893 | O4: A | R4: 1 | S4: 0.924421 | T4: 0.122159 | U4: - | V4: 100000000 | W4: =SUM(AA11:AA24,AD11:AD24) -> 13938446 | X4: =W4/V4 -> 0.13938446
A5: 0 | B5: 97570 | C5: B | D5: 0 | E5: 97883 | F5: B | G5: 0 | H5: 37060 | I5: B | J5: 0 | K5: 97570 | L5: A | M5: 0 | N5: 11212 | O5: A | R5: 5 | S5: 0.925082 | T5: 0.06123 | U5: 0.224109 | V5: 100000000 | W5: =SUM(AA26:AA43,AD26:AD43) -> 6038039 | X5: =W5/V5 -> 0.06038039
A6: 1 | B6: 1523 | C6: B | D6: 1 | E6: 3000 | F6: B | G6: 1 | H6: 58950 | I6: B | J6: 1 | K6: 1500 | L6: B | M6: 1 | N6: 39741 | O6: B | R6: 10 | S6: 0.925132 | T6: 0.081793 | U6: 0.16207 | V6: 300000000 | W6: =SUM(AA45:AA62,AD45:AD62) -> 9640371 | X6: =W6/V6 -> 0.03213457
A7: 2 | B7: 0 | C7: B | D7: 2 | E7: 6000 | F7: B | G7: 2 | H7: 500 | I7: B | J7: 2 | K7: 0 | L7: B | M7: 2 | N7: 945 | O7: B | R7: 50 | S7: 0.925361 | T7: 0.049855 | U7: 0.337065 | V7: 100000000 | W7: =SUM(AA64:AA77,AD64:AD77) -> 5723247 | X7: =W7/V7 -> 0.05723247
A8: 3 | B8: 0 | C8: B | D8: 3 | E8: 0 | F8: B | G8: 3 | H8: 0 | I8: B | J8: 3 | K8: 0 | L8: B | M8: 3 | N8: 0 | O8: B | R8: 100 | S8: 0.924687 | T8: 0.131463 | U8: 0.220799 | V8: 100000000 | W8: =SUM(AA79:AA97,AD79:AD97) -> 9874309 | X8: =W8/V8 -> 0.09874309
A9: 4 | B9: 64244 | C9: B | D9: 4 | E9: 45000 | F9: B | G9: 4 | H9: 23100 | I9: B | J9: 4 | K9: 64200 | L9: B | M9: 4 | N9: 30000 | O9: B
A10: 5 | B10: 1729 | C10: B | D10: 5 | E10: 1545 | F10: B | G10: 5 | H10: 27525 | I10: B | J10: 5 | K10: 1729 | L10: B | M10: 5 | N10: 50250 | O10: B
A11: 6 | B11: 0 | C11: B | D11: 6 | E11: 0 | F11: B | G11: 6 | H11: 105 | I11: B | J11: 6 | K11: 0 | L11: B | M11: 6 | N11: 56 | O11: B | R11: BaseGame | S11: 0x | T11: = | U11: 9755188 | V11: Pay | W11: = | X11: 975518800 | Y11: 1C1 | Z11: = | AA11: null | AB11: 2C1 | AC11: = | AD11: 9755188 | AE11: 3C1 | AF11: = | AG11: null | AH11: 4C1 | AI11: = | AJ11: null | AK11: 5C1 | AL11: = | AM11: null
A12: 7 | B12: 0 | C12: B | D12: 7 | E12: 0 | F12: B | G12: 7 | H12: 0 | I12: B | J12: 7 | K12: 0 | L12: B | M12: 7 | N12: 0 | O12: B | R12: BaseGame | S12: 1x | T12: = | U12: 152207 | V12: Pay | W12: = | X12: 30441400 | Y12: 1C1 | Z12: = | AA12: null | AB12: 2C1 | AC12: = | AD12: 30555 | AE12: 3C1 | AF12: = | AG12: null | AH12: 4C1 | AI12: = | AJ12: null | AK12: 5C1 | AL12: = | AM12: null
A13: 8 | B13: 0 | C13: B | D13: 8 | E13: 0 | F13: B | G13: 8 | H13: 0 | I13: B | J13: 8 | K13: 0 | L13: B | M13: 8 | N13: 0 | O13: B | R13: BaseGame | S13: 4x | T13: = | U13: 6417437 | V13: Pay | W13: = | X13: 3208718500 | Y13: 1C1 | Z13: = | AA13: null | AB13: 2C1 | AC13: = | AD13: 2139248 | AE13: 3C1 | AF13: = | AG13: null | AH13: 4C1 | AI13: = | AJ13: null | AK13: 5C1 | AL13: = | AM13: null
A14: 9 | B14: 14775 | C14: B | D14: 9 | E14: 7650 | F14: B | G14: 9 | H14: 6773 | I14: B | J14: 9 | K14: 12900 | L14: B | M14: 9 | N14: 9375 | O14: B | R14: BaseGame | S14: 5x | T14: = | U14: 172541 | V14: Pay | W14: = | X14: 103524600 | Y14: 1C1 | Z14: = | AA14: null | AB14: 2C1 | AC14: = | AD14: 172541 | AE14: 3C1 | AF14: = | AG14: null | AH14: 4C1 | AI14: = | AJ14: null | AK14: 5C1 | AL14: = | AM14: null
A15: 10 | B15: 7500 | C15: B | D15: 10 | E15: 8700 | F15: B | G15: 10 | H15: 14284 | I15: B | J15: 10 | K15: 9269 | L15: B | M15: 10 | N15: 15000 | O15: B | R15: BaseGame | S15: 9x | T15: = | U15: 1478807 | V15: Pay | W15: = | X15: 1478807000 | Y15: 1C1 | Z15: = | AA15: null | AB15: 2C1 | AC15: = | AD15: 544867 | AE15: 3C1 | AF15: = | AG15: null | AH15: 4C1 | AI15: = | AJ15: null | AK15: 5C1 | AL15: = | AM15: null
A16: 15 | B16: 7500 | C16: B | D16: 15 | E16: 4305 | F16: B | G16: 15 | H16: 7368 | I16: B | J16: 15 | K16: 8982 | L16: B | M16: 15 | N16: 10500 | O16: B | R16: BaseGame | S16: 10x | T16: = | U16: 750491 | V16: Pay | W16: = | X16: 968719300 | Y16: 1C1 | Z16: = | AA16: null | AB16: 2C1 | AC16: = | AD16: 750491 | AE16: 3C1 | AF16: = | AG16: null | AH16: 4C1 | AI16: = | AJ16: null | AK16: 5C1 | AL16: = | AM16: null
A17: 20 | B17: 5100 | C17: B | D17: 20 | E17: 9450 | F17: B | G17: 20 | H17: 6600 | I17: B | J17: 20 | K17: 5131 | L17: B | M17: 20 | N17: 2609 | O17: B | R17: BaseGame | S17: 15x | T17: = | U17: 749839 | V17: Pay | W17: = | X17: 1451040000 | Y17: 1C1 | Z17: = | AA17: null | AB17: 2C1 | AC17: = | AD17: 262598 | AE17: 3C1 | AF17: = | AG17: null | AH17: 4C1 | AI17: = | AJ17: null | AK17: 5C1 | AL17: = | AM17: null
A18: 25 | B18: 1695 | C18: B | D18: 25 | E18: 2550 | F18: B | G18: 25 | H18: 1650 | I18: B | J18: 25 | K18: 1635 | L18: B | M18: 25 | N18: 777 | O18: B | R18: BaseGame | S18: 20x | T18: = | U18: 509765 | V18: Pay | W18: = | X18: 1244903600 | Y18: 1C1 | Z18: = | AA18: null | AB18: 2C1 | AC18: = | AD18: 46891 | AE18: 3C1 | AF18: = | AG18: null | AH18: 4C1 | AI18: = | AJ18: null | AK18: 5C1 | AL18: = | AM18: null
A19: 30 | B19: 0 | C19: B | D19: 30 | E19: 2700 | F19: B | G19: 30 | H19: 0 | I19: B | J19: 30 | K19: 0 | L19: B | M19: 30 | N19: 389 | O19: B | R19: BaseGame | S19: 25x | T19: = | U19: 169621 | V19: Pay | W19: = | X19: 503892600 | Y19: 1C1 | Z19: = | AA19: null | AB19: 2C1 | AC19: = | AD19: 18829 | AE19: 3C1 | AF19: = | AG19: null | AH19: 4C1 | AI19: = | AJ19: null | AK19: 5C1 | AL19: = | AM19: null
A20: 35 | B20: 0 | C20: B | D20: 35 | E20: 0 | F20: B | G20: 35 | H20: 0 | I20: B | J20: 35 | K20: 0 | L20: B | M20: 35 | N20: 278 | O20: B | R20: BaseGame | S20: 45x | T20: = | U20: 539156 | V20: Pay | W20: = | X20: 2695780000 | Y20: 1C1 | Z20: = | AA20: null | AB20: 2C1 | AC20: = | AD20: 59535 | AE20: 3C1 | AF20: = | AG20: null | AH20: 4C1 | AI20: = | AJ20: null | AK20: 5C1 | AL20: = | AM20: null
A21: 40 | B21: 0 | C21: B | D21: 40 | E21: 0 | F21: B | G21: 40 | H21: 0 | I21: B | J21: 40 | K21: 0 | L21: B | M21: 40 | N21: 777 | O21: B | R21: BaseGame | S21: 50x | T21: = | U21: 180209 | V21: Pay | W21: = | X21: 990081500 | Y21: 1C1 | Z21: = | AA21: null | AB21: 2C1 | AC21: = | AD21: 146376 | AE21: 3C1 | AF21: = | AG21: null | AH21: 4C1 | AI21: = | AJ21: null | AK21: 5C1 | AL21: = | AM21: null
A22: 45 | B22: 5400 | C22: B | D22: 45 | E22: 8265 | F22: B | G22: 45 | H22: 2610 | I22: B | J22: 45 | K22: 5470 | L22: B | M22: 45 | N22: 1388 | O22: B | R22: BaseGame | S22: 90x | T22: = | U22: 9852 | V22: Pay | W22: = | X22: 98520000 | Y22: 1C1 | Z22: = | AA22: null | AB22: 2C1 | AC22: = | AD22: 3425 | AE22: 3C1 | AF22: = | AG22: null | AH22: 4C1 | AI22: = | AJ22: null | AK22: 5C1 | AL22: = | AM22: null
A23: 50 | B23: 1800 | C23: B | D23: 50 | E23: 0 | F23: B | G23: 50 | H23: 5370 | I23: B | J23: 50 | K23: 2683 | L23: B | M23: 50 | N23: 4598 | O23: B | R23: BaseGame | S23: 100x | T23: = | U23: 10551 | V23: Pay | W23: = | X23: 112345800 | Y23: 1C1 | Z23: = | AA23: null | AB23: 2C1 | AC23: = | AD23: 7902 | AE23: 3C1 | AF23: = | AG23: null | AH23: 4C1 | AI23: = | AJ23: null | AK23: 5C1 | AL23: = | AM23: null
A24: 60 | B24: 0 | C24: B | D24: 60 | E24: 0 | F24: B | G24: 60 | H24: 0 | I24: B | J24: 60 | K24: 0 | L24: B | M24: 60 | N24: 0 | O24: B | R24: BaseGame | S24: 450x | T24: = | U24: 205 | V24: Pay | W24: = | X24: 10250000 | Y24: 1C1 | Z24: = | AA24: null | AB24: 2C1 | AC24: = | AD24: null | AE24: 3C1 | AF24: = | AG24: null | AH24: 4C1 | AI24: = | AJ24: null | AK24: 5C1 | AL24: = | AM24: null
A25: 70 | B25: 0 | C25: B | D25: 70 | E25: 0 | F25: B | G25: 70 | H25: 0 | I25: B | J25: 70 | K25: 0 | L25: B | M25: 70 | N25: 0 | O25: B
A26: 80 | B26: 0 | C26: B | D26: 80 | E26: 0 | F26: B | G26: 80 | H26: 0 | I26: B | J26: 80 | K26: 0 | L26: B | M26: 80 | N26: 0 | O26: B | R26: BaseGame | S26: 0x | T26: = | U26: 9789906 | V26: Pay | W26: = | X26: 3645464700 | Y26: 1C1 | Z26: = | AA26: null | AB26: 2C1 | AC26: = | AD26: 1451276 | AE26: 3C1 | AF26: = | AG26: null | AH26: 4C1 | AI26: = | AJ26: null | AK26: 5C1 | AL26: = | AM26: null
A27: 90 | B27: 98 | C27: B | D27: 90 | E27: 138 | F27: B | G27: 90 | H27: 110 | I27: B | J27: 90 | K27: 90 | L27: B | M27: 90 | N27: 56 | O27: B | R27: BaseGame | S27: 1x | T27: = | U27: 300187 | V27: Pay | W27: = | X27: 273465800 | Y27: 1C1 | Z27: = | AA27: null | AB27: 2C1 | AC27: = | AD27: 131738 | AE27: 3C1 | AF27: = | AG27: null | AH27: 4C1 | AI27: = | AJ27: null | AK27: 5C1 | AL27: = | AM27: null
A28: 100 | B28: 105 | C28: B | D28: 100 | E28: 68 | F28: B | G28: 100 | H28: 150 | I28: B | J28: 100 | K28: 120 | L28: B | M28: 100 | N28: 111 | O28: B | R28: BaseGame | S28: 2x | T28: = | U28: 599434 | V28: Pay | W28: = | X28: 766524100 | Y28: 1C1 | Z28: = | AA28: null | AB28: 2C1 | AC28: = | AD28: 599434 | AE28: 3C1 | AF28: = | AG28: null | AH28: 4C1 | AI28: = | AJ28: null | AK28: 5C1 | AL28: = | AM28: null
A29: 120 | B29: 0 | C29: B | D29: 120 | E29: 0 | F29: B | G29: 120 | H29: 0 | I29: B | J29: 120 | K29: 0 | L29: B | M29: 120 | N29: 0 | O29: B | R29: BaseGame | S29: 4x | T29: = | U29: 4500174 | V29: Pay | W29: = | X29: 10920661900 | Y29: 1C1 | Z29: = | AA29: 547632 | AB29: 2C1 | AC29: = | AD29: 395533 | AE29: 3C1 | AF29: = | AG29: null | AH29: 4C1 | AI29: = | AJ29: null | AK29: 5C1 | AL29: = | AM29: null
A30: 140 | B30: 0 | C30: B | D30: 140 | E30: 0 | F30: B | G30: 140 | H30: 2 | I30: B | J30: 140 | K30: 0 | L30: B | M30: 140 | N30: 0 | O30: B | R30: BaseGame | S30: 5x | T30: = | U30: 154433 | V30: Pay | W30: = | X30: 447120600 | Y30: 1C1 | Z30: = | AA30: 64460 | AB30: 2C1 | AC30: = | AD30: 12463 | AE30: 3C1 | AF30: = | AG30: null | AH30: 4C1 | AI30: = | AJ30: null | AK30: 5C1 | AL30: = | AM30: null
A31: 160 | B31: 0 | C31: B | D31: 160 | E31: 0 | F31: B | G31: 160 | H31: 0 | I31: B | J31: 160 | K31: 0 | L31: B | M31: 160 | N31: 0 | O31: B | R31: BaseGame | S31: 9x | T31: = | U31: 763866 | V31: Pay | W31: = | X31: 3819330000 | Y31: 1C1 | Z31: = | AA31: 168486 | AB31: 2C1 | AC31: = | AD31: 88079 | AE31: 3C1 | AF31: = | AG31: null | AH31: 4C1 | AI31: = | AJ31: null | AK31: 5C1 | AL31: = | AM31: null
A32: 180 | B32: 0 | C32: B | D32: 180 | E32: 30 | F32: B | G32: 180 | H32: 51 | I32: B | J32: 180 | K32: 0 | L32: B | M32: 180 | N32: 45 | O32: B | R32: BaseGame | S32: 10x | T32: = | U32: 869364 | V32: Pay | W32: = | X32: 5266796600 | Y32: 1C1 | Z32: = | AA32: 220318 | AB32: 2C1 | AC32: = | AD32: 440883 | AE32: 3C1 | AF32: = | AG32: null | AH32: 4C1 | AI32: = | AJ32: null | AK32: 5C1 | AL32: = | AM32: null
A33: 200 | B33: 0 | C33: B | D33: 200 | E33: 15 | F33: B | G33: 200 | H33: 0 | I33: B | J33: 200 | K33: 0 | L33: B | M33: 200 | N33: 0 | O33: B | R33: BaseGame | S33: 15x | T33: = | U33: 431354 | V33: Pay | W33: = | X33: 3955755700 | Y33: 1C1 | Z33: = | AA33: 277720 | AB33: 2C1 | AC33: = | AD33: 37460 | AE33: 3C1 | AF33: = | AG33: null | AH33: 4C1 | AI33: = | AJ33: null | AK33: 5C1 | AL33: = | AM33: null
A34: 250 | B34: 0 | C34: B | D34: 250 | E34: 0 | F34: B | G34: 250 | H34: 0 | I34: B | J34: 250 | K34: 0 | L34: B | M34: 250 | N34: 0 | O34: B | R34: BaseGame | S34: 20x | T34: = | U34: 946060 | V34: Pay | W34: = | X34: 10166434700 | Y34: 1C1 | Z34: = | AA34: 213479 | AB34: 2C1 | AC34: = | AD34: 496752 | AE34: 3C1 | AF34: = | AG34: null | AH34: 4C1 | AI34: = | AJ34: null | AK34: 5C1 | AL34: = | AM34: null
A35: 300 | B35: 0 | C35: B | D35: 300 | E35: 5 | F35: B | G35: 300 | H35: 0 | I35: B | J35: 300 | K35: 0 | L35: B | M35: 300 | N35: 0 | O35: B | R35: BaseGame | S35: 25x | T35: = | U35: 255080 | V35: Pay | W35: = | X35: 3641477900 | Y35: 1C1 | Z35: = | AA35: 228780 | AB35: 2C1 | AC35: = | AD35: 26300 | AE35: 3C1 | AF35: = | AG35: null | AH35: 4C1 | AI35: = | AJ35: null | AK35: 5C1 | AL35: = | AM35: null
A36: 350 | B36: 0 | C36: B | D36: 350 | E36: 0 | F36: B | G36: 350 | H36: 0 | I36: B | J36: 350 | K36: 0 | L36: B | M36: 350 | N36: 0 | O36: B | R36: BaseGame | S36: 30x | T36: = | U36: 270974 | V36: Pay | W36: = | X36: 4241809500 | Y36: 1C1 | Z36: = | AA36: 164626 | AB36: 2C1 | AC36: = | AD36: 106348 | AE36: 3C1 | AF36: = | AG36: null | AH36: 4C1 | AI36: = | AJ36: null | AK36: 5C1 | AL36: = | AM36: null
A37: 400 | B37: 0 | C37: B | D37: 400 | E37: 0 | F37: B | G37: 400 | H37: 0 | I37: B | J37: 400 | K37: 0 | L37: B | M37: 400 | N37: 0 | O37: B | R37: BaseGame | S37: 45x | T37: = | U37: 827600 | V37: Pay | W37: = | X37: 20566450800 | Y37: 1C1 | Z37: = | AA37: 345980 | AB37: 2C1 | AC37: = | AD37: 4746 | AE37: 3C1 | AF37: = | AG37: null | AH37: 4C1 | AI37: = | AJ37: null | AK37: 5C1 | AL37: = | AM37: null
A38: 450 | B38: 2 | C38: B | D38: 450 | E38: 0 | F38: B | G38: 450 | H38: 0 | I38: B | J38: 450 | K38: 0 | L38: B | M38: 450 | N38: 0 | O38: B | R38: BaseGame | S38: 90x | T38: = | U38: 13756 | V38: Pay | W38: = | X38: 687800000 | Y38: 1C1 | Z38: = | AA38: 6183 | AB38: 2C1 | AC38: = | AD38: 355 | AE38: 3C1 | AF38: = | AG38: null | AH38: 4C1 | AI38: = | AJ38: null | AK38: 5C1 | AL38: = | AM38: null
A39: 500 | B39: 0 | C39: B | D39: 500 | E39: 5 | F39: B | G39: 500 | H39: 2 | I39: B | J39: 500 | K39: 10 | L39: B | M39: 500 | N39: 0 | O39: B | R39: BaseGame | S39: 100x | T39: = | U39: 6789 | V39: Pay | W39: = | X39: 358070200 | Y39: 1C1 | Z39: = | AA39: 2584 | AB39: 2C1 | AC39: = | AD39: 2017 | AE39: 3C1 | AF39: = | AG39: null | AH39: 4C1 | AI39: = | AJ39: null | AK39: 5C1 | AL39: = | AM39: null
A40: 550 | B40: 0 | C40: B | D40: 550 | E40: 0 | F40: B | G40: 550 | H40: 0 | I40: B | J40: 550 | K40: 0 | L40: B | M40: 550 | N40: 0 | O40: B | R40: BaseGame | S40: 180x | T40: = | U40: 2943 | V40: Pay | W40: = | X40: 294300000 | Y40: 1C1 | Z40: = | AA40: 2440 | AB40: 2C1 | AC40: = | AD40: 154 | AE40: 3C1 | AF40: = | AG40: null | AH40: 4C1 | AI40: = | AJ40: null | AK40: 5C1 | AL40: = | AM40: null
...

Sheet Card_Bet1
C1: Hit% | F1: Mul | R1: =SUM(R3:R54) -> 1.3796901 | V1: =SUM(V3:V54) -> 0.9199948 | AB1: =SUM(AB3:AB54) -> 1.3873502 | AF1: =SUM(AF3:AF54) -> 0.92485711
B2: Interval | C2: A | D2: B | E2: C | F2: A | G2: B | H2: C | J2: Index | K2: Interval | L2: Sheet | M2: Mul | N2: Avg Mul | O2: Hit%_tune | P2: Hit%_ori | Q2: Jili Hit% | R2: RTP_tune | T2: Hit%_Weight_Final | U2: Hit%_Final | V2: RTP_Final | Y2: Hit%_tune | Z2: Hit%_ori | AA2: Jili Hit% | AB2: RTP_tune | AD2: Hit%_Weight_Final | AE2: Hit%_Final | AF2: RTP_Final
B3: -1 | C3: {=_xlfn.IFNA( _xlfn._xlws.FILTER( Sim_Mul_Bet1!$F$2:$F$100, (Sim_Mul_Bet1!$A$2:$A$100=C$2) * (Sim_Mul_Bet1!$C$2:$C$100=$B3),0 ), 0 )} -> 0.79597221 | D3: {=_xlfn.IFNA( _xlfn._xlws.FILTER( Sim_Mul_Bet1!$F$2:$F$100, (Sim_Mul_Bet1!$A$2:$A$100=D$2) * (Sim_Mul_Bet1!$C$2:$C$100=$B3),0 ), 0 )} -> 0.22225457 | E3: {=_xlfn.IFNA( _xlfn._xlws.FILTER( Sim_Mul_Bet1!$F$2:$F$100, (Sim_Mul_Bet1!$A$2:$A$100=E$2) * (Sim_Mul_Bet1!$C$2:$C$100=$B3),0 ), 0 )} -> 0 | F3: {=_xlfn.IFNA( _xlfn._xlws.FILTER( Sim_Mul_Bet1!$L$2:$L$100, (Sim_Mul_Bet1!$A$2:$A$100=F$2) * (Sim_Mul_Bet1!$C$2:$C$100=$B3),0 ), 0 )} -> 0 | G3: {=_xlfn.IFNA( _xlfn._xlws.FILTER( Sim_Mul_Bet1!$L$2:$L$100, (Sim_Mul_Bet1!$A$2:$A$100=G$2) * (Sim_Mul_Bet1!$C$2:$C$100=$B3),0 ), 0 )} -> 0 | H3: {=_xlfn.IFNA( _xlfn._xlws.FILTER( Sim_Mul_Bet1!$L$2:$L$100, (Sim_Mul_Bet1!$A$2:$A$100=H$2) * (Sim_Mul_Bet1!$C$2:$C$100=$B3),0 ), 0 )} -> 0 | J3: 0 | K3: -1 | L3: A | M3: =HLOOKUP(L3,$C$2:$E$54,J3+2,FALSE) -> 0.79597221 | N3: =HLOOKUP(L3,$F$2:$H$54,J3+2,FALSE) -> 0 | O3: =1-SUM(O4:O53) -> 0.7917287 | P3: =1-SUM(P4:P53) -> 0.86115247 | Q3: =1-SUM(Q4:Q54) -> 0.85905995 | R3: =N3*O3 -> 0 | T3: =1000000-SUM(T4:T54) -> 791728 | U3: {=T3:T54/SUM($T$3:$T$54)} -> 0.791728 | V3: =U3*N3/1.5 -> 0 | Y3: =1-SUM(Y4:Y53) -> 0.82889058 | Z3: =1-SUM(Z4:Z53) -> 0.88592705 | AA3: =1-SUM(AA4:AA54) -> 0.85905995 | AB3: =N3*Y3 -> 0 | AD3: =1000000-SUM(AD4:AD54) -> 828891 | AE3: {=AD3:AD54/SUM($T$3:$T$54)} -> 0.828891 | AF3: =AE3*N3/1.5 -> 0
B4: 0 | C4: {=_xlfn.IFNA( _xlfn._xlws.FILTER( Sim_Mul_Bet1!$F$2:$F$100, (Sim_Mul_Bet1!$A$2:$A$100=C$2) * (Sim_Mul_Bet1!$C$2:$C$100=$B4),0 ), 0 )} -> 0.05778729 | D4: {=_xlfn.IFNA( _xlfn._xlws.FILTER( Sim_Mul_Bet1!$F$2:$F$100, (Sim_Mul_Bet1!$A$2:$A$100=D$2) * (Sim_Mul_Bet1!$C$2:$C$100=$B4),0 ), 0 )} -> 0.02778646 | E4: {=_xlfn.IFNA( _xlfn._xlws.FILTER( Sim_Mul_Bet1!$F$2:$F$100, (Sim_Mul_Bet1!$A$2:$A$100=E$2) * (Sim_Mul_Bet1!$C$2:$C$100=$B4),0 ), 0 )} -> 0 | F4: {=_xlfn.IFNA( _xlfn._xlws.FILTER( Sim_Mul_Bet1!$L$2:$L$100, (Sim_Mul_Bet1!$A$2:$A$100=F$2) * (Sim_Mul_Bet1!$C$2:$C$100=$B4),0 ), 0 )} -> 1 | G4: {=_xlfn.IFNA( _xlfn._xlws.FILTER( Sim_Mul_Bet1!$L$2:$L$100, (Sim_Mul_Bet1!$A$2:$A$100=G$2) * (Sim_Mul_Bet1!$C$2:$C$100=$B4),0 ), 0 )} -> 1 | H4: {=_xlfn.IFNA( _xlfn._xlws.FILTER( Sim_Mul_Bet1!$L$2:$L$100, (Sim_Mul_Bet1!$A$2:$A$100=H$2) * (Sim_Mul_Bet1!$C$2:$C$100=$B4),0 ), 0 )} -> 0 | J4: 1 | K4: 0 | L4: B | M4: =HLOOKUP(L4,$C$2:$E$54,J4+2,FALSE) -> 0.02778646 | N4: =HLOOKUP(L4,$F$2:$H$54,J4+2,FALSE) -> 1 | O4: =P4*1.5 -> 0.097570091 | P4: 0.065046727 | Q4: 0.065046727 | R4: =N4*O4 -> 0.097570091 | T4: =ROUND(O4*1000000,0) -> 97570 | U4: 0.09757 | V4: =U4*N4/1.5 -> 0.065046667 | Y4: =Z4*1.5 -> 0.075 | Z4: 0.05 | AA4: 0.065046727 | AB4: =N4*Y4 -> 0.075 | AD4: =ROUND(Y4*1000000,0) -> 75000 | AE4: 0.075 | AF4: =AE4*N4/1.5 -> 0.05
B5: 1 | C5: {=_xlfn.IFNA( _xlfn._xlws.FILTER( Sim_Mul_Bet1!$F$2:$F$100, (Sim_Mul_Bet1!$A$2:$A$100=C$2) * (Sim_Mul_Bet1!$C$2:$C$100=$B5),0 ), 0 )} -> 0.00506731 | D5: {=_xlfn.IFNA( _xlfn._xlws.FILTER( Sim_Mul_Bet1!$F$2:$F$100, (Sim_Mul_Bet1!$A$2:$A$100=D$2) * (Sim_Mul_Bet1!$C$2:$C$100=$B5),0 ), 0 )} -> 0.06946658 | E5: {=_xlfn.IFNA( _xlfn._xlws.FILTER( Sim_Mul_Bet1!$F$2:$F$100, (Sim_Mul_Bet1!$A$2:$A$100=E$2) * (Sim_Mul_Bet1!$C$2:$C$100=$B5),0 ), 0 )} -> 0 | F5: {=_xlfn.IFNA( _xlfn._xlws.FILTER( Sim_Mul_Bet1!$L$2:$L$100, (Sim_Mul_Bet1!$A$2:$A$100=F$2) * (Sim_Mul_Bet1!$C$2:$C$100=$B5),0 ), 0 )} -> 2 | G5: {=_xlfn.IFNA( _xlfn._xlws.FILTER( Sim_Mul_Bet1!$L$2:$L$100, (Sim_Mul_Bet1!$A$2:$A$100=G$2) * (Sim_Mul_Bet1!$C$2:$C$100=$B5),0 ), 0 )} -> 2 | H5: {=_xlfn.IFNA( _xlfn._xlws.FILTER( Sim_Mul_Bet1!$L$2:$L$100, (Sim_Mul_Bet1!$A$2:$A$100=H$2) * (Sim_Mul_Bet1!$C$2:$C$100=$B5),0 ), 0 )} -> 0 | J5: 2 | K5: 1 | L5: B | M5: =HLOOKUP(L5,$C$2:$E$54,J5+2,FALSE) -> 0.06946658 | N5: =HLOOKUP(L5,$F$2:$H$54,J5+2,FALSE) -> 2 | O5: =P5*1.5 -> 0.0015232701 | P5: 0.0010155134 | Q5: 0.0010155134 | R5: =N5*O5 -> 0.0030465402 | T5: =ROUND(O5*1000000,0) -> 1523 | U5: 0.001523 | V5: =U5*N5/1.5 -> 0.0020306667 | Y5: =Z5*1.5 -> 0.00045 | Z5: 0.0003 | AA5: 0.0010155134 | AB5: =N5*Y5 -> 0.0009 | AD5: =ROUND(Y5*1000000,0) -> 450 | AE5: 0.00045 | AF5: =AE5*N5/1.5 -> 0.0006
B6: 2 | C6: {=_xlfn.IFNA( _xlfn._xlws.FILTER( Sim_Mul_Bet1!$F$2:$F$100, (Sim_Mul_Bet1!$A$2:$A$100=C$2) * (Sim_Mul_Bet1!$C$2:$C$100=$B6),0 ), 0 )} -> 0 | D6: {=_xlfn.IFNA( _xlfn._xlws.FILTER( Sim_Mul_Bet1!$F$2:$F$100, (Sim_Mul_Bet1!$A$2:$A$100=D$2) * (Sim_Mul_Bet1!$C$2:$C$100=$B6),0 ), 0 )} -> 0 | E6: {=_xlfn.IFNA( _xlfn._xlws.FILTER( Sim_Mul_Bet1!$F$2:$F$100, (Sim_Mul_Bet1!$A$2:$A$100=E$2) * (Sim_Mul_Bet1!$C$2:$C$100=$B6),0 ), 0 )} -> 0 | F6: {=_xlfn.IFNA( _xlfn._xlws.FILTER( Sim_Mul_Bet1!$L$2:$L$100, (Sim_Mul_Bet1!$A$2:$A$100=F$2) * (Sim_Mul_Bet1!$C$2:$C$100=$B6),0 ), 0 )} -> 0 | G6: {=_xlfn.IFNA( _xlfn._xlws.FILTER( Sim_Mul_Bet1!$L$2:$L$100, (Sim_Mul_Bet1!$A$2:$A$100=G$2) * (Sim_Mul_Bet1!$C$2:$C$100=$B6),0 ), 0 )} -> 0 | H6: {=_xlfn.IFNA( _xlfn._xlws.FILTER( Sim_Mul_Bet1!$L$2:$L$100, (Sim_Mul_Bet1!$A$2:$A$100=H$2) * (Sim_Mul_Bet1!$C$2:$C$100=$B6),0 ), 0 )} -> 0 | J6: 3 | K6: 2 | L6: B | M6: =HLOOKUP(L6,$C$2:$E$54,J6+2,FALSE) -> 0 | N6: =HLOOKUP(L6,$F$2:$H$54,J6+2,FALSE) -> 0 | O6: =P6*1.5 -> 0 | P6: 0 | Q6: 0 | R6: =N6*O6 -> 0 | T6: =ROUND(O6*1000000,0) -> 0 | U6: 0 | V6: =U6*N6/1.5 -> 0 | Y6: =Z6*1.5 -> 0 | Z6: 0 | AA6: 0 | AB6: =N6*Y6 -> 0 | AD6: =ROUND(Y6*1000000,0) -> 0 | AE6: 0 | AF6: =AE6*N6/1.5 -> 0
B7: 3 | C7: {=_xlfn.IFNA( _xlfn._xlws.FILTER( Sim_Mul_Bet1!$F$2:$F$100, (Sim_Mul_Bet1!$A$2:$A$100=C$2) * (Sim_Mul_Bet1!$C$2:$C$100=$B7),0 ), 0 )} -> 0 | D7: {=_xlfn.IFNA( _xlfn._xlws.FILTER( Sim_Mul_Bet1!$F$2:$F$100, (Sim_Mul_Bet1!$A$2:$A$100=D$2) * (Sim_Mul_Bet1!$C$2:$C$100=$B7),0 ), 0 )} -> 0 | E7: {=_xlfn.IFNA( _xlfn._xlws.FILTER( Sim_Mul_Bet1!$F$2:$F$100, (Sim_Mul_Bet1!$A$2:$A$100=E$2) * (Sim_Mul_Bet1!$C$2:$C$100=$B7),0 ), 0 )} -> 0 | F7: {=_xlfn.IFNA( _xlfn._xlws.FILTER( Sim_Mul_Bet1!$L$2:$L$100, (Sim_Mul_Bet1!$A$2:$A$100=F$2) * (Sim_Mul_Bet1!$C$2:$C$100=$B7),0 ), 0 )} -> 0 | G7: {=_xlfn.IFNA( _xlfn._xlws.FILTER( Sim_Mul_Bet1!$L$2:$L$100, (Sim_Mul_Bet1!$A$2:$A$100=G$2) * (Sim_Mul_Bet1!$C$2:$C$100=$B7),0 ), 0 )} -> 0 | H7: {=_xlfn.IFNA( _xlfn._xlws.FILTER( Sim_Mul_Bet1!$L$2:$L$100, (Sim_Mul_Bet1!$A$2:$A$100=H$2) * (Sim_Mul_Bet1!$C$2:$C$100=$B7),0 ), 0 )} -> 0 | J7: 4 | K7: 3 | L7: B | M7: =HLOOKUP(L7,$C$2:$E$54,J7+2,FALSE) -> 0 | N7: =HLOOKUP(L7,$F$2:$H$54,J7+2,FALSE) -> 0 | O7: =P7*1.5 -> 0 | P7: 0 | Q7: 0 | R7: =N7*O7 -> 0 | T7: =ROUND(O7*1000000,0) -> 0 | U7: 0 | V7: =U7*N7/1.5 -> 0 | Y7: =Z7*1.5 -> 0 | Z7: 0 | AA7: 0 | AB7: =N7*Y7 -> 0 | AD7: =ROUND(Y7*1000000,0) -> 0 | AE7: 0 | AF7: =AE7*N7/1.5 -> 0
B8: 4 | C8: {=_xlfn.IFNA( _xlfn._xlws.FILTER( Sim_Mul_Bet1!$F$2:$F$100, (Sim_Mul_Bet1!$A$2:$A$100=C$2) * (Sim_Mul_Bet1!$C$2:$C$100=$B8),0 ), 0 )} -> 0.07348217 | D8: {=_xlfn.IFNA( _xlfn._xlws.FILTER( Sim_Mul_Bet1!$F$2:$F$100, (Sim_Mul_Bet1!$A$2:$A$100=D$2) * (Sim_Mul_Bet1!$C$2:$C$100=$B8),0 ), 0 )} -> 0.08329281 | E8: {=_xlfn.IFNA( _xlfn._xlws.FILTER( Sim_Mul_Bet1!$F$2:$F$100, (Sim_Mul_Bet1!$A$2:$A$100=E$2) * (Sim_Mul_Bet1!$C$2:$C$100=$B8),0 ), 0 )} -> 0 | F8: {=_xlfn.IFNA( _xlfn._xlws.FILTER( Sim_Mul_Bet1!$L$2:$L$100, (Sim_Mul_Bet1!$A$2:$A$100=F$2) * (Sim_Mul_Bet1!$C$2:$C$100=$B8),0 ), 0 )} -> 5 | G8: {=_xlfn.IFNA( _xlfn._xlws.FILTER( Sim_Mul_Bet1!$L$2:$L$100, (Sim_Mul_Bet1!$A$2:$A$100=G$2) * (Sim_Mul_Bet1!$C$2:$C$100=$B8),0 ), 0 )} -> 5 | H8: {=_xlfn.IFNA( _xlfn._xlws.FILTER( Sim_Mul_Bet1!$L$2:$L$100, (Sim_Mul_Bet1!$A$2:$A$100=H$2) * (Sim_Mul_Bet1!$C$2:$C$100=$B8),0 ), 0 )} -> 0 | J8: 5 | K8: 4 | L8: B | M8: =HLOOKUP(L8,$C$2:$E$54,J8+2,FALSE) -> 0.08329281 | N8: =HLOOKUP(L8,$F$2:$H$54,J8+2,FALSE) -> 5 | O8: =P8*1.5 -> 0.064244375 | P8: 0.042829583 | Q8: 0.042829583 | R8: =N8*O8 -> 0.32122187 | T8: =ROUND(O8*1000000,0) -> 64244 | U8: 0.064244 | V8: =U8*N8/1.5 -> 0.21414667 | Y8: =Z8*1.5 -> 0.0375 | Z8: 0.025 | AA8: 0.042829583 | AB8: =N8*Y8 -> 0.1875 | AD8: =ROUND(Y8*1000000,0) -> 37500 | AE8: 0.0375 | AF8: =AE8*N8/1.5 -> 0.125
B9: 5 | C9: {=_xlfn.IFNA( _xlfn._xlws.FILTER( Sim_Mul_Bet1!$F$2:$F$100, (Sim_Mul_Bet1!$A$2:$A$100=C$2) * (Sim_Mul_Bet1!$C$2:$C$100=$B9),0 ), 0 )} -> 0.0007927 | D9: {=_xlfn.IFNA( _xlfn._xlws.FILTER( Sim_Mul_Bet1!$F$2:$F$100, (Sim_Mul_Bet1!$A$2:$A$100=D$2) * (Sim_Mul_Bet1!$C$2:$C$100=$B9),0 ), 0 )} -> 0.02778618 | E9: {=_xlfn.IFNA( _xlfn._xlws.FILTER( Sim_Mul_Bet1!$F$2:$F$100, (Sim_Mul_Bet1!$A$2:$A$100=E$2) * (Sim_Mul_Bet1!$C$2:$C$100=$B9),0 ), 0 )} -> 0 | F9: {=_xlfn.IFNA( _xlfn._xlws.FILTER( Sim_Mul_Bet1!$L$2:$L$100, (Sim_Mul_Bet1!$A$2:$A$100=F$2) * (Sim_Mul_Bet1!$C$2:$C$100=$B9),0 ), 0 )} -> 6 | G9: {=_xlfn.IFNA( _xlfn._xlws.FILTER( Sim_Mul_Bet1!$L$2:$L$100, (Sim_Mul_Bet1!$A$2:$A$100=G$2) * (Sim_Mul_Bet1!$C$2:$C$100=$B9),0 ), 0 )} -> 6 | H9: {=_xlfn.IFNA( _xlfn._xlws.FILTER( Sim_Mul_Bet1!$L$2:$L$100, (Sim_Mul_Bet1!$A$2:$A$100=H$2) * (Sim_Mul_Bet1!$C$2:$C$100=$B9),0 ), 0 )} -> 0 | J9: 6 | K9: 5 | L9: B | M9: =HLOOKUP(L9,$C$2:$E$54,J9+2,FALSE) -> 0.02778618 | N9: =HLOOKUP(L9,$F$2:$H$54,J9+2,FALSE) -> 6 | O9: =P9*1.5 -> 0.0017290662 | P9: 0.0011527108 | Q9: 0.0011527108 | R9: =N9*O9 -> 0.010374397 | T9: =ROUND(O9*1000000,0) -> 1729 | U9: 0.001729 | V9: =U9*N9/1.5 -> 0.006916 | Y9: =Z9*1.5 -> 0 | Z9: 0 | AA9: 0.0011527108 | AB9: =N9*Y9 -> 0 | AD9: =ROUND(Y9*1000000,0) -> 0 | AE9: 0 | AF9: =AE9*N9/1.5 -> 0
B10: 6 | C10: {=_xlfn.IFNA( _xlfn._xlws.FILTER( Sim_Mul_Bet1!$F$2:$F$100, (Sim_Mul_Bet1!$A$2:$A$100=C$2) * (Sim_Mul_Bet1!$C$2:$C$100=$B10),0 ), 0 )} -> 0 | D10: {=_xlfn.IFNA( _xlfn._xlws.FILTER( Sim_Mul_Bet1!$F$2:$F$100, (Sim_Mul_Bet1!$A$2:$A$100=D$2) * (Sim_Mul_Bet1!$C$2:$C$100=$B10),0 ), 0 )} -> 0 | E10: {=_xlfn.IFNA( _xlfn._xlws.FILTER( Sim_Mul_Bet1!$F$2:$F$100, (Sim_Mul_Bet1!$A$2:$A$100=E$2) * (Sim_Mul_Bet1!$C$2:$C$100=$B10),0 ), 0 )} -> 0 | F10: {=_xlfn.IFNA( _xlfn._xlws.FILTER( Sim_Mul_Bet1!$L$2:$L$100, (Sim_Mul_Bet1!$A$2:$A$100=F$2) * (Sim_Mul_Bet1!$C$2:$C$100=$B10),0 ), 0 )} -> 0 | G10: {=_xlfn.IFNA( _xlfn._xlws.FILTER( Sim_Mul_Bet1!$L$2:$L$100, (Sim_Mul_Bet1!$A$2:$A$100=G$2) * (Sim_Mul_Bet1!$C$2:$C$100=$B10),0 ), 0 )} -> 0 | H10: {=_xlfn.IFNA( _xlfn._xlws.FILTER( Sim_Mul_Bet1!$L$2:$L$100, (Sim_Mul_Bet1!$A$2:$A$100=H$2) * (Sim_Mul_Bet1!$C$2:$C$100=$B10),0 ), 0 )} -> 0 | J10: 7 | K10: 6 | L10: B | M10: =HLOOKUP(L10,$C$2:$E$54,J10+2,FALSE) -> 0 | N10: =HLOOKUP(L10,$F$2:$H$54,J10+2,FALSE) -> 0 | O10: =P10*1.5 -> 0 | P10: 0 | Q10: 0 | R10: =N10*O10 -> 0 | T10: =ROUND(O10*1000000,0) -> 0 | U10: 0 | V10: =U10*N10/1.5 -> 0 | Y10: =Z10*1.5 -> 0 | Z10: 0 | AA10: 0 | AB10: =N10*Y10 -> 0 | AD10: =ROUND(Y10*1000000,0) -> 0 | AE10: 0 | AF10: =AE10*N10/1.5 -> 0
B11: 7 | C11: {=_xlfn.IFNA( _xlfn._xlws.FILTER( Sim_Mul_Bet1!$F$2:$F$100, (Sim_Mul_Bet1!$A$2:$A$100=C$2) * (Sim_Mul_Bet1!$C$2:$C$100=$B11),0 ), 0 )} -> 0 | D11: {=_xlfn.IFNA( _xlfn._xlws.FILTER( Sim_Mul_Bet1!$F$2:$F$100, (Sim_Mul_Bet1!$A$2:$A$100=D$2) * (Sim_Mul_Bet1!$C$2:$C$100=$B11),0 ), 0 )} -> 0 | E11: {=_xlfn.IFNA( _xlfn._xlws.FILTER( Sim_Mul_Bet1!$F$2:$F$100, (Sim_Mul_Bet1!$A$2:$A$100=E$2) * (Sim_Mul_Bet1!$C$2:$C$100=$B11),0 ), 0 )} -> 0 | F11: {=_xlfn.IFNA( _xlfn._xlws.FILTER( Sim_Mul_Bet1!$L$2:$L$100, (Sim_Mul_Bet1!$A$2:$A$100=F$2) * (Sim_Mul_Bet1!$C$2:$C$100=$B11),0 ), 0 )} -> 0 | G11: {=_xlfn.IFNA( _xlfn._xlws.FILTER( Sim_Mul_Bet1!$L$2:$L$100, (Sim_Mul_Bet1!$A$2:$A$100=G$2) * (Sim_Mul_Bet1!$C$2:$C$100=$B11),0 ), 0 )} -> 0 | H11: {=_xlfn.IFNA( _xlfn._xlws.FILTER( Sim_Mul_Bet1!$L$2:$L$100, (Sim_Mul_Bet1!$A$2:$A$100=H$2) * (Sim_Mul_Bet1!$C$2:$C$100=$B11),0 ), 0 )} -> 0 | J11: 8 | K11: 7 | L11: B | M11: =HLOOKUP(L11,$C$2:$E$54,J11+2,FALSE) -> 0 | N11: =HLOOKUP(L11,$F$2:$H$54,J11+2,FALSE) -> 0 | O11: =P11*1.5 -> 0 | P11: 0 | Q11: 0 | R11: =N11*O11 -> 0 | T11: =ROUND(O11*1000000,0) -> 0 | U11: 0 | V11: =U11*N11/1.5 -> 0 | Y11: =Z11*1.5 -> 0 | Z11: 0 | AA11: 0 | AB11: =N11*Y11 -> 0 | AD11: =ROUND(Y11*1000000,0) -> 0 | AE11: 0 | AF11: =AE11*N11/1.5 -> 0
B12: 8 | C12: {=_xlfn.IFNA( _xlfn._xlws.FILTER( Sim_Mul_Bet1!$F$2:$F$100, (Sim_Mul_Bet1!$A$2:$A$100=C$2) * (Sim_Mul_Bet1!$C$2:$C$100=$B12),0 ), 0 )} -> 0 | D12: {=_xlfn.IFNA( _xlfn._xlws.FILTER( Sim_Mul_Bet1!$F$2:$F$100, (Sim_Mul_Bet1!$A$2:$A$100=D$2) * (Sim_Mul_Bet1!$C$2:$C$100=$B12),0 ), 0 )} -> 0 | E12: {=_xlfn.IFNA( _xlfn._xlws.FILTER( Sim_Mul_Bet1!$F$2:$F$100, (Sim_Mul_Bet1!$A$2:$A$100=E$2) * (Sim_Mul_Bet1!$C$2:$C$100=$B12),0 ), 0 )} -> 0 | F12: {=_xlfn.IFNA( _xlfn._xlws.FILTER( Sim_Mul_Bet1!$L$2:$L$100, (Sim_Mul_Bet1!$A$2:$A$100=F$2) * (Sim_Mul_Bet1!$C$2:$C$100=$B12),0 ), 0 )} -> 0 | G12: {=_xlfn.IFNA( _xlfn._xlws.FILTER( Sim_Mul_Bet1!$L$2:$L$100, (Sim_Mul_Bet1!$A$2:$A$100=G$2) * (Sim_Mul_Bet1!$C$2:$C$100=$B12),0 ), 0 )} -> 0 | H12: {=_xlfn.IFNA( _xlfn._xlws.FILTER( Sim_Mul_Bet1!$L$2:$L$100, (Sim_Mul_Bet1!$A$2:$A$100=H$2) * (Sim_Mul_Bet1!$C$2:$C$100=$B12),0 ), 0 )} -> 0 | J12: 9 | K12: 8 | L12: B | M12: =HLOOKUP(L12,$C$2:$E$54,J12+2,FALSE) -> 0 | N12: =HLOOKUP(L12,$F$2:$H$54,J12+2,FALSE) -> 0 | O12: =P12*1.5 -> 0 | P12: 0 | Q12: 0 | R12: =N12*O12 -> 0 | T12: =ROUND(O12*1000000,0) -> 0 | U12: 0 | V12: =U12*N12/1.5 -> 0 | Y12: =Z12*1.5 -> 0 | Z12: 0 | AA12: 0 | AB12: =N12*Y12 -> 0 | AD12: =ROUND(Y12*1000000,0) -> 0 | AE12: 0 | AF12: =AE12*N12/1.5 -> 0
B13: 9 | C13: {=_xlfn.IFNA( _xlfn._xlws.FILTER( Sim_Mul_Bet1!$F$2:$F$100, (Sim_Mul_Bet1!$A$2:$A$100=C$2) * (Sim_Mul_Bet1!$C$2:$C$100=$B13),0 ), 0 )} -> 0.05260601 | D13: {=_xlfn.IFNA( _xlfn._xlws.FILTER( Sim_Mul_Bet1!$F$2:$F$100, (Sim_Mul_Bet1!$A$2:$A$100=D$2) * (Sim_Mul_Bet1!$C$2:$C$100=$B13),0 ), 0 )} -> 0.08799973 | E13: {=_xlfn.IFNA( _xlfn._xlws.FILTER( Sim_Mul_Bet1!$F$2:$F$100, (Sim_Mul_Bet1!$A$2:$A$100=E$2) * (Sim_Mul_Bet1!$C$2:$C$100=$B13),0 ), 0 )} -> 0 | F13: {=_xlfn.IFNA( _xlfn._xlws.FILTER( Sim_Mul_Bet1!$L$2:$L$100, (Sim_Mul_Bet1!$A$2:$A$100=F$2) * (Sim_Mul_Bet1!$C$2:$C$100=$B13),0 ), 0 )} -> 10 | G13: {=_xlfn.IFNA( _xlfn._xlws.FILTER( Sim_Mul_Bet1!$L$2:$L$100, (Sim_Mul_Bet1!$A$2:$A$100=G$2) * (Sim_Mul_Bet1!$C$2:$C$100=$B13),0 ), 0 )} -> 10 | H13: {=_xlfn.IFNA( _xlfn._xlws.FILTER( Sim_Mul_Bet1!$L$2:$L$100, (Sim_Mul_Bet1!$A$2:$A$100=H$2) * (Sim_Mul_Bet1!$C$2:$C$100=$B13),0 ), 0 )} -> 0 | J13: 10 | K13: 9 | L13: B | M13: =HLOOKUP(L13,$C$2:$E$54,J13+2,FALSE) -> 0.08799973 | N13: =HLOOKUP(L13,$F$2:$H$54,J13+2,FALSE) -> 10 | O13: =P13*1.5 -> 0.0140055 | P13: 0.009337 | Q13: 0.0084216489 | R13: =N13*O13 -> 0.140055 | T13: =ROUND(O13*1000000,0) -> 14006 | U13: 0.014006 | V13: =U13*N13/1.5 -> 0.093373333 | Y13: =Z13*1.5 -> 0.03 | Z13: 0.02 | AA13: 0.0084216489 | AB13: =N13*Y13 -> 0.3 | AD13: =ROUND(Y13*1000000,0) -> 30000 | AE13: 0.03 | AF13: =AE13*N13/1.5 -> 0.2
B14: 10 | C14: {=_xlfn.IFNA( _xlfn._xlws.FILTER( Sim_Mul_Bet1!$F$2:$F$100, (Sim_Mul_Bet1!$A$2:$A$100=C$2) * (Sim_Mul_Bet1!$C$2:$C$100=$B14),0 ), 0 )} -> 0.00344485 | D14: {=_xlfn.IFNA( _xlfn._xlws.FILTER( Sim_Mul_Bet1!$F$2:$F$100, (Sim_Mul_Bet1!$A$2:$A$100=D$2) * (Sim_Mul_Bet1!$C$2:$C$100=$B14),0 ), 0 )} -> 0.05091928 | E14: {=_xlfn.IFNA( _xlfn._xlws.FILTER( Sim_Mul_Bet1!$F$2:$F$100, (Sim_Mul_Bet1!$A$2:$A$100=E$2) * (Sim_Mul_Bet1!$C$2:$C$100=$B14),0 ), 0 )} -> 0 | F14: {=_xlfn.IFNA( _xlfn._xlws.FILTER( Sim_Mul_Bet1!$L$2:$L$100, (Sim_Mul_Bet1!$A$2:$A$100=F$2) * (Sim_Mul_Bet1!$C$2:$C$100=$B14),0 ), 0 )} -> 12.127477 | G14: {=_xlfn.IFNA( _xlfn._xlws.FILTER( Sim_Mul_Bet1!$L$2:$L$100, (Sim_Mul_Bet1!$A$2:$A$100=G$2) * (Sim_Mul_Bet1!$C$2:$C$100=$B14),0 ), 0 )} -> 12.9095 | H14: {=_xlfn.IFNA( _xlfn._xlws.FILTER( Sim_Mul_Bet1!$L$2:$L$100, (Sim_Mul_Bet1!$A$2:$A$100=H$2) * (Sim_Mul_Bet1!$C$2:$C$100=$B14),0 ), 0 )} -> 0 | J14: 11 | K14: 10 | L14: B | M14: =HLOOKUP(L14,$C$2:$E$54,J14+2,FALSE) -> 0.05091928 | N14: =HLOOKUP(L14,$F$2:$H$54,J14+2,FALSE) -> 12.9095 | O14: =P14*1.5 -> 0.0075 | P14: 0.005 | Q14: 0.0061793549 | R14: =N14*O14 -> 0.096821249 | T14: =ROUND(O14*1000000,0) -> 7500 | U14: 0.0075 | V14: =U14*N14/1.5 -> 0.064547499 | Y14: =Z14*1.5 -> 0.0015 | Z14: 0.001 | AA14: 0.0061793549 | AB14: =N14*Y14 -> 0.01936425 | AD14: =ROUND(Y14*1000000,0) -> 1500 | AE14: 0.0015 | AF14: =AE14*N14/1.5 -> 0.0129095
B15: 15 | C15: {=_xlfn.IFNA( _xlfn._xlws.FILTER( Sim_Mul_Bet1!$F$2:$F$100, (Sim_Mul_Bet1!$A$2:$A$100=C$2) * (Sim_Mul_Bet1!$C$2:$C$100=$B15),0 ), 0 )} -> 0.00336342 | D15: {=_xlfn.IFNA( _xlfn._xlws.FILTER( Sim_Mul_Bet1!$F$2:$F$100, (Sim_Mul_Bet1!$A$2:$A$100=D$2) * (Sim_Mul_Bet1!$C$2:$C$100=$B15),0 ), 0 )} -> 0.05708653 | E15: {=_xlfn.IFNA( _xlfn._xlws.FILTER( Sim_Mul_Bet1!$F$2:$F$100, (Sim_Mul_Bet1!$A$2:$A$100=E$2) * (Sim_Mul_Bet1!$C$2:$C$100=$B15),0 ), 0 )} -> 0 | F15: {=_xlfn.IFNA( _xlfn._xlws.FILTER( Sim_Mul_Bet1!$L$2:$L$100, (Sim_Mul_Bet1!$A$2:$A$100=F$2) * (Sim_Mul_Bet1!$C$2:$C$100=$B15),0 ), 0 )} -> 19.963478 | G15: {=_xlfn.IFNA( _xlfn._xlws.FILTER( Sim_Mul_Bet1!$L$2:$L$100, (Sim_Mul_Bet1!$A$2:$A$100=G$2) * (Sim_Mul_Bet1!$C$2:$C$100=$B15),0 ), 0 )} -> 19.351528 | H15: {=_xlfn.IFNA( _xlfn._xlws.FILTER( Sim_Mul_Bet1!$L$2:$L$100, (Sim_Mul_Bet1!$A$2:$A$100=H$2) * (Sim_Mul_Bet1!$C$2:$C$100=$B15),0 ), 0 )} -> 0 | J15: 12 | K15: 15 | L15: B | M15: =HLOOKUP(L15,$C$2:$E$54,J15+2,FALSE) -> 0.05708653 | N15: =HLOOKUP(L15,$F$2:$H$54,J15+2,FALSE) -> 19.351528 | O15: =P15*1.5 -> 0.0075 | P15: 0.005 | Q15: 0.0059882886 | R15: =N15*O15 -> 0.14513646 | T15: =ROUND(O15*1000000,0) -> 7500 | U15: 0.0075 | V15: =U15*N15/1.5 -> 0.096757641 | Y15: =Z15*1.5 -> 0.018 | Z15: 0.012 | AA15: 0.0059882886 | AB15: =N15*Y15 -> 0.34832751 | AD15: =ROUND(Y15*1000000,0) -> 18000 | AE15: 0.018 | AF15: =AE15*N15/1.5 -> 0.23221834
... B54: 7000 | C54: {=_xlfn.IFNA( _xlfn._xlws.FILTER( Sim_Mul_Bet1!$F$2:$F$100, (Sim_Mul_Bet1!$A$2:$A$100=C$2) * (Sim_Mul_Bet1!$C$2:$C$100=$B54),0 ), 0 )} -> 0 | D54: {=_xlfn.IFNA( _xlfn._xlws.FILTER( Sim_Mul_Bet1!$F$2:$F$100, (Sim_Mul_Bet1!$A$2:$A$100=D$2) * (Sim_Mul_Bet1!$C$2:$C$100=$B54),0 ), 0 )} -> 0 | E54: {=_xlfn.IFNA( _xlfn._xlws.FILTER( Sim_Mul_Bet1!$F$2:$F$100, (Sim_Mul_Bet1!$A$2:$A$100=E$2) * (Sim_Mul_Bet1!$C$2:$C$100=$B54),0 ), 0 )} -> 0 | F54: {=_xlfn.IFNA( _xlfn._xlws.FILTER( Sim_Mul_Bet1!$L$2:$L$100, (Sim_Mul_Bet1!$A$2:$A$100=F$2) * (Sim_Mul_Bet1!$C$2:$C$100=$B54),0 ), 0 )} -> 0 | G54: {=_xlfn.IFNA( _xlfn._xlws.FILTER( Sim_Mul_Bet1!$L$2:$L$100, (Sim_Mul_Bet1!$A$2:$A$100=G$2) * (Sim_Mul_Bet1!$C$2:$C$100=$B54),0 ), 0 )} -> 0 | H54: {=_xlfn.IFNA( _xlfn._xlws.FILTER( Sim_Mul_Bet1!$L$2:$L$100, (Sim_Mul_Bet1!$A$2:$A$100=H$2) * (Sim_Mul_Bet1!$C$2:$C$100=$B54),0 ), 0 )} -> 0 | J54: 51 | K54: 7000 | L54: B | M54: =HLOOKUP(L54,$C$2:$E$54,J54+2,FALSE) -> 0 | N54: =HLOOKUP(L54,$F$2:$H$54,J54+2,FALSE) -> 0 | O54: =P54*1.5 -> 0 | P54: 0 | Q54: 0 | R54: =N54*O54 -> 0 | T54: =ROUND(O54*1000000,0) -> 0 | U54: 0 | V54: =U54*N54/1.5 -> 0 | Y54: =Z54*1.5 -> 0 | Z54: 0 | AA54: 0 | AB54: =N54*Y54 -> 0 | AD54: =ROUND(Y54*1000000,0) -> 0 | AE54: 0 | AF54: =AE54*N54/1.5 -> 0

Sheet Sim_Mul_Bet1
F1: Hit% | L1: 1
A2: A | B2: BaseGame | C2: -1 | D2: = | E2: 79597221 | F2: {=E2:E18/SUM(E2:E18)} -> 0.79597221
A3: A | B3: BaseGame | C3: 0 | D3: = | E3: 5778729 | F3: 0.05778729 | H3: Pay | I3: = | J3: 577872900 | L3: =J3/E3/100/$L$1 -> 1 | O3: 1C1 | P3: = | Q3: null | R3: 2C1 | S3: = | T3: 5778729 | U3: 3C1 | V3: = | W3: null | X3: 4C1 | Y3: = | Z3: null | AA3: 5C1 | AB3: = | AC3: null
A4: A | B4: BaseGame | C4: 1 | D4: = | E4: 506731 | F4: 0.00506731 | H4: Pay | I4: = | J4: 101346200 | L4: =J4/E4/100/$L$1 -> 2 | O4: 1C1 | P4: = | Q4: null | R4: 2C1 | S4: = | T4: 134795 | U4: 3C1 | V4: = | W4: null | X4: 4C1 | Y4: = | Z4: null | AA4: 5C1 | AB4: = | AC4: null
A5: A | B5: BaseGame | C5: 4 | D5: = | E5: 7348217 | F5: 0.07348217 | H5: Pay | I5: = | J5: 3674108500 | L5: =J5/E5/100/$L$1 -> 5 | O5: 1C1 | P5: = | Q5: null | R5: 2C1 | S5: = | T5: 1673259 | U5: 3C1 | V5: = | W5: null | X5: 4C1 | Y5: = | Z5: null | AA5: 5C1 | AB5: = | AC5: null
A6: A | B6: BaseGame | C6: 5 | D6: = | E6: 79270 | F6: 0.0007927 | H6: Pay | I6: = | J6: 47562000 | L6: =J6/E6/100/$L$1 -> 6 | O6: 1C1 | P6: = | Q6: null | R6: 2C1 | S6: = | T6: 79270 | U6: 3C1 | V6: = | W6: null | X6: 4C1 | Y6: = | Z6: null | AA6: 5C1 | AB6: = | AC6: null
A7: A | B7: BaseGame | C7: 9 | D7: = | E7: 5260601 | F7: 0.05260601 | H7: Pay | I7: = | J7: 5260601000 | L7: =J7/E7/100/$L$1 -> 10 | O7: 1C1 | P7: = | Q7: null | R7: 2C1 | S7: = | T7: 4137078 | U7: 3C1 | V7: = | W7: null | X7: 4C1 | Y7: = | Z7: null | AA7: 5C1 | AB7: = | AC7: null
A8: A | B8: BaseGame | C8: 10 | D8: = | E8: 344485 | F8: 0.00344485 | H8: Pay | I8: = | J8: 417773400 | L8: =J8/E8/100/$L$1 -> 12.127477 | O8: 1C1 | P8: = | Q8: null | R8: 2C1 | S8: = | T8: 344485 | U8: 3C1 | V8: = | W8: null | X8: 4C1 | Y8: = | Z8: null | AA8: 5C1 | AB8: = | AC8: null
A9: A | B9: BaseGame | C9: 15 | D9: = | E9: 336342 | F9: 0.00336342 | H9: Pay | I9: = | J9: 671455600 | L9: =J9/E9/100/$L$1 -> 19.963478 | O9: 1C1 | P9: = | Q9: null | R9: 2C1 | S9: = | T9: 9736 | U9: 3C1 | V9: = | W9: null | X9: 4C1 | Y9: = | Z9: null | AA9: 5C1 | AB9: = | AC9: null
A10: A | B10: BaseGame | C10: 20 | D10: = | E10: 432671 | F10: 0.00432671 | H10: Pay | I10: = | J10: 1066968700 | L10: =J10/E10/100/$L$1 -> 24.660047 | O10: 1C1 | P10: = | Q10: null | R10: 2C1 | S10: = | T10: 1529 | U10: 3C1 | V10: = | W10: null | X10: 4C1 | Y10: = | Z10: null | AA10: 5C1 | AB10: = | AC10: null
A11: A | B11: BaseGame | C11: 25 | D11: = | E11: 21366 | F11: 0.00021366 | H11: Pay | I11: = | J11: 64087200 | L11: =J11/E11/100/$L$1 -> 29.994945 | O11: 1C1 | P11: = | Q11: null | R11: 2C1 | S11: = | T11: 30 | U11: 3C1 | V11: = | W11: null | X11: 4C1 | Y11: = | Z11: null | AA11: 5C1 | AB11: = | AC11: null
A12: A | B12: BaseGame | C12: 45 | D12: = | E12: 174124 | F12: 0.00174124 | H12: Pay | I12: = | J12: 870620000 | L12: =J12/E12/100/$L$1 -> 50 | O12: 1C1 | P12: = | Q12: null | R12: 2C1 | S12: = | T12: 115195 | U12: 3C1 | V12: = | W12: null | X12: 4C1 | Y12: = | Z12: null | AA12: 5C1 | AB12: = | AC12: null
A13: A | B13: BaseGame | C13: 50 | D13: = | E13: 53310 | F13: 0.0005331 | H13: Pay | I13: = | J13: 281634900 | L13: =J13/E13/100/$L$1 -> 52.829657 | O13: 1C1 | P13: = | Q13: null | R13: 2C1 | S13: = | T13: 44823 | U13: 3C1 | V13: = | W13: null | X13: 4C1 | Y13: = | Z13: null | AA13: 5C1 | AB13: = | AC13: null
A14: A | B14: BaseGame | C14: 60 | D14: = | E14: 241 | F14: 2.41e-06 | H14: Pay | I14: = | J14: 1502700 | L14: =J14/E14/100/$L$1 -> 62.352697 | O14: 1C1 | P14: = | Q14: null | R14: 2C1 | S14: = | T14: 241 | U14: 3C1 | V14: = | W14: null | X14: 4C1 | Y14: = | Z14: null | AA14: 5C1 | AB14: = | AC14: null
... A16: A | B16: BaseGame | C16: 100 | D16: = | E16: 14816 | F16: 0.00014816 | H16: Pay | I16: = | J16: 154137500 | L16: =J16/E16/100/$L$1 -> 104.03449 | O16: 1C1 | P16: = | Q16: null | R16: 2C1 | S16: = | T16: 1415 | U16: 3C1 | V16: = | W16: null | X16: 4C1 | Y16: = | Z16: null | AA16: 5C1 | AB16: = | AC16: null
A17: A | B17: BaseGame | C17: 450 | D17: = | E17: 1735 | F17: 1.735e-05 | H17: Pay | I17: = | J17: 86750000 | L17: =J17/E17/100/$L$1 -> 500 | O17: 1C1 | P17: = | Q17: null | R17: 2C1 | S17: = | T17: null | U17: 3C1 | V17: = | W17: null | X17: 4C1 | Y17: = | Z17: null | AA17: 5C1 | AB17: = | AC17: null
A18: A | B18: BaseGame | C18: 500 | D18: = | E18: 517 | F18: 5.17e-06 | H18: Pay | I18: = | J18: 26408500 | L18: =J18/E18/100/$L$1 -> 510.80271 | O18: 1C1 | P18: = | Q18: null | R18: 2C1 | S18: = | T18: null | U18: 3C1 | V18: = | W18: null | X18: 4C1 | Y18: = | Z18: null | AA18: 5C1 | AB18: = | AC18: null
A21: B | B21: BaseGame | C21: -1 | D21: = | E21: 22225457 | F21: {=E21:E42/SUM(E21:E42)} -> 0.22225457
A22: B | B22: BaseGame | C22: 0 | D22: = | E22: 2778646 | F22: 0.02778646 | H22: Pay | I22: = | J22: 277864600 | L22: =J22/E22/100/$L$1 -> 1 | O22: 1C1 | P22: = | Q22: null | R22: 2C1 | S22: = | T22: 2778646 | U22: 3C1 | V22: = | W22: null | X22: 4C1 | Y22: = | Z22: null | AA22: 5C1 | AB22: = | AC22: null
A23: B | B23: BaseGame | C23: 1 | D23: = | E23: 6946658 | F23: 0.06946658 | H23: Pay | I23: = | J23: 1389331600 | L23: =J23/E23/100/$L$1 -> 2 | O23: 1C1 | P23: = | Q23: null | R23: 2C1 | S23: = | T23: 1389397 | U23: 3C1 | V23: = | W23: null | X23: 4C1 | Y23: = | Z23: null | AA23: 5C1 | AB23: = | AC23: null
A24: B | B24: BaseGame | C24: 4 | D24: = | E24: 8329281 | F24: 0.08329281 | H24: Pay | I24: = | J24: 4164640500 | L24: =J24/E24/100/$L$1 -> 5 | O24: 1C1 | P24: = | Q24: null | R24: 2C1 | S24: = | T24: 2779582 | U24: 3C1 | V24: = | W24: null | X24: 4C1 | Y24: = | Z24: null | AA24: 5C1 | AB24: = | AC24: null
A25: B | B25: BaseGame | C25: 5 | D25: = | E25: 2778618 | F25: 0.02778618 | H25: Pay | I25: = | J25: 1667170800 | L25: =J25/E25/100/$L$1 -> 6 | O25: 1C1 | P25: = | Q25: null | R25: 2C1 | S25: = | T25: 2778618 | U25: 3C1 | V25: = | W25: null | X25: 4C1 | Y25: = | Z25: null | AA25: 5C1 | AB25: = | AC25: null
A26: B | B26: BaseGame | C26: 9 | D26: = | E26: 8799973 | F26: 0.08799973 | H26: Pay | I26: = | J26: 8799973000 | L26: =J26/E26/100/$L$1 -> 10 | O26: 1C1 | P26: = | Q26: null | R26: 2C1 | S26: = | T26: 3241572 | U26: 3C1 | V26: = | W26: null | X26: 4C1 | Y26: = | Z26: null | AA26: 5C1 | AB26: = | AC26: null
A27: B | B27: BaseGame | C27: 10 | D27: = | E27: 5091928 | F27: 0.05091928 | H27: Pay | I27: = | J27: 6573424400 | L27: =J27/E27/100/$L$1 -> 12.9095 | O27: 1C1 | P27: = | Q27: null | R27: 2C1 | S27: = | T27: 5091928 | U27: 3C1 | V27: = | W27: null | X27: 4C1 | Y27: = | Z27: null | AA27: 5C1 | AB27: = | AC27: null
A28: B | B28: BaseGame | C28: 15 | D28: = | E28: 5708653 | F28: 0.05708653 | H28: Pay | I28: = | J28: 11047116000 | L28: =J28/E28/100/$L$1 -> 19.351528 | O28: 1C1 | P28: = | Q28: null | R28: 2C1 | S28: = | T28: 2006229 | U28: 3C1 | V28: = | W28: null | X28: 4C1 | Y28: = | Z28: null | AA28: 5C1 | AB28: = | AC28: null
A29: B | B29: BaseGame | C29: 20 | D29: = | E29: 7139482 | F29: 0.07139482 | H29: Pay | I29: = | J29: 17436248800 | L29: =J29/E29/100/$L$1 -> 24.422288 | O29: 1C1 | P29: = | Q29: null | R29: 2C1 | S29: = | T29: 656403 | U29: 3C1 | V29: = | W29: null | X29: 4C1 | Y29: = | Z29: null | AA29: 5C1 | AB29: = | AC29: null
A30: B | B30: BaseGame | C30: 25 | D30: = | E30: 1041965 | F30: 0.01041965 | H30: Pay | I30: = | J30: 3094709800 | L30: =J30/E30/100/$L$1 -> 29.700708 | O30: 1C1 | P30: = | Q30: null | R30: 2C1 | S30: = | T30: 116658 | U30: 3C1 | V30: = | W30: null | X30: 4C1 | Y30: = | Z30: null | AA30: 5C1 | AB30: = | AC30: null
A31: B | B31: BaseGame | C31: 45 | D31: = | E31: 4169275 | F31: 0.04169275 | H31: Pay | I31: = | J31: 20846375000 | L31: =J31/E31/100/$L$1 -> 50 | O31: 1C1 | P31: = | Q31: null | R31: 2C1 | S31: = | T31: 463653 | U31: 3C1 | V31: = | W31: null | X31: 4C1 | Y31: = | Z31: null | AA31: 5C1 | AB31: = | AC31: null
