Workbook

Sheet Overview
A3: Model: | B3: 0.0.0.1
A4: Coin | B4: Multiway | C4: Pay Back 1 | D4: Pay Back 2
A5: 100 | B5: 1024 | C5: =Card!AF3 -> 0.92999946 | D5: =Card!AH3 -> 0.91999702
A7: Total Pay Back Percentage includes the following adjustments.
A8: Coin | B8: Description of feature
A9: 100 | B9: 3+ SC Free Spin Bonus
A11: Set1 | B11: Pay Back | C11: Hit% | D11: Pulls/Hit
B12: =Card!AF62 -> 0.26678737 | C12: =Card!AF57 -> 0.00849 | D12: =1/C12 -> 117.78563
A13: Set2 | B13: Pay Back | C13: Hit% | D13: Pulls/Hit
B14: =Card!AH62 -> 0.2728177 | C14: =Card!AH57 -> 0.00849 | D14: =1/C14 -> 117.78563
A16: Reel # | B16: 1 | C16: 2 | D16: 3 | E16: 4 | F16: 5
A17: Visible Window Size | B17: 4 | C17: 4 | D17: 4 | E17: 4 | F17: 4
A19: Feature：
A20: 1. Base Game中，為4*5盤面，1024 Ways Game。連線後消除所有連線的標誌後，剩餘標誌依照輪帶順序往下掉落。 2. 當連線的盤面每達成一次消除時，得分倍率往上提升。 3. 當連線的盤面消除到金框符號時，有機會在原地留下一個WW1，或是有機會將目前這格與額外2~4格取代成WW2。 4. 每一滾輪皆有機會出現C1，連線消除後也有機會出現C1，一輪可以出現超過1顆C1。
A31: Pay Table： | B31: All wins show for 100 credit bet.
A33: Scatter Pay： | B33: C1 *
A34: 3+ | B34: 0X
A35: *[C1]僅計算出現總數，對應倍數乘以押分。
B37: 1 | C37: 2 | D37: 3 | E37: 4 | F37: 5
A38: WW1 | B38: -- | C38: -- | D38: -- | E38: -- | F38: --
A39: WW2 | B39: -- | C39: -- | D39: -- | E39: -- | F39: --
A40: C1 | B40: 0 | C40: 0 | D40: 0 | E40: 0 | F40: 0
A41: M1 | B41: 0 | C41: 0 | D41: 50 | E41: 150 | F41: 250
A42: M2 | B42: 0 | C42: 0 | D42: 40 | E42: 120 | F42: 200
A43: M3 | B43: 0 | C43: 0 | D43: 30 | E43: 90 | F43: 150
A44: M4 | B44: 0 | C44: 0 | D44: 20 | E44: 60 | F44: 100
A45: A | B45: 0 | C45: 0 | D45: 10 | E45: 30 | F45: 50
A46: K | B46: 0 | C46: 0 | D46: 10 | E46: 30 | F46: 50
A47: Q | B47: 0 | C47: 0 | D47: 5 | E47: 15 | F47: 25
A48: J | B48: 0 | C48: 0 | D48: 5 | E48: 15 | F48: 25

Sheet Card
AD2: =SUMPRODUCT(AC65:AC115,AK6:AK56)/AB3 -> 0 | AF2: 新手 | AH2: 老手 | AJ2: 未啟用
A3: Lower | B3: Upper | C3: Simulator Cnt | F3: Simulator Pay | I3: Simulator Rate | L3: Simulator RTP | P3: Range | Q3: Base Game | Y3: Threshold | AB3: =10^9 -> 1000000000 | AE3: Final RTP 1 | AF3: =SUM(AE5:AE57)+AF57*(SUM(AE64:AE122)+AE57) -> 0.92999946 | AG3: Final RTP 2 | AH3: =SUM(AG5:AG57)+AH57*(SUM(AG64:AG122)+AG57) -> 0.91999702 | AI3: Final RTP 3 | AJ3: =SUM(AI5:AI57)+AJ57*(SUM(AI64:AI122)) -> 1.216331 | AM3: 新手 | AN3: 老手1 | AO3: 老手2
C4: A | D4: B | E4: C | F4: A | G4: B | H4: C | I4: A | J4: B | K4: C | L4: A | M4: B | N4: C | Q4: 使用的表 | R4: Rate | S4: Fix Num 1 | T4: Fix Num 2 | U4: Fix Num 3 | V4: Fix Rate 1 | W4: Fix Rate 2 | X4: Fix Rate 3 | Y4: Final Rate 1 | Z4: Final Rate 2 | AA4: Final Rate 3 | AB4: Weight 1 | AC4: Weight 2 | AD4: Weight 3 | AE4: Simulator RTP | AF4: Hit Rate | AG4: Simulator RTP | AH4: Hit Rate | AI4: Simulator RTP | AJ4: Hit Rate | AL4: Super Ace | AM4: 調性1 | AN4: 調性2 | AO4: 調性3
A5: -1 | B5: 0 | C5: 81444439 | D5: 44611398 | F5: 0 | G5: 0 | I5: {=_xlfn.LET(_xlpm.x, C5:C56, _xlpm.x/SUM(_xlpm.x))} -> 0.82275434 | J5: {=_xlfn.LET(_xlpm.x, D5:D56, _xlpm.x/SUM(_xlpm.x))} -> 0.44990451 | L5: {=F5:F56/C5:C56/[1]Overview!$A$5/5} -> 0 | M5: {=G5:G56/D5:D56/[1]Overview!$A$5/5} -> 0 | O5: =SUMPRODUCT(J5:J51,M5:M51) -> 9.1572377 | P5: ="("&$A5&", "&$B5&"]" -> (-1, 0] | Q5: B | R5: =_xlfn.XLOOKUP(Q5, $I$4:$K$4, I5:K5) -> 0.44990451 | S5: 1.986 | T5: 1.7108 | U5: 1.5 | V5: {=$R5:$R57*S5:S57} -> 0.89351035 | W5: {=$R5:$R57*T5:T57} -> 0.76969663 | X5: {=$R5:$R57*U5:U57} -> 0.67485676 | Y5: {=V5:V56/SUM(_xlfn.ANCHORARRAY(V5))} -> 0.71016486 | Z5: {=W5:W56/SUM(_xlfn.ANCHORARRAY(W5))} -> 0.74656841 | AA5: {=X5:X56/SUM(_xlfn.ANCHORARRAY(X5))} -> 0.72004258 | AB5: =INT($AB3-SUM(_xlfn.ANCHORARRAY(AB6))) -> 708422750 | AC5: =INT($AB3-SUM(_xlfn.ANCHORARRAY(AC6))) -> 746313311 | AD5: =INT($AB3-SUM(_xlfn.ANCHORARRAY(AD6))) -> 720611054 | AE5: =_xlfn.LET(_xlpm.x, _xlfn.XLOOKUP($Q5, $L$4:$N$4, $L5:$N5), IF(ISERROR(_xlpm.x), 0, _xlpm.x)*AB5/$AB$3) -> 0 | AF5: {=_xlfn.LET(_xlpm.x, AB5:AB57, _xlpm.x/SUM(_xlpm.x))} -> 0.70842275 | AG5: =_xlfn.LET(_xlpm.x, _xlfn.XLOOKUP($Q5, $L$4:$N$4, $L5:$N5), IF(ISERROR(_xlpm.x), 0, _xlpm.x)*AC5/$AB$3) -> 0 | AH5: {=_xlfn.LET(_xlpm.x, AC5:AC57, _xlpm.x/SUM(_xlpm.x))} -> 0.74631331 | AI5: =_xlfn.LET(_xlpm.x, _xlfn.XLOOKUP($Q5, $L$4:$N$4, $L5:$N5), IF(ISERROR(_xlpm.x), 0, _xlpm.x)*AD5/$AB$3) -> 0 | AJ5: {=_xlfn.LET(_xlpm.x, AD5:AD57, _xlpm.x/SUM(_xlpm.x))} -> 0.72061105 | AL5: 0.75950714 | AM5: {=(1-AF57)*AF5:AF56+AF57*AF64:AF115} -> 0.70240824 | AN5: {=(1-AH57)*AH5:AH56+AH57*AH64:AH115} -> 0.73997711 | AO5: {=(1-AJ57)*AJ5:AJ56+AJ57*AJ64:AJ115} -> 0.71449307
A6: 0 | B6: 1 | C6: 13113310 | D6: 18412850 | F6: 2531346475 | G6: 3398022375 | I6: 0.13247108 | J6: 0.185693 | L6: 0.38607285 | M6: 0.3690925 | P6: ="("&$A6&", "&$B6&"]" -> (0, 1] | Q6: B | R6: =_xlfn.SINGLE(_xlfn.XLOOKUP(Q6, $I$4:$K$4, I6:K6)) -> 0.185693 | S6: 1 | T6: 0.865 | U6: 0.68 | V6: 0.185693 | W6: 0.16062444 | X6: 0.12627124 | Y6: 0.14758938 | Z6: 0.15579792 | AA6: 0.13472588 | AB6: {=INT(Y6:Y57*$AB3)} -> 147589383 | AC6: {=INT(Z6:Z57*$AB3)} -> 155797920 | AD6: {=INT(AA6:AA57*$AB3)} -> 134725876 | AE6: =_xlfn.LET(_xlpm.x, _xlfn.XLOOKUP($Q6, $L$4:$N$4, $L6:$N6), IF(ISERROR(_xlpm.x), 0, _xlpm.x)*AB6/$AB$3) -> 0.054474134 | AF6: 0.14758938 | AG6: =_xlfn.LET(_xlpm.x, _xlfn.XLOOKUP($Q6, $L$4:$N$4, $L6:$N6), IF(ISERROR(_xlpm.x), 0, _xlpm.x)*AC6/$AB$3) -> 0.057503843 | AH6: 0.15579792 | AI6: =_xlfn.LET(_xlpm.x, _xlfn.XLOOKUP($Q6, $L$4:$N$4, $L6:$N6), IF(ISERROR(_xlpm.x), 0, _xlpm.x)*AD6/$AB$3) -> 0.04972631 | AJ6: 0.13472588 | AL6: 0.13313845 | AM6: 0.14633635 | AN6: 0.1544752 | AO6: 0.13358205
A7: 1 | B7: 2 | C7: 2076337 | D7: 4580344 | F7: 1560262150 | G7: 3412133350 | I7: 0.020975223 | J7: 0.046192621 | L7: 1.5028988 | M7: 1.4899027 | P7: ="("&$A7&", "&$B7&"]" -> (1, 2] | Q7: B | R7: =_xlfn.SINGLE(_xlfn.XLOOKUP(Q7, $I$4:$K$4, I7:K7)) -> 0.046192621 | S7: 1 | T7: 0.58 | U7: 0.8 | V7: 0.046192621 | W7: 0.02679172 | X7: 0.036954097 | Y7: 0.036714042 | Z7: 0.02598667 | AA7: 0.039428402 | AB7: 36714042 | AC7: 25986669 | AD7: 39428401 | AE7: =_xlfn.LET(_xlpm.x, _xlfn.XLOOKUP($Q7, $L$4:$N$4, $L7:$N7), IF(ISERROR(_xlpm.x), 0, _xlpm.x)*AB7/$AB$3) -> 0.054700349 | AF7: 0.036714042 | AG7: =_xlfn.LET(_xlpm.x, _xlfn.XLOOKUP($Q7, $L$4:$N$4, $L7:$N7), IF(ISERROR(_xlpm.x), 0, _xlpm.x)*AC7/$AB$3) -> 0.038717607 | AH7: 0.025986669 | AI7: =_xlfn.LET(_xlpm.x, _xlfn.XLOOKUP($Q7, $L$4:$N$4, $L7:$N7), IF(ISERROR(_xlpm.x), 0, _xlpm.x)*AD7/$AB$3) -> 0.058744479 | AJ7: 0.039428401 | AL7: 0.031854304 | AM7: 0.03640234 | AN7: 0.025766042 | AO7: 0.039093654
A8: 2 | B8: 3 | C8: 894630 | D8: 2912418 | F8: 1126665375 | G8: 3666796450 | I8: 0.009037581 | J8: 0.029371641 | L8: 2.5187293 | M8: 2.5180427 | P8: ="("&$A8&", "&$B8&"]" -> (2, 3] | Q8: B | R8: =_xlfn.SINGLE(_xlfn.XLOOKUP(Q8, $I$4:$K$4, I8:K8)) -> 0.029371641 | S8: 1 | T8: 0.52 | U8: 0.5 | V8: 0.029371641 | W8: 0.015273254 | X8: 0.014685821 | Y8: 0.023344674 | Z8: 0.014814315 | AA8: 0.015669127 | AB8: 23344673 | AC8: 14814315 | AD8: 15669126 | AE8: =_xlfn.LET(_xlpm.x, _xlfn.XLOOKUP($Q8, $L$4:$N$4, $L8:$N8), IF(ISERROR(_xlpm.x), 0, _xlpm.x)*AB8/$AB$3) -> 0.058782884 | AF8: 0.023344673 | AG8: =_xlfn.LET(_xlpm.x, _xlfn.XLOOKUP($Q8, $L$4:$N$4, $L8:$N8), IF(ISERROR(_xlpm.x), 0, _xlpm.x)*AC8/$AB$3) -> 0.037303078 | AH8: 0.014814315 | AI8: =_xlfn.LET(_xlpm.x, _xlfn.XLOOKUP($Q8, $L$4:$N$4, $L8:$N8), IF(ISERROR(_xlpm.x), 0, _xlpm.x)*AD8/$AB$3) -> 0.039455528 | AJ8: 0.015669126 | AL8: 0.017710586 | AM8: 0.023146477 | AN8: 0.014688541 | AO8: 0.015536095
A9: 3 | B9: 4 | C9: 457771 | D9: 1995806 | F9: 815422300 | G9: 3530115825 | I9: 0.0046244174 | J9: 0.020127639 | L9: 3.5625774 | M9: 3.537534 | P9: ="("&$A9&", "&$B9&"]" -> (3, 4] | Q9: B | R9: =_xlfn.SINGLE(_xlfn.XLOOKUP(Q9, $I$4:$K$4, I9:K9)) -> 0.020127639 | S9: 1.042 | T9: 0.53 | U9: 0.5 | V9: 0.020973 | W9: 0.010667649 | X9: 0.010063819 | Y9: 0.016669407 | Z9: 0.010347102 | AA9: 0.010737654 | AB9: 16669406 | AC9: 10347101 | AD9: 10737654 | AE9: =_xlfn.LET(_xlpm.x, _xlfn.XLOOKUP($Q9, $L$4:$N$4, $L9:$N9), IF(ISERROR(_xlpm.x), 0, _xlpm.x)*AB9/$AB$3) -> 0.058968591 | AF9: 0.016669406 | AG9: =_xlfn.LET(_xlpm.x, _xlfn.XLOOKUP($Q9, $L$4:$N$4, $L9:$N9), IF(ISERROR(_xlpm.x), 0, _xlpm.x)*AC9/$AB$3) -> 0.036603222 | AH9: 0.010347101 | AI9: =_xlfn.LET(_xlpm.x, _xlfn.XLOOKUP($Q9, $L$4:$N$4, $L9:$N9), IF(ISERROR(_xlpm.x), 0, _xlpm.x)*AD9/$AB$3) -> 0.037984816 | AJ9: 0.010737654 | AL9: 0.0116448 | AM9: 0.016527883 | AN9: 0.010259254 | AO9: 0.010646491
A10: 4 | B10: 5 | C10: 297012 | D10: 1826101 | F10: 670352000 | G10: 4129988800 | I10: 0.0030004248 | J10: 0.01841617 | L10: 4.5139725 | M10: 4.5232863 | P10: ="("&$A10&", "&$B10&"]" -> (4, 5] | Q10: B | R10: =_xlfn.SINGLE(_xlfn.XLOOKUP(Q10, $I$4:$K$4, I10:K10)) -> 0.01841617 | S10: 0.8 | T10: 0.5 | U10: 0.5 | V10: 0.014732936 | W10: 0.0092080848 | X10: 0.0092080848 | Y10: 0.011709784 | Z10: 0.0089313957 | AA10: 0.0098246228 | AB10: 11709784 | AC10: 8931395 | AD10: 9824622 | AE10: =_xlfn.LET(_xlpm.x, _xlfn.XLOOKUP($Q10, $L$4:$N$4, $L10:$N10), IF(ISERROR(_xlpm.x), 0, _xlpm.x)*AB10/$AB$3) -> 0.052966705 | AF10: 0.011709784 | AG10: =_xlfn.LET(_xlpm.x, _xlfn.XLOOKUP($Q10, $L$4:$N$4, $L10:$N10), IF(ISERROR(_xlpm.x), 0, _xlpm.x)*AC10/$AB$3) -> 0.040399256 | AH10: 0.008931395 | AI10: =_xlfn.LET(_xlpm.x, _xlfn.XLOOKUP($Q10, $L$4:$N$4, $L10:$N10), IF(ISERROR(_xlpm.x), 0, _xlpm.x)*AD10/$AB$3) -> 0.044439578 | AJ10: 0.009824622 | AL10: 0.0093752676 | AM10: 0.011610368 | AN10: 0.0088555675 | AO10: 0.009741211
A11: 5 | B11: 6 | C11: 177151 | D11: 1461544 | F11: 491783775 | G11: 4037335500 | I11: 0.0017895851 | J11: 0.014739624 | L11: 5.5521422 | M11: 5.524754 | P11: ="("&$A11&", "&$B11&"]" -> (5, 6] | Q11: B | R11: =_xlfn.SINGLE(_xlfn.XLOOKUP(Q11, $I$4:$K$4, I11:K11)) -> 0.014739624 | S11: 1 | T11: 0.3 | U11: 0.3 | V11: 0.014739624 | W11: 0.0044218872 | X11: 0.0044218872 | Y11: 0.0117151 | Z11: 0.0042890162 | AA11: 0.0047179598 | AB11: 11715099 | AC11: 4289016 | AD11: 4717959 | AE11: =_xlfn.LET(_xlpm.x, _xlfn.XLOOKUP($Q11, $L$4:$N$4, $L11:$N11), IF(ISERROR(_xlpm.x), 0, _xlpm.x)*AB11/$AB$3) -> 0.06472304 | AF11: 0.011715099 | AG11: =_xlfn.LET(_xlpm.x, _xlfn.XLOOKUP($Q11, $L$4:$N$4, $L11:$N11), IF(ISERROR(_xlpm.x), 0, _xlpm.x)*AC11/$AB$3) -> 0.023695758 | AH11: 0.004289016 | AI11: =_xlfn.LET(_xlpm.x, _xlfn.XLOOKUP($Q11, $L$4:$N$4, $L11:$N11), IF(ISERROR(_xlpm.x), 0, _xlpm.x)*AD11/$AB$3) -> 0.026065563 | AJ11: 0.004717959 | AL11: 0.004243089 | AM11: 0.011615638 | AN11: 0.0042526023 | AO11: 0.0046779035
A12: 6 | B12: 7 | C12: 124646 | D12: 1323139 | F12: 405090625 | G12: 4311237575 | I12: 0.0012591779 | J12: 0.013343814 | L12: 6.4998576 | M12: 6.5166813 | P12: ="("&$A12&", "&$B12&"]" -> (6, 7] | Q12: B | R12: =_xlfn.SINGLE(_xlfn.XLOOKUP(Q12, $I$4:$K$4, I12:K12)) -> 0.013343814 | S12: 0.8 | T12: 0.3 | U12: 0.8 | V12: 0.010675051 | W12: 0.0040031442 | X12: 0.010675051 | Y12: 0.0084845646 | Z12: 0.0038828558 | AA12: 0.011389812 | AB12: 8484564 | AC12: 3882855 | AD12: 11389811 | AE12: =_xlfn.LET(_xlpm.x, _xlfn.XLOOKUP($Q12, $L$4:$N$4, $L12:$N12), IF(ISERROR(_xlpm.x), 0, _xlpm.x)*AB12/$AB$3) -> 0.055291199 | AF12: 0.008484564 | AG12: =_xlfn.LET(_xlpm.x, _xlfn.XLOOKUP($Q12, $L$4:$N$4, $L12:$N12), IF(ISERROR(_xlpm.x), 0, _xlpm.x)*AC12/$AB$3) -> 0.025303328 | AH12: 0.003882855 | AI12: =_xlfn.LET(_xlpm.x, _xlfn.XLOOKUP($Q12, $L$4:$N$4, $L12:$N12), IF(ISERROR(_xlpm.x), 0, _xlpm.x)*AD12/$AB$3) -> 0.074223768 | AJ12: 0.011389811 | AL12: 0.0034818862 | AM12: 0.0084125301 | AN12: 0.0038498896 | AO12: 0.011293112
A13: 7 | B13: 8 | C13: 84482 | D13: 1121685 | F13: 319837600 | G13: 4225509550 | I13: 0.00085343988 | J13: 0.011312157 | L13: 7.5717336 | M13: 7.5342178 | P13: ="("&$A13&", "&$B13&"]" -> (7, 8] | Q13: B | R13: =_xlfn.SINGLE(_xlfn.XLOOKUP(Q13, $I$4:$K$4, I13:K13)) -> 0.011312157 | S13: 0.9 | T13: 0.3 | U13: 0.8 | V13: 0.010180941 | W13: 0.0033936471 | X13: 0.0090497256 | Y13: 0.0080918445 | Z13: 0.0032916731 | AA13: 0.0096556605 | AB13: 8091844 | AC13: 3291673 | AD13: 9655660 | AE13: =_xlfn.LET(_xlpm.x, _xlfn.XLOOKUP($Q13, $L$4:$N$4, $L13:$N13), IF(ISERROR(_xlpm.x), 0, _xlpm.x)*AB13/$AB$3) -> 0.060965715 | AF13: 0.008091844 | AG13: =_xlfn.LET(_xlpm.x, _xlfn.XLOOKUP($Q13, $L$4:$N$4, $L13:$N13), IF(ISERROR(_xlpm.x), 0, _xlpm.x)*AC13/$AB$3) -> 0.024800181 | AH13: 0.003291673 | AI13: =_xlfn.LET(_xlpm.x, _xlfn.XLOOKUP($Q13, $L$4:$N$4, $L13:$N13), IF(ISERROR(_xlpm.x), 0, _xlpm.x)*AD13/$AB$3) -> 0.072747846 | AJ13: 0.00965566 | AL13: 0.0031388401 | AM13: 0.0080231442 | AN13: 0.0032637267 | AO13: 0.0095736834
A14: 8 | B14: 9 | C14: 71204 | D14: 1089744 | F14: 303032850 | G14: 4639783525 | I14: 0.0007193051 | J14: 0.010990033 | L14: 8.5116805 | M14: 8.5153642 | P14: ="("&$A14&", "&$B14&"]" -> (8, 9] | Q14: B | R14: =_xlfn.SINGLE(_xlfn.XLOOKUP(Q14, $I$4:$K$4, I14:K14)) -> 0.010990033 | S14: 0.7 | T14: 0.28 | U14: 0.8 | V14: 0.0076930231 | W14: 0.0030772092 | X14: 0.0087920264 | Y14: 0.0061144392 | Z14: 0.0029847437 | AA14: 0.0093807068 | AB14: 6114439 | AC14: 2984743 | AD14: 9380706 | AE14: =_xlfn.LET(_xlpm.x, _xlfn.XLOOKUP($Q14, $L$4:$N$4, $L14:$N14), IF(ISERROR(_xlpm.x), 0, _xlpm.x)*AB14/$AB$3) -> 0.052066675 | AF14: 0.006114439 | AG14: =_xlfn.LET(_xlpm.x, _xlfn.XLOOKUP($Q14, $L$4:$N$4, $L14:$N14), IF(ISERROR(_xlpm.x), 0, _xlpm.x)*AC14/$AB$3) -> 0.025416174 | AH14: 0.002984743 | AI14: =_xlfn.LET(_xlpm.x, _xlfn.XLOOKUP($Q14, $L$4:$N$4, $L14:$N14), IF(ISERROR(_xlpm.x), 0, _xlpm.x)*AD14/$AB$3) -> 0.079880128 | AJ14: 0.009380706 | AL14: 0.0026829592 | AM14: 0.0060625274 | AN14: 0.0029594025 | AO14: 0.0093010638
A15: 9 | B15: 10 | C15: 48023 | D15: 944073 | F15: 228958500 | G15: 4499878525 | I15: 0.00048512989 | J15: 0.0095209457 | L15: 9.5353685 | M15: 9.5329038 | P15: ="("&$A15&", "&$B15&"]" -> (9, 10] | Q15: B | R15: =_xlfn.SINGLE(_xlfn.XLOOKUP(Q15, $I$4:$K$4, I15:K15)) -> 0.0095209457 | S15: 0.44 | T15: 0.32 | U15: 0.3 | V15: 0.0041892161 | W15: 0.0030467026 | X15: 0.0028562837 | Y15: 0.0033296023 | Z15: 0.0029551538 | AA15: 0.0030475295 | AB15: 3329602 | AC15: 2955153 | AD15: 3047529 | AE15: =_xlfn.LET(_xlpm.x, _xlfn.XLOOKUP($Q15, $L$4:$N$4, $L15:$N15), IF(ISERROR(_xlpm.x), 0, _xlpm.x)*AB15/$AB$3) -> 0.031740775 | AF15: 0.003329602 | AG15: =_xlfn.LET(_xlpm.x, _xlfn.XLOOKUP($Q15, $L$4:$N$4, $L15:$N15), IF(ISERROR(_xlpm.x), 0, _xlpm.x)*AC15/$AB$3) -> 0.028171189 | AH15: 0.002955153 | AI15: =_xlfn.LET(_xlpm.x, _xlfn.XLOOKUP($Q15, $L$4:$N$4, $L15:$N15), IF(ISERROR(_xlpm.x), 0, _xlpm.x)*AD15/$AB$3) -> 0.029051801 | AJ15: 0.003047529 | AL15: 0.0025624295 | AM15: 0.0033013337 | AN15: 0.0029300638 | AO15: 0.0030216555
A16: 10 | B16: 15 | C16: 117843 | D16: 3698851 | F16: 711361275 | G16: 22888608900 | I16: 0.0011904538 | J16: 0.037302793 | L16: 12.073034 | M16: 12.376064 | P16: ="("&$A16&", "&$B16&"]" -> (10, 15] | Q16: B | R16: =_xlfn.SINGLE(_xlfn.XLOOKUP(Q16, $I$4:$K$4, I16:K16)) -> 0.037302793 | S16: 0.3145 | T16: 0.14 | U16: 0.422 | V16: 0.011731728 | W16: 0.005222391 | X16: 0.015741779 | Y16: 0.0093244149 | Z16: 0.005065466 | AA16: 0.016795788 | AB16: 9324414 | AC16: 5065466 | AD16: 16795787 | AE16: =_xlfn.LET(_xlpm.x, _xlfn.XLOOKUP($Q16, $L$4:$N$4, $L16:$N16), IF(ISERROR(_xlpm.x), 0, _xlpm.x)*AB16/$AB$3) -> 0.11539955 | AF16: 0.009324414 | AG16: =_xlfn.LET(_xlpm.x, _xlfn.XLOOKUP($Q16, $L$4:$N$4, $L16:$N16), IF(ISERROR(_xlpm.x), 0, _xlpm.x)*AC16/$AB$3) -> 0.062690533 | AH16: 0.005065466 | AI16: =_xlfn.LET(_xlpm.x, _xlfn.XLOOKUP($Q16, $L$4:$N$4, $L16:$N16), IF(ISERROR(_xlpm.x), 0, _xlpm.x)*AD16/$AB$3) -> 0.20786574 | AJ16: 0.016795787 | AL16: 0.0055396749 | AM16: 0.0092452497 | AN16: 0.0059292089 | AO16: 0.016746832
A17: 15 | B17: 20 | C17: 45036 | D17: 2622561 | F17: 386935925 | G17: 22832281425 | I17: 0.00045495512 | J17: 0.026448443 | L17: 17.183405 | M17: 17.412202 | P17: ="("&$A17&", "&$B17&"]" -> (15, 20] | Q17: B | R17: =_xlfn.SINGLE(_xlfn.XLOOKUP(Q17, $I$4:$K$4, I17:K17)) -> 0.026448443 | S17: 0 | T17: 0.1 | U17: 0.01 | V17: 0 | W17: 0.0026448443 | X17: 0.00026448443 | Y17: 0 | Z17: 0.0025653707 | AA17: 0.00028219329 | AB17: 0 | AC17: 2565370 | AD17: 282193 | AE17: =_xlfn.LET(_xlpm.x, _xlfn.XLOOKUP($Q17, $L$4:$N$4, $L17:$N17), IF(ISERROR(_xlpm.x), 0, _xlpm.x)*AB17/$AB$3) -> 0 | AF17: 0 | AG17: =_xlfn.LET(_xlpm.x, _xlfn.XLOOKUP($Q17, $L$4:$N$4, $L17:$N17), IF(ISERROR(_xlpm.x), 0, _xlpm.x)*AC17/$AB$3) -> 0.044668742 | AH17: 0.00256537 | AI17: =_xlfn.LET(_xlpm.x, _xlfn.XLOOKUP($Q17, $L$4:$N$4, $L17:$N17), IF(ISERROR(_xlpm.x), 0, _xlpm.x)*AD17/$AB$3) -> 0.0049136016 | AJ17: 0.000282193 | AL17: 0.003905861 | AM17: 0 | AN17: 0.0035328161 | AO17: 0.00044430475
A18: 20 | B18: 25 | C18: 17393 | D18: 1975704 | F18: 193861550 | G18: 22152755175 | I18: 0.00017570465 | J18: 0.019924911 | L18: 22.291905 | M18: 22.425176 | P18: ="("&$A18&", "&$B18&"]" -> (20, 25] | Q18: B | R18: =_xlfn.SINGLE(_xlfn.XLOOKUP(Q18, $I$4:$K$4, I18:K18)) -> 0.019924911 | S18: 0 | T18: 0.07 | U18: 0.01 | V18: 0 | W18: 0.0013947438 | X18: 0.00019924911 | Y18: 0 | Z18: 0.0013528338 | AA18: 0.00021259007 | AB18: 0 | AC18: 1352833 | AD18: 212590 | AE18: =_xlfn.LET(_xlpm.x, _xlfn.XLOOKUP($Q18, $L$4:$N$4, $L18:$N18), IF(ISERROR(_xlpm.x), 0, _xlpm.x)*AB18/$AB$3) -> 0 | AF18: 0 | AG18: =_xlfn.LET(_xlpm.x, _xlfn.XLOOKUP($Q18, $L$4:$N$4, $L18:$N18), IF(ISERROR(_xlpm.x), 0, _xlpm.x)*AC18/$AB$3) -> 0.030337518 | AH18: 0.001352833 | AI18: =_xlfn.LET(_xlpm.x, _xlfn.XLOOKUP($Q18, $L$4:$N$4, $L18:$N18), IF(ISERROR(_xlpm.x), 0, _xlpm.x)*AD18/$AB$3) -> 0.0047673682 | AJ18: 0.00021259 | AL18: 0.0029427494 | AM18: 0.0012335986 | AN18: 0.0025176253 | AO18: 0.00041324573
... A35: 250 | B35: 300 | C35: 2 | D35: 60786 | F35: 267175 | G35: 8260336800 | I35: 2.0204064e-08 | J35: 0.00061302484 | L35: 267.175 | M35: 271.78419 | P35: ="("&$A35&", "&$B35&"]" -> (250, 300] | Q35: B | R35: =_xlfn.SINGLE(_xlfn.XLOOKUP(Q35, $I$4:$K$4, I35:K35)) -> 0.00061302484 | S35: 0 | T35: 0 | U35: 0 | V35: 0 | W35: 0 | X35: 0 | Y35: 0 | Z35: 0 | AA35: 0 | AB35: 0 | AC35: 0 | AD35: 0 | AE35: =_xlfn.LET(_xlpm.x, _xlfn.XLOOKUP($Q35, $L$4:$N$4, $L35:$N35), IF(ISERROR(_xlpm.x), 0, _xlpm.x)*AB35/$AB$3) -> 0 | AF35: 0 | AG35: =_xlfn.LET(_xlpm.x, _xlfn.XLOOKUP($Q35, $L$4:$N$4, $L35:$N35), IF(ISERROR(_xlpm.x), 0, _xlpm.x)*AC35/$AB$3) -> 0 | AH35: 0 | AI35: =_xlfn.LET(_xlpm.x, _xlfn.XLOOKUP($Q35, $L$4:$N$4, $L35:$N35), IF(ISERROR(_xlpm.x), 0, _xlpm.x)*AD35/$AB$3) -> 0 | AJ35: 0 | AL35: 2.3009877e-05 | AM35: 0 | AN35: 3.89691e-09 | AO35: 0
A36: 300 | B36: 350 | D36: 28345 | G36: 4564465400 | I36: 0 | J36: 0.00028585841 | L36: #DIV/0! | M36: 322.06494 | P36: ="("&$A36&", "&$B36&"]" -> (300, 350] | Q36: B | R36: =_xlfn.SINGLE(_xlfn.XLOOKUP(Q36, $I$4:$K$4, I36:K36)) -> 0.00028585841 | S36: 0 | T36: 0 | U36: 0 | V36: 0 | W36: 0 | X36: 0 | Y36: 0 | Z36: 0 | AA36: 0 | AB36: 0 | AC36: 0 | AD36: 0 | AE36: =_xlfn.LET(_xlpm.x, _xlfn.XLOOKUP($Q36, $L$4:$N$4, $L36:$N36), IF(ISERROR(_xlpm.x), 0, _xlpm.x)*AB36/$AB$3) -> 0 | AF36: 0 | AG36: =_xlfn.LET(_xlpm.x, _xlfn.XLOOKUP($Q36, $L$4:$N$4, $L36:$N36), IF(ISERROR(_xlpm.x), 0, _xlpm.x)*AC36/$AB$3) -> 0 | AH36: 0 | AI36: =_xlfn.LET(_xlpm.x, _xlfn.XLOOKUP($Q36, $L$4:$N$4, $L36:$N36), IF(ISERROR(_xlpm.x), 0, _xlpm.x)*AD36/$AB$3) -> 0 | AJ36: 0 | AL36: 1.2799948e-05 | AM36: 0 | AN36: 3.00546e-09 | AO36: 0
A37: 350 | B37: 400 | D37: 14283 | G37: 2664886025 | I37: 0 | J37: 0.00014404359 | L37: #DIV/0! | M37: 373.15494 | P37: ="("&$A37&", "&$B37&"]" -> (350, 400] | Q37: B | R37: =_xlfn.SINGLE(_xlfn.XLOOKUP(Q37, $I$4:$K$4, I37:K37)) -> 0.00014404359 | S37: 0 | T37: 0 | U37: 0 | V37: 0 | W37: 0 | X37: 0 | Y37: 0 | Z37: 0 | AA37: 0 | AB37: 0 | AC37: 0 | AD37: 0 | AE37: =_xlfn.LET(_xlpm.x, _xlfn.XLOOKUP($Q37, $L$4:$N$4, $L37:$N37), IF(ISERROR(_xlpm.x), 0, _xlpm.x)*AB37/$AB$3) -> 0 | AF37: 0 | AG37: =_xlfn.LET(_xlpm.x, _xlfn.XLOOKUP($Q37, $L$4:$N$4, $L37:$N37), IF(ISERROR(_xlpm.x), 0, _xlpm.x)*AC37/$AB$3) -> 0 | AH37: 0 | AI37: =_xlfn.LET(_xlpm.x, _xlfn.XLOOKUP($Q37, $L$4:$N$4, $L37:$N37), IF(ISERROR(_xlpm.x), 0, _xlpm.x)*AD37/$AB$3) -> 0 | AJ37: 0 | AL37: 6.1184503e-06 | AM37: 0 | AN37: 0 | AO37: 0
A38: 400 | B38: 450 | D38: 7594 | G38: 1604572700 | I38: 0 | J38: 7.6585244e-05 | L38: #DIV/0! | M38: 422.5896 | P38: ="("&$A38&", "&$B38&"]" -> (400, 450] | Q38: B | R38: =_xlfn.SINGLE(_xlfn.XLOOKUP(Q38, $I$4:$K$4, I38:K38)) -> 7.6585244e-05 | S38: 0 | T38: 0 | U38: 0 | V38: 0 | W38: 0 | X38: 0 | Y38: 0 | Z38: 0 | AA38: 0 | AB38: 0 | AC38: 0 | AD38: 0 | AE38: =_xlfn.LET(_xlpm.x, _xlfn.XLOOKUP($Q38, $L$4:$N$4, $L38:$N38), IF(ISERROR(_xlpm.x), 0, _xlpm.x)*AB38/$AB$3) -> 0 | AF38: 0 | AG38: =_xlfn.LET(_xlpm.x, _xlfn.XLOOKUP($Q38, $L$4:$N$4, $L38:$N38), IF(ISERROR(_xlpm.x), 0, _xlpm.x)*AC38/$AB$3) -> 0 | AH38: 0 | AI38: =_xlfn.LET(_xlpm.x, _xlfn.XLOOKUP($Q38, $L$4:$N$4, $L38:$N38), IF(ISERROR(_xlpm.x), 0, _xlpm.x)*AD38/$AB$3) -> 0 | AJ38: 0 | AL38: 4.4668441e-06 | AM38: 0 | AN38: 0 | AO38: 0
A39: 450 | B39: 500 | D39: 4278 | G39: 1012271950 | I39: 0 | J39: 4.3143492e-05 | L39: #DIV/0! | M39: 473.24542 | P39: ="("&$A39&", "&$B39&"]" -> (450, 500] | Q39: B | R39: =_xlfn.SINGLE(_xlfn.XLOOKUP(Q39, $I$4:$K$4, I39:K39)) -> 4.3143492e-05 | S39: 0 | T39: 0 | U39: 0 | V39: 0 | W39: 0 | X39: 0 | Y39: 0 | Z39: 0 | AA39: 0 | AB39: 0 | AC39: 0 | AD39: 0 | AE39: =_xlfn.LET(_xlpm.x, _xlfn.XLOOKUP($Q39, $L$4:$N$4, $L39:$N39), IF(ISERROR(_xlpm.x), 0, _xlpm.x)*AB39/$AB$3) -> 0 | AF39: 0 | AG39: =_xlfn.LET(_xlpm.x, _xlfn.XLOOKUP($Q39, $L$4:$N$4, $L39:$N39), IF(ISERROR(_xlpm.x), 0, _xlpm.x)*AC39/$AB$3) -> 0 | AH39: 0 | AI39: =_xlfn.LET(_xlpm.x, _xlfn.XLOOKUP($Q39, $L$4:$N$4, $L39:$N39), IF(ISERROR(_xlpm.x), 0, _xlpm.x)*AD39/$AB$3) -> 0 | AJ39: 0 | AL39: 2.2897268e-06 | AM39: 0 | AN39: 0 | AO39: 0
A40: 500 | B40: 550 | D40: 2588 | G40: 675360325 | I40: 0 | J40: 2.6099896e-05 | L40: #DIV/0! | M40: 521.91679 | P40: ="("&$A40&", "&$B40&"]" -> (500, 550] | Q40: B | R40: =_xlfn.SINGLE(_xlfn.XLOOKUP(Q40, $I$4:$K$4, I40:K40)) -> 2.6099896e-05 | S40: 0 | T40: 0 | U40: 0 | V40: 0 | W40: 0 | X40: 0 | Y40: 0 | Z40: 0 | AA40: 0 | AB40: 0 | AC40: 0 | AD40: 0 | AE40: =_xlfn.LET(_xlpm.x, _xlfn.XLOOKUP($Q40, $L$4:$N$4, $L40:$N40), IF(ISERROR(_xlpm.x), 0, _xlpm.x)*AB40/$AB$3) -> 0 | AF40: 0 | AG40: =_xlfn.LET(_xlpm.x, _xlfn.XLOOKUP($Q40, $L$4:$N$4, $L40:$N40), IF(ISERROR(_xlpm.x), 0, _xlpm.x)*AC40/$AB$3) -> 0 | AH40: 0 | AI40: =_xlfn.LET(_xlpm.x, _xlfn.XLOOKUP($Q40, $L$4:$N$4, $L40:$N40), IF(ISERROR(_xlpm.x), 0, _xlpm.x)*AD40/$AB$3) -> 0 | AJ40: 0 | AL40: 5.2551107e-07 | AM40: 0 | AN40: 0 | AO40: 0
A41: 550 | B41: 600 | D41: 1682 | G41: 481706800 | I41: 0 | J41: 1.6962916e-05 | L41: #DIV/0! | M41: 572.7786 | P41: ="("&$A41&", "&$B41&"]" -> (550, 600] | Q41: B | R41: =_xlfn.SINGLE(_xlfn.XLOOKUP(Q41, $I$4:$K$4, I41:K41)) -> 1.6962916e-05 | S41: 0 | T41: 0 | U41: 0 | V41: 0 | W41: 0 | X41: 0 | Y41: 0 | Z41: 0 | AA41: 0 | AB41: 0 | AC41: 0 | AD41: 0 | AE41: =_xlfn.LET(_xlpm.x, _xlfn.XLOOKUP($Q41, $L$4:$N$4, $L41:$N41), IF(ISERROR(_xlpm.x), 0, _xlpm.x)*AB41/$AB$3) -> 0 | AF41: 0 | AG41: =_xlfn.LET(_xlpm.x, _xlfn.XLOOKUP($Q41, $L$4:$N$4, $L41:$N41), IF(ISERROR(_xlpm.x), 0, _xlpm.x)*AC41/$AB$3) -> 0 | AH41: 0 | AI41: =_xlfn.LET(_xlpm.x, _xlfn.XLOOKUP($Q41, $L$4:$N$4, $L41:$N41), IF(ISERROR(_xlpm.x), 0, _xlpm.x)*AD41/$AB$3) -> 0 | AJ41: 0 | AL41: 5.2551107e-07 | AM41: 0 | AN41: 0 | AO41: 0
A42: 600 | B42: 650 | D42: 994 | G42: 309967200 | I42: 0 | J42: 1.0024458e-05 | L42: #DIV/0! | M42: 623.67646 | P42: ="("&$A42&", "&$B42&"]" -> (600, 650] | Q42: B | R42: =_xlfn.SINGLE(_xlfn.XLOOKUP(Q42, $I$4:$K$4, I42:K42)) -> 1.0024458e-05 | S42: 0 | T42: 0 | U42: 0 | V42: 0 | W42: 0 | X42: 0 | Y42: 0 | Z42: 0 | AA42: 0 | AB42: 0 | AC42: 0 | AD42: 0 | AE42: =_xlfn.LET(_xlpm.x, _xlfn.XLOOKUP($Q42, $L$4:$N$4, $L42:$N42), IF(ISERROR(_xlpm.x), 0, _xlpm.x)*AB42/$AB$3) -> 0 | AF42: 0 | AG42: =_xlfn.LET(_xlpm.x, _xlfn.XLOOKUP($Q42, $L$4:$N$4, $L42:$N42), IF(ISERROR(_xlpm.x), 0, _xlpm.x)*AC42/$AB$3) -> 0 | AH42: 0 | AI42: =_xlfn.LET(_xlpm.x, _xlfn.XLOOKUP($Q42, $L$4:$N$4, $L42:$N42), IF(ISERROR(_xlpm.x), 0, _xlpm.x)*AD42/$AB$3) -> 0 | AJ42: 0 | AL42: 3.7536505e-07 | AM42: 0 | AN42: 0 | AO42: 0
A43: 650 | B43: 700 | D43: 630 | G43: 211839550 | I43: 0 | J43: 6.3535296e-06 | L43: #DIV/0! | M43: 672.50651 | P43: ="("&$A43&", "&$B43&"]" -> (650, 700] | Q43: B | R43: =_xlfn.SINGLE(_xlfn.XLOOKUP(Q43, $I$4:$K$4, I43:K43)) -> 6.3535296e-06 | S43: 0 | T43: 0 | U43: 0 | V43: 0 | W43: 0 | X43: 0 | Y43: 0 | Z43: 0 | AA43: 0 | AB43: 0 | AC43: 0 | AD43: 0 | AE43: =_xlfn.LET(_xlpm.x, _xlfn.XLOOKUP($Q43, $L$4:$N$4, $L43:$N43), IF(ISERROR(_xlpm.x), 0, _xlpm.x)*AB43/$AB$3) -> 0 | AF43: 0 | AG43: =_xlfn.LET(_xlpm.x, _xlfn.XLOOKUP($Q43, $L$4:$N$4, $L43:$N43), IF(ISERROR(_xlpm.x), 0, _xlpm.x)*AC43/$AB$3) -> 0 | AH43: 0 | AI43: =_xlfn.LET(_xlpm.x, _xlfn.XLOOKUP($Q43, $L$4:$N$4, $L43:$N43), IF(ISERROR(_xlpm.x), 0, _xlpm.x)*AD43/$AB$3) -> 0 | AJ43: 0 | AL43: 3.0029204e-07 | AM43: 0 | AN43: 0 | AO43: 0
A44: 700 | B44: 750 | D44: 446 | G44: 161844225 | I44: 0 | J44: 4.4978956e-06 | L44: #DIV/0! | M44: 725.75886 | P44: ="("&$A44&", "&$B44&"]" -> (700, 750] | Q44: B | R44: =_xlfn.SINGLE(_xlfn.XLOOKUP(Q44, $I$4:$K$4, I44:K44)) -> 4.4978956e-06 | S44: 0 | T44: 0 | U44: 0 | V44: 0 | W44: 0 | X44: 0 | Y44: 0 | Z44: 0 | AA44: 0 | AB44: 0 | AC44: 0 | AD44: 0 | AE44: =_xlfn.LET(_xlpm.x, _xlfn.XLOOKUP($Q44, $L$4:$N$4, $L44:$N44), IF(ISERROR(_xlpm.x), 0, _xlpm.x)*AB44/$AB$3) -> 0 | AF44: 0 | AG44: =_xlfn.LET(_xlpm.x, _xlfn.XLOOKUP($Q44, $L$4:$N$4, $L44:$N44), IF(ISERROR(_xlpm.x), 0, _xlpm.x)*AC44/$AB$3) -> 0 | AH44: 0 | AI44: =_xlfn.LET(_xlpm.x, _xlfn.XLOOKUP($Q44, $L$4:$N$4, $L44:$N44), IF(ISERROR(_xlpm.x), 0, _xlpm.x)*AD44/$AB$3) -> 0 | AJ44: 0 | AL44: 7.5073009e-08 | AM44: 0 | AN44: 0 | AO44: 0
A45: 750 | B45: 800 | D45: 400 | G45: 154544850 | I45: 0 | J45: 4.0339871e-06 | L45: #DIV/0! | M45: 772.72425 | P45: ="("&$A45&", "&$B45&"]" -> (750, 800] | Q45: B | R45: =_xlfn.SINGLE(_xlfn.XLOOKUP(Q45, $I$4:$K$4, I45:K45)) -> 4.0339871e-06 | S45: 0 | T45: 0 | U45: 0 | V45: 0 | W45: 0 | X45: 0 | Y45: 0 | Z45: 0 | AA45: 0 | AB45: 0 | AC45: 0 | AD45: 0 | AE45: =_xlfn.LET(_xlpm.x, _xlfn.XLOOKUP($Q45, $L$4:$N$4, $L45:$N45), IF(ISERROR(_xlpm.x), 0, _xlpm.x)*AB45/$AB$3) -> 0 | AF45: 0 | AG45: =_xlfn.LET(_xlpm.x, _xlfn.XLOOKUP($Q45, $L$4:$N$4, $L45:$N45), IF(ISERROR(_xlpm.x), 0, _xlpm.x)*AC45/$AB$3) -> 0 | AH45: 0 | AI45: =_xlfn.LET(_xlpm.x, _xlfn.XLOOKUP($Q45, $L$4:$N$4, $L45:$N45), IF(ISERROR(_xlpm.x), 0, _xlpm.x)*AD45/$AB$3) -> 0 | AJ45: 0 | AL45: 1.5014602e-07 | AM45: 0 | AN45: 0 | AO45: 0
A46: 800 | B46: 850 | D46: 222 | G46: 91442900 | I46: 0 | J46: 2.2388628e-06 | L46: #DIV/0! | M46: 823.80991 | P46: ="("&$A46&", "&$B46&"]" -> (800, 850] | Q46: B | R46: =_xlfn.SINGLE(_xlfn.XLOOKUP(Q46, $I$4:$K$4, I46:K46)) -> 2.2388628e-06 | S46: 0 | T46: 0 | U46: 0 | V46: 0 | W46: 0 | X46: 0 | Y46: 0 | Z46: 0 | AA46: 0 | AB46: 0 | AC46: 0 | AD46: 0 | AE46: =_xlfn.LET(_xlpm.x, _xlfn.XLOOKUP($Q46, $L$4:$N$4, $L46:$N46), IF(ISERROR(_xlpm.x), 0, _xlpm.x)*AB46/$AB$3) -> 0 | AF46: 0 | AG46: =_xlfn.LET(_xlpm.x, _xlfn.XLOOKUP($Q46, $L$4:$N$4, $L46:$N46), IF(ISERROR(_xlpm.x), 0, _xlpm.x)*AC46/$AB$3) -> 0 | AH46: 0 | AI46: =_xlfn.LET(_xlpm.x, _xlfn.XLOOKUP($Q46, $L$4:$N$4, $L46:$N46), IF(ISERROR(_xlpm.x), 0, _xlpm.x)*AD46/$AB$3) -> 0 | AJ46: 0 | AL46: 1.5014602e-07 | AM46: 0 | AN46: 0 | AO46: 0
A47: 850 | B47: 900 | D47: 141 | G47: 61482425 | I47: 0 | J47: 1.4219804e-06 | L47: #DIV/0! | M47: 872.09113 | P47: ="("&$A47&", "&$B47&"]" -> (850, 900] | Q47: B | R47: =_xlfn.SINGLE(_xlfn.XLOOKUP(Q47, $I$4:$K$4, I47:K47)) -> 1.4219804e-06 | S47: 0 | T47: 0 | U47: 0 | V47: 0 | W47: 0 | X47: 0 | Y47: 0 | Z47: 0 | AA47: 0 | AB47: 0 | AC47: 0 | AD47: 0 | AE47: =_xlfn.LET(_xlpm.x, _xlfn.XLOOKUP($Q47, $L$4:$N$4, $L47:$N47), IF(ISERROR(_xlpm.x), 0, _xlpm.x)*AB47/$AB$3) -> 0 | AF47: 0 | AG47: =_xlfn.LET(_xlpm.x, _xlfn.XLOOKUP($Q47, $L$4:$N$4, $L47:$N47), IF(ISERROR(_xlpm.x), 0, _xlpm.x)*AC47/$AB$3) -> 0 | AH47: 0 | AI47: =_xlfn.LET(_xlpm.x, _xlfn.XLOOKUP($Q47, $L$4:$N$4, $L47:$N47), IF(ISERROR(_xlpm.x), 0, _xlpm.x)*AD47/$AB$3) -> 0 | AJ47: 0 | AL47: 7.5073009e-08 | AM47: 0 | AN47: 0 | AO47: 0
... A51: 2000 | B51: 3000 | D51: 1 | G51: 1044650 | I51: 0 | J51: 1.0084968e-08 | L51: #DIV/0! | M51: 2089.3 | P51: ="("&$A51&", "&$B51&"]" -> (2000, 3000] | Q51: B | R51: =_xlfn.SINGLE(_xlfn.XLOOKUP(Q51, $I$4:$K$4, I51:K51)) -> 1.0084968e-08 | S51: 0 | T51: 0 | U51: 0 | V51: 0 | W51: 0 | X51: 0 | Y51: 0 | Z51: 0 | AA51: 0 | AB51: 0 | AC51: 0 | AD51: 0 | AE51: =_xlfn.LET(_xlpm.x, _xlfn.XLOOKUP($Q51, $L$4:$N$4, $L51:$N51), IF(ISERROR(_xlpm.x), 0, _xlpm.x)*AB51/$AB$3) -> 0 | AF51: 0 | AG51: =_xlfn.LET(_xlpm.x, _xlfn.XLOOKUP($Q51, $L$4:$N$4, $L51:$N51), IF(ISERROR(_xlpm.x), 0, _xlpm.x)*AC51/$AB$3) -> 0 | AH51: 0 | AI51: =_xlfn.LET(_xlpm.x, _xlfn.XLOOKUP($Q51, $L$4:$N$4, $L51:$N51), IF(ISERROR(_xlpm.x), 0, _xlpm.x)*AD51/$AB$3) -> 0 | AJ51: 0 | AL51: 0 | AM51: 0 | AN51: 0 | AO51: 0
A52: 3000 | B52: 4000 | I52: 0 | J52: 0 | L52: #DIV/0! | M52: #DIV/0! | P52: ="("&$A52&", "&$B52&"]" -> (3000, 4000] | Q52: B | R52: =_xlfn.SINGLE(_xlfn.XLOOKUP(Q52, $I$4:$K$4, I52:K52)) -> 0 | S52: 0 | T52: 0 | U52: 0 | V52: 0 | W52: 0 | X52: 0 | Y52: 0 | Z52: 0 | AA52: 0 | AB52: 0 | AC52: 0 | AD52: 0 | AE52: =_xlfn.LET(_xlpm.x, _xlfn.XLOOKUP($Q52, $L$4:$N$4, $L52:$N52), IF(ISERROR(_xlpm.x), 0, _xlpm.x)*AB52/$AB$3) -> 0 | AF52: 0 | AG52: =_xlfn.LET(_xlpm.x, _xlfn.XLOOKUP($Q52, $L$4:$N$4, $L52:$N52), IF(ISERROR(_xlpm.x), 0, _xlpm.x)*AC52/$AB$3) -> 0 | AH52: 0 | AI52: =_xlfn.LET(_xlpm.x, _xlfn.XLOOKUP($Q52, $L$4:$N$4, $L52:$N52), IF(ISERROR(_xlpm.x), 0, _xlpm.x)*AD52/$AB$3) -> 0 | AJ52: 0 | AL52: 4.5043806e-07 | AM52: 0 | AN52: 0 | AO52: 0
A53: 4000 | B53: 5000 | I53: 0 | J53: 0 | L53: #DIV/0! | M53: #DIV/0! | P53: ="("&$A53&", "&$B53&"]" -> (4000, 5000] | Q53: B | R53: =_xlfn.SINGLE(_xlfn.XLOOKUP(Q53, $I$4:$K$4, I53:K53)) -> 0 | S53: 0 | T53: 0 | U53: 0 | V53: 0 | W53: 0 | X53: 0 | Y53: 0 | Z53: 0 | AA53: 0 | AB53: 0 | AC53: 0 | AD53: 0 | AE53: =_xlfn.LET(_xlpm.x, _xlfn.XLOOKUP($Q53, $L$4:$N$4, $L53:$N53), IF(ISERROR(_xlpm.x), 0, _xlpm.x)*AB53/$AB$3) -> 0 | AF53: 0 | AG53: =_xlfn.LET(_xlpm.x, _xlfn.XLOOKUP($Q53, $L$4:$N$4, $L53:$N53), IF(ISERROR(_xlpm.x), 0, _xlpm.x)*AC53/$AB$3) -> 0 | AH53: 0 | AI53: =_xlfn.LET(_xlpm.x, _xlfn.XLOOKUP($Q53, $L$4:$N$4, $L53:$N53), IF(ISERROR(_xlpm.x), 0, _xlpm.x)*AD53/$AB$3) -> 0 | AJ53: 0 | AL53: 1.1260951e-07 | AM53: 0 | AN53: 0 | AO53: 0
A54: 5000 | B54: 6000 | I54: 0 | J54: 0 | L54: #DIV/0! | M54: #DIV/0! | P54: ="("&$A54&", "&$B54&"]" -> (5000, 6000] | Q54: B | R54: =_xlfn.SINGLE(_xlfn.XLOOKUP(Q54, $I$4:$K$4, I54:K54)) -> 0 | S54: 0 | T54: 0 | U54: 0 | V54: 0 | W54: 0 | X54: 0 | Y54: 0 | Z54: 0 | AA54: 0 | AB54: 0 | AC54: 0 | AD54: 0 | AE54: =_xlfn.LET(_xlpm.x, _xlfn.XLOOKUP($Q54, $L$4:$N$4, $L54:$N54), IF(ISERROR(_xlpm.x), 0, _xlpm.x)*AB54/$AB$3) -> 0 | AF54: 0 | AG54: =_xlfn.LET(_xlpm.x, _xlfn.XLOOKUP($Q54, $L$4:$N$4, $L54:$N54), IF(ISERROR(_xlpm.x), 0, _xlpm.x)*AC54/$AB$3) -> 0 | AH54: 0 | AI54: =_xlfn.LET(_xlpm.x, _xlfn.XLOOKUP($Q54, $L$4:$N$4, $L54:$N54), IF(ISERROR(_xlpm.x), 0, _xlpm.x)*AD54/$AB$3) -> 0 | AJ54: 0 | AL54: 3.7536505e-08 | AM54: 0 | AN54: 0 | AO54: 0
A55: 6000 | B55: 7000 | I55: 0 | J55: 0 | L55: #DIV/0! | M55: #DIV/0! | P55: ="("&$A55&", "&$B55&"]" -> (6000, 7000] | Q55: B | R55: =_xlfn.SINGLE(_xlfn.XLOOKUP(Q55, $I$4:$K$4, I55:K55)) -> 0 | S55: 0 | T55: 0 | U55: 0 | V55: 0 | W55: 0 | X55: 0 | Y55: 0 | Z55: 0 | AA55: 0 | AB55: 0 | AC55: 0 | AD55: 0 | AE55: =_xlfn.LET(_xlpm.x, _xlfn.XLOOKUP($Q55, $L$4:$N$4, $L55:$N55), IF(ISERROR(_xlpm.x), 0, _xlpm.x)*AB55/$AB$3) -> 0 | AF55: 0 | AG55: =_xlfn.LET(_xlpm.x, _xlfn.XLOOKUP($Q55, $L$4:$N$4, $L55:$N55), IF(ISERROR(_xlpm.x), 0, _xlpm.x)*AC55/$AB$3) -> 0 | AH55: 0 | AI55: =_xlfn.LET(_xlpm.x, _xlfn.XLOOKUP($Q55, $L$4:$N$4, $L55:$N55), IF(ISERROR(_xlpm.x), 0, _xlpm.x)*AD55/$AB$3) -> 0 | AJ55: 0 | AL55: 0 | AM55: 0 | AN55: 0 | AO55: 0
A56: 7000 | B56: 8000 | I56: 0 | J56: 0 | L56: #DIV/0! | M56: #DIV/0! | P56: ="("&$A56&", "&$B56&"]" -> (7000, 8000] | Q56: B | R56: =_xlfn.SINGLE(_xlfn.XLOOKUP(Q56, $I$4:$K$4, I56:K56)) -> 0 | S56: 0 | T56: 0 | U56: 0 | V56: 0 | W56: 0 | X56: 0 | Y56: 0 | Z56: 0 | AA56: 0 | AB56: 0 | AC56: 0 | AD56: 0 | AE56: =_xlfn.LET(_xlpm.x, _xlfn.XLOOKUP($Q56, $L$4:$N$4, $L56:$N56), IF(ISERROR(_xlpm.x), 0, _xlpm.x)*AB56/$AB$3) -> 0 | AF56: 0 | AG56: =_xlfn.LET(_xlpm.x, _xlfn.XLOOKUP($Q56, $L$4:$N$4, $L56:$N56), IF(ISERROR(_xlpm.x), 0, _xlpm.x)*AC56/$AB$3) -> 0 | AH56: 0 | AI56: =_xlfn.LET(_xlpm.x, _xlfn.XLOOKUP($Q56, $L$4:$N$4, $L56:$N56), IF(ISERROR(_xlpm.x), 0, _xlpm.x)*AD56/$AB$3) -> 0 | AJ56: 0 | AL56: 3.7536505e-08 | AM56: 0 | AN56: 0 | AO56: 0
A57: FG Trigger | B57: =C57/SUM(C5:C57) -> 0.01010016 | C57: 1010016 | D57: 842518 | F57: 184759625 | G57: 12104979525 | P57: FG Trigger | Q57: A | R57: =0.00849 -> 0.00849 | S57: 1 | T57: 1 | U57: 1 | V57: 0.00849 | W57: 0.00849 | X57: 0.00849 | Y57: =V57 -> 0.00849 | Z57: =V57 -> 0.00849 | AA57: =V57 -> 0.00849 | AB57: 8490000 | AC57: 8490000 | AD57: 8490000 | AE57: =F57/C57/500*AB57/AB3 -> 0.0031061077 | AF57: 0.00849 | AG57: =F57/C57/500*AB57/AB3 -> 0.0031061077 | AH57: 0.00849 | AI57: =F57/C57/500*AB57/AB3 -> 0.0031061077 | AJ57: 0.00849
A58: 0.001
AF61: 新手 | AH61: 老手 | AJ61: 未啟用
A62: Lower | B62: Upper | C62: Simulator Cnt | F62: Simulator Pay | I62: Simulator Rate | L62: Simulator RTP | P62: Range | Q62: Free Game | Y62: Threshold | AB62: =10^9 -> 1000000000 | AE62: Free Game 1 RTP | AF62: =SUM(AE64:AE122)*AF57 -> 0.26678737 | AG62: Free Game 2 RTP | AH62: =SUM(AG64:AG122)*AH57 -> 0.2728177 | AI62: Free Game 3 RTP | AJ62: =SUM(AI64:AI122)*AJ57 -> 0.30013259
...

Sheet OP Jack Pot
A1: 新手 | F1: 老手 | K1: Buy Feature | P1: Buy Super Feature
B2: Num | C2: Normal Bet | G2: Num | H2: Base Game | L2: Num | M2: Base Game | Q2: Num | R2: Base Game
A3: bgC1Count | B3: 0 | C3: 68973231 | F3: bgC1Count | G3: 0 | H3: 69402436 | K3: bgC1Count | L3: 0 | M3: 0 | P3: bgC1Count | Q3: 0 | R3: 0 | S3: =SUMPRODUCT(R3:R17,Q3:Q17)/SUM(R3:R9) -> 4.9352015
A4: bgC1Count | B4: 1 | C4: 26114515 | F4: bgC1Count | G4: 1 | H4: 25844647 | K4: bgC1Count | L4: 1 | M4: 0 | P4: bgC1Count | Q4: 1 | R4: 0
A5: bgC1Count | B5: 2 | C5: 4065821 | F5: bgC1Count | G5: 2 | H5: 3905458 | K5: bgC1Count | L5: 2 | M5: 0 | P5: bgC1Count | Q5: 2 | R5: 0
A6: bgC1Count | B6: 3 | C6: 795808 | F6: bgC1Count | G6: 3 | H6: 797096 | K6: bgC1Count | L6: 3 | M6: 4994541 | P6: bgC1Count | Q6: 3 | R6: 1997776
A7: bgC1Count | B7: 4 | C7: 48889 | F7: bgC1Count | G7: 4 | H7: 48596 | K7: bgC1Count | L7: 4 | M7: 5125 | P7: bgC1Count | Q7: 4 | R7: 2085
A8: bgC1Count | B8: 5 | C8: 1686 | F8: bgC1Count | G8: 5 | H8: 1709 | K8: bgC1Count | L8: 5 | M8: 320 | P8: bgC1Count | Q8: 5 | R8: 133
A9: bgC1Count | B9: 6 | C9: 50 | F9: bgC1Count | G9: 6 | H9: 58 | K9: bgC1Count | L9: 6 | M9: 14 | P9: bgC1Count | Q9: 6 | R9: 6
A11: fgC1Count | B11: 0 | C11: 5773921 | F11: fgC1Count | G11: 0 | H11: 5788195 | K11: fgC1Count | L11: 0 | M11: 34194899 | P11: fgC1Count | Q11: 0 | R11: 16483814
A12: fgC1Count | B12: 1 | C12: 2338724 | F12: fgC1Count | G12: 1 | H12: 2339282 | K12: fgC1Count | L12: 1 | M12: 13798140 | P12: fgC1Count | Q12: 1 | R12: 3221899
A13: fgC1Count | B13: 2 | C13: 409449 | F13: fgC1Count | G13: 2 | H13: 406313 | K13: fgC1Count | L13: 2 | M13: 2396261 | P13: fgC1Count | Q13: 2 | R13: 315063
A14: fgC1Count | B14: 3 | C14: 13453 | F14: fgC1Count | G14: 3 | H14: 13765 | K14: fgC1Count | L14: 3 | M14: 89848 | P14: fgC1Count | Q14: 3 | R14: 4798
A15: fgC1Count | B15: 4 | C15: 938 | F15: fgC1Count | G15: 4 | H15: 980 | K15: fgC1Count | L15: 4 | M15: 6949 | P15: fgC1Count | Q15: 4 | R15: 369
A16: fgC1Count | B16: 5 | C16: 46 | F16: fgC1Count | G16: 5 | H16: 52 | K16: fgC1Count | L16: 5 | M16: 493 | P16: fgC1Count | Q16: 5 | R16: 23
A17: fgC1Count | B17: 6 | C17: 4 | F17: fgC1Count | G17: 6 | H17: 3 | K17: fgC1Count | L17: 6 | M17: 35 | P17: fgC1Count | Q17: 6 | R17: 4
A18: SC Trig | C18: =_xlfn.FLOOR.MATH(SUM(C4:C9,C12:C17)/SUM(C3:C9)*10^10) -> 3378938300 | F18: SC Trig | H18: =_xlfn.FLOOR.MATH(SUM(H4:H9,H12:H17)/SUM(H3:H9)*10^10) -> 3335795900 | K18: SC Trig | M18: =_xlfn.FLOOR.MATH(SUM(M4:M9,M12:M17)/SUM(M3:M9)*10^10) -> 42583452000 | P18: SC Trig | R18: =_xlfn.FLOOR.MATH(SUM(R4:R9,R12:R17)/SUM(R3:R9)*10^10) -> 27710780000

Sheet Description
B2: Base Game
B3: 1. 在Base Game中每次Spin時，按照卡片系統對應到的表不斷抽取直到抽取出對應區間。
C4: 種類 | F4: ID
C5: Base Game Symbol - High | F5: B
C6: Base Game Symbol - Low | F6: A
B7: 2. 初始盤面依照選到的Base Game Symbol中5個轉輪表，並依照"Symbol Weight"權重決定RNG，再依照權重決定MY的Symbol。
B8: 3. 若有連線，則消除連線標誌，並從輪帶中隨機抽取一格來補上空格。
B9: 4. 當Combo隨著消除上升時，得分倍率也會跟著上升，倍數為X1、X2、X3、X5、X10，達到X10時就不會再上升了。
B10: 5. 隨機百搭判定:
C11: (1) 當連線的盤面有消除到至少一個金框符號(M1G~JG)，會進行以下的判定。
C12: (2) 每次的SPIN都會有一個是否已經出現隨機百搭的FLAG，當這個FLAG還沒觸發過時每次的Combo只要有消除到金框符號時都會進行一次判定，當FLAG被使用過之後後續的Combo就不用走這個判定。
C13: (3) 當消到金框符號時，根據Random Wild的權重，如果骰到2~4，則會將目前這格取代為WW2，並且額外複製2~4個WW2，並取代掉R2~R5當中隨機的格子，不會蓋掉原本是C1、WW1、WW2的格子。
C14: (4) 當有多個金框符號都被使用到時，一樣走上面的判定，但是最多只會有其中一個金框符號觸發隨機百搭，其餘都是取代成WW1。
C15: (5) 順序是: 消除→補格子→所有金框符號瞇牌→所有金框那格變成WW1或WW2→如果有複製WW2，等前面的步驟跑完了再處理要蓋掉哪些格子。
B16: 6. 每一次連線消除後，有機會掉落C1，同一輪中可以出現超過1個C1。
B17: 7. C1在連線消除過程中，並不會連線消除，直到已經無法再連線時，才會計算場上C1，決定是否進入Free Spins。
B19: Free Game
B20: 1. 進入Free Game後依照卡片系統對應表獲得指定場數的高表與低表，獲得的順序隨機排列，持續抽取直到抽取出對應區間。
C21: D | G21: E
C22: 高表場數 | D22: 低表場數 | E22: Weight | G22: 高表場數 | H22: 低表場數 | I22: Weight
C23: 0 | D23: 10 | E23: 1 | G23: 0 | H23: 10 | I23: 0
C24: 3 | D24: 7 | E24: 0 | G24: 3 | H24: 7 | I24: 0
C25: 4 | D25: 6 | E25: 0 | G25: 4 | H25: 6 | I25: 0
C26: 5 | D26: 5 | E26: 0 | G26: 5 | H26: 5 | I26: 0
C27: 6 | D27: 4 | E27: 0 | G27: 6 | H27: 4 | I27: 0
C28: 10 | D28: 0 | E28: 0 | G28: 10 | H28: 0 | I28: 1
B29: 2. 在Free Game中每次Spin時，如果這次是高表則使用"Free Game Symbol - High"的表，如果這次是低表則使用"Free Game Symbol - Low"的表，依照"Symbol Weight"權重決定RNG，並依照權重決定MY的Symbol。
C30: 高表Symbol輪帶 | E30: Weight
C31: A | E31: 1
C32: K | E32: 1
C33: Q | E33: 1
C34: J | E34: 1
B35: 3. 在Free Game中獲得3顆以上C1時，固定增加5場，其中會有1場高表與4場低表，獲得的順序也是隨機排列。
B36: 4. 若有連線，則消除連線標誌，並從輪帶中隨機抽取一格來補上空格。
B37: 5. 當Combo隨著消除上升時，得分倍率也會跟著上升，倍數為X2、X4、X6、X10、X20，達到X20時就不會再上升了。
B38: 6. 隨機百搭判定:
C39: (1) 當連線的盤面有消除到至少一個金框符號(M1G~JG)，會進行以下的判定。
C40: (2) 每次的SPIN都會有一個是否已經出現隨機百搭的FLAG，當這個FLAG還沒觸發過時每次的Combo只要有消除到金框符號時都會進行一次判定，當FLAG被使用過之後後續的Combo就不用走這個判定。
C41: (3) 當消到金框符號時，根據Random Wild的權重，如果骰到2~4，則會將目前這格取代為WW2，並且額外複製2~4個WW2，並取代掉R2~R5當中隨機的格子，不會蓋掉原本是C1、WW1、WW2的格子。
C42: (4) 當有多個金框符號都被使用到時，一樣走上面的判定，但是最多只會有其中一個金框符號觸發隨機百搭，其餘都是取代成WW1。
...

Sheet Symbol Weight
A1: Symbol
A2: Base Game Symbol - High | H2: Base Game Symbol - Low | O2: Free Game Symbol - High | V2: Free Game Symbol - Low | AC2: Buy Feature Symbol | AJ2: Super Buy Feature Symbol
B4: R1 | C4: R2 | D4: R3 | E4: R4 | F4: R5 | I4: R1 | J4: R2 | K4: R3 | L4: R4 | M4: R5 | P4: R1 | Q4: R2 | R4: R3 | S4: R4 | T4: R5 | W4: R1 | X4: R2 | Y4: R3 | Z4: R4 | AA4: R5 | AD4: R1 | AE4: R2 | AF4: R3 | AG4: R4 | AH4: R5 | AK4: R1 | AL4: R2 | AM4: R3 | AN4: R4 | AO4: R5
A5: 0 | B5: 1 | C5: 1 | D5: 1 | E5: 1 | F5: 1 | H5: 0 | I5: 1 | J5: 1 | K5: 1 | L5: 1 | M5: 1 | O5: 0 | P5: 1 | Q5: 1 | R5: 1 | S5: 1 | T5: 1 | V5: 0 | W5: 1 | X5: 1 | Y5: 1 | Z5: 1 | AA5: 1 | AC5: 0 | AD5: 1 | AE5: 1 | AF5: 1 | AG5: 1 | AH5: 1 | AJ5: 0 | AK5: 1 | AL5: 1 | AM5: 1 | AN5: 1 | AO5: 1
A6: 1 | B6: 1 | C6: 1 | D6: 1 | E6: 1 | F6: 1 | H6: 1 | I6: 1 | J6: 1 | K6: 1 | L6: 1 | M6: 1 | O6: 1 | P6: 1 | Q6: 1 | R6: 1 | S6: 1 | T6: 1 | V6: 1 | W6: 1 | X6: 1 | Y6: 1 | Z6: 1 | AA6: 1 | AC6: 1 | AD6: 1 | AE6: 1 | AF6: 1 | AG6: 1 | AH6: 1 | AJ6: 1 | AK6: 1 | AL6: 1 | AM6: 1 | AN6: 1 | AO6: 1
A7: 2 | B7: 1 | C7: 1 | D7: 1 | E7: 1 | F7: 1 | H7: 2 | I7: 1 | J7: 1 | K7: 1 | L7: 1 | M7: 1 | O7: 2 | P7: 1 | Q7: 1 | R7: 1 | S7: 1 | T7: 1 | V7: 2 | W7: 1 | X7: 1 | Y7: 1 | Z7: 1 | AA7: 1 | AC7: 2 | AD7: 1 | AE7: 1 | AF7: 1 | AG7: 1 | AH7: 1 | AJ7: 2 | AK7: 1 | AL7: 1 | AM7: 1 | AN7: 1 | AO7: 1
A8: 3 | B8: 1 | C8: 1 | D8: 1 | E8: 1 | F8: 1 | H8: 3 | I8: 1 | J8: 1 | K8: 1 | L8: 1 | M8: 1 | O8: 3 | P8: 1 | Q8: 1 | R8: 1 | S8: 1 | T8: 1 | V8: 3 | W8: 1 | X8: 1 | Y8: 1 | Z8: 1 | AA8: 1 | AC8: 3 | AD8: 1 | AE8: 1 | AF8: 1 | AG8: 1 | AH8: 1 | AJ8: 3 | AK8: 1 | AL8: 1 | AM8: 1 | AN8: 1 | AO8: 1
A9: 4 | B9: 1 | C9: 1 | D9: 1 | E9: 1 | F9: 1 | H9: 4 | I9: 1 | J9: 1 | K9: 1 | L9: 1 | M9: 1 | O9: 4 | P9: 1 | Q9: 1 | R9: 1 | S9: 1 | T9: 1 | V9: 4 | W9: 1 | X9: 1 | Y9: 1 | Z9: 1 | AA9: 1 | AC9: 4 | AD9: 0 | AE9: 0 | AF9: 0 | AG9: 1 | AH9: 1 | AJ9: 4 | AK9: 1 | AL9: 1 | AM9: 1 | AN9: 1 | AO9: 1
A10: 5 | B10: 1 | C10: 1 | D10: 1 | E10: 1 | F10: 1 | H10: 5 | I10: 1 | J10: 1 | K10: 1 | L10: 1 | M10: 1 | O10: 5 | P10: 1 | Q10: 1 | R10: 1 | S10: 1 | T10: 1 | V10: 5 | W10: 1 | X10: 1 | Y10: 1 | Z10: 1 | AA10: 1 | AC10: 5 | AD10: 0 | AE10: 0 | AF10: 0 | AG10: 1 | AH10: 1 | AJ10: 5 | AK10: 1 | AL10: 1 | AM10: 1 | AN10: 1 | AO10: 1
A11: 6 | B11: 1 | C11: 1 | D11: 1 | E11: 1 | F11: 1 | H11: 6 | I11: 1 | J11: 1 | K11: 1 | L11: 1 | M11: 1 | O11: 6 | P11: 1 | Q11: 1 | R11: 1 | S11: 1 | T11: 1 | V11: 6 | W11: 1 | X11: 1 | Y11: 1 | Z11: 1 | AA11: 1 | AC11: 6 | AD11: 0 | AE11: 0 | AF11: 0 | AG11: 1 | AH11: 1 | AJ11: 6 | AK11: 1 | AL11: 1 | AM11: 1 | AN11: 1 | AO11: 1
A12: 7 | B12: 1 | C12: 1 | D12: 1 | E12: 1 | F12: 1 | H12: 7 | I12: 1 | J12: 1 | K12: 1 | L12: 1 | M12: 1 | O12: 7 | P12: 1 | Q12: 1 | R12: 1 | S12: 1 | T12: 1 | V12: 7 | W12: 1 | X12: 1 | Y12: 1 | Z12: 1 | AA12: 1 | AC12: 7 | AD12: 0 | AE12: 0 | AF12: 0 | AG12: 1 | AH12: 1 | AJ12: 7 | AK12: 1 | AL12: 1 | AM12: 1 | AN12: 1 | AO12: 1
A13: 8 | B13: 1 | C13: 1 | D13: 1 | E13: 1 | F13: 1 | H13: 8 | I13: 1 | J13: 1 | K13: 1 | L13: 1 | M13: 1 | O13: 8 | P13: 1 | Q13: 1 | R13: 1 | S13: 1 | T13: 1 | V13: 8 | W13: 1 | X13: 1 | Y13: 1 | Z13: 1 | AA13: 1 | AC13: 8 | AD13: 0 | AE13: 0 | AF13: 0 | AG13: 1 | AH13: 1 | AJ13: 8 | AK13: 1 | AL13: 1 | AM13: 1 | AN13: 1 | AO13: 1
A14: 9 | B14: 1 | C14: 1 | D14: 1 | E14: 1 | F14: 1 | H14: 9 | I14: 1 | J14: 1 | K14: 1 | L14: 1 | M14: 1 | O14: 9 | P14: 1 | Q14: 1 | R14: 1 | S14: 1 | T14: 1 | V14: 9 | W14: 1 | X14: 1 | Y14: 1 | Z14: 1 | AA14: 1 | AC14: 9 | AD14: 0 | AE14: 0 | AF14: 0 | AG14: 1 | AH14: 1 | AJ14: 9 | AK14: 1 | AL14: 1 | AM14: 1 | AN14: 1 | AO14: 1
A15: 10 | B15: 1 | C15: 1 | D15: 1 | E15: 1 | F15: 1 | H15: 10 | I15: 1 | J15: 1 | K15: 1 | L15: 1 | M15: 1 | O15: 10 | P15: 1 | Q15: 1 | R15: 1 | S15: 1 | T15: 1 | V15: 10 | W15: 1 | X15: 1 | Y15: 1 | Z15: 1 | AA15: 1 | AC15: 10 | AD15: 0 | AE15: 0 | AF15: 0 | AG15: 1 | AH15: 1 | AJ15: 10 | AK15: 1 | AL15: 1 | AM15: 1 | AN15: 1 | AO15: 1
A16: 11 | B16: 1 | C16: 1 | D16: 1 | E16: 1 | F16: 1 | H16: 11 | I16: 1 | J16: 1 | K16: 1 | L16: 1 | M16: 1 | O16: 11 | P16: 1 | Q16: 1 | R16: 1 | S16: 1 | T16: 1 | V16: 11 | W16: 1 | X16: 1 | Y16: 1 | Z16: 1 | AA16: 1 | AC16: 11 | AD16: 0 | AE16: 0 | AF16: 0 | AG16: 1 | AH16: 1 | AJ16: 11 | AK16: 1 | AL16: 1 | AM16: 1 | AN16: 1 | AO16: 1
... A404: 399 | B404: 1 | C404: 1 | D404: 1 | E404: 1 | F404: 1 | H404: 399 | I404: 1 | J404: 1 | K404: 1 | L404: 1 | M404: 1 | O404: 399 | P404: 1 | Q404: 1 | R404: 1 | S404: 1 | T404: 1 | V404: 399 | W404: 1 | X404: 1 | Y404: 1 | Z404: 1 | AA404: 1 | AC404: 399 | AD404: 0 | AE404: 0 | AF404: 0 | AG404: 1 | AH404: 1 | AJ404: 399 | AK404: 1 | AL404: 1 | AM404: 1 | AN404: 1 | AO404: 1

Sheet Base Game Symbol - High
J2: Symbol | Q2: ID | W2: Description | AC2: Random Wild | AD2: Weight
A3: Symbol | B3: Description | C3: R1 | D3: R2 | E3: R3 | F3: R4 | G3: R5 | H3: ID | J3: Line # | K3: R1 | L3: R2 | M3: R3 | N3: R4 | O3: R5 | Q3: R1 | R3: R2 | S3: R3 | T3: R4 | U3: R5 | W3: R1 | X3: R2 | Y3: R3 | Z3: R4 | AA3: R5 | AC3: 0 | AD3: 26128
A4: WW1 | B4: Wild1 | C4: =COUNTIF(K:K,$A4) -> 0 | D4: =COUNTIF(L:L,$A4) -> 0 | E4: =COUNTIF(M:M,$A4) -> 0 | F4: =COUNTIF(N:N,$A4) -> 0 | G4: =COUNTIF(O:O,$A4) -> 0 | H4: 0 | J4: 0 | K4: K | L4: M1G | M4: J | N4: J | O4: J | Q4: =IF(K4="","",VLOOKUP(K4,$A:$H,8,FALSE)) -> 8 | R4: =IF(L4="","",VLOOKUP(L4,$A:$H,8,FALSE)) -> 11 | S4: =IF(M4="","",VLOOKUP(M4,$A:$H,8,FALSE)) -> 10 | T4: =IF(N4="","",VLOOKUP(N4,$A:$H,8,FALSE)) -> 10 | U4: =IF(O4="","",VLOOKUP(O4,$A:$H,8,FALSE)) -> 10 | W4: =IF(K4="","",VLOOKUP(K4,$A:$H,2,FALSE)) -> K | X4: =IF(L4="","",VLOOKUP(L4,$A:$H,2,FALSE)) -> M1G | Y4: =IF(M4="","",VLOOKUP(M4,$A:$H,2,FALSE)) -> J | Z4: =IF(N4="","",VLOOKUP(N4,$A:$H,2,FALSE)) -> J | AA4: =IF(O4="","",VLOOKUP(O4,$A:$H,2,FALSE)) -> J | AC4: 2 | AD4: 4404
A5: WW2 | B5: Wild2 | C5: =COUNTIF(K:K,$A5) -> 0 | D5: =COUNTIF(L:L,$A5) -> 0 | E5: =COUNTIF(M:M,$A5) -> 0 | F5: =COUNTIF(N:N,$A5) -> 0 | G5: =COUNTIF(O:O,$A5) -> 0 | H5: 1 | J5: 1 | K5: K | L5: M1 | M5: AG | N5: M4 | O5: Q | Q5: =IF(K5="","",VLOOKUP(K5,$A:$H,8,FALSE)) -> 8 | R5: =IF(L5="","",VLOOKUP(L5,$A:$H,8,FALSE)) -> 3 | S5: =IF(M5="","",VLOOKUP(M5,$A:$H,8,FALSE)) -> 15 | T5: =IF(N5="","",VLOOKUP(N5,$A:$H,8,FALSE)) -> 6 | U5: =IF(O5="","",VLOOKUP(O5,$A:$H,8,FALSE)) -> 9 | W5: =IF(K5="","",VLOOKUP(K5,$A:$H,2,FALSE)) -> K | X5: =IF(L5="","",VLOOKUP(L5,$A:$H,2,FALSE)) -> M1 | Y5: =IF(M5="","",VLOOKUP(M5,$A:$H,2,FALSE)) -> AG | Z5: =IF(N5="","",VLOOKUP(N5,$A:$H,2,FALSE)) -> M4 | AA5: =IF(O5="","",VLOOKUP(O5,$A:$H,2,FALSE)) -> Q | AC5: 3 | AD5: 1101
A6: C1 | B6: Scatter | C6: =COUNTIF(K:K,$A6) -> 5 | D6: =COUNTIF(L:L,$A6) -> 8 | E6: =COUNTIF(M:M,$A6) -> 8 | F6: =COUNTIF(N:N,$A6) -> 4 | G6: =COUNTIF(O:O,$A6) -> 4 | H6: 2 | J6: 2 | K6: Q | L6: Q | M6: M2 | N6: M1G | O6: J | Q6: =IF(K6="","",VLOOKUP(K6,$A:$H,8,FALSE)) -> 9 | R6: =IF(L6="","",VLOOKUP(L6,$A:$H,8,FALSE)) -> 9 | S6: =IF(M6="","",VLOOKUP(M6,$A:$H,8,FALSE)) -> 4 | T6: =IF(N6="","",VLOOKUP(N6,$A:$H,8,FALSE)) -> 11 | U6: =IF(O6="","",VLOOKUP(O6,$A:$H,8,FALSE)) -> 10 | W6: =IF(K6="","",VLOOKUP(K6,$A:$H,2,FALSE)) -> Q | X6: =IF(L6="","",VLOOKUP(L6,$A:$H,2,FALSE)) -> Q | Y6: =IF(M6="","",VLOOKUP(M6,$A:$H,2,FALSE)) -> M2 | Z6: =IF(N6="","",VLOOKUP(N6,$A:$H,2,FALSE)) -> M1G | AA6: =IF(O6="","",VLOOKUP(O6,$A:$H,2,FALSE)) -> J | AC6: 4 | AD6: 367
A7: M1 | B7: M1 | C7: =COUNTIF(K:K,$A7) -> 27 | D7: =COUNTIF(L:L,$A7) -> 22 | E7: =COUNTIF(M:M,$A7) -> 24 | F7: =COUNTIF(N:N,$A7) -> 28 | G7: =COUNTIF(O:O,$A7) -> 32 | H7: 3 | J7: 3 | K7: A | L7: KG | M7: A | N7: A | O7: J | Q7: =IF(K7="","",VLOOKUP(K7,$A:$H,8,FALSE)) -> 7 | R7: =IF(L7="","",VLOOKUP(L7,$A:$H,8,FALSE)) -> 16 | S7: =IF(M7="","",VLOOKUP(M7,$A:$H,8,FALSE)) -> 7 | T7: =IF(N7="","",VLOOKUP(N7,$A:$H,8,FALSE)) -> 7 | U7: =IF(O7="","",VLOOKUP(O7,$A:$H,8,FALSE)) -> 10 | W7: =IF(K7="","",VLOOKUP(K7,$A:$H,2,FALSE)) -> A | X7: =IF(L7="","",VLOOKUP(L7,$A:$H,2,FALSE)) -> KG | Y7: =IF(M7="","",VLOOKUP(M7,$A:$H,2,FALSE)) -> A | Z7: =IF(N7="","",VLOOKUP(N7,$A:$H,2,FALSE)) -> A | AA7: =IF(O7="","",VLOOKUP(O7,$A:$H,2,FALSE)) -> J
A8: M2 | B8: M2 | C8: =COUNTIF(K:K,$A8) -> 36 | D8: =COUNTIF(L:L,$A8) -> 32 | E8: =COUNTIF(M:M,$A8) -> 23 | F8: =COUNTIF(N:N,$A8) -> 37 | G8: =COUNTIF(O:O,$A8) -> 32 | H8: 4 | J8: 4 | K8: M2 | L8: Q | M8: M4 | N8: M3 | O8: J | Q8: =IF(K8="","",VLOOKUP(K8,$A:$H,8,FALSE)) -> 4 | R8: =IF(L8="","",VLOOKUP(L8,$A:$H,8,FALSE)) -> 9 | S8: =IF(M8="","",VLOOKUP(M8,$A:$H,8,FALSE)) -> 6 | T8: =IF(N8="","",VLOOKUP(N8,$A:$H,8,FALSE)) -> 5 | U8: =IF(O8="","",VLOOKUP(O8,$A:$H,8,FALSE)) -> 10 | W8: =IF(K8="","",VLOOKUP(K8,$A:$H,2,FALSE)) -> M2 | X8: =IF(L8="","",VLOOKUP(L8,$A:$H,2,FALSE)) -> Q | Y8: =IF(M8="","",VLOOKUP(M8,$A:$H,2,FALSE)) -> M4 | Z8: =IF(N8="","",VLOOKUP(N8,$A:$H,2,FALSE)) -> M3 | AA8: =IF(O8="","",VLOOKUP(O8,$A:$H,2,FALSE)) -> J | AC8: Multiplier
A9: M3 | B9: M3 | C9: =COUNTIF(K:K,$A9) -> 32 | D9: =COUNTIF(L:L,$A9) -> 26 | E9: =COUNTIF(M:M,$A9) -> 35 | F9: =COUNTIF(N:N,$A9) -> 26 | G9: =COUNTIF(O:O,$A9) -> 62 | H9: 5 | J9: 5 | K9: J | L9: K | M9: M4G | N9: J | O9: M1 | Q9: =IF(K9="","",VLOOKUP(K9,$A:$H,8,FALSE)) -> 10 | R9: =IF(L9="","",VLOOKUP(L9,$A:$H,8,FALSE)) -> 8 | S9: =IF(M9="","",VLOOKUP(M9,$A:$H,8,FALSE)) -> 14 | T9: =IF(N9="","",VLOOKUP(N9,$A:$H,8,FALSE)) -> 10 | U9: =IF(O9="","",VLOOKUP(O9,$A:$H,8,FALSE)) -> 3 | W9: =IF(K9="","",VLOOKUP(K9,$A:$H,2,FALSE)) -> J | X9: =IF(L9="","",VLOOKUP(L9,$A:$H,2,FALSE)) -> K | Y9: =IF(M9="","",VLOOKUP(M9,$A:$H,2,FALSE)) -> M4G | Z9: =IF(N9="","",VLOOKUP(N9,$A:$H,2,FALSE)) -> J | AA9: =IF(O9="","",VLOOKUP(O9,$A:$H,2,FALSE)) -> M1 | AC9: X1
A10: M4 | B10: M4 | C10: =COUNTIF(K:K,$A10) -> 38 | D10: =COUNTIF(L:L,$A10) -> 42 | E10: =COUNTIF(M:M,$A10) -> 35 | F10: =COUNTIF(N:N,$A10) -> 58 | G10: =COUNTIF(O:O,$A10) -> 21 | H10: 6 | J10: 6 | K10: Q | L10: Q | M10: M2 | N10: A | O10: A | Q10: =IF(K10="","",VLOOKUP(K10,$A:$H,8,FALSE)) -> 9 | R10: =IF(L10="","",VLOOKUP(L10,$A:$H,8,FALSE)) -> 9 | S10: =IF(M10="","",VLOOKUP(M10,$A:$H,8,FALSE)) -> 4 | T10: =IF(N10="","",VLOOKUP(N10,$A:$H,8,FALSE)) -> 7 | U10: =IF(O10="","",VLOOKUP(O10,$A:$H,8,FALSE)) -> 7 | W10: =IF(K10="","",VLOOKUP(K10,$A:$H,2,FALSE)) -> Q | X10: =IF(L10="","",VLOOKUP(L10,$A:$H,2,FALSE)) -> Q | Y10: =IF(M10="","",VLOOKUP(M10,$A:$H,2,FALSE)) -> M2 | Z10: =IF(N10="","",VLOOKUP(N10,$A:$H,2,FALSE)) -> A | AA10: =IF(O10="","",VLOOKUP(O10,$A:$H,2,FALSE)) -> A | AC10: X2
A11: A | B11: A | C11: =COUNTIF(K:K,$A11) -> 72 | D11: =COUNTIF(L:L,$A11) -> 60 | E11: =COUNTIF(M:M,$A11) -> 52 | F11: =COUNTIF(N:N,$A11) -> 24 | G11: =COUNTIF(O:O,$A11) -> 48 | H11: 7 | J11: 7 | K11: M4 | L11: JG | M11: C1 | N11: KG | O11: J | Q11: =IF(K11="","",VLOOKUP(K11,$A:$H,8,FALSE)) -> 6 | R11: =IF(L11="","",VLOOKUP(L11,$A:$H,8,FALSE)) -> 18 | S11: =IF(M11="","",VLOOKUP(M11,$A:$H,8,FALSE)) -> 2 | T11: =IF(N11="","",VLOOKUP(N11,$A:$H,8,FALSE)) -> 16 | U11: =IF(O11="","",VLOOKUP(O11,$A:$H,8,FALSE)) -> 10 | W11: =IF(K11="","",VLOOKUP(K11,$A:$H,2,FALSE)) -> M4 | X11: =IF(L11="","",VLOOKUP(L11,$A:$H,2,FALSE)) -> JG | Y11: =IF(M11="","",VLOOKUP(M11,$A:$H,2,FALSE)) -> Scatter | Z11: =IF(N11="","",VLOOKUP(N11,$A:$H,2,FALSE)) -> KG | AA11: =IF(O11="","",VLOOKUP(O11,$A:$H,2,FALSE)) -> J | AC11: X3
A12: K | B12: K | C12: =COUNTIF(K:K,$A12) -> 63 | D12: =COUNTIF(L:L,$A12) -> 40 | E12: =COUNTIF(M:M,$A12) -> 40 | F12: =COUNTIF(N:N,$A12) -> 69 | G12: =COUNTIF(O:O,$A12) -> 56 | H12: 8 | J12: 8 | K12: M3 | L12: M1 | M12: A | N12: A | O12: K | Q12: =IF(K12="","",VLOOKUP(K12,$A:$H,8,FALSE)) -> 5 | R12: =IF(L12="","",VLOOKUP(L12,$A:$H,8,FALSE)) -> 3 | S12: =IF(M12="","",VLOOKUP(M12,$A:$H,8,FALSE)) -> 7 | T12: =IF(N12="","",VLOOKUP(N12,$A:$H,8,FALSE)) -> 7 | U12: =IF(O12="","",VLOOKUP(O12,$A:$H,8,FALSE)) -> 8 | W12: =IF(K12="","",VLOOKUP(K12,$A:$H,2,FALSE)) -> M3 | X12: =IF(L12="","",VLOOKUP(L12,$A:$H,2,FALSE)) -> M1 | Y12: =IF(M12="","",VLOOKUP(M12,$A:$H,2,FALSE)) -> A | Z12: =IF(N12="","",VLOOKUP(N12,$A:$H,2,FALSE)) -> A | AA12: =IF(O12="","",VLOOKUP(O12,$A:$H,2,FALSE)) -> K | AC12: X5
A13: Q | B13: Q | C13: =COUNTIF(K:K,$A13) -> 63 | D13: =COUNTIF(L:L,$A13) -> 32 | E13: =COUNTIF(M:M,$A13) -> 57 | F13: =COUNTIF(N:N,$A13) -> 60 | G13: =COUNTIF(O:O,$A13) -> 60 | H13: 9 | J13: 9 | K13: A | L13: J | M13: M1G | N13: K | O13: M1 | Q13: =IF(K13="","",VLOOKUP(K13,$A:$H,8,FALSE)) -> 7 | R13: =IF(L13="","",VLOOKUP(L13,$A:$H,8,FALSE)) -> 10 | S13: =IF(M13="","",VLOOKUP(M13,$A:$H,8,FALSE)) -> 11 | T13: =IF(N13="","",VLOOKUP(N13,$A:$H,8,FALSE)) -> 8 | U13: =IF(O13="","",VLOOKUP(O13,$A:$H,8,FALSE)) -> 3 | W13: =IF(K13="","",VLOOKUP(K13,$A:$H,2,FALSE)) -> A | X13: =IF(L13="","",VLOOKUP(L13,$A:$H,2,FALSE)) -> J | Y13: =IF(M13="","",VLOOKUP(M13,$A:$H,2,FALSE)) -> M1G | Z13: =IF(N13="","",VLOOKUP(N13,$A:$H,2,FALSE)) -> K | AA13: =IF(O13="","",VLOOKUP(O13,$A:$H,2,FALSE)) -> M1 | AC13: X10
A14: J | B14: J | C14: =COUNTIF(K:K,$A14) -> 64 | D14: =COUNTIF(L:L,$A14) -> 33 | E14: =COUNTIF(M:M,$A14) -> 37 | F14: =COUNTIF(N:N,$A14) -> 30 | G14: =COUNTIF(O:O,$A14) -> 85 | H14: 10 | J14: 10 | K14: Q | L14: QG | M14: J | N14: M2 | O14: J | Q14: =IF(K14="","",VLOOKUP(K14,$A:$H,8,FALSE)) -> 9 | R14: =IF(L14="","",VLOOKUP(L14,$A:$H,8,FALSE)) -> 17 | S14: =IF(M14="","",VLOOKUP(M14,$A:$H,8,FALSE)) -> 10 | T14: =IF(N14="","",VLOOKUP(N14,$A:$H,8,FALSE)) -> 4 | U14: =IF(O14="","",VLOOKUP(O14,$A:$H,8,FALSE)) -> 10 | W14: =IF(K14="","",VLOOKUP(K14,$A:$H,2,FALSE)) -> Q | X14: =IF(L14="","",VLOOKUP(L14,$A:$H,2,FALSE)) -> QG | Y14: =IF(M14="","",VLOOKUP(M14,$A:$H,2,FALSE)) -> J | Z14: =IF(N14="","",VLOOKUP(N14,$A:$H,2,FALSE)) -> M2 | AA14: =IF(O14="","",VLOOKUP(O14,$A:$H,2,FALSE)) -> J
A15: M1G | B15: M1G | C15: =COUNTIF(K:K,$A15) -> 0 | D15: =COUNTIF(L:L,$A15) -> 2 | E15: =COUNTIF(M:M,$A15) -> 3 | F15: =COUNTIF(N:N,$A15) -> 3 | G15: =COUNTIF(O:O,$A15) -> 0 | H15: 11 | J15: 11 | K15: A | L15: M3 | M15: Q | N15: A | O15: M4 | Q15: =IF(K15="","",VLOOKUP(K15,$A:$H,8,FALSE)) -> 7 | R15: =IF(L15="","",VLOOKUP(L15,$A:$H,8,FALSE)) -> 5 | S15: =IF(M15="","",VLOOKUP(M15,$A:$H,8,FALSE)) -> 9 | T15: =IF(N15="","",VLOOKUP(N15,$A:$H,8,FALSE)) -> 7 | U15: =IF(O15="","",VLOOKUP(O15,$A:$H,8,FALSE)) -> 6 | W15: =IF(K15="","",VLOOKUP(K15,$A:$H,2,FALSE)) -> A | X15: =IF(L15="","",VLOOKUP(L15,$A:$H,2,FALSE)) -> M3 | Y15: =IF(M15="","",VLOOKUP(M15,$A:$H,2,FALSE)) -> Q | Z15: =IF(N15="","",VLOOKUP(N15,$A:$H,2,FALSE)) -> A | AA15: =IF(O15="","",VLOOKUP(O15,$A:$H,2,FALSE)) -> M4
A16: M2G | B16: M2G | C16: =COUNTIF(K:K,$A16) -> 0 | D16: =COUNTIF(L:L,$A16) -> 7 | E16: =COUNTIF(M:M,$A16) -> 2 | F16: =COUNTIF(N:N,$A16) -> 4 | G16: =COUNTIF(O:O,$A16) -> 0 | H16: 12 | J16: 12 | K16: J | L16: M1G | M16: JG | N16: AG | O16: M3 | Q16: =IF(K16="","",VLOOKUP(K16,$A:$H,8,FALSE)) -> 10 | R16: =IF(L16="","",VLOOKUP(L16,$A:$H,8,FALSE)) -> 11 | S16: =IF(M16="","",VLOOKUP(M16,$A:$H,8,FALSE)) -> 18 | T16: =IF(N16="","",VLOOKUP(N16,$A:$H,8,FALSE)) -> 15 | U16: =IF(O16="","",VLOOKUP(O16,$A:$H,8,FALSE)) -> 5 | W16: =IF(K16="","",VLOOKUP(K16,$A:$H,2,FALSE)) -> J | X16: =IF(L16="","",VLOOKUP(L16,$A:$H,2,FALSE)) -> M1G | Y16: =IF(M16="","",VLOOKUP(M16,$A:$H,2,FALSE)) -> JG | Z16: =IF(N16="","",VLOOKUP(N16,$A:$H,2,FALSE)) -> AG | AA16: =IF(O16="","",VLOOKUP(O16,$A:$H,2,FALSE)) -> M3
A17: M3G | B17: M3G | C17: =COUNTIF(K:K,$A17) -> 0 | D17: =COUNTIF(L:L,$A17) -> 4 | E17: =COUNTIF(M:M,$A17) -> 8 | F17: =COUNTIF(N:N,$A17) -> 4 | G17: =COUNTIF(O:O,$A17) -> 0 | H17: 13 | J17: 13 | K17: M2 | L17: K | M17: A | N17: K | O17: J | Q17: =IF(K17="","",VLOOKUP(K17,$A:$H,8,FALSE)) -> 4 | R17: =IF(L17="","",VLOOKUP(L17,$A:$H,8,FALSE)) -> 8 | S17: =IF(M17="","",VLOOKUP(M17,$A:$H,8,FALSE)) -> 7 | T17: =IF(N17="","",VLOOKUP(N17,$A:$H,8,FALSE)) -> 8 | U17: =IF(O17="","",VLOOKUP(O17,$A:$H,8,FALSE)) -> 10 | W17: =IF(K17="","",VLOOKUP(K17,$A:$H,2,FALSE)) -> M2 | X17: =IF(L17="","",VLOOKUP(L17,$A:$H,2,FALSE)) -> K | Y17: =IF(M17="","",VLOOKUP(M17,$A:$H,2,FALSE)) -> A | Z17: =IF(N17="","",VLOOKUP(N17,$A:$H,2,FALSE)) -> K | AA17: =IF(O17="","",VLOOKUP(O17,$A:$H,2,FALSE)) -> J
A18: M4G | B18: M4G | C18: =COUNTIF(K:K,$A18) -> 0 | D18: =COUNTIF(L:L,$A18) -> 16 | E18: =COUNTIF(M:M,$A18) -> 8 | F18: =COUNTIF(N:N,$A18) -> 9 | G18: =COUNTIF(O:O,$A18) -> 0 | H18: 14 | J18: 14 | K18: Q | L18: M3 | M18: J | N18: A | O18: M1 | Q18: =IF(K18="","",VLOOKUP(K18,$A:$H,8,FALSE)) -> 9 | R18: =IF(L18="","",VLOOKUP(L18,$A:$H,8,FALSE)) -> 5 | S18: =IF(M18="","",VLOOKUP(M18,$A:$H,8,FALSE)) -> 10 | T18: =IF(N18="","",VLOOKUP(N18,$A:$H,8,FALSE)) -> 7 | U18: =IF(O18="","",VLOOKUP(O18,$A:$H,8,FALSE)) -> 3 | W18: =IF(K18="","",VLOOKUP(K18,$A:$H,2,FALSE)) -> Q | X18: =IF(L18="","",VLOOKUP(L18,$A:$H,2,FALSE)) -> M3 | Y18: =IF(M18="","",VLOOKUP(M18,$A:$H,2,FALSE)) -> J | Z18: =IF(N18="","",VLOOKUP(N18,$A:$H,2,FALSE)) -> A | AA18: =IF(O18="","",VLOOKUP(O18,$A:$H,2,FALSE)) -> M1
A19: AG | B19: AG | C19: =COUNTIF(K:K,$A19) -> 0 | D19: =COUNTIF(L:L,$A19) -> 20 | E19: =COUNTIF(M:M,$A19) -> 14 | F19: =COUNTIF(N:N,$A19) -> 7 | G19: =COUNTIF(O:O,$A19) -> 0 | H19: 15 | J19: 15 | K19: C1 | L19: Q | M19: AG | N19: M2G | O19: J | Q19: =IF(K19="","",VLOOKUP(K19,$A:$H,8,FALSE)) -> 2 | R19: =IF(L19="","",VLOOKUP(L19,$A:$H,8,FALSE)) -> 9 | S19: =IF(M19="","",VLOOKUP(M19,$A:$H,8,FALSE)) -> 15 | T19: =IF(N19="","",VLOOKUP(N19,$A:$H,8,FALSE)) -> 12 | U19: =IF(O19="","",VLOOKUP(O19,$A:$H,8,FALSE)) -> 10 | W19: =IF(K19="","",VLOOKUP(K19,$A:$H,2,FALSE)) -> Scatter | X19: =IF(L19="","",VLOOKUP(L19,$A:$H,2,FALSE)) -> Q | Y19: =IF(M19="","",VLOOKUP(M19,$A:$H,2,FALSE)) -> AG | Z19: =IF(N19="","",VLOOKUP(N19,$A:$H,2,FALSE)) -> M2G | AA19: =IF(O19="","",VLOOKUP(O19,$A:$H,2,FALSE)) -> J
A20: KG | B20: KG | C20: =COUNTIF(K:K,$A20) -> 0 | D20: =COUNTIF(L:L,$A20) -> 16 | E20: =COUNTIF(M:M,$A20) -> 16 | F20: =COUNTIF(N:N,$A20) -> 17 | G20: =COUNTIF(O:O,$A20) -> 0 | H20: 16 | J20: 16 | K20: J | L20: J | M20: A | N20: K | O20: M1 | Q20: =IF(K20="","",VLOOKUP(K20,$A:$H,8,FALSE)) -> 10 | R20: =IF(L20="","",VLOOKUP(L20,$A:$H,8,FALSE)) -> 10 | S20: =IF(M20="","",VLOOKUP(M20,$A:$H,8,FALSE)) -> 7 | T20: =IF(N20="","",VLOOKUP(N20,$A:$H,8,FALSE)) -> 8 | U20: =IF(O20="","",VLOOKUP(O20,$A:$H,8,FALSE)) -> 3 | W20: =IF(K20="","",VLOOKUP(K20,$A:$H,2,FALSE)) -> J | X20: =IF(L20="","",VLOOKUP(L20,$A:$H,2,FALSE)) -> J | Y20: =IF(M20="","",VLOOKUP(M20,$A:$H,2,FALSE)) -> A | Z20: =IF(N20="","",VLOOKUP(N20,$A:$H,2,FALSE)) -> K | AA20: =IF(O20="","",VLOOKUP(O20,$A:$H,2,FALSE)) -> M1
A21: QG | B21: QG | C21: =COUNTIF(K:K,$A21) -> 0 | D21: =COUNTIF(L:L,$A21) -> 15 | E21: =COUNTIF(M:M,$A21) -> 19 | F21: =COUNTIF(N:N,$A21) -> 11 | G21: =COUNTIF(O:O,$A21) -> 0 | H21: 17 | J21: 17 | K21: A | L21: AG | M21: J | N21: K | O21: J | Q21: =IF(K21="","",VLOOKUP(K21,$A:$H,8,FALSE)) -> 7 | R21: =IF(L21="","",VLOOKUP(L21,$A:$H,8,FALSE)) -> 15 | S21: =IF(M21="","",VLOOKUP(M21,$A:$H,8,FALSE)) -> 10 | T21: =IF(N21="","",VLOOKUP(N21,$A:$H,8,FALSE)) -> 8 | U21: =IF(O21="","",VLOOKUP(O21,$A:$H,8,FALSE)) -> 10 | W21: =IF(K21="","",VLOOKUP(K21,$A:$H,2,FALSE)) -> A | X21: =IF(L21="","",VLOOKUP(L21,$A:$H,2,FALSE)) -> AG | Y21: =IF(M21="","",VLOOKUP(M21,$A:$H,2,FALSE)) -> J | Z21: =IF(N21="","",VLOOKUP(N21,$A:$H,2,FALSE)) -> K | AA21: =IF(O21="","",VLOOKUP(O21,$A:$H,2,FALSE)) -> J
A22: JG | B22: JG | C22: =COUNTIF(K:K,$A22) -> 0 | D22: =COUNTIF(L:L,$A22) -> 25 | E22: =COUNTIF(M:M,$A22) -> 19 | F22: =COUNTIF(N:N,$A22) -> 9 | G22: =COUNTIF(O:O,$A22) -> 0 | H22: 18 | J22: 18 | K22: Q | L22: K | M22: JG | N22: M4 | O22: M2 | Q22: =IF(K22="","",VLOOKUP(K22,$A:$H,8,FALSE)) -> 9 | R22: =IF(L22="","",VLOOKUP(L22,$A:$H,8,FALSE)) -> 8 | S22: =IF(M22="","",VLOOKUP(M22,$A:$H,8,FALSE)) -> 18 | T22: =IF(N22="","",VLOOKUP(N22,$A:$H,8,FALSE)) -> 6 | U22: =IF(O22="","",VLOOKUP(O22,$A:$H,8,FALSE)) -> 4 | W22: =IF(K22="","",VLOOKUP(K22,$A:$H,2,FALSE)) -> Q | X22: =IF(L22="","",VLOOKUP(L22,$A:$H,2,FALSE)) -> K | Y22: =IF(M22="","",VLOOKUP(M22,$A:$H,2,FALSE)) -> JG | Z22: =IF(N22="","",VLOOKUP(N22,$A:$H,2,FALSE)) -> M4 | AA22: =IF(O22="","",VLOOKUP(O22,$A:$H,2,FALSE)) -> M2
A23: -- | C23: =SUM(C4:C22) -> 400 | D23: =SUM(D4:D22) -> 400 | E23: =SUM(E4:E22) -> 400 | F23: =SUM(F4:F22) -> 400 | G23: =SUM(G4:G22) -> 400 | J23: 19 | K23: A | L23: J | M23: J | N23: K | O23: M3 | Q23: =IF(K23="","",VLOOKUP(K23,$A:$H,8,FALSE)) -> 7 | R23: =IF(L23="","",VLOOKUP(L23,$A:$H,8,FALSE)) -> 10 | S23: =IF(M23="","",VLOOKUP(M23,$A:$H,8,FALSE)) -> 10 | T23: =IF(N23="","",VLOOKUP(N23,$A:$H,8,FALSE)) -> 8 | U23: =IF(O23="","",VLOOKUP(O23,$A:$H,8,FALSE)) -> 5 | W23: =IF(K23="","",VLOOKUP(K23,$A:$H,2,FALSE)) -> A | X23: =IF(L23="","",VLOOKUP(L23,$A:$H,2,FALSE)) -> J | Y23: =IF(M23="","",VLOOKUP(M23,$A:$H,2,FALSE)) -> J | Z23: =IF(N23="","",VLOOKUP(N23,$A:$H,2,FALSE)) -> K | AA23: =IF(O23="","",VLOOKUP(O23,$A:$H,2,FALSE)) -> M3
J24: 20 | K24: M1 | L24: M3 | M24: A | N24: KG | O24: Q | Q24: =IF(K24="","",VLOOKUP(K24,$A:$H,8,FALSE)) -> 3 | R24: =IF(L24="","",VLOOKUP(L24,$A:$H,8,FALSE)) -> 5 | S24: =IF(M24="","",VLOOKUP(M24,$A:$H,8,FALSE)) -> 7 | T24: =IF(N24="","",VLOOKUP(N24,$A:$H,8,FALSE)) -> 16 | U24: =IF(O24="","",VLOOKUP(O24,$A:$H,8,FALSE)) -> 9 | W24: =IF(K24="","",VLOOKUP(K24,$A:$H,2,FALSE)) -> M1 | X24: =IF(L24="","",VLOOKUP(L24,$A:$H,2,FALSE)) -> M3 | Y24: =IF(M24="","",VLOOKUP(M24,$A:$H,2,FALSE)) -> A | Z24: =IF(N24="","",VLOOKUP(N24,$A:$H,2,FALSE)) -> KG | AA24: =IF(O24="","",VLOOKUP(O24,$A:$H,2,FALSE)) -> Q
