Workbook

Sheet Overview
A2: Model: | B2: H026192
A3: Version: | B3: 0.0.1.1
A6: Base Bet
A7: 100
A10: Coin in | B10: Price(x) | C10: Total RTP | D10: Bet Type
A11: {=B11:B12*A7} -> 100 | B11: 1 | C11: =SUM(B17:B18) -> 0 | D11: Normal Bet
A12: 7500 | B12: 75 | C12: =SUM(B21:B22) -> 0 | D12: Buy Feature
A15: Total Pay Back Percentage includes the following adjustments.
A16: Bet Type | B16: Pay Back | C16: Hit% | D16: Pulls/Hit | E16: Description
A17: =D11 -> Normal Bet | C17: =1/D17 -> #DIV/0! | E17: Base Game
E18: Free Game
A20: Bet Type | B20: Pay Back | C20: Hit% | D20: Pulls/Hit | E20: Description
A21: =D12 -> Buy Feature | C21: =1/D21 -> 1 | D21: 1 | E21: Base Game
E22: Free Game
A25: Reel # | B25: 1 | C25: 2 | D25: 3 | E25: 4 | F25: 5
A26: Visible Window Size | B26: 3 | C26: 3 | D26: 3 | E26: 3 | F26: 3
A29: Free Spins Setting
A30: C1 Num. | B30: Base Game | C30: Free Game
A31: 3 | B31: 15 | C31: 15
A32: 4 | B32: 17 | C32: 17
A33: 5 | B33: 19 | C33: 19
A34: The maximum of free spins is 50.
A36: Pay Table： | B36: ="All wins show for "&A7&" credit bet." -> All wins show for 100 credit bet.
A37: Symbol | B37: Description | C37: 3 | D37: 4 | E37: 5 | F37: Id
A38: WW | B38: Wild | C38: 0 | D38: 0 | E38: 0 | F38: 0
A39: C1 | B39: Scatter | C39: 0 | D39: 0 | E39: 0 | F39: 1
A40: M1 | B40: M1 | C40: 250 | D40: 1250 | E40: 5000 | F40: 2
A41: M2 | B41: M2 | C41: 100 | D41: 500 | E41: 2000 | F41: 3
A42: M3 | B42: M3 | C42: 75 | D42: 250 | E42: 1000 | F42: 4
A43: M4 | B43: M4 | C43: 50 | D43: 200 | E43: 750 | F43: 5
A44: M5 | B44: M5 | C44: 25 | D44: 100 | E44: 500 | F44: 6
A45: A | B45: A | C45: 10 | D45: 50 | E45: 250 | F45: 7
A46: K | B46: K | C46: 10 | D46: 50 | E46: 250 | F46: 8
A47: Q | B47: Q | C47: 10 | D47: 50 | E47: 250 | F47: 9
A48: J | B48: J | C48: 10 | D48: 50 | E48: 250 | F48: 10
A49: G1 | B49: Gold M1 | C49: 250 | D49: 1250 | E49: 5000 | F49: 11
... A57: GJ | B57: Gold J | C57: 10 | D57: 50 | E57: 250 | F57: 19

Sheet Description
B3: 7. BG 流程對應
B5: 7.1 BG 開局流程
B7: BG 每局的主要參數流程如下：
B8: 1. 先用 Table Selection Weight - Base Game 選出 BG table。
B9: 2. 再用該 strip 的 Symbol Weight R1~R5 抽停輪位置。
B10: 3. 依 Symbol ID R1~R5 生成初始盤面。
B11: 4. 盤面上的金框會先判定是否觸發 Used Special Pool Weight。
B12: 5. 若命中特殊池，該金框用 Multiple Selection Weight - Special Pool 抽倍率。
B13: 6. 若沒命中特殊池：
B14: - 且是 BG_Symbol (2) 則第 3 輪金框用 Multiple Selection Weight - Reel3 Before Eliminate
B15: - 其他輪金框用 Multiple Selection Weight - Before Eliminate
B16: 7. 再用 Eliminate Table Weight 決定本局是掉落表 A 或 B。
... B83: 5. BG_Symbol (3): 觸發 FG 用的表。得分少、C1 多，盡量不要有倍數百搭參與 → 控制進 FG 時的得分

Sheet Parameter
B3: Line | I3: Table Selection Weight - Base Game (Weight/Total) | N3: Multiple Selection Weight - Special Pool (Weight/Total) | AC3: Used Special Pool Weight (Weight/10000)
B4: ID | C4: R1 | D4: R2 | E4: R3 | F4: R4 | G4: R5 | I4: Worksheet Name | J4: Weight | K4: RTP | N4: Worksheet Name \ Multiple | O4: 0 | P4: 2 | Q4: 3 | R4: 5 | S4: 8 | T4: 10 | U4: 15 | V4: 20 | W4: 25 | X4: 35 | Y4: 50 | Z4: 80 | AA4: 100 | AC4: Worksheet Name \ Multiple | AD4: 1 | AE4: 2 | AF4: 3 | AG4: 4 | AH4: 5 | AI4: 6 | AJ4: 7 | AK4: 8 | AL4: 9
B5: {=_xlfn.SEQUENCE(20,,0)} -> 0 | C5: 1 | D5: 1 | E5: 1 | F5: 1 | G5: 1 | I5: BG_Symbol | J5: =10000-J6-J7 -> 5999 | L5: {=J5:J7/J8} -> 0.5999 | N5: BG_Symbol | O5: 0 | P5: 0 | Q5: 0 | R5: 0 | S5: 0 | T5: =10000-SUM(U5:AA5) -> 3400 | U5: 1200 | V5: 2400 | W5: 500 | X5: 200 | Y5: 200 | Z5: 1200 | AA5: 900 | AB5: {=SUMPRODUCT(O5:AA5/SUM(O5:AA5),$O$4:$AA$4)} -> 31.55 | AC5: BG_Symbol | AD5: 500 | AE5: 1000 | AF5: 1500 | AG5: 3000 | AH5: 10000 | AI5: 10000 | AJ5: 10000 | AK5: 10000 | AL5: 10000
B6: 1 | C6: 0 | D6: 0 | E6: 0 | F6: 0 | G6: 0 | I6: BG_Symbol (2) | J6: 1001 | L6: 0.1001 | N6: BG_Symbol (2) | O6: 0 | P6: 0 | Q6: 0 | R6: 0 | S6: 0 | T6: =10000-SUM(U6:AA6) -> 4450 | U6: 600 | V6: 2400 | W6: 250 | X6: 100 | Y6: 100 | Z6: 1200 | AA6: 900 | AB6: {=SUMPRODUCT(O6:AA6/SUM(O6:AA6),$O$4:$AA$4)} -> 30.225 | AC6: BG_Symbol (2) | AD6: 0 | AE6: 0 | AF6: 1000 | AG6: 1500 | AH6: 2500 | AI6: 5000 | AJ6: 10000 | AK6: 10000 | AL6: 10000
B7: 2 | C7: 2 | D7: 2 | E7: 2 | F7: 2 | G7: 2 | I7: BG_Symbol (3) | J7: 3000 | L7: 0.3 | N7: BG_Symbol (3) | O7: 0 | P7: 0 | Q7: 0 | R7: 0 | S7: 0 | T7: =10000-SUM(U7:AA7) -> 10000 | U7: 0 | V7: 0 | W7: 0 | X7: 0 | Y7: 0 | Z7: 0 | AA7: 0 | AB7: {=SUMPRODUCT(O7:AA7/SUM(O7:AA7),$O$4:$AA$4)} -> 10 | AC7: BG_Symbol (3) | AD7: 0 | AE7: 0 | AF7: 0 | AG7: 0 | AH7: 0 | AI7: 0 | AJ7: 0 | AK7: 0 | AL7: 0
B8: 3 | C8: 0 | D8: 1 | E8: 2 | F8: 1 | G8: 0 | J8: =SUM(J5:J7) -> 10000 | K8: =SUMPRODUCT(K5:K7,_xlfn.ANCHORARRAY(L5)) -> 0 | N8: FG_Symbol | O8: 0 | P8: 0 | Q8: 0 | R8: 0 | S8: 0 | T8: =10000-SUM(U8:AA8) -> 3900 | U8: 1500 | V8: 2500 | W8: 100 | X8: 100 | Y8: 100 | Z8: 1000 | AA8: 800 | AB8: {=SUMPRODUCT(O8:AA8/SUM(O8:AA8),$O$4:$AA$4)} -> 28.25 | AC8: FG_Symbol | AD8: 0 | AE8: 0 | AF8: 1000 | AG8: 1500 | AH8: 2500 | AI8: 4000 | AJ8: 10000 | AK8: 10000 | AL8: 10000
B9: 4 | C9: 2 | D9: 1 | E9: 0 | F9: 1 | G9: 2 | N9: FG_Symbol (2) | O9: 0 | P9: 0 | Q9: 0 | R9: 0 | S9: 0 | T9: =10000-SUM(U9:AA9) -> 3900 | U9: 1500 | V9: 2500 | W9: 100 | X9: 100 | Y9: 100 | Z9: 1000 | AA9: 800 | AB9: {=SUMPRODUCT(O9:AA9/SUM(O9:AA9),$O$4:$AA$4)} -> 28.25 | AC9: FG_Symbol (2) | AD9: 0 | AE9: 0 | AF9: 1000 | AG9: 1500 | AH9: 2500 | AI9: 4000 | AJ9: 10000 | AK9: 10000 | AL9: 10000
B10: 5 | C10: 0 | D10: 0 | E10: 1 | F10: 0 | G10: 0 | I10: Table Selection Weight - Free Game (Weight/Total) | N10: FG_Symbol (3) | O10: 0 | P10: 0 | Q10: 0 | R10: 0 | S10: 0 | T10: =10000-SUM(U10:AA10) -> 3900 | U10: 1500 | V10: 2500 | W10: 100 | X10: 100 | Y10: 100 | Z10: 1000 | AA10: 800 | AB10: {=SUMPRODUCT(O10:AA10/SUM(O10:AA10),$O$4:$AA$4)} -> 28.25 | AC10: FG_Symbol (3) | AD10: 0 | AE10: 0 | AF10: 1000 | AG10: 1500 | AH10: 2500 | AI10: 4000 | AJ10: 10000 | AK10: 10000 | AL10: 10000
B11: 6 | C11: 2 | D11: 2 | E11: 1 | F11: 2 | G11: 2 | I11: Worksheet Name | J11: Weight | K11: RTP | N11: BF_Symbol | O11: 0 | P11: 0 | Q11: 0 | R11: 0 | S11: 0 | T11: =10000-SUM(U11:AA11) -> 10000 | U11: 0 | V11: 0 | W11: 0 | X11: 0 | Y11: 0 | Z11: 0 | AA11: 0 | AB11: {=SUMPRODUCT(O11:AA11/SUM(O11:AA11),$O$4:$AA$4)} -> 10 | AC11: BF_Symbol | AD11: 0 | AE11: 0 | AF11: 0 | AG11: 0 | AH11: 0 | AI11: 0 | AJ11: 0 | AK11: 0 | AL11: 0
B12: 7 | C12: 1 | D12: 2 | E12: 2 | F12: 2 | G12: 1 | I12: FG_Symbol | J12: =10000-SUM(J13:J14) -> 10000 | L12: {=J12:J14/SUM(J15)} -> 1
B13: 8 | C13: 1 | D13: 0 | E13: 0 | F13: 0 | G13: 1 | I13: FG_Symbol (2) | J13: 0 | L13: 0
B14: 9 | C14: 0 | D14: 1 | E14: 1 | F14: 1 | G14: 0 | I14: FG_Symbol (3) | J14: 0 | L14: 0 | N14: Multiple Selection Weight - Reel3 Before Eliminate (Weight/Total)
B15: 10 | C15: 2 | D15: 1 | E15: 1 | F15: 1 | G15: 2 | J15: =SUM(J12:J14) -> 10000 | K15: =SUMPRODUCT(K12:K14,_xlfn.ANCHORARRAY(L12)) -> 0 | N15: Worksheet Name \ Multiple | O15: 0 | P15: 2 | Q15: 3 | R15: 5 | S15: 8 | T15: 10 | U15: 15 | V15: 20 | W15: 25 | X15: 35 | Y15: 50 | Z15: 80 | AA15: 100
B16: 11 | C16: 1 | D16: 1 | E16: 0 | F16: 1 | G16: 1 | N16: BG_Symbol | O16: =10000-SUM(P16:AA16) -> 8100 | P16: 600 | Q16: 500 | R16: 400 | S16: 400 | T16: 0 | U16: 0 | V16: 0 | W16: 0 | X16: 0 | Y16: 0 | Z16: 0 | AA16: 0 | AB16: {=SUMPRODUCT(O16:AA16/SUM(O16:AA16),$O$4:$AA$4)} -> 0.79
B17: 12 | C17: 1 | D17: 1 | E17: 2 | F17: 1 | G17: 1 | I17: Table Selection Weight - Buy Feature (Weight/Total) | N17: BG_Symbol (2) | O17: =10000-SUM(P17:AA17) -> 0 | P17: =10000-SUM(Q17:AA17) -> 3200 | Q17: 2600 | R17: 2100 | S17: 2100 | T17: 0 | U17: 0 | V17: 0 | W17: 0 | X17: 0 | Y17: 0 | Z17: 0 | AA17: 0 | AB17: {=SUMPRODUCT(O17:AA17/SUM(O17:AA17),$O$4:$AA$4)} -> 4.15
B18: 13 | C18: 1 | D18: 0 | E18: 1 | F18: 0 | G18: 1 | I18: Worksheet Name | J18: Weight | K18: RTP | N18: BG_Symbol (3) | O18: =10000-SUM(P18:AA18) -> 8100 | P18: 800 | Q18: 700 | R18: 400 | S18: 0 | T18: 0 | U18: 0 | V18: 0 | W18: 0 | X18: 0 | Y18: 0 | Z18: 0 | AA18: 0 | AB18: {=SUMPRODUCT(O18:AA18/SUM(O18:AA18),$O$4:$AA$4)} -> 0.57
B19: 14 | C19: 1 | D19: 2 | E19: 1 | F19: 2 | G19: 1 | I19: FG_Symbol | J19: =10000-SUM(J20:J21) -> 10000 | L19: {=J19:J21/SUM(J22)} -> 1 | N19: FG_Symbol | O19: =10000-SUM(P19:AA19) -> 0 | P19: =10000-SUM(Q19:AA19) -> 6440 | Q19: 2600 | R19: 660 | S19: 300 | T19: 0 | U19: 0 | V19: 0 | W19: 0 | X19: 0 | Y19: 0 | Z19: 0 | AA19: 0 | AB19: {=SUMPRODUCT(O19:AA19/SUM(O19:AA19),$O$4:$AA$4)} -> 2.638
B20: 15 | C20: 0 | D20: 1 | E20: 0 | F20: 1 | G20: 0 | I20: FG_Symbol (2) | J20: 0 | L20: 0 | N20: FG_Symbol (2) | O20: =10000-SUM(P20:AA20) -> 0 | P20: =10000-SUM(Q20:AA20) -> 6440 | Q20: 2600 | R20: 660 | S20: 300 | T20: 0 | U20: 0 | V20: 0 | W20: 0 | X20: 0 | Y20: 0 | Z20: 0 | AA20: 0 | AB20: {=SUMPRODUCT(O20:AA20/SUM(O20:AA20),$O$4:$AA$4)} -> 2.638
B21: 16 | C21: 2 | D21: 1 | E21: 2 | F21: 1 | G21: 2 | I21: FG_Symbol (3) | J21: 0 | L21: 0 | N21: FG_Symbol (3) | O21: =10000-SUM(P21:AA21) -> 0 | P21: =10000-SUM(Q21:AA21) -> 6440 | Q21: 2600 | R21: 660 | S21: 300 | T21: 0 | U21: 0 | V21: 0 | W21: 0 | X21: 0 | Y21: 0 | Z21: 0 | AA21: 0 | AB21: {=SUMPRODUCT(O21:AA21/SUM(O21:AA21),$O$4:$AA$4)} -> 2.638
B22: 17 | C22: 0 | D22: 0 | E22: 1 | F22: 2 | G22: 2 | J22: =SUM(J19:J21) -> 10000 | K22: =SUMPRODUCT(K19:K21,_xlfn.ANCHORARRAY(L19)) -> 0 | N22: BF_Symbol | O22: =10000-SUM(P22:AA22) -> 8100 | P22: 800 | Q22: 700 | R22: 400 | S22: 0 | T22: 0 | U22: 0 | V22: 0 | W22: 0 | X22: 0 | Y22: 0 | Z22: 0 | AA22: 0 | AB22: {=SUMPRODUCT(O22:AA22/SUM(O22:AA22),$O$4:$AA$4)} -> 0.57
B23: 18 | C23: 2 | D23: 2 | E23: 1 | F23: 0 | G23: 0
B24: 19 | C24: 0 | D24: 2 | E24: 0 | F24: 2 | G24: 0 | I24: Multiplier Range
I25: Multiplier | N25: Multiple Selection Weight - Reel3 After Eliminate (Weight/Total)
I26: 0 | N26: Worksheet Name \ Multiple | O26: 0 | P26: 2 | Q26: 3 | R26: 5 | S26: 8 | T26: 10 | U26: 15 | V26: 20 | W26: 25 | X26: 35 | Y26: 50 | Z26: 80 | AA26: 100
I27: 2 | N27: BG_Symbol | O27: =10000-SUM(P27:AA27) -> 8700 | P27: 500 | Q27: 400 | R27: 200 | S27: 200 | T27: 0 | U27: 0 | V27: 0 | W27: 0 | X27: 0 | Y27: 0 | Z27: 0 | AA27: 0 | AB27: {=SUMPRODUCT(O27:AA27/SUM(O27:AA27),$O$4:$AA$4)} -> 0.48
I28: 3 | N28: BG_Symbol (2) | O28: =10000-SUM(P28:AA28) -> 0 | P28: =10000-SUM(Q28:AA28) -> 4400 | Q28: 2600 | R28: 1500 | S28: 1500 | T28: 0 | U28: 0 | V28: 0 | W28: 0 | X28: 0 | Y28: 0 | Z28: 0 | AA28: 0 | AB28: {=SUMPRODUCT(O28:AA28/SUM(O28:AA28),$O$4:$AA$4)} -> 3.61
I29: 5 | N29: BG_Symbol (3) | O29: =10000-SUM(P29:AA29) -> 8100 | P29: 800 | Q29: 700 | R29: 400 | S29: 0 | T29: 0 | U29: 0 | V29: 0 | W29: 0 | X29: 0 | Y29: 0 | Z29: 0 | AA29: 0 | AB29: {=SUMPRODUCT(O29:AA29/SUM(O29:AA29),$O$4:$AA$4)} -> 0.57
I30: 8 | N30: FG_Symbol | O30: =10000-SUM(P30:AA30) -> 0 | P30: =10000-SUM(Q30:AA30) -> 7100 | Q30: 2500 | R30: 300 | S30: 100 | T30: 0 | U30: 0 | V30: 0 | W30: 0 | X30: 0 | Y30: 0 | Z30: 0 | AA30: 0 | AB30: {=SUMPRODUCT(O30:AA30/SUM(O30:AA30),$O$4:$AA$4)} -> 2.4
I31: 10 | N31: FG_Symbol (2) | O31: =10000-SUM(P31:AA31) -> 0 | P31: =10000-SUM(Q31:AA31) -> 7100 | Q31: 2500 | R31: 300 | S31: 100 | T31: 0 | U31: 0 | V31: 0 | W31: 0 | X31: 0 | Y31: 0 | Z31: 0 | AA31: 0 | AB31: {=SUMPRODUCT(O31:AA31/SUM(O31:AA31),$O$4:$AA$4)} -> 2.4
I32: 15 | N32: FG_Symbol (3) | O32: =10000-SUM(P32:AA32) -> 0 | P32: =10000-SUM(Q32:AA32) -> 7100 | Q32: 2500 | R32: 300 | S32: 100 | T32: 0 | U32: 0 | V32: 0 | W32: 0 | X32: 0 | Y32: 0 | Z32: 0 | AA32: 0 | AB32: {=SUMPRODUCT(O32:AA32/SUM(O32:AA32),$O$4:$AA$4)} -> 2.4
I33: 20 | N33: BF_Symbol | O33: =10000-SUM(P33:AA33) -> 8100 | P33: 800 | Q33: 700 | R33: 400 | S33: 0 | T33: 0 | U33: 0 | V33: 0 | W33: 0 | X33: 0 | Y33: 0 | Z33: 0 | AA33: 0 | AB33: {=SUMPRODUCT(O33:AA33/SUM(O33:AA33),$O$4:$AA$4)} -> 0.57
I34: 25
I35: 35 | T35: 10 | U35: 60 | V35: 30 | W35: 20 | X35: 20 | Y35: 10 | Z35: 50
I36: 50 | N36: Multiple Selection Weight - Before Eliminate (Weight/Total)
I37: 80 | N37: Worksheet Name \ Multiple | O37: 0 | P37: 2 | Q37: 3 | R37: 5 | S37: 8 | T37: 10 | U37: 15 | V37: 20 | W37: 25 | X37: 35 | Y37: 50 | Z37: 80 | AA37: 100
I38: 100 | N38: BG_Symbol | O38: =10000-SUM(P38:AA38) -> 8100 | P38: 600 | Q38: 500 | R38: 400 | S38: 400 | T38: 0 | U38: 0 | V38: 0 | W38: 0 | X38: 0 | Y38: 0 | Z38: 0 | AA38: 0 | AB38: {=SUMPRODUCT(O38:AA38/SUM(O38:AA38),$O$4:$AA$4)} -> 0.79
N39: BG_Symbol (2) | O39: =10000-SUM(P39:AA39) -> 8100 | P39: 600 | Q39: 500 | R39: 400 | S39: 400 | T39: 0 | U39: 0 | V39: 0 | W39: 0 | X39: 0 | Y39: 0 | Z39: 0 | AA39: 0 | AB39: {=SUMPRODUCT(O39:AA39/SUM(O39:AA39),$O$4:$AA$4)} -> 0.79
N40: BG_Symbol (3) | O40: =10000-SUM(P40:AA40) -> 8100 | P40: 800 | Q40: 700 | R40: 400 | S40: 0 | T40: 0 | U40: 0 | V40: 0 | W40: 0 | X40: 0 | Y40: 0 | Z40: 0 | AA40: 0 | AB40: {=SUMPRODUCT(O40:AA40/SUM(O40:AA40),$O$4:$AA$4)} -> 0.57
I41: Eliminate Table Weight | N41: FG_Symbol | O41: =10000-SUM(P41:AA41) -> 6500 | P41: 2100 | Q41: 1000 | R41: 200 | S41: 200 | T41: 0 | U41: 0 | V41: 0 | W41: 0 | X41: 0 | Y41: 0 | Z41: 0 | AA41: 0 | AB41: {=SUMPRODUCT(O41:AA41/SUM(O41:AA41),$O$4:$AA$4)} -> 0.98
J42: A | K42: B | N42: FG_Symbol (2) | O42: =10000-SUM(P42:AA42) -> 6500 | P42: 2100 | Q42: 1000 | R42: 200 | S42: 200 | T42: 0 | U42: 0 | V42: 0 | W42: 0 | X42: 0 | Y42: 0 | Z42: 0 | AA42: 0 | AB42: {=SUMPRODUCT(O42:AA42/SUM(O42:AA42),$O$4:$AA$4)} -> 0.98
...

Sheet Multiplier_Weight
B3: {=Multiplier_Weight_Oldhand!H14:H79} -> Range | C3: Weight_BG | D3: cum | E3: Weight_FG | F3: Weight_BF
B4: (-1, 0] | C4: {=Multiplier_Weight_Oldhand!L15:L79} -> 740278469 | D4: =SUM($C$4:C4) -> 740278469 | E4: {=Multiplier_Weight_Oldhand!L87:L150} -> 0 | F4: 0 | H4: 746296 | I4: {=_xlfn.ANCHORARRAY(C4)/SUM(_xlfn.ANCHORARRAY(C4))} -> 0.74027847 | J4: {=H4:H67/SUM(H4:H67)} -> 0.746296 | L4: 0 | M4: {=_xlfn.ANCHORARRAY(E4)/SUM(_xlfn.ANCHORARRAY(E4))} -> 0 | N4: {=L4:L67/SUM(L4:L67)} -> 0
B5: (0, 1] | C5: 168065068 | D5: =SUM($C$4:C5) -> 908343537 | E5: 0 | F5: 0 | H5: 168324 | I5: 0.16806507 | J5: 0.168324 | L5: 0 | M5: 0 | N5: 0
B6: (1, 2] | C6: 36253475 | D6: =SUM($C$4:C6) -> 944597012 | E6: 0 | F6: 0 | H6: 36147 | I6: 0.036253475 | J6: 0.036147 | L6: 0 | M6: 0 | N6: 0
B7: (2, 3] | C7: 16477087 | D7: =SUM($C$4:C7) -> 961074099 | E7: 0 | F7: 0 | H7: 16571 | I7: 0.016477087 | J7: 0.016571 | L7: 0 | M7: 0 | N7: 0
B8: (3, 4] | C8: 7840052 | D8: =SUM($C$4:C8) -> 968914151 | E8: 0 | F8: 0 | H8: 7879 | I8: 0.007840052 | J8: 0.007879 | L8: 0 | M8: 0 | N8: 0
B9: (4, 5] | C9: 5404149 | D9: =SUM($C$4:C9) -> 974318300 | E9: 0 | F9: 0 | H9: 5318 | I9: 0.005404149 | J9: 0.005318 | L9: 0 | M9: 0 | N9: 0
B10: (5, 6] | C10: 4037019 | D10: =SUM($C$4:C10) -> 978355319 | E10: 0 | F10: 0 | H10: 4051 | I10: 0.004037019 | J10: 0.004051 | L10: 0 | M10: 0 | N10: 0
B11: (6, 7] | C11: 2596321 | D11: =SUM($C$4:C11) -> 980951640 | E11: 0 | F11: 0 | H11: 2617 | I11: 0.002596321 | J11: 0.002617 | L11: 0 | M11: 0 | N11: 0
B12: (7, 8] | C12: 2902852 | D12: =SUM($C$4:C12) -> 983854492 | E12: 0 | F12: 0 | H12: 2899 | I12: 0.002902852 | J12: 0.002899 | L12: 0 | M12: 0 | N12: 0
B13: (8, 9] | C13: 1921952 | D13: =SUM($C$4:C13) -> 985776444 | E13: 0 | F13: 0 | H13: 1900 | I13: 0.001921952 | J13: 0.0019 | L13: 0 | M13: 0 | N13: 0
B14: (9, 10] | C14: 1837145 | D14: =SUM($C$4:C14) -> 987613589 | E14: 0 | F14: 0 | H14: 1896 | I14: 0.001837145 | J14: 0.001896 | L14: 0 | M14: 0 | N14: 0
B15: (10, 15] | C15: 6120411 | D15: =SUM($C$4:C15) -> 993734000 | E15: 0 | F15: 0 | H15: 6101 | I15: 0.006120411 | J15: 0.006101 | L15: 0 | M15: 0 | N15: 0
B16: (15, 20] | C16: 0 | D16: =SUM($C$4:C16) -> 993734000 | E16: 0 | F16: 0 | H16: 0 | I16: 0 | J16: 0 | L16: 0 | M16: 0 | N16: 0
... B67: (100000, 9999999] | C67: 0 | D67: =SUM($C$4:C67) -> 993734000 | E67: 0 | F67: 0 | H67: 0 | I67: 0 | J67: 0 | L67: 0 | M67: 0 | N67: 0
B68: Free Game | C68: 6266000 | D68: =SUM($C$4:C68) -> 1000000000 | I68: 0.006266

Sheet 工作表2
B2: 金框出現率(B1)
B3: Cnt | C3: PG | D3: OP
B4: 0 | C4: 0.12890728 | D4: 0.1798 | G4: 0 | H4: {=G4:G13/10000} -> 0
B5: 1 | C5: 0.30351325 | D5: 0.3534 | G5: {=TRANSPOSE(Parameter!AD5:AL5)} -> 500 | H5: 0.05
B6: 2 | C6: 0.30338117 | D6: 0.2963 | G6: 1000 | H6: 0.1
B7: 3 | C7: 0.18173814 | D7: 0.1327 | G7: 1500 | H7: 0.15
B8: 4 | C8: 0.063705204 | D8: 0.0333 | G8: 3000 | H8: 0.3
B9: 5 | C9: 0.014748613 | D9: 0.0044 | G9: 10000 | H9: 1
B10: 6 | C10: 0.0036101083 | D10: 0.0002 | G10: 10000 | H10: 1
B11: 7 | C11: 0.0003962314 | D11: 0 | G11: 10000 | H11: 1
B12: 8 | C12: 0 | D12: 0 | G12: 10000 | H12: 1
B13: 9 | C13: 0 | D13: 0 | G13: 10000 | H13: 1
B16: 倍數出現率 | I16: =1/I17 -> 12.225686
C17: PG | D17: OP | I17: =SUMPRODUCT(H4:H13,D4:D13) -> 0.081795
B18: 0 | C18: 0.86973562 | D18: {=J18:J30} -> 0.74374605 | F18: {=TRANSPOSE(Parameter!O16:AA16)} -> 8100 | G18: {=TRANSPOSE(Parameter!O5:AA5)} -> 0 | H18: {=_xlfn.ANCHORARRAY(F18)/SUM(_xlfn.ANCHORARRAY(F18))*(1-I17)} -> 0.74374605 | I18: {=_xlfn.ANCHORARRAY(G18)/SUM(_xlfn.ANCHORARRAY(G18))*I17} -> 0 | J18: {=H18:H22} -> 0.74374605
B19: 2 | C19: 0.034690102 | D19: 0.0550923 | F19: 600 | G19: 0 | H19: 0.0550923 | I19: 0 | J19: 0.0550923
B20: 3 | C20: 0.028506743 | D20: 0.04591025 | F20: 500 | G20: 0 | H20: 0.04591025 | I20: 0 | J20: 0.04591025
B21: 5 | C21: 0.019109986 | D21: 0.0367282 | F21: 400 | G21: 0 | H21: 0.0367282 | I21: 0 | J21: 0.0367282
B22: 8 | C22: 0.018111885 | D22: 0.0367282 | F22: 400 | G22: 0 | H22: 0.0367282 | I22: 0 | J22: 0.0367282
B23: 10 | C23: 0.014849798 | D23: 0.0278103 | F23: 0 | G23: 3400 | H23: 0 | I23: 0.0278103 | J23: {=I23:I30} -> 0.0278103
B24: 15 | C24: 0.0087881591 | D24: 0.0098154 | F24: 0 | G24: 1200 | H24: 0 | I24: 0.0098154 | J24: 0.0098154
B25: 20 | C25: 0.0045523151 | D25: 0.0196308 | F25: 0 | G25: 2400 | H25: 0 | I25: 0.0196308 | J25: 0.0196308
B26: 25 | C26: 0.0013876041 | D26: 0.00408975 | F26: 0 | G26: 500 | H26: 0 | I26: 0.00408975 | J26: 0.00408975
B27: 35 | C27: 0.00019475145 | D27: 0.0016359 | F27: 0 | G27: 200 | H27: 0 | I27: 0.0016359 | J27: 0.0016359
B28: 50 | C28: 2.4343931e-05 | D28: 0.0016359 | F28: 0 | G28: 200 | H28: 0 | I28: 0.0016359 | J28: 0.0016359
B29: 80 | C29: 4.8687862e-05 | D29: 0.0098154 | F29: 0 | G29: 1200 | H29: 0 | I29: 0.0098154 | J29: 0.0098154
B30: 100 | C30: 0 | D30: 0.00736155 | F30: 0 | G30: 900 | H30: 0 | I30: 0.00736155 | J30: 0.00736155
C31: =SUMPRODUCT(C18:C30,B18:B30) -> 0.81333074 | D31: =SUMPRODUCT(D18:D30,B18:B30) -> 3.3060142
B34: 金框出現率(B2)
B35: Cnt | C35: PG | D35: OP
B36: 0 | C36: 0.12890728 | D36: 0 | G36: 0 | H36: {=G36:G45/10000} -> 0
B37: 1 | C37: 0.30351325 | D37: 0 | G37: {=TRANSPOSE(Parameter!AD6:AL6)} -> 0 | H37: 0
B38: 2 | C38: 0.30338117 | D38: 0 | G38: 0 | H38: 0
B39: 3 | C39: 0.18173814 | D39: 0.1796 | G39: 1000 | H39: 0.1
B40: 4 | C40: 0.063705204 | D40: 0.3822 | G40: 1500 | H40: 0.15
B41: 5 | C41: 0.014748613 | D41: 0.2992 | G41: 2500 | H41: 0.25
B42: 6 | C42: 0.0036101083 | D42: 0.1134 | G42: 5000 | H42: 0.5
B43: 7 | C43: 0.0003962314 | D43: 0.023 | G43: 10000 | H43: 1
B44: 8 | C44: 0 | D44: 0.0024 | G44: 10000 | H44: 1
B45: 9 | C45: 0 | D45: 0.0001 | G45: 10000 | H45: 1
...

Sheet Multiplier_Weight_Newbie
A2: Threshold | B2: 1000000000
A3: Coin in | B3: =Overview!A7 -> 100
C5: RTP
B6: Bet | C6: Base Game | D6: Free Game | E6: Total | F6: Hit Rate | G6: FG Period | H6: Avg Multi
A7: Normal Bet | B7: {=Overview!B11:B12} -> 1 | C7: =SUM(N15:N79) -> #DIV/0! | D7: =SUM(_xlfn.ANCHORARRAY(N87))*M79 -> #DIV/0! | E7: =SUM(C7:D7) -> #DIV/0! | F7: =M79 -> #DIV/0! | G7: =1/F7 -> #DIV/0! | H7: =D7*G7 -> #DIV/0!
B8: 75
A11: Base Game
A13: Simulator | B13: =10^8 -> 100000000 | H13: Calculate
A14: Lower | B14: Upper | C14: Cnt | D14: Pay | E14: Hit Rate | F14: Avg. Multi. | H14: Range | I14: Fix Num | J14: Fix Rate | K14: Final Rate | L14: Weight | M14: Hit Rate | N14: Simulator RTP | O14: 1.1
A15: -1 | B15: 0 | E15: {=_xlfn.LET(_xlpm.x, C15:C78, _xlpm.x/SUM(_xlpm.x))} -> #DIV/0! | F15: {=_xlfn.LET(_xlpm.x, D15:D80/C15:C80/B3, IF(ISERR(_xlpm.x), 0, _xlpm.x))} -> 0 | H15: ="("&$A15&", "&$B15&"]" -> (-1, 0] | I15: 1 | J15: {=E15:E79*I15:I79} -> #DIV/0! | K15: {=J15:J78/SUM(_xlfn.ANCHORARRAY(J15))} -> #DIV/0! | L15: =INT($B$2-SUM(_xlfn.ANCHORARRAY(L16))) -> #DIV/0! | M15: {=_xlfn.LET(_xlpm.x, L15:L79, _xlpm.x/SUM(_xlpm.x))} -> #DIV/0! | N15: {=M15:M79*F15:F79} -> #DIV/0! | O15: {=I15:I78*O14} -> 1.1
A16: 0 | B16: 1 | E16: #DIV/0! | F16: 0 | H16: ="("&$A16&", "&$B16&"]" -> (0, 1] | I16: 1 | J16: #DIV/0! | K16: #DIV/0! | L16: {=INT(K16:K79*$B$2)} -> #DIV/0! | M16: #DIV/0! | N16: #DIV/0! | O16: 1.1
A17: 1 | B17: 2 | E17: #DIV/0! | F17: 0 | H17: ="("&$A17&", "&$B17&"]" -> (1, 2] | I17: 1 | J17: #DIV/0! | K17: #DIV/0! | L17: #DIV/0! | M17: #DIV/0! | N17: #DIV/0! | O17: 1.1
A18: 2 | B18: 3 | E18: #DIV/0! | F18: 0 | H18: ="("&$A18&", "&$B18&"]" -> (2, 3] | I18: 1 | J18: #DIV/0! | K18: #DIV/0! | L18: #DIV/0! | M18: #DIV/0! | N18: #DIV/0! | O18: 1.1
A19: 3 | B19: 4 | E19: #DIV/0! | F19: 0 | H19: ="("&$A19&", "&$B19&"]" -> (3, 4] | I19: 1 | J19: #DIV/0! | K19: #DIV/0! | L19: #DIV/0! | M19: #DIV/0! | N19: #DIV/0! | O19: 1.1
A20: 4 | B20: 5 | E20: #DIV/0! | F20: 0 | H20: ="("&$A20&", "&$B20&"]" -> (4, 5] | I20: 1 | J20: #DIV/0! | K20: #DIV/0! | L20: #DIV/0! | M20: #DIV/0! | N20: #DIV/0! | O20: 1.1
A21: 5 | B21: 6 | E21: #DIV/0! | F21: 0 | H21: ="("&$A21&", "&$B21&"]" -> (5, 6] | I21: 1 | J21: #DIV/0! | K21: #DIV/0! | L21: #DIV/0! | M21: #DIV/0! | N21: #DIV/0! | O21: 1.1
A22: 6 | B22: 7 | E22: #DIV/0! | F22: 0 | H22: ="("&$A22&", "&$B22&"]" -> (6, 7] | I22: 1 | J22: #DIV/0! | K22: #DIV/0! | L22: #DIV/0! | M22: #DIV/0! | N22: #DIV/0! | O22: 1.1
A23: 7 | B23: 8 | E23: #DIV/0! | F23: 0 | H23: ="("&$A23&", "&$B23&"]" -> (7, 8] | I23: 1 | J23: #DIV/0! | K23: #DIV/0! | L23: #DIV/0! | M23: #DIV/0! | N23: #DIV/0! | O23: 1.1
A24: 8 | B24: 9 | E24: #DIV/0! | F24: 0 | H24: ="("&$A24&", "&$B24&"]" -> (8, 9] | I24: 1 | J24: #DIV/0! | K24: #DIV/0! | L24: #DIV/0! | M24: #DIV/0! | N24: #DIV/0! | O24: 1.1
A25: 9 | B25: 10 | E25: #DIV/0! | F25: 0 | H25: ="("&$A25&", "&$B25&"]" -> (9, 10] | I25: 1 | J25: #DIV/0! | K25: #DIV/0! | L25: #DIV/0! | M25: #DIV/0! | N25: #DIV/0! | O25: 1.1
A26: 10 | B26: 15 | E26: #DIV/0! | F26: 0 | G26: =SUM($L$15:L25)-1000 -> #DIV/0! | H26: ="("&$A26&", "&$B26&"]" -> (10, 15] | I26: 1 | J26: #DIV/0! | K26: #DIV/0! | L26: #DIV/0! | M26: #DIV/0! | N26: #DIV/0! | O26: 1.1
A27: 15 | B27: 20 | E27: #DIV/0! | F27: 0 | G27: =SUM($L$15:L26)-1000 -> #DIV/0! | H27: ="("&$A27&", "&$B27&"]" -> (15, 20] | I27: 1 | J27: #DIV/0! | K27: #DIV/0! | L27: #DIV/0! | M27: #DIV/0! | N27: #DIV/0! | O27: 1.1
A28: 20 | B28: 25 | E28: #DIV/0! | F28: 0 | G28: =SUM($L$15:L27)-1000 -> #DIV/0! | H28: ="("&$A28&", "&$B28&"]" -> (20, 25] | I28: 1 | J28: #DIV/0! | K28: #DIV/0! | L28: #DIV/0! | M28: #DIV/0! | N28: #DIV/0! | O28: 1.1
A29: 25 | B29: 30 | E29: #DIV/0! | F29: 0 | G29: =SUM($L$15:L28)-1000 -> #DIV/0! | H29: ="("&$A29&", "&$B29&"]" -> (25, 30] | I29: 1 | J29: #DIV/0! | K29: #DIV/0! | L29: #DIV/0! | M29: #DIV/0! | N29: #DIV/0! | O29: 1.1
A30: 30 | B30: 35 | E30: #DIV/0! | F30: 0 | G30: =SUM($L$15:L29)-1000 -> #DIV/0! | H30: ="("&$A30&", "&$B30&"]" -> (30, 35] | I30: 1 | J30: #DIV/0! | K30: #DIV/0! | L30: #DIV/0! | M30: #DIV/0! | N30: #DIV/0! | O30: 1.1
A31: 35 | B31: 40 | E31: #DIV/0! | F31: 0 | G31: =SUM($L$15:L30)-1000 -> #DIV/0! | H31: ="("&$A31&", "&$B31&"]" -> (35, 40] | I31: 1 | J31: #DIV/0! | K31: #DIV/0! | L31: #DIV/0! | M31: #DIV/0! | N31: #DIV/0! | O31: 1.1
A32: 40 | B32: 45 | E32: #DIV/0! | F32: 0 | G32: =SUM($L$15:L31)-1000 -> #DIV/0! | H32: ="("&$A32&", "&$B32&"]" -> (40, 45] | I32: 1 | J32: #DIV/0! | K32: #DIV/0! | L32: #DIV/0! | M32: #DIV/0! | N32: #DIV/0! | O32: 1.1
A33: 45 | B33: 50 | E33: #DIV/0! | F33: 0 | G33: =SUM($L$15:L32)-1000 -> #DIV/0! | H33: ="("&$A33&", "&$B33&"]" -> (45, 50] | I33: 1 | J33: #DIV/0! | K33: #DIV/0! | L33: #DIV/0! | M33: #DIV/0! | N33: #DIV/0! | O33: 1.1
A34: 50 | B34: 60 | E34: #DIV/0! | F34: 0 | G34: =SUM($L$15:L33)-1000 -> #DIV/0! | H34: ="("&$A34&", "&$B34&"]" -> (50, 60] | I34: 1 | J34: #DIV/0! | K34: #DIV/0! | L34: #DIV/0! | M34: #DIV/0! | N34: #DIV/0! | O34: 1.1
A35: 60 | B35: 70 | E35: #DIV/0! | F35: 0 | H35: ="("&$A35&", "&$B35&"]" -> (60, 70] | I35: 1 | J35: #DIV/0! | K35: #DIV/0! | L35: #DIV/0! | M35: #DIV/0! | N35: #DIV/0! | O35: 1.1
A36: 70 | B36: 80 | E36: #DIV/0! | F36: 0 | H36: ="("&$A36&", "&$B36&"]" -> (70, 80] | I36: 1 | J36: #DIV/0! | K36: #DIV/0! | L36: #DIV/0! | M36: #DIV/0! | N36: #DIV/0! | O36: 1.1
A37: 80 | B37: 90 | E37: #DIV/0! | F37: 0 | H37: ="("&$A37&", "&$B37&"]" -> (80, 90] | I37: 1 | J37: #DIV/0! | K37: #DIV/0! | L37: #DIV/0! | M37: #DIV/0! | N37: #DIV/0! | O37: 1.1
A38: 90 | B38: 100 | E38: #DIV/0! | F38: 0 | H38: ="("&$A38&", "&$B38&"]" -> (90, 100] | I38: 1 | J38: #DIV/0! | K38: #DIV/0! | L38: #DIV/0! | M38: #DIV/0! | N38: #DIV/0! | O38: 1.1
A39: 100 | B39: 120 | E39: #DIV/0! | F39: 0 | H39: ="("&$A39&", "&$B39&"]" -> (100, 120] | I39: 1 | J39: #DIV/0! | K39: #DIV/0! | L39: #DIV/0! | M39: #DIV/0! | N39: #DIV/0! | O39: 1.1
A40: 120 | B40: 140 | E40: #DIV/0! | F40: 0 | H40: ="("&$A40&", "&$B40&"]" -> (120, 140] | I40: 1 | J40: #DIV/0! | K40: #DIV/0! | L40: #DIV/0! | M40: #DIV/0! | N40: #DIV/0! | O40: 1.1
A41: 140 | B41: 160 | E41: #DIV/0! | F41: 0 | H41: ="("&$A41&", "&$B41&"]" -> (140, 160] | I41: 1 | J41: #DIV/0! | K41: #DIV/0! | L41: #DIV/0! | M41: #DIV/0! | N41: #DIV/0! | O41: 1.1
A42: 160 | B42: 180 | E42: #DIV/0! | F42: 0 | H42: ="("&$A42&", "&$B42&"]" -> (160, 180] | I42: 1 | J42: #DIV/0! | K42: #DIV/0! | L42: #DIV/0! | M42: #DIV/0! | N42: #DIV/0! | O42: 1.1
A43: 180 | B43: 200 | E43: #DIV/0! | F43: 0 | H43: ="("&$A43&", "&$B43&"]" -> (180, 200] | I43: 1 | J43: #DIV/0! | K43: #DIV/0! | L43: #DIV/0! | M43: #DIV/0! | N43: #DIV/0! | O43: 1.1
A44: 200 | B44: 250 | E44: #DIV/0! | F44: 0 | H44: ="("&$A44&", "&$B44&"]" -> (200, 250] | I44: 1 | J44: #DIV/0! | K44: #DIV/0! | L44: #DIV/0! | M44: #DIV/0! | N44: #DIV/0! | O44: 1.1
A45: 250 | B45: 300 | E45: #DIV/0! | F45: 0 | H45: ="("&$A45&", "&$B45&"]" -> (250, 300] | I45: 1 | J45: #DIV/0! | K45: #DIV/0! | L45: #DIV/0! | M45: #DIV/0! | N45: #DIV/0! | O45: 1.1
...

Sheet Multiplier_Weight_Oldhand
A2: Threshold | B2: 1000000000
A3: Coin in | B3: =Overview!A7 -> 100
C5: RTP
B6: Bet | C6: Base Game | D6: Free Game | E6: Total | F6: Hit Rate | G6: FG Period | H6: Avg Multi
A7: Normal Bet | B7: {=Overview!B11:B12} -> 1 | C7: =SUM(N15:N79) -> 0.39055499 | D7: =SUM(_xlfn.ANCHORARRAY(N87))*M79 -> 0.76715504 | E7: =SUM(C7:D7) -> 1.15771 | F7: =M79 -> 0.006266 | G7: =1/F7 -> 159.59145 | H7: =D7*G7 -> 122.43138
A8: Buy Feature | B8: 75 | C8: =N80 -> 0 | D8: =SUM(_xlfn.ANCHORARRAY(N157))/B8 -> 6.6445586 | E8: =SUM(C8:D8) -> 6.6445586 | F8: =E80 -> 1 | G8: =1/F8 -> 1 | H8: =D8*G8*B8 -> 498.3419
A11: Base Game
A13: Simulator | B13: =10^8 -> 100000000 | H13: Calculate | P13: Compare | U13: 0.71068527
A14: Lower | B14: Upper | C14: Cnt | D14: Pay | E14: Hit Rate | F14: Avg. Multi. | H14: Range | I14: Fix Num | J14: Fix Rate | K14: Final Rate | L14: Weight | M14: Hit Rate | N14: Simulator RTP | O14: 0.95 | P14: 目前 | Q14: 賞金大對決 | R14: 差異 | T14: Range | U14: 賞金大對決 | V14: 糖果
A15: -1 | B15: 0 | C15: 724391 | D15: 0 | E15: {=_xlfn.LET(_xlpm.x, C15:C78, _xlpm.x/SUM(_xlpm.x))} -> 0.72666765 | F15: {=_xlfn.LET(_xlpm.x, D15:D80/C15:C80/B3, IF(ISERR(_xlpm.x), 0, _xlpm.x))} -> 0 | H15: ="("&$A15&", "&$B15&"]" -> (-1, 0] | I15: 1 | J15: {=E15:E79*I15:I79} -> 0.72666765 | K15: {=J15:J78/SUM(_xlfn.ANCHORARRAY(J15))} -> 0.7401621 | L15: =INT($B$2-SUM(_xlfn.ANCHORARRAY(L16))) -> 740278469 | M15: {=_xlfn.LET(_xlpm.x, L15:L79, _xlpm.x/SUM(_xlpm.x))} -> 0.74027847 | N15: {=M15:M79*F15:F79} -> 0 | O15: {=I15:I78*O14} -> 0.95 | P15: {=M15:M78} -> 0.74027847 | Q15: {=_xlfn.XLOOKUP(Q14,U14:W14,U15:W78)} -> 0.71593622 | R15: {=_xlfn.LET(_xlpm.x, Q15:Q78/M15:M78, IF(ISERR(_xlpm.x), 0, ROUND(_xlpm.x,2)))} -> 0.97 | T15: ="("&$A15&", "&$B15&"]" -> (-1, 0] | U15: 0.71593622
A16: 0 | B16: 1 | C16: 164484 | D16: 6793075 | E16: 0.16500095 | F16: 0.41299306 | H16: ="("&$A16&", "&$B16&"]" -> (0, 1] | I16: 1 | J16: 0.16500095 | K16: 0.16806507 | L16: {=INT(K16:K79*$B$2)} -> 168065068 | M16: 0.16806507 | N16: 0.069409706 | O16: 0.95 | P16: 0.16806507 | Q16: 0.19096725 | R16: 1.14 | T16: ="("&$A16&", "&$B16&"]" -> (0, 1] | U16: 0.19096725
A17: 1 | B17: 2 | C17: 35481 | D17: 5292945 | E17: 0.035592511 | F17: 1.4917688 | H17: ="("&$A17&", "&$B17&"]" -> (1, 2] | I17: 1 | J17: 0.035592511 | K17: 0.036253476 | L17: 36253475 | M17: 0.036253475 | N17: 0.054081804 | O17: 0.95 | P17: 0.036253475 | Q17: 0.032464432 | R17: 0.9 | T17: ="("&$A17&", "&$B17&"]" -> (1, 2] | U17: 0.032464432
A18: 2 | B18: 3 | C18: 16126 | D18: 4066310 | E18: 0.016176682 | F18: 2.5215863 | H18: ="("&$A18&", "&$B18&"]" -> (2, 3] | I18: 1 | J18: 0.016176682 | K18: 0.016477088 | L18: 16477087 | M18: 0.016477087 | N18: 0.041548396 | O18: 0.95 | P18: 0.016477087 | Q18: 0.014990929 | R18: 0.91 | T18: ="("&$A18&", "&$B18&"]" -> (2, 3] | U18: 0.014990929
A19: 3 | B19: 4 | C19: 7673 | D19: 2744615 | E19: 0.0076971151 | F19: 3.5769777 | H19: ="("&$A19&", "&$B19&"]" -> (3, 4] | I19: 1 | J19: 0.0076971151 | K19: 0.007840053 | L19: 7840052 | M19: 0.007840052 | N19: 0.028043691 | O19: 0.95 | P19: 0.007840052 | Q19: 0.0080206245 | R19: 1.02 | T19: ="("&$A19&", "&$B19&"]" -> (3, 4] | U19: 0.0080206245
A20: 4 | B20: 5 | C20: 5289 | D20: 2441570 | E20: 0.0053056225 | F20: 4.6163169 | H20: ="("&$A20&", "&$B20&"]" -> (4, 5] | I20: 1 | J20: 0.0053056225 | K20: 0.0054041496 | L20: 5404149 | M20: 0.005404149 | N20: 0.024947264 | O20: 0.95 | P20: 0.005404149 | Q20: 0.0067793373 | R20: 1.25 | T20: ="("&$A20&", "&$B20&"]" -> (4, 5] | U20: 0.0067793373
A21: 5 | B21: 6 | C21: 3951 | D21: 2214305 | E21: 0.0039634174 | F21: 5.6044166 | H21: ="("&$A21&", "&$B21&"]" -> (5, 6] | I21: 1 | J21: 0.0039634174 | K21: 0.0040370193 | L21: 4037019 | M21: 0.004037019 | N21: 0.022625136 | O21: 0.95 | P21: 0.004037019 | Q21: 0.0043922467 | R21: 1.09 | T21: ="("&$A21&", "&$B21&"]" -> (5, 6] | U21: 0.0043922467
A22: 6 | B22: 7 | C22: 2541 | D22: 1670120 | E22: 0.002548986 | F22: 6.5726879 | H22: ="("&$A22&", "&$B22&"]" -> (6, 7] | I22: 1 | J22: 0.002548986 | K22: 0.0025963215 | L22: 2596321 | M22: 0.002596321 | N22: 0.017064808 | O22: 0.95 | P22: 0.002596321 | Q22: 0.0046786976 | R22: 1.8 | T22: ="("&$A22&", "&$B22&"]" -> (6, 7] | U22: 0.0046786976
A23: 7 | B23: 8 | C23: 2841 | D23: 2175740 | E23: 0.0028499288 | F23: 7.6583597 | H23: ="("&$A23&", "&$B23&"]" -> (7, 8] | I23: 1 | J23: 0.0028499288 | K23: 0.0029028529 | L23: 2902852 | M23: 0.002902852 | N23: 0.022231085 | O23: 0.95 | P23: 0.002902852 | Q23: 0.0040103122 | R23: 1.38 | T23: ="("&$A23&", "&$B23&"]" -> (7, 8] | U23: 0.0040103122
A24: 8 | B24: 9 | C24: 1881 | D24: 1620565 | E24: 0.0018869117 | F24: 8.6154439 | H24: ="("&$A24&", "&$B24&"]" -> (8, 9] | I24: 1 | J24: 0.0018869117 | K24: 0.0019219523 | L24: 1921952 | M24: 0.001921952 | N24: 0.01655847 | O24: 0.95 | P24: 0.001921952 | Q24: 0.0035328941 | R24: 1.84 | T24: ="("&$A24&", "&$B24&"]" -> (8, 9] | U24: 0.0035328941
A25: 9 | B25: 10 | C25: 1798 | D25: 1744480 | E25: 0.0018036508 | F25: 9.7023359 | H25: ="("&$A25&", "&$B25&"]" -> (9, 10] | I25: 1 | J25: 0.0018036508 | K25: 0.0018371452 | L25: 1837145 | M25: 0.001837145 | N25: 0.017824598 | O25: 0.95 | P25: 0.001837145 | Q25: 0.0012412871 | R25: 0.68 | T25: ="("&$A25&", "&$B25&"]" -> (9, 10] | U25: 0.0012412871
A26: 10 | B26: 15 | C26: 5990 | D26: 7459035 | E26: 0.0060088257 | F26: 12.452479 | G26: =SUM($L$15:L25)-1000 -> 987612589 | H26: ="("&$A26&", "&$B26&"]" -> (10, 15] | I26: 1 | J26: 0.0060088257 | K26: 0.0061204115 | L26: 6120411 | M26: 0.006120411 | N26: 0.07621429 | O26: 0.95 | P26: 0.006120411 | Q26: 0.0046786976 | R26: 0.76 | T26: ="("&$A26&", "&$B26&"]" -> (10, 15] | U26: 0.0046786976
A27: 15 | B27: 20 | C27: 4007 | D27: 7050070 | E27: 0.0040195934 | F27: 17.594385 | G27: =SUM($L$15:L26)-1000 -> 993733000 | H27: ="("&$A27&", "&$B27&"]" -> (15, 20] | I27: 0 | J27: 0 | K27: 0 | L27: 0 | M27: 0 | N27: 0 | O27: 0 | P27: 0 | Q27: 0.0024825742 | R27: 0 | T27: ="("&$A27&", "&$B27&"]" -> (15, 20] | U27: 0.0024825742
A28: 20 | B28: 25 | C28: 2755 | D28: 6227820 | E28: 0.0027636585 | F28: 22.605517 | G28: =SUM($L$15:L27)-1000 -> 993733000 | H28: ="("&$A28&", "&$B28&"]" -> (20, 25] | I28: 0 | J28: 0 | K28: 0 | L28: 0 | M28: 0 | N28: 0 | O28: 0 | P28: 0 | Q28: 0.00095483625 | R28: 0 | T28: ="("&$A28&", "&$B28&"]" -> (20, 25] | U28: 0.00095483625
A29: 25 | B29: 30 | C29: 2166 | D29: 5974070 | E29: 0.0021728074 | F29: 27.581117 | G29: =SUM($L$15:L28)-1000 -> 993733000 | H29: ="("&$A29&", "&$B29&"]" -> (25, 30] | I29: 0 | J29: 0 | K29: 0 | L29: 0 | M29: 0 | N29: 0 | O29: 0 | P29: 0 | Q29: 0.0011458035 | R29: 0 | T29: ="("&$A29&", "&$B29&"]" -> (25, 30] | U29: 0.0011458035
A30: 30 | B30: 35 | C30: 1524 | D30: 4962115 | E30: 0.0015287897 | F30: 32.55981 | G30: =SUM($L$15:L29)-1000 -> 993733000 | H30: ="("&$A30&", "&$B30&"]" -> (30, 35] | I30: 0 | J30: 0 | K30: 0 | L30: 0 | M30: 0 | N30: 0 | O30: 0 | P30: 0 | Q30: 0.0013367707 | R30: 0 | T30: ="("&$A30&", "&$B30&"]" -> (30, 35] | U30: 0.0013367707
A31: 35 | B31: 40 | C31: 1404 | D31: 5290095 | E31: 0.0014084126 | F31: 37.678739 | G31: =SUM($L$15:L30)-1000 -> 993733000 | H31: ="("&$A31&", "&$B31&"]" -> (35, 40] | I31: 0 | J31: 0 | K31: 0 | L31: 0 | M31: 0 | N31: 0 | O31: 0 | P31: 0 | Q31: 0.00095483625 | R31: 0 | T31: ="("&$A31&", "&$B31&"]" -> (35, 40] | U31: 0.00095483625
A32: 40 | B32: 45 | C32: 1062 | D32: 4537870 | E32: 0.0010653377 | F32: 42.729473 | G32: =SUM($L$15:L31)-1000 -> 993733000 | H32: ="("&$A32&", "&$B32&"]" -> (40, 45] | I32: 0 | J32: 0 | K32: 0 | L32: 0 | M32: 0 | N32: 0 | O32: 0 | P32: 0 | Q32: 0 | R32: 0 | T32: ="("&$A32&", "&$B32&"]" -> (40, 45] | U32: 0
A33: 45 | B33: 50 | C33: 898 | D33: 4301205 | E33: 0.00090082228 | F33: 47.897606 | G33: =SUM($L$15:L32)-1000 -> 993733000 | H33: ="("&$A33&", "&$B33&"]" -> (45, 50] | I33: 0 | J33: 0 | K33: 0 | L33: 0 | M33: 0 | N33: 0 | O33: 0 | P33: 0 | Q33: 0.00057290175 | R33: 0 | T33: ="("&$A33&", "&$B33&"]" -> (45, 50] | U33: 0.00057290175
A34: 50 | B34: 60 | C34: 1594 | D34: 8835000 | E34: 0.0015990097 | F34: 55.4266 | G34: =SUM($L$15:L33)-1000 -> 993733000 | H34: ="("&$A34&", "&$B34&"]" -> (50, 60] | I34: 0 | J34: 0 | K34: 0 | L34: 0 | M34: 0 | N34: 0 | O34: 0 | P34: 0 | Q34: 9.5483625e-05 | R34: 0 | T34: ="("&$A34&", "&$B34&"]" -> (50, 60] | U34: 9.5483625e-05
A35: 60 | B35: 70 | C35: 1145 | D35: 7455825 | E35: 0.0011485986 | F35: 65.116376 | H35: ="("&$A35&", "&$B35&"]" -> (60, 70] | I35: 0 | J35: 0 | K35: 0 | L35: 0 | M35: 0 | N35: 0 | O35: 0 | P35: 0 | Q35: 0.00019096725 | R35: 0 | T35: ="("&$A35&", "&$B35&"]" -> (60, 70] | U35: 0.00019096725
A36: 70 | B36: 80 | C36: 990 | D36: 7468905 | E36: 0.00099311142 | F36: 75.443485 | H36: ="("&$A36&", "&$B36&"]" -> (70, 80] | I36: 0 | J36: 0 | K36: 0 | L36: 0 | M36: 0 | N36: 0 | O36: 0 | P36: 0 | Q36: 0.00019096725 | R36: 0 | T36: ="("&$A36&", "&$B36&"]" -> (70, 80] | U36: 0.00019096725
A37: 80 | B37: 90 | C37: 686 | D37: 5848215 | E37: 0.00068815599 | F37: 85.250948 | H37: ="("&$A37&", "&$B37&"]" -> (80, 90] | I37: 0 | J37: 0 | K37: 0 | L37: 0 | M37: 0 | N37: 0 | O37: 0 | P37: 0 | Q37: 0.00019096725 | R37: 0 | T37: ="("&$A37&", "&$B37&"]" -> (80, 90] | U37: 0.00019096725
A38: 90 | B38: 100 | C38: 591 | D38: 5632880 | E38: 0.00059285742 | F38: 95.310998 | H38: ="("&$A38&", "&$B38&"]" -> (90, 100] | I38: 0 | J38: 0 | K38: 0 | L38: 0 | M38: 0 | N38: 0 | O38: 0 | P38: 0 | Q38: 0 | R38: 0 | T38: ="("&$A38&", "&$B38&"]" -> (90, 100] | U38: 0
A39: 100 | B39: 120 | C39: 965 | D39: 10627980 | E39: 0.00096803285 | F39: 110.13451 | G39: =SUM(M46:M69) -> 0 | H39: ="("&$A39&", "&$B39&"]" -> (100, 120] | I39: 0 | J39: 0 | K39: 0 | L39: 0 | M39: 0 | N39: 0 | O39: 0 | P39: 0 | Q39: 0 | R39: 0 | T39: ="("&$A39&", "&$B39&"]" -> (100, 120] | U39: 0
A40: 120 | B40: 140 | C40: 687 | D40: 8922710 | E40: 0.00068915914 | F40: 129.87933 | G40: =1/G39 -> #DIV/0! | H40: ="("&$A40&", "&$B40&"]" -> (120, 140] | I40: 0 | J40: 0 | K40: 0 | L40: 0 | M40: 0 | N40: 0 | O40: 0 | P40: 0 | Q40: 0 | R40: 0 | T40: ="("&$A40&", "&$B40&"]" -> (120, 140] | U40: 0
A41: 140 | B41: 160 | C41: 579 | D41: 8719640 | E41: 0.00058081971 | F41: 150.59827 | H41: ="("&$A41&", "&$B41&"]" -> (140, 160] | I41: 0 | J41: 0 | K41: 0 | L41: 0 | M41: 0 | N41: 0 | O41: 0 | P41: 0 | Q41: 0 | R41: 0 | T41: ="("&$A41&", "&$B41&"]" -> (140, 160] | U41: 0
A42: 160 | B42: 180 | C42: 434 | D42: 7409365 | E42: 0.000435364 | F42: 170.7227 | H42: ="("&$A42&", "&$B42&"]" -> (160, 180] | I42: 0 | J42: 0 | K42: 0 | L42: 0 | M42: 0 | N42: 0 | O42: 0 | P42: 0 | Q42: 0 | R42: 0 | T42: ="("&$A42&", "&$B42&"]" -> (160, 180] | U42: 0
A43: 180 | B43: 200 | C43: 384 | D43: 7315430 | E43: 0.00038520685 | F43: 190.50599 | H43: ="("&$A43&", "&$B43&"]" -> (180, 200] | I43: 0 | J43: 0 | K43: 0 | L43: 0 | M43: 0 | N43: 0 | O43: 0 | P43: 0 | Q43: 0 | R43: 0 | T43: ="("&$A43&", "&$B43&"]" -> (180, 200] | U43: 0
A44: 200 | B44: 250 | C44: 689 | D44: 15443900 | E44: 0.00069116542 | F44: 224.14949 | H44: ="("&$A44&", "&$B44&"]" -> (200, 250] | I44: 0 | J44: 0 | K44: 0 | L44: 0 | M44: 0 | N44: 0 | O44: 0 | P44: 0 | Q44: 0 | R44: 0 | T44: ="("&$A44&", "&$B44&"]" -> (200, 250] | U44: 0
A45: 250 | B45: 300 | C45: 438 | D45: 12037700 | E45: 0.00043937657 | F45: 274.83333 | H45: ="("&$A45&", "&$B45&"]" -> (250, 300] | I45: 0 | J45: 0 | K45: 0 | L45: 0 | M45: 0 | N45: 0 | O45: 0 | P45: 0 | Q45: 0 | R45: 0 | T45: ="("&$A45&", "&$B45&"]" -> (250, 300] | U45: 0
...

Sheet 工作表1
B2: +-平均值(列) | AQ2: 黃金底板
I3: >0 變大 斷爛
I4: <0 變大 平均 | AR4: Rate | AS4: 0.3
AK5: 200 | AL5: 200 | AM5: 200 | AN5: 200 | AO5: 200 | AP5: 200
B6: R1 | C6: R2 | D6: R3 | E6: R4 | F6: R5 | G6: R6 | I6: R1 | J6: R2 | K6: R3 | L6: R4 | M6: R5 | N6: R6 | P6: R1 | Q6: R2 | R6: R3 | S6: R4 | T6: R5 | U6: R6 | W6: R1 | X6: R2 | Y6: R3 | Z6: R4 | AA6: R5 | AB6: R6 | AD6: R1 | AE6: R2 | AF6: R3 | AG6: R4 | AH6: R5 | AI6: R6 | AK6: R1 | AL6: R2 | AM6: R3 | AN6: R4 | AO6: R5 | AP6: R6 | AR6: R1 | AS6: R2 | AT6: R3 | AU6: R4 | AV6: R5 | AW6: R6
A7: M1 | B7: 2 | C7: 31 | D7: 6 | E7: 38 | F7: 38 | G7: 1 | I7: -0.5 | J7: -0.5 | K7: -0.5 | L7: -0.5 | M7: -0.5 | N7: -0.5 | P7: {=_xlfn.LET(_xlpm.x, B7:G7, _xlpm.val, INT(_xlpm.x+(_xlpm.x-AVERAGE(_xlpm.x))*I7:N7), IF(_xlpm.val<0, 0, _xlpm.val))} -> 10 | Q7: 25 | R7: 12 | S7: 28 | T7: 28 | U7: 10 | W7: 1 | X7: 1 | Y7: 1 | Z7: 1 | AA7: 1 | AB7: 1 | AD7: {=P7:U14*W7:AB14} -> 10 | AE7: 25 | AF7: 12 | AG7: 28 | AH7: 28 | AI7: 10 | AK7: {=_xlfn.LET(_xlpm.x, AD7:AD14, INT(_xlpm.x/SUM(_xlpm.x)*200))} -> 10 | AL7: {=_xlfn.LET(_xlpm.x, AE7:AE14, INT(_xlpm.x/SUM(_xlpm.x)*200))} -> 26 | AM7: {=_xlfn.LET(_xlpm.x, AF7:AF14, INT(_xlpm.x/SUM(_xlpm.x)*200))} -> 12 | AN7: {=_xlfn.LET(_xlpm.x, AG7:AG14, INT(_xlpm.x/SUM(_xlpm.x)*200))} -> 29 | AO7: {=_xlfn.LET(_xlpm.x, AH7:AH14, INT(_xlpm.x/SUM(_xlpm.x)*200))} -> 29 | AP7: {=_xlfn.LET(_xlpm.x, AI7:AI14, INT(_xlpm.x/SUM(_xlpm.x)*200))} -> 10 | AR7: {=P7:Q14} -> 10 | AS7: 25 | AT7: {=R7:S14-_xlfn.ANCHORARRAY(AT15)} -> 9 | AU7: 20 | AV7: {=T7:U14} -> 28 | AW7: 10 | AY7: {=AR7:AW14+AR15:AW22} -> 10 | AZ7: 25 | BA7: 12 | BB7: 28 | BC7: 28 | BD7: 10 | BG7: 16 | BH7: {=BG7:BG14-_xlfn.ANCHORARRAY(BH15)} -> 12
A8: M2 | B8: 34 | C8: 4 | D8: 35 | E8: 8 | F8: 3 | G8: 33 | I8: -0.5 | J8: -0.5 | K8: -0.5 | L8: -0.5 | M8: -0.5 | N8: -0.5 | P8: {=_xlfn.LET(_xlpm.x, B8:G8, _xlpm.val, INT(_xlpm.x+(_xlpm.x-AVERAGE(_xlpm.x))*I8:N8), IF(_xlpm.val<0, 0, _xlpm.val))} -> 26 | Q8: 11 | R8: 27 | S8: 13 | T8: 11 | U8: 26 | W8: 1 | X8: 1 | Y8: 1 | Z8: 1 | AA8: 1 | AB8: 1 | AD8: 26 | AE8: 11 | AF8: 27 | AG8: 13 | AH8: 11 | AI8: 26 | AK8: 27 | AL8: 11 | AM8: 27 | AN8: 13 | AO8: 11 | AP8: 26 | AR8: 26 | AS8: 11 | AT8: 19 | AU8: 10 | AV8: 11 | AW8: 26 | AY8: 26 | AZ8: 11 | BA8: 27 | BB8: 13 | BC8: 11 | BD8: 26 | BG8: 16 | BH8: 12
A9: M3 | B9: 10 | C9: 46 | D9: 6 | E9: 44 | F9: 45 | G9: 4 | I9: -0.5 | J9: -0.5 | K9: -0.5 | L9: -0.5 | M9: -0.5 | N9: -0.5 | P9: {=_xlfn.LET(_xlpm.x, B9:G9, _xlpm.val, INT(_xlpm.x+(_xlpm.x-AVERAGE(_xlpm.x))*I9:N9), IF(_xlpm.val<0, 0, _xlpm.val))} -> 17 | Q9: 35 | R9: 15 | S9: 34 | T9: 35 | U9: 14 | W9: 1 | X9: 1 | Y9: 1 | Z9: 1 | AA9: 1 | AB9: 1 | AD9: 17 | AE9: 35 | AF9: 15 | AG9: 34 | AH9: 35 | AI9: 14 | AK9: 17 | AL9: 36 | AM9: 15 | AN9: 35 | AO9: 36 | AP9: 14 | AR9: 17 | AS9: 35 | AT9: 11 | AU9: 24 | AV9: 35 | AW9: 14 | AY9: 17 | AZ9: 35 | BA9: 15 | BB9: 34 | BC9: 35 | BD9: 14 | BG9: 16 | BH9: 12
A10: M4 | B10: 48 | C10: 13 | D10: 44 | E10: 7 | F10: 3 | G10: 45 | I10: -0.5 | J10: -0.5 | K10: -0.5 | L10: -0.5 | M10: -0.5 | N10: -0.5 | P10: {=_xlfn.LET(_xlpm.x, B10:G10, _xlpm.val, INT(_xlpm.x+(_xlpm.x-AVERAGE(_xlpm.x))*I10:N10), IF(_xlpm.val<0, 0, _xlpm.val))} -> 37 | Q10: 19 | R10: 35 | S10: 16 | T10: 14 | U10: 35 | W10: 1 | X10: 1 | Y10: 1 | Z10: 1 | AA10: 1 | AB10: 1 | AD10: 37 | AE10: 19 | AF10: 35 | AG10: 16 | AH10: 14 | AI10: 35 | AK10: 38 | AL10: 19 | AM10: 36 | AN10: 16 | AO10: 14 | AP10: 36 | AR10: 37 | AS10: 19 | AT10: 25 | AU10: 12 | AV10: 14 | AW10: 35 | AY10: 37 | AZ10: 19 | BA10: 35 | BB10: 16 | BC10: 14 | BD10: 35 | BG10: 30 | BH10: 22
A11: A | B11: 23 | C11: 50 | D11: 6 | E11: 48 | F11: 54 | G11: 9 | I11: -0.5 | J11: -0.5 | K11: -0.5 | L11: -0.5 | M11: -0.5 | N11: -0.5 | P11: {=_xlfn.LET(_xlpm.x, B11:G11, _xlpm.val, INT(_xlpm.x+(_xlpm.x-AVERAGE(_xlpm.x))*I11:N11), IF(_xlpm.val<0, 0, _xlpm.val))} -> 27 | Q11: 40 | R11: 18 | S11: 39 | T11: 42 | U11: 20 | W11: 1 | X11: 1 | Y11: 1 | Z11: 1 | AA11: 1 | AB11: 1 | AD11: 27 | AE11: 40 | AF11: 18 | AG11: 39 | AH11: 42 | AI11: 20 | AK11: 28 | AL11: 41 | AM11: 18 | AN11: 40 | AO11: 43 | AP11: 20 | AR11: 27 | AS11: 40 | AT11: 13 | AU11: 28 | AV11: 42 | AW11: 20 | AY11: 27 | AZ11: 40 | BA11: 18 | BB11: 39 | BC11: 42 | BD11: 20 | BG11: 24 | BH11: 18
A12: K | B12: 16 | C12: 40 | D12: 7 | E12: 39 | F12: 45 | G12: 6 | I12: -0.5 | J12: -0.5 | K12: -0.5 | L12: -0.5 | M12: -0.5 | N12: -0.5 | P12: {=_xlfn.LET(_xlpm.x, B12:G12, _xlpm.val, INT(_xlpm.x+(_xlpm.x-AVERAGE(_xlpm.x))*I12:N12), IF(_xlpm.val<0, 0, _xlpm.val))} -> 20 | Q12: 32 | R12: 16 | S12: 32 | T12: 35 | U12: 15 | W12: 1 | X12: 1 | Y12: 1 | Z12: 1 | AA12: 1 | AB12: 1 | AD12: 20 | AE12: 32 | AF12: 16 | AG12: 32 | AH12: 35 | AI12: 15 | AK12: 20 | AL12: 33 | AM12: 16 | AN12: 33 | AO12: 36 | AP12: 15 | AR12: 20 | AS12: 32 | AT12: 12 | AU12: 23 | AV12: 35 | AW12: 15 | AY12: 20 | AZ12: 32 | BA12: 16 | BB12: 32 | BC12: 35 | BD12: 15 | BG12: 30 | BH12: 22
A13: Q | B13: 32 | C13: 9 | D13: 45 | E13: 6 | F13: 3 | G13: 47 | I13: -0.5 | J13: -0.5 | K13: -0.5 | L13: -0.5 | M13: -0.5 | N13: -0.5 | P13: {=_xlfn.LET(_xlpm.x, B13:G13, _xlpm.val, INT(_xlpm.x+(_xlpm.x-AVERAGE(_xlpm.x))*I13:N13), IF(_xlpm.val<0, 0, _xlpm.val))} -> 27 | Q13: 16 | R13: 34 | S13: 14 | T13: 13 | U13: 35 | W13: 1 | X13: 1 | Y13: 1 | Z13: 1 | AA13: 1 | AB13: 1 | AD13: 27 | AE13: 16 | AF13: 34 | AG13: 14 | AH13: 13 | AI13: 35 | AK13: 28 | AL13: 16 | AM13: 35 | AN13: 14 | AO13: 13 | AP13: 36 | AR13: 27 | AS13: 16 | AT13: 24 | AU13: 10 | AV13: 13 | AW13: 35 | AY13: 27 | AZ13: 16 | BA13: 34 | BB13: 14 | BC13: 13 | BD13: 35 | BG13: 30 | BH13: 22
A14: J | B14: 32 | C14: 4 | D14: 48 | E14: 7 | F14: 6 | G14: 52 | I14: -0.5 | J14: -0.5 | K14: -0.5 | L14: -0.5 | M14: -0.5 | N14: -0.5 | P14: {=_xlfn.LET(_xlpm.x, B14:G14, _xlpm.val, INT(_xlpm.x+(_xlpm.x-AVERAGE(_xlpm.x))*I14:N14), IF(_xlpm.val<0, 0, _xlpm.val))} -> 28 | Q14: 14 | R14: 36 | S14: 15 | T14: 15 | U14: 38 | W14: 1 | X14: 1 | Y14: 1 | Z14: 1 | AA14: 1 | AB14: 1 | AD14: 28 | AE14: 14 | AF14: 36 | AG14: 15 | AH14: 15 | AI14: 38 | AK14: 29 | AL14: 14 | AM14: 37 | AN14: 15 | AO14: 15 | AP14: 39 | AR14: 28 | AS14: 14 | AT14: 26 | AU14: 11 | AV14: 15 | AW14: 38 | AY14: 28 | AZ14: 14 | BA14: 36 | BB14: 15 | BC14: 15 | BD14: 38 | BG14: 24 | BH14: 18
B15: =SUM(B7:B14) -> 197 | C15: =SUM(C7:C14) -> 197 | D15: =SUM(D7:D14) -> 197 | E15: =SUM(E7:E14) -> 197 | F15: =SUM(F7:F14) -> 197 | G15: =SUM(G7:G14) -> 197 | P15: =SUM(P7:P14) -> 192 | Q15: =SUM(Q7:Q14) -> 192 | R15: =SUM(R7:R14) -> 193 | S15: =SUM(S7:S14) -> 191 | T15: =SUM(T7:T14) -> 193 | U15: =SUM(U7:U14) -> 193 | AD15: =SUM(AD7:AD14) -> 192 | AE15: =SUM(AE7:AE14) -> 192 | AF15: =SUM(AF7:AF14) -> 193 | AG15: =SUM(AG7:AG14) -> 191 | AH15: =SUM(AH7:AH14) -> 193 | AI15: =SUM(AI7:AI14) -> 193 | AK15: =SUM(AK7:AK14) -> 197 | AL15: =SUM(AL7:AL14) -> 196 | AM15: =SUM(AM7:AM14) -> 196 | AN15: =SUM(AN7:AN14) -> 195 | AO15: =SUM(AO7:AO14) -> 197 | AP15: =SUM(AP7:AP14) -> 196 | AR15: 0 | AS15: 0 | AT15: {=INT(AS4*R7:S14)} -> 3 | AU15: 8 | AV15: 0 | AW15: 0 | BH15: {=INT(BG7:BG14*0.27)} -> 4
AR16: 0 | AS16: 0 | AT16: 8 | AU16: 3 | AV16: 0 | AW16: 0 | BH16: 4
I17: R1 | J17: R2 | K17: R3 | L17: R4 | M17: R5 | N17: R6 | AR17: 0 | AS17: 0 | AT17: 4 | AU17: 10 | AV17: 0 | AW17: 0 | BH17: 4
B18: {=BG_Symbol!C7:G14+BG_Symbol!C15:G22} -> 4 | C18: 15 | D18: 5 | E18: 25 | F18: 23 | I18: {=_xlfn.LET(_xlpm.x, I7:N14, _xlfn.IFS(_xlpm.x<0, "平均", _xlpm.x<1, "斷", TRUE, "斷爛"))} -> 平均 | J18: 平均 | K18: 平均 | L18: 平均 | M18: 平均 | N18: 平均 | AR18: 0 | AS18: 0 | AT18: 10 | AU18: 4 | AV18: 0 | AW18: 0 | BH18: 8
B19: 4 | C19: 16 | D19: 5 | E19: 25 | F19: 22 | I19: 平均 | J19: 平均 | K19: 平均 | L19: 平均 | M19: 平均 | N19: 平均 | AR19: 0 | AS19: 0 | AT19: 5 | AU19: 11 | AV19: 0 | AW19: 0 | BH19: 6
B20: 43 | C20: 25 | D20: 41 | E20: 18 | F20: 22 | I20: 平均 | J20: 平均 | K20: 平均 | L20: 平均 | M20: 平均 | N20: 平均 | AR20: 0 | AS20: 0 | AT20: 4 | AU20: 9 | AV20: 0 | AW20: 0 | BH20: 8
B21: 43 | C21: 29 | D21: 44 | E21: 17 | F21: 22 | I21: 平均 | J21: 平均 | K21: 平均 | L21: 平均 | M21: 平均 | N21: 平均 | AR21: 0 | AS21: 0 | AT21: 10 | AU21: 4 | AV21: 0 | AW21: 0 | BH21: 8
B22: 47 | C22: 29 | D22: 44 | E22: 17 | F22: 22 | I22: 平均 | J22: 平均 | K22: 平均 | L22: 平均 | M22: 平均 | N22: 平均 | AR22: 0 | AS22: 0 | AT22: 10 | AU22: 4 | AV22: 0 | AW22: 0 | BH22: 6
B23: 47 | C23: 29 | D23: 44 | E23: 17 | F23: 22 | I23: 平均 | J23: 平均 | K23: 平均 | L23: 平均 | M23: 平均 | N23: 平均
B24: 4 | C24: 19 | D24: 8 | E24: 23 | F24: 22 | I24: 平均 | J24: 平均 | K24: 平均 | L24: 平均 | M24: 平均 | N24: 平均
B25: 4 | C25: 16 | D25: 4 | E25: 24 | F25: 22 | I25: 平均 | J25: 平均 | K25: 平均 | L25: 平均 | M25: 平均 | N25: 平均
B29: N-X
P30: N | Q30: 50
P31: F | Q31: 1.2 | AR31: Rate | AS31: 0.3
AK32: 200 | AL32: 200 | AM32: 200 | AN32: 200 | AO32: 200 | AP32: 200
B33: R1 | C33: R2 | D33: R3 | E33: R4 | F33: R5 | G33: R6 | P33: R1 | Q33: R2 | R33: R3 | S33: R4 | T33: R5 | U33: R6 | W33: R1 | X33: R2 | Y33: R3 | Z33: R4 | AA33: R5 | AB33: R6 | AD33: R1 | AE33: R2 | AF33: R3 | AG33: R4 | AH33: R5 | AI33: R6 | AK33: R1 | AL33: R2 | AM33: R3 | AN33: R4 | AO33: R5 | AP33: R6 | AR33: R1 | AS33: R2 | AT33: R3 | AU33: R4 | AV33: R5 | AW33: R6
A34: M1 | B34: 2 | C34: 31 | D34: 6 | E34: 38 | F34: 38 | G34: 1 | P34: {=_xlfn.LET(_xlpm.x, INT($Q$30-B34:G41*Q31), IF(_xlpm.x<0, 0, _xlpm.x))} -> 47 | Q34: 12 | R34: 42 | S34: 4 | T34: 4 | U34: 48 | W34: 1 | X34: 1 | Y34: 1 | Z34: 1 | AA34: 1 | AB34: 1 | AD34: {=P34:U41*W34:AB41} -> 47 | AE34: 12 | AF34: 42 | AG34: 4 | AH34: 4 | AI34: 48 | AK34: {=_xlfn.LET(_xlpm.x, AD34:AD41, INT(_xlpm.x/SUM(_xlpm.x)*200))} -> 55 | AL34: {=_xlfn.LET(_xlpm.x, AE34:AE41, INT(_xlpm.x/SUM(_xlpm.x)*200))} -> 13 | AM34: {=_xlfn.LET(_xlpm.x, AF34:AF41, INT(_xlpm.x/SUM(_xlpm.x)*200))} -> 48 | AN34: {=_xlfn.LET(_xlpm.x, AG34:AG41, INT(_xlpm.x/SUM(_xlpm.x)*200))} -> 4 | AO34: {=_xlfn.LET(_xlpm.x, AH34:AH41, INT(_xlpm.x/SUM(_xlpm.x)*200))} -> 4 | AP34: {=_xlfn.LET(_xlpm.x, AI34:AI41, INT(_xlpm.x/SUM(_xlpm.x)*200))} -> 52 | AR34: {=AK34:AL41} -> 55 | AS34: 13 | AT34: {=AM34:AN41-_xlfn.ANCHORARRAY(AT42)} -> 36 | AU34: 3 | AV34: {=AO34:AP41} -> 4 | AW34: 52 | AY34: {=AR34:AW41+AR42:AW49} -> 55 | AZ34: 13 | BA34: 48 | BB34: 4 | BC34: 4 | BD34: 52
A35: M2 | B35: 34 | C35: 4 | D35: 35 | E35: 8 | F35: 3 | G35: 33 | P35: 9 | Q35: 45 | R35: 8 | S35: 40 | T35: 46 | U35: 10 | W35: 1 | X35: 1 | Y35: 1 | Z35: 1 | AA35: 1 | AB35: 1 | AD35: 9 | AE35: 45 | AF35: 8 | AG35: 40 | AH35: 46 | AI35: 10 | AK35: 10 | AL35: 50 | AM35: 9 | AN35: 46 | AO35: 50 | AP35: 10 | AR35: 10 | AS35: 50 | AT35: 7 | AU35: 34 | AV35: 50 | AW35: 10 | AY35: 10 | AZ35: 50 | BA35: 9 | BB35: 46 | BC35: 50 | BD35: 10
A36: M3 | B36: 10 | C36: 46 | D36: 6 | E36: 44 | F36: 45 | G36: 4 | P36: 38 | Q36: 0 | R36: 42 | S36: 0 | T36: 0 | U36: 45 | W36: 1 | X36: 1 | Y36: 1 | Z36: 1 | AA36: 1 | AB36: 1 | AD36: 38 | AE36: 0 | AF36: 42 | AG36: 0 | AH36: 0 | AI36: 45 | AK36: 45 | AL36: 0 | AM36: 48 | AN36: 0 | AO36: 0 | AP36: 48 | AR36: 45 | AS36: 0 | AT36: 36 | AU36: 0 | AV36: 0 | AW36: 48 | AY36: 45 | AZ36: 0 | BA36: 48 | BB36: 0 | BC36: 0 | BD36: 48
A37: M4 | B37: 48 | C37: 13 | D37: 44 | E37: 7 | F37: 3 | G37: 45 | P37: 0 | Q37: 34 | R37: 0 | S37: 41 | T37: 46 | U37: 0 | W37: 1 | X37: 1 | Y37: 1 | Z37: 1 | AA37: 1 | AB37: 1 | AD37: 0 | AE37: 34 | AF37: 0 | AG37: 41 | AH37: 46 | AI37: 0 | AK37: 0 | AL37: 38 | AM37: 0 | AN37: 47 | AO37: 50 | AP37: 0 | AR37: 0 | AS37: 38 | AT37: 0 | AU37: 35 | AV37: 50 | AW37: 0 | AY37: 0 | AZ37: 38 | BA37: 0 | BB37: 47 | BC37: 50 | BD37: 0
A38: A | B38: 23 | C38: 50 | D38: 6 | E38: 48 | F38: 54 | G38: 9 | P38: 22 | Q38: 0 | R38: 42 | S38: 0 | T38: 0 | U38: 39 | W38: 1 | X38: 1 | Y38: 1 | Z38: 1 | AA38: 1 | AB38: 1 | AD38: 22 | AE38: 0 | AF38: 42 | AG38: 0 | AH38: 0 | AI38: 39 | AK38: 26 | AL38: 0 | AM38: 48 | AN38: 0 | AO38: 0 | AP38: 42 | AR38: 26 | AS38: 0 | AT38: 36 | AU38: 0 | AV38: 0 | AW38: 42 | AY38: 26 | AZ38: 0 | BA38: 48 | BB38: 0 | BC38: 0 | BD38: 42
A39: K | B39: 16 | C39: 40 | D39: 7 | E39: 39 | F39: 45 | G39: 6 | P39: 30 | Q39: 2 | R39: 41 | S39: 3 | T39: 0 | U39: 42 | W39: 1 | X39: 1 | Y39: 1 | Z39: 1 | AA39: 1 | AB39: 1 | AD39: 30 | AE39: 2 | AF39: 41 | AG39: 3 | AH39: 0 | AI39: 42 | AK39: 35 | AL39: 2 | AM39: 46 | AN39: 3 | AO39: 0 | AP39: 45 | AR39: 35 | AS39: 2 | AT39: 34 | AU39: 3 | AV39: 0 | AW39: 45 | AY39: 35 | AZ39: 2 | BA39: 46 | BB39: 3 | BC39: 0 | BD39: 45
A40: Q | B40: 32 | C40: 9 | D40: 45 | E40: 6 | F40: 3 | G40: 47 | P40: 11 | Q40: 39 | R40: 0 | S40: 42 | T40: 46 | U40: 0 | W40: 1 | X40: 1 | Y40: 1 | Z40: 1 | AA40: 1 | AB40: 1 | AD40: 11 | AE40: 39 | AF40: 0 | AG40: 42 | AH40: 46 | AI40: 0 | AK40: 13 | AL40: 44 | AM40: 0 | AN40: 49 | AO40: 50 | AP40: 0 | AR40: 13 | AS40: 44 | AT40: 0 | AU40: 37 | AV40: 50 | AW40: 0 | AY40: 13 | AZ40: 44 | BA40: 0 | BB40: 49 | BC40: 50 | BD40: 0
A41: J | B41: 32 | C41: 4 | D41: 48 | E41: 7 | F41: 6 | G41: 52 | P41: 11 | Q41: 45 | R41: 0 | S41: 41 | T41: 42 | U41: 0 | W41: 1 | X41: 1 | Y41: 1 | Z41: 1 | AA41: 1 | AB41: 1 | AD41: 11 | AE41: 45 | AF41: 0 | AG41: 41 | AH41: 42 | AI41: 0 | AK41: 13 | AL41: 50 | AM41: 0 | AN41: 47 | AO41: 45 | AP41: 0 | AR41: 13 | AS41: 50 | AT41: 0 | AU41: 35 | AV41: 45 | AW41: 0 | AY41: 13 | AZ41: 50 | BA41: 0 | BB41: 47 | BC41: 45 | BD41: 0
B42: =SUM(B34:B41) -> 197 | C42: =SUM(C34:C41) -> 197 | D42: =SUM(D34:D41) -> 197 | E42: =SUM(E34:E41) -> 197 | F42: =SUM(F34:F41) -> 197 | G42: =SUM(G34:G41) -> 197 | P42: =SUM(P34:P41) -> 168 | Q42: =SUM(Q34:Q41) -> 177 | R42: =SUM(R34:R41) -> 175 | S42: =SUM(S34:S41) -> 171 | T42: =SUM(T34:T41) -> 184 | U42: =SUM(U34:U41) -> 184 | AD42: =SUM(AD34:AD41) -> 168 | AE42: =SUM(AE34:AE41) -> 177 | AF42: =SUM(AF34:AF41) -> 175 | AG42: =SUM(AG34:AG41) -> 171 | AH42: =SUM(AH34:AH41) -> 184 | AI42: =SUM(AI34:AI41) -> 184 | AK42: =SUM(AK34:AK41) -> 197 | AL42: =SUM(AL34:AL41) -> 197 | AM42: =SUM(AM34:AM41) -> 199 | AN42: =SUM(AN34:AN41) -> 196 | AO42: =SUM(AO34:AO41) -> 199 | AP42: =SUM(AP34:AP41) -> 197 | AR42: 0 | AS42: 0 | AT42: {=INT(AS31*R34:S41)} -> 12 | AU42: 1 | AV42: 0 | AW42: 0
AR43: 0 | AS43: 0 | AT43: 2 | AU43: 12 | AV43: 0 | AW43: 0
AR44: 0 | AS44: 0 | AT44: 12 | AU44: 0 | AV44: 0 | AW44: 0
...

Sheet OP Jackpot
B3: NB-Newbie-A
B4: BGC1Screen | E4: =SUM(D4:D5)/C4 -> #DIV/0!
B5: FGC1Screen
B7: NB-Newbie-B
B8: BGC1Screen | E8: =SUM(D8:D9)/C8 -> #DIV/0!
B9: FGC1Screen
B11: NB-Oldhand-A
B12: BGC1Screen | E12: =SUM(D12:D13)/C12 -> #DIV/0!
B13: FGC1Screen
B15: NB-Oldhand-B
B16: BGC1Screen | E16: =SUM(D16:D17)/C16 -> #DIV/0!
B17: FGC1Screen
B19: BF-A
B20: BGC1Screen | E20: =SUM(D20:D21)/C20 -> #DIV/0!
B21: FGC1Screen
B23: BF-B
B24: BGC1Screen | E24: =SUM(D24:D25)/C24 -> #DIV/0!
B25: FGC1Screen
B28: Threshold | C28: 10000000000
B30: NB-Newbie-A | C30: =ROUND(E4*$C$28, 0) -> #DIV/0!
B31: NB-Newbie-B | C31: =ROUND(E8*$C$28, 0) -> #DIV/0!
B32: NB-Oldhand-A | C32: =ROUND(E12*$C$28, 0) -> #DIV/0!
B33: NB-Oldhand-B | C33: =ROUND(E16*$C$28, 0) -> #DIV/0!
B34: BF-A | C34: =ROUND(E20*$C$28, 0) -> #DIV/0!
B35: BF-B | C35: =ROUND(E24*$C$28, 0) -> #DIV/0!

Sheet BG_Symbol
J2: Symbol | Q2: Symbol ID | W2: Symbol Weight | AC2: Eliminate Wheel Weight A | AJ2: Eliminate Wheel Weight B
A3: Symbol | B3: Description | C3: R1 | D3: R2 | E3: R3 | F3: R4 | G3: R5 | H3: ID | K3: R1 | L3: R2 | M3: R3 | N3: R4 | O3: R5 | Q3: R1 | R3: R2 | S3: R3 | T3: R4 | U3: R5 | W3: R1 | X3: R2 | Y3: R3 | Z3: R4 | AA3: R5
A4: {=Overview!A38:B57} -> WW | B4: Wild | C4: =COUNTIF(K:K, $A4) -> 0 | D4: =COUNTIF(L:L, $A4) -> 0 | E4: =COUNTIF(M:M, $A4) -> 0 | F4: =COUNTIF(N:N, $A4) -> 0 | G4: =COUNTIF(O:O, $A4) -> 0 | H4: {=Overview!F38:F57} -> 0 | J4: {=_xlfn.SEQUENCE(MAX(COUNTA(K:K), COUNTA(L:L), COUNTA(M:M), COUNTA(N:N), COUNTA(O:O))-1,,0)} -> 0 | K4: M5 | L4: M5 | M4: M5 | N4: GK | O4: M4 | Q4: {=_xlfn.LET(_xlpm.x, K4:O304, IF(_xlpm.x="", "", _xlfn.XLOOKUP(_xlpm.x, $A$4:$A$23,_xlfn.ANCHORARRAY( H4))))} -> 6 | R4: 6 | S4: 6 | T4: 17 | U4: 5 | W4: 1 | X4: 1 | Y4: 1 | Z4: 1 | AA4: 1 | AC4: 1 Combo | AJ4: 1 Combo
A5: C1 | B5: Scatter | C5: =COUNTIF(K:K, $A5) -> 0 | D5: =COUNTIF(L:L, $A5) -> 6 | E5: =COUNTIF(M:M, $A5) -> 0 | F5: =COUNTIF(N:N, $A5) -> 9 | G5: =COUNTIF(O:O, $A5) -> 0 | H5: 1 | J5: 1 | K5: K | L5: M1 | M5: K | N5: Q | O5: M2 | Q5: 8 | R5: 2 | S5: 8 | T5: 9 | U5: 3 | W5: 1 | X5: 1 | Y5: 1 | Z5: 1 | AA5: 1 | AC5: Symbol | AD5: R1 | AE5: R2 | AF5: R3 | AG5: R4 | AH5: R5 | AJ5: Symbol | AK5: R1 | AL5: R2 | AM5: R3 | AN5: R4 | AO5: R5
A6: M1 | B6: M1 | C6: =COUNTIF(K:K, $A6) -> 4 | D6: =COUNTIF(L:L, $A6) -> 11 | E6: =COUNTIF(M:M, $A6) -> 5 | F6: =COUNTIF(N:N, $A6) -> 21 | G6: =COUNTIF(O:O, $A6) -> 23 | H6: 2 | J6: 2 | K6: M4 | L6: G4 | M6: GK | N6: M3 | O6: M2 | Q6: 5 | R6: 14 | S6: 17 | T6: 4 | U6: 3 | W6: 1 | X6: 1 | Y6: 1 | Z6: 1 | AA6: 1 | AC6: {=$A$4:$A$23} -> WW | AD6: 0 | AE6: 0 | AF6: 0 | AG6: 0 | AH6: 0 | AJ6: {=$A$4:$A$23} -> WW | AK6: 0 | AL6: 0 | AM6: 0 | AN6: 0 | AO6: 0
A7: M2 | B7: M2 | C7: =COUNTIF(K:K, $A7) -> 4 | D7: =COUNTIF(L:L, $A7) -> 11 | E7: =COUNTIF(M:M, $A7) -> 5 | F7: =COUNTIF(N:N, $A7) -> 21 | G7: =COUNTIF(O:O, $A7) -> 23 | H7: 3 | J7: 3 | K7: A | L7: A | M7: M4 | N7: M3 | O7: J | Q7: 7 | R7: 7 | S7: 5 | T7: 4 | U7: 10 | W7: 1 | X7: 1 | Y7: 1 | Z7: 1 | AA7: 1 | AC7: C1 | AD7: 0 | AE7: 6 | AF7: 0 | AG7: 9 | AH7: 0 | AJ7: C1 | AK7: 0 | AL7: 6 | AM7: 0 | AN7: 9 | AO7: 0
A8: M3 | B8: M3 | C8: =COUNTIF(K:K, $A8) -> 4 | D8: =COUNTIF(L:L, $A8) -> 11 | E8: =COUNTIF(M:M, $A8) -> 5 | F8: =COUNTIF(N:N, $A8) -> 21 | G8: =COUNTIF(O:O, $A8) -> 22 | H8: 4 | J8: 4 | K8: K | L8: M5 | M8: M2 | N8: GK | O8: K | Q8: 8 | R8: 6 | S8: 3 | T8: 17 | U8: 8 | W8: 1 | X8: 1 | Y8: 1 | Z8: 1 | AA8: 1 | AC8: M1 | AD8: 4 | AE8: 11 | AF8: 5 | AG8: 21 | AH8: 23 | AJ8: M1 | AK8: 4 | AL8: 11 | AM8: 5 | AN8: 21 | AO8: 23
A9: M4 | B9: M4 | C9: =COUNTIF(K:K, $A9) -> 43 | D9: =COUNTIF(L:L, $A9) -> 20 | E9: =COUNTIF(M:M, $A9) -> 41 | F9: =COUNTIF(N:N, $A9) -> 14 | G9: =COUNTIF(O:O, $A9) -> 22 | H9: 5 | J9: 5 | K9: A | L9: G2 | M9: A | N9: GQ | O9: J | Q9: 7 | R9: 12 | S9: 7 | T9: 18 | U9: 10 | W9: 1 | X9: 1 | Y9: 1 | Z9: 1 | AA9: 1 | AC9: M2 | AD9: 4 | AE9: 11 | AF9: 5 | AG9: 21 | AH9: 23 | AJ9: M2 | AK9: 4 | AL9: 11 | AM9: 5 | AN9: 21 | AO9: 23
A10: M5 | B10: M5 | C10: =COUNTIF(K:K, $A10) -> 43 | D10: =COUNTIF(L:L, $A10) -> 21 | E10: =COUNTIF(M:M, $A10) -> 41 | F10: =COUNTIF(N:N, $A10) -> 14 | G10: =COUNTIF(O:O, $A10) -> 22 | H10: 6 | J10: 6 | K10: K | L10: A | M10: G5 | N10: M5 | O10: A | Q10: 8 | R10: 7 | S10: 15 | T10: 6 | U10: 7 | W10: 1 | X10: 1 | Y10: 1 | Z10: 1 | AA10: 1 | AC10: M3 | AD10: 4 | AE10: 11 | AF10: 5 | AG10: 21 | AH10: 22 | AJ10: M3 | AK10: 4 | AL10: 11 | AM10: 5 | AN10: 21 | AO10: 22
A11: A | B11: A | C11: =COUNTIF(K:K, $A11) -> 47 | D11: =COUNTIF(L:L, $A11) -> 21 | E11: =COUNTIF(M:M, $A11) -> 41 | F11: =COUNTIF(N:N, $A11) -> 14 | G11: =COUNTIF(O:O, $A11) -> 22 | H11: 7 | J11: 7 | K11: K | L11: A | M11: Q | N11: M1 | O11: A | Q11: 8 | R11: 7 | S11: 9 | T11: 2 | U11: 7 | W11: 1 | X11: 1 | Y11: 1 | Z11: 1 | AA11: 1 | AC11: M4 | AD11: 43 | AE11: 20 | AF11: 41 | AG11: 14 | AH11: 22 | AJ11: M4 | AK11: 43 | AL11: 20 | AM11: 41 | AN11: 14 | AO11: 22
A12: K | B12: K | C12: =COUNTIF(K:K, $A12) -> 47 | D12: =COUNTIF(L:L, $A12) -> 21 | E12: =COUNTIF(M:M, $A12) -> 41 | F12: =COUNTIF(N:N, $A12) -> 14 | G12: =COUNTIF(O:O, $A12) -> 22 | H12: 8 | J12: 8 | K12: A | L12: A | M12: K | N12: G2 | O12: M4 | Q12: 7 | R12: 7 | S12: 8 | T12: 12 | U12: 5 | W12: 1 | X12: 1 | Y12: 1 | Z12: 1 | AA12: 1 | AC12: M5 | AD12: 43 | AE12: 21 | AF12: 41 | AG12: 14 | AH12: 22 | AJ12: M5 | AK12: 43 | AL12: 21 | AM12: 41 | AN12: 14 | AO12: 22
A13: Q | B13: Q | C13: =COUNTIF(K:K, $A13) -> 4 | D13: =COUNTIF(L:L, $A13) -> 11 | E13: =COUNTIF(M:M, $A13) -> 5 | F13: =COUNTIF(N:N, $A13) -> 20 | G13: =COUNTIF(O:O, $A13) -> 22 | H13: 9 | J13: 9 | K13: M5 | L13: M4 | M13: K | N13: A | O13: Q | Q13: 6 | R13: 5 | S13: 8 | T13: 7 | U13: 9 | W13: 1 | X13: 1 | Y13: 1 | Z13: 1 | AA13: 1 | AC13: A | AD13: 47 | AE13: 21 | AF13: 41 | AG13: 14 | AH13: 22 | AJ13: A | AK13: 47 | AL13: 21 | AM13: 41 | AN13: 14 | AO13: 22
A14: J | B14: J | C14: =COUNTIF(K:K, $A14) -> 4 | D14: =COUNTIF(L:L, $A14) -> 11 | E14: =COUNTIF(M:M, $A14) -> 4 | F14: =COUNTIF(N:N, $A14) -> 20 | G14: =COUNTIF(O:O, $A14) -> 22 | H14: 10 | J14: 10 | K14: A | L14: J | M14: M5 | N14: G5 | O14: K | Q14: 7 | R14: 10 | S14: 6 | T14: 15 | U14: 8 | W14: 1 | X14: 1 | Y14: 1 | Z14: 1 | AA14: 1 | AC14: K | AD14: 47 | AE14: 21 | AF14: 41 | AG14: 14 | AH14: 22 | AJ14: K | AK14: 47 | AL14: 21 | AM14: 41 | AN14: 14 | AO14: 22
A15: G1 | B15: Gold M1 | C15: =COUNTIF(K:K, $A15) -> 0 | D15: =COUNTIF(L:L, $A15) -> 4 | E15: =COUNTIF(M:M, $A15) -> 0 | F15: =COUNTIF(N:N, $A15) -> 4 | G15: =COUNTIF(O:O, $A15) -> 0 | H15: 11 | J15: 11 | K15: M5 | L15: A | M15: A | N15: K | O15: M1 | Q15: 6 | R15: 7 | S15: 7 | T15: 8 | U15: 2 | W15: 1 | X15: 1 | Y15: 1 | Z15: 1 | AA15: 1 | AC15: Q | AD15: 4 | AE15: 11 | AF15: 5 | AG15: 20 | AH15: 22 | AJ15: Q | AK15: 4 | AL15: 11 | AM15: 5 | AN15: 20 | AO15: 22
A16: G2 | B16: Gold M2 | C16: =COUNTIF(K:K, $A16) -> 0 | D16: =COUNTIF(L:L, $A16) -> 5 | E16: =COUNTIF(M:M, $A16) -> 0 | F16: =COUNTIF(N:N, $A16) -> 4 | G16: =COUNTIF(O:O, $A16) -> 0 | H16: 12 | J16: 12 | K16: A | L16: G1 | M16: A | N16: K | O16: M2 | Q16: 7 | R16: 11 | S16: 7 | T16: 8 | U16: 3 | W16: 1 | X16: 1 | Y16: 1 | Z16: 1 | AA16: 1 | AC16: J | AD16: 4 | AE16: 11 | AF16: 4 | AG16: 20 | AH16: 22 | AJ16: J | AK16: 4 | AL16: 11 | AM16: 4 | AN16: 20 | AO16: 22
A17: G3 | B17: Gold M3 | C17: =COUNTIF(K:K, $A17) -> 0 | D17: =COUNTIF(L:L, $A17) -> 5 | E17: =COUNTIF(M:M, $A17) -> 0 | F17: =COUNTIF(N:N, $A17) -> 4 | G17: =COUNTIF(O:O, $A17) -> 0 | H17: 13 | J17: 13 | K17: K | L17: M1 | M17: A | N17: M3 | O17: Q | Q17: 8 | R17: 2 | S17: 7 | T17: 4 | U17: 9 | W17: 1 | X17: 1 | Y17: 1 | Z17: 1 | AA17: 1 | AC17: G1 | AD17: 0 | AE17: 4 | AF17: 0 | AG17: 4 | AH17: 0 | AJ17: G1 | AK17: 0 | AL17: 4 | AM17: 0 | AN17: 4 | AO17: 0
A18: G4 | B18: Gold M4 | C18: =COUNTIF(K:K, $A18) -> 0 | D18: =COUNTIF(L:L, $A18) -> 8 | E18: =COUNTIF(M:M, $A18) -> 3 | F18: =COUNTIF(N:N, $A18) -> 3 | G18: =COUNTIF(O:O, $A18) -> 0 | H18: 14 | J18: 14 | K18: M5 | L18: A | M18: G4 | N18: K | O18: Q | Q18: 6 | R18: 7 | S18: 14 | T18: 8 | U18: 9 | W18: 1 | X18: 1 | Y18: 1 | Z18: 1 | AA18: 1 | AC18: G2 | AD18: 0 | AE18: 5 | AF18: 0 | AG18: 4 | AH18: 0 | AJ18: G2 | AK18: 0 | AL18: 5 | AM18: 0 | AN18: 4 | AO18: 0
... A23: GJ | B23: Gold J | C23: =COUNTIF(K:K, $A23) -> 0 | D23: =COUNTIF(L:L, $A23) -> 5 | E23: =COUNTIF(M:M, $A23) -> 0 | F23: =COUNTIF(N:N, $A23) -> 4 | G23: =COUNTIF(O:O, $A23) -> 0 | H23: 19 | J23: 19 | K23: M4 | L23: M5 | M23: GA | N23: G4 | O23: M1 | Q23: 5 | R23: 6 | S23: 16 | T23: 14 | U23: 2 | W23: 1 | X23: 1 | Y23: 1 | Z23: 1 | AA23: 1 | AC23: GK | AD23: 0 | AE23: 8 | AF23: 3 | AG23: 3 | AH23: 0 | AJ23: GK | AK23: 0 | AL23: 8 | AM23: 3 | AN23: 3 | AO23: 0
