Workbook

Sheet Overview
A2: Model: | B2: H016194
A3: Version: | B3: 6.4.0.0
A6: Base Bet | B6: Multiway
A7: 100 | B7: 1024
A10: Coin in | B10: Price(x) | C10: Total RTP | D10: Bet Type
A11: =B11*$A$7 -> 100 | B11: 1 | C11: =B17+B18 -> 0.93999999 | D11: Normal Bet
A12: =B12*$A$7 -> 4050 | B12: 40.5 | C12: =B21+B22 -> 0.92499999 | D12: Buy Feature
A13: =B13*A7 -> 25000 | B13: 250 | C13: =B25+B26 -> 0.92499999 | D13: Super Buy
A15: Total Pay Back Percentage includes the following adjustments.
A16: Bet Type | B16: Pay Back | C16: Hit% | D16: Pulls/Hit | E16: Description
A17: =D11 -> Normal Bet | B17: =Detail!C7 -> 0.64999999 | C17: =1/D17 -> 0.0076923077 | D17: =Detail!G7 -> 130 | E17: Base Game
B18: =Detail!D7 -> 0.29 | E18: Free Game
A20: Bet Type | B20: Pay Back | C20: Hit% | D20: Pulls/Hit | E20: Description
A21: =D12 -> Buy Feature | B21: =Detail!C8 -> 0 | C21: =1/D21 -> 1 | D21: 1 | E21: Base Game
B22: =Detail!D8 -> 0.92499999 | E22: Free Game
A24: Bet Type | B24: Pay Back | C24: Hit% | D24: Pulls/Hit | E24: Description
A25: =D13 -> Super Buy | B25: =Detail!C9 -> 0 | C25: =IFERROR(1/D25,0) -> 1 | D25: 1 | E25: Base Game
B26: =Detail!D9 -> 0.92499999 | E26: Free Game

Sheet Multiplier_Weight
A2: Range | B2: Weight_NB_BG_Newbie | C2: Weight_NB_FG_Newbie | D2: Weight_NB_BG | E2: Weight_NB_FG | F2: Weight_BF | G2: Weight_SF
A3: (-1, 0] | B3: =Detail_Newbie!K15 -> 748474171 | C3: =Detail_Newbie!K86 -> 0 | D3: =Detail!K15 -> 780374874 | E3: =Detail!K86 -> 0 | F3: =Detail!K163 -> 0 | G3: =Detail!K234 -> 0
A4: (0, 1] | B4: =Detail_Newbie!K16 -> 141274773 | C4: =Detail_Newbie!K87 -> 0 | D4: =Detail!K16 -> 122295421 | E4: =Detail!K87 -> 0 | F4: =Detail!K164 -> 0 | G4: =Detail!K235 -> 0
A5: (1, 2] | B5: =Detail_Newbie!K17 -> 35403536 | C5: =Detail_Newbie!K88 -> 0 | D5: =Detail!K17 -> 30647302 | E5: =Detail!K88 -> 0 | F5: =Detail!K165 -> 0 | G5: =Detail!K236 -> 0
A6: (2, 3] | B6: =Detail_Newbie!K18 -> 19721991 | C6: =Detail_Newbie!K89 -> 0 | D6: =Detail!K18 -> 17072470 | E6: =Detail!K89 -> 0 | F6: =Detail!K166 -> 0 | G6: =Detail!K237 -> 0
A7: (3, 4] | B7: =Detail_Newbie!K19 -> 12447907 | C7: =Detail_Newbie!K90 -> 0 | D7: =Detail!K19 -> 10775613 | E7: =Detail!K90 -> 0 | F7: =Detail!K167 -> 0 | G7: =Detail!K238 -> 0
A8: (4, 5] | B8: =Detail_Newbie!K20 -> 10078705 | C8: =Detail_Newbie!K91 -> 0 | D8: =Detail!K20 -> 8724697 | E8: =Detail!K91 -> 0 | F8: =Detail!K168 -> 0 | G8: =Detail!K239 -> 0
A9: (5, 6] | B9: =Detail_Newbie!K21 -> 4130093 | C9: =Detail_Newbie!K92 -> 27989937 | D9: =Detail!K21 -> 3575241 | E9: =Detail!K92 -> 34366617 | F9: =Detail!K169 -> 34499126 | G9: =Detail!K240 -> 0
A10: (6, 7] | B10: =Detail_Newbie!K22 -> 3534591 | C10: =Detail_Newbie!K93 -> 24287702 | D10: =Detail!K22 -> 3059741 | E10: =Detail!K93 -> 29563828 | F10: =Detail!K170 -> 29674200 | G10: =Detail!K241 -> 0
A11: (7, 8] | B11: =Detail_Newbie!K23 -> 3073557 | C11: =Detail_Newbie!K94 -> 26217804 | D11: =Detail!K23 -> 2660645 | E11: =Detail!K94 -> 31635636 | F11: =Detail!K171 -> 31749801 | G11: =Detail!K242 -> 0
A12: (8, 9] | B12: =Detail_Newbie!K24 -> 2618927 | C12: =Detail_Newbie!K95 -> 25303013 | D12: =Detail!K24 -> 2267090 | E12: =Detail!K95 -> 30268903 | F12: =Detail!K172 -> 30374449 | G12: =Detail!K243 -> 0
A13: (9, 10] | B13: =Detail_Newbie!K25 -> 2574104 | C13: =Detail_Newbie!K96 -> 27271779 | D13: =Detail!K25 -> 2228289 | E13: =Detail!K96 -> 32342055 | F13: =Detail!K173 -> 32450850 | G13: =Detail!K244 -> 0
A14: (10, 15] | B14: =Detail_Newbie!K26 -> 9592060 | C14: =Detail_Newbie!K97 -> 121586766 | D14: =Detail!K26 -> 8303428 | E14: =Detail!K97 -> 140499777 | F14: =Detail!K174 -> 140920893 | G14: =Detail!K245 -> 0
... A66: (100000, 9999999] | B66: =Detail_Newbie!K78 -> 0 | C66: =Detail_Newbie!K149 -> 0 | D66: =Detail!K78 -> 0 | E66: =Detail!K149 -> 0 | F66: =Detail!K226 -> 0 | G66: =Detail!K297 -> 0
A67: Free Game | B67: =Detail_Newbie!K79 -> 7751938 | C67: 0 | D67: =Detail!K79 -> 7751938 | E67: 0 | F67: 0 | G67: =0 -> 0

Sheet Detail
A2: Threshold | B2: 1000000000
A3: Coin in | B3: =Overview!A7 -> 100
C5: RTP
B6: Bet | C6: Base Game | D6: Free Game | E6: Total | F6: Hit Rate | G6: FG Period | H6: Avg Multi | I6: BG | J6: FG
A7: Normal Bet | B7: =Overview!B11 -> 1 | C7: =SUM(M15:M79) -> 0.64999999 | D7: =SUM(M86:M149)*F7 -> 0.29 | E7: =SUM(C7:D7) -> 0.93999999 | F7: =L79 -> 0.0076923077 | G7: =1/F7 -> 130 | H7: =D7*G7 -> 37.7 | I7: =IFERROR(LOOKUP(2,1/(K15:K78<>0),P15:P78),0) -> 70 | J7: =IFERROR(LOOKUP(2,1/(K86:K149<>0),P86:P149),0) -> 2000
A8: Buy Feature | B8: =Overview!B12 -> 40.5 | C8: =M156/B8 -> 0 | D8: =SUM(M163:M226)/B8 -> 0.92499999 | E8: =SUM(C8:D8) -> 0.92499999 | F8: =D156 -> 1 | G8: =1/F8 -> 1 | H8: =D8*G8*B8 -> 37.4625 | J8: =IFERROR(LOOKUP(2,1/(K163:K226<>0),P163:P226),0) -> 2000
A9: Super Buy | B9: 250 | C9: =0 -> 0 | D9: =IFERROR(SUM(M234:M297)/B9,0) -> 0.92499999 | E9: =SUM(C9:D9) -> 0.92499999 | F9: =1 -> 1 | G9: =IFERROR(1/F9,0) -> 1 | H9: =D9*G9*B9 -> 231.25 | J9: =IFERROR(LOOKUP(2,1/(K234:K297<>0),P234:P297),0) -> 4000
A11: Normal Bet | B11: Base Game | G11: Normal Bet | H11: Base Game | O11: Normal Bet | P11: Base Game
A13: Simulate | B13: 1000000000 | G13: Calculate
A14: Range | B14: Cnt | C14: Pay | D14: Hit Rate | E14: Avg. Multi. | G14: Range | H14: Fix Num | I14: Fix Rate | J14: Final Rate | K14: Weight | L14: Hit Rate | M14: Simulator RTP | O14: Lower | P14: Upper | Q14: 目前 | R14: 競品 | T14: 目前 | U14: 差異
A15: ="("&$O15&", "&$P15&"]" -> (-1, 0] | B15: 631527917 | C15: 0 | D15: =IFERROR(B15/SUM($B$15:$B$78),0) -> 0.63152792 | E15: =IFERROR(C15/B15/$B$3,0) -> 0 | G15: ="("&$O15&", "&$P15&"]" -> (-1, 0] | H15: 1.2356934 | I15: =D15*H15 -> 0.78037487 | J15: =IFERROR(I15/SUM($I$15:$I$78),0) -> 0.78037487 | K15: =INT(J15*$B$2) -> 780374874 | L15: =IFERROR(K15/SUM($K$15:$K$79),0) -> 0.77437199 | M15: =L15*E15 -> 0 | O15: -1 | P15: 0 | Q15: =L15 -> 0.77437199 | R15: 0.76387345 | U15: =IFERROR(ROUND(T15/L15,2),0) -> 0
A16: ="("&$O16&", "&$P16&"]" -> (0, 1] | B16: 168741642 | C16: 6991084375 | D16: =IFERROR(B16/SUM($B$15:$B$78),0) -> 0.16874164 | E16: =IFERROR(C16/B16/$B$3,0) -> 0.414307 | G16: ="("&$O16&", "&$P16&"]" -> (0, 1] | H16: 0.7247495 | I16: =D16*H16 -> 0.12229542 | J16: =IFERROR(I16/SUM($I$15:$I$78),0) -> 0.12229542 | K16: =INT(J16*$B$2) -> 122295421 | L16: =IFERROR(K16/SUM($K$15:$K$79),0) -> 0.12135469 | M16: =L16*E16 -> 0.050278097 | O16: 0 | P16: 1 | Q16: =L16 -> 0.12135469 | R16: 0.13400021 | U16: =IFERROR(ROUND(T16/L16,2),0) -> 0
A17: ="("&$O17&", "&$P17&"]" -> (1, 2] | B17: 49179091 | C17: 7386239950 | D17: =IFERROR(B17/SUM($B$15:$B$78),0) -> 0.049179091 | E17: =IFERROR(C17/B17/$B$3,0) -> 1.5019066 | G17: ="("&$O17&", "&$P17&"]" -> (1, 2] | H17: 0.62317748 | I17: =D17*H17 -> 0.030647302 | J17: =IFERROR(I17/SUM($I$15:$I$78),0) -> 0.030647302 | K17: =INT(J17*$B$2) -> 30647302 | L17: =IFERROR(K17/SUM($K$15:$K$79),0) -> 0.030411554 | M17: =L17*E17 -> 0.045675312 | O17: 1 | P17: 2 | Q17: =L17 -> 0.030411554 | R17: 0.033580526 | U17: =IFERROR(ROUND(T17/L17,2),0) -> 0
A18: ="("&$O18&", "&$P18&"]" -> (2, 3] | B18: 27802915 | C18: 7026127570 | D18: =IFERROR(B18/SUM($B$15:$B$78),0) -> 0.027802915 | E18: =IFERROR(C18/B18/$B$3,0) -> 2.527119 | G18: ="("&$O18&", "&$P18&"]" -> (2, 3] | H18: 0.61405324 | I18: =D18*H18 -> 0.01707247 | J18: =IFERROR(I18/SUM($I$15:$I$78),0) -> 0.01707247 | K18: =INT(J18*$B$2) -> 17072470 | L18: =IFERROR(K18/SUM($K$15:$K$79),0) -> 0.016941143 | M18: =L18*E18 -> 0.042812286 | O18: 2 | P18: 3 | Q18: =L18 -> 0.016941143 | R18: 0.01870646 | U18: =IFERROR(ROUND(T18/L18,2),0) -> 0
A19: ="("&$O19&", "&$P19&"]" -> (3, 4] | B19: 18076094 | C19: 6434648930 | D19: =IFERROR(B19/SUM($B$15:$B$78),0) -> 0.018076094 | E19: =IFERROR(C19/B19/$B$3,0) -> 3.5597563 | G19: ="("&$O19&", "&$P19&"]" -> (3, 4] | H19: 0.59612508 | I19: =D19*H19 -> 0.010775613 | J19: =IFERROR(I19/SUM($I$15:$I$78),0) -> 0.010775613 | K19: =INT(J19*$B$2) -> 10775613 | L19: =IFERROR(K19/SUM($K$15:$K$79),0) -> 0.010692724 | M19: =L19*E19 -> 0.03806349 | O19: 3 | P19: 4 | Q19: =L19 -> 0.010692724 | R19: 0.011806935 | U19: =IFERROR(ROUND(T19/L19,2),0) -> 0
A20: ="("&$O20&", "&$P20&"]" -> (4, 5] | B20: 13913831 | C20: 6300738315 | D20: =IFERROR(B20/SUM($B$15:$B$78),0) -> 0.013913831 | E20: =IFERROR(C20/B20/$B$3,0) -> 4.5283993 | G20: ="("&$O20&", "&$P20&"]" -> (4, 5] | H20: 0.6270521 | I20: =D20*H20 -> 0.008724697 | J20: =IFERROR(I20/SUM($I$15:$I$78),0) -> 0.008724697 | K20: =INT(J20*$B$2) -> 8724697 | L20: =IFERROR(K20/SUM($K$15:$K$79),0) -> 0.0086575839 | M20: =L20*E20 -> 0.039204997 | O20: 4 | P20: 5 | Q20: =L20 -> 0.0086575839 | R20: 0.0095597301 | U20: =IFERROR(ROUND(T20/L20,2),0) -> 0
A21: ="("&$O21&", "&$P21&"]" -> (5, 6] | B21: 10559309 | C21: 5858454015 | D21: =IFERROR(B21/SUM($B$15:$B$78),0) -> 0.010559309 | E21: =IFERROR(C21/B21/$B$3,0) -> 5.5481415 | G21: ="("&$O21&", "&$P21&"]" -> (5, 6] | H21: 0.33858664 | I21: =D21*H21 -> 0.003575241 | J21: =IFERROR(I21/SUM($I$15:$I$78),0) -> 0.003575241 | K21: =INT(J21*$B$2) -> 3575241 | L21: =IFERROR(K21/SUM($K$15:$K$79),0) -> 0.0035477391 | M21: =L21*E21 -> 0.019683359 | O21: 5 | P21: 6 | Q21: =L21 -> 0.0035477391 | R21: 0.0039174243 | U21: =IFERROR(ROUND(T21/L21,2),0) -> 0
A22: ="("&$O22&", "&$P22&"]" -> (6, 7] | B22: 8233456 | C22: 5364354110 | D22: =IFERROR(B22/SUM($B$15:$B$78),0) -> 0.008233456 | E22: =IFERROR(C22/B22/$B$3,0) -> 6.5153128 | G22: ="("&$O22&", "&$P22&"]" -> (6, 7] | H22: 0.37162292 | I22: =D22*H22 -> 0.003059741 | J22: =IFERROR(I22/SUM($I$15:$I$78),0) -> 0.003059741 | K22: =INT(J22*$B$2) -> 3059741 | L22: =IFERROR(K22/SUM($K$15:$K$79),0) -> 0.0030362045 | M22: =L22*E22 -> 0.019781822 | O22: 6 | P22: 7 | Q22: =L22 -> 0.0030362045 | R22: 0.0033525864 | U22: =IFERROR(ROUND(T22/L22,2),0) -> 0
A23: ="("&$O23&", "&$P23&"]" -> (7, 8] | B23: 7402250 | C23: 5582946445 | D23: =IFERROR(B23/SUM($B$15:$B$78),0) -> 0.00740225 | E23: =IFERROR(C23/B23/$B$3,0) -> 7.542229 | G23: ="("&$O23&", "&$P23&"]" -> (7, 8] | H23: 0.35943733 | I23: =D23*H23 -> 0.002660645 | J23: =IFERROR(I23/SUM($I$15:$I$78),0) -> 0.002660645 | K23: =INT(J23*$B$2) -> 2660645 | L23: =IFERROR(K23/SUM($K$15:$K$79),0) -> 0.0026401785 | M23: =L23*E23 -> 0.019912831 | O23: 7 | P23: 8 | Q23: =L23 -> 0.0026401785 | R23: 0.0029152925 | U23: =IFERROR(ROUND(T23/L23,2),0) -> 0
A24: ="("&$O24&", "&$P24&"]" -> (8, 9] | B24: 6145959 | C24: 5236519725 | D24: =IFERROR(B24/SUM($B$15:$B$78),0) -> 0.006145959 | E24: =IFERROR(C24/B24/$B$3,0) -> 8.5202647 | G24: ="("&$O24&", "&$P24&"]" -> (8, 9] | H24: 0.3688749 | I24: =D24*H24 -> 0.00226709 | J24: =IFERROR(I24/SUM($I$15:$I$78),0) -> 0.00226709 | K24: =INT(J24*$B$2) -> 2267090 | L24: =IFERROR(K24/SUM($K$15:$K$79),0) -> 0.0022496508 | M24: =L24*E24 -> 0.019167621 | O24: 8 | P24: 9 | Q24: =L24 -> 0.0022496508 | R24: 0.0024840722 | U24: =IFERROR(ROUND(T24/L24,2),0) -> 0
A25: ="("&$O25&", "&$P25&"]" -> (9, 10] | B25: 5019063 | C25: 4784548545 | D25: =IFERROR(B25/SUM($B$15:$B$78),0) -> 0.005019063 | E25: =IFERROR(C25/B25/$B$3,0) -> 9.5327525 | G25: ="("&$O25&", "&$P25&"]" -> (9, 10] | H25: 0.44396514 | I25: =D25*H25 -> 0.002228289 | J25: =IFERROR(I25/SUM($I$15:$I$78),0) -> 0.002228289 | K25: =INT(J25*$B$2) -> 2228289 | L25: =IFERROR(K25/SUM($K$15:$K$79),0) -> 0.0022111483 | M25: =L25*E25 -> 0.02107833 | O25: 9 | P25: 10 | Q25: =L25 -> 0.0022111483 | R25: 0.0024415575 | U25: =IFERROR(ROUND(T25/L25,2),0) -> 0
A26: ="("&$O26&", "&$P26&"]" -> (10, 15] | B26: 17254137 | C26: 21231801930 | D26: =IFERROR(B26/SUM($B$15:$B$78),0) -> 0.017254137 | E26: =IFERROR(C26/B26/$B$3,0) -> 12.30534 | G26: ="("&$O26&", "&$P26&"]" -> (10, 15] | H26: 0.48124273 | I26: =D26*H26 -> 0.008303428 | J26: =IFERROR(I26/SUM($I$15:$I$78),0) -> 0.008303428 | K26: =INT(J26*$B$2) -> 8303428 | L26: =IFERROR(K26/SUM($K$15:$K$79),0) -> 0.0082395555 | M26: =L26*E26 -> 0.10139053 | O26: 10 | P26: 15 | Q26: =L26 -> 0.0082395555 | R26: 0.0045490711 | U26: =IFERROR(ROUND(T26/L26,2),0) -> 0
... A78: ="("&$O78&", "&$P78&"]" -> (100000, 9999999] | B78: 0 | C78: 0 | D78: =IFERROR(B78/SUM($B$15:$B$78),0) -> 0 | E78: =IFERROR(C78/B78/$B$3,0) -> 0 | G78: ="("&$O78&", "&$P78&"]" -> (100000, 9999999] | H78: 0 | I78: =D78*H78 -> 0 | J78: =IFERROR(I78/SUM($I$15:$I$78),0) -> 0 | K78: =INT(J78*$B$2) -> 0 | L78: =IFERROR(K78/SUM($K$15:$K$79),0) -> 0 | M78: =L78*E78 -> 0 | O78: 100000 | P78: 9999999 | Q78: =L78 -> 0 | R78: 0 | U78: =IFERROR(ROUND(T78/L78,2),0) -> 0
A79: Free Game | B79: 8997512 | C79: 2594257240 | D79: =B79/B13 -> 0.008997512 | E79: =IFERROR(C79/B79/$B$3,0) -> 2.8833051 | G79: Free Game | H79: 0.86156462 | I79: =D79*H79 -> 0.007751938 | J79: =I79 -> 0.007751938 | K79: =INT(J79*$B$2) -> 7751938 | L79: =IFERROR(K79/SUM($K$15:$K$79),0) -> 0.0076923077 | M79: =L79*E79 -> 0.02217927
A82: Normal Bet | B82: Free Game | G82: Normal Bet | H82: Free Game | O82: Normal Bet | P82: Free Game
A84: Simulate | G84: Calculate
A85: Range | B85: Cnt | C85: Pay | D85: Hit Rate | E85: Avg. Multi. | G85: Range | H85: Fix Num | I85: Fix Rate | J85: Final Rate | K85: Weight | L85: Hit Rate | M85: Simulator RTP | O85: Lower | P85: Upper | Q85: 目前 | R85: 競品 | T85: 目前 | U85: 差異
A86: ="("&$O86&", "&$P86&"]" -> (-1, 0] | B86: 17757 | C86: 0 | D86: =IFERROR(B86/SUM($B$86:$B$149),0) -> 0.0019679053 | E86: =IFERROR(C86/B86/$B$3,0) -> 0 | G86: ="("&$O86&", "&$P86&"]" -> (-1, 0] | H86: 0 | I86: =D86*H86 -> 0 | J86: =IFERROR(I86/SUM($I$86:$I$149),0) -> 0 | K86: =INT(J86*$B$2) -> 0 | L86: =IFERROR(K86/SUM($K$86:$K$149),0) -> 0 | M86: =L86*E86 -> 0 | O86: -1 | P86: 0 | Q86: =L86 -> 0 | R86: 0 | U86: =IFERROR(ROUND(T86/L86,2),0) -> 0
A87: ="("&$O87&", "&$P87&"]" -> (0, 1] | B87: 51825 | C87: 2951940 | D87: =IFERROR(B87/SUM($B$86:$B$149),0) -> 0.0057434641 | E87: =IFERROR(C87/B87/$B$3,0) -> 0.56959768 | G87: ="("&$O87&", "&$P87&"]" -> (0, 1] | H87: 0 | I87: =D87*H87 -> 0 | J87: =IFERROR(I87/SUM($I$86:$I$149),0) -> 0 | K87: =INT(J87*$B$2) -> 0 | L87: =IFERROR(K87/SUM($K$86:$K$149),0) -> 0 | M87: =L87*E87 -> 0 | O87: 0 | P87: 1 | Q87: =L87 -> 0 | R87: 0 | U87: =IFERROR(ROUND(T87/L87,2),0) -> 0
A88: ="("&$O88&", "&$P88&"]" -> (1, 2] | B88: 50461 | C88: 7896650 | D88: =IFERROR(B88/SUM($B$86:$B$149),0) -> 0.0055922999 | E88: =IFERROR(C88/B88/$B$3,0) -> 1.5649016 | G88: ="("&$O88&", "&$P88&"]" -> (1, 2] | H88: 0 | I88: =D88*H88 -> 0 | J88: =IFERROR(I88/SUM($I$86:$I$149),0) -> 0 | K88: =INT(J88*$B$2) -> 0 | L88: =IFERROR(K88/SUM($K$86:$K$149),0) -> 0 | M88: =L88*E88 -> 0 | O88: 1 | P88: 2 | Q88: =L88 -> 0 | R88: 0 | U88: =IFERROR(ROUND(T88/L88,2),0) -> 0
A89: ="("&$O89&", "&$P89&"]" -> (2, 3] | B89: 50095 | C89: 12863820 | D89: =IFERROR(B89/SUM($B$86:$B$149),0) -> 0.0055517383 | E89: =IFERROR(C89/B89/$B$3,0) -> 2.567885 | G89: ="("&$O89&", "&$P89&"]" -> (2, 3] | H89: 0 | I89: =D89*H89 -> 0 | J89: =IFERROR(I89/SUM($I$86:$I$149),0) -> 0 | K89: =INT(J89*$B$2) -> 0 | L89: =IFERROR(K89/SUM($K$86:$K$149),0) -> 0 | M89: =L89*E89 -> 0 | O89: 2 | P89: 3 | Q89: =L89 -> 0 | R89: 0 | U89: =IFERROR(ROUND(T89/L89,2),0) -> 0
A90: ="("&$O90&", "&$P90&"]" -> (3, 4] | B90: 47166 | C90: 16819970 | D90: =IFERROR(B90/SUM($B$86:$B$149),0) -> 0.0052271342 | E90: =IFERROR(C90/B90/$B$3,0) -> 3.5661218 | G90: ="("&$O90&", "&$P90&"]" -> (3, 4] | H90: 0 | I90: =D90*H90 -> 0 | J90: =IFERROR(I90/SUM($I$86:$I$149),0) -> 0 | K90: =INT(J90*$B$2) -> 0 | L90: =IFERROR(K90/SUM($K$86:$K$149),0) -> 0 | M90: =L90*E90 -> 0 | O90: 3 | P90: 4 | Q90: =L90 -> 0 | R90: 0 | U90: =IFERROR(ROUND(T90/L90,2),0) -> 0
A91: ="("&$O91&", "&$P91&"]" -> (4, 5] | B91: 47329 | C91: 21614690 | D91: =IFERROR(B91/SUM($B$86:$B$149),0) -> 0.0052451985 | E91: =IFERROR(C91/B91/$B$3,0) -> 4.5669019 | G91: ="("&$O91&", "&$P91&"]" -> (4, 5] | H91: 0 | I91: =D91*H91 -> 0 | J91: =IFERROR(I91/SUM($I$86:$I$149),0) -> 0 | K91: =INT(J91*$B$2) -> 0 | L91: =IFERROR(K91/SUM($K$86:$K$149),0) -> 0 | M91: =L91*E91 -> 0 | O91: 4 | P91: 5 | Q91: =L91 -> 0 | R91: 0.0035688794 | U91: =IFERROR(ROUND(T91/L91,2),0) -> 0
A92: ="("&$O92&", "&$P92&"]" -> (5, 6] | B92: 46826 | C92: 26050370 | D92: =IFERROR(B92/SUM($B$86:$B$149),0) -> 0.005189454 | E92: =IFERROR(C92/B92/$B$3,0) -> 5.5632277 | G92: ="("&$O92&", "&$P92&"]" -> (5, 6] | H92: 6.6223956 | I92: =D92*H92 -> 0.034366617 | J92: =IFERROR(I92/SUM($I$86:$I$149),0) -> 0.034366617 | K92: =INT(J92*$B$2) -> 34366617 | L92: =IFERROR(K92/SUM($K$86:$K$149),0) -> 0.034366617 | M92: =L92*E92 -> 0.19118932 | O92: 5 | P92: 6 | Q92: =L92 -> 0.034366617 | R92: 0.035688794 | U92: =IFERROR(ROUND(T92/L92,2),0) -> 0
A93: ="("&$O93&", "&$P93&"]" -> (6, 7] | B93: 45678 | C93: 29965010 | D93: =IFERROR(B93/SUM($B$86:$B$149),0) -> 0.0050622278 | E93: =IFERROR(C93/B93/$B$3,0) -> 6.560053 | G93: ="("&$O93&", "&$P93&"]" -> (6, 7] | H93: 5.8400825 | I93: =D93*H93 -> 0.029563828 | J93: =IFERROR(I93/SUM($I$86:$I$149),0) -> 0.029563828 | K93: =INT(J93*$B$2) -> 29563828 | L93: =IFERROR(K93/SUM($K$86:$K$149),0) -> 0.029563828 | M93: =L93*E93 -> 0.19394028 | O93: 6 | P93: 7 | Q93: =L93 -> 0.029563828 | R93: 0.030692363 | U93: =IFERROR(ROUND(T93/L93,2),0) -> 0
A94: ="("&$O94&", "&$P94&"]" -> (7, 8] | B94: 45247 | C94: 34232610 | D94: =IFERROR(B94/SUM($B$86:$B$149),0) -> 0.0050144626 | E94: =IFERROR(C94/B94/$B$3,0) -> 7.5657193 | G94: ="("&$O94&", "&$P94&"]" -> (7, 8] | H94: 6.3088787 | I94: =D94*H94 -> 0.031635636 | J94: =IFERROR(I94/SUM($I$86:$I$149),0) -> 0.031635636 | K94: =INT(J94*$B$2) -> 31635636 | L94: =IFERROR(K94/SUM($K$86:$K$149),0) -> 0.031635636 | M94: =L94*E94 -> 0.23934634 | O94: 7 | P94: 8 | Q94: =L94 -> 0.031635636 | R94: 0.03283369 | U94: =IFERROR(ROUND(T94/L94,2),0) -> 0
A95: ="("&$O95&", "&$P95&"]" -> (8, 9] | B95: 45343 | C95: 38819360 | D95: =IFERROR(B95/SUM($B$86:$B$149),0) -> 0.0050251017 | E95: =IFERROR(C95/B95/$B$3,0) -> 8.5612686 | G95: ="("&$O95&", "&$P95&"]" -> (8, 9] | H95: 6.0235404 | I95: =D95*H95 -> 0.030268903 | J95: =IFERROR(I95/SUM($I$86:$I$149),0) -> 0.030268903 | K95: =INT(J95*$B$2) -> 30268903 | L95: =IFERROR(K95/SUM($K$86:$K$149),0) -> 0.030268903 | M95: =L95*E95 -> 0.25914021 | O95: 8 | P95: 9 | Q95: =L95 -> 0.030268903 | R95: 0.031406138 | U95: =IFERROR(ROUND(T95/L95,2),0) -> 0
A96: ="("&$O96&", "&$P96&"]" -> (9, 10] | B96: 45213 | C96: 43226590 | D96: =IFERROR(B96/SUM($B$86:$B$149),0) -> 0.0050106945 | E96: =IFERROR(C96/B96/$B$3,0) -> 9.5606551 | G96: ="("&$O96&", "&$P96&"]" -> (9, 10] | H96: 6.4546052 | I96: =D96*H96 -> 0.032342055 | J96: =IFERROR(I96/SUM($I$86:$I$149),0) -> 0.032342055 | K96: =INT(J96*$B$2) -> 32342055 | L96: =IFERROR(K96/SUM($K$86:$K$149),0) -> 0.032342055 | M96: =L96*E96 -> 0.30921123 | O96: 9 | P96: 10 | Q96: =L96 -> 0.032342055 | R96: 0.033547466 | U96: =IFERROR(ROUND(T96/L96,2),0) -> 0
A97: ="("&$O97&", "&$P97&"]" -> (10, 15] | B97: 221826 | C97: 278316430 | D97: =IFERROR(B97/SUM($B$86:$B$149),0) -> 0.024583689 | E97: =IFERROR(C97/B97/$B$3,0) -> 12.54661 | G97: ="("&$O97&", "&$P97&"]" -> (10, 15] | H97: 5.7151625 | I97: =D97*H97 -> 0.14049978 | J97: =IFERROR(I97/SUM($I$86:$I$149),0) -> 0.14049978 | K97: =INT(J97*$B$2) -> 140499777 | L97: =IFERROR(K97/SUM($K$86:$K$149),0) -> 0.14049978 | M97: =L97*E97 -> 1.7627959 | O97: 10 | P97: 15 | Q97: =L97 -> 0.14049978 | R97: 0.14561028 | U97: =IFERROR(ROUND(T97/L97,2),0) -> 0
... A149: ="("&$O149&", "&$P149&"]" -> (100000, 9999999] | B149: 0 | C149: 0 | D149: =IFERROR(B149/SUM($B$86:$B$149),0) -> 0 | E149: =IFERROR(C149/B149/$B$3,0) -> 0 | G149: ="("&$O149&", "&$P149&"]" -> (100000, 9999999] | H149: 0 | I149: =D149*H149 -> 0 | J149: =IFERROR(I149/SUM($I$86:$I$149),0) -> 0 | K149: =INT(J149*$B$2) -> 0 | L149: =IFERROR(K149/SUM($K$86:$K$149),0) -> 0 | M149: =L149*E149 -> 0 | O149: 100000 | P149: 9999999 | Q149: =L149 -> 0 | R149: 0 | U149: =IFERROR(ROUND(T149/L149,2),0) -> 0
...

Sheet Detail_Newbie
A2: Threshold | B2: 1000000000
A3: Coin in | B3: =Overview!A7 -> 100
C5: RTP
B6: Bet | C6: Base Game | D6: Free Game | E6: Total | F6: Hit Rate | G6: FG Period | H6: Avg Multi | I6: BG | J6: FG
A7: Normal Bet | B7: =Overview!B11 -> 1 | C7: =SUM(M15:M79) -> 0.65 | D7: =SUM(M86:M149)*F7 -> 0.28 | E7: =SUM(C7:D7) -> 0.93 | F7: =L79 -> 0.0076923077 | G7: =1/F7 -> 130 | H7: =D7*G7 -> 36.4 | I7: =IFERROR(LOOKUP(2,1/(K15:K78<>0),P15:P78),0) -> 30 | J7: =IFERROR(LOOKUP(2,1/(K86:K149<>0),P86:P149),0) -> 120
A11: Normal Bet | B11: Base Game | G11: Normal Bet | H11: Base Game | O11: Normal Bet | P11: Base Game
A13: Simulate | B13: 1000000000 | G13: Calculate
A14: Range | B14: Cnt | C14: Pay | D14: Hit Rate | E14: Avg. Multi. | G14: Range | H14: Fix Num | I14: Fix Rate | J14: Final Rate | K14: Weight | L14: Hit Rate | M14: Simulator RTP | O14: Lower | P14: Upper | Q14: 目前 | R14: 競品 | T14: 目前 | U14: 差異
A15: ="("&$O15&", "&$P15&"]" -> (-1, 0] | B15: 631527917 | C15: 0 | D15: =IFERROR(B15/SUM($B$15:$B$78),0) -> 0.63152792 | E15: =IFERROR(C15/B15/$B$3,0) -> 0 | G15: ="("&$O15&", "&$P15&"]" -> (-1, 0] | H15: 1.1851799 | I15: =D15*H15 -> 0.74847417 | J15: =IFERROR(I15/SUM($I$15:$I$78),0) -> 0.74847417 | K15: =INT(J15*$B$2) -> 748474171 | L15: =IFERROR(K15/SUM($K$15:$K$79),0) -> 0.74271668 | M15: =L15*E15 -> 0 | O15: -1 | P15: 0 | Q15: =L15 -> 0.74271668 | R15: 0.723799 | U15: =IFERROR(ROUND(T15/L15,2),0) -> 0
A16: ="("&$O16&", "&$P16&"]" -> (0, 1] | B16: 168741642 | C16: 6991084375 | D16: =IFERROR(B16/SUM($B$15:$B$78),0) -> 0.16874164 | E16: =IFERROR(C16/B16/$B$3,0) -> 0.414307 | G16: ="("&$O16&", "&$P16&"]" -> (0, 1] | H16: 0.83722531 | I16: =D16*H16 -> 0.14127477 | J16: =IFERROR(I16/SUM($I$15:$I$78),0) -> 0.14127477 | K16: =INT(J16*$B$2) -> 141274773 | L16: =IFERROR(K16/SUM($K$15:$K$79),0) -> 0.14018804 | M16: =L16*E16 -> 0.058080888 | O16: 0 | P16: 1 | Q16: =L16 -> 0.14018804 | R16: 0.154266 | U16: =IFERROR(ROUND(T16/L16,2),0) -> 0
A17: ="("&$O17&", "&$P17&"]" -> (1, 2] | B17: 49179091 | C17: 7386239950 | D17: =IFERROR(B17/SUM($B$15:$B$78),0) -> 0.049179091 | E17: =IFERROR(C17/B17/$B$3,0) -> 1.5019066 | G17: ="("&$O17&", "&$P17&"]" -> (1, 2] | H17: 0.71989 | I17: =D17*H17 -> 0.035403536 | J17: =IFERROR(I17/SUM($I$15:$I$78),0) -> 0.035403536 | K17: =INT(J17*$B$2) -> 35403536 | L17: =IFERROR(K17/SUM($K$15:$K$79),0) -> 0.035131201 | M17: =L17*E17 -> 0.052763781 | O17: 1 | P17: 2 | Q17: =L17 -> 0.035131201 | R17: 0.045428 | U17: =IFERROR(ROUND(T17/L17,2),0) -> 0
A18: ="("&$O18&", "&$P18&"]" -> (2, 3] | B18: 27802915 | C18: 7026127570 | D18: =IFERROR(B18/SUM($B$15:$B$78),0) -> 0.027802915 | E18: =IFERROR(C18/B18/$B$3,0) -> 2.527119 | G18: ="("&$O18&", "&$P18&"]" -> (2, 3] | H18: 0.70934976 | I18: =D18*H18 -> 0.019721991 | J18: =IFERROR(I18/SUM($I$15:$I$78),0) -> 0.019721991 | K18: =INT(J18*$B$2) -> 19721991 | L18: =IFERROR(K18/SUM($K$15:$K$79),0) -> 0.019570283 | M18: =L18*E18 -> 0.049456436 | O18: 2 | P18: 3 | Q18: =L18 -> 0.019570283 | R18: 0.02091 | U18: =IFERROR(ROUND(T18/L18,2),0) -> 0
A19: ="("&$O19&", "&$P19&"]" -> (3, 4] | B19: 18076094 | C19: 6434648930 | D19: =IFERROR(B19/SUM($B$15:$B$78),0) -> 0.018076094 | E19: =IFERROR(C19/B19/$B$3,0) -> 3.5597563 | G19: ="("&$O19&", "&$P19&"]" -> (3, 4] | H19: 0.6886392 | I19: =D19*H19 -> 0.012447907 | J19: =IFERROR(I19/SUM($I$15:$I$78),0) -> 0.012447907 | K19: =INT(J19*$B$2) -> 12447907 | L19: =IFERROR(K19/SUM($K$15:$K$79),0) -> 0.012352154 | M19: =L19*E19 -> 0.043970657 | O19: 3 | P19: 4 | Q19: =L19 -> 0.012352154 | R19: 0.012886 | U19: =IFERROR(ROUND(T19/L19,2),0) -> 0
A20: ="("&$O20&", "&$P20&"]" -> (4, 5] | B20: 13913831 | C20: 6300738315 | D20: =IFERROR(B20/SUM($B$15:$B$78),0) -> 0.013913831 | E20: =IFERROR(C20/B20/$B$3,0) -> 4.5283993 | G20: ="("&$O20&", "&$P20&"]" -> (4, 5] | H20: 0.72436592 | I20: =D20*H20 -> 0.010078705 | J20: =IFERROR(I20/SUM($I$15:$I$78),0) -> 0.010078705 | K20: =INT(J20*$B$2) -> 10078705 | L20: =IFERROR(K20/SUM($K$15:$K$79),0) -> 0.010001176 | M20: =L20*E20 -> 0.045289321 | O20: 4 | P20: 5 | Q20: =L20 -> 0.010001176 | R20: 0.008406 | U20: =IFERROR(ROUND(T20/L20,2),0) -> 0
A21: ="("&$O21&", "&$P21&"]" -> (5, 6] | B21: 10559309 | C21: 5858454015 | D21: =IFERROR(B21/SUM($B$15:$B$78),0) -> 0.010559309 | E21: =IFERROR(C21/B21/$B$3,0) -> 5.5481415 | G21: ="("&$O21&", "&$P21&"]" -> (5, 6] | H21: 0.39113289 | I21: =D21*H21 -> 0.004130093 | J21: =IFERROR(I21/SUM($I$15:$I$78),0) -> 0.004130093 | K21: =INT(J21*$B$2) -> 4130093 | L21: =IFERROR(K21/SUM($K$15:$K$79),0) -> 0.0040983231 | M21: =L21*E21 -> 0.022738076 | O21: 5 | P21: 6 | Q21: =L21 -> 0.0040983231 | R21: 0.006517 | U21: =IFERROR(ROUND(T21/L21,2),0) -> 0
A22: ="("&$O22&", "&$P22&"]" -> (6, 7] | B22: 8233456 | C22: 5364354110 | D22: =IFERROR(B22/SUM($B$15:$B$78),0) -> 0.008233456 | E22: =IFERROR(C22/B22/$B$3,0) -> 6.5153128 | G22: ="("&$O22&", "&$P22&"]" -> (6, 7] | H22: 0.42929615 | I22: =D22*H22 -> 0.003534591 | J22: =IFERROR(I22/SUM($I$15:$I$78),0) -> 0.003534591 | K22: =INT(J22*$B$2) -> 3534591 | L22: =IFERROR(K22/SUM($K$15:$K$79),0) -> 0.0035074018 | M22: =L22*E22 -> 0.02285182 | O22: 6 | P22: 7 | Q22: =L22 -> 0.0035074018 | R22: 0.003524 | U22: =IFERROR(ROUND(T22/L22,2),0) -> 0
A23: ="("&$O23&", "&$P23&"]" -> (7, 8] | B23: 7402250 | C23: 5582946445 | D23: =IFERROR(B23/SUM($B$15:$B$78),0) -> 0.00740225 | E23: =IFERROR(C23/B23/$B$3,0) -> 7.542229 | G23: ="("&$O23&", "&$P23&"]" -> (7, 8] | H23: 0.41521929 | I23: =D23*H23 -> 0.003073557 | J23: =IFERROR(I23/SUM($I$15:$I$78),0) -> 0.003073557 | K23: =INT(J23*$B$2) -> 3073557 | L23: =IFERROR(K23/SUM($K$15:$K$79),0) -> 0.0030499143 | M23: =L23*E23 -> 0.023003152 | O23: 7 | P23: 8 | Q23: =L23 -> 0.0030499143 | R23: 0.00397 | U23: =IFERROR(ROUND(T23/L23,2),0) -> 0
A24: ="("&$O24&", "&$P24&"]" -> (8, 9] | B24: 6145959 | C24: 5236519725 | D24: =IFERROR(B24/SUM($B$15:$B$78),0) -> 0.006145959 | E24: =IFERROR(C24/B24/$B$3,0) -> 8.5202647 | G24: ="("&$O24&", "&$P24&"]" -> (8, 9] | H24: 0.42612178 | I24: =D24*H24 -> 0.002618927 | J24: =IFERROR(I24/SUM($I$15:$I$78),0) -> 0.002618927 | K24: =INT(J24*$B$2) -> 2618927 | L24: =IFERROR(K24/SUM($K$15:$K$79),0) -> 0.0025987814 | M24: =L24*E24 -> 0.022142305 | O24: 8 | P24: 9 | Q24: =L24 -> 0.0025987814 | R24: 0.003227 | U24: =IFERROR(ROUND(T24/L24,2),0) -> 0
A25: ="("&$O25&", "&$P25&"]" -> (9, 10] | B25: 5019063 | C25: 4784548545 | D25: =IFERROR(B25/SUM($B$15:$B$78),0) -> 0.005019063 | E25: =IFERROR(C25/B25/$B$3,0) -> 9.5327525 | G25: ="("&$O25&", "&$P25&"]" -> (9, 10] | H25: 0.51286545 | I25: =D25*H25 -> 0.002574104 | J25: =IFERROR(I25/SUM($I$15:$I$78),0) -> 0.002574104 | K25: =INT(J25*$B$2) -> 2574104 | L25: =IFERROR(K25/SUM($K$15:$K$79),0) -> 0.0025543032 | M25: =L25*E25 -> 0.02434954 | O25: 9 | P25: 10 | Q25: =L25 -> 0.0025543032 | R25: 0.002102 | U25: =IFERROR(ROUND(T25/L25,2),0) -> 0
A26: ="("&$O26&", "&$P26&"]" -> (10, 15] | B26: 17254137 | C26: 21231801930 | D26: =IFERROR(B26/SUM($B$15:$B$78),0) -> 0.017254137 | E26: =IFERROR(C26/B26/$B$3,0) -> 12.30534 | G26: ="("&$O26&", "&$P26&"]" -> (10, 15] | H26: 0.55592812 | I26: =D26*H26 -> 0.00959206 | J26: =IFERROR(I26/SUM($I$15:$I$78),0) -> 0.00959206 | K26: =INT(J26*$B$2) -> 9592060 | L26: =IFERROR(K26/SUM($K$15:$K$79),0) -> 0.0095182749 | M26: =L26*E26 -> 0.11712561 | O26: 10 | P26: 15 | Q26: =L26 -> 0.0095182749 | R26: 0.006432 | U26: =IFERROR(ROUND(T26/L26,2),0) -> 0
... A78: ="("&$O78&", "&$P78&"]" -> (100000, 9999999] | B78: 0 | C78: 0 | D78: =IFERROR(B78/SUM($B$15:$B$78),0) -> 0 | E78: =IFERROR(C78/B78/$B$3,0) -> 0 | G78: ="("&$O78&", "&$P78&"]" -> (100000, 9999999] | H78: 0 | I78: =D78*H78 -> 0 | J78: =IFERROR(I78/SUM($I$15:$I$78),0) -> 0 | K78: =INT(J78*$B$2) -> 0 | L78: =IFERROR(K78/SUM($K$15:$K$79),0) -> 0 | M78: =L78*E78 -> 0 | O78: 100000 | P78: 9999999 | Q78: =L78 -> 0 | R78: 0 | U78: =IFERROR(ROUND(T78/L78,2),0) -> 0
A79: Free Game | B79: 8837552 | C79: 1910155240 | D79: =B79/B13 -> 0.008837552 | E79: =IFERROR(C79/B79/$B$3,0) -> 2.1614076 | G79: Free Game | H79: 0.87715897 | I79: =D79*H79 -> 0.007751938 | J79: =I79 -> 0.007751938 | K79: =INT(J79*$B$2) -> 7751938 | L79: =IFERROR(K79/SUM($K$15:$K$79),0) -> 0.0076923077 | M79: =L79*E79 -> 0.016626213
A82: Normal Bet | B82: Free Game | G82: Normal Bet | H82: Free Game | O82: Normal Bet | P82: Free Game
A84: Simulate | G84: Calculate
A85: Range | B85: Cnt | C85: Pay | D85: Hit Rate | E85: Avg. Multi. | G85: Range | H85: Fix Num | I85: Fix Rate | J85: Final Rate | K85: Weight | L85: Hit Rate | M85: Simulator RTP | O85: Lower | P85: Upper | Q85: 目前 | R85: 競品 | T85: 目前 | U85: 差異
A86: ="("&$O86&", "&$P86&"]" -> (-1, 0] | B86: 17757 | C86: 0 | D86: =IFERROR(B86/SUM($B$86:$B$149),0) -> 0.0019679053 | E86: =IFERROR(C86/B86/$B$3,0) -> 0 | G86: ="("&$O86&", "&$P86&"]" -> (-1, 0] | H86: 0 | I86: =D86*H86 -> 0 | J86: =IFERROR(I86/SUM($I$86:$I$149),0) -> 0 | K86: =INT(J86*$B$2) -> 0 | L86: =IFERROR(K86/SUM($K$86:$K$149),0) -> 0 | M86: =L86*E86 -> 0 | O86: -1 | P86: 0 | Q86: =L86 -> 0 | R86: 0.02069 | U86: =IFERROR(ROUND(T86/L86,2),0) -> 0
A87: ="("&$O87&", "&$P87&"]" -> (0, 1] | B87: 51825 | C87: 2951940 | D87: =IFERROR(B87/SUM($B$86:$B$149),0) -> 0.0057434641 | E87: =IFERROR(C87/B87/$B$3,0) -> 0.56959768 | G87: ="("&$O87&", "&$P87&"]" -> (0, 1] | H87: 0 | I87: =D87*H87 -> 0 | J87: =IFERROR(I87/SUM($I$86:$I$149),0) -> 0 | K87: =INT(J87*$B$2) -> 0 | L87: =IFERROR(K87/SUM($K$86:$K$149),0) -> 0 | M87: =L87*E87 -> 0 | O87: 0 | P87: 1 | Q87: =L87 -> 0 | R87: 0.006897 | U87: =IFERROR(ROUND(T87/L87,2),0) -> 0
A88: ="("&$O88&", "&$P88&"]" -> (1, 2] | B88: 50461 | C88: 7896650 | D88: =IFERROR(B88/SUM($B$86:$B$149),0) -> 0.0055922999 | E88: =IFERROR(C88/B88/$B$3,0) -> 1.5649016 | G88: ="("&$O88&", "&$P88&"]" -> (1, 2] | H88: 0 | I88: =D88*H88 -> 0 | J88: =IFERROR(I88/SUM($I$86:$I$149),0) -> 0 | K88: =INT(J88*$B$2) -> 0 | L88: =IFERROR(K88/SUM($K$86:$K$149),0) -> 0 | M88: =L88*E88 -> 0 | O88: 1 | P88: 2 | Q88: =L88 -> 0 | R88: 0.006897 | U88: =IFERROR(ROUND(T88/L88,2),0) -> 0
A89: ="("&$O89&", "&$P89&"]" -> (2, 3] | B89: 50095 | C89: 12863820 | D89: =IFERROR(B89/SUM($B$86:$B$149),0) -> 0.0055517383 | E89: =IFERROR(C89/B89/$B$3,0) -> 2.567885 | G89: ="("&$O89&", "&$P89&"]" -> (2, 3] | H89: 0 | I89: =D89*H89 -> 0 | J89: =IFERROR(I89/SUM($I$86:$I$149),0) -> 0 | K89: =INT(J89*$B$2) -> 0 | L89: =IFERROR(K89/SUM($K$86:$K$149),0) -> 0 | M89: =L89*E89 -> 0 | O89: 2 | P89: 3 | Q89: =L89 -> 0 | R89: 0.006897 | U89: =IFERROR(ROUND(T89/L89,2),0) -> 0
A90: ="("&$O90&", "&$P90&"]" -> (3, 4] | B90: 47166 | C90: 16819970 | D90: =IFERROR(B90/SUM($B$86:$B$149),0) -> 0.0052271342 | E90: =IFERROR(C90/B90/$B$3,0) -> 3.5661218 | G90: ="("&$O90&", "&$P90&"]" -> (3, 4] | H90: 0 | I90: =D90*H90 -> 0 | J90: =IFERROR(I90/SUM($I$86:$I$149),0) -> 0 | K90: =INT(J90*$B$2) -> 0 | L90: =IFERROR(K90/SUM($K$86:$K$149),0) -> 0 | M90: =L90*E90 -> 0 | O90: 3 | P90: 4 | Q90: =L90 -> 0 | R90: 0.006897 | U90: =IFERROR(ROUND(T90/L90,2),0) -> 0
A91: ="("&$O91&", "&$P91&"]" -> (4, 5] | B91: 47329 | C91: 21614690 | D91: =IFERROR(B91/SUM($B$86:$B$149),0) -> 0.0052451985 | E91: =IFERROR(C91/B91/$B$3,0) -> 4.5669019 | G91: ="("&$O91&", "&$P91&"]" -> (4, 5] | H91: 0 | I91: =D91*H91 -> 0 | J91: =IFERROR(I91/SUM($I$86:$I$149),0) -> 0 | K91: =INT(J91*$B$2) -> 0 | L91: =IFERROR(K91/SUM($K$86:$K$149),0) -> 0 | M91: =L91*E91 -> 0 | O91: 4 | P91: 5 | Q91: =L91 -> 0 | R91: 0.006897 | U91: =IFERROR(ROUND(T91/L91,2),0) -> 0
A92: ="("&$O92&", "&$P92&"]" -> (5, 6] | B92: 46826 | C92: 26050370 | D92: =IFERROR(B92/SUM($B$86:$B$149),0) -> 0.005189454 | E92: =IFERROR(C92/B92/$B$3,0) -> 5.5632277 | G92: ="("&$O92&", "&$P92&"]" -> (5, 6] | H92: 5.3936189 | I92: =D92*H92 -> 0.027989937 | J92: =IFERROR(I92/SUM($I$86:$I$149),0) -> 0.027989937 | K92: =INT(J92*$B$2) -> 27989937 | L92: =IFERROR(K92/SUM($K$86:$K$149),0) -> 0.027989937 | M92: =L92*E92 -> 0.15571439 | O92: 5 | P92: 6 | Q92: =L92 -> 0.027989937 | R92: 0.006897 | U92: =IFERROR(ROUND(T92/L92,2),0) -> 0
A93: ="("&$O93&", "&$P93&"]" -> (6, 7] | B93: 45678 | C93: 29965010 | D93: =IFERROR(B93/SUM($B$86:$B$149),0) -> 0.0050622278 | E93: =IFERROR(C93/B93/$B$3,0) -> 6.560053 | G93: ="("&$O93&", "&$P93&"]" -> (6, 7] | H93: 4.7978287 | I93: =D93*H93 -> 0.024287702 | J93: =IFERROR(I93/SUM($I$86:$I$149),0) -> 0.024287702 | K93: =INT(J93*$B$2) -> 24287702 | L93: =IFERROR(K93/SUM($K$86:$K$149),0) -> 0.024287702 | M93: =L93*E93 -> 0.15932861 | O93: 6 | P93: 7 | Q93: =L93 -> 0.024287702 | R93: 0.02069 | U93: =IFERROR(ROUND(T93/L93,2),0) -> 0
A94: ="("&$O94&", "&$P94&"]" -> (7, 8] | B94: 45247 | C94: 34232610 | D94: =IFERROR(B94/SUM($B$86:$B$149),0) -> 0.0050144626 | E94: =IFERROR(C94/B94/$B$3,0) -> 7.5657193 | G94: ="("&$O94&", "&$P94&"]" -> (7, 8] | H94: 5.2284375 | I94: =D94*H94 -> 0.026217804 | J94: =IFERROR(I94/SUM($I$86:$I$149),0) -> 0.026217804 | K94: =INT(J94*$B$2) -> 26217804 | L94: =IFERROR(K94/SUM($K$86:$K$149),0) -> 0.026217804 | M94: =L94*E94 -> 0.19835655 | O94: 7 | P94: 8 | Q94: =L94 -> 0.026217804 | R94: 0 | U94: =IFERROR(ROUND(T94/L94,2),0) -> 0
A95: ="("&$O95&", "&$P95&"]" -> (8, 9] | B95: 45343 | C95: 38819360 | D95: =IFERROR(B95/SUM($B$86:$B$149),0) -> 0.0050251017 | E95: =IFERROR(C95/B95/$B$3,0) -> 8.5612686 | G95: ="("&$O95&", "&$P95&"]" -> (8, 9] | H95: 5.0353236 | I95: =D95*H95 -> 0.025303013 | J95: =IFERROR(I95/SUM($I$86:$I$149),0) -> 0.025303013 | K95: =INT(J95*$B$2) -> 25303013 | L95: =IFERROR(K95/SUM($K$86:$K$149),0) -> 0.025303013 | M95: =L95*E95 -> 0.21662589 | O95: 8 | P95: 9 | Q95: =L95 -> 0.025303013 | R95: 0.006897 | U95: =IFERROR(ROUND(T95/L95,2),0) -> 0
A96: ="("&$O96&", "&$P96&"]" -> (9, 10] | B96: 45213 | C96: 43226590 | D96: =IFERROR(B96/SUM($B$86:$B$149),0) -> 0.0050106945 | E96: =IFERROR(C96/B96/$B$3,0) -> 9.5606551 | G96: ="("&$O96&", "&$P96&"]" -> (9, 10] | H96: 5.4427143 | I96: =D96*H96 -> 0.027271779 | J96: =IFERROR(I96/SUM($I$86:$I$149),0) -> 0.027271779 | K96: =INT(J96*$B$2) -> 27271779 | L96: =IFERROR(K96/SUM($K$86:$K$149),0) -> 0.027271779 | M96: =L96*E96 -> 0.26073607 | O96: 9 | P96: 10 | Q96: =L96 -> 0.027271779 | R96: 0 | U96: =IFERROR(ROUND(T96/L96,2),0) -> 0
A97: ="("&$O97&", "&$P97&"]" -> (10, 15] | B97: 221826 | C97: 278316430 | D97: =IFERROR(B97/SUM($B$86:$B$149),0) -> 0.024583689 | E97: =IFERROR(C97/B97/$B$3,0) -> 12.54661 | G97: ="("&$O97&", "&$P97&"]" -> (10, 15] | H97: 4.9458308 | I97: =D97*H97 -> 0.12158677 | J97: =IFERROR(I97/SUM($I$86:$I$149),0) -> 0.12158677 | K97: =INT(J97*$B$2) -> 121586766 | L97: =IFERROR(K97/SUM($K$86:$K$149),0) -> 0.12158677 | M97: =L97*E97 -> 1.5255017 | O97: 10 | P97: 15 | Q97: =L97 -> 0.12158677 | R97: 0.062069 | U97: =IFERROR(ROUND(T97/L97,2),0) -> 0
... A149: ="("&$O149&", "&$P149&"]" -> (100000, 9999999] | B149: 0 | C149: 0 | D149: =IFERROR(B149/SUM($B$86:$B$149),0) -> 0 | E149: =IFERROR(C149/B149/$B$3,0) -> 0 | G149: ="("&$O149&", "&$P149&"]" -> (100000, 9999999] | H149: 0 | I149: =D149*H149 -> 0 | J149: =IFERROR(I149/SUM($I$86:$I$149),0) -> 0 | K149: =INT(J149*$B$2) -> 0 | L149: =IFERROR(K149/SUM($K$86:$K$149),0) -> 0 | M149: =L149*E149 -> 0 | O149: 100000 | P149: 9999999 | Q149: =L149 -> 0 | R149: 0 | U149: =IFERROR(ROUND(T149/L149,2),0) -> 0

Sheet OP Jackpot
B2: Threshold | C2: 10000000000
B4: Bet Type | C4: SCR
B5: NB_Newbie | C5: 1,920,848,730
B6: NB | C6: 1,923,568,544
B7: BF | C7: 3,103,313,635
B8: SF
