Workbook

Sheet Overview
A2: Model: | B2: H0281
A3: Version: | B3: 2.0.0.36
A6: Base Bet | B6: Multiway
A7: 100 | B7: 32400
A10: Coin in | B10: Price(x) | C10: Total RTP | D10: Bet Type
A11: {=B11:B12*A7} -> 100 | B11: 1 | C11: =B17+B18 -> #DIV/0! | D11: Normal Bet
A12: 7500 | B12: 75 | C12: =B21+B22 -> #DIV/0! | D12: Buy Feature
A15: Total Pay Back Percentage includes the following adjustments.
A16: Bet Type | B16: Pay Back | C16: Hit% | D16: Pulls/Hit | E16: Description
A17: =D10 -> Bet Type | B17: =Detail!C7 -> #DIV/0! | C17: =1/D17 -> #DIV/0! | D17: =Detail!G7 -> #DIV/0! | E17: Base Game
B18: =Detail!D7 -> #DIV/0! | E18: Free Game
A20: Bet Type | B20: Pay Back | C20: Hit% | D20: Pulls/Hit | E20: Description
A21: =D12 -> Buy Feature | B21: =Detail!C8 -> #DIV/0! | C21: =1/D21 -> 1 | D21: 1 | E21: Base Game
B22: =Detail!D8 -> #DIV/0! | E22: Free Game

Sheet Description
B3: 7. BG 流程對應
B5: 7.1 BG 開局流程
B7: BG 每局的主要參數流程如下：
B8: 1. 先用 Table Selection Weight - Base Game 選出 BG table。
B9: 2. 再用該 strip 的 Symbol Weight R1~R5 抽停輪位置。
B10: 3. 依 Symbol ID R1~R5 生成初始盤面。
B11: 4. 盤面上的彩虹框會先判定是否觸發 Used Special Pool Weight。
B12: 5. 若命中特殊池，該彩虹框用 Multiple Selection Weight - Special Pool 抽倍率。
B13: 6. 若沒命中特殊池：
B14: - 且是 BG_Symbol (2) 則第 3 輪彩虹框用 Multiple Selection Weight - Reel3 Before Eliminate
B15: - 其他輪彩虹框用 Multiple Selection Weight - Before Eliminate
B16: 7. 再用 Eliminate Table Weight 決定本局是掉落表 A 或 B。
... B83: 5. BG_Symbol (3): 觸發 FG 用的表。得分少、C1 多，盡量不要有倍數百搭參與 → 控制進 FG 時的得分

Sheet Multiplier_Weight
A2: Range | B2: Weight_NB_BG_Newbie | C2: Weight_NB_FG_Newbie | D2: Weight_EB_BG_Newbie | E2: Weight_EB_FG_Newbie | F2: Weight_NB_BG | G2: Weight_NB_FG | H2: Weight_EB_BG | I2: Weight_EB_FG | J2: Weight_BF
A3: (-1, 0] | B3: 735407088 | C3: 74868190 | F3: 735407088 | G3: 74868190
A4: (0, 1] | B4: 147782558 | C4: 6515392 | F4: 147782558 | G4: 6515392
A5: (1, 2] | B5: 43518766 | C5: 6515392 | F5: 43518766 | G5: 6515392
A6: (2, 3] | B6: 20031201 | C6: 6515392 | F6: 20031201 | G6: 6515392
A7: (3, 4] | B7: 12344431 | C7: 6515392 | F7: 12344431 | G7: 6515392
A8: (4, 5] | B8: 8052715 | C8: 6515392 | F8: 8052715 | G8: 6515392
A9: (5, 6] | B9: 6243106 | C9: 6515392 | F9: 6243106 | G9: 6515392
A10: (6, 7] | B10: 3375894 | C10: 19545231 | F10: 3375894 | G10: 19545231
A11: (7, 8] | B11: 3803150 | C11: 0 | F11: 3803150 | G11: 0
A12: (8, 9] | B12: 3091377 | C12: 6515392 | F12: 3091377 | G12: 6515392
A13: (9, 10] | B13: 2013658 | C13: 0 | F13: 2013658 | G13: 0
A14: (10, 15] | B14: 6161678 | C14: 58634749 | F14: 6161678 | G14: 58634749
... A67: Free Game | B67: 3087503 | C67: 0 | F67: 3087503 | G67: 0

Sheet Detail
A2: Threshold | B2: 1000000000
A3: Coin in | B3: =Overview!A7 -> 100
C5: RTP
B6: Bet | C6: Base Game | D6: Free Game | E6: Total | F6: Hit Rate | G6: FG Period | H6: Avg Multi | I6: BG | J6: FG
A7: Normal Bet | B7: {=Overview!B11:B12} -> 1 | C7: =SUM(M15:M79) -> #DIV/0! | D7: =SUM(_xlfn.ANCHORARRAY(M86))*F7 -> #DIV/0! | E7: =SUM(C7:D7) -> #DIV/0! | F7: =L79 -> #DIV/0! | G7: =1/F7 -> #DIV/0! | H7: =D7*G7 -> #DIV/0! | I7: {=LOOKUP(2,1/(K15:K78<>0),P15:P78)} -> #N/A | J7: {=LOOKUP(2,1/(_xlfn.ANCHORARRAY(K86)<>0),P15:P78)} -> #N/A
A8: Buy Feature | B8: 75 | C8: =M156/B8 -> #DIV/0! | D8: =SUM(_xlfn.ANCHORARRAY(M163))/B8 -> #DIV/0! | E8: =SUM(C8:D8) -> #DIV/0! | F8: =D156 -> 1 | G8: =1/F8 -> 1 | H8: =D8*G8*B8 -> #DIV/0! | J8: {=LOOKUP(2,1/(_xlfn.ANCHORARRAY(K163)<>0),P15:P78)} -> #N/A
A11: Normal Bet | B11: Base Game | G11: Normal Bet | H11: Base Game | O11: Normal Bet | P11: Base Game
A13: Simulate | B13: 1000000000 | G13: Calculate
A14: Range | B14: Cnt | C14: Pay | D14: Hit Rate | E14: Avg. Multi. | G14: Range | H14: Fix Num | I14: Fix Rate | J14: Final Rate | K14: Weight | L14: Hit Rate | M14: Simulator RTP | O14: Lower | P14: Upper | Q14: 目前 | R14: 競品 | T14: 目前 | U14: 差異
A15: ="("&$O15&", "&$P15&"]" -> (-1, 0] | B15: 624764779 | C15: 0 | D15: {=_xlfn.LET(_xlpm.x, B15:B78, _xlpm.x/SUM(_xlpm.x))} -> #DIV/0! | E15: {=_xlfn.LET(_xlpm.x, C15:C79/B15:B79/B3, IF(ISERR(_xlpm.x), 0, _xlpm.x))} -> 0 | G15: ="("&$O15&", "&$P15&"]" -> (-1, 0] | H15: 1.1770943 | I15: {=D15:D79*H15:H79} -> #DIV/0! | J15: {=I15:I78/SUM(_xlfn.ANCHORARRAY(I15))} -> #DIV/0! | K15: {=INT(J15:J79*$B$2)} -> #DIV/0! | L15: {=_xlfn.LET(_xlpm.x, K15:K79, _xlpm.x/SUM(_xlpm.x))} -> #DIV/0! | M15: {=L15:L79*E15:E79} -> #DIV/0! | O15: -1 | P15: 0 | Q15: {=L15:L78} -> #DIV/0! | R15: 0.723799 | U15: {=_xlfn.LET(_xlpm.x, T15:T78/L15:L78, IF(ISERR(_xlpm.x), 0, ROUND(_xlpm.x,2)))} -> 0
A16: ="("&$O16&", "&$P16&"]" -> (0, 1] | B16: 143254516 | C16: 6213627750 | D16: #DIV/0! | E16: 0 | G16: ="("&$O16&", "&$P16&"]" -> (0, 1] | H16: 1.0316084 | I16: #DIV/0! | J16: #DIV/0! | K16: #DIV/0! | L16: #DIV/0! | M16: #DIV/0! | O16: 0 | P16: 1 | Q16: #DIV/0! | R16: 0.154266 | U16: 0
A17: ="("&$O17&", "&$P17&"]" -> (1, 2] | B17: 54941394 | C17: 8271310400 | D17: #DIV/0! | E17: 0 | G17: ="("&$O17&", "&$P17&"]" -> (1, 2] | H17: 0.79209433 | I17: #DIV/0! | J17: #DIV/0! | K17: #DIV/0! | L17: #DIV/0! | M17: #DIV/0! | O17: 1 | P17: 2 | Q17: #DIV/0! | R17: 0.045428 | U17: 0
A18: ="("&$O18&", "&$P18&"]" -> (2, 3] | B18: 33052702 | C18: 8367423885 | D18: #DIV/0! | E18: 0 | G18: ="("&$O18&", "&$P18&"]" -> (2, 3] | H18: 0.60603823 | I18: #DIV/0! | J18: #DIV/0! | K18: #DIV/0! | L18: #DIV/0! | M18: #DIV/0! | O18: 2 | P18: 3 | Q18: #DIV/0! | R18: 0.02091 | U18: 0
A19: ="("&$O19&", "&$P19&"]" -> (3, 4] | B19: 22868741 | C19: 8068853980 | D19: #DIV/0! | E19: 0 | G19: ="("&$O19&", "&$P19&"]" -> (3, 4] | H19: 0.53979497 | I19: #DIV/0! | J19: #DIV/0! | K19: #DIV/0! | L19: #DIV/0! | M19: #DIV/0! | O19: 3 | P19: 4 | Q19: #DIV/0! | R19: 0.012886 | U19: 0
A20: ="("&$O20&", "&$P20&"]" -> (4, 5] | B20: 16964682 | C20: 7689266290 | D20: #DIV/0! | E20: 0 | G20: ="("&$O20&", "&$P20&"]" -> (4, 5] | H20: 0.47467529 | I20: #DIV/0! | J20: #DIV/0! | K20: #DIV/0! | L20: #DIV/0! | M20: #DIV/0! | O20: 4 | P20: 5 | Q20: #DIV/0! | R20: 0.008406 | U20: 0
A21: ="("&$O21&", "&$P21&"]" -> (5, 6] | B21: 13467081 | C21: 7477223845 | D21: #DIV/0! | E21: 0 | G21: ="("&$O21&", "&$P21&"]" -> (5, 6] | H21: 0.46358269 | I21: #DIV/0! | J21: #DIV/0! | K21: #DIV/0! | L21: #DIV/0! | M21: #DIV/0! | O21: 5 | P21: 6 | Q21: #DIV/0! | R21: 0.006517 | U21: 0
A22: ="("&$O22&", "&$P22&"]" -> (6, 7] | B22: 10632034 | C22: 6936975045 | D22: #DIV/0! | E22: 0 | G22: ="("&$O22&", "&$P22&"]" -> (6, 7] | H22: 0.31752104 | I22: #DIV/0! | J22: #DIV/0! | K22: #DIV/0! | L22: #DIV/0! | M22: #DIV/0! | O22: 6 | P22: 7 | Q22: #DIV/0! | R22: 0.003524 | U22: 0
A23: ="("&$O23&", "&$P23&"]" -> (7, 8] | B23: 8953486 | C23: 6744195935 | D23: #DIV/0! | E23: 0 | G23: ="("&$O23&", "&$P23&"]" -> (7, 8] | H23: 0.42476753 | I23: #DIV/0! | J23: #DIV/0! | K23: #DIV/0! | L23: #DIV/0! | M23: #DIV/0! | O23: 7 | P23: 8 | Q23: #DIV/0! | R23: 0.00397 | U23: 0
A24: ="("&$O24&", "&$P24&"]" -> (8, 9] | B24: 7534128 | C24: 6443473090 | D24: #DIV/0! | E24: 0 | G24: ="("&$O24&", "&$P24&"]" -> (8, 9] | H24: 0.41031645 | I24: #DIV/0! | J24: #DIV/0! | K24: #DIV/0! | L24: #DIV/0! | M24: #DIV/0! | O24: 8 | P24: 9 | Q24: #DIV/0! | R24: 0.003227 | U24: 0
A25: ="("&$O25&", "&$P25&"]" -> (9, 10] | B25: 6231775 | C25: 5943691225 | D25: #DIV/0! | E25: 0 | G25: ="("&$O25&", "&$P25&"]" -> (9, 10] | H25: 0.32312749 | I25: #DIV/0! | J25: #DIV/0! | K25: #DIV/0! | L25: #DIV/0! | M25: #DIV/0! | O25: 9 | P25: 10 | Q25: #DIV/0! | R25: 0.002102 | U25: 0
A26: ="("&$O26&", "&$P26&"]" -> (10, 15] | B26: 20720821 | C26: 25446656890 | D26: #DIV/0! | E26: 0 | G26: ="("&$O26&", "&$P26&"]" -> (10, 15] | H26: 0.2973665 | I26: #DIV/0! | J26: #DIV/0! | K26: #DIV/0! | L26: #DIV/0! | M26: #DIV/0! | O26: 10 | P26: 15 | Q26: #DIV/0! | R26: 0.006432 | U26: 0
A27: ="("&$O27&", "&$P27&"]" -> (15, 20] | B27: 11152939 | C27: 19336495675 | D27: #DIV/0! | E27: 0 | G27: ="("&$O27&", "&$P27&"]" -> (15, 20] | H27: 0.24247921 | I27: #DIV/0! | J27: #DIV/0! | K27: #DIV/0! | L27: #DIV/0! | M27: #DIV/0! | O27: 15 | P27: 20 | Q27: #DIV/0! | R27: 0.002823 | U27: 0
... A78: ="("&$O78&", "&$P78&"]" -> (100000, 9999999] | B78: 0 | C78: 0 | D78: #DIV/0! | E78: 0 | G78: ="("&$O78&", "&$P78&"]" -> (100000, 9999999] | H78: 1 | I78: #DIV/0! | J78: #DIV/0! | K78: #DIV/0! | L78: #DIV/0! | M78: #DIV/0! | O78: 100000 | P78: 9999999 | Q78: #DIV/0! | R78: 0 | U78: 0
A79: Free Game | B79: 85378410 | D79: =B79/B13 -> 0 | E79: 0 | G79: Free Game | H79: 0.036162577 | I79: 0 | J79: =I79 -> 0 | K79: 0 | L79: #DIV/0! | M79: #DIV/0!
A82: Normal Bet | B82: Free Game | G82: Normal Bet | H82: Free Game | O82: Normal Bet | P82: Free Game
A84: Simulate | G84: Calculate
A85: Range | B85: Cnt | C85: Pay | D85: Hit Rate | E85: Avg. Multi. | G85: Range | H85: Fix Num | I85: Fix Rate | J85: Final Rate | K85: Weight | L85: Hit Rate | M85: Simulator RTP | O85: Lower | P85: Upper | Q85: 目前 | R85: 競品 | T85: 目前 | U85: 差異
A86: ="("&$O86&", "&$P86&"]" -> (-1, 0] | B86: 25733 | C86: 0 | D86: {=_xlfn.LET(_xlpm.x, B86:B149, _xlpm.x/SUM(_xlpm.x))} -> #DIV/0! | E86: {=_xlfn.LET(_xlpm.x, C86:C149/B86:B149/B3, IF(ISERR(_xlpm.x), 0, _xlpm.x))} -> 0 | G86: ="("&$O86&", "&$P86&"]" -> (-1, 0] | H86: 248.40193 | I86: {=_xlfn.ANCHORARRAY(D86)*H86:H149} -> #DIV/0! | J86: {=I86:I149/SUM(_xlfn.ANCHORARRAY(I86))} -> #DIV/0! | K86: {=INT(_xlfn.ANCHORARRAY(J86)*$B$2)} -> #DIV/0! | L86: {=_xlfn.LET(_xlpm.x, K86:K149, _xlpm.x/SUM(_xlpm.x))} -> #DIV/0! | M86: {=L86:L149*_xlfn.ANCHORARRAY(E86)} -> #DIV/0! | O86: -1 | P86: 0 | Q86: {=_xlfn.ANCHORARRAY(L86)} -> #DIV/0! | R86: 0.02069 | U86: {=_xlfn.LET(_xlpm.x, T86:T149/L86:L149, IF(ISERR(_xlpm.x), 0, ROUND(_xlpm.x,2)))} -> 0
A87: ="("&$O87&", "&$P87&"]" -> (0, 1] | B87: 10103 | C87: 620285 | D87: #DIV/0! | E87: 0 | G87: ="("&$O87&", "&$P87&"]" -> (0, 1] | H87: 55.06026 | I87: #DIV/0! | J87: #DIV/0! | K87: #DIV/0! | L87: #DIV/0! | M87: #DIV/0! | O87: 0 | P87: 1 | Q87: #DIV/0! | R87: 0.006897 | U87: 0
A88: ="("&$O88&", "&$P88&"]" -> (1, 2] | B88: 12745 | C88: 1986100 | D88: #DIV/0! | E88: 0 | G88: ="("&$O88&", "&$P88&"]" -> (1, 2] | H88: 43.646434 | I88: #DIV/0! | J88: #DIV/0! | K88: #DIV/0! | L88: #DIV/0! | M88: #DIV/0! | O88: 1 | P88: 2 | Q88: #DIV/0! | R88: 0.006897 | U88: 0
A89: ="("&$O89&", "&$P89&"]" -> (2, 3] | B89: 12974 | C89: 3346690 | D89: #DIV/0! | E89: 0 | G89: ="("&$O89&", "&$P89&"]" -> (2, 3] | H89: 42.876045 | I89: #DIV/0! | J89: #DIV/0! | K89: #DIV/0! | L89: #DIV/0! | M89: #DIV/0! | O89: 2 | P89: 3 | Q89: #DIV/0! | R89: 0.006897 | U89: 0
A90: ="("&$O90&", "&$P90&"]" -> (3, 4] | B90: 13264 | C90: 4759360 | D90: #DIV/0! | E90: 0 | G90: ="("&$O90&", "&$P90&"]" -> (3, 4] | H90: 41.938616 | I90: #DIV/0! | J90: #DIV/0! | K90: #DIV/0! | L90: #DIV/0! | M90: #DIV/0! | O90: 3 | P90: 4 | Q90: #DIV/0! | R90: 0.006897 | U90: 0
A91: ="("&$O91&", "&$P91&"]" -> (4, 5] | B91: 13259 | C91: 6071400 | D91: #DIV/0! | E91: 0 | G91: ="("&$O91&", "&$P91&"]" -> (4, 5] | H91: 41.954431 | I91: #DIV/0! | J91: #DIV/0! | K91: #DIV/0! | L91: #DIV/0! | M91: #DIV/0! | O91: 4 | P91: 5 | Q91: #DIV/0! | R91: 0.006897 | U91: 0
A92: ="("&$O92&", "&$P92&"]" -> (5, 6] | B92: 14611 | C92: 8170270 | D92: #DIV/0! | E92: 0 | G92: ="("&$O92&", "&$P92&"]" -> (5, 6] | H92: 38.072261 | I92: #DIV/0! | J92: #DIV/0! | K92: #DIV/0! | L92: #DIV/0! | M92: #DIV/0! | O92: 5 | P92: 6 | Q92: #DIV/0! | R92: 0.006897 | U92: 0
A93: ="("&$O93&", "&$P93&"]" -> (6, 7] | B93: 13100 | C93: 8615115 | D93: #DIV/0! | E93: 0 | G93: ="("&$O93&", "&$P93&"]" -> (6, 7] | H93: 127.38479 | I93: #DIV/0! | J93: #DIV/0! | K93: #DIV/0! | L93: #DIV/0! | M93: #DIV/0! | O93: 6 | P93: 7 | Q93: #DIV/0! | R93: 0.02069 | U93: 0
A94: ="("&$O94&", "&$P94&"]" -> (7, 8] | B94: 14716 | C94: 11128800 | D94: #DIV/0! | E94: 0 | G94: ="("&$O94&", "&$P94&"]" -> (7, 8] | H94: 0 | I94: #DIV/0! | J94: #DIV/0! | K94: #DIV/0! | L94: #DIV/0! | M94: #DIV/0! | O94: 7 | P94: 8 | Q94: #DIV/0! | R94: 0 | U94: 0
A95: ="("&$O95&", "&$P95&"]" -> (8, 9] | B95: 14381 | C95: 12340410 | D95: #DIV/0! | E95: 0 | G95: ="("&$O95&", "&$P95&"]" -> (8, 9] | H95: 38.681163 | I95: #DIV/0! | J95: #DIV/0! | K95: #DIV/0! | L95: #DIV/0! | M95: #DIV/0! | O95: 8 | P95: 9 | Q95: #DIV/0! | R95: 0.006897 | U95: 0
A96: ="("&$O96&", "&$P96&"]" -> (9, 10] | B96: 14299 | C96: 13696660 | D96: #DIV/0! | E96: 0 | G96: ="("&$O96&", "&$P96&"]" -> (9, 10] | H96: 0 | I96: #DIV/0! | J96: #DIV/0! | K96: #DIV/0! | L96: #DIV/0! | M96: #DIV/0! | O96: 9 | P96: 10 | Q96: #DIV/0! | R96: 0 | U96: 0
A97: ="("&$O97&", "&$P97&"]" -> (10, 15] | B97: 73611 | C97: 92606940 | D97: #DIV/0! | E97: 0 | G97: ="("&$O97&", "&$P97&"]" -> (10, 15] | H97: 68.008064 | I97: #DIV/0! | J97: #DIV/0! | K97: #DIV/0! | L97: #DIV/0! | M97: #DIV/0! | O97: 10 | P97: 15 | Q97: #DIV/0! | R97: 0.062069 | U97: 0
A98: ="("&$O98&", "&$P98&"]" -> (15, 20] | B98: 74130 | C98: 130221780 | D98: #DIV/0! | E98: 0 | G98: ="("&$O98&", "&$P98&"]" -> (15, 20] | H98: 30.013947 | I98: #DIV/0! | J98: #DIV/0! | K98: #DIV/0! | L98: #DIV/0! | M98: #DIV/0! | O98: 15 | P98: 20 | Q98: #DIV/0! | R98: 0.027586 | U98: 0
...

Sheet OP Jackpot
B2: Threshold | C2: 10000000000
B4: Bet Type | C4: SCR
B5: NB_Newbie
B6: EB_Newbie
B7: NB
B8: EB
B9: BF
