Workbook

Sheet Overview
A2: Model: | B2: H028192A
A3: Version: | B3: 1.0.0.5
A6: Base Bet | B6: Multiway
A7: 100 | B7: =PRODUCT(B26:G26) -> 32400
A10: Coin in | B10: Price(x) | C10: Total RTP | D10: Bet Type
A11: {=B11:B12*A7} -> 100 | B11: 1 | D11: Normal Bet
A12: 7500 | B12: 75 | D12: Buy Feature
A15: Total Pay Back Percentage includes the following adjustments.
A16: Bet Type | B16: Pay Back | C16: Hit% | D16: Pulls/Hit | E16: Description
A17: =D10 -> Bet Type | C17: =1/D17 -> #DIV/0! | E17: Base Game
E18: Free Game
A20: Bet Type | B20: Pay Back | C20: Hit% | D20: Pulls/Hit | E20: Description
A21: =D12 -> Buy Feature | C21: =1/D21 -> 1 | D21: 1 | E21: Base Game
E22: Free Game
A25: Reel # | B25: 1 | C25: 2 | D25: 3 | E25: 4 | F25: 5 | G25: 6
A26: Visible Window Size | B26: 5 | C26: 6 | D26: 6 | E26: 6 | F26: 6 | G26: 5
A29: Free Spins Setting
A30: C1 Num | B30: Add Free Spin
A31: 4 | B31: 8
A32: 5 | B32: 10
A33: 6 | B33: 12
A34: 7 | B34: 14
A35: 8 | B35: 16
A36: … | B36: …
A37: The maximum of free spins is 50.
A40: Pay Table： | B40: ="All wins show for "&A7&" credit bet." -> All wins show for 100 credit bet.
A41: Symbol | B41: Description | C41: 3 | D41: 4 | E41: 5 | F41: 6 | G41: Id
A42: WW | B42: Wild | C42: 0 | D42: 0 | E42: 0 | F42: 0 | G42: 0
A43: C1 | B43: Scatter | C43: 0 | D43: 0 | E43: 0 | F43: 0 | G43: 1
A44: M1 | B44: M1 | C44: 150 | D44: 200 | E44: 250 | F44: 400 | G44: 2
A45: M2 | B45: M2 | C45: 100 | D45: 125 | E45: 150 | F45: 250 | G45: 3
A46: M3 | B46: M3 | C46: 50 | D46: 125 | E46: 150 | F46: 200 | G46: 4
A47: M4 | B47: M4 | C47: 40 | D47: 75 | E47: 100 | F47: 150 | G47: 5
A48: M5 | B48: M5 | C48: 30 | D48: 50 | E48: 60 | F48: 75 | G48: 6
A49: M6 | B49: M6 | C49: 30 | D49: 50 | E49: 60 | F49: 75 | G49: 7
A50: A | B50: A | C50: 20 | D50: 30 | E50: 40 | F50: 50 | G50: 8
A51: K | B51: K | C51: 20 | D51: 30 | E51: 40 | F51: 50 | G51: 9
A52: Q | B52: Q | C52: 5 | D52: 10 | E52: 15 | F52: 20 | G52: 10
A53: J | B53: J | C53: 5 | D53: 10 | E53: 15 | F53: 20 | G53: 11
... A67: GM | B67: Golden Mystery | C67: 0 | D67: 0 | E67: 0 | F67: 0 | G67: 25

Sheet Description
B2: 1. 初始盤面(Combo 0)依照BaseGam權種Weights抽選BaseGameSymbol (Free Game Symbol) 中的轉輪表。 Table Selection Weight - Base Game / Free Game
B4: 2. 使用Mega way參數決定R1-R6的長度形狀然後利用BG Reel Weight / FG Reel Weight 抽選輪帶表(例:Mega way[1,3,1]->[M1,A,K])
B6: 3. MY符號透過MY Weight決定MY,GM轉換符號，一次Spin只需抽選一次
B8: 4. 初始盤面抽選完後使用Post Scatter決定要替換幾顆C1到版面上，替後N顆需要從7條轉輪抽選N條每條替換1顆，被替換的輪帶會從最短長度的符號進行替換，若有重複的最短長度符號則隨機抽選其中一個(例 : [1,3,1]->[M1,A,K]->[M1,A,C1])
B10: 5.FreeGame額外產生的場次透過Retrigger抽選 Table Selection Weight - Retrigger
B12: 6. Buy Feature透過Base Game Symbol_FB抽選

Sheet Parameter
B3: Table Selection Weight - Base Game (Weight/Total)
B4: Worksheet Name | C4: Weight
B5: BG_Symbol | C5: 1500
B6: BG_Symbol (2) | C6: 1200
B9: Table Selection Weight - Free Game (Weight/Total)
B10: Worksheet Name | C10: Weight
B11: FG_Symbol | C11: 800
B12: FG_Symbol (2) | C12: 300
B13: FG_Symbol (3) | C13: 400
B16: Table Selection Weight - Retrigger (Weight/Total)
B17: Worksheet Name | C17: Weight
B18: FG_Symbol | C18: 400
B19: FG_Symbol (2) | C19: 0
B20: FG_Symbol (3) | C20: 800

Sheet Multiplier_Weight
B2: A | C2: Newbie | D2: Newbie | E2: Oldhand | F2: Oldhand | G2: Oldhand
B3: Range | C3: Weight_NB_BG | D3: Weight_NB_FG | E3: Weight_NB_BG | F3: Weight_NB_FG | G3: Weight_BF_FG
B4: (-1, 0] | C4: {=_xlfn.ANCHORARRAY(Multiplier_Weight_Newbie!L15)} -> 691253713 | D4: {=_xlfn.ANCHORARRAY(Multiplier_Weight_Newbie!L87)} -> 0 | E4: {=_xlfn.ANCHORARRAY(Multiplier_Weight_Oldhand!L15)} -> 706833174 | F4: {=_xlfn.ANCHORARRAY(Multiplier_Weight_Oldhand!L87)} -> 0 | G4: {=_xlfn.ANCHORARRAY(Multiplier_Weight_Oldhand!L157)} -> 0
B5: (0, 1] | C5: 183427816 | D5: 0 | E5: 197850114 | F5: 0 | G5: 0
B6: (1, 2] | C6: 45729236 | D6: 0 | E6: 36993576 | F6: 0 | G6: 0
B7: (2, 3] | C7: 18697578 | D7: 0 | E7: 12449200 | F7: 0 | G7: 0
B8: (3, 4] | C8: 13283710 | D8: 0 | E8: 7164081 | F8: 0 | G8: 0
B9: (4, 5] | C9: 9169344 | D9: 0 | E9: 4945149 | F9: 0 | G9: 0
B10: (5, 6] | C10: 6408899 | D10: 0 | E10: 3456404 | F10: 0 | G10: 0
B11: (6, 7] | C11: 6852265 | D11: 0 | E11: 2463678 | F11: 0 | G11: 0
B12: (7, 8] | C12: 2551314 | D12: 0 | E12: 1289960 | F12: 0 | G12: 0
B13: (8, 9] | C13: 2102920 | D13: 0 | E13: 1046892 | F13: 0 | G13: 0
B14: (9, 10] | C14: 1719045 | D14: 0 | E14: 855788 | F14: 0 | G14: 0
B15: (10, 15] | C15: 1547168 | D15: 0 | E15: 2086021 | F15: 0 | G15: 0
B16: (15, 20] | C16: 2989200 | D16: 0 | E16: 3761602 | F16: 0 | G16: 93302689
... B67: (100000, 9999999] | C67: 0 | D67: 0 | E67: 0 | F67: 0 | G67: 0
B68: Free Game | C68: 6853371 | E68: 6396479

Sheet Multiplier_Weight_Newbie
A2: Threshold | B2: 1000000000
A3: Coin in | B3: =Overview!A7 -> 100
C5: RTP
B6: Bet | C6: Base Game | D6: Free Game | E6: Total | F6: Hit Rate | G6: FG Period | H6: Avg Multi | I6: BG | J6: FG
A7: Normal Bet | B7: {=Overview!B11:B11} -> 1 | C7: =SUM(N15:N79) -> 0.48883559 | D7: =SUM(_xlfn.ANCHORARRAY(N87))*F7 -> 0.4462816 | E7: =SUM(C7:D7) -> 0.93511719 | F7: =M79 -> 0.0069045643 | G7: =1/F7 -> 144.83173 | H7: =D7*G7 -> 64.635737 | I7: {=LOOKUP(2,1/(L15:L78<>0),B15:B78)} -> 20 | J7: {=LOOKUP(2,1/(_xlfn.ANCHORARRAY(L87)<>0),B15:B78)} -> 140
A11: Base Game
A13: Simulator | B13: 1000000000 | H13: Calculate
A14: Lower | B14: Upper | C14: Cnt | D14: Pay | E14: Hit Rate | F14: Avg. Multi. | H14: Range | I14: Fix Num | J14: Fix Rate | K14: Final Rate | L14: Weight | M14: Hit Rate | N14: Simulator RTP
A15: -1 | B15: 0 | C15: 65390071 | D15: 0 | E15: {=_xlfn.LET(_xlpm.x, C15:C78, _xlpm.x/SUM(_xlpm.x))} -> 0.66407191 | F15: {=_xlfn.LET(_xlpm.x, D15:D80/C15:C80/B3, IF(ISERR(_xlpm.x), 0, _xlpm.x))} -> 0 | G15: 1e-06 | H15: ="("&$A15&", "&$B15&"]" -> (-1, 0] | I15: 0.5 | J15: {=E15:E79*I15:I79} -> 0.33203595 | K15: {=J15:J78/SUM(_xlfn.ANCHORARRAY(J15))} -> 0.69125371 | L15: {=INT(K15:K79*$B$2)} -> 691253713 | M15: {=_xlfn.LET(_xlpm.x, L15:L79, _xlpm.x/SUM(_xlpm.x))} -> 0.69641724 | N15: {=M15:M79*F15:F79} -> 0
A16: 0 | B16: 1 | C16: 17351600 | D16: 712785570 | E16: 0.17621498 | F16: 0.41078954 | G16: 0 | H16: ="("&$A16&", "&$B16&"]" -> (0, 1] | I16: 0.5 | J16: 0.08810749 | K16: 0.18342782 | L16: 183427816 | M16: 0.18479799 | N16: 0.075913079
A17: 1 | B17: 2 | C17: 5407273 | D17: 802609240 | E17: 0.054913812 | F17: 1.4843143 | G17: =1+G16*G15 -> 1 | H17: ="("&$A17&", "&$B17&"]" -> (1, 2] | I17: 0.4 | J17: 0.021965525 | K17: 0.045729237 | L17: 45729236 | M17: 0.046070824 | N17: 0.068383582
A18: 2 | B18: 3 | C18: 2729510 | D18: 691016145 | E18: 0.027719666 | F18: 2.5316491 | H18: ="("&$A18&", "&$B18&"]" -> (2, 3] | I18: 0.324 | J18: 0.0089811717 | K18: 0.018697578 | L18: 18697578 | M18: 0.018837245 | N18: 0.047689294
A19: 3 | B19: 4 | C19: 1570738 | D19: 556155520 | E19: 0.015951703 | F19: 3.5407275 | H19: ="("&$A19&", "&$B19&"]" -> (3, 4] | I19: 0.4 | J19: 0.0063806811 | K19: 0.013283711 | L19: 13283710 | M19: 0.013382937 | N19: 0.047385332
A20: 4 | B20: 5 | C20: 1084233 | D20: 494968815 | E20: 0.011010979 | F20: 4.5651517 | H20: ="("&$A20&", "&$B20&"]" -> (4, 5] | I20: 0.4 | J20: 0.0044043915 | K20: 0.0091693442 | L20: 9169344 | M20: 0.0092378372 | N20: 0.042172128
A21: 5 | B21: 6 | C21: 757823 | D21: 422988420 | E21: 0.0076961067 | F21: 5.5816255 | G21: 1.79 | H21: ="("&$A21&", "&$B21&"]" -> (5, 6] | I21: 0.4 | J21: 0.0030784427 | K21: 0.0064088991 | L21: 6408899 | M21: 0.0064567722 | N21: 0.036039285
A22: 6 | B22: 7 | C22: 540166 | D22: 351987175 | E22: 0.0054856809 | F22: 6.5162779 | G22: 1.24 | H22: ="("&$A22&", "&$B22&"]" -> (6, 7] | I22: 0.6 | J22: 0.0032914086 | K22: 0.0068522651 | L22: 6852265 | M22: 0.0069034501 | N22: 0.044984799
A23: 7 | B23: 8 | C23: 471377 | D23: 355806505 | E23: 0.004787091 | F23: 7.5482364 | G23: 1.02 | H23: ="("&$A23&", "&$B23&"]" -> (7, 8] | I23: 0.256 | J23: 0.0012254953 | K23: 0.0025513146 | L23: 2551314 | M23: 0.0025703718 | N23: 0.019401774
A24: 8 | B24: 9 | C24: 382555 | D24: 329270680 | E24: 0.0038850551 | F24: 8.6071462 | G24: 1.26 | H24: ="("&$A24&", "&$B24&"]" -> (8, 9] | I24: 0.26 | J24: 0.0010101143 | K24: 0.0021029207 | L24: 2102920 | M24: 0.0021186284 | N24: 0.018235344
A25: 9 | B25: 10 | C25: 312722 | D25: 299181170 | E25: 0.0031758628 | F25: 9.567001 | G25: 1.21 | H25: ="("&$A25&", "&$B25&"]" -> (9, 10] | I25: 0.26 | J25: 0.00082572433 | K25: 0.0017190458 | L25: 1719045 | M25: 0.0017318859 | N25: 0.016568955
A26: 10 | B26: 15 | C26: 914728 | D26: 1123098055 | E26: 0.0092895628 | F26: 12.277946 | G26: 0.48 | H26: ="("&$A26&", "&$B26&"]" -> (10, 15] | I26: 0.08 | J26: 0.00074316502 | K26: 0.0015471685 | L26: 1547168 | M26: 0.001558725 | N26: 0.019137941
A27: 15 | B27: 20 | C27: 471279 | D27: 819221540 | E27: 0.0047860958 | F27: 17.382942 | G27: 1.13 | H27: ="("&$A27&", "&$B27&"]" -> (15, 20] | I27: 0.3 | J27: 0.0014358287 | K27: 0.0029892002 | L27: 2989200 | M27: 0.0030115287 | N27: 0.052349229
A28: 20 | B28: 25 | C28: 278340 | D28: 623999005 | E28: 0.0028266948 | F28: 22.418589 | G28: 0.54 | H28: ="("&$A28&", "&$B28&"]" -> (20, 25] | I28: 0 | J28: 0 | K28: 0 | L28: 0 | M28: 0 | N28: 0
A29: 25 | B29: 30 | C29: 187951 | D29: 515280570 | E29: 0.0019087451 | F29: 27.415687 | G29: 0.2 | H29: ="("&$A29&", "&$B29&"]" -> (25, 30] | I29: 0 | J29: 0 | K29: 0 | L29: 0 | M29: 0 | N29: 0
A30: 30 | B30: 35 | C30: 123190 | D30: 399019550 | E30: 0.0012510618 | F30: 32.39058 | G30: 0.22 | H30: ="("&$A30&", "&$B30&"]" -> (30, 35] | I30: 0 | J30: 0 | K30: 0 | L30: 0 | M30: 0 | N30: 0
A31: 35 | B31: 40 | C31: 97176 | D31: 363839415 | E31: 0.00098687539 | F31: 37.441283 | G31: 0.33 | H31: ="("&$A31&", "&$B31&"]" -> (35, 40] | I31: 0 | J31: 0 | K31: 0 | L31: 0 | M31: 0 | N31: 0
A32: 40 | B32: 45 | C32: 69470 | D32: 294779905 | E32: 0.00070550582 | F32: 42.432691 | G32: 0.16 | H32: ="("&$A32&", "&$B32&"]" -> (40, 45] | I32: 0 | J32: 0 | K32: 0 | L32: 0 | M32: 0 | N32: 0
... A78: 100000 | B78: 9999999 | C78: 0 | D78: 0 | E78: 0 | F78: 0 | G78: 0 | H78: ="("&$A78&", "&$B78&"]" -> (100000, 9999999] | I78: 0 | J78: 0 | K78: 0 | L78: 0 | M78: 0 | N78: 0
A79: Free Game | C79: =E79*B13 -> 22844570 | D79: 190196215 | E79: 0.02284457 | F79: 0.08325664 | H79: Free Game | I79: 0.3 | J79: 0.006853371 | K79: =J79 -> 0.006853371 | L79: 6853371 | M79: 0.0069045643 | N79: 0.00057485083
A80: Buy Feature | C80: 10000000 | E80: 1 | F80: 0 | H80: Buy Feature | M80: =E80 -> 1 | N80: =F80/#REF! -> #REF!
K81: =1/K79 -> 145.91359
A83: Free Game
A85: Simulator | B85: =B13 -> 1000000000 | H85: Calculate
A86: Lower | B86: Upper | C86: Cnt | D86: Pay | E86: Hit Rate | F86: Avg. Multi. | H86: Range | I86: Fix Num | J86: Fix Rate | K86: Final Rate | L86: Weight | M86: Hit Rate | N86: Simulator RTP
A87: -1 | B87: 0 | C87: 6070 | D87: 0 | E87: {=_xlfn.LET(_xlpm.x, C87:C150, _xlpm.x/SUM(_xlpm.x))} -> 0.0026641655 | F87: {=_xlfn.LET(_xlpm.x, D87:D150/C87:C150/B3, IF(ISERR(_xlpm.x), 0, _xlpm.x))} -> 0 | G87: 1e-05 | H87: ="("&$A87&", "&$B87&"]" -> (-1, 0] | I87: 0 | J87: {=_xlfn.ANCHORARRAY(E87)*I87:I150} -> 0 | K87: {=J87:J150/SUM(_xlfn.ANCHORARRAY(J87))} -> 0 | L87: {=INT(_xlfn.ANCHORARRAY(K87)*$B$2)} -> 0 | M87: {=_xlfn.LET(_xlpm.x, L87:L150, _xlpm.x/SUM(_xlpm.x))} -> 0 | N87: {=M87:M150*_xlfn.ANCHORARRAY(F87)} -> 0
A88: 0 | B88: 1 | C88: 13289 | D88: 1090600 | E88: 0.0058326351 | F88: 0.82067876 | G88: 0 | H88: ="("&$A88&", "&$B88&"]" -> (0, 1] | I88: 0 | J88: 0 | K88: 0 | L88: 0 | M88: 0 | N88: 0
A89: 1 | B89: 2 | C89: 20810 | D89: 3233730 | E89: 0.0091336546 | F89: 1.5539308 | G89: =1+G88*G87 -> 1 | H89: ="("&$A89&", "&$B89&"]" -> (1, 2] | I89: 0 | J89: 0 | K89: 0 | L89: 0 | M89: 0 | N89: 0
A90: 2 | B90: 3 | C90: 21254 | D90: 5431450 | E90: 0.0093285293 | F90: 2.5554954 | H90: ="("&$A90&", "&$B90&"]" -> (2, 3] | I90: 0 | J90: 0 | K90: 0 | L90: 0 | M90: 0 | N90: 0
A91: 3 | B91: 4 | C91: 21645 | D91: 7695990 | E91: 0.009500142 | F91: 3.5555509 | H91: ="("&$A91&", "&$B91&"]" -> (3, 4] | I91: 0 | J91: 0 | K91: 0 | L91: 0 | M91: 0 | N91: 0
A92: 4 | B92: 5 | C92: 21438 | D92: 9764380 | E92: 0.0094092882 | F92: 4.5547066 | H92: ="("&$A92&", "&$B92&"]" -> (4, 5] | I92: 0 | J92: 0 | K92: 0 | L92: 0 | M92: 0 | N92: 0
A93: 5 | B93: 6 | C93: 21633 | D93: 12019590 | E93: 0.0094948751 | F93: 5.5561365 | H93: ="("&$A93&", "&$B93&"]" -> (5, 6] | I93: 0 | J93: 0 | K93: 0 | L93: 0 | M93: 0 | N93: 0
...

Sheet Multiplier_Weight_Oldhand
A2: Threshold | B2: 1000000000
A3: Coin in | B3: =Overview!A7 -> 100
C5: RTP
B6: Bet | C6: Base Game | D6: Free Game | E6: Total | F6: Hit Rate | G6: FG Period | H6: Avg Multi | I6: BG | J6: FG
A7: Normal Bet | B7: {=Overview!B11:B12} -> 1 | C7: =SUM(N15:N79) -> 0.50693161 | D7: =SUM(_xlfn.ANCHORARRAY(N87))*F7 -> 0.41676154 | E7: =SUM(C7:D7) -> 0.92369316 | F7: =M79 -> 0.0064478501 | G7: =1/F7 -> 155.09045 | H7: =D7*G7 -> 64.635737 | I7: {=LOOKUP(2,1/(L15:L78<>0),B15:B78)} -> 40 | J7: {=LOOKUP(2,1/(_xlfn.ANCHORARRAY(L87)<>0),B15:B78)} -> 140
A8: Buy Feature | B8: 75 | C8: =N80 -> 0 | D8: =SUM(_xlfn.ANCHORARRAY(N157))/B8 -> 0.93768387 | E8: =SUM(C8:D8) -> 0.93768387 | F8: =E80 -> 1 | G8: =1/F8 -> 1 | H8: =D8*G8*B8 -> 70.32629 | J8: {=LOOKUP(2,1/(_xlfn.ANCHORARRAY(L157)<>0),B15:B78)} -> 3000
A11: Base Game
A13: Simulator | B13: 1000000000 | H13: Calculate
A14: Lower | B14: Upper | C14: Cnt | D14: Pay | E14: Hit Rate | F14: Avg. Multi. | H14: Range | I14: Fix Num | J14: Fix Rate | K14: Final Rate | L14: Weight | M14: Hit Rate | N14: Simulator RTP | P14: 目前 | Q14: 目前 | R14: 競品 | S14: 差異
A15: -1 | B15: 0 | C15: 65390071 | D15: 0 | E15: {=_xlfn.LET(_xlpm.x, C15:C78, _xlpm.x/SUM(_xlpm.x))} -> 0.66407191 | F15: {=_xlfn.LET(_xlpm.x, D15:D80/C15:C80/B3, IF(ISERR(_xlpm.x), 0, _xlpm.x))} -> 0 | G15: 1e-06 | H15: ="("&$A15&", "&$B15&"]" -> (-1, 0] | I15: 0.474 | J15: {=E15:E79*I15:I79} -> 0.31477008 | K15: {=J15:J78/SUM(_xlfn.ANCHORARRAY(J15))} -> 0.70683317 | L15: {=INT(K15:K79*$B$2)} -> 706833174 | M15: {=_xlfn.LET(_xlpm.x, L15:L79, _xlpm.x/SUM(_xlpm.x))} -> 0.71250986 | N15: {=M15:M79*F15:F79} -> 0 | P15: {=M15:M78} -> 0.71250986 | S15: {=_xlfn.LET(_xlpm.x, Q15:Q78/M15:M78, IF(ISERR(_xlpm.x), 0, ROUND(_xlpm.x,2)))} -> 0
A16: 0 | B16: 1 | C16: 17351600 | D16: 712785570 | E16: 0.17621498 | F16: 0.41078954 | G16: 0 | H16: ="("&$A16&", "&$B16&"]" -> (0, 1] | I16: 0.5 | J16: 0.08810749 | K16: 0.19785011 | L16: 197850114 | M16: 0.19943908 | N16: 0.081927487 | P16: 0.19943908 | S16: 0
A17: 1 | B17: 2 | C17: 5407273 | D17: 802609240 | E17: 0.054913812 | F17: 1.4843143 | G17: =1+G16*G15 -> 1 | H17: ="("&$A17&", "&$B17&"]" -> (1, 2] | I17: 0.3 | J17: 0.016474144 | K17: 0.036993577 | L17: 36993576 | M17: 0.037290677 | N17: 0.055351084 | P17: 0.037290677 | S17: 0
A18: 2 | B18: 3 | C18: 2729510 | D18: 691016145 | E18: 0.027719666 | F18: 2.5316491 | H18: ="("&$A18&", "&$B18&"]" -> (2, 3] | I18: 0.2 | J18: 0.0055439332 | K18: 0.0124492 | L18: 12449200 | M18: 0.012549181 | N18: 0.031770124 | P18: 0.012549181 | S18: 0
A19: 3 | B19: 4 | C19: 1570738 | D19: 556155520 | E19: 0.015951703 | F19: 3.5407275 | H19: ="("&$A19&", "&$B19&"]" -> (3, 4] | I19: 0.2 | J19: 0.0031903406 | K19: 0.0071640815 | L19: 7164081 | M19: 0.0072216168 | N19: 0.025569777 | P19: 0.0072216168 | S19: 0
A20: 4 | B20: 5 | C20: 1084233 | D20: 494968815 | E20: 0.011010979 | F20: 4.5651517 | H20: ="("&$A20&", "&$B20&"]" -> (4, 5] | I20: 0.2 | J20: 0.0022021957 | K20: 0.0049451491 | L20: 4945149 | M20: 0.0049848643 | N20: 0.022756662 | P20: 0.0049848643 | S20: 0
A21: 5 | B21: 6 | C21: 757823 | D21: 422988420 | E21: 0.0076961067 | F21: 5.5816255 | G21: 1.79 | H21: ="("&$A21&", "&$B21&"]" -> (5, 6] | I21: 0.2 | J21: 0.0015392213 | K21: 0.0034564044 | L21: 3456404 | M21: 0.0034841629 | N21: 0.019447293 | P21: 0.0034841629 | S21: 0
A22: 6 | B22: 7 | C22: 540166 | D22: 351987175 | E22: 0.0054856809 | F22: 6.5162779 | G22: 1.24 | H22: ="("&$A22&", "&$B22&"]" -> (6, 7] | I22: 0.2 | J22: 0.0010971362 | K22: 0.0024636784 | L22: 2463678 | M22: 0.0024834642 | N22: 0.016182943 | P22: 0.0024834642 | S22: 0
A23: 7 | B23: 8 | C23: 471377 | D23: 355806505 | E23: 0.004787091 | F23: 7.5482364 | G23: 1.02 | H23: ="("&$A23&", "&$B23&"]" -> (7, 8] | I23: 0.12 | J23: 0.00057445093 | K23: 0.0012899605 | L23: 1289960 | M23: 0.0013003199 | N23: 0.0098151218 | P23: 0.0013003199 | S23: 0
A24: 8 | B24: 9 | C24: 382555 | D24: 329270680 | E24: 0.0038850551 | F24: 8.6071462 | G24: 1.26 | H24: ="("&$A24&", "&$B24&"]" -> (8, 9] | I24: 0.12 | J24: 0.00046620661 | K24: 0.0010468921 | L24: 1046892 | M24: 0.0010552998 | N24: 0.0090831192 | P24: 0.0010552998 | S24: 0
A25: 9 | B25: 10 | C25: 312722 | D25: 299181170 | E25: 0.0031758628 | F25: 9.567001 | G25: 1.21 | H25: ="("&$A25&", "&$B25&"]" -> (9, 10] | I25: 0.12 | J25: 0.00038110354 | K25: 0.00085578852 | L25: 855788 | M25: 0.00086266097 | N25: 0.0082530784 | P25: 0.00086266097 | S25: 0
A26: 10 | B26: 15 | C26: 914728 | D26: 1123098055 | E26: 0.0092895628 | F26: 12.277946 | G26: 0.48 | H26: ="("&$A26&", "&$B26&"]" -> (10, 15] | I26: 0.1 | J26: 0.00092895628 | K26: 0.0020860213 | L26: 2086021 | M26: 0.0021027742 | N26: 0.025817747 | P26: 0.0021027742 | S26: 0
A27: 15 | B27: 20 | C27: 471279 | D27: 819221540 | E27: 0.0047860958 | F27: 17.382942 | G27: 1.13 | H27: ="("&$A27&", "&$B27&"]" -> (15, 20] | I27: 0.35 | J27: 0.0016751335 | K27: 0.0037616026 | L27: 3761602 | M27: 0.003791812 | N27: 0.065912847 | P27: 0.003791812 | S27: 0
A28: 20 | B28: 25 | C28: 278340 | D28: 623999005 | E28: 0.0028266948 | F28: 22.418589 | G28: 0.54 | H28: ="("&$A28&", "&$B28&"]" -> (20, 25] | I28: 0.15 | J28: 0.00042400422 | K28: 0.00095212431 | L28: 952124 | M28: 0.00095977066 | N28: 0.021516704 | P28: 0.00095977066 | S28: 0
A29: 25 | B29: 30 | C29: 187951 | D29: 515280570 | E29: 0.0019087451 | F29: 27.415687 | G29: 0.2 | H29: ="("&$A29&", "&$B29&"]" -> (25, 30] | I29: 0.2 | J29: 0.00038174902 | K29: 0.00085723799 | L29: 857237 | M29: 0.0008641216 | N29: 0.023690487 | P29: 0.0008641216 | S29: 0
A30: 30 | B30: 35 | C30: 123190 | D30: 399019550 | E30: 0.0012510618 | F30: 32.39058 | G30: 0.22 | H30: ="("&$A30&", "&$B30&"]" -> (30, 35] | I30: 0.7 | J30: 0.00087574324 | K30: 0.0019665286 | L30: 1966528 | M30: 0.0019823215 | N30: 0.064208542 | P30: 0.0019823215 | S30: 0
A31: 35 | B31: 40 | C31: 97176 | D31: 363839415 | E31: 0.00098687539 | F31: 37.441283 | G31: 0.33 | H31: ="("&$A31&", "&$B31&"]" -> (35, 40] | I31: 0.3 | J31: 0.00029606262 | K31: 0.00066482455 | L31: 664824 | M31: 0.0006701633 | N31: 0.025091774 | P31: 0.0006701633 | S31: 0
A32: 40 | B32: 45 | C32: 69470 | D32: 294779905 | E32: 0.00070550582 | F32: 42.432691 | G32: 0.16 | H32: ="("&$A32&", "&$B32&"]" -> (40, 45] | I32: 0 | J32: 0 | K32: 0 | L32: 0 | M32: 0 | N32: 0 | P32: 0 | S32: 0
... A78: 100000 | B78: 9999999 | C78: 0 | D78: 0 | E78: 0 | F78: 0 | G78: 0 | H78: ="("&$A78&", "&$B78&"]" -> (100000, 9999999] | I78: 0 | J78: 0 | K78: 0 | L78: 0 | M78: 0 | N78: 0 | P78: 0 | S78: 0
A79: Free Game | C79: =E79*B13 -> 22844570 | D79: 190196215 | E79: 0.02284457 | F79: 0.08325664 | H79: Free Game | I79: 0.28 | J79: 0.0063964796 | K79: =J79 -> 0.0063964796 | L79: 6396479 | M79: 0.0064478501 | N79: 0.00053682634
A80: Buy Feature | C80: 10000000 | E80: 1 | F80: 0 | H80: Buy Feature | M80: =E80 -> 1 | N80: =F80/B8 -> 0
A83: Free Game
A85: Simulator | B85: =B13 -> 1000000000 | H85: Calculate
A86: Lower | B86: Upper | C86: Cnt | D86: Pay | E86: Hit Rate | F86: Avg. Multi. | H86: Range | I86: Fix Num | J86: Fix Rate | K86: Final Rate | L86: Weight | M86: Hit Rate | N86: Simulator RTP | P86: 目前 | Q86: 目前 | R86: 競品 | S86: 差異
A87: -1 | B87: 0 | C87: 6070 | D87: 0 | E87: {=_xlfn.LET(_xlpm.x, C87:C150, _xlpm.x/SUM(_xlpm.x))} -> 0.0026641655 | F87: {=_xlfn.LET(_xlpm.x, D87:D150/C87:C150/B3, IF(ISERR(_xlpm.x), 0, _xlpm.x))} -> 0 | G87: 1e-05 | H87: ="("&$A87&", "&$B87&"]" -> (-1, 0] | I87: 0 | J87: {=_xlfn.ANCHORARRAY(E87)*I87:I150} -> 0 | K87: {=J87:J150/SUM(_xlfn.ANCHORARRAY(J87))} -> 0 | L87: {=INT(_xlfn.ANCHORARRAY(K87)*$B$2)} -> 0 | M87: {=_xlfn.LET(_xlpm.x, L87:L150, _xlpm.x/SUM(_xlpm.x))} -> 0 | N87: {=M87:M150*_xlfn.ANCHORARRAY(F87)} -> 0 | P87: {=_xlfn.ANCHORARRAY(M87)} -> 0 | S87: {=_xlfn.LET(_xlpm.x, Q87:Q150/M87:M150, IF(ISERR(_xlpm.x), 0, ROUND(_xlpm.x,2)))} -> 0
A88: 0 | B88: 1 | C88: 13289 | D88: 1090600 | E88: 0.0058326351 | F88: 0.82067876 | G88: 0 | H88: ="("&$A88&", "&$B88&"]" -> (0, 1] | I88: 0 | J88: 0 | K88: 0 | L88: 0 | M88: 0 | N88: 0 | P88: 0 | S88: 0
A89: 1 | B89: 2 | C89: 20810 | D89: 3233730 | E89: 0.0091336546 | F89: 1.5539308 | G89: =1+G88*G87 -> 1 | H89: ="("&$A89&", "&$B89&"]" -> (1, 2] | I89: 0 | J89: 0 | K89: 0 | L89: 0 | M89: 0 | N89: 0 | P89: 0 | S89: 0
A90: 2 | B90: 3 | C90: 21254 | D90: 5431450 | E90: 0.0093285293 | F90: 2.5554954 | H90: ="("&$A90&", "&$B90&"]" -> (2, 3] | I90: 0 | J90: 0 | K90: 0 | L90: 0 | M90: 0 | N90: 0 | P90: 0 | S90: 0
A91: 3 | B91: 4 | C91: 21645 | D91: 7695990 | E91: 0.009500142 | F91: 3.5555509 | H91: ="("&$A91&", "&$B91&"]" -> (3, 4] | I91: 0 | J91: 0 | K91: 0 | L91: 0 | M91: 0 | N91: 0 | P91: 0 | S91: 0
A92: 4 | B92: 5 | C92: 21438 | D92: 9764380 | E92: 0.0094092882 | F92: 4.5547066 | H92: ="("&$A92&", "&$B92&"]" -> (4, 5] | I92: 0 | J92: 0 | K92: 0 | L92: 0 | M92: 0 | N92: 0 | P92: 0 | S92: 0
A93: 5 | B93: 6 | C93: 21633 | D93: 12019590 | E93: 0.0094948751 | F93: 5.5561365 | H93: ="("&$A93&", "&$B93&"]" -> (5, 6] | I93: 0 | J93: 0 | K93: 0 | L93: 0 | M93: 0 | N93: 0 | P93: 0 | S93: 0
...

Sheet OP Jackpot
B2: Threshold | C2: 10000000000
B4: Status | C4: Bet Type | D4: Screen | E4: Spin | F4: C1 cnt | G4: SCR
B5: Newbie | C5: Normal Bet | D5: BG | G5: =SUM(F5:F6)/E5*$C$2 -> #DIV/0!
D6: FG
B7: Oldhand | C7: Normal Bet | D7: BG | G7: =SUM(F7:F8)/E7*$C$2 -> #DIV/0!
D8: FG
B9: - | C9: Buy Feature | D9: BG | E9: =F9 -> 0 | G9: =SUM(F9:F10)/E9*$C$2 -> #DIV/0!
D10: FG

Sheet BG_Symbol
L2: Symbol | U2: Symbol ID | AC2: Symbol Weight | AK2: Drop Weights Weight (1 Combo)
A3: Symbol | B3: Description | C3: R1 | D3: R2 | E3: R3 | F3: R4 | G3: R5 | H3: R6 | I3: R7 | J3: ID | L3: Line # | M3: R1 | N3: R2 | O3: R3 | P3: R4 | Q3: R5 | R3: R6 | S3: R7 | U3: R1 | V3: R2 | W3: R3 | X3: R4 | Y3: R5 | Z3: R6 | AA3: R7 | AC3: R1 | AD3: R2 | AE3: R3 | AF3: R4 | AG3: R5 | AH3: R6 | AI3: R7 | AK3: Symbol | AL3: R1 | AM3: R2 | AN3: R3 | AO3: R4 | AP3: R5 | AQ3: R6 | AR3: R7 | AS3: ID
A4: {=Overview!$A$42:$B$67} -> WW | B4: Wild | C4: =COUNTIF(M$4:M$304,$A4) -> 0 | D4: =COUNTIF(N$4:N$304,$A4) -> 0 | E4: =COUNTIF(O$4:O$304,$A4) -> 0 | F4: =COUNTIF(P$4:P$304,$A4) -> 0 | G4: =COUNTIF(Q$4:Q$304,$A4) -> 0 | H4: =COUNTIF(R$4:R$304,$A4) -> 0 | I4: =COUNTIF(S$4:S$304,$A4) -> 0 | J4: 0 | L4: 0 | M4: M6 | N4: A | O4: M4 | P4: M3 | Q4: J | R4: Q | S4: M4 | U4: =VLOOKUP(M4, $A$4:$J$29, 9, 0) -> 6 | V4: =VLOOKUP(N4, $A$4:$J$29, 9, 0) -> 5 | W4: =VLOOKUP(O4, $A$4:$J$29, 9, 0) -> 15 | X4: =VLOOKUP(P4, $A$4:$J$29, 9, 0) -> 16 | Y4: =VLOOKUP(Q4, $A$4:$J$29, 9, 0) -> 5 | Z4: =VLOOKUP(R4, $A$4:$J$29, 9, 0) -> 15 | AA4: =VLOOKUP(S4, $A$4:$J$29, 9, 0) -> 15 | AC4: 1 | AD4: 1 | AE4: 1 | AF4: 1 | AG4: 1 | AH4: 1 | AI4: 3 | AK4: WW | AL4: 0 | AM4: 0 | AN4: 0 | AO4: 0 | AP4: 0 | AQ4: 0 | AR4: 0 | AS4: 0
A5: C1 | B5: Scatter | C5: =COUNTIF(M$4:M$304,$A5) -> 0 | D5: =COUNTIF(N$4:N$304,$A5) -> 0 | E5: =COUNTIF(O$4:O$304,$A5) -> 0 | F5: =COUNTIF(P$4:P$304,$A5) -> 0 | G5: =COUNTIF(Q$4:Q$304,$A5) -> 0 | H5: =COUNTIF(R$4:R$304,$A5) -> 0 | I5: =COUNTIF(S$4:S$304,$A5) -> 0 | J5: 1 | L5: 1 | M5: J | N5: M5 | O5: A | P5: M3 | Q5: J | R5: Q | S5: M4 | U5: =VLOOKUP(M5, $A$4:$J$29, 9, 0) -> 5 | V5: =VLOOKUP(N5, $A$4:$J$29, 9, 0) -> 17 | W5: =VLOOKUP(O5, $A$4:$J$29, 9, 0) -> 5 | X5: =VLOOKUP(P5, $A$4:$J$29, 9, 0) -> 16 | Y5: =VLOOKUP(Q5, $A$4:$J$29, 9, 0) -> 5 | Z5: =VLOOKUP(R5, $A$4:$J$29, 9, 0) -> 15 | AA5: =VLOOKUP(S5, $A$4:$J$29, 9, 0) -> 15 | AC5: 1 | AD5: 1 | AE5: 1 | AF5: 1 | AG5: 1 | AH5: 1 | AI5: 1 | AK5: C1 | AL5: 10 | AM5: 10 | AN5: 10 | AO5: 10 | AP5: 10 | AQ5: 10 | AR5: 5 | AS5: 1
A6: M1 | B6: M1 | C6: =COUNTIF(M$4:M$304,$A6) -> 1 | D6: =COUNTIF(N$4:N$304,$A6) -> 1 | E6: =COUNTIF(O$4:O$304,$A6) -> 2 | F6: =COUNTIF(P$4:P$304,$A6) -> 1 | G6: =COUNTIF(Q$4:Q$304,$A6) -> 1 | H6: =COUNTIF(R$4:R$304,$A6) -> 2 | I6: =COUNTIF(S$4:S$304,$A6) -> 4 | J6: 2 | L6: 2 | M6: J | N6: Q | O6: J | P6: G3 | Q6: K | R6: Q | S6: M4 | U6: =VLOOKUP(M6, $A$4:$J$29, 9, 0) -> 5 | V6: =VLOOKUP(N6, $A$4:$J$29, 9, 0) -> 15 | W6: =VLOOKUP(O6, $A$4:$J$29, 9, 0) -> 5 | X6: =VLOOKUP(P6, $A$4:$J$29, 9, 0) -> 0 | Y6: =VLOOKUP(Q6, $A$4:$J$29, 9, 0) -> 13 | Z6: =VLOOKUP(R6, $A$4:$J$29, 9, 0) -> 15 | AA6: =VLOOKUP(S6, $A$4:$J$29, 9, 0) -> 15 | AC6: 1 | AD6: 1 | AE6: 1 | AF6: 1 | AG6: 1 | AH6: 1 | AI6: 1 | AK6: M1 | AL6: 8 | AM6: 8 | AN6: 8 | AO6: 8 | AP6: 8 | AQ6: 8 | AR6: 8 | AS6: 2
A7: M2 | B7: M2 | C7: =COUNTIF(M$4:M$304,$A7) -> 1 | D7: =COUNTIF(N$4:N$304,$A7) -> 5 | E7: =COUNTIF(O$4:O$304,$A7) -> 6 | F7: =COUNTIF(P$4:P$304,$A7) -> 10 | G7: =COUNTIF(Q$4:Q$304,$A7) -> 2 | H7: =COUNTIF(R$4:R$304,$A7) -> 5 | I7: =COUNTIF(S$4:S$304,$A7) -> 11 | J7: 3 | L7: 3 | M7: TE | N7: M5 | O7: J | P7: M5 | Q7: G3 | R7: TE | S7: M2 | U7: =VLOOKUP(M7, $A$4:$J$29, 9, 0) -> 12 | V7: =VLOOKUP(N7, $A$4:$J$29, 9, 0) -> 17 | W7: =VLOOKUP(O7, $A$4:$J$29, 9, 0) -> 5 | X7: =VLOOKUP(P7, $A$4:$J$29, 9, 0) -> 17 | Y7: =VLOOKUP(Q7, $A$4:$J$29, 9, 0) -> 0 | Z7: =VLOOKUP(R7, $A$4:$J$29, 9, 0) -> 12 | AA7: =VLOOKUP(S7, $A$4:$J$29, 9, 0) -> 11 | AC7: 1 | AD7: 1 | AE7: 1 | AF7: 1 | AG7: 1 | AH7: 1 | AI7: 1 | AK7: M2 | AL7: 10 | AM7: 13 | AN7: 10 | AO7: 5 | AP7: 20 | AQ7: 5 | AR7: 10 | AS7: 3
A8: M3 | B8: M3 | C8: =COUNTIF(M$4:M$304,$A8) -> 11 | D8: =COUNTIF(N$4:N$304,$A8) -> 4 | E8: =COUNTIF(O$4:O$304,$A8) -> 8 | F8: =COUNTIF(P$4:P$304,$A8) -> 5 | G8: =COUNTIF(Q$4:Q$304,$A8) -> 7 | H8: =COUNTIF(R$4:R$304,$A8) -> 4 | I8: =COUNTIF(S$4:S$304,$A8) -> 16 | J8: 4 | L8: 4 | M8: TE | N8: M4 | O8: A | P8: M2 | Q8: M4 | R8: TE | S8: M2 | U8: =VLOOKUP(M8, $A$4:$J$29, 9, 0) -> 12 | V8: =VLOOKUP(N8, $A$4:$J$29, 9, 0) -> 15 | W8: =VLOOKUP(O8, $A$4:$J$29, 9, 0) -> 5 | X8: =VLOOKUP(P8, $A$4:$J$29, 9, 0) -> 11 | Y8: =VLOOKUP(Q8, $A$4:$J$29, 9, 0) -> 15 | Z8: =VLOOKUP(R8, $A$4:$J$29, 9, 0) -> 12 | AA8: =VLOOKUP(S8, $A$4:$J$29, 9, 0) -> 11 | AC8: 1 | AD8: 1 | AE8: 1 | AF8: 1 | AG8: 1 | AH8: 1 | AI8: 3 | AK8: M3 | AL8: 15 | AM8: 10 | AN8: 15 | AO8: 5 | AP8: 18 | AQ8: 20 | AR8: 10 | AS8: 4
A9: M4 | B9: M4 | C9: =COUNTIF(M$4:M$304,$A9) -> 10 | D9: =COUNTIF(N$4:N$304,$A9) -> 6 | E9: =COUNTIF(O$4:O$304,$A9) -> 16 | F9: =COUNTIF(P$4:P$304,$A9) -> 6 | G9: =COUNTIF(Q$4:Q$304,$A9) -> 17 | H9: =COUNTIF(R$4:R$304,$A9) -> 2 | I9: =COUNTIF(S$4:S$304,$A9) -> 15 | J9: 5 | L9: 5 | M9: J | N9: Q | O9: K | P9: M2 | Q9: J | R9: TE | S9: M2 | U9: =VLOOKUP(M9, $A$4:$J$29, 9, 0) -> 5 | V9: =VLOOKUP(N9, $A$4:$J$29, 9, 0) -> 15 | W9: =VLOOKUP(O9, $A$4:$J$29, 9, 0) -> 13 | X9: =VLOOKUP(P9, $A$4:$J$29, 9, 0) -> 11 | Y9: =VLOOKUP(Q9, $A$4:$J$29, 9, 0) -> 5 | Z9: =VLOOKUP(R9, $A$4:$J$29, 9, 0) -> 12 | AA9: =VLOOKUP(S9, $A$4:$J$29, 9, 0) -> 11 | AC9: 1 | AD9: 1 | AE9: 1 | AF9: 1 | AG9: 1 | AH9: 1 | AI9: 1 | AK9: M4 | AL9: 10 | AM9: 20 | AN9: 20 | AO9: 20 | AP9: 10 | AQ9: 20 | AR9: 10 | AS9: 5
A10: M5 | B10: M5 | C10: =COUNTIF(M$4:M$304,$A10) -> 7 | D10: =COUNTIF(N$4:N$304,$A10) -> 16 | E10: =COUNTIF(O$4:O$304,$A10) -> 10 | F10: =COUNTIF(P$4:P$304,$A10) -> 19 | G10: =COUNTIF(Q$4:Q$304,$A10) -> 5 | H10: =COUNTIF(R$4:R$304,$A10) -> 25 | I10: =COUNTIF(S$4:S$304,$A10) -> 17 | J10: 6 | L10: 6 | M10: A | N10: Q | O10: K | P10: M3 | Q10: J | R10: M4 | S10: M5 | U10: =VLOOKUP(M10, $A$4:$J$29, 9, 0) -> 5 | V10: =VLOOKUP(N10, $A$4:$J$29, 9, 0) -> 15 | W10: =VLOOKUP(O10, $A$4:$J$29, 9, 0) -> 13 | X10: =VLOOKUP(P10, $A$4:$J$29, 9, 0) -> 16 | Y10: =VLOOKUP(Q10, $A$4:$J$29, 9, 0) -> 5 | Z10: =VLOOKUP(R10, $A$4:$J$29, 9, 0) -> 15 | AA10: =VLOOKUP(S10, $A$4:$J$29, 9, 0) -> 17 | AC10: 1 | AD10: 1 | AE10: 1 | AF10: 1 | AG10: 1 | AH10: 1 | AI10: 1 | AK10: M5 | AL10: 50 | AM10: 50 | AN10: 50 | AO10: 50 | AP10: 50 | AQ10: 50 | AR10: 10 | AS10: 6
A11: M6 | B11: M6 | C11: =COUNTIF(M$4:M$304,$A11) -> 15 | D11: =COUNTIF(N$4:N$304,$A11) -> 9 | E11: =COUNTIF(O$4:O$304,$A11) -> 12 | F11: =COUNTIF(P$4:P$304,$A11) -> 6 | G11: =COUNTIF(Q$4:Q$304,$A11) -> 21 | H11: =COUNTIF(R$4:R$304,$A11) -> 1 | I11: =COUNTIF(S$4:S$304,$A11) -> 6 | J11: 7 | L11: 7 | M11: K | N11: M5 | O11: M5 | P11: Q | Q11: TE | R11: A | S11: TE | U11: =VLOOKUP(M11, $A$4:$J$29, 9, 0) -> 13 | V11: =VLOOKUP(N11, $A$4:$J$29, 9, 0) -> 17 | W11: =VLOOKUP(O11, $A$4:$J$29, 9, 0) -> 17 | X11: =VLOOKUP(P11, $A$4:$J$29, 9, 0) -> 15 | Y11: =VLOOKUP(Q11, $A$4:$J$29, 9, 0) -> 12 | Z11: =VLOOKUP(R11, $A$4:$J$29, 9, 0) -> 5 | AA11: =VLOOKUP(S11, $A$4:$J$29, 9, 0) -> 12 | AC11: 1 | AD11: 1 | AE11: 1 | AF11: 1 | AG11: 1 | AH11: 1 | AI11: 1 | AK11: M6 | AL11: 50 | AM11: 50 | AN11: 50 | AO11: 50 | AP11: 50 | AQ11: 50 | AR11: 10 | AS11: 7
A12: A | B12: A | C12: =COUNTIF(M$4:M$304,$A12) -> 11 | D12: =COUNTIF(N$4:N$304,$A12) -> 16 | E12: =COUNTIF(O$4:O$304,$A12) -> 10 | F12: =COUNTIF(P$4:P$304,$A12) -> 20 | G12: =COUNTIF(Q$4:Q$304,$A12) -> 2 | H12: =COUNTIF(R$4:R$304,$A12) -> 31 | I12: =COUNTIF(S$4:S$304,$A12) -> 5 | J12: 8 | L12: 8 | M12: M6 | N12: G3 | O12: M4 | P12: M5 | Q12: M4 | R12: M5 | S12: TE | U12: =VLOOKUP(M12, $A$4:$J$29, 9, 0) -> 6 | V12: =VLOOKUP(N12, $A$4:$J$29, 9, 0) -> 0 | W12: =VLOOKUP(O12, $A$4:$J$29, 9, 0) -> 15 | X12: =VLOOKUP(P12, $A$4:$J$29, 9, 0) -> 17 | Y12: =VLOOKUP(Q12, $A$4:$J$29, 9, 0) -> 15 | Z12: =VLOOKUP(R12, $A$4:$J$29, 9, 0) -> 17 | AA12: =VLOOKUP(S12, $A$4:$J$29, 9, 0) -> 12 | AC12: 1 | AD12: 1 | AE12: 1 | AF12: 1 | AG12: 1 | AH12: 1 | AI12: 3 | AK12: A | AL12: 10 | AM12: 10 | AN12: 40 | AO12: 1 | AP12: 40 | AQ12: 1 | AR12: 10 | AS12: 8
A13: K | B13: K | C13: =COUNTIF(M$4:M$304,$A13) -> 16 | D13: =COUNTIF(N$4:N$304,$A13) -> 9 | E13: =COUNTIF(O$4:O$304,$A13) -> 12 | F13: =COUNTIF(P$4:P$304,$A13) -> 5 | G13: =COUNTIF(Q$4:Q$304,$A13) -> 16 | H13: =COUNTIF(R$4:R$304,$A13) -> 4 | I13: =COUNTIF(S$4:S$304,$A13) -> 13 | J13: 9 | L13: 9 | M13: J | N13: M3 | O13: M4 | P13: TE | Q13: M4 | R13: M5 | S13: A | U13: =VLOOKUP(M13, $A$4:$J$29, 9, 0) -> 5 | V13: =VLOOKUP(N13, $A$4:$J$29, 9, 0) -> 16 | W13: =VLOOKUP(O13, $A$4:$J$29, 9, 0) -> 15 | X13: =VLOOKUP(P13, $A$4:$J$29, 9, 0) -> 12 | Y13: =VLOOKUP(Q13, $A$4:$J$29, 9, 0) -> 15 | Z13: =VLOOKUP(R13, $A$4:$J$29, 9, 0) -> 17 | AA13: =VLOOKUP(S13, $A$4:$J$29, 9, 0) -> 5 | AC13: 1 | AD13: 1 | AE13: 1 | AF13: 1 | AG13: 1 | AH13: 1 | AI13: 1 | AK13: K | AL13: 40 | AM13: 8 | AN13: 25 | AO13: 10 | AP13: 1 | AQ13: 40 | AR13: 10 | AS13: 9
A14: Q | B14: Q | C14: =COUNTIF(M$4:M$304,$A14) -> 3 | D14: =COUNTIF(N$4:N$304,$A14) -> 17 | E14: =COUNTIF(O$4:O$304,$A14) -> 4 | F14: =COUNTIF(P$4:P$304,$A14) -> 19 | G14: =COUNTIF(Q$4:Q$304,$A14) -> 2 | H14: =COUNTIF(R$4:R$304,$A14) -> 22 | I14: =COUNTIF(S$4:S$304,$A14) -> 15 | J14: 10 | L14: 10 | M14: J | N14: M3 | O14: M4 | P14: TE | Q14: J | R14: TE | S14: M4 | U14: =VLOOKUP(M14, $A$4:$J$29, 9, 0) -> 5 | V14: =VLOOKUP(N14, $A$4:$J$29, 9, 0) -> 16 | W14: =VLOOKUP(O14, $A$4:$J$29, 9, 0) -> 15 | X14: =VLOOKUP(P14, $A$4:$J$29, 9, 0) -> 12 | Y14: =VLOOKUP(Q14, $A$4:$J$29, 9, 0) -> 5 | Z14: =VLOOKUP(R14, $A$4:$J$29, 9, 0) -> 12 | AA14: =VLOOKUP(S14, $A$4:$J$29, 9, 0) -> 15 | AC14: 1 | AD14: 1 | AE14: 1 | AF14: 1 | AG14: 1 | AH14: 1 | AI14: 1 | AK14: Q | AL14: 10 | AM14: 40 | AN14: 40 | AO14: 10 | AP14: 40 | AQ14: 1 | AR14: 10 | AS14: 10
A15: J | B15: J | C15: =COUNTIF(M$4:M$304,$A15) -> 25 | D15: =COUNTIF(N$4:N$304,$A15) -> 1 | E15: =COUNTIF(O$4:O$304,$A15) -> 20 | F15: =COUNTIF(P$4:P$304,$A15) -> 6 | G15: =COUNTIF(Q$4:Q$304,$A15) -> 27 | H15: =COUNTIF(R$4:R$304,$A15) -> 5 | I15: =COUNTIF(S$4:S$304,$A15) -> 5 | J15: 11 | L15: 11 | M15: M3 | N15: Q | O15: M6 | P15: M6 | Q15: M6 | R15: TE | S15: TE | U15: =VLOOKUP(M15, $A$4:$J$29, 9, 0) -> 16 | V15: =VLOOKUP(N15, $A$4:$J$29, 9, 0) -> 15 | W15: =VLOOKUP(O15, $A$4:$J$29, 9, 0) -> 6 | X15: =VLOOKUP(P15, $A$4:$J$29, 9, 0) -> 6 | Y15: =VLOOKUP(Q15, $A$4:$J$29, 9, 0) -> 6 | Z15: =VLOOKUP(R15, $A$4:$J$29, 9, 0) -> 12 | AA15: =VLOOKUP(S15, $A$4:$J$29, 9, 0) -> 12 | AC15: 1 | AD15: 1 | AE15: 1 | AF15: 1 | AG15: 1 | AH15: 1 | AI15: 1 | AK15: J | AL15: 40 | AM15: 40 | AN15: 40 | AO15: 1 | AP15: 1 | AQ15: 1 | AR15: 10 | AS15: 11
A16: TE | B16: TE | C16: =COUNTIF(M$4:M$304,$A16) -> 19 | D16: =COUNTIF(N$4:N$304,$A16) -> 15 | E16: =COUNTIF(O$4:O$304,$A16) -> 6 | F16: =COUNTIF(P$4:P$304,$A16) -> 13 | G16: =COUNTIF(Q$4:Q$304,$A16) -> 10 | H16: =COUNTIF(R$4:R$304,$A16) -> 18 | I16: =COUNTIF(S$4:S$304,$A16) -> 12 | J16: 12 | L16: 12 | M16: M6 | N16: Q | O16: J | P16: Q | Q16: M6 | R16: TE | S16: TE | U16: =VLOOKUP(M16, $A$4:$J$29, 9, 0) -> 6 | V16: =VLOOKUP(N16, $A$4:$J$29, 9, 0) -> 15 | W16: =VLOOKUP(O16, $A$4:$J$29, 9, 0) -> 5 | X16: =VLOOKUP(P16, $A$4:$J$29, 9, 0) -> 15 | Y16: =VLOOKUP(Q16, $A$4:$J$29, 9, 0) -> 6 | Z16: =VLOOKUP(R16, $A$4:$J$29, 9, 0) -> 12 | AA16: =VLOOKUP(S16, $A$4:$J$29, 9, 0) -> 12 | AC16: 1 | AD16: 1 | AE16: 1 | AF16: 1 | AG16: 1 | AH16: 1 | AI16: 3 | AK16: TE | AL16: 5 | AM16: 40 | AN16: 20 | AO16: 1 | AP16: 1 | AQ16: 1 | AR16: 10 | AS16: 12
... A29: GM | B29: Golden Mystery | C29: =COUNTIF(M$4:M$304,$A29) -> 0 | D29: =COUNTIF(N$4:N$304,$A29) -> 1 | E29: =COUNTIF(O$4:O$304,$A29) -> 1 | F29: =COUNTIF(P$4:P$304,$A29) -> 1 | G29: =COUNTIF(Q$4:Q$304,$A29) -> 1 | H29: =COUNTIF(R$4:R$304,$A29) -> 0 | I29: =COUNTIF(S$4:S$304,$A29) -> 0 | J29: 25 | L29: 25 | M29: J | N29: M5 | O29: M4 | P29: M3 | Q29: Q | R29: A | S29: M2 | U29: =VLOOKUP(M29, $A$4:$J$29, 9, 0) -> 5 | V29: =VLOOKUP(N29, $A$4:$J$29, 9, 0) -> 17 | W29: =VLOOKUP(O29, $A$4:$J$29, 9, 0) -> 15 | X29: =VLOOKUP(P29, $A$4:$J$29, 9, 0) -> 16 | Y29: =VLOOKUP(Q29, $A$4:$J$29, 9, 0) -> 15 | Z29: =VLOOKUP(R29, $A$4:$J$29, 9, 0) -> 5 | AA29: =VLOOKUP(S29, $A$4:$J$29, 9, 0) -> 11 | AC29: 1 | AD29: 1 | AE29: 1 | AF29: 1 | AG29: 1 | AH29: 1 | AI29: 1 | AK29: GM | AL29: 0 | AM29: 1 | AN29: 1 | AO29: 1 | AP29: 1 | AQ29: 0 | AR29: 0 | AS29: 25
C30: =SUM(C4:C29) -> 121 | D30: =SUM(D4:D29) -> 121 | E30: =SUM(E4:E29) -> 121 | F30: =SUM(F4:F29) -> 121 | G30: =SUM(G4:G29) -> 121 | H30: =SUM(H4:H29) -> 121 | I30: =SUM(I4:I29) -> 121 | L30: 26 | M30: K | N30: M5 | O30: TE | P30: Q | Q30: K | R30: M5 | S30: M2 | U30: =VLOOKUP(M30, $A$4:$J$29, 9, 0) -> 13 | V30: =VLOOKUP(N30, $A$4:$J$29, 9, 0) -> 17 | W30: =VLOOKUP(O30, $A$4:$J$29, 9, 0) -> 12 | X30: =VLOOKUP(P30, $A$4:$J$29, 9, 0) -> 15 | Y30: =VLOOKUP(Q30, $A$4:$J$29, 9, 0) -> 13 | Z30: =VLOOKUP(R30, $A$4:$J$29, 9, 0) -> 17 | AA30: =VLOOKUP(S30, $A$4:$J$29, 9, 0) -> 11 | AC30: 1 | AD30: 1 | AE30: 1 | AF30: 1 | AG30: 1 | AH30: 1 | AI30: 1
L31: 27 | M31: M4 | N31: G2 | O31: TE | P31: Q | Q31: M1 | R31: M5 | S31: K | U31: =VLOOKUP(M31, $A$4:$J$29, 9, 0) -> 15 | V31: =VLOOKUP(N31, $A$4:$J$29, 9, 0) -> 0 | W31: =VLOOKUP(O31, $A$4:$J$29, 9, 0) -> 12 | X31: =VLOOKUP(P31, $A$4:$J$29, 9, 0) -> 15 | Y31: =VLOOKUP(Q31, $A$4:$J$29, 9, 0) -> 4 | Z31: =VLOOKUP(R31, $A$4:$J$29, 9, 0) -> 17 | AA31: =VLOOKUP(S31, $A$4:$J$29, 9, 0) -> 13 | AC31: 1 | AD31: 1 | AE31: 1 | AF31: 1 | AG31: 1 | AH31: 1 | AI31: 1 | AK31: Drop Weights Weight (2 Combo)
B32: Mega way | C32: R1 | D32: R2 | E32: R3 | F32: R4 | G32: R5 | H32: R6 | L32: 28 | M32: TE | N32: M2 | O32: M2 | P32: Q | Q32: J | R32: M5 | S32: K | U32: =VLOOKUP(M32, $A$4:$J$29, 9, 0) -> 12 | V32: =VLOOKUP(N32, $A$4:$J$29, 9, 0) -> 11 | W32: =VLOOKUP(O32, $A$4:$J$29, 9, 0) -> 11 | X32: =VLOOKUP(P32, $A$4:$J$29, 9, 0) -> 15 | Y32: =VLOOKUP(Q32, $A$4:$J$29, 9, 0) -> 5 | Z32: =VLOOKUP(R32, $A$4:$J$29, 9, 0) -> 17 | AA32: =VLOOKUP(S32, $A$4:$J$29, 9, 0) -> 13 | AC32: 1 | AD32: 1 | AE32: 1 | AF32: 1 | AG32: 1 | AH32: 1 | AI32: 3 | AK32: Symbol | AL32: R1 | AM32: R2 | AN32: R3 | AO32: R4 | AP32: R5 | AQ32: R6 | AR32: R7 | AS32: ID
B33: [4,1] | C33: 0 | D33: 390 | E33: 390 | F33: 185 | G33: 120 | H33: 0 | L33: 29 | M33: TE | N33: M2 | O33: G2 | P33: M5 | Q33: J | R33: TE | S33: A | U33: =VLOOKUP(M33, $A$4:$J$29, 9, 0) -> 12 | V33: =VLOOKUP(N33, $A$4:$J$29, 9, 0) -> 11 | W33: =VLOOKUP(O33, $A$4:$J$29, 9, 0) -> 0 | X33: =VLOOKUP(P33, $A$4:$J$29, 9, 0) -> 17 | Y33: =VLOOKUP(Q33, $A$4:$J$29, 9, 0) -> 5 | Z33: =VLOOKUP(R33, $A$4:$J$29, 9, 0) -> 12 | AA33: =VLOOKUP(S33, $A$4:$J$29, 9, 0) -> 5 | AC33: 1 | AD33: 1 | AE33: 1 | AF33: 1 | AG33: 1 | AH33: 1 | AI33: 1 | AK33: WW | AL33: 0 | AM33: 0 | AN33: 0 | AO33: 0 | AP33: 0 | AQ33: 0 | AR33: 0 | AS33: 0
B34: [1,4] | C34: 0 | D34: 390 | E34: 390 | F34: 185 | G34: 120 | H34: 0 | L34: 30 | M34: J | N34: M3 | O34: G3 | P34: M5 | Q34: M2 | R34: M5 | S34: A | U34: =VLOOKUP(M34, $A$4:$J$29, 9, 0) -> 5 | V34: =VLOOKUP(N34, $A$4:$J$29, 9, 0) -> 16 | W34: =VLOOKUP(O34, $A$4:$J$29, 9, 0) -> 0 | X34: =VLOOKUP(P34, $A$4:$J$29, 9, 0) -> 17 | Y34: =VLOOKUP(Q34, $A$4:$J$29, 9, 0) -> 11 | Z34: =VLOOKUP(R34, $A$4:$J$29, 9, 0) -> 17 | AA34: =VLOOKUP(S34, $A$4:$J$29, 9, 0) -> 5 | AC34: 1 | AD34: 1 | AE34: 1 | AF34: 1 | AG34: 1 | AH34: 1 | AI34: 1 | AK34: C1 | AL34: 0 | AM34: 0 | AN34: 0 | AO34: 0 | AP34: 0 | AQ34: 0 | AR34: 0 | AS34: 1
B35: [3,2] | C35: 0 | D35: 2035 | E35: 2010 | F35: 1125 | G35: 860 | H35: 0 | L35: 31 | M35: K | N35: M3 | O35: M3 | P35: A | Q35: M6 | R35: M5 | S35: M1 | U35: =VLOOKUP(M35, $A$4:$J$29, 9, 0) -> 13 | V35: =VLOOKUP(N35, $A$4:$J$29, 9, 0) -> 16 | W35: =VLOOKUP(O35, $A$4:$J$29, 9, 0) -> 16 | X35: =VLOOKUP(P35, $A$4:$J$29, 9, 0) -> 5 | Y35: =VLOOKUP(Q35, $A$4:$J$29, 9, 0) -> 6 | Z35: =VLOOKUP(R35, $A$4:$J$29, 9, 0) -> 17 | AA35: =VLOOKUP(S35, $A$4:$J$29, 9, 0) -> 4 | AC35: 1 | AD35: 1 | AE35: 1 | AF35: 1 | AG35: 1 | AH35: 1 | AI35: 1 | AK35: M1 | AL35: 8 | AM35: 8 | AN35: 8 | AO35: 8 | AP35: 8 | AQ35: 8 | AR35: 8 | AS35: 2
B36: [2,3] | C36: 0 | D36: 2035 | E36: 2010 | F36: 1125 | G36: 860 | H36: 0 | L36: 32 | M36: K | N36: A | O36: A | P36: M2 | Q36: M6 | R36: Q | S36: M1 | U36: =VLOOKUP(M36, $A$4:$J$29, 9, 0) -> 13 | V36: =VLOOKUP(N36, $A$4:$J$29, 9, 0) -> 5 | W36: =VLOOKUP(O36, $A$4:$J$29, 9, 0) -> 5 | X36: =VLOOKUP(P36, $A$4:$J$29, 9, 0) -> 11 | Y36: =VLOOKUP(Q36, $A$4:$J$29, 9, 0) -> 6 | Z36: =VLOOKUP(R36, $A$4:$J$29, 9, 0) -> 15 | AA36: =VLOOKUP(S36, $A$4:$J$29, 9, 0) -> 4 | AC36: 1 | AD36: 1 | AE36: 1 | AF36: 1 | AG36: 1 | AH36: 1 | AI36: 3 | AK36: M2 | AL36: 10 | AM36: 13 | AN36: 10 | AO36: 5 | AP36: 20 | AQ36: 5 | AR36: 10 | AS36: 3
B37: [3,1,1] | C37: 0 | D37: 290 | E37: 283 | F37: 803 | G37: 520 | H37: 0 | L37: 33 | M37: M6 | N37: A | O37: J | P37: M2 | Q37: M5 | R37: M6 | S37: M2 | U37: =VLOOKUP(M37, $A$4:$J$29, 9, 0) -> 6 | V37: =VLOOKUP(N37, $A$4:$J$29, 9, 0) -> 5 | W37: =VLOOKUP(O37, $A$4:$J$29, 9, 0) -> 5 | X37: =VLOOKUP(P37, $A$4:$J$29, 9, 0) -> 11 | Y37: =VLOOKUP(Q37, $A$4:$J$29, 9, 0) -> 17 | Z37: =VLOOKUP(R37, $A$4:$J$29, 9, 0) -> 6 | AA37: =VLOOKUP(S37, $A$4:$J$29, 9, 0) -> 11 | AC37: 1 | AD37: 1 | AE37: 1 | AF37: 1 | AG37: 1 | AH37: 1 | AI37: 1 | AK37: M3 | AL37: 15 | AM37: 10 | AN37: 15 | AO37: 5 | AP37: 18 | AQ37: 20 | AR37: 10 | AS37: 4
B38: [1,3,1] | C38: 0 | D38: 290 | E38: 283 | F38: 803 | G38: 520 | H38: 0 | L38: 34 | M38: TE | N38: M5 | O38: M6 | P38: M5 | Q38: M4 | R38: TE | S38: M2 | U38: =VLOOKUP(M38, $A$4:$J$29, 9, 0) -> 12 | V38: =VLOOKUP(N38, $A$4:$J$29, 9, 0) -> 17 | W38: =VLOOKUP(O38, $A$4:$J$29, 9, 0) -> 6 | X38: =VLOOKUP(P38, $A$4:$J$29, 9, 0) -> 17 | Y38: =VLOOKUP(Q38, $A$4:$J$29, 9, 0) -> 15 | Z38: =VLOOKUP(R38, $A$4:$J$29, 9, 0) -> 12 | AA38: =VLOOKUP(S38, $A$4:$J$29, 9, 0) -> 11 | AC38: 1 | AD38: 1 | AE38: 1 | AF38: 1 | AG38: 1 | AH38: 1 | AI38: 1 | AK38: M4 | AL38: 10 | AM38: 20 | AN38: 20 | AO38: 20 | AP38: 10 | AQ38: 20 | AR38: 10 | AS38: 5
B39: [1,1,3] | C39: 0 | D39: 290 | E39: 283 | F39: 803 | G39: 520 | H39: 0 | L39: 35 | M39: TE | N39: TE | O39: K | P39: A | Q39: G2 | R39: TE | S39: TE | U39: =VLOOKUP(M39, $A$4:$J$29, 9, 0) -> 12 | V39: =VLOOKUP(N39, $A$4:$J$29, 9, 0) -> 12 | W39: =VLOOKUP(O39, $A$4:$J$29, 9, 0) -> 13 | X39: =VLOOKUP(P39, $A$4:$J$29, 9, 0) -> 5 | Y39: =VLOOKUP(Q39, $A$4:$J$29, 9, 0) -> 0 | Z39: =VLOOKUP(R39, $A$4:$J$29, 9, 0) -> 12 | AA39: =VLOOKUP(S39, $A$4:$J$29, 9, 0) -> 12 | AC39: 1 | AD39: 1 | AE39: 1 | AF39: 1 | AG39: 1 | AH39: 1 | AI39: 1 | AK39: M5 | AL39: 50 | AM39: 50 | AN39: 50 | AO39: 50 | AP39: 50 | AQ39: 50 | AR39: 10 | AS39: 6
B40: [2,2,1] | C40: 0 | D40: 880 | E40: 830 | F40: 850 | G40: 1250 | H40: 0 | L40: 36 | M40: M4 | N40: TE | O40: M3 | P40: A | Q40: J | R40: TE | S40: M3 | U40: =VLOOKUP(M40, $A$4:$J$29, 9, 0) -> 15 | V40: =VLOOKUP(N40, $A$4:$J$29, 9, 0) -> 12 | W40: =VLOOKUP(O40, $A$4:$J$29, 9, 0) -> 16 | X40: =VLOOKUP(P40, $A$4:$J$29, 9, 0) -> 5 | Y40: =VLOOKUP(Q40, $A$4:$J$29, 9, 0) -> 5 | Z40: =VLOOKUP(R40, $A$4:$J$29, 9, 0) -> 12 | AA40: =VLOOKUP(S40, $A$4:$J$29, 9, 0) -> 16 | AC40: 1 | AD40: 1 | AE40: 1 | AF40: 1 | AG40: 1 | AH40: 1 | AI40: 3 | AK40: M6 | AL40: 50 | AM40: 50 | AN40: 50 | AO40: 50 | AP40: 50 | AQ40: 50 | AR40: 10 | AS40: 7
B41: [2,1,2] | C41: 0 | D41: 880 | E41: 830 | F41: 850 | G41: 1250 | H41: 0 | L41: 37 | M41: M3 | N41: GT | O41: M3 | P41: Q | Q41: J | R41: M5 | S41: M3 | U41: =VLOOKUP(M41, $A$4:$J$29, 9, 0) -> 16 | V41: =VLOOKUP(N41, $A$4:$J$29, 9, 0) -> 0 | W41: =VLOOKUP(O41, $A$4:$J$29, 9, 0) -> 16 | X41: =VLOOKUP(P41, $A$4:$J$29, 9, 0) -> 15 | Y41: =VLOOKUP(Q41, $A$4:$J$29, 9, 0) -> 5 | Z41: =VLOOKUP(R41, $A$4:$J$29, 9, 0) -> 17 | AA41: =VLOOKUP(S41, $A$4:$J$29, 9, 0) -> 16 | AC41: 1 | AD41: 1 | AE41: 1 | AF41: 1 | AG41: 1 | AH41: 1 | AI41: 1 | AK41: A | AL41: 10 | AM41: 10 | AN41: 40 | AO41: 1 | AP41: 40 | AQ41: 1 | AR41: 10 | AS41: 7
B42: [1,2,2] | C42: 0 | D42: 880 | E42: 830 | F42: 850 | G42: 1250 | H42: 0 | L42: 38 | M42: M3 | N42: M6 | O42: G6 | P42: Q | Q42: K | R42: M5 | S42: M3 | U42: =VLOOKUP(M42, $A$4:$J$29, 9, 0) -> 16 | V42: =VLOOKUP(N42, $A$4:$J$29, 9, 0) -> 6 | W42: =VLOOKUP(O42, $A$4:$J$29, 9, 0) -> 0 | X42: =VLOOKUP(P42, $A$4:$J$29, 9, 0) -> 15 | Y42: =VLOOKUP(Q42, $A$4:$J$29, 9, 0) -> 13 | Z42: =VLOOKUP(R42, $A$4:$J$29, 9, 0) -> 17 | AA42: =VLOOKUP(S42, $A$4:$J$29, 9, 0) -> 16 | AC42: 1 | AD42: 1 | AE42: 1 | AF42: 1 | AG42: 1 | AH42: 1 | AI42: 1 | AK42: K | AL42: 40 | AM42: 8 | AN42: 25 | AO42: 10 | AP42: 1 | AQ42: 40 | AR42: 10 | AS42: 8
B43: [2,1,1,1] | C43: 0 | D43: 292 | E43: 305 | F43: 514 | G43: 608 | H43: 0 | L43: 39 | M43: M5 | N43: M4 | O43: M6 | P43: M4 | Q43: K | R43: Q | S43: M5 | U43: =VLOOKUP(M43, $A$4:$J$29, 9, 0) -> 17 | V43: =VLOOKUP(N43, $A$4:$J$29, 9, 0) -> 15 | W43: =VLOOKUP(O43, $A$4:$J$29, 9, 0) -> 6 | X43: =VLOOKUP(P43, $A$4:$J$29, 9, 0) -> 15 | Y43: =VLOOKUP(Q43, $A$4:$J$29, 9, 0) -> 13 | Z43: =VLOOKUP(R43, $A$4:$J$29, 9, 0) -> 15 | AA43: =VLOOKUP(S43, $A$4:$J$29, 9, 0) -> 17 | AC43: 1 | AD43: 1 | AE43: 1 | AF43: 1 | AG43: 1 | AH43: 1 | AI43: 1 | AK43: Q | AL43: 10 | AM43: 40 | AN43: 40 | AO43: 10 | AP43: 40 | AQ43: 1 | AR43: 10 | AS43: 9
B44: [1,2,1,1] | C44: 0 | D44: 292 | E44: 305 | F44: 514 | G44: 608 | H44: 0 | L44: 40 | M44: M6 | N44: G4 | O44: TE | P44: M4 | Q44: M3 | R44: A | S44: M5 | U44: =VLOOKUP(M44, $A$4:$J$29, 9, 0) -> 6 | V44: =VLOOKUP(N44, $A$4:$J$29, 9, 0) -> 0 | W44: =VLOOKUP(O44, $A$4:$J$29, 9, 0) -> 12 | X44: =VLOOKUP(P44, $A$4:$J$29, 9, 0) -> 15 | Y44: =VLOOKUP(Q44, $A$4:$J$29, 9, 0) -> 16 | Z44: =VLOOKUP(R44, $A$4:$J$29, 9, 0) -> 5 | AA44: =VLOOKUP(S44, $A$4:$J$29, 9, 0) -> 17 | AC44: 1 | AD44: 1 | AE44: 1 | AF44: 1 | AG44: 1 | AH44: 1 | AI44: 3 | AK44: J | AL44: 40 | AM44: 40 | AN44: 40 | AO44: 1 | AP44: 1 | AQ44: 1 | AR44: 10 | AS44: 10
... B47: [1,1,1,1,1] | C47: 1 | D47: 470 | E47: 640 | F47: 360 | G47: 290 | H47: 1 | L47: 43 | M47: M3 | N47: Q | O47: G4 | P47: M5 | Q47: M6 | R47: M2 | S47: M3 | U47: =VLOOKUP(M47, $A$4:$J$29, 9, 0) -> 16 | V47: =VLOOKUP(N47, $A$4:$J$29, 9, 0) -> 15 | W47: =VLOOKUP(O47, $A$4:$J$29, 9, 0) -> 0 | X47: =VLOOKUP(P47, $A$4:$J$29, 9, 0) -> 17 | Y47: =VLOOKUP(Q47, $A$4:$J$29, 9, 0) -> 6 | Z47: =VLOOKUP(R47, $A$4:$J$29, 9, 0) -> 11 | AA47: =VLOOKUP(S47, $A$4:$J$29, 9, 0) -> 16 | AC47: 1 | AD47: 1 | AE47: 1 | AF47: 1 | AG47: 1 | AH47: 1 | AI47: 3 | AK47: G2 | AL47: 0 | AM47: 4 | AN47: 4 | AO47: 2 | AP47: 2 | AQ47: 0 | AR47: 0 | AS47: 13
L48: 44 | M48: M3 | N48: GQ | O48: MY | P48: A | Q48: M6 | R48: Q | S48: M3 | U48: =VLOOKUP(M48, $A$4:$J$29, 9, 0) -> 16 | V48: =VLOOKUP(N48, $A$4:$J$29, 9, 0) -> 0 | W48: =VLOOKUP(O48, $A$4:$J$29, 9, 0) -> 2 | X48: =VLOOKUP(P48, $A$4:$J$29, 9, 0) -> 5 | Y48: =VLOOKUP(Q48, $A$4:$J$29, 9, 0) -> 6 | Z48: =VLOOKUP(R48, $A$4:$J$29, 9, 0) -> 15 | AA48: =VLOOKUP(S48, $A$4:$J$29, 9, 0) -> 16 | AC48: 1 | AD48: 1 | AE48: 1 | AF48: 1 | AG48: 1 | AH48: 1 | AI48: 1 | AK48: G3 | AL48: 0 | AM48: 5 | AN48: 5 | AO48: 2 | AP48: 2 | AQ48: 0 | AR48: 0 | AS48: 14
L49: 45 | M49: M6 | N49: G6 | O49: M2 | P49: TE | Q49: M4 | R49: Q | S49: M6 | U49: =VLOOKUP(M49, $A$4:$J$29, 9, 0) -> 6 | V49: =VLOOKUP(N49, $A$4:$J$29, 9, 0) -> 0 | W49: =VLOOKUP(O49, $A$4:$J$29, 9, 0) -> 11 | X49: =VLOOKUP(P49, $A$4:$J$29, 9, 0) -> 12 | Y49: =VLOOKUP(Q49, $A$4:$J$29, 9, 0) -> 15 | Z49: =VLOOKUP(R49, $A$4:$J$29, 9, 0) -> 15 | AA49: =VLOOKUP(S49, $A$4:$J$29, 9, 0) -> 6 | AC49: 1 | AD49: 1 | AE49: 1 | AF49: 1 | AG49: 1 | AH49: 1 | AI49: 3 | AK49: G4 | AL49: 0 | AM49: 5 | AN49: 5 | AO49: 5 | AP49: 8 | AQ49: 0 | AR49: 0 | AS49: 15
B50: MY Weight | C50: Weight | L50: 46 | M50: A | N50: M6 | O50: M6 | P50: M4 | Q50: Q | R50: Q | S50: M5 | U50: =VLOOKUP(M50, $A$4:$J$29, 9, 0) -> 5 | V50: =VLOOKUP(N50, $A$4:$J$29, 9, 0) -> 6 | W50: =VLOOKUP(O50, $A$4:$J$29, 9, 0) -> 6 | X50: =VLOOKUP(P50, $A$4:$J$29, 9, 0) -> 15 | Y50: =VLOOKUP(Q50, $A$4:$J$29, 9, 0) -> 15 | Z50: =VLOOKUP(R50, $A$4:$J$29, 9, 0) -> 15 | AA50: =VLOOKUP(S50, $A$4:$J$29, 9, 0) -> 17 | AC50: 1 | AD50: 1 | AE50: 1 | AF50: 1 | AG50: 1 | AH50: 1 | AI50: 1 | AK50: G5 | AL50: 0 | AM50: 15 | AN50: 15 | AO50: 10 | AP50: 15 | AQ50: 0 | AR50: 0 | AS50: 16
B51: WW | C51: 0 | L51: 47 | M51: M5 | N51: A | O51: G5 | P51: M4 | Q51: M4 | R51: M5 | S51: M2 | U51: =VLOOKUP(M51, $A$4:$J$29, 9, 0) -> 17 | V51: =VLOOKUP(N51, $A$4:$J$29, 9, 0) -> 5 | W51: =VLOOKUP(O51, $A$4:$J$29, 9, 0) -> 0 | X51: =VLOOKUP(P51, $A$4:$J$29, 9, 0) -> 15 | Y51: =VLOOKUP(Q51, $A$4:$J$29, 9, 0) -> 15 | Z51: =VLOOKUP(R51, $A$4:$J$29, 9, 0) -> 17 | AA51: =VLOOKUP(S51, $A$4:$J$29, 9, 0) -> 11 | AC51: 1 | AD51: 1 | AE51: 1 | AF51: 1 | AG51: 1 | AH51: 1 | AI51: 1 | AK51: G6 | AL51: 0 | AM51: 10 | AN51: 15 | AO51: 15 | AP51: 10 | AQ51: 0 | AR51: 0 | AS51: 17
B52: C1 | C52: 0 | L52: 48 | M52: TE | N52: TE | O52: G6 | P52: TE | Q52: M3 | R52: Q | S52: TE | U52: =VLOOKUP(M52, $A$4:$J$29, 9, 0) -> 12 | V52: =VLOOKUP(N52, $A$4:$J$29, 9, 0) -> 12 | W52: =VLOOKUP(O52, $A$4:$J$29, 9, 0) -> 0 | X52: =VLOOKUP(P52, $A$4:$J$29, 9, 0) -> 12 | Y52: =VLOOKUP(Q52, $A$4:$J$29, 9, 0) -> 16 | Z52: =VLOOKUP(R52, $A$4:$J$29, 9, 0) -> 15 | AA52: =VLOOKUP(S52, $A$4:$J$29, 9, 0) -> 12 | AC52: 1 | AD52: 1 | AE52: 1 | AF52: 1 | AG52: 1 | AH52: 1 | AI52: 3 | AK52: GA | AL52: 0 | AM52: 12 | AN52: 12 | AO52: 4 | AP52: 6 | AQ52: 0 | AR52: 0 | AS52: 17
B53: M1 | C53: 2 | L53: 49 | M53: M3 | N53: TE | O53: M6 | P53: A | Q53: M3 | R53: Q | S53: TE | U53: =VLOOKUP(M53, $A$4:$J$29, 9, 0) -> 16 | V53: =VLOOKUP(N53, $A$4:$J$29, 9, 0) -> 12 | W53: =VLOOKUP(O53, $A$4:$J$29, 9, 0) -> 6 | X53: =VLOOKUP(P53, $A$4:$J$29, 9, 0) -> 5 | Y53: =VLOOKUP(Q53, $A$4:$J$29, 9, 0) -> 16 | Z53: =VLOOKUP(R53, $A$4:$J$29, 9, 0) -> 15 | AA53: =VLOOKUP(S53, $A$4:$J$29, 9, 0) -> 12 | AC53: 1 | AD53: 1 | AE53: 1 | AF53: 1 | AG53: 1 | AH53: 1 | AI53: 1 | AK53: GK | AL53: 0 | AM53: 8 | AN53: 12 | AO53: 4 | AP53: 4 | AQ53: 0 | AR53: 0 | AS53: 18
B54: M2 | C54: 3 | L54: 50 | M54: M3 | N54: Q | O54: J | P54: M5 | Q54: GT | R54: M5 | S54: TE | U54: =VLOOKUP(M54, $A$4:$J$29, 9, 0) -> 16 | V54: =VLOOKUP(N54, $A$4:$J$29, 9, 0) -> 15 | W54: =VLOOKUP(O54, $A$4:$J$29, 9, 0) -> 5 | X54: =VLOOKUP(P54, $A$4:$J$29, 9, 0) -> 17 | Y54: =VLOOKUP(Q54, $A$4:$J$29, 9, 0) -> 0 | Z54: =VLOOKUP(R54, $A$4:$J$29, 9, 0) -> 17 | AA54: =VLOOKUP(S54, $A$4:$J$29, 9, 0) -> 12 | AC54: 1 | AD54: 1 | AE54: 1 | AF54: 1 | AG54: 1 | AH54: 1 | AI54: 1 | AK54: GQ | AL54: 0 | AM54: 10 | AN54: 6 | AO54: 2 | AP54: 8 | AQ54: 0 | AR54: 0 | AS54: 19
B55: M3 | C55: 5 | L55: 51 | M55: M2 | N55: A | O55: M2 | P55: M2 | Q55: TE | R55: M5 | S55: M6 | U55: =VLOOKUP(M55, $A$4:$J$29, 9, 0) -> 11 | V55: =VLOOKUP(N55, $A$4:$J$29, 9, 0) -> 5 | W55: =VLOOKUP(O55, $A$4:$J$29, 9, 0) -> 11 | X55: =VLOOKUP(P55, $A$4:$J$29, 9, 0) -> 11 | Y55: =VLOOKUP(Q55, $A$4:$J$29, 9, 0) -> 12 | Z55: =VLOOKUP(R55, $A$4:$J$29, 9, 0) -> 17 | AA55: =VLOOKUP(S55, $A$4:$J$29, 9, 0) -> 6 | AC55: 1 | AD55: 1 | AE55: 1 | AF55: 1 | AG55: 1 | AH55: 1 | AI55: 3 | AK55: GJ | AL55: 0 | AM55: 5 | AN55: 6 | AO55: 2 | AP55: 4 | AQ55: 0 | AR55: 0 | AS55: 20
...

Sheet BG_Symbol (2)
L2: Symbol | U2: Symbol ID | AC2: Symbol Weight | AK2: Drop Weights Weight (1 Combo)
A3: Symbol | B3: Description | C3: R1 | D3: R2 | E3: R3 | F3: R4 | G3: R5 | H3: R6 | I3: R7 | J3: ID | L3: Line # | M3: R1 | N3: R2 | O3: R3 | P3: R4 | Q3: R5 | R3: R6 | S3: R7 | U3: R1 | V3: R2 | W3: R3 | X3: R4 | Y3: R5 | Z3: R6 | AA3: R7 | AC3: R1 | AD3: R2 | AE3: R3 | AF3: R4 | AG3: R5 | AH3: R6 | AI3: R7 | AK3: Symbol | AL3: R1 | AM3: R2 | AN3: R3 | AO3: R4 | AP3: R5 | AQ3: R6 | AR3: R7 | AS3: ID
A4: {=Overview!$A$42:$B$67} -> WW | B4: Wild | C4: =COUNTIF(M$4:M$304,$A4) -> 0 | D4: =COUNTIF(N$4:N$304,$A4) -> 0 | E4: =COUNTIF(O$4:O$304,$A4) -> 0 | F4: =COUNTIF(P$4:P$304,$A4) -> 0 | G4: =COUNTIF(Q$4:Q$304,$A4) -> 0 | H4: =COUNTIF(R$4:R$304,$A4) -> 0 | I4: =COUNTIF(S$4:S$304,$A4) -> 0 | J4: 0 | L4: 0 | M4: M6 | N4: M6 | O4: K | P4: M5 | Q4: M4 | R4: A | S4: A | U4: =VLOOKUP(M4, $A$4:$J$29, 9, 0) -> 7 | V4: =VLOOKUP(N4, $A$4:$J$29, 9, 0) -> 7 | W4: =VLOOKUP(O4, $A$4:$J$29, 9, 0) -> 7 | X4: =VLOOKUP(P4, $A$4:$J$29, 9, 0) -> 14 | Y4: =VLOOKUP(Q4, $A$4:$J$29, 9, 0) -> 10 | Z4: =VLOOKUP(R4, $A$4:$J$29, 9, 0) -> 11 | AA4: =VLOOKUP(S4, $A$4:$J$29, 9, 0) -> 11 | AC4: 1 | AD4: 1 | AE4: 1 | AF4: 1 | AG4: 1 | AH4: 1 | AI4: 3 | AK4: WW | AL4: 0 | AM4: 0 | AN4: 0 | AO4: 0 | AP4: 0 | AQ4: 0 | AR4: 0 | AS4: 0
A5: C1 | B5: Scatter | C5: =COUNTIF(M$4:M$304,$A5) -> 0 | D5: =COUNTIF(N$4:N$304,$A5) -> 0 | E5: =COUNTIF(O$4:O$304,$A5) -> 0 | F5: =COUNTIF(P$4:P$304,$A5) -> 0 | G5: =COUNTIF(Q$4:Q$304,$A5) -> 0 | H5: =COUNTIF(R$4:R$304,$A5) -> 0 | I5: =COUNTIF(S$4:S$304,$A5) -> 0 | J5: 1 | L5: 1 | M5: K | N5: J | O5: K | P5: A | Q5: G4 | R5: K | S5: A | U5: =VLOOKUP(M5, $A$4:$J$29, 9, 0) -> 7 | V5: =VLOOKUP(N5, $A$4:$J$29, 9, 0) -> 15 | W5: =VLOOKUP(O5, $A$4:$J$29, 9, 0) -> 7 | X5: =VLOOKUP(P5, $A$4:$J$29, 9, 0) -> 11 | Y5: =VLOOKUP(Q5, $A$4:$J$29, 9, 0) -> 0 | Z5: =VLOOKUP(R5, $A$4:$J$29, 9, 0) -> 7 | AA5: =VLOOKUP(S5, $A$4:$J$29, 9, 0) -> 11 | AC5: 1 | AD5: 1 | AE5: 1 | AF5: 1 | AG5: 1 | AH5: 1 | AI5: 1 | AK5: C1 | AL5: 10 | AM5: 10 | AN5: 10 | AO5: 10 | AP5: 10 | AQ5: 10 | AR5: 5 | AS5: 1
A6: M1 | B6: M1 | C6: =COUNTIF(M$4:M$304,$A6) -> 0 | D6: =COUNTIF(N$4:N$304,$A6) -> 0 | E6: =COUNTIF(O$4:O$304,$A6) -> 0 | F6: =COUNTIF(P$4:P$304,$A6) -> 0 | G6: =COUNTIF(Q$4:Q$304,$A6) -> 0 | H6: =COUNTIF(R$4:R$304,$A6) -> 0 | I6: =COUNTIF(S$4:S$304,$A6) -> 0 | J6: 2 | L6: 2 | M6: J | N6: TE | O6: M2 | P6: A | Q6: M5 | R6: M5 | S6: A | U6: =VLOOKUP(M6, $A$4:$J$29, 9, 0) -> 15 | V6: =VLOOKUP(N6, $A$4:$J$29, 9, 0) -> 19 | W6: =VLOOKUP(O6, $A$4:$J$29, 9, 0) -> 12 | X6: =VLOOKUP(P6, $A$4:$J$29, 9, 0) -> 11 | Y6: =VLOOKUP(Q6, $A$4:$J$29, 9, 0) -> 14 | Z6: =VLOOKUP(R6, $A$4:$J$29, 9, 0) -> 14 | AA6: =VLOOKUP(S6, $A$4:$J$29, 9, 0) -> 11 | AC6: 1 | AD6: 1 | AE6: 1 | AF6: 1 | AG6: 1 | AH6: 1 | AI6: 1 | AK6: M1 | AL6: 8 | AM6: 8 | AN6: 8 | AO6: 8 | AP6: 8 | AQ6: 8 | AR6: 8 | AS6: 2
A7: M2 | B7: M2 | C7: =COUNTIF(M$4:M$304,$A7) -> 1 | D7: =COUNTIF(N$4:N$304,$A7) -> 12 | E7: =COUNTIF(O$4:O$304,$A7) -> 7 | F7: =COUNTIF(P$4:P$304,$A7) -> 3 | G7: =COUNTIF(Q$4:Q$304,$A7) -> 9 | H7: =COUNTIF(R$4:R$304,$A7) -> 0 | I7: =COUNTIF(S$4:S$304,$A7) -> 12 | J7: 3 | L7: 3 | M7: TE | N7: Q | O7: A | P7: A | Q7: M5 | R7: TE | S7: A | U7: =VLOOKUP(M7, $A$4:$J$29, 9, 0) -> 19 | V7: =VLOOKUP(N7, $A$4:$J$29, 9, 0) -> 12 | W7: =VLOOKUP(O7, $A$4:$J$29, 9, 0) -> 11 | X7: =VLOOKUP(P7, $A$4:$J$29, 9, 0) -> 11 | Y7: =VLOOKUP(Q7, $A$4:$J$29, 9, 0) -> 14 | Z7: =VLOOKUP(R7, $A$4:$J$29, 9, 0) -> 19 | AA7: =VLOOKUP(S7, $A$4:$J$29, 9, 0) -> 11 | AC7: 1 | AD7: 1 | AE7: 1 | AF7: 1 | AG7: 1 | AH7: 1 | AI7: 1 | AK7: M2 | AL7: 10 | AM7: 13 | AN7: 10 | AO7: 5 | AP7: 20 | AQ7: 5 | AR7: 10 | AS7: 3
A8: M3 | B8: M3 | C8: =COUNTIF(M$4:M$304,$A8) -> 3 | D8: =COUNTIF(N$4:N$304,$A8) -> 1 | E8: =COUNTIF(O$4:O$304,$A8) -> 3 | F8: =COUNTIF(P$4:P$304,$A8) -> 8 | G8: =COUNTIF(Q$4:Q$304,$A8) -> 3 | H8: =COUNTIF(R$4:R$304,$A8) -> 3 | I8: =COUNTIF(S$4:S$304,$A8) -> 14 | J8: 4 | L8: 4 | M8: K | N8: TE | O8: G3 | P8: Q | Q8: K | R8: TE | S8: M2 | U8: =VLOOKUP(M8, $A$4:$J$29, 9, 0) -> 7 | V8: =VLOOKUP(N8, $A$4:$J$29, 9, 0) -> 19 | W8: =VLOOKUP(O8, $A$4:$J$29, 9, 0) -> 0 | X8: =VLOOKUP(P8, $A$4:$J$29, 9, 0) -> 12 | Y8: =VLOOKUP(Q8, $A$4:$J$29, 9, 0) -> 7 | Z8: =VLOOKUP(R8, $A$4:$J$29, 9, 0) -> 19 | AA8: =VLOOKUP(S8, $A$4:$J$29, 9, 0) -> 12 | AC8: 1 | AD8: 1 | AE8: 1 | AF8: 1 | AG8: 1 | AH8: 1 | AI8: 3 | AK8: M3 | AL8: 15 | AM8: 10 | AN8: 15 | AO8: 5 | AP8: 18 | AQ8: 20 | AR8: 10 | AS8: 4
A9: M4 | B9: M4 | C9: =COUNTIF(M$4:M$304,$A9) -> 8 | D9: =COUNTIF(N$4:N$304,$A9) -> 1 | E9: =COUNTIF(O$4:O$304,$A9) -> 16 | F9: =COUNTIF(P$4:P$304,$A9) -> 3 | G9: =COUNTIF(Q$4:Q$304,$A9) -> 15 | H9: =COUNTIF(R$4:R$304,$A9) -> 5 | I9: =COUNTIF(S$4:S$304,$A9) -> 10 | J9: 5 | L9: 5 | M9: J | N9: M2 | O9: M3 | P9: Q | Q9: K | R9: M5 | S9: M2 | U9: =VLOOKUP(M9, $A$4:$J$29, 9, 0) -> 15 | V9: =VLOOKUP(N9, $A$4:$J$29, 9, 0) -> 12 | W9: =VLOOKUP(O9, $A$4:$J$29, 9, 0) -> 14 | X9: =VLOOKUP(P9, $A$4:$J$29, 9, 0) -> 12 | Y9: =VLOOKUP(Q9, $A$4:$J$29, 9, 0) -> 7 | Z9: =VLOOKUP(R9, $A$4:$J$29, 9, 0) -> 14 | AA9: =VLOOKUP(S9, $A$4:$J$29, 9, 0) -> 12 | AC9: 1 | AD9: 1 | AE9: 1 | AF9: 1 | AG9: 1 | AH9: 1 | AI9: 1 | AK9: M4 | AL9: 10 | AM9: 20 | AN9: 20 | AO9: 20 | AP9: 10 | AQ9: 20 | AR9: 10 | AS9: 5
A10: M5 | B10: M5 | C10: =COUNTIF(M$4:M$304,$A10) -> 8 | D10: =COUNTIF(N$4:N$304,$A10) -> 17 | E10: =COUNTIF(O$4:O$304,$A10) -> 1 | F10: =COUNTIF(P$4:P$304,$A10) -> 26 | G10: =COUNTIF(Q$4:Q$304,$A10) -> 6 | H10: =COUNTIF(R$4:R$304,$A10) -> 27 | I10: =COUNTIF(S$4:S$304,$A10) -> 14 | J10: 6 | L10: 6 | M10: K | N10: M2 | O10: A | P10: Q | Q10: M6 | R10: M5 | S10: M2 | U10: =VLOOKUP(M10, $A$4:$J$29, 9, 0) -> 7 | V10: =VLOOKUP(N10, $A$4:$J$29, 9, 0) -> 12 | W10: =VLOOKUP(O10, $A$4:$J$29, 9, 0) -> 11 | X10: =VLOOKUP(P10, $A$4:$J$29, 9, 0) -> 12 | Y10: =VLOOKUP(Q10, $A$4:$J$29, 9, 0) -> 7 | Z10: =VLOOKUP(R10, $A$4:$J$29, 9, 0) -> 14 | AA10: =VLOOKUP(S10, $A$4:$J$29, 9, 0) -> 12 | AC10: 1 | AD10: 1 | AE10: 1 | AF10: 1 | AG10: 1 | AH10: 1 | AI10: 1 | AK10: M5 | AL10: 50 | AM10: 50 | AN10: 50 | AO10: 50 | AP10: 50 | AQ10: 50 | AR10: 10 | AS10: 6
A11: M6 | B11: M6 | C11: =COUNTIF(M$4:M$304,$A11) -> 13 | D11: =COUNTIF(N$4:N$304,$A11) -> 10 | E11: =COUNTIF(O$4:O$304,$A11) -> 1 | F11: =COUNTIF(P$4:P$304,$A11) -> 3 | G11: =COUNTIF(Q$4:Q$304,$A11) -> 28 | H11: =COUNTIF(R$4:R$304,$A11) -> 3 | I11: =COUNTIF(S$4:S$304,$A11) -> 7 | J11: 7 | L11: 7 | M11: TE | N11: M6 | O11: K | P11: TE | Q11: J | R11: M5 | S11: M2 | U11: =VLOOKUP(M11, $A$4:$J$29, 9, 0) -> 19 | V11: =VLOOKUP(N11, $A$4:$J$29, 9, 0) -> 7 | W11: =VLOOKUP(O11, $A$4:$J$29, 9, 0) -> 7 | X11: =VLOOKUP(P11, $A$4:$J$29, 9, 0) -> 19 | Y11: =VLOOKUP(Q11, $A$4:$J$29, 9, 0) -> 15 | Z11: =VLOOKUP(R11, $A$4:$J$29, 9, 0) -> 14 | AA11: =VLOOKUP(S11, $A$4:$J$29, 9, 0) -> 12 | AC11: 1 | AD11: 1 | AE11: 1 | AF11: 1 | AG11: 1 | AH11: 1 | AI11: 1 | AK11: M6 | AL11: 50 | AM11: 50 | AN11: 50 | AO11: 50 | AP11: 50 | AQ11: 50 | AR11: 10 | AS11: 7
A12: A | B12: A | C12: =COUNTIF(M$4:M$304,$A12) -> 2 | D12: =COUNTIF(N$4:N$304,$A12) -> 12 | E12: =COUNTIF(O$4:O$304,$A12) -> 21 | F12: =COUNTIF(P$4:P$304,$A12) -> 10 | G12: =COUNTIF(Q$4:Q$304,$A12) -> 3 | H12: =COUNTIF(R$4:R$304,$A12) -> 29 | I12: =COUNTIF(S$4:S$304,$A12) -> 11 | J12: 8 | L12: 8 | M12: M5 | N12: M6 | O12: K | P12: M5 | Q12: J | R12: M6 | S12: M3 | U12: =VLOOKUP(M12, $A$4:$J$29, 9, 0) -> 14 | V12: =VLOOKUP(N12, $A$4:$J$29, 9, 0) -> 7 | W12: =VLOOKUP(O12, $A$4:$J$29, 9, 0) -> 7 | X12: =VLOOKUP(P12, $A$4:$J$29, 9, 0) -> 14 | Y12: =VLOOKUP(Q12, $A$4:$J$29, 9, 0) -> 15 | Z12: =VLOOKUP(R12, $A$4:$J$29, 9, 0) -> 7 | AA12: =VLOOKUP(S12, $A$4:$J$29, 9, 0) -> 14 | AC12: 1 | AD12: 1 | AE12: 1 | AF12: 1 | AG12: 1 | AH12: 1 | AI12: 3 | AK12: A | AL12: 10 | AM12: 10 | AN12: 40 | AO12: 1 | AP12: 40 | AQ12: 1 | AR12: 10 | AS12: 8
A13: K | B13: K | C13: =COUNTIF(M$4:M$304,$A13) -> 19 | D13: =COUNTIF(N$4:N$304,$A13) -> 2 | E13: =COUNTIF(O$4:O$304,$A13) -> 19 | F13: =COUNTIF(P$4:P$304,$A13) -> 4 | G13: =COUNTIF(Q$4:Q$304,$A13) -> 16 | H13: =COUNTIF(R$4:R$304,$A13) -> 7 | I13: =COUNTIF(S$4:S$304,$A13) -> 7 | J13: 9 | L13: 9 | M13: J | N13: G5 | O13: M3 | P13: Q | Q13: M6 | R13: M5 | S13: M3 | U13: =VLOOKUP(M13, $A$4:$J$29, 9, 0) -> 15 | V13: =VLOOKUP(N13, $A$4:$J$29, 9, 0) -> 0 | W13: =VLOOKUP(O13, $A$4:$J$29, 9, 0) -> 14 | X13: =VLOOKUP(P13, $A$4:$J$29, 9, 0) -> 12 | Y13: =VLOOKUP(Q13, $A$4:$J$29, 9, 0) -> 7 | Z13: =VLOOKUP(R13, $A$4:$J$29, 9, 0) -> 14 | AA13: =VLOOKUP(S13, $A$4:$J$29, 9, 0) -> 14 | AC13: 1 | AD13: 1 | AE13: 1 | AF13: 1 | AG13: 1 | AH13: 1 | AI13: 1 | AK13: K | AL13: 40 | AM13: 8 | AN13: 25 | AO13: 10 | AP13: 1 | AQ13: 40 | AR13: 10 | AS13: 9
A14: Q | B14: Q | C14: =COUNTIF(M$4:M$304,$A14) -> 14 | D14: =COUNTIF(N$4:N$304,$A14) -> 27 | E14: =COUNTIF(O$4:O$304,$A14) -> 2 | F14: =COUNTIF(P$4:P$304,$A14) -> 25 | G14: =COUNTIF(Q$4:Q$304,$A14) -> 7 | H14: =COUNTIF(R$4:R$304,$A14) -> 24 | I14: =COUNTIF(S$4:S$304,$A14) -> 12 | J14: 10 | L14: 10 | M14: J | N14: M5 | O14: J | P14: G5 | Q14: M6 | R14: M5 | S14: M3 | U14: =VLOOKUP(M14, $A$4:$J$29, 9, 0) -> 15 | V14: =VLOOKUP(N14, $A$4:$J$29, 9, 0) -> 14 | W14: =VLOOKUP(O14, $A$4:$J$29, 9, 0) -> 15 | X14: =VLOOKUP(P14, $A$4:$J$29, 9, 0) -> 0 | Y14: =VLOOKUP(Q14, $A$4:$J$29, 9, 0) -> 7 | Z14: =VLOOKUP(R14, $A$4:$J$29, 9, 0) -> 14 | AA14: =VLOOKUP(S14, $A$4:$J$29, 9, 0) -> 14 | AC14: 1 | AD14: 1 | AE14: 1 | AF14: 1 | AG14: 1 | AH14: 1 | AI14: 1 | AK14: Q | AL14: 10 | AM14: 40 | AN14: 40 | AO14: 10 | AP14: 40 | AQ14: 1 | AR14: 10 | AS14: 10
A15: J | B15: J | C15: =COUNTIF(M$4:M$304,$A15) -> 23 | D15: =COUNTIF(N$4:N$304,$A15) -> 5 | E15: =COUNTIF(O$4:O$304,$A15) -> 35 | F15: =COUNTIF(P$4:P$304,$A15) -> 6 | G15: =COUNTIF(Q$4:Q$304,$A15) -> 20 | H15: =COUNTIF(R$4:R$304,$A15) -> 2 | I15: =COUNTIF(S$4:S$304,$A15) -> 15 | J15: 11 | L15: 11 | M15: TE | N15: M5 | O15: J | P15: GA | Q15: K | R15: M6 | S15: M3 | U15: =VLOOKUP(M15, $A$4:$J$29, 9, 0) -> 19 | V15: =VLOOKUP(N15, $A$4:$J$29, 9, 0) -> 14 | W15: =VLOOKUP(O15, $A$4:$J$29, 9, 0) -> 15 | X15: =VLOOKUP(P15, $A$4:$J$29, 9, 0) -> 0 | Y15: =VLOOKUP(Q15, $A$4:$J$29, 9, 0) -> 7 | Z15: =VLOOKUP(R15, $A$4:$J$29, 9, 0) -> 7 | AA15: =VLOOKUP(S15, $A$4:$J$29, 9, 0) -> 14 | AC15: 1 | AD15: 1 | AE15: 1 | AF15: 1 | AG15: 1 | AH15: 1 | AI15: 1 | AK15: J | AL15: 40 | AM15: 40 | AN15: 40 | AO15: 1 | AP15: 1 | AQ15: 1 | AR15: 10 | AS15: 11
A16: TE | B16: TE | C16: =COUNTIF(M$4:M$304,$A16) -> 30 | D16: =COUNTIF(N$4:N$304,$A16) -> 16 | E16: =COUNTIF(O$4:O$304,$A16) -> 5 | F16: =COUNTIF(P$4:P$304,$A16) -> 19 | G16: =COUNTIF(Q$4:Q$304,$A16) -> 5 | H16: =COUNTIF(R$4:R$304,$A16) -> 21 | I16: =COUNTIF(S$4:S$304,$A16) -> 19 | J16: 12 | L16: 12 | M16: TE | N16: Q | O16: G2 | P16: A | Q16: K | R16: M6 | S16: M4 | U16: =VLOOKUP(M16, $A$4:$J$29, 9, 0) -> 19 | V16: =VLOOKUP(N16, $A$4:$J$29, 9, 0) -> 12 | W16: =VLOOKUP(O16, $A$4:$J$29, 9, 0) -> 0 | X16: =VLOOKUP(P16, $A$4:$J$29, 9, 0) -> 11 | Y16: =VLOOKUP(Q16, $A$4:$J$29, 9, 0) -> 7 | Z16: =VLOOKUP(R16, $A$4:$J$29, 9, 0) -> 7 | AA16: =VLOOKUP(S16, $A$4:$J$29, 9, 0) -> 10 | AC16: 1 | AD16: 1 | AE16: 1 | AF16: 1 | AG16: 1 | AH16: 1 | AI16: 3 | AK16: TE | AL16: 5 | AM16: 40 | AN16: 20 | AO16: 1 | AP16: 1 | AQ16: 1 | AR16: 10 | AS16: 12
