Workbook

Sheet Overview
A2: Model: | B2: H0281
A3: Version: | B3: 2.0
A6: Base Bet | B6: Multiway
A7: 100 | B7: 32400
A10: Coin in | B10: Price(x) | C10: Total RTP | D10: Bet Type
A11: {=B11:B12*A7} -> 100 | B11: 1 | C11: =B17+B18 -> 0.93999976 | D11: Normal Bet
A12: 7500 | B12: 75 | C12: =B21+B22 -> 0.92499987 | D12: Buy Feature
A15: Total Pay Back Percentage includes the following adjustments.
A16: Bet Type | B16: Pay Back | C16: Hit% | D16: Pulls/Hit | E16: Description
A17: =D11 -> Normal Bet | B17: =Detail!C7 -> 0.71999981 | C17: =1/D17 -> 0.0033333328 | D17: =Detail!G7 -> 300.00005 | E17: Base Game
B18: =Detail!D7 -> 0.21999995 | E18: Free Game
A20: Bet Type | B20: Pay Back | C20: Hit% | D20: Pulls/Hit | E20: Description
A21: =D12 -> Buy Feature | B21: =Detail!C8 -> 0 | C21: =1/D21 -> 1 | D21: 1 | E21: Base Game
B22: =Detail!D8 -> 0.92499987 | E22: Free Game

Sheet Description
B3: 7. BG 流程對應
B5: 7.1 BG 開局流程
B7: BG 每局的主要參數流程如下：
B8: 1. 先用 Table Selection Weight - Base Game 選出 BG table。
B9: 2. 再用該 strip 的 Symbol Weight R1~R5 抽停輪位置。
B10: 3. 依 Symbol ID R1~R5 生成初始盤面。
B11: 4. 盤面上的彩虹框會先判定是否觸發 Used Special Pool Weight。
B12: 5. 若命中特殊池，該彩虹框用 Multiple Selection Weight - Special Pool 抽倍率。
B13: 6. 若沒命中特殊池：
B14: - 且是 BG_Symbol (2) 則第 3 輪彩虹框用 Multiple Selection Weight - Reel3 Before Eliminate
B15: - 其他輪彩虹框用 Multiple Selection Weight - Before Eliminate
B16: 7. 再用 Eliminate Table Weight 決定本局是掉落表 A 或 B。
... B83: 5. BG_Symbol (3): 觸發 FG 用的表。得分少、C1 多，盡量不要有倍數百搭參與 → 控制進 FG 時的得分

Sheet Multiplier_Weight
A2: Range | B2: Weight_NB_BG_Newbie | C2: Weight_NB_FG_Newbie | D2: Weight_NB_BG | E2: Weight_NB_FG | F2: Weight_BF
A3: (-1, 0] | B3: =Detail_Newbie!K15 -> 733363665 | C3: =Detail_Newbie!K86 -> 0 | D3: =Detail!K15 -> 725330891 | E3: =Detail!K86 -> 0 | F3: =Detail!K163 -> 0
A4: (0, 1] | B4: =Detail_Newbie!K16 -> 147073596 | C4: =Detail_Newbie!K87 -> 0 | D4: =Detail!K16 -> 154427797 | E4: =Detail!K87 -> 0 | F4: =Detail!K164 -> 0
A5: (1, 2] | B5: =Detail_Newbie!K17 -> 43093408 | C5: =Detail_Newbie!K88 -> 0 | D5: =Detail!K17 -> 45355835 | E5: =Detail!K88 -> 0 | F5: =Detail!K165 -> 0
A6: (2, 3] | B6: =Detail_Newbie!K18 -> 19740462 | C6: =Detail_Newbie!K89 -> 0 | D6: =Detail!K18 -> 20824139 | E6: =Detail!K89 -> 0 | F6: =Detail!K166 -> 0
A7: (3, 4] | B7: =Detail_Newbie!K19 -> 12108784 | C7: =Detail_Newbie!K90 -> 0 | D7: =Detail!K19 -> 12801719 | E7: =Detail!K90 -> 0 | F7: =Detail!K167 -> 0
A8: (4, 5] | B8: =Detail_Newbie!K20 -> 7862043 | C8: =Detail_Newbie!K91 -> 0 | D8: =Detail!K20 -> 8330451 | E8: =Detail!K91 -> 0 | F8: =Detail!K168 -> 0
A9: (5, 6] | B9: =Detail_Newbie!K21 -> 6066266 | C9: =Detail_Newbie!K92 -> 0 | D9: =Detail!K21 -> 6442230 | E9: =Detail!K92 -> 0 | F9: =Detail!K169 -> 0
A10: (6, 7] | B10: =Detail_Newbie!K22 -> 3265393 | C10: =Detail_Newbie!K93 -> 0 | D10: =Detail!K22 -> 3475246 | E10: =Detail!K93 -> 0 | F10: =Detail!K170 -> 0
A11: (7, 8] | B11: =Detail_Newbie!K23 -> 3661358 | C11: =Detail_Newbie!K94 -> 0 | D11: =Detail!K23 -> 3905374 | E11: =Detail!K94 -> 0 | F11: =Detail!K171 -> 0
A12: (8, 9] | B12: =Detail_Newbie!K24 -> 2961953 | C12: =Detail_Newbie!K95 -> 0 | D12: =Detail!K24 -> 3166507 | E12: =Detail!K95 -> 0 | F12: =Detail!K172 -> 0
A13: (9, 10] | B13: =Detail_Newbie!K25 -> 1920487 | C13: =Detail_Newbie!K96 -> 0 | D13: =Detail!K25 -> 2057605 | E13: =Detail!K96 -> 0 | F13: =Detail!K173 -> 0
A14: (10, 15] | B14: =Detail_Newbie!K26 -> 10160063 | C14: =Detail_Newbie!K97 -> 0 | D14: =Detail!K26 -> 6253894 | E14: =Detail!K97 -> 0 | F14: =Detail!K174 -> 0
... A66: (100000, 9999999] | B66: =Detail_Newbie!K78 -> 0 | C66: =Detail_Newbie!K149 -> 0 | D66: =Detail!K78 -> 0 | E66: =Detail!K149 -> 0 | F66: =Detail!K226 -> 0
A67: Free Game | B67: =Detail_Newbie!K79 -> 3590650 | C67: 0 | D67: =Detail!K79 -> 3344481 | E67: 0 | F67: 0

Sheet Detail
A2: Threshold | B2: 1000000000
A3: Coin in | B3: =Overview!A7 -> 100
C5: RTP
B6: Bet | C6: Base Game | D6: Free Game | E6: Total | F6: Hit Rate | G6: FG Period | H6: Avg Multi | I6: BG | J6: FG
A7: Normal Bet | B7: {=Overview!B11:B12} -> 1 | C7: =SUM(M15:M79) -> 0.71999981 | D7: =SUM(_xlfn.ANCHORARRAY(M86))*F7 -> 0.21999995 | E7: =SUM(C7:D7) -> 0.93999976 | F7: =L79 -> 0.0033333328 | G7: =1/F7 -> 300.00005 | H7: =D7*G7 -> 65.999995 | I7: {=LOOKUP(2,1/(K15:K78<>0),P15:P78)} -> 70 | J7: {=LOOKUP(2,1/(_xlfn.ANCHORARRAY(K86)<>0),P15:P78)} -> 20000
A8: Buy Feature | B8: 75 | C8: =M156/B8 -> 0 | D8: =SUM(_xlfn.ANCHORARRAY(M163))/B8 -> 0.92499987 | E8: =SUM(C8:D8) -> 0.92499987 | F8: =D156 -> 1 | G8: =1/F8 -> 1 | H8: =D8*G8*B8 -> 69.37499 | J8: {=LOOKUP(2,1/(_xlfn.ANCHORARRAY(K163)<>0),P15:P78)} -> 20000
A11: Normal Bet | B11: Base Game | G11: Normal Bet | H11: Base Game | O11: Normal Bet | P11: Base Game
A13: Simulate | B13: 1000000000 | G13: Calculate
A14: Range | B14: Cnt | C14: Pay | D14: Hit Rate | E14: Avg. Multi. | G14: Range | H14: Fix Num | I14: Fix Rate | J14: Final Rate | K14: Weight | L14: Hit Rate | M14: Simulator RTP | O14: Lower | P14: Upper | Q14: 目前 | R14: 競品 | T14: 目前 | U14: 差異
A15: ="("&$O15&", "&$P15&"]" -> (-1, 0] | B15: 624764779 | C15: 0 | D15: {=_xlfn.LET(_xlpm.x, B15:B78, _xlpm.x/SUM(_xlpm.x))} -> 0.62476478 | E15: {=_xlfn.LET(_xlpm.x, C15:C79/B15:B79/B3, IF(ISERR(_xlpm.x), 0, _xlpm.x))} -> 0 | G15: ="("&$O15&", "&$P15&"]" -> (-1, 0] | H15: 1.1609664 | I15: {=D15:D79*H15:H79} -> 0.72533089 | J15: {=I15:I78/SUM(I15:I78)} -> 0.72533089 | K15: {=INT(J15:J79*$B$2)} -> 725330891 | L15: {=_xlfn.LET(_xlpm.x, K15:K79, _xlpm.x/SUM(_xlpm.x))} -> 0.72291313 | M15: {=L15:L79*E15:E79} -> 0 | O15: -1 | P15: 0 | Q15: {=L15:L78} -> 0.72291313 | R15: 0.723799 | U15: {=_xlfn.LET(_xlpm.x, T15:T78/L15:L78, IF(ISERR(_xlpm.x), 0, ROUND(_xlpm.x,2)))} -> 0
A16: ="("&$O16&", "&$P16&"]" -> (0, 1] | B16: 143254516 | C16: 6213627750 | D16: 0.14325452 | E16: 0.43374743 | G16: ="("&$O16&", "&$P16&"]" -> (0, 1] | H16: 1.077996 | I16: 0.1544278 | J16: 0.1544278 | K16: 154427797 | L16: 0.15391304 | M16: 0.066759385 | O16: 0 | P16: 1 | Q16: 0.15391304 | R16: 0.154266 | U16: 0
A17: ="("&$O17&", "&$P17&"]" -> (1, 2] | B17: 54941394 | C17: 8271310400 | D17: 0.054941394 | E17: 1.5054788 | G17: ="("&$O17&", "&$P17&"]" -> (1, 2] | H17: 0.82553122 | I17: 0.045355836 | J17: 0.045355836 | K17: 45355835 | L17: 0.04520465 | M17: 0.068054642 | O17: 1 | P17: 2 | Q17: 0.04520465 | R17: 0.045428 | U17: 0
A18: ="("&$O18&", "&$P18&"]" -> (2, 3] | B18: 33052702 | C18: 8367423885 | D18: 0.033052702 | E18: 2.53154 | G18: ="("&$O18&", "&$P18&"]" -> (2, 3] | H18: 0.63002837 | I18: 0.02082414 | J18: 0.02082414 | K18: 20824139 | L18: 0.020754726 | M18: 0.052541419 | O18: 2 | P18: 3 | Q18: 0.020754726 | R18: 0.02091 | U18: 0
A19: ="("&$O19&", "&$P19&"]" -> (3, 4] | B19: 22868741 | C19: 8068853980 | D19: 0.022868741 | E19: 3.5283333 | G19: ="("&$O19&", "&$P19&"]" -> (3, 4] | H19: 0.55979116 | I19: 0.012801719 | J19: 0.012801719 | K19: 12801719 | L19: 0.012759047 | M19: 0.045018169 | O19: 3 | P19: 4 | Q19: 0.012759047 | R19: 0.012886 | U19: 0
A20: ="("&$O20&", "&$P20&"]" -> (4, 5] | B20: 16964682 | C20: 7689266290 | D20: 0.016964682 | E20: 4.5325142 | G20: ="("&$O20&", "&$P20&"]" -> (4, 5] | H20: 0.49104675 | I20: 0.008330452 | J20: 0.008330452 | K20: 8330451 | L20: 0.008302683 | M20: 0.037632029 | O20: 4 | P20: 5 | Q20: 0.008302683 | R20: 0.008406 | U20: 0
A21: ="("&$O21&", "&$P21&"]" -> (5, 6] | B21: 13467081 | C21: 7477223845 | D21: 0.013467081 | E21: 5.5522231 | G21: ="("&$O21&", "&$P21&"]" -> (5, 6] | H21: 0.47836877 | I21: 0.006442231 | J21: 0.006442231 | K21: 6442230 | L21: 0.006420756 | M21: 0.03564947 | O21: 5 | P21: 6 | Q21: 0.006420756 | R21: 0.006517 | U21: 0
A22: ="("&$O22&", "&$P22&"]" -> (6, 7] | B22: 10632034 | C22: 6936975045 | D22: 0.010632034 | E22: 6.5245983 | G22: ="("&$O22&", "&$P22&"]" -> (6, 7] | H22: 0.32686568 | I22: 0.003475247 | J22: 0.003475247 | K22: 3475246 | L22: 0.0034636619 | M22: 0.022599002 | O22: 6 | P22: 7 | Q22: 0.0034636619 | R22: 0.003524 | U22: 0
A23: ="("&$O23&", "&$P23&"]" -> (7, 8] | B23: 8953486 | C23: 6744195935 | D23: 0.008953486 | E23: 7.5324806 | G23: ="("&$O23&", "&$P23&"]" -> (7, 8] | H23: 0.43618486 | I23: 0.003905375 | J23: 0.003905375 | K23: 3905374 | L23: 0.0038923561 | M23: 0.029319097 | O23: 7 | P23: 8 | Q23: 0.0038923561 | R23: 0.00397 | U23: 0
A24: ="("&$O24&", "&$P24&"]" -> (8, 9] | B24: 7534128 | C24: 6443473090 | D24: 0.007534128 | E24: 8.5523807 | G24: ="("&$O24&", "&$P24&"]" -> (8, 9] | H24: 0.42028859 | I24: 0.003166508 | J24: 0.003166508 | K24: 3166507 | L24: 0.003155952 | M24: 0.026990903 | O24: 8 | P24: 9 | Q24: 0.003155952 | R24: 0.003227 | U24: 0
A25: ="("&$O25&", "&$P25&"]" -> (9, 10] | B25: 6231775 | C25: 5943691225 | D25: 0.006231775 | E25: 9.5377179 | G25: ="("&$O25&", "&$P25&"]" -> (9, 10] | H25: 0.3301796 | I25: 0.002057605 | J25: 0.002057605 | K25: 2057605 | L25: 0.0020507463 | M25: 0.01955944 | O25: 9 | P25: 10 | Q25: 0.0020507463 | R25: 0.002102 | U25: 0
A26: ="("&$O26&", "&$P26&"]" -> (10, 15] | B26: 20720821 | C26: 25446656890 | D26: 0.020720821 | E26: 12.280718 | G26: ="("&$O26&", "&$P26&"]" -> (10, 15] | H26: 0.30181695 | I26: 0.006253895 | J26: 0.006253895 | K26: 6253894 | L26: 0.0062330478 | M26: 0.076546305 | O26: 10 | P26: 15 | Q26: 0.0062330478 | R26: 0.006432 | U26: 0
A27: ="("&$O27&", "&$P27&"]" -> (15, 20] | B27: 11152939 | C27: 19336495675 | D27: 0.011152939 | E27: 17.337579 | G27: ="("&$O27&", "&$P27&"]" -> (15, 20] | H27: 0.24306777 | I27: 0.00271092 | J27: 0.00271092 | K27: 2710919 | L27: 0.0027018826 | M27: 0.046844103 | O27: 15 | P27: 20 | Q27: 0.0027018826 | R27: 0.002823 | U27: 0
... A78: ="("&$O78&", "&$P78&"]" -> (100000, 9999999] | B78: 0 | C78: 0 | D78: 0 | E78: 0 | G78: ="("&$O78&", "&$P78&"]" -> (100000, 9999999] | H78: 0 | I78: 0 | J78: 0 | K78: 0 | L78: 0 | M78: 0 | O78: 100000 | P78: 9999999 | Q78: 0 | R78: 0 | U78: 0
A79: Free Game | B79: 7003536 | C79: 6174466305 | D79: =B79/B13 -> 0.007003536 | E79: 8.8162127 | G79: Free Game | H79: 0.47754177 | I79: 0.003344481 | J79: =I79 -> 0.003344481 | K79: 3344481 | L79: 0.0033333328 | M79: 0.029387371
A82: Normal Bet | B82: Free Game | G82: Normal Bet | H82: Free Game | O82: Normal Bet | P82: Free Game
A84: Simulate | G84: Calculate
A85: Range | B85: Cnt | C85: Pay | D85: Hit Rate | E85: Avg. Multi. | G85: Range | H85: Fix Num | I85: Fix Rate | J85: Final Rate | K85: Weight | L85: Hit Rate | M85: Simulator RTP | O85: Lower | P85: Upper | Q85: 目前 | R85: 競品 | T85: 目前 | U85: 差異
A86: ="("&$O86&", "&$P86&"]" -> (-1, 0] | B86: 25733 | C86: 0 | D86: {=_xlfn.LET(_xlpm.x, B86:B149, _xlpm.x/SUM(_xlpm.x))} -> 0.0036742868 | E86: {=_xlfn.LET(_xlpm.x, C86:C149/B86:B149/B3, IF(ISERR(_xlpm.x), 0, _xlpm.x))} -> 0 | G86: ="("&$O86&", "&$P86&"]" -> (-1, 0] | H86: 0 | I86: {=_xlfn.ANCHORARRAY(D86)*H86:H149} -> 0 | J86: {=I86:I149/SUM(_xlfn.ANCHORARRAY(I86))} -> 0 | K86: {=INT(_xlfn.ANCHORARRAY(J86)*$B$2)} -> 0 | L86: {=_xlfn.LET(_xlpm.x, K86:K149, _xlpm.x/SUM(_xlpm.x))} -> 0 | M86: {=L86:L149*_xlfn.ANCHORARRAY(E86)} -> 0 | O86: -1 | P86: 0 | Q86: {=_xlfn.ANCHORARRAY(L86)} -> 0 | R86: 0.02069 | U86: {=_xlfn.LET(_xlpm.x, T86:T149/L86:L149, IF(ISERR(_xlpm.x), 0, ROUND(_xlpm.x,2)))} -> 0
A87: ="("&$O87&", "&$P87&"]" -> (0, 1] | B87: 10103 | C87: 620285 | D87: 0.001442557 | E87: 0.6139612 | G87: ="("&$O87&", "&$P87&"]" -> (0, 1] | H87: 0 | I87: 0 | J87: 0 | K87: 0 | L87: 0 | M87: 0 | O87: 0 | P87: 1 | Q87: 0 | R87: 0.006897 | U87: 0
A88: ="("&$O88&", "&$P88&"]" -> (1, 2] | B88: 12745 | C88: 1986100 | D88: 0.001819795 | E88: 1.5583366 | G88: ="("&$O88&", "&$P88&"]" -> (1, 2] | H88: 0 | I88: 0 | J88: 0 | K88: 0 | L88: 0 | M88: 0 | O88: 1 | P88: 2 | Q88: 0 | R88: 0.006897 | U88: 0
A89: ="("&$O89&", "&$P89&"]" -> (2, 3] | B89: 12974 | C89: 3346690 | D89: 0.0018524928 | E89: 2.579536 | G89: ="("&$O89&", "&$P89&"]" -> (2, 3] | H89: 0 | I89: 0 | J89: 0 | K89: 0 | L89: 0 | M89: 0 | O89: 2 | P89: 3 | Q89: 0 | R89: 0.006897 | U89: 0
A90: ="("&$O90&", "&$P90&"]" -> (3, 4] | B90: 13264 | C90: 4759360 | D90: 0.0018939005 | E90: 3.5881785 | G90: ="("&$O90&", "&$P90&"]" -> (3, 4] | H90: 0 | I90: 0 | J90: 0 | K90: 0 | L90: 0 | M90: 0 | O90: 3 | P90: 4 | Q90: 0 | R90: 0.006897 | U90: 0
A91: ="("&$O91&", "&$P91&"]" -> (4, 5] | B91: 13259 | C91: 6071400 | D91: 0.0018931865 | E91: 4.5790784 | G91: ="("&$O91&", "&$P91&"]" -> (4, 5] | H91: 0 | I91: 0 | J91: 0 | K91: 0 | L91: 0 | M91: 0 | O91: 4 | P91: 5 | Q91: 0 | R91: 0.006897 | U91: 0
A92: ="("&$O92&", "&$P92&"]" -> (5, 6] | B92: 14611 | C92: 8170270 | D92: 0.0020862319 | E92: 5.5918623 | G92: ="("&$O92&", "&$P92&"]" -> (5, 6] | H92: 0 | I92: 0 | J92: 0 | K92: 0 | L92: 0 | M92: 0 | O92: 5 | P92: 6 | Q92: 0 | R92: 0.006897 | U92: 0
A93: ="("&$O93&", "&$P93&"]" -> (6, 7] | B93: 13100 | C93: 8615115 | D93: 0.0018704837 | E93: 6.5764237 | G93: ="("&$O93&", "&$P93&"]" -> (6, 7] | H93: 0 | I93: 0 | J93: 0 | K93: 0 | L93: 0 | M93: 0 | O93: 6 | P93: 7 | Q93: 0 | R93: 0.02069 | U93: 0
A94: ="("&$O94&", "&$P94&"]" -> (7, 8] | B94: 14716 | C94: 11128800 | D94: 0.0021012243 | E94: 7.5623811 | G94: ="("&$O94&", "&$P94&"]" -> (7, 8] | H94: 0 | I94: 0 | J94: 0 | K94: 0 | L94: 0 | M94: 0 | O94: 7 | P94: 8 | Q94: 0 | R94: 0 | U94: 0
A95: ="("&$O95&", "&$P95&"]" -> (8, 9] | B95: 14381 | C95: 12340410 | D95: 0.0020533913 | E95: 8.5810514 | G95: ="("&$O95&", "&$P95&"]" -> (8, 9] | H95: 0 | I95: 0 | J95: 0 | K95: 0 | L95: 0 | M95: 0 | O95: 8 | P95: 9 | Q95: 0 | R95: 0.006897 | U95: 0
A96: ="("&$O96&", "&$P96&"]" -> (9, 10] | B96: 14299 | C96: 13696660 | D96: 0.0020416829 | E96: 9.5787538 | G96: ="("&$O96&", "&$P96&"]" -> (9, 10] | H96: 0 | I96: 0 | J96: 0 | K96: 0 | L96: 0 | M96: 0 | O96: 9 | P96: 10 | Q96: 0 | R96: 0 | U96: 0
A97: ="("&$O97&", "&$P97&"]" -> (10, 15] | B97: 73611 | C97: 92606940 | D97: 0.010510548 | E97: 12.580584 | G97: ="("&$O97&", "&$P97&"]" -> (10, 15] | H97: 0 | I97: 0 | J97: 0 | K97: 0 | L97: 0 | M97: 0 | O97: 10 | P97: 15 | Q97: 0 | R97: 0.062069 | U97: 0
A98: ="("&$O98&", "&$P98&"]" -> (15, 20] | B98: 74130 | C98: 130221780 | D98: 0.010584653 | E98: 17.566677 | G98: ="("&$O98&", "&$P98&"]" -> (15, 20] | H98: 0 | I98: 0 | J98: 0 | K98: 0 | L98: 0 | M98: 0 | O98: 15 | P98: 20 | Q98: 0 | R98: 0.027586 | U98: 0
...

Sheet Detail_Newbie
A2: Threshold | B2: 1000000000
A3: Coin in | B3: =Overview!A7 -> 100
C5: RTP
B6: Bet | C6: Base Game | D6: Free Game | E6: Total | F6: Hit Rate | G6: FG Period | H6: Avg Multi | I6: BG | J6: FG
A7: Normal Bet | B7: =Overview!B11 -> 1 | C7: =SUM(M15:M79) -> 0.71999992 | D7: =SUM(_xlfn.ANCHORARRAY(M86))*F7 -> 0.20999996 | E7: =SUM(C7:D7) -> 0.92999988 | F7: =L79 -> 0.0035778034 | G7: =1/F7 -> 279.5011 | H7: =D7*G7 -> 58.695222 | I7: {=LOOKUP(2,1/(K15:K78<>0),P15:P78)} -> 30 | J7: {=LOOKUP(2,1/(_xlfn.ANCHORARRAY(K86)<>0),P15:P78)} -> 100
A11: Normal Bet | B11: Base Game | G11: Normal Bet | H11: Base Game | O11: Normal Bet | P11: Base Game
A13: Simulate | B13: 1000000000 | G13: Calculate
A14: Range | B14: Cnt | C14: Pay | D14: Hit Rate | E14: Avg. Multi. | G14: Range | H14: Fix Num | I14: Fix Rate | J14: Final Rate | K14: Weight | L14: Hit Rate | M14: Simulator RTP | O14: Lower | P14: Upper | Q14: 目前 | R14: 競品 | T14: 目前 | U14: 差異
A15: ="("&$O15&", "&$P15&"]" -> (-1, 0] | B15: 624764779 | C15: 0 | D15: {=_xlfn.LET(_xlpm.x, B15:B78, _xlpm.x/SUM(_xlpm.x))} -> 0.62476478 | E15: {=_xlfn.LET(_xlpm.x, C15:C79/B15:B79/B3, IF(ISERR(_xlpm.x), 0, _xlpm.x))} -> 0 | G15: ="("&$O15&", "&$P15&"]" -> (-1, 0] | H15: 1.1738236 | I15: {=D15:D79*H15:H79} -> 0.73336367 | J15: {=I15:I78/SUM(I15:I78)} -> 0.73336367 | K15: {=INT(J15:J79*$B$2)} -> 733363665 | L15: {=_xlfn.LET(_xlpm.x, K15:K79, _xlpm.x/SUM(_xlpm.x))} -> 0.73073984 | M15: {=L15:L79*E15:E79} -> 0 | O15: -1 | P15: 0 | Q15: {=L15:L78} -> 0.73073984 | R15: 0.723799 | U15: {=_xlfn.LET(_xlpm.x, T15:T78/L15:L78, IF(ISERR(_xlpm.x), 0, ROUND(_xlpm.x,2)))} -> 0
A16: ="("&$O16&", "&$P16&"]" -> (0, 1] | B16: 143254516 | C16: 6213627750 | D16: 0.14325452 | E16: 0.43374743 | G16: ="("&$O16&", "&$P16&"]" -> (0, 1] | H16: 1.0266594 | I16: 0.1470736 | J16: 0.1470736 | K16: 147073596 | L16: 0.1465474 | M16: 0.063564556 | O16: 0 | P16: 1 | Q16: 0.1465474 | R16: 0.154266 | U16: 0
A17: ="("&$O17&", "&$P17&"]" -> (1, 2] | B17: 54941394 | C17: 8271310400 | D17: 0.054941394 | E17: 1.5054788 | G17: ="("&$O17&", "&$P17&"]" -> (1, 2] | H17: 0.7843523 | I17: 0.043093409 | J17: 0.043093409 | K17: 43093408 | L17: 0.042939229 | M17: 0.064644098 | O17: 1 | P17: 2 | Q17: 0.042939229 | R17: 0.045428 | U17: 0
A18: ="("&$O18&", "&$P18&"]" -> (2, 3] | B18: 33052702 | C18: 8367423885 | D18: 0.033052702 | E18: 2.53154 | G18: ="("&$O18&", "&$P18&"]" -> (2, 3] | H18: 0.597242 | I18: 0.019740462 | J18: 0.019740462 | K18: 19740462 | L18: 0.019669835 | M18: 0.049794974 | O18: 2 | P18: 3 | Q18: 0.019669835 | R18: 0.02091 | U18: 0
A19: ="("&$O19&", "&$P19&"]" -> (3, 4] | B19: 22868741 | C19: 8068853980 | D19: 0.022868741 | E19: 3.5283333 | G19: ="("&$O19&", "&$P19&"]" -> (3, 4] | H19: 0.52949063 | I19: 0.012108784 | J19: 0.012108784 | K19: 12108784 | L19: 0.012065461 | M19: 0.042570968 | O19: 3 | P19: 4 | Q19: 0.012065461 | R19: 0.012886 | U19: 0
A20: ="("&$O20&", "&$P20&"]" -> (4, 5] | B20: 16964682 | C20: 7689266290 | D20: 0.016964682 | E20: 4.5325142 | G20: ="("&$O20&", "&$P20&"]" -> (4, 5] | H20: 0.46343598 | I20: 0.007862044 | J20: 0.007862044 | K20: 7862043 | L20: 0.0078339142 | M20: 0.035507328 | O20: 4 | P20: 5 | Q20: 0.0078339142 | R20: 0.008406 | U20: 0
A21: ="("&$O21&", "&$P21&"]" -> (5, 6] | B21: 13467081 | C21: 7477223845 | D21: 0.013467081 | E21: 5.5522231 | G21: ="("&$O21&", "&$P21&"]" -> (5, 6] | H21: 0.45045151 | I21: 0.006066267 | J21: 0.006066267 | K21: 6066266 | L21: 0.0060445621 | M21: 0.033560758 | O21: 5 | P21: 6 | Q21: 0.0060445621 | R21: 0.006517 | U21: 0
A22: ="("&$O22&", "&$P22&"]" -> (6, 7] | B22: 10632034 | C22: 6936975045 | D22: 0.010632034 | E22: 6.5245983 | G22: ="("&$O22&", "&$P22&"]" -> (6, 7] | H22: 0.30712778 | I22: 0.003265393 | J22: 0.003265393 | K22: 3265393 | L22: 0.0032537101 | M22: 0.021229151 | O22: 6 | P22: 7 | Q22: 0.0032537101 | R22: 0.003524 | U22: 0
A23: ="("&$O23&", "&$P23&"]" -> (7, 8] | B23: 8953486 | C23: 6744195935 | D23: 0.008953486 | E23: 7.5324806 | G23: ="("&$O23&", "&$P23&"]" -> (7, 8] | H23: 0.40893111 | I23: 0.003661359 | J23: 0.003661359 | K23: 3661358 | L23: 0.0036482584 | M23: 0.027480436 | O23: 7 | P23: 8 | Q23: 0.0036482584 | R23: 0.00397 | U23: 0
A24: ="("&$O24&", "&$P24&"]" -> (8, 9] | B24: 7534128 | C24: 6443473090 | D24: 0.007534128 | E24: 8.5523807 | G24: ="("&$O24&", "&$P24&"]" -> (8, 9] | H24: 0.39313826 | I24: 0.002961954 | J24: 0.002961954 | K24: 2961953 | L24: 0.0029513557 | M24: 0.025241118 | O24: 8 | P24: 9 | Q24: 0.0029513557 | R24: 0.003227 | U24: 0
A25: ="("&$O25&", "&$P25&"]" -> (9, 10] | B25: 6231775 | C25: 5943691225 | D25: 0.006231775 | E25: 9.5377179 | G25: ="("&$O25&", "&$P25&"]" -> (9, 10] | H25: 0.30817672 | I25: 0.001920488 | J25: 0.001920488 | K25: 1920487 | L25: 0.0019136159 | M25: 0.018251529 | O25: 9 | P25: 10 | Q25: 0.0019136159 | R25: 0.002102 | U25: 0
A26: ="("&$O26&", "&$P26&"]" -> (10, 15] | B26: 20720821 | C26: 25446656890 | D26: 0.020720821 | E26: 12.280718 | G26: ="("&$O26&", "&$P26&"]" -> (10, 15] | H26: 0.4903311 | I26: 0.010160063 | J26: 0.010160063 | K26: 10160063 | L26: 0.010123712 | M26: 0.12432646 | O26: 10 | P26: 15 | Q26: 0.010123712 | R26: 0.006432 | U26: 0
A27: ="("&$O27&", "&$P27&"]" -> (15, 20] | B27: 11152939 | C27: 19336495675 | D27: 0.011152939 | E27: 17.337579 | G27: ="("&$O27&", "&$P27&"]" -> (15, 20] | H27: 0.3904899 | I27: 0.00435511 | J27: 0.00435511 | K27: 4355109 | L27: 0.0043395273 | M27: 0.075236896 | O27: 15 | P27: 20 | Q27: 0.0043395273 | R27: 0.002823 | U27: 0
... A78: ="("&$O78&", "&$P78&"]" -> (100000, 9999999] | B78: 0 | C78: 0 | D78: 0 | E78: 0 | G78: ="("&$O78&", "&$P78&"]" -> (100000, 9999999] | H78: 0 | I78: 0 | J78: 0 | K78: 0 | L78: 0 | M78: 0 | O78: 100000 | P78: 9999999 | Q78: 0 | R78: 0 | U78: 0
A79: Free Game | B79: 7003536 | C79: 6174466305 | D79: =B79/B13 -> 0.007003536 | E79: 8.8162127 | G79: Free Game | H79: 0.51269102 | I79: 0.00359065 | J79: =I79 -> 0.00359065 | K79: 3590650 | L79: 0.0035778034 | M79: 0.031542676
A82: Normal Bet | B82: Free Game | G82: Normal Bet | H82: Free Game | O82: Normal Bet | P82: Free Game
A84: Simulate | G84: Calculate
A85: Range | B85: Cnt | C85: Pay | D85: Hit Rate | E85: Avg. Multi. | G85: Range | H85: Fix Num | I85: Fix Rate | J85: Final Rate | K85: Weight | L85: Hit Rate | M85: Simulator RTP | O85: Lower | P85: Upper | Q85: 目前 | R85: 競品 | T85: 目前 | U85: 差異
A86: ="("&$O86&", "&$P86&"]" -> (-1, 0] | B86: 25733 | C86: 0 | D86: {=_xlfn.LET(_xlpm.x, B86:B149, _xlpm.x/SUM(_xlpm.x))} -> 0.0036742868 | E86: {=_xlfn.LET(_xlpm.x, C86:C149/B86:B149/B3, IF(ISERR(_xlpm.x), 0, _xlpm.x))} -> 0 | G86: ="("&$O86&", "&$P86&"]" -> (-1, 0] | H86: 0 | I86: {=_xlfn.ANCHORARRAY(D86)*H86:H149} -> 0 | J86: {=I86:I149/SUM(_xlfn.ANCHORARRAY(I86))} -> 0 | K86: {=INT(_xlfn.ANCHORARRAY(J86)*$B$2)} -> 0 | L86: {=_xlfn.LET(_xlpm.x, K86:K149, _xlpm.x/SUM(_xlpm.x))} -> 0 | M86: {=L86:L149*_xlfn.ANCHORARRAY(E86)} -> 0 | O86: -1 | P86: 0 | Q86: {=_xlfn.ANCHORARRAY(L86)} -> 0 | R86: 0.02069 | U86: {=_xlfn.LET(_xlpm.x, T86:T149/L86:L149, IF(ISERR(_xlpm.x), 0, ROUND(_xlpm.x,2)))} -> 0
A87: ="("&$O87&", "&$P87&"]" -> (0, 1] | B87: 10103 | C87: 620285 | D87: 0.001442557 | E87: 0.6139612 | G87: ="("&$O87&", "&$P87&"]" -> (0, 1] | H87: 0 | I87: 0 | J87: 0 | K87: 0 | L87: 0 | M87: 0 | O87: 0 | P87: 1 | Q87: 0 | R87: 0.006897 | U87: 0
A88: ="("&$O88&", "&$P88&"]" -> (1, 2] | B88: 12745 | C88: 1986100 | D88: 0.001819795 | E88: 1.5583366 | G88: ="("&$O88&", "&$P88&"]" -> (1, 2] | H88: 0 | I88: 0 | J88: 0 | K88: 0 | L88: 0 | M88: 0 | O88: 1 | P88: 2 | Q88: 0 | R88: 0.006897 | U88: 0
A89: ="("&$O89&", "&$P89&"]" -> (2, 3] | B89: 12974 | C89: 3346690 | D89: 0.0018524928 | E89: 2.579536 | G89: ="("&$O89&", "&$P89&"]" -> (2, 3] | H89: 0 | I89: 0 | J89: 0 | K89: 0 | L89: 0 | M89: 0 | O89: 2 | P89: 3 | Q89: 0 | R89: 0.006897 | U89: 0
A90: ="("&$O90&", "&$P90&"]" -> (3, 4] | B90: 13264 | C90: 4759360 | D90: 0.0018939005 | E90: 3.5881785 | G90: ="("&$O90&", "&$P90&"]" -> (3, 4] | H90: 0 | I90: 0 | J90: 0 | K90: 0 | L90: 0 | M90: 0 | O90: 3 | P90: 4 | Q90: 0 | R90: 0.006897 | U90: 0
A91: ="("&$O91&", "&$P91&"]" -> (4, 5] | B91: 13259 | C91: 6071400 | D91: 0.0018931865 | E91: 4.5790784 | G91: ="("&$O91&", "&$P91&"]" -> (4, 5] | H91: 0 | I91: 0 | J91: 0 | K91: 0 | L91: 0 | M91: 0 | O91: 4 | P91: 5 | Q91: 0 | R91: 0.006897 | U91: 0
A92: ="("&$O92&", "&$P92&"]" -> (5, 6] | B92: 14611 | C92: 8170270 | D92: 0.0020862319 | E92: 5.5918623 | G92: ="("&$O92&", "&$P92&"]" -> (5, 6] | H92: 0 | I92: 0 | J92: 0 | K92: 0 | L92: 0 | M92: 0 | O92: 5 | P92: 6 | Q92: 0 | R92: 0.006897 | U92: 0
A93: ="("&$O93&", "&$P93&"]" -> (6, 7] | B93: 13100 | C93: 8615115 | D93: 0.0018704837 | E93: 6.5764237 | G93: ="("&$O93&", "&$P93&"]" -> (6, 7] | H93: 0 | I93: 0 | J93: 0 | K93: 0 | L93: 0 | M93: 0 | O93: 6 | P93: 7 | Q93: 0 | R93: 0.02069 | U93: 0
A94: ="("&$O94&", "&$P94&"]" -> (7, 8] | B94: 14716 | C94: 11128800 | D94: 0.0021012243 | E94: 7.5623811 | G94: ="("&$O94&", "&$P94&"]" -> (7, 8] | H94: 0 | I94: 0 | J94: 0 | K94: 0 | L94: 0 | M94: 0 | O94: 7 | P94: 8 | Q94: 0 | R94: 0 | U94: 0
A95: ="("&$O95&", "&$P95&"]" -> (8, 9] | B95: 14381 | C95: 12340410 | D95: 0.0020533913 | E95: 8.5810514 | G95: ="("&$O95&", "&$P95&"]" -> (8, 9] | H95: 0 | I95: 0 | J95: 0 | K95: 0 | L95: 0 | M95: 0 | O95: 8 | P95: 9 | Q95: 0 | R95: 0.006897 | U95: 0
A96: ="("&$O96&", "&$P96&"]" -> (9, 10] | B96: 14299 | C96: 13696660 | D96: 0.0020416829 | E96: 9.5787538 | G96: ="("&$O96&", "&$P96&"]" -> (9, 10] | H96: 0 | I96: 0 | J96: 0 | K96: 0 | L96: 0 | M96: 0 | O96: 9 | P96: 10 | Q96: 0 | R96: 0 | U96: 0
A97: ="("&$O97&", "&$P97&"]" -> (10, 15] | B97: 73611 | C97: 92606940 | D97: 0.010510548 | E97: 12.580584 | G97: ="("&$O97&", "&$P97&"]" -> (10, 15] | H97: 0 | I97: 0 | J97: 0 | K97: 0 | L97: 0 | M97: 0 | O97: 10 | P97: 15 | Q97: 0 | R97: 0.062069 | U97: 0
A98: ="("&$O98&", "&$P98&"]" -> (15, 20] | B98: 74130 | C98: 130221780 | D98: 0.010584653 | E98: 17.566677 | G98: ="("&$O98&", "&$P98&"]" -> (15, 20] | H98: 0 | I98: 0 | J98: 0 | K98: 0 | L98: 0 | M98: 0 | O98: 15 | P98: 20 | Q98: 0 | R98: 0.027586 | U98: 0
... A149: ="("&$O149&", "&$P149&"]" -> (100000, 9999999] | B149: 0 | C149: 0 | D149: 0 | E149: 0 | G149: ="("&$O149&", "&$P149&"]" -> (100000, 9999999] | H149: 0 | I149: 0 | J149: 0 | K149: 0 | L149: 0 | M149: 0 | O149: 100000 | P149: 9999999 | Q149: 0 | R149: 0 | U149: 0

Sheet OP Jackpot
B2: Threshold | C2: 10000000000
B4: Bet Type | C4: SCR
B5: NB_Newbie
B6: EB_Newbie
B7: NB
B8: EB
B9: BF
