Workbook
Name Bet_1: Overview!$A$6
Name Bet_2: Overview!$A$7
Name Bet_3: Overview!$A$8
Name Bet_4: Overview!$A$9

Sheet Overview
A2: Model: | B2: =C2&"-"&B3 -> H020192-1.0.1.4 | C2: H020192
A3: Version: | B3: 1.0.1.4
A4: Hold: | B4: =1-C6 -> 0.079999985
A5: Coin | B5: Payline | C5: Pay Back | D5: Hit% | E5: Big win | F5: Mega win | G5: Jumbo win | H5: RTP(New)
A6: 1 | B6: 5 | C6: ='Multiplier Weight'!O2 -> 0.92000001 | D6: =1-'Multiplier Weight'!N4 -> 0.11403224 | E6: =SUM('Multiplier Weight'!$N$12:$N$61)-F6-G6 -> 0.017704605 | F6: =SUM('Multiplier Weight'!$N$15:$N$61)-G6 -> 0.020362849 | G6: =SUM('Multiplier Weight'!$N$19:$N$61) -> 0.0037195306 | H6: ='Multiplier Weight (new_player)'!O2 -> 0.91999954
A7: 1.5 | B7: 5 | C7: ='Multiplier Weight'!O67 -> 0.91999674 | D7: =1-'Multiplier Weight'!N69 -> 0.11535027 | E7: =SUM('Multiplier Weight'!N79:N126)-F7-G7 -> 0.022973885 | F7: =SUM('Multiplier Weight'!N81:N126)-G7 -> 0.021163181 | G7: =SUM('Multiplier Weight'!N87:N126) -> 0.003685189 | H7: ='Multiplier Weight (new_player)'!O67 -> 0.92000351
A8: 8 | B8: 5 | C8: ='Multiplier Weight'!O132 -> 0.91999937 | D8: =1-'Multiplier Weight'!N134 -> 0.1458621 | E8: =SUM('Multiplier Weight'!N153:N191)-F8-G8 -> 0.0054962516 | F8: =SUM('Multiplier Weight'!N156:N191)-G8 -> 0.023092958 | G8: =SUM('Multiplier Weight'!N164:N191) -> 0.0041767057 | H8: ='Multiplier Weight (new_player)'!O132 -> 0.9199969
A9: 250 | B9: 5 | C9: ='Multiplier Weight'!O197 -> 0.91999585 | D9: =1-'Multiplier Weight'!N199 -> 1 | H9: --
A12: Reel # | B12: 1 | C12: 2 | D12: 3 | E12: 4
A13: Visible Window Size | B13: 3 | C13: 3 | D13: 3 | E13: 3
A18: Feature:
A19: Normal Bet : x1, multiple : 1x, 2x, 3x, 5x, 10x, 15x, 20x, 25x, 50x, 100x, 500x Extra Bet 1 : x1.5, multiple : 1x, 2x, 3x, 5x, 10x, 15x, 20x, 25x, 50x, 100x, 500x Extra Bet 2 : x8, multiple : 1x, 2x, 3x, 5x, 10x, 15x, 20x, 25x, 50x, 100x, 500x Super Feature Buy : x250, 5 Spins multiplier stay, multiple : 1x, 2x, 3x, 5x, 10x, 15x, 20x, 25x, 50x, 100x, 500x
A25: Pay Table： | B25: All wins show for 1 credit bet.
B26: WW | C26: C1*
A27: 5 | B27: 0 | C27: 0
A28: 4 | B28: 0 | C28: 0
A29: 3 | B29: 5 | C29: 0
B30: W1 | C30: W2 | D30: W3
A31: 5 | B31: 0 | C31: 0 | D31: 0
A32: 4 | B32: 0 | C32: 0 | D32: 0
A33: 3 | B33: 4 | C33: 3 | D33: 2.4
B34: WA | C34: WK | D34: WQ | E34: WJ
A35: 5 | B35: 0 | C35: 0 | D35: 0 | E35: 0
A36: 4 | B36: 0 | C36: 0 | D36: 0 | E36: 0
A37: 3 | B37: 2 | C37: 1.6 | D37: 1 | E37: 0.4
A40: For Pay Combo | B40: All wins show for 1 credit bet.
A41: WW | B41: =B29 -> 5
A42: W1 | B42: =B33 -> 4
A43: W2 | B43: =C33 -> 3
A44: W3 | B44: =D33 -> 2.4
A45: WA | B45: =B37 -> 2
A46: WK | B46: =C37 -> 1.6
A47: WQ | B47: =D37 -> 1
A48: WJ | B48: =E37 -> 0.4

Sheet Parameter
B1: Strip Table | F1: Normal Bet Weight | J1: Extra Bet 1 Weight | N1: Extra Bet 2 Weight | R1: Super Feature Buy Weight | V1: Normal Bet R4 | Y1: Extra Bet 1 R4 | AB1: Extra Bet 2 R4 | AE1: Super Feature Buy R4 | AH1: Reel 4 Multiple
B2: {=_xlfn.LET(_xlpm.x, 'Regular Symbol'!BW2:BY211, IF(_xlpm.x="", "", _xlpm.x))} -> R1 | C2: R2 | D2: R3 | F2: {=_xlfn.LET(_xlpm.x, 'Regular Symbol'!AA2:AC211, IF(_xlpm.x="", "", _xlpm.x))} -> R1 | G2: R2 | H2: R3 | J2: {=_xlfn.LET(_xlpm.x, 'Regular Symbol'!AM2:AO211, IF(_xlpm.x="", "", _xlpm.x))} -> R1 | K2: R2 | L2: R3 | N2: {=_xlfn.LET(_xlpm.x, 'Regular Symbol'!AY2:BA211, IF(_xlpm.x="", "", _xlpm.x))} -> R1 | O2: R2 | P2: R3 | R2: {=_xlfn.LET(_xlpm.x, 'Regular Symbol'!BK2:BM211, IF(_xlpm.x="", "", _xlpm.x))} -> R1 | S2: R2 | T2: R3 | V2: Normal | W2: Re-spin | Y2: Normal | Z2: Re-spin | AB2: Normal | AC2: Re-spin | AE2: Normal | AF2: Re-spin | AH2: {='Pay Combo Normal Bet'!$L$2:$N$14} -> R4 Multiplier | AI2: prob. | AJ2: weight
B3: 7 | C3: 0 | D3: 1 | F3: 1 | G3: 1 | H3: 1 | J3: 1 | K3: 1 | L3: 1 | N3: 1 | O3: 1 | P3: 1 | R3: 1 | S3: 1 | T3: 1 | V3: {='Reel 4 Symbol'!AC3:AD211} -> 18 | W3: 30 | Y3: {='Reel 4 Symbol'!AM3:AN211} -> 18 | Z3: 30 | AB3: {='Reel 4 Symbol'!AW3:AX211} -> 18 | AC3: 30 | AE3: {='Reel 4 Symbol'!BG3:BH211} -> 18 | AF3: 30 | AH3: 1 | AI3: 0.2247191 | AJ3: 220000000
B4: 5 | C4: 0 | D4: 1 | F4: 1 | G4: 1 | H4: 1 | J4: 1 | K4: 1 | L4: 1 | N4: 1 | O4: 1 | P4: 1 | R4: 1 | S4: 1 | T4: 1 | V4: 17 | W4: 17 | Y4: 17 | Z4: 17 | AB4: 17 | AC4: 17 | AE4: 17 | AF4: 17 | AH4: 2 | AI4: 0.2247191 | AJ4: 220000000
B5: 5 | C5: 0 | D5: 1 | F5: 1 | G5: 1 | H5: 1 | J5: 1 | K5: 1 | L5: 1 | N5: 1 | O5: 1 | P5: 1 | R5: 1 | S5: 1 | T5: 1 | V5: 16 | W5: 28 | Y5: 16 | Z5: 28 | AB5: 16 | AC5: 28 | AE5: 16 | AF5: 28 | AH5: 3 | AI5: 0.2247191 | AJ5: 220000000
B6: 0 | C6: 7 | D6: 0 | F6: 1 | G6: 1 | H6: 1 | J6: 1 | K6: 1 | L6: 1 | N6: 1 | O6: 1 | P6: 1 | R6: 1 | S6: 1 | T6: 1 | V6: 12 | W6: 12 | Y6: 12 | Z6: 12 | AB6: 12 | AC6: 12 | AE6: 12 | AF6: 12 | AH6: 5 | AI6: 0.06639428 | AJ6: 65000000
B7: 0 | C7: 7 | D7: 0 | F7: 1 | G7: 1 | H7: 1 | J7: 1 | K7: 1 | L7: 1 | N7: 1 | O7: 1 | P7: 1 | R7: 1 | S7: 1 | T7: 1 | V7: 13 | W7: 25 | Y7: 13 | Z7: 25 | AB7: 13 | AC7: 25 | AE7: 13 | AF7: 25 | AH7: 10 | AI7: 0.030643514 | AJ7: 30000000
B8: 0 | C8: 4 | D8: 0 | F8: 1 | G8: 1 | H8: 1 | J8: 1 | K8: 1 | L8: 1 | N8: 1 | O8: 1 | P8: 1 | R8: 1 | S8: 1 | T8: 1 | V8: 15 | W8: 15 | Y8: 15 | Z8: 15 | AB8: 15 | AC8: 15 | AE8: 15 | AF8: 15 | AH8: 15 | AI8: 0.010214505 | AJ8: 10000000
B9: 4 | C9: 4 | D9: 4 | F9: 1 | G9: 1 | H9: 1 | J9: 1 | K9: 1 | L9: 1 | N9: 1 | O9: 1 | P9: 1 | R9: 1 | S9: 1 | T9: 1 | V9: 14 | W9: 26 | Y9: 14 | Z9: 26 | AB9: 14 | AC9: 26 | AE9: 14 | AF9: 26 | AH9: 20 | AI9: 0.0051072523 | AJ9: 5000000
B10: 4 | C10: 4 | D10: 4 | F10: 1 | G10: 1 | H10: 1 | J10: 1 | K10: 1 | L10: 1 | N10: 1 | O10: 1 | P10: 1 | R10: 1 | S10: 1 | T10: 1 | V10: 11 | W10: 11 | Y10: 11 | Z10: 11 | AB10: 13 | AC10: 13 | AE10: 11 | AF10: 11 | AH10: 25 | AI10: 0.0020429009 | AJ10: 2000000
B11: 4 | C11: 2 | D11: 4 | F11: 1 | G11: 1 | H11: 1 | J11: 1 | K11: 1 | L11: 1 | N11: 1 | O11: 1 | P11: 1 | R11: 1 | S11: 1 | T11: 1 | V11: 10 | W11: 22 | Y11: 10 | Z11: 22 | AB11: 12 | AC11: 24 | AE11: 10 | AF11: 22 | AH11: 50 | AI11: 0.0020429009 | AJ11: 2000000
B12: 2 | C12: 2 | D12: 2 | F12: 1 | G12: 1 | H12: 1 | J12: 1 | K12: 1 | L12: 1 | N12: 1 | O12: 1 | P12: 1 | R12: 1 | S12: 1 | T12: 1 | V12: 19 | W12: 11 | Y12: 19 | Z12: 11 | AB12: 19 | AC12: 12 | AE12: 19 | AF12: 11 | AH12: 100 | AI12: 0.0020429009 | AJ12: 2000000
B13: 2 | C13: 2 | D13: 2 | F13: 1 | G13: 1 | H13: 1 | J13: 1 | K13: 1 | L13: 1 | N13: 1 | O13: 1 | P13: 1 | R13: 1 | S13: 1 | T13: 1 | V13: 9 | W13: 21 | Y13: 9 | Z13: 21 | AB13: 12 | AC13: 24 | AE13: 9 | AF13: 21 | AH13: 500 | AI13: 0.0030643514 | AJ13: 3000000
B14: 5 | C14: 5 | D14: 2 | F14: 1 | G14: 1 | H14: 1 | J14: 1 | K14: 1 | L14: 1 | N14: 1 | O14: 1 | P14: 1 | R14: 1 | S14: 1 | T14: 1 | V14: 8 | W14: 8 | Y14: 9 | Z14: 9 | AB14: 13 | AC14: 13 | AE14: 9 | AF14: 9 | AH14: Re-spin | AI14: 0.20429009 | AJ14: 200000000
B15: 5 | C15: 5 | D15: 5 | F15: 1 | G15: 1 | H15: 1 | J15: 1 | K15: 1 | L15: 1 | N15: 1 | O15: 1 | P15: 1 | R15: 1 | S15: 1 | T15: 1 | V15: 11 | W15: 23 | Y15: 11 | Z15: 23 | AB15: 14 | AC15: 26 | AE15: 11 | AF15: 23
B16: 1 | C16: 5 | D16: 5 | F16: 1 | G16: 1 | H16: 1 | J16: 1 | K16: 1 | L16: 1 | N16: 1 | O16: 1 | P16: 1 | R16: 1 | S16: 1 | T16: 1 | V16: 12 | W16: 12 | Y16: 12 | Z16: 12 | AB16: 12 | AC16: 12 | AE16: 12 | AF16: 12
B17: 1 | C17: 4 | D17: 5 | F17: 1 | G17: 1 | H17: 1 | J17: 1 | K17: 1 | L17: 1 | N17: 1 | O17: 1 | P17: 1 | R17: 1 | S17: 1 | T17: 1 | V17: 13 | W17: 25 | Y17: 13 | Z17: 25 | AB17: 13 | AC17: 25 | AE17: 13 | AF17: 25 | AH17: Re-spin times
B18: 1 | C18: 4 | D18: 1 | F18: 1 | G18: 1 | H18: 1 | J18: 1 | K18: 1 | L18: 1 | N18: 1 | O18: 1 | P18: 1 | R18: 1 | S18: 1 | T18: 1 | V18: 14 | W18: 14 | Y18: 14 | Z18: 14 | AB18: 14 | AC18: 14 | AE18: 14 | AF18: 14 | AH18: {='Pay Combo Normal Bet'!$Q$2:$S$13} -> Re-spin times | AI18: prob. | AJ18: weight
B19: 7 | C19: 4 | D19: 1 | F19: 1 | G19: 1 | H19: 1 | J19: 1 | K19: 1 | L19: 1 | N19: 1 | O19: 1 | P19: 1 | R19: 1 | S19: 1 | T19: 1 | V19: 15 | W19: 27 | Y19: 15 | Z19: 27 | AB19: 15 | AC19: 27 | AE19: 15 | AF19: 27 | AH19: 2 | AI19: 0.11111111 | AJ19: 120000000
B20: 7 | C20: 2 | D20: 1 | F20: 1 | G20: 1 | H20: 1 | J20: 1 | K20: 1 | L20: 1 | N20: 1 | O20: 1 | P20: 1 | R20: 1 | S20: 1 | T20: 1 | V20: 16 | W20: 16 | Y20: 16 | Z20: 16 | AB20: 16 | AC20: 16 | AE20: 16 | AF20: 16 | AH20: 3 | AI20: 0.11111111 | AJ20: 120000000
B21: 2 | C21: 2 | D21: 3 | F21: 1 | G21: 1 | H21: 1 | J21: 1 | K21: 1 | L21: 1 | N21: 1 | O21: 1 | P21: 1 | R21: 1 | S21: 1 | T21: 1 | V21: 17 | W21: 29 | Y21: 17 | Z21: 29 | AB21: 17 | AC21: 29 | AE21: 17 | AF21: 29 | AH21: 4 | AI21: 0.11111111 | AJ21: 120000000
B22: 2 | C22: 2 | D22: 3 | F22: 1 | G22: 1 | H22: 1 | J22: 1 | K22: 1 | L22: 1 | N22: 1 | O22: 1 | P22: 1 | R22: 1 | S22: 1 | T22: 1 | V22: 13 | W22: 13 | Y22: 13 | Z22: 13 | AB22: 13 | AC22: 13 | AE22: 13 | AF22: 13 | AH22: 5 | AI22: 0.11111111 | AJ22: 120000000
B23: 4 | C23: 4 | D23: 6 | F23: 1 | G23: 1 | H23: 1 | J23: 1 | K23: 1 | L23: 1 | N23: 1 | O23: 1 | P23: 1 | R23: 1 | S23: 1 | T23: 1 | V23: 12 | W23: 24 | Y23: 12 | Z23: 24 | AB23: 12 | AC23: 24 | AE23: 12 | AF23: 24 | AH23: 6 | AI23: 0.11111111 | AJ23: 120000000
B24: 4 | C24: 4 | D24: 6 | F24: 1 | G24: 1 | H24: 1 | J24: 1 | K24: 1 | L24: 1 | N24: 1 | O24: 1 | P24: 1 | R24: 1 | S24: 1 | T24: 1 | V24: 16 | W24: 16 | Y24: 16 | Z24: 16 | AB24: 16 | AC24: 16 | AE24: 16 | AF24: 16 | AH24: 7 | AI24: 0.074074074 | AJ24: 80000000
B25: 4 | C25: 0 | D25: 6 | F25: 1 | G25: 1 | H25: 1 | J25: 1 | K25: 1 | L25: 1 | N25: 1 | O25: 1 | P25: 1 | R25: 1 | S25: 1 | T25: 1 | V25: 15 | W25: 15 | Y25: 15 | Z25: 15 | AB25: 15 | AC25: 15 | AE25: 15 | AF25: 15 | AH25: 8 | AI25: 0.074074074 | AJ25: 80000000
B26: 3 | C26: 0 | D26: 4 | F26: 1 | G26: 1 | H26: 1 | J26: 1 | K26: 1 | L26: 1 | N26: 1 | O26: 1 | P26: 1 | R26: 1 | S26: 1 | T26: 1 | V26: 14 | W26: 14 | Y26: 14 | Z26: 14 | AB26: 14 | AC26: 14 | AE26: 14 | AF26: 14 | AH26: 9 | AI26: 0.074074074 | AJ26: 80000000
B27: 3 | C27: 0 | D27: 4 | F27: 1 | G27: 1 | H27: 1 | J27: 1 | K27: 1 | L27: 1 | N27: 1 | O27: 1 | P27: 1 | R27: 1 | S27: 1 | T27: 1 | V27: 11 | W27: 23 | Y27: 11 | Z27: 23 | AB27: 13 | AC27: 25 | AE27: 11 | AF27: 23 | AH27: 10 | AI27: 0.074074074 | AJ27: 80000000
B28: 6 | C28: 6 | D28: 4 | F28: 1 | G28: 1 | H28: 1 | J28: 1 | K28: 1 | L28: 1 | N28: 1 | O28: 1 | P28: 1 | R28: 1 | S28: 1 | T28: 1 | V28: 9 | W28: 9 | Y28: 9 | Z28: 9 | AB28: 12 | AC28: 12 | AE28: 9 | AF28: 9 | AH28: 20 | AI28: 0.074074074 | AJ28: 80000000
B29: 6 | C29: 6 | D29: 2 | F29: 1 | G29: 1 | H29: 1 | J29: 1 | K29: 1 | L29: 1 | N29: 1 | O29: 1 | P29: 1 | R29: 1 | S29: 1 | T29: 1 | V29: 19 | W29: 22 | Y29: 19 | Z29: 22 | AB29: 19 | AC29: 25 | AE29: 19 | AF29: 22 | AH29: 50 | AI29: 0.074074074 | AJ29: 80000000
B30: 1 | C30: 3 | D30: 2 | F30: 1 | G30: 1 | H30: 1 | J30: 1 | K30: 1 | L30: 1 | N30: 1 | O30: 1 | P30: 1 | R30: 1 | S30: 1 | T30: 1 | V30: 8 | W30: 8 | Y30: 9 | Z30: 9 | AB30: 12 | AC30: 12 | AE30: 9 | AF30: 9
B31: 1 | C31: 3 | D31: 7 | F31: 1 | G31: 1 | H31: 1 | J31: 1 | K31: 1 | L31: 1 | N31: 1 | O31: 1 | P31: 1 | R31: 1 | S31: 1 | T31: 1 | V31: 10 | W31: 22 | Y31: 10 | Z31: 22 | AB31: 13 | AC31: 13 | AE31: 10 | AF31: 22
B32: 7 | C32: 3 | D32: 7 | F32: 1 | G32: 1 | H32: 1 | J32: 1 | K32: 1 | L32: 1 | N32: 1 | O32: 1 | P32: 1 | R32: 1 | S32: 1 | T32: 1 | V32: 11 | W32: 11 | Y32: 11 | Z32: 11 | AB32: 12 | AC32: 12 | AE32: 11 | AF32: 11 | AH32: Multiple per Re-spin
B33: 7 | C33: 6 | D33: 7 | F33: 1 | G33: 1 | H33: 1 | J33: 1 | K33: 1 | L33: 1 | N33: 1 | O33: 1 | P33: 1 | R33: 1 | S33: 1 | T33: 1 | V33: 12 | W33: 24 | Y33: 12 | Z33: 24 | AB33: 12 | AC33: 24 | AE33: 12 | AF33: 24 | AH33: 倍數\nudge次數 | AI33: {='Pay Combo Normal Bet'!$AH$2:$AR$13} -> 2 | AJ33: 3 | AK33: 4 | AL33: 5 | AM33: 6 | AN33: 7 | AO33: 8 | AP33: 9 | AQ33: 10 | AR33: 20 | AS33: 50
B34: 2 | C34: 6 | D34: 0 | F34: 1 | G34: 1 | H34: 1 | J34: 1 | K34: 1 | L34: 1 | N34: 1 | O34: 1 | P34: 1 | R34: 1 | S34: 1 | T34: 1 | V34: 13 | W34: 13 | Y34: 13 | Z34: 13 | AB34: 13 | AC34: 13 | AE34: 13 | AF34: 13 | AH34: {='Pay Combo Normal Bet'!$V$3:$V$13} -> 1 | AI34: 0 | AJ34: 0 | AK34: 0 | AL34: 0 | AM34: 0 | AN34: 0 | AO34: 0 | AP34: 0 | AQ34: 265000000 | AR34: 265000000 | AS34: 265000000
B35: 2 | C35: 6 | D35: 0 | F35: 1 | G35: 1 | H35: 1 | J35: 1 | K35: 1 | L35: 1 | N35: 1 | O35: 1 | P35: 1 | R35: 1 | S35: 1 | T35: 1 | V35: 14 | W35: 26 | Y35: 14 | Z35: 26 | AB35: 14 | AC35: 26 | AE35: 14 | AF35: 26 | AH35: 2 | AI35: 0 | AJ35: 0 | AK35: 0 | AL35: 250000000 | AM35: 250000000 | AN35: 250000000 | AO35: 240000000 | AP35: 240000000 | AQ35: 240000000 | AR35: 240000000 | AS35: 240000000
B36: 5 | C36: 2 | D36: 0 | F36: 1 | G36: 1 | H36: 1 | J36: 1 | K36: 1 | L36: 1 | N36: 1 | O36: 1 | P36: 1 | R36: 1 | S36: 1 | T36: 1 | V36: 15 | W36: 15 | Y36: 15 | Z36: 15 | AB36: 15 | AC36: 15 | AE36: 15 | AF36: 15 | AH36: 3 | AI36: 0 | AJ36: 250000000 | AK36: 250000000 | AL36: 200000000 | AM36: 200000000 | AN36: 200000000 | AO36: 170000000 | AP36: 170000000 | AQ36: 170000000 | AR36: 170000000 | AS36: 170000000
B37: 5 | C37: 2 | D37: 6 | F37: 1 | G37: 1 | H37: 1 | J37: 1 | K37: 1 | L37: 1 | N37: 1 | O37: 1 | P37: 1 | R37: 1 | S37: 1 | T37: 1 | V37: 16 | W37: 28 | Y37: 16 | Z37: 28 | AB37: 16 | AC37: 28 | AE37: 16 | AF37: 28 | AH37: 5 | AI37: 150000000 | AJ37: 150000000 | AK37: 150000000 | AL37: 160000000 | AM37: 160000000 | AN37: 160000000 | AO37: 130000000 | AP37: 130000000 | AQ37: 130000000 | AR37: 130000000 | AS37: 130000000
B38: 1 | C38: 2 | D38: 6 | F38: 1 | G38: 1 | H38: 1 | J38: 1 | K38: 1 | L38: 1 | N38: 1 | O38: 1 | P38: 1 | R38: 1 | S38: 1 | T38: 1 | V38: 18 | W38: 18 | Y38: 18 | Z38: 18 | AB38: 18 | AC38: 18 | AE38: 18 | AF38: 18 | AH38: 10 | AI38: 100000000 | AJ38: 100000000 | AK38: 100000000 | AL38: 80000000 | AM38: 80000000 | AN38: 80000000 | AO38: 80000000 | AP38: 80000000 | AQ38: 80000000 | AR38: 80000000 | AS38: 80000000
B39: 1 | C39: 5 | D39: 6 | F39: 1 | G39: 1 | H39: 1 | J39: 1 | K39: 1 | L39: 1 | N39: 1 | O39: 1 | P39: 1 | R39: 1 | S39: 1 | T39: 1 | V39: 17 | W39: 17 | Y39: 17 | Z39: 17 | AB39: 17 | AC39: 17 | AE39: 17 | AF39: 17 | AH39: 15 | AI39: 80000000 | AJ39: 80000000 | AK39: 80000000 | AL39: 50000000 | AM39: 50000000 | AN39: 50000000 | AO39: 50000000 | AP39: 50000000 | AQ39: 50000000 | AR39: 50000000 | AS39: 50000000
B40: 7 | C40: 5 | D40: 6 | F40: 1 | G40: 1 | H40: 1 | J40: 1 | K40: 1 | L40: 1 | N40: 1 | O40: 1 | P40: 1 | R40: 1 | S40: 1 | T40: 1 | V40: 9 | W40: 9 | Y40: 9 | Z40: 9 | AB40: 15 | AC40: 27 | AE40: 9 | AF40: 9 | AH40: 20 | AI40: 20000000 | AJ40: 20000000 | AK40: 20000000 | AL40: 20000000 | AM40: 20000000 | AN40: 20000000 | AO40: 20000000 | AP40: 20000000 | AQ40: 20000000 | AR40: 20000000 | AS40: 20000000
...

Sheet Parameter-卡片
C1: Normal Bet Weight | D1: Extra Bet 1 Weight | E1: Extra Bet 2 Weight | F1: Super Feature Buy Weight | G1: Normal Bet Weight | H1: Extra Bet 1 Weight | I1: Extra Bet 2 Weight | J1: Super Feature Buy Weight
A2: {='Multiplier Weight'!A3:B61} -> Lower | B2: Upper | C2: {='Multiplier Weight'!M3:M61} -> Fixed Weight | D2: {='Multiplier Weight'!M68:M126} -> Fixed Weight | E2: {='Multiplier Weight'!M133:M191} -> Fixed Weight | F2: {='Multiplier Weight'!M198:M256} -> Fixed Weight | G2: {='Multiplier Weight (new_player)'!M3:M61} -> Fixed Weight | H2: {='Multiplier Weight (new_player)'!M68:M126} -> Fixed Weight | I2: {='Multiplier Weight (new_player)'!M133:M191} -> Fixed Weight | J2: {='Multiplier Weight (new_player)'!#REF!} -> #REF! | L2: Scatter Combo Rate
A3: -1 | B3: 0 | C3: 885913313 | D3: 884641100 | E3: 110431432 | F3: 0 | G3: 195166480 | H3: 1048252570 | I3: 289747728 | M3: Normal | N3: EX1 | O3: EX2 | P3: Super Buy
A4: 0 | B4: 1 | C4: 11764624 | D4: 4036131 | E4: 0 | F4: 0 | G4: 1221030 | H4: 12210300 | I4: 0 | L4: 老手 | M4: 3736664782 | N4: 4093759000 | O4: 3100258235 | P4: 31318315000
A5: 1 | B5: 2 | C5: 16365756 | D5: 11713167 | E5: 0 | F5: 0 | G5: 1983581 | H5: 19835810 | I5: 0 | L5: 新手 | M5: 3731618775 | N5: 4085671071 | O5: 3139769444 | P5: --
A6: 2 | B6: 3 | C6: 11623926 | D6: 6004218 | E6: 0 | F6: 0 | G6: 1400402 | H6: 14004020 | I6: 0
A7: 3 | B7: 4 | C7: 12367038 | D7: 11078967 | E7: 0 | F7: 0 | G7: 1843384 | H7: 15287872 | I7: 0
A8: 4 | B8: 5 | C8: 10095520 | D8: 10345960 | E8: 0 | F8: 0 | G8: 1261039 | H8: 10458267 | I8: 0
A9: 5 | B9: 6 | C9: 8063906 | D9: 9145346 | E9: 0 | F9: 0 | G9: 1254493 | H9: 10403979 | I9: 0
A10: 6 | B10: 7 | C10: 1960044 | D10: 2087574 | E10: 0 | F10: 0 | G10: 316037 | H10: 2621012 | I10: 0
A11: 7 | B11: 8 | C11: 8419726 | D11: 9519892 | E11: 4346920 | F11: 0 | G11: 3291012 | H11: 10917438 | I11: 10867300
A12: 8 | B12: 9 | C12: 3082035 | D12: 3596097 | E12: 0 | F12: 0 | G12: 717711 | H12: 4761798 | I12: 0
A13: 9 | B13: 10 | C13: 6201756 | D13: 8367532 | E13: 3277630 | F13: 0 | G13: 892300 | H13: 5920141 | I13: 1638815
A14: 10 | B14: 15 | C14: 9885740 | D14: 14606129 | E14: 523644 | F14: 0 | G14: 4477577 | H14: 8955155 | I14: 1309110
A15: 15 | B15: 20 | C15: 5874476 | D15: 9202792 | E15: 1800254 | F15: 0 | G15: 1124732 | H15: 22494640 | I15: 4500635
A16: 20 | B16: 25 | C16: 2464217 | D16: 5141385 | E16: 1134864 | F16: 0 | G16: 1554967 | H16: 3109935 | I16: 2837160
A17: 25 | B17: 30 | C17: 2137165 | D17: 3428356 | E17: 900740 | F17: 0 | G17: 541256 | H17: 2165025 | I17: 2251850
... A60: 100000 | B60: 999999 | C60: 0 | D60: 0 | E60: 0 | F60: 0 | G60: 0 | H60: 0 | I60: 0

Sheet Regular Symbol
A1: Normal Bet Row 1 | H1: Normal Bet Row 2 | O1: Normal Bet Row 3 | V1: Symbol | AA1: Normal Row 1 | AE1: Normal Row 2 | AI1: Normal Row 3 | AM1: Extra Bet 1 Row 1 | AQ1: Extra Bet 1 Row 2 | AU1: Extra Bet 1 Row 3 | AY1: Extra Bet 2 Row 1 | BC1: Extra Bet 2 Row 2 | BG1: Extra Bet 2 Row 3 | BK1: Super Feature Buy Row 1 | BO1: Super Feature Buy Row 2 | BS1: Super Feature Buy Row 3 | BW1: ID | CA1: Description
A2: Symbol | B2: Symbol Name | C2: R1 | D2: R2 | E2: R3 | F2: ID | H2: Symbol | I2: Symbol Name | J2: R1 | K2: R2 | L2: R3 | M2: ID | O2: Symbol | P2: Symbol Name | Q2: R1 | R2: R2 | S2: R3 | T2: ID | V2: Line # | W2: R1 | X2: R2 | Y2: R3 | AA2: R1 | AB2: R2 | AC2: R3 | AE2: R1 | AF2: R2 | AG2: R3 | AI2: R1 | AJ2: R2 | AK2: R3 | AM2: R1 | AN2: R2 | AO2: R3 | AQ2: R1 | AR2: R2 | AS2: R3 | AU2: R1 | AV2: R2 | AW2: R3 | AY2: R1 | AZ2: R2 | BA2: R3 | BC2: R1 | BD2: R2 | BE2: R3 | BG2: R1 | BH2: R2 | BI2: R3 | BK2: R1 | BL2: R2 | BM2: R3 | BO2: R1 | BP2: R2 | BQ2: R3 | BS2: R1 | BT2: R2 | BU2: R3 | BW2: R1 | BX2: R2 | BY2: R3 | CA2: R1 | CB2: R2 | CC2: R3
A3: WW | B3: Wild | C3: =SUMIF(W$3:W$211, $A3, AA$3:AA$211) -> 9 | D3: =SUMIF(X$3:X$211, $A3, AB$3:AB$211) -> 21 | E3: =SUMIF(Y$3:Y$211, $A3, AC$3:AC$211) -> 21 | F3: 0 | H3: {=A3:B10} -> WW | I3: Wild | J3: =SUMIF(W$3:W$211, $H3, AE$3:AE$211) -> 9 | K3: =SUMIF(X$3:X$211, $H3, AF$3:AF$211) -> 21 | L3: =SUMIF(Y$3:Y$211, $H3, AG$3:AG$211) -> 21 | M3: 0 | O3: {=_xlfn.ANCHORARRAY(H3)} -> WW | P3: Wild | Q3: =SUMIF(W$3:W$211, $H3, AI$3:AI$211) -> 9 | R3: =SUMIF(X$3:X$211, $H3, AJ$3:AJ$211) -> 21 | S3: =SUMIF(Y$3:Y$211, $H3, AK$3:AK$211) -> 21 | T3: 0 | V3: 0 | W3: J | X3: WW | Y3: M1 | AA3: 1 | AB3: 1 | AC3: 1 | AE3: =OFFSET(AA$2,COUNTA(AA$3:AA$211),0) -> 1 | AF3: =OFFSET(AB$2,COUNTA(AB$3:AB$211),0) -> 1 | AG3: =OFFSET(AC$2,COUNTA(AC$3:AC$211),0) -> 1 | AI3: =OFFSET(AA$2,COUNTA(AA$3:AA$211)-1,0) -> 1 | AJ3: =OFFSET(AB$2,COUNTA(AB$3:AB$211)-1,0) -> 1 | AK3: =OFFSET(AC$2,COUNTA(AC$3:AC$211)-1,0) -> 1 | AM3: 1 | AN3: 1 | AO3: 1 | AQ3: =OFFSET(AM$2,COUNTA(AM$3:AM$211),0) -> 1 | AR3: =OFFSET(AN$2,COUNTA(AN$3:AN$211),0) -> 1 | AS3: =OFFSET(AO$2,COUNTA(AO$3:AO$211),0) -> 1 | AU3: =OFFSET(AM$2,COUNTA(AM$3:AM$211)-1,0) -> 1 | AV3: =OFFSET(AN$2,COUNTA(AN$3:AN$211)-1,0) -> 1 | AW3: =OFFSET(AO$2,COUNTA(AO$3:AO$211)-1,0) -> 1 | AY3: 1 | AZ3: 1 | BA3: 1 | BC3: =OFFSET(AY$2,COUNTA(AY$3:AY$211),0) -> 1 | BD3: =OFFSET(AZ$2,COUNTA(AZ$3:AZ$211),0) -> 1 | BE3: =OFFSET(BA$2,COUNTA(BA$3:BA$211),0) -> 1 | BG3: =OFFSET(AY$2,COUNTA(AY$3:AY$211)-1,0) -> 1 | BH3: =OFFSET(AZ$2,COUNTA(AZ$3:AZ$211)-1,0) -> 1 | BI3: =OFFSET(BA$2,COUNTA(BA$3:BA$211)-1,0) -> 1 | BK3: 1 | BL3: 1 | BM3: 1 | BO3: =OFFSET(BK$2,COUNTA(BK$3:BK$211),0) -> 1 | BP3: =OFFSET(BL$2,COUNTA(BL$3:BL$211),0) -> 1 | BQ3: =OFFSET(BM$2,COUNTA(BM$3:BM$211),0) -> 1 | BS3: =OFFSET(BK$2,COUNTA(BK$3:BK$211)-1,0) -> 1 | BT3: =OFFSET(BL$2,COUNTA(BL$3:BL$211)-1,0) -> 1 | BU3: =OFFSET(BM$2,COUNTA(BM$3:BM$211)-1,0) -> 1 | BW3: =IF(W3="","",VLOOKUP('Regular Symbol'!W3,'Regular Symbol'!$O$3:$T$13,6,0)) -> 7 | BX3: =IF(X3="","",VLOOKUP('Regular Symbol'!X3,'Regular Symbol'!$O$3:$T$13,6,0)) -> 0 | BY3: =IF(Y3="","",VLOOKUP('Regular Symbol'!Y3,'Regular Symbol'!$O$3:$T$13,6,0)) -> 1 | CA3: =IF(W3<>"", VLOOKUP(W3,$O$3:$P$13,2,0), "") -> J | CB3: =IF(X3<>"", VLOOKUP(X3,$O$3:$P$13,2,0), "") -> Wild | CC3: =IF(Y3<>"", VLOOKUP(Y3,$O$3:$P$13,2,0), "") -> M1
A4: M1 | B4: M1 | C4: =SUMIF(W$3:W$211, $A4, AA$3:AA$211) -> 14 | D4: =SUMIF(X$3:X$211, $A4, AB$3:AB$211) -> 24 | E4: =SUMIF(Y$3:Y$211, $A4, AC$3:AC$211) -> 23 | F4: 1 | H4: M1 | I4: M1 | J4: =SUMIF(W$3:W$211, $H4, AE$3:AE$211) -> 14 | K4: =SUMIF(X$3:X$211, $H4, AF$3:AF$211) -> 24 | L4: =SUMIF(Y$3:Y$211, $H4, AG$3:AG$211) -> 23 | M4: 1 | O4: M1 | P4: M1 | Q4: =SUMIF(W$3:W$211, $H4, AI$3:AI$211) -> 14 | R4: =SUMIF(X$3:X$211, $H4, AJ$3:AJ$211) -> 24 | S4: =SUMIF(Y$3:Y$211, $H4, AK$3:AK$211) -> 23 | T4: 1 | V4: 1 | W4: K | X4: WW | Y4: M1 | AA4: 1 | AB4: 1 | AC4: 1 | AE4: =IF(AA3="","",AA3) -> 1 | AF4: =IF(AB3="","",AB3) -> 1 | AG4: =IF(AC3="","",AC3) -> 1 | AI4: =OFFSET(AA$2,COUNTA(AA$3:AA$211),0) -> 1 | AJ4: =OFFSET(AB$2,COUNTA(AB$3:AB$211),0) -> 1 | AK4: =OFFSET(AC$2,COUNTA(AC$3:AC$211),0) -> 1 | AM4: 1 | AN4: 1 | AO4: 1 | AQ4: =IF(AM3="","",AM3) -> 1 | AR4: =IF(AN3="","",AN3) -> 1 | AS4: =IF(AO3="","",AO3) -> 1 | AU4: =OFFSET(AM$2,COUNTA(AM$3:AM$211),0) -> 1 | AV4: =OFFSET(AN$2,COUNTA(AN$3:AN$211),0) -> 1 | AW4: =OFFSET(AO$2,COUNTA(AO$3:AO$211),0) -> 1 | AY4: 1 | AZ4: 1 | BA4: 1 | BC4: =IF(AY3="","",AY3) -> 1 | BD4: =IF(AZ3="","",AZ3) -> 1 | BE4: =IF(BA3="","",BA3) -> 1 | BG4: =OFFSET(AY$2,COUNTA(AY$3:AY$211),0) -> 1 | BH4: =OFFSET(AZ$2,COUNTA(AZ$3:AZ$211),0) -> 1 | BI4: =OFFSET(BA$2,COUNTA(BA$3:BA$211),0) -> 1 | BK4: 1 | BL4: 1 | BM4: 1 | BO4: =IF(BK3="","",BK3) -> 1 | BP4: =IF(BL3="","",BL3) -> 1 | BQ4: =IF(BM3="","",BM3) -> 1 | BS4: =OFFSET(BK$2,COUNTA(BK$3:BK$211),0) -> 1 | BT4: =OFFSET(BL$2,COUNTA(BL$3:BL$211),0) -> 1 | BU4: =OFFSET(BM$2,COUNTA(BM$3:BM$211),0) -> 1 | BW4: =IF(W4="","",VLOOKUP('Regular Symbol'!W4,'Regular Symbol'!$O$3:$T$13,6,0)) -> 5 | BX4: =IF(X4="","",VLOOKUP('Regular Symbol'!X4,'Regular Symbol'!$O$3:$T$13,6,0)) -> 0 | BY4: =IF(Y4="","",VLOOKUP('Regular Symbol'!Y4,'Regular Symbol'!$O$3:$T$13,6,0)) -> 1 | CA4: =IF(W4<>"", VLOOKUP(W4,$O$3:$P$13,2,0), "") -> K | CB4: =IF(X4<>"", VLOOKUP(X4,$O$3:$P$13,2,0), "") -> Wild | CC4: =IF(Y4<>"", VLOOKUP(Y4,$O$3:$P$13,2,0), "") -> M1
A5: M2 | B5: M2 | C5: =SUMIF(W$3:W$211, $A5, AA$3:AA$211) -> 13 | D5: =SUMIF(X$3:X$211, $A5, AB$3:AB$211) -> 26 | E5: =SUMIF(Y$3:Y$211, $A5, AC$3:AC$211) -> 27 | F5: 2 | H5: M2 | I5: M2 | J5: =SUMIF(W$3:W$211, $H5, AE$3:AE$211) -> 13 | K5: =SUMIF(X$3:X$211, $H5, AF$3:AF$211) -> 26 | L5: =SUMIF(Y$3:Y$211, $H5, AG$3:AG$211) -> 27 | M5: 2 | O5: M2 | P5: M2 | Q5: =SUMIF(W$3:W$211, $H5, AI$3:AI$211) -> 13 | R5: =SUMIF(X$3:X$211, $H5, AJ$3:AJ$211) -> 26 | S5: =SUMIF(Y$3:Y$211, $H5, AK$3:AK$211) -> 27 | T5: 2 | V5: 2 | W5: K | X5: WW | Y5: M1 | AA5: 1 | AB5: 1 | AC5: 1 | AE5: =IF(AA4="","",AA4) -> 1 | AF5: =IF(AB4="","",AB4) -> 1 | AG5: =IF(AC4="","",AC4) -> 1 | AI5: =IF(AA3="","",AA3) -> 1 | AJ5: =IF(AB3="","",AB3) -> 1 | AK5: =IF(AC3="","",AC3) -> 1 | AM5: 1 | AN5: 1 | AO5: 1 | AQ5: =IF(AM4="","",AM4) -> 1 | AR5: =IF(AN4="","",AN4) -> 1 | AS5: =IF(AO4="","",AO4) -> 1 | AU5: =IF(AM3="","",AM3) -> 1 | AV5: =IF(AN3="","",AN3) -> 1 | AW5: =IF(AO3="","",AO3) -> 1 | AY5: 1 | AZ5: 1 | BA5: 1 | BC5: =IF(AY4="","",AY4) -> 1 | BD5: =IF(AZ4="","",AZ4) -> 1 | BE5: =IF(BA4="","",BA4) -> 1 | BG5: =IF(AY3="","",AY3) -> 1 | BH5: =IF(AZ3="","",AZ3) -> 1 | BI5: =IF(BA3="","",BA3) -> 1 | BK5: 1 | BL5: 1 | BM5: 1 | BO5: =IF(BK4="","",BK4) -> 1 | BP5: =IF(BL4="","",BL4) -> 1 | BQ5: =IF(BM4="","",BM4) -> 1 | BS5: =IF(BK3="","",BK3) -> 1 | BT5: =IF(BL3="","",BL3) -> 1 | BU5: =IF(BM3="","",BM3) -> 1 | BW5: =IF(W5="","",VLOOKUP('Regular Symbol'!W5,'Regular Symbol'!$O$3:$T$13,6,0)) -> 5 | BX5: =IF(X5="","",VLOOKUP('Regular Symbol'!X5,'Regular Symbol'!$O$3:$T$13,6,0)) -> 0 | BY5: =IF(Y5="","",VLOOKUP('Regular Symbol'!Y5,'Regular Symbol'!$O$3:$T$13,6,0)) -> 1 | CA5: =IF(W5<>"", VLOOKUP(W5,$O$3:$P$13,2,0), "") -> K | CB5: =IF(X5<>"", VLOOKUP(X5,$O$3:$P$13,2,0), "") -> Wild | CC5: =IF(Y5<>"", VLOOKUP(Y5,$O$3:$P$13,2,0), "") -> M1
A6: M3 | B6: M3 | C6: =SUMIF(W$3:W$211, $A6, AA$3:AA$211) -> 14 | D6: =SUMIF(X$3:X$211, $A6, AB$3:AB$211) -> 25 | E6: =SUMIF(Y$3:Y$211, $A6, AC$3:AC$211) -> 28 | F6: 3 | H6: M3 | I6: M3 | J6: =SUMIF(W$3:W$211, $H6, AE$3:AE$211) -> 14 | K6: =SUMIF(X$3:X$211, $H6, AF$3:AF$211) -> 25 | L6: =SUMIF(Y$3:Y$211, $H6, AG$3:AG$211) -> 28 | M6: 3 | O6: M3 | P6: M3 | Q6: =SUMIF(W$3:W$211, $H6, AI$3:AI$211) -> 14 | R6: =SUMIF(X$3:X$211, $H6, AJ$3:AJ$211) -> 25 | S6: =SUMIF(Y$3:Y$211, $H6, AK$3:AK$211) -> 28 | T6: 3 | V6: 3 | W6: WW | X6: J | Y6: WW | AA6: 1 | AB6: 1 | AC6: 1 | AE6: =IF(AA5="","",AA5) -> 1 | AF6: =IF(AB5="","",AB5) -> 1 | AG6: =IF(AC5="","",AC5) -> 1 | AI6: =IF(AA4="","",AA4) -> 1 | AJ6: =IF(AB4="","",AB4) -> 1 | AK6: =IF(AC4="","",AC4) -> 1 | AM6: 1 | AN6: 1 | AO6: 1 | AQ6: =IF(AM5="","",AM5) -> 1 | AR6: =IF(AN5="","",AN5) -> 1 | AS6: =IF(AO5="","",AO5) -> 1 | AU6: =IF(AM4="","",AM4) -> 1 | AV6: =IF(AN4="","",AN4) -> 1 | AW6: =IF(AO4="","",AO4) -> 1 | AY6: 1 | AZ6: 1 | BA6: 1 | BC6: =IF(AY5="","",AY5) -> 1 | BD6: =IF(AZ5="","",AZ5) -> 1 | BE6: =IF(BA5="","",BA5) -> 1 | BG6: =IF(AY4="","",AY4) -> 1 | BH6: =IF(AZ4="","",AZ4) -> 1 | BI6: =IF(BA4="","",BA4) -> 1 | BK6: 1 | BL6: 1 | BM6: 1 | BO6: =IF(BK5="","",BK5) -> 1 | BP6: =IF(BL5="","",BL5) -> 1 | BQ6: =IF(BM5="","",BM5) -> 1 | BS6: =IF(BK4="","",BK4) -> 1 | BT6: =IF(BL4="","",BL4) -> 1 | BU6: =IF(BM4="","",BM4) -> 1 | BW6: =IF(W6="","",VLOOKUP('Regular Symbol'!W6,'Regular Symbol'!$O$3:$T$13,6,0)) -> 0 | BX6: =IF(X6="","",VLOOKUP('Regular Symbol'!X6,'Regular Symbol'!$O$3:$T$13,6,0)) -> 7 | BY6: =IF(Y6="","",VLOOKUP('Regular Symbol'!Y6,'Regular Symbol'!$O$3:$T$13,6,0)) -> 0 | CA6: =IF(W6<>"", VLOOKUP(W6,$O$3:$P$13,2,0), "") -> Wild | CB6: =IF(X6<>"", VLOOKUP(X6,$O$3:$P$13,2,0), "") -> J | CC6: =IF(Y6<>"", VLOOKUP(Y6,$O$3:$P$13,2,0), "") -> Wild
A7: A | B7: A | C7: =SUMIF(W$3:W$211, $A7, AA$3:AA$211) -> 18 | D7: =SUMIF(X$3:X$211, $A7, AB$3:AB$211) -> 30 | E7: =SUMIF(Y$3:Y$211, $A7, AC$3:AC$211) -> 23 | F7: 4 | H7: A | I7: A | J7: =SUMIF(W$3:W$211, $H7, AE$3:AE$211) -> 18 | K7: =SUMIF(X$3:X$211, $H7, AF$3:AF$211) -> 30 | L7: =SUMIF(Y$3:Y$211, $H7, AG$3:AG$211) -> 23 | M7: 4 | O7: A | P7: A | Q7: =SUMIF(W$3:W$211, $H7, AI$3:AI$211) -> 18 | R7: =SUMIF(X$3:X$211, $H7, AJ$3:AJ$211) -> 30 | S7: =SUMIF(Y$3:Y$211, $H7, AK$3:AK$211) -> 23 | T7: 4 | V7: 4 | W7: WW | X7: J | Y7: WW | AA7: 1 | AB7: 1 | AC7: 1 | AE7: =IF(AA6="","",AA6) -> 1 | AF7: =IF(AB6="","",AB6) -> 1 | AG7: =IF(AC6="","",AC6) -> 1 | AI7: =IF(AA5="","",AA5) -> 1 | AJ7: =IF(AB5="","",AB5) -> 1 | AK7: =IF(AC5="","",AC5) -> 1 | AM7: 1 | AN7: 1 | AO7: 1 | AQ7: =IF(AM6="","",AM6) -> 1 | AR7: =IF(AN6="","",AN6) -> 1 | AS7: =IF(AO6="","",AO6) -> 1 | AU7: =IF(AM5="","",AM5) -> 1 | AV7: =IF(AN5="","",AN5) -> 1 | AW7: =IF(AO5="","",AO5) -> 1 | AY7: 1 | AZ7: 1 | BA7: 1 | BC7: =IF(AY6="","",AY6) -> 1 | BD7: =IF(AZ6="","",AZ6) -> 1 | BE7: =IF(BA6="","",BA6) -> 1 | BG7: =IF(AY5="","",AY5) -> 1 | BH7: =IF(AZ5="","",AZ5) -> 1 | BI7: =IF(BA5="","",BA5) -> 1 | BK7: 1 | BL7: 1 | BM7: 1 | BO7: =IF(BK6="","",BK6) -> 1 | BP7: =IF(BL6="","",BL6) -> 1 | BQ7: =IF(BM6="","",BM6) -> 1 | BS7: =IF(BK5="","",BK5) -> 1 | BT7: =IF(BL5="","",BL5) -> 1 | BU7: =IF(BM5="","",BM5) -> 1 | BW7: =IF(W7="","",VLOOKUP('Regular Symbol'!W7,'Regular Symbol'!$O$3:$T$13,6,0)) -> 0 | BX7: =IF(X7="","",VLOOKUP('Regular Symbol'!X7,'Regular Symbol'!$O$3:$T$13,6,0)) -> 7 | BY7: =IF(Y7="","",VLOOKUP('Regular Symbol'!Y7,'Regular Symbol'!$O$3:$T$13,6,0)) -> 0 | CA7: =IF(W7<>"", VLOOKUP(W7,$O$3:$P$13,2,0), "") -> Wild | CB7: =IF(X7<>"", VLOOKUP(X7,$O$3:$P$13,2,0), "") -> J | CC7: =IF(Y7<>"", VLOOKUP(Y7,$O$3:$P$13,2,0), "") -> Wild
A8: K | B8: K | C8: =SUMIF(W$3:W$211, $A8, AA$3:AA$211) -> 19 | D8: =SUMIF(X$3:X$211, $A8, AB$3:AB$211) -> 28 | E8: =SUMIF(Y$3:Y$211, $A8, AC$3:AC$211) -> 27 | F8: 5 | H8: K | I8: K | J8: =SUMIF(W$3:W$211, $H8, AE$3:AE$211) -> 19 | K8: =SUMIF(X$3:X$211, $H8, AF$3:AF$211) -> 28 | L8: =SUMIF(Y$3:Y$211, $H8, AG$3:AG$211) -> 27 | M8: 5 | O8: K | P8: K | Q8: =SUMIF(W$3:W$211, $H8, AI$3:AI$211) -> 19 | R8: =SUMIF(X$3:X$211, $H8, AJ$3:AJ$211) -> 28 | S8: =SUMIF(Y$3:Y$211, $H8, AK$3:AK$211) -> 27 | T8: 5 | V8: 5 | W8: WW | X8: A | Y8: WW | AA8: 1 | AB8: 1 | AC8: 1 | AE8: =IF(AA7="","",AA7) -> 1 | AF8: =IF(AB7="","",AB7) -> 1 | AG8: =IF(AC7="","",AC7) -> 1 | AI8: =IF(AA6="","",AA6) -> 1 | AJ8: =IF(AB6="","",AB6) -> 1 | AK8: =IF(AC6="","",AC6) -> 1 | AM8: 1 | AN8: 1 | AO8: 1 | AQ8: =IF(AM7="","",AM7) -> 1 | AR8: =IF(AN7="","",AN7) -> 1 | AS8: =IF(AO7="","",AO7) -> 1 | AU8: =IF(AM6="","",AM6) -> 1 | AV8: =IF(AN6="","",AN6) -> 1 | AW8: =IF(AO6="","",AO6) -> 1 | AY8: 1 | AZ8: 1 | BA8: 1 | BC8: =IF(AY7="","",AY7) -> 1 | BD8: =IF(AZ7="","",AZ7) -> 1 | BE8: =IF(BA7="","",BA7) -> 1 | BG8: =IF(AY6="","",AY6) -> 1 | BH8: =IF(AZ6="","",AZ6) -> 1 | BI8: =IF(BA6="","",BA6) -> 1 | BK8: 1 | BL8: 1 | BM8: 1 | BO8: =IF(BK7="","",BK7) -> 1 | BP8: =IF(BL7="","",BL7) -> 1 | BQ8: =IF(BM7="","",BM7) -> 1 | BS8: =IF(BK6="","",BK6) -> 1 | BT8: =IF(BL6="","",BL6) -> 1 | BU8: =IF(BM6="","",BM6) -> 1 | BW8: =IF(W8="","",VLOOKUP('Regular Symbol'!W8,'Regular Symbol'!$O$3:$T$13,6,0)) -> 0 | BX8: =IF(X8="","",VLOOKUP('Regular Symbol'!X8,'Regular Symbol'!$O$3:$T$13,6,0)) -> 4 | BY8: =IF(Y8="","",VLOOKUP('Regular Symbol'!Y8,'Regular Symbol'!$O$3:$T$13,6,0)) -> 0 | CA8: =IF(W8<>"", VLOOKUP(W8,$O$3:$P$13,2,0), "") -> Wild | CB8: =IF(X8<>"", VLOOKUP(X8,$O$3:$P$13,2,0), "") -> A | CC8: =IF(Y8<>"", VLOOKUP(Y8,$O$3:$P$13,2,0), "") -> Wild
A9: Q | B9: Q | C9: =SUMIF(W$3:W$211, $A9, AA$3:AA$211) -> 17 | D9: =SUMIF(X$3:X$211, $A9, AB$3:AB$211) -> 29 | E9: =SUMIF(Y$3:Y$211, $A9, AC$3:AC$211) -> 27 | F9: 6 | H9: Q | I9: Q | J9: =SUMIF(W$3:W$211, $H9, AE$3:AE$211) -> 17 | K9: =SUMIF(X$3:X$211, $H9, AF$3:AF$211) -> 29 | L9: =SUMIF(Y$3:Y$211, $H9, AG$3:AG$211) -> 27 | M9: 6 | O9: Q | P9: Q | Q9: =SUMIF(W$3:W$211, $H9, AI$3:AI$211) -> 17 | R9: =SUMIF(X$3:X$211, $H9, AJ$3:AJ$211) -> 29 | S9: =SUMIF(Y$3:Y$211, $H9, AK$3:AK$211) -> 27 | T9: 6 | V9: 6 | W9: A | X9: A | Y9: A | AA9: 1 | AB9: 1 | AC9: 1 | AE9: =IF(AA8="","",AA8) -> 1 | AF9: =IF(AB8="","",AB8) -> 1 | AG9: =IF(AC8="","",AC8) -> 1 | AI9: =IF(AA7="","",AA7) -> 1 | AJ9: =IF(AB7="","",AB7) -> 1 | AK9: =IF(AC7="","",AC7) -> 1 | AM9: 1 | AN9: 1 | AO9: 1 | AQ9: =IF(AM8="","",AM8) -> 1 | AR9: =IF(AN8="","",AN8) -> 1 | AS9: =IF(AO8="","",AO8) -> 1 | AU9: =IF(AM7="","",AM7) -> 1 | AV9: =IF(AN7="","",AN7) -> 1 | AW9: =IF(AO7="","",AO7) -> 1 | AY9: 1 | AZ9: 1 | BA9: 1 | BC9: =IF(AY8="","",AY8) -> 1 | BD9: =IF(AZ8="","",AZ8) -> 1 | BE9: =IF(BA8="","",BA8) -> 1 | BG9: =IF(AY7="","",AY7) -> 1 | BH9: =IF(AZ7="","",AZ7) -> 1 | BI9: =IF(BA7="","",BA7) -> 1 | BK9: 1 | BL9: 1 | BM9: 1 | BO9: =IF(BK8="","",BK8) -> 1 | BP9: =IF(BL8="","",BL8) -> 1 | BQ9: =IF(BM8="","",BM8) -> 1 | BS9: =IF(BK7="","",BK7) -> 1 | BT9: =IF(BL7="","",BL7) -> 1 | BU9: =IF(BM7="","",BM7) -> 1 | BW9: =IF(W9="","",VLOOKUP('Regular Symbol'!W9,'Regular Symbol'!$O$3:$T$13,6,0)) -> 4 | BX9: =IF(X9="","",VLOOKUP('Regular Symbol'!X9,'Regular Symbol'!$O$3:$T$13,6,0)) -> 4 | BY9: =IF(Y9="","",VLOOKUP('Regular Symbol'!Y9,'Regular Symbol'!$O$3:$T$13,6,0)) -> 4 | CA9: =IF(W9<>"", VLOOKUP(W9,$O$3:$P$13,2,0), "") -> A | CB9: =IF(X9<>"", VLOOKUP(X9,$O$3:$P$13,2,0), "") -> A | CC9: =IF(Y9<>"", VLOOKUP(Y9,$O$3:$P$13,2,0), "") -> A
A10: J | B10: J | C10: =SUMIF(W$3:W$211, $A10, AA$3:AA$211) -> 19 | D10: =SUMIF(X$3:X$211, $A10, AB$3:AB$211) -> 26 | E10: =SUMIF(Y$3:Y$211, $A10, AC$3:AC$211) -> 27 | F10: 7 | H10: J | I10: J | J10: =SUMIF(W$3:W$211, $H10, AE$3:AE$211) -> 19 | K10: =SUMIF(X$3:X$211, $H10, AF$3:AF$211) -> 26 | L10: =SUMIF(Y$3:Y$211, $H10, AG$3:AG$211) -> 27 | M10: 7 | O10: J | P10: J | Q10: =SUMIF(W$3:W$211, $H10, AI$3:AI$211) -> 19 | R10: =SUMIF(X$3:X$211, $H10, AJ$3:AJ$211) -> 26 | S10: =SUMIF(Y$3:Y$211, $H10, AK$3:AK$211) -> 27 | T10: 7 | V10: 7 | W10: A | X10: A | Y10: A | AA10: 1 | AB10: 1 | AC10: 1 | AE10: =IF(AA9="","",AA9) -> 1 | AF10: =IF(AB9="","",AB9) -> 1 | AG10: =IF(AC9="","",AC9) -> 1 | AI10: =IF(AA8="","",AA8) -> 1 | AJ10: =IF(AB8="","",AB8) -> 1 | AK10: =IF(AC8="","",AC8) -> 1 | AM10: 1 | AN10: 1 | AO10: 1 | AQ10: =IF(AM9="","",AM9) -> 1 | AR10: =IF(AN9="","",AN9) -> 1 | AS10: =IF(AO9="","",AO9) -> 1 | AU10: =IF(AM8="","",AM8) -> 1 | AV10: =IF(AN8="","",AN8) -> 1 | AW10: =IF(AO8="","",AO8) -> 1 | AY10: 1 | AZ10: 1 | BA10: 1 | BC10: =IF(AY9="","",AY9) -> 1 | BD10: =IF(AZ9="","",AZ9) -> 1 | BE10: =IF(BA9="","",BA9) -> 1 | BG10: =IF(AY8="","",AY8) -> 1 | BH10: =IF(AZ8="","",AZ8) -> 1 | BI10: =IF(BA8="","",BA8) -> 1 | BK10: 1 | BL10: 1 | BM10: 1 | BO10: =IF(BK9="","",BK9) -> 1 | BP10: =IF(BL9="","",BL9) -> 1 | BQ10: =IF(BM9="","",BM9) -> 1 | BS10: =IF(BK8="","",BK8) -> 1 | BT10: =IF(BL8="","",BL8) -> 1 | BU10: =IF(BM8="","",BM8) -> 1 | BW10: =IF(W10="","",VLOOKUP('Regular Symbol'!W10,'Regular Symbol'!$O$3:$T$13,6,0)) -> 4 | BX10: =IF(X10="","",VLOOKUP('Regular Symbol'!X10,'Regular Symbol'!$O$3:$T$13,6,0)) -> 4 | BY10: =IF(Y10="","",VLOOKUP('Regular Symbol'!Y10,'Regular Symbol'!$O$3:$T$13,6,0)) -> 4 | CA10: =IF(W10<>"", VLOOKUP(W10,$O$3:$P$13,2,0), "") -> A | CB10: =IF(X10<>"", VLOOKUP(X10,$O$3:$P$13,2,0), "") -> A | CC10: =IF(Y10<>"", VLOOKUP(Y10,$O$3:$P$13,2,0), "") -> A
V11: 8 | W11: A | X11: M2 | Y11: A | AA11: 1 | AB11: 1 | AC11: 1 | AE11: =IF(AA10="","",AA10) -> 1 | AF11: =IF(AB10="","",AB10) -> 1 | AG11: =IF(AC10="","",AC10) -> 1 | AI11: =IF(AA9="","",AA9) -> 1 | AJ11: =IF(AB9="","",AB9) -> 1 | AK11: =IF(AC9="","",AC9) -> 1 | AM11: 1 | AN11: 1 | AO11: 1 | AQ11: =IF(AM10="","",AM10) -> 1 | AR11: =IF(AN10="","",AN10) -> 1 | AS11: =IF(AO10="","",AO10) -> 1 | AU11: =IF(AM9="","",AM9) -> 1 | AV11: =IF(AN9="","",AN9) -> 1 | AW11: =IF(AO9="","",AO9) -> 1 | AY11: 1 | AZ11: 1 | BA11: 1 | BC11: =IF(AY10="","",AY10) -> 1 | BD11: =IF(AZ10="","",AZ10) -> 1 | BE11: =IF(BA10="","",BA10) -> 1 | BG11: =IF(AY9="","",AY9) -> 1 | BH11: =IF(AZ9="","",AZ9) -> 1 | BI11: =IF(BA9="","",BA9) -> 1 | BK11: 1 | BL11: 1 | BM11: 1 | BO11: =IF(BK10="","",BK10) -> 1 | BP11: =IF(BL10="","",BL10) -> 1 | BQ11: =IF(BM10="","",BM10) -> 1 | BS11: =IF(BK9="","",BK9) -> 1 | BT11: =IF(BL9="","",BL9) -> 1 | BU11: =IF(BM9="","",BM9) -> 1 | BW11: =IF(W11="","",VLOOKUP('Regular Symbol'!W11,'Regular Symbol'!$O$3:$T$13,6,0)) -> 4 | BX11: =IF(X11="","",VLOOKUP('Regular Symbol'!X11,'Regular Symbol'!$O$3:$T$13,6,0)) -> 2 | BY11: =IF(Y11="","",VLOOKUP('Regular Symbol'!Y11,'Regular Symbol'!$O$3:$T$13,6,0)) -> 4 | CA11: =IF(W11<>"", VLOOKUP(W11,$O$3:$P$13,2,0), "") -> A | CB11: =IF(X11<>"", VLOOKUP(X11,$O$3:$P$13,2,0), "") -> M2 | CC11: =IF(Y11<>"", VLOOKUP(Y11,$O$3:$P$13,2,0), "") -> A
V12: 9 | W12: M2 | X12: M2 | Y12: M2 | AA12: 1 | AB12: 1 | AC12: 1 | AE12: =IF(AA11="","",AA11) -> 1 | AF12: =IF(AB11="","",AB11) -> 1 | AG12: =IF(AC11="","",AC11) -> 1 | AI12: =IF(AA10="","",AA10) -> 1 | AJ12: =IF(AB10="","",AB10) -> 1 | AK12: =IF(AC10="","",AC10) -> 1 | AM12: 1 | AN12: 1 | AO12: 1 | AQ12: =IF(AM11="","",AM11) -> 1 | AR12: =IF(AN11="","",AN11) -> 1 | AS12: =IF(AO11="","",AO11) -> 1 | AU12: =IF(AM10="","",AM10) -> 1 | AV12: =IF(AN10="","",AN10) -> 1 | AW12: =IF(AO10="","",AO10) -> 1 | AY12: 1 | AZ12: 1 | BA12: 1 | BC12: =IF(AY11="","",AY11) -> 1 | BD12: =IF(AZ11="","",AZ11) -> 1 | BE12: =IF(BA11="","",BA11) -> 1 | BG12: =IF(AY10="","",AY10) -> 1 | BH12: =IF(AZ10="","",AZ10) -> 1 | BI12: =IF(BA10="","",BA10) -> 1 | BK12: 1 | BL12: 1 | BM12: 1 | BO12: =IF(BK11="","",BK11) -> 1 | BP12: =IF(BL11="","",BL11) -> 1 | BQ12: =IF(BM11="","",BM11) -> 1 | BS12: =IF(BK10="","",BK10) -> 1 | BT12: =IF(BL10="","",BL10) -> 1 | BU12: =IF(BM10="","",BM10) -> 1 | BW12: =IF(W12="","",VLOOKUP('Regular Symbol'!W12,'Regular Symbol'!$O$3:$T$13,6,0)) -> 2 | BX12: =IF(X12="","",VLOOKUP('Regular Symbol'!X12,'Regular Symbol'!$O$3:$T$13,6,0)) -> 2 | BY12: =IF(Y12="","",VLOOKUP('Regular Symbol'!Y12,'Regular Symbol'!$O$3:$T$13,6,0)) -> 2 | CA12: =IF(W12<>"", VLOOKUP(W12,$O$3:$P$13,2,0), "") -> M2 | CB12: =IF(X12<>"", VLOOKUP(X12,$O$3:$P$13,2,0), "") -> M2 | CC12: =IF(Y12<>"", VLOOKUP(Y12,$O$3:$P$13,2,0), "") -> M2
V13: 10 | W13: M2 | X13: M2 | Y13: M2 | AA13: 1 | AB13: 1 | AC13: 1 | AE13: =IF(AA12="","",AA12) -> 1 | AF13: =IF(AB12="","",AB12) -> 1 | AG13: =IF(AC12="","",AC12) -> 1 | AI13: =IF(AA11="","",AA11) -> 1 | AJ13: =IF(AB11="","",AB11) -> 1 | AK13: =IF(AC11="","",AC11) -> 1 | AM13: 1 | AN13: 1 | AO13: 1 | AQ13: =IF(AM12="","",AM12) -> 1 | AR13: =IF(AN12="","",AN12) -> 1 | AS13: =IF(AO12="","",AO12) -> 1 | AU13: =IF(AM11="","",AM11) -> 1 | AV13: =IF(AN11="","",AN11) -> 1 | AW13: =IF(AO11="","",AO11) -> 1 | AY13: 1 | AZ13: 1 | BA13: 1 | BC13: =IF(AY12="","",AY12) -> 1 | BD13: =IF(AZ12="","",AZ12) -> 1 | BE13: =IF(BA12="","",BA12) -> 1 | BG13: =IF(AY11="","",AY11) -> 1 | BH13: =IF(AZ11="","",AZ11) -> 1 | BI13: =IF(BA11="","",BA11) -> 1 | BK13: 1 | BL13: 1 | BM13: 1 | BO13: =IF(BK12="","",BK12) -> 1 | BP13: =IF(BL12="","",BL12) -> 1 | BQ13: =IF(BM12="","",BM12) -> 1 | BS13: =IF(BK11="","",BK11) -> 1 | BT13: =IF(BL11="","",BL11) -> 1 | BU13: =IF(BM11="","",BM11) -> 1 | BW13: =IF(W13="","",VLOOKUP('Regular Symbol'!W13,'Regular Symbol'!$O$3:$T$13,6,0)) -> 2 | BX13: =IF(X13="","",VLOOKUP('Regular Symbol'!X13,'Regular Symbol'!$O$3:$T$13,6,0)) -> 2 | BY13: =IF(Y13="","",VLOOKUP('Regular Symbol'!Y13,'Regular Symbol'!$O$3:$T$13,6,0)) -> 2 | CA13: =IF(W13<>"", VLOOKUP(W13,$O$3:$P$13,2,0), "") -> M2 | CB13: =IF(X13<>"", VLOOKUP(X13,$O$3:$P$13,2,0), "") -> M2 | CC13: =IF(Y13<>"", VLOOKUP(Y13,$O$3:$P$13,2,0), "") -> M2
A14: Total | C14: =SUM(C3:C13) -> 123 | D14: =SUM(D3:D13) -> 209 | E14: =SUM(E3:E13) -> 203 | H14: Total | J14: =SUM(J3:J13) -> 123 | K14: =SUM(K3:K13) -> 209 | L14: =SUM(L3:L13) -> 203 | O14: Total | Q14: =SUM(Q3:Q13) -> 123 | R14: =SUM(R3:R13) -> 209 | S14: =SUM(S3:S13) -> 203 | V14: 11 | W14: K | X14: K | Y14: M2 | AA14: 1 | AB14: 1 | AC14: 1 | AE14: =IF(AA13="","",AA13) -> 1 | AF14: =IF(AB13="","",AB13) -> 1 | AG14: =IF(AC13="","",AC13) -> 1 | AI14: =IF(AA12="","",AA12) -> 1 | AJ14: =IF(AB12="","",AB12) -> 1 | AK14: =IF(AC12="","",AC12) -> 1 | AM14: 1 | AN14: 1 | AO14: 1 | AQ14: =IF(AM13="","",AM13) -> 1 | AR14: =IF(AN13="","",AN13) -> 1 | AS14: =IF(AO13="","",AO13) -> 1 | AU14: =IF(AM12="","",AM12) -> 1 | AV14: =IF(AN12="","",AN12) -> 1 | AW14: =IF(AO12="","",AO12) -> 1 | AY14: 1 | AZ14: 1 | BA14: 1 | BC14: =IF(AY13="","",AY13) -> 1 | BD14: =IF(AZ13="","",AZ13) -> 1 | BE14: =IF(BA13="","",BA13) -> 1 | BG14: =IF(AY12="","",AY12) -> 1 | BH14: =IF(AZ12="","",AZ12) -> 1 | BI14: =IF(BA12="","",BA12) -> 1 | BK14: 1 | BL14: 1 | BM14: 1 | BO14: =IF(BK13="","",BK13) -> 1 | BP14: =IF(BL13="","",BL13) -> 1 | BQ14: =IF(BM13="","",BM13) -> 1 | BS14: =IF(BK12="","",BK12) -> 1 | BT14: =IF(BL12="","",BL12) -> 1 | BU14: =IF(BM12="","",BM12) -> 1 | BW14: =IF(W14="","",VLOOKUP('Regular Symbol'!W14,'Regular Symbol'!$O$3:$T$13,6,0)) -> 5 | BX14: =IF(X14="","",VLOOKUP('Regular Symbol'!X14,'Regular Symbol'!$O$3:$T$13,6,0)) -> 5 | BY14: =IF(Y14="","",VLOOKUP('Regular Symbol'!Y14,'Regular Symbol'!$O$3:$T$13,6,0)) -> 2 | CA14: =IF(W14<>"", VLOOKUP(W14,$O$3:$P$13,2,0), "") -> K | CB14: =IF(X14<>"", VLOOKUP(X14,$O$3:$P$13,2,0), "") -> K | CC14: =IF(Y14<>"", VLOOKUP(Y14,$O$3:$P$13,2,0), "") -> M2
V15: 12 | W15: K | X15: K | Y15: K | AA15: 1 | AB15: 1 | AC15: 1 | AE15: =IF(AA14="","",AA14) -> 1 | AF15: =IF(AB14="","",AB14) -> 1 | AG15: =IF(AC14="","",AC14) -> 1 | AI15: =IF(AA13="","",AA13) -> 1 | AJ15: =IF(AB13="","",AB13) -> 1 | AK15: =IF(AC13="","",AC13) -> 1 | AM15: 1 | AN15: 1 | AO15: 1 | AQ15: =IF(AM14="","",AM14) -> 1 | AR15: =IF(AN14="","",AN14) -> 1 | AS15: =IF(AO14="","",AO14) -> 1 | AU15: =IF(AM13="","",AM13) -> 1 | AV15: =IF(AN13="","",AN13) -> 1 | AW15: =IF(AO13="","",AO13) -> 1 | AY15: 1 | AZ15: 1 | BA15: 1 | BC15: =IF(AY14="","",AY14) -> 1 | BD15: =IF(AZ14="","",AZ14) -> 1 | BE15: =IF(BA14="","",BA14) -> 1 | BG15: =IF(AY13="","",AY13) -> 1 | BH15: =IF(AZ13="","",AZ13) -> 1 | BI15: =IF(BA13="","",BA13) -> 1 | BK15: 1 | BL15: 1 | BM15: 1 | BO15: =IF(BK14="","",BK14) -> 1 | BP15: =IF(BL14="","",BL14) -> 1 | BQ15: =IF(BM14="","",BM14) -> 1 | BS15: =IF(BK13="","",BK13) -> 1 | BT15: =IF(BL13="","",BL13) -> 1 | BU15: =IF(BM13="","",BM13) -> 1 | BW15: =IF(W15="","",VLOOKUP('Regular Symbol'!W15,'Regular Symbol'!$O$3:$T$13,6,0)) -> 5 | BX15: =IF(X15="","",VLOOKUP('Regular Symbol'!X15,'Regular Symbol'!$O$3:$T$13,6,0)) -> 5 | BY15: =IF(Y15="","",VLOOKUP('Regular Symbol'!Y15,'Regular Symbol'!$O$3:$T$13,6,0)) -> 5 | CA15: =IF(W15<>"", VLOOKUP(W15,$O$3:$P$13,2,0), "") -> K | CB15: =IF(X15<>"", VLOOKUP(X15,$O$3:$P$13,2,0), "") -> K | CC15: =IF(Y15<>"", VLOOKUP(Y15,$O$3:$P$13,2,0), "") -> K
A16: Special Include Symbols | H16: Special Include Symbols | O16: Special Include Symbols | V16: 13 | W16: M1 | X16: K | Y16: K | AA16: 1 | AB16: 1 | AC16: 1 | AE16: =IF(AA15="","",AA15) -> 1 | AF16: =IF(AB15="","",AB15) -> 1 | AG16: =IF(AC15="","",AC15) -> 1 | AI16: =IF(AA14="","",AA14) -> 1 | AJ16: =IF(AB14="","",AB14) -> 1 | AK16: =IF(AC14="","",AC14) -> 1 | AM16: 1 | AN16: 1 | AO16: 1 | AQ16: =IF(AM15="","",AM15) -> 1 | AR16: =IF(AN15="","",AN15) -> 1 | AS16: =IF(AO15="","",AO15) -> 1 | AU16: =IF(AM14="","",AM14) -> 1 | AV16: =IF(AN14="","",AN14) -> 1 | AW16: =IF(AO14="","",AO14) -> 1 | AY16: 1 | AZ16: 1 | BA16: 1 | BC16: =IF(AY15="","",AY15) -> 1 | BD16: =IF(AZ15="","",AZ15) -> 1 | BE16: =IF(BA15="","",BA15) -> 1 | BG16: =IF(AY14="","",AY14) -> 1 | BH16: =IF(AZ14="","",AZ14) -> 1 | BI16: =IF(BA14="","",BA14) -> 1 | BK16: 1 | BL16: 1 | BM16: 1 | BO16: =IF(BK15="","",BK15) -> 1 | BP16: =IF(BL15="","",BL15) -> 1 | BQ16: =IF(BM15="","",BM15) -> 1 | BS16: =IF(BK14="","",BK14) -> 1 | BT16: =IF(BL14="","",BL14) -> 1 | BU16: =IF(BM14="","",BM14) -> 1 | BW16: =IF(W16="","",VLOOKUP('Regular Symbol'!W16,'Regular Symbol'!$O$3:$T$13,6,0)) -> 1 | BX16: =IF(X16="","",VLOOKUP('Regular Symbol'!X16,'Regular Symbol'!$O$3:$T$13,6,0)) -> 5 | BY16: =IF(Y16="","",VLOOKUP('Regular Symbol'!Y16,'Regular Symbol'!$O$3:$T$13,6,0)) -> 5 | CA16: =IF(W16<>"", VLOOKUP(W16,$O$3:$P$13,2,0), "") -> M1 | CB16: =IF(X16<>"", VLOOKUP(X16,$O$3:$P$13,2,0), "") -> K | CC16: =IF(Y16<>"", VLOOKUP(Y16,$O$3:$P$13,2,0), "") -> K
A17: Symbol | B17: Is Any Of These | C17: R1 | D17: R2 | E17: R3 | H17: Symbol | I17: Is Any Of These | J17: R1 | K17: R2 | L17: R3 | O17: Symbol | P17: Is Any Of These | Q17: R1 | R17: R2 | S17: R3 | V17: 14 | W17: M1 | X17: A | Y17: K | AA17: 1 | AB17: 1 | AC17: 1 | AE17: =IF(AA16="","",AA16) -> 1 | AF17: =IF(AB16="","",AB16) -> 1 | AG17: =IF(AC16="","",AC16) -> 1 | AI17: =IF(AA15="","",AA15) -> 1 | AJ17: =IF(AB15="","",AB15) -> 1 | AK17: =IF(AC15="","",AC15) -> 1 | AM17: 1 | AN17: 1 | AO17: 1 | AQ17: =IF(AM16="","",AM16) -> 1 | AR17: =IF(AN16="","",AN16) -> 1 | AS17: =IF(AO16="","",AO16) -> 1 | AU17: =IF(AM15="","",AM15) -> 1 | AV17: =IF(AN15="","",AN15) -> 1 | AW17: =IF(AO15="","",AO15) -> 1 | AY17: 1 | AZ17: 1 | BA17: 1 | BC17: =IF(AY16="","",AY16) -> 1 | BD17: =IF(AZ16="","",AZ16) -> 1 | BE17: =IF(BA16="","",BA16) -> 1 | BG17: =IF(AY15="","",AY15) -> 1 | BH17: =IF(AZ15="","",AZ15) -> 1 | BI17: =IF(BA15="","",BA15) -> 1 | BK17: 1 | BL17: 1 | BM17: 1 | BO17: =IF(BK16="","",BK16) -> 1 | BP17: =IF(BL16="","",BL16) -> 1 | BQ17: =IF(BM16="","",BM16) -> 1 | BS17: =IF(BK15="","",BK15) -> 1 | BT17: =IF(BL15="","",BL15) -> 1 | BU17: =IF(BM15="","",BM15) -> 1 | BW17: =IF(W17="","",VLOOKUP('Regular Symbol'!W17,'Regular Symbol'!$O$3:$T$13,6,0)) -> 1 | BX17: =IF(X17="","",VLOOKUP('Regular Symbol'!X17,'Regular Symbol'!$O$3:$T$13,6,0)) -> 4 | BY17: =IF(Y17="","",VLOOKUP('Regular Symbol'!Y17,'Regular Symbol'!$O$3:$T$13,6,0)) -> 5 | CA17: =IF(W17<>"", VLOOKUP(W17,$O$3:$P$13,2,0), "") -> M1 | CB17: =IF(X17<>"", VLOOKUP(X17,$O$3:$P$13,2,0), "") -> A | CC17: =IF(Y17<>"", VLOOKUP(Y17,$O$3:$P$13,2,0), "") -> K
A18: -- | B18: WW,C1,M1,M2,M3,M4,A,K,Q,J,TE,NI | C18: =SUM(C3:C13) -> 123 | D18: =SUM(D3:D13) -> 209 | E18: =SUM(E3:E13) -> 203 | H18: {=A18:B25} -> -- | I18: WW,C1,M1,M2,M3,M4,A,K,Q,J,TE,NI | J18: =SUM(J3:J13) -> 123 | K18: =SUM(K3:K13) -> 209 | L18: =SUM(L3:L13) -> 203 | O18: {=_xlfn.ANCHORARRAY(H18)} -> -- | P18: WW,C1,M1,M2,M3,M4,A,K,Q,J,TE,NI | Q18: =SUM(Q3:Q13) -> 123 | R18: =SUM(R3:R13) -> 209 | S18: =SUM(S3:S13) -> 203 | V18: 15 | W18: M1 | X18: A | Y18: M1 | AA18: 1 | AB18: 1 | AC18: 1 | AE18: =IF(AA17="","",AA17) -> 1 | AF18: =IF(AB17="","",AB17) -> 1 | AG18: =IF(AC17="","",AC17) -> 1 | AI18: =IF(AA16="","",AA16) -> 1 | AJ18: =IF(AB16="","",AB16) -> 1 | AK18: =IF(AC16="","",AC16) -> 1 | AM18: 1 | AN18: 1 | AO18: 1 | AQ18: =IF(AM17="","",AM17) -> 1 | AR18: =IF(AN17="","",AN17) -> 1 | AS18: =IF(AO17="","",AO17) -> 1 | AU18: =IF(AM16="","",AM16) -> 1 | AV18: =IF(AN16="","",AN16) -> 1 | AW18: =IF(AO16="","",AO16) -> 1 | AY18: 1 | AZ18: 1 | BA18: 1 | BC18: =IF(AY17="","",AY17) -> 1 | BD18: =IF(AZ17="","",AZ17) -> 1 | BE18: =IF(BA17="","",BA17) -> 1 | BG18: =IF(AY16="","",AY16) -> 1 | BH18: =IF(AZ16="","",AZ16) -> 1 | BI18: =IF(BA16="","",BA16) -> 1 | BK18: 1 | BL18: 1 | BM18: 1 | BO18: =IF(BK17="","",BK17) -> 1 | BP18: =IF(BL17="","",BL17) -> 1 | BQ18: =IF(BM17="","",BM17) -> 1 | BS18: =IF(BK16="","",BK16) -> 1 | BT18: =IF(BL16="","",BL16) -> 1 | BU18: =IF(BM16="","",BM16) -> 1 | BW18: =IF(W18="","",VLOOKUP('Regular Symbol'!W18,'Regular Symbol'!$O$3:$T$13,6,0)) -> 1 | BX18: =IF(X18="","",VLOOKUP('Regular Symbol'!X18,'Regular Symbol'!$O$3:$T$13,6,0)) -> 4 | BY18: =IF(Y18="","",VLOOKUP('Regular Symbol'!Y18,'Regular Symbol'!$O$3:$T$13,6,0)) -> 1 | CA18: =IF(W18<>"", VLOOKUP(W18,$O$3:$P$13,2,0), "") -> M1 | CB18: =IF(X18<>"", VLOOKUP(X18,$O$3:$P$13,2,0), "") -> A | CC18: =IF(Y18<>"", VLOOKUP(Y18,$O$3:$P$13,2,0), "") -> M1
A19: W1 | B19: WW,M1 | C19: =C$3+C$4 -> 23 | D19: =D$3+D$4 -> 45 | E19: =E$3+E$4 -> 44 | H19: W1 | I19: WW,M1 | J19: =J$3+J$4 -> 23 | K19: =K$3+K$4 -> 45 | L19: =L$3+L$4 -> 44 | O19: W1 | P19: WW,M1 | Q19: =Q$3+Q$4 -> 23 | R19: =R$3+R$4 -> 45 | S19: =S$3+S$4 -> 44 | V19: 16 | W19: J | X19: A | Y19: M1 | AA19: 1 | AB19: 1 | AC19: 1 | AE19: =IF(AA18="","",AA18) -> 1 | AF19: =IF(AB18="","",AB18) -> 1 | AG19: =IF(AC18="","",AC18) -> 1 | AI19: =IF(AA17="","",AA17) -> 1 | AJ19: =IF(AB17="","",AB17) -> 1 | AK19: =IF(AC17="","",AC17) -> 1 | AM19: 1 | AN19: 1 | AO19: 1 | AQ19: =IF(AM18="","",AM18) -> 1 | AR19: =IF(AN18="","",AN18) -> 1 | AS19: =IF(AO18="","",AO18) -> 1 | AU19: =IF(AM17="","",AM17) -> 1 | AV19: =IF(AN17="","",AN17) -> 1 | AW19: =IF(AO17="","",AO17) -> 1 | AY19: 1 | AZ19: 1 | BA19: 1 | BC19: =IF(AY18="","",AY18) -> 1 | BD19: =IF(AZ18="","",AZ18) -> 1 | BE19: =IF(BA18="","",BA18) -> 1 | BG19: =IF(AY17="","",AY17) -> 1 | BH19: =IF(AZ17="","",AZ17) -> 1 | BI19: =IF(BA17="","",BA17) -> 1 | BK19: 1 | BL19: 1 | BM19: 1 | BO19: =IF(BK18="","",BK18) -> 1 | BP19: =IF(BL18="","",BL18) -> 1 | BQ19: =IF(BM18="","",BM18) -> 1 | BS19: =IF(BK17="","",BK17) -> 1 | BT19: =IF(BL17="","",BL17) -> 1 | BU19: =IF(BM17="","",BM17) -> 1 | BW19: =IF(W19="","",VLOOKUP('Regular Symbol'!W19,'Regular Symbol'!$O$3:$T$13,6,0)) -> 7 | BX19: =IF(X19="","",VLOOKUP('Regular Symbol'!X19,'Regular Symbol'!$O$3:$T$13,6,0)) -> 4 | BY19: =IF(Y19="","",VLOOKUP('Regular Symbol'!Y19,'Regular Symbol'!$O$3:$T$13,6,0)) -> 1 | CA19: =IF(W19<>"", VLOOKUP(W19,$O$3:$P$13,2,0), "") -> J | CB19: =IF(X19<>"", VLOOKUP(X19,$O$3:$P$13,2,0), "") -> A | CC19: =IF(Y19<>"", VLOOKUP(Y19,$O$3:$P$13,2,0), "") -> M1
A20: W2 | B20: WW,M2 | C20: =C$3+C$5 -> 22 | D20: =D$3+D$5 -> 47 | E20: =E$3+E$5 -> 48 | H20: W2 | I20: WW,M2 | J20: =J$3+J$5 -> 22 | K20: =K$3+K$5 -> 47 | L20: =L$3+L$5 -> 48 | O20: W2 | P20: WW,M2 | Q20: =Q$3+Q$5 -> 22 | R20: =R$3+R$5 -> 47 | S20: =S$3+S$5 -> 48 | V20: 17 | W20: J | X20: M2 | Y20: M1 | AA20: 1 | AB20: 1 | AC20: 1 | AE20: =IF(AA19="","",AA19) -> 1 | AF20: =IF(AB19="","",AB19) -> 1 | AG20: =IF(AC19="","",AC19) -> 1 | AI20: =IF(AA18="","",AA18) -> 1 | AJ20: =IF(AB18="","",AB18) -> 1 | AK20: =IF(AC18="","",AC18) -> 1 | AM20: 1 | AN20: 1 | AO20: 1 | AQ20: =IF(AM19="","",AM19) -> 1 | AR20: =IF(AN19="","",AN19) -> 1 | AS20: =IF(AO19="","",AO19) -> 1 | AU20: =IF(AM18="","",AM18) -> 1 | AV20: =IF(AN18="","",AN18) -> 1 | AW20: =IF(AO18="","",AO18) -> 1 | AY20: 1 | AZ20: 1 | BA20: 1 | BC20: =IF(AY19="","",AY19) -> 1 | BD20: =IF(AZ19="","",AZ19) -> 1 | BE20: =IF(BA19="","",BA19) -> 1 | BG20: =IF(AY18="","",AY18) -> 1 | BH20: =IF(AZ18="","",AZ18) -> 1 | BI20: =IF(BA18="","",BA18) -> 1 | BK20: 1 | BL20: 1 | BM20: 1 | BO20: =IF(BK19="","",BK19) -> 1 | BP20: =IF(BL19="","",BL19) -> 1 | BQ20: =IF(BM19="","",BM19) -> 1 | BS20: =IF(BK18="","",BK18) -> 1 | BT20: =IF(BL18="","",BL18) -> 1 | BU20: =IF(BM18="","",BM18) -> 1 | BW20: =IF(W20="","",VLOOKUP('Regular Symbol'!W20,'Regular Symbol'!$O$3:$T$13,6,0)) -> 7 | BX20: =IF(X20="","",VLOOKUP('Regular Symbol'!X20,'Regular Symbol'!$O$3:$T$13,6,0)) -> 2 | BY20: =IF(Y20="","",VLOOKUP('Regular Symbol'!Y20,'Regular Symbol'!$O$3:$T$13,6,0)) -> 1 | CA20: =IF(W20<>"", VLOOKUP(W20,$O$3:$P$13,2,0), "") -> J | CB20: =IF(X20<>"", VLOOKUP(X20,$O$3:$P$13,2,0), "") -> M2 | CC20: =IF(Y20<>"", VLOOKUP(Y20,$O$3:$P$13,2,0), "") -> M1
A21: W3 | B21: WW,M3 | C21: =C$3+C$6 -> 23 | D21: =D$3+D$6 -> 46 | E21: =E$3+E$6 -> 49 | H21: W3 | I21: WW,M3 | J21: =J$3+J$6 -> 23 | K21: =K$3+K$6 -> 46 | L21: =L$3+L$6 -> 49 | O21: W3 | P21: WW,M3 | Q21: =Q$3+Q$6 -> 23 | R21: =R$3+R$6 -> 46 | S21: =S$3+S$6 -> 49 | V21: 18 | W21: M2 | X21: M2 | Y21: M3 | AA21: 1 | AB21: 1 | AC21: 1 | AE21: =IF(AA20="","",AA20) -> 1 | AF21: =IF(AB20="","",AB20) -> 1 | AG21: =IF(AC20="","",AC20) -> 1 | AI21: =IF(AA19="","",AA19) -> 1 | AJ21: =IF(AB19="","",AB19) -> 1 | AK21: =IF(AC19="","",AC19) -> 1 | AM21: 1 | AN21: 1 | AO21: 1 | AQ21: =IF(AM20="","",AM20) -> 1 | AR21: =IF(AN20="","",AN20) -> 1 | AS21: =IF(AO20="","",AO20) -> 1 | AU21: =IF(AM19="","",AM19) -> 1 | AV21: =IF(AN19="","",AN19) -> 1 | AW21: =IF(AO19="","",AO19) -> 1 | AY21: 1 | AZ21: 1 | BA21: 1 | BC21: =IF(AY20="","",AY20) -> 1 | BD21: =IF(AZ20="","",AZ20) -> 1 | BE21: =IF(BA20="","",BA20) -> 1 | BG21: =IF(AY19="","",AY19) -> 1 | BH21: =IF(AZ19="","",AZ19) -> 1 | BI21: =IF(BA19="","",BA19) -> 1 | BK21: 1 | BL21: 1 | BM21: 1 | BO21: =IF(BK20="","",BK20) -> 1 | BP21: =IF(BL20="","",BL20) -> 1 | BQ21: =IF(BM20="","",BM20) -> 1 | BS21: =IF(BK19="","",BK19) -> 1 | BT21: =IF(BL19="","",BL19) -> 1 | BU21: =IF(BM19="","",BM19) -> 1 | BW21: =IF(W21="","",VLOOKUP('Regular Symbol'!W21,'Regular Symbol'!$O$3:$T$13,6,0)) -> 2 | BX21: =IF(X21="","",VLOOKUP('Regular Symbol'!X21,'Regular Symbol'!$O$3:$T$13,6,0)) -> 2 | BY21: =IF(Y21="","",VLOOKUP('Regular Symbol'!Y21,'Regular Symbol'!$O$3:$T$13,6,0)) -> 3 | CA21: =IF(W21<>"", VLOOKUP(W21,$O$3:$P$13,2,0), "") -> M2 | CB21: =IF(X21<>"", VLOOKUP(X21,$O$3:$P$13,2,0), "") -> M2 | CC21: =IF(Y21<>"", VLOOKUP(Y21,$O$3:$P$13,2,0), "") -> M3
A22: WA | B22: WW,A | C22: =C$3+C$7 -> 27 | D22: =D$3+D$7 -> 51 | E22: =E$3+E$7 -> 44 | H22: WA | I22: WW,A | J22: =J$3+J$7 -> 27 | K22: =K$3+K$7 -> 51 | L22: =L$3+L$7 -> 44 | O22: WA | P22: WW,A | Q22: =Q$3+Q$7 -> 27 | R22: =R$3+R$7 -> 51 | S22: =S$3+S$7 -> 44 | V22: 19 | W22: M2 | X22: M2 | Y22: M3 | AA22: 1 | AB22: 1 | AC22: 1 | AE22: =IF(AA21="","",AA21) -> 1 | AF22: =IF(AB21="","",AB21) -> 1 | AG22: =IF(AC21="","",AC21) -> 1 | AI22: =IF(AA20="","",AA20) -> 1 | AJ22: =IF(AB20="","",AB20) -> 1 | AK22: =IF(AC20="","",AC20) -> 1 | AM22: 1 | AN22: 1 | AO22: 1 | AQ22: =IF(AM21="","",AM21) -> 1 | AR22: =IF(AN21="","",AN21) -> 1 | AS22: =IF(AO21="","",AO21) -> 1 | AU22: =IF(AM20="","",AM20) -> 1 | AV22: =IF(AN20="","",AN20) -> 1 | AW22: =IF(AO20="","",AO20) -> 1 | AY22: 1 | AZ22: 1 | BA22: 1 | BC22: =IF(AY21="","",AY21) -> 1 | BD22: =IF(AZ21="","",AZ21) -> 1 | BE22: =IF(BA21="","",BA21) -> 1 | BG22: =IF(AY20="","",AY20) -> 1 | BH22: =IF(AZ20="","",AZ20) -> 1 | BI22: =IF(BA20="","",BA20) -> 1 | BK22: 1 | BL22: 1 | BM22: 1 | BO22: =IF(BK21="","",BK21) -> 1 | BP22: =IF(BL21="","",BL21) -> 1 | BQ22: =IF(BM21="","",BM21) -> 1 | BS22: =IF(BK20="","",BK20) -> 1 | BT22: =IF(BL20="","",BL20) -> 1 | BU22: =IF(BM20="","",BM20) -> 1 | BW22: =IF(W22="","",VLOOKUP('Regular Symbol'!W22,'Regular Symbol'!$O$3:$T$13,6,0)) -> 2 | BX22: =IF(X22="","",VLOOKUP('Regular Symbol'!X22,'Regular Symbol'!$O$3:$T$13,6,0)) -> 2 | BY22: =IF(Y22="","",VLOOKUP('Regular Symbol'!Y22,'Regular Symbol'!$O$3:$T$13,6,0)) -> 3 | CA22: =IF(W22<>"", VLOOKUP(W22,$O$3:$P$13,2,0), "") -> M2 | CB22: =IF(X22<>"", VLOOKUP(X22,$O$3:$P$13,2,0), "") -> M2 | CC22: =IF(Y22<>"", VLOOKUP(Y22,$O$3:$P$13,2,0), "") -> M3
A23: WK | B23: WW,K | C23: =C$3+C$8 -> 28 | D23: =D$3+D$8 -> 49 | E23: =E$3+E$8 -> 48 | H23: WK | I23: WW,K | J23: =J$3+J$8 -> 28 | K23: =K$3+K$8 -> 49 | L23: =L$3+L$8 -> 48 | O23: WK | P23: WW,K | Q23: =Q$3+Q$8 -> 28 | R23: =R$3+R$8 -> 49 | S23: =S$3+S$8 -> 48 | V23: 20 | W23: A | X23: A | Y23: Q | AA23: 1 | AB23: 1 | AC23: 1 | AE23: =IF(AA22="","",AA22) -> 1 | AF23: =IF(AB22="","",AB22) -> 1 | AG23: =IF(AC22="","",AC22) -> 1 | AI23: =IF(AA21="","",AA21) -> 1 | AJ23: =IF(AB21="","",AB21) -> 1 | AK23: =IF(AC21="","",AC21) -> 1 | AM23: 1 | AN23: 1 | AO23: 1 | AQ23: =IF(AM22="","",AM22) -> 1 | AR23: =IF(AN22="","",AN22) -> 1 | AS23: =IF(AO22="","",AO22) -> 1 | AU23: =IF(AM21="","",AM21) -> 1 | AV23: =IF(AN21="","",AN21) -> 1 | AW23: =IF(AO21="","",AO21) -> 1 | AY23: 1 | AZ23: 1 | BA23: 1 | BC23: =IF(AY22="","",AY22) -> 1 | BD23: =IF(AZ22="","",AZ22) -> 1 | BE23: =IF(BA22="","",BA22) -> 1 | BG23: =IF(AY21="","",AY21) -> 1 | BH23: =IF(AZ21="","",AZ21) -> 1 | BI23: =IF(BA21="","",BA21) -> 1 | BK23: 1 | BL23: 1 | BM23: 1 | BO23: =IF(BK22="","",BK22) -> 1 | BP23: =IF(BL22="","",BL22) -> 1 | BQ23: =IF(BM22="","",BM22) -> 1 | BS23: =IF(BK21="","",BK21) -> 1 | BT23: =IF(BL21="","",BL21) -> 1 | BU23: =IF(BM21="","",BM21) -> 1 | BW23: =IF(W23="","",VLOOKUP('Regular Symbol'!W23,'Regular Symbol'!$O$3:$T$13,6,0)) -> 4 | BX23: =IF(X23="","",VLOOKUP('Regular Symbol'!X23,'Regular Symbol'!$O$3:$T$13,6,0)) -> 4 | BY23: =IF(Y23="","",VLOOKUP('Regular Symbol'!Y23,'Regular Symbol'!$O$3:$T$13,6,0)) -> 6 | CA23: =IF(W23<>"", VLOOKUP(W23,$O$3:$P$13,2,0), "") -> A | CB23: =IF(X23<>"", VLOOKUP(X23,$O$3:$P$13,2,0), "") -> A | CC23: =IF(Y23<>"", VLOOKUP(Y23,$O$3:$P$13,2,0), "") -> Q
A24: WQ | B24: WW,Q | C24: =C$3+C$9 -> 26 | D24: =D$3+D$9 -> 50 | E24: =E$3+E$9 -> 48 | H24: WQ | I24: WW,Q | J24: =J$3+J$9 -> 26 | K24: =K$3+K$9 -> 50 | L24: =L$3+L$9 -> 48 | O24: WQ | P24: WW,Q | Q24: =Q$3+Q$9 -> 26 | R24: =R$3+R$9 -> 50 | S24: =S$3+S$9 -> 48 | V24: 21 | W24: A | X24: A | Y24: Q | AA24: 1 | AB24: 1 | AC24: 1 | AE24: =IF(AA23="","",AA23) -> 1 | AF24: =IF(AB23="","",AB23) -> 1 | AG24: =IF(AC23="","",AC23) -> 1 | AI24: =IF(AA22="","",AA22) -> 1 | AJ24: =IF(AB22="","",AB22) -> 1 | AK24: =IF(AC22="","",AC22) -> 1 | AM24: 1 | AN24: 1 | AO24: 1 | AQ24: =IF(AM23="","",AM23) -> 1 | AR24: =IF(AN23="","",AN23) -> 1 | AS24: =IF(AO23="","",AO23) -> 1 | AU24: =IF(AM22="","",AM22) -> 1 | AV24: =IF(AN22="","",AN22) -> 1 | AW24: =IF(AO22="","",AO22) -> 1 | AY24: 1 | AZ24: 1 | BA24: 1 | BC24: =IF(AY23="","",AY23) -> 1 | BD24: =IF(AZ23="","",AZ23) -> 1 | BE24: =IF(BA23="","",BA23) -> 1 | BG24: =IF(AY22="","",AY22) -> 1 | BH24: =IF(AZ22="","",AZ22) -> 1 | BI24: =IF(BA22="","",BA22) -> 1 | BK24: 1 | BL24: 1 | BM24: 1 | BO24: =IF(BK23="","",BK23) -> 1 | BP24: =IF(BL23="","",BL23) -> 1 | BQ24: =IF(BM23="","",BM23) -> 1 | BS24: =IF(BK22="","",BK22) -> 1 | BT24: =IF(BL22="","",BL22) -> 1 | BU24: =IF(BM22="","",BM22) -> 1 | BW24: =IF(W24="","",VLOOKUP('Regular Symbol'!W24,'Regular Symbol'!$O$3:$T$13,6,0)) -> 4 | BX24: =IF(X24="","",VLOOKUP('Regular Symbol'!X24,'Regular Symbol'!$O$3:$T$13,6,0)) -> 4 | BY24: =IF(Y24="","",VLOOKUP('Regular Symbol'!Y24,'Regular Symbol'!$O$3:$T$13,6,0)) -> 6 | CA24: =IF(W24<>"", VLOOKUP(W24,$O$3:$P$13,2,0), "") -> A | CB24: =IF(X24<>"", VLOOKUP(X24,$O$3:$P$13,2,0), "") -> A | CC24: =IF(Y24<>"", VLOOKUP(Y24,$O$3:$P$13,2,0), "") -> Q
A25: WJ | B25: WW,J | C25: =C$3+C$10 -> 28 | D25: =D$3+D$10 -> 47 | E25: =E$3+E$10 -> 48 | H25: WJ | I25: WW,J | J25: =J$3+J$10 -> 28 | K25: =K$3+K$10 -> 47 | L25: =L$3+L$10 -> 48 | O25: WJ | P25: WW,J | Q25: =Q$3+Q$10 -> 28 | R25: =R$3+R$10 -> 47 | S25: =S$3+S$10 -> 48 | V25: 22 | W25: A | X25: WW | Y25: Q | AA25: 1 | AB25: 1 | AC25: 1 | AE25: =IF(AA24="","",AA24) -> 1 | AF25: =IF(AB24="","",AB24) -> 1 | AG25: =IF(AC24="","",AC24) -> 1 | AI25: =IF(AA23="","",AA23) -> 1 | AJ25: =IF(AB23="","",AB23) -> 1 | AK25: =IF(AC23="","",AC23) -> 1 | AM25: 1 | AN25: 1 | AO25: 1 | AQ25: =IF(AM24="","",AM24) -> 1 | AR25: =IF(AN24="","",AN24) -> 1 | AS25: =IF(AO24="","",AO24) -> 1 | AU25: =IF(AM23="","",AM23) -> 1 | AV25: =IF(AN23="","",AN23) -> 1 | AW25: =IF(AO23="","",AO23) -> 1 | AY25: 1 | AZ25: 1 | BA25: 1 | BC25: =IF(AY24="","",AY24) -> 1 | BD25: =IF(AZ24="","",AZ24) -> 1 | BE25: =IF(BA24="","",BA24) -> 1 | BG25: =IF(AY23="","",AY23) -> 1 | BH25: =IF(AZ23="","",AZ23) -> 1 | BI25: =IF(BA23="","",BA23) -> 1 | BK25: 1 | BL25: 1 | BM25: 1 | BO25: =IF(BK24="","",BK24) -> 1 | BP25: =IF(BL24="","",BL24) -> 1 | BQ25: =IF(BM24="","",BM24) -> 1 | BS25: =IF(BK23="","",BK23) -> 1 | BT25: =IF(BL23="","",BL23) -> 1 | BU25: =IF(BM23="","",BM23) -> 1 | BW25: =IF(W25="","",VLOOKUP('Regular Symbol'!W25,'Regular Symbol'!$O$3:$T$13,6,0)) -> 4 | BX25: =IF(X25="","",VLOOKUP('Regular Symbol'!X25,'Regular Symbol'!$O$3:$T$13,6,0)) -> 0 | BY25: =IF(Y25="","",VLOOKUP('Regular Symbol'!Y25,'Regular Symbol'!$O$3:$T$13,6,0)) -> 6 | CA25: =IF(W25<>"", VLOOKUP(W25,$O$3:$P$13,2,0), "") -> A | CB25: =IF(X25<>"", VLOOKUP(X25,$O$3:$P$13,2,0), "") -> Wild | CC25: =IF(Y25<>"", VLOOKUP(Y25,$O$3:$P$13,2,0), "") -> Q
V26: 23 | W26: M3 | X26: WW | Y26: A | AA26: 1 | AB26: 1 | AC26: 1 | AE26: =IF(AA25="","",AA25) -> 1 | AF26: =IF(AB25="","",AB25) -> 1 | AG26: =IF(AC25="","",AC25) -> 1 | AI26: =IF(AA24="","",AA24) -> 1 | AJ26: =IF(AB24="","",AB24) -> 1 | AK26: =IF(AC24="","",AC24) -> 1 | AM26: 1 | AN26: 1 | AO26: 1 | AQ26: =IF(AM25="","",AM25) -> 1 | AR26: =IF(AN25="","",AN25) -> 1 | AS26: =IF(AO25="","",AO25) -> 1 | AU26: =IF(AM24="","",AM24) -> 1 | AV26: =IF(AN24="","",AN24) -> 1 | AW26: =IF(AO24="","",AO24) -> 1 | AY26: 1 | AZ26: 1 | BA26: 1 | BC26: =IF(AY25="","",AY25) -> 1 | BD26: =IF(AZ25="","",AZ25) -> 1 | BE26: =IF(BA25="","",BA25) -> 1 | BG26: =IF(AY24="","",AY24) -> 1 | BH26: =IF(AZ24="","",AZ24) -> 1 | BI26: =IF(BA24="","",BA24) -> 1 | BK26: 1 | BL26: 1 | BM26: 1 | BO26: =IF(BK25="","",BK25) -> 1 | BP26: =IF(BL25="","",BL25) -> 1 | BQ26: =IF(BM25="","",BM25) -> 1 | BS26: =IF(BK24="","",BK24) -> 1 | BT26: =IF(BL24="","",BL24) -> 1 | BU26: =IF(BM24="","",BM24) -> 1 | BW26: =IF(W26="","",VLOOKUP('Regular Symbol'!W26,'Regular Symbol'!$O$3:$T$13,6,0)) -> 3 | BX26: =IF(X26="","",VLOOKUP('Regular Symbol'!X26,'Regular Symbol'!$O$3:$T$13,6,0)) -> 0 | BY26: =IF(Y26="","",VLOOKUP('Regular Symbol'!Y26,'Regular Symbol'!$O$3:$T$13,6,0)) -> 4 | CA26: =IF(W26<>"", VLOOKUP(W26,$O$3:$P$13,2,0), "") -> M3 | CB26: =IF(X26<>"", VLOOKUP(X26,$O$3:$P$13,2,0), "") -> Wild | CC26: =IF(Y26<>"", VLOOKUP(Y26,$O$3:$P$13,2,0), "") -> A
